{
    size: [14, 22, 19],
    data: [
        {pos: [0, 0, 0], state: "minecraft:tuff_bricks"},
        {pos: [0, 0, 1], state: "minecraft:tuff_bricks"},
        {pos: [0, 0, 2], state: "minecraft:tuff_bricks"},
        {pos: [0, 0, 3], state: "minecraft:tuff_bricks"},
        {pos: [0, 0, 4], state: "minecraft:tuff_bricks"},
        {pos: [0, 0, 5], state: "minecraft:tuff_bricks"},
        {pos: [0, 0, 6], state: "minecraft:tuff_bricks"},
        {pos: [0, 0, 7], state: "minecraft:tuff_bricks"},
        {pos: [0, 0, 8], state: "minecraft:tuff_bricks"},
        {pos: [0, 0, 9], state: "minecraft:tuff_bricks"},
        {pos: [0, 0, 10], state: "minecraft:tuff_bricks"},
        {pos: [0, 0, 11], state: "minecraft:tuff_bricks"},
        {pos: [0, 0, 12], state: "minecraft:tuff_bricks"},
        {pos: [0, 0, 13], state: "minecraft:tuff_bricks"},
        {pos: [0, 0, 14], state: "minecraft:tuff_bricks"},
        {pos: [0, 0, 15], state: "minecraft:tuff_bricks"},
        {pos: [0, 0, 16], state: "minecraft:tuff_bricks"},
        {pos: [0, 0, 17], state: "minecraft:tuff_bricks"},
        {pos: [0, 0, 18], state: "minecraft:tuff_bricks"},
        {pos: [1, 0, 0], state: "minecraft:tuff_bricks"},
        {pos: [1, 0, 1], state: "minecraft:tuff_bricks"},
        {pos: [1, 0, 2], state: "minecraft:tuff_bricks"},
        {pos: [1, 0, 3], state: "minecraft:tuff_bricks"},
        {pos: [1, 0, 4], state: "minecraft:tuff_bricks"},
        {pos: [1, 0, 5], state: "minecraft:tuff_bricks"},
        {pos: [1, 0, 6], state: "minecraft:tuff_bricks"},
        {pos: [1, 0, 7], state: "minecraft:tuff_bricks"},
        {pos: [1, 0, 8], state: "minecraft:tuff_bricks"},
        {pos: [1, 0, 9], state: "minecraft:tuff_bricks"},
        {pos: [1, 0, 10], state: "minecraft:tuff_bricks"},
        {pos: [1, 0, 11], state: "minecraft:tuff_bricks"},
        {pos: [1, 0, 12], state: "minecraft:tuff_bricks"},
        {pos: [1, 0, 13], state: "minecraft:tuff_bricks"},
        {pos: [1, 0, 14], state: "minecraft:tuff_bricks"},
        {pos: [1, 0, 15], state: "minecraft:tuff_bricks"},
        {pos: [1, 0, 16], state: "minecraft:tuff_bricks"},
        {pos: [1, 0, 17], state: "minecraft:tuff_bricks"},
        {pos: [1, 0, 18], state: "minecraft:tuff_bricks"},
        {pos: [2, 0, 0], state: "minecraft:tuff_bricks"},
        {pos: [2, 0, 1], state: "minecraft:tuff_bricks"},
        {pos: [2, 0, 2], state: "minecraft:tuff_bricks"},
        {pos: [2, 0, 3], state: "minecraft:tuff_bricks"},
        {pos: [2, 0, 4], state: "minecraft:tuff_bricks"},
        {pos: [2, 0, 5], state: "minecraft:tuff_bricks"},
        {pos: [2, 0, 6], state: "minecraft:tuff_bricks"},
        {pos: [2, 0, 7], state: "minecraft:tuff_bricks"},
        {pos: [2, 0, 8], state: "minecraft:tuff_bricks"},
        {pos: [2, 0, 9], state: "minecraft:tuff_bricks"},
        {pos: [2, 0, 10], state: "minecraft:tuff_bricks"},
        {pos: [2, 0, 11], state: "minecraft:tuff_bricks"},
        {pos: [2, 0, 12], state: "minecraft:tuff_bricks"},
        {pos: [2, 0, 13], state: "minecraft:tuff_bricks"},
        {pos: [2, 0, 14], state: "minecraft:tuff_bricks"},
        {pos: [2, 0, 15], state: "minecraft:tuff_bricks"},
        {pos: [2, 0, 16], state: "minecraft:tuff_bricks"},
        {pos: [2, 0, 17], state: "minecraft:tuff_bricks"},
        {pos: [2, 0, 18], state: "minecraft:tuff_bricks"},
        {pos: [3, 0, 0], state: "minecraft:tuff_bricks"},
        {pos: [3, 0, 1], state: "minecraft:tuff_bricks"},
        {pos: [3, 0, 2], state: "minecraft:tuff_bricks"},
        {pos: [3, 0, 3], state: "minecraft:tuff_bricks"},
        {pos: [3, 0, 4], state: "minecraft:tuff_bricks"},
        {pos: [3, 0, 5], state: "minecraft:tuff_bricks"},
        {pos: [3, 0, 6], state: "minecraft:tuff_bricks"},
        {pos: [3, 0, 7], state: "minecraft:tuff_bricks"},
        {pos: [3, 0, 8], state: "minecraft:tuff_bricks"},
        {pos: [3, 0, 9], state: "minecraft:tuff_bricks"},
        {pos: [3, 0, 10], state: "minecraft:tuff_bricks"},
        {pos: [3, 0, 11], state: "minecraft:tuff_bricks"},
        {pos: [3, 0, 12], state: "minecraft:tuff_bricks"},
        {pos: [3, 0, 13], state: "minecraft:tuff_bricks"},
        {pos: [3, 0, 14], state: "minecraft:tuff_bricks"},
        {pos: [3, 0, 15], state: "minecraft:tuff_bricks"},
        {pos: [3, 0, 16], state: "minecraft:tuff_bricks"},
        {pos: [3, 0, 17], state: "minecraft:tuff_bricks"},
        {pos: [3, 0, 18], state: "minecraft:tuff_bricks"},
        {pos: [4, 0, 0], state: "minecraft:tuff_bricks"},
        {pos: [4, 0, 1], state: "minecraft:tuff_bricks"},
        {pos: [4, 0, 2], state: "minecraft:tuff_bricks"},
        {pos: [4, 0, 3], state: "minecraft:tuff_bricks"},
        {pos: [4, 0, 4], state: "minecraft:tuff_bricks"},
        {pos: [4, 0, 5], state: "minecraft:tuff_bricks"},
        {pos: [4, 0, 6], state: "minecraft:tuff_bricks"},
        {pos: [4, 0, 7], state: "minecraft:tuff_bricks"},
        {pos: [4, 0, 8], state: "minecraft:tuff_bricks"},
        {pos: [4, 0, 9], state: "minecraft:tuff_bricks"},
        {pos: [4, 0, 10], state: "minecraft:tuff_bricks"},
        {pos: [4, 0, 11], state: "minecraft:tuff_bricks"},
        {pos: [4, 0, 12], state: "minecraft:tuff_bricks"},
        {pos: [4, 0, 13], state: "minecraft:tuff_bricks"},
        {pos: [4, 0, 14], state: "minecraft:tuff_bricks"},
        {pos: [4, 0, 15], state: "minecraft:tuff_bricks"},
        {pos: [4, 0, 16], state: "minecraft:tuff_bricks"},
        {pos: [4, 0, 17], state: "minecraft:tuff_bricks"},
        {pos: [4, 0, 18], state: "minecraft:tuff_bricks"},
        {pos: [5, 0, 0], state: "minecraft:tuff_bricks"},
        {pos: [5, 0, 1], state: "minecraft:tuff_bricks"},
        {pos: [5, 0, 2], state: "minecraft:tuff_bricks"},
        {pos: [5, 0, 3], state: "minecraft:tuff_bricks"},
        {pos: [5, 0, 4], state: "minecraft:tuff_bricks"},
        {pos: [5, 0, 5], state: "minecraft:tuff_bricks"},
        {pos: [5, 0, 6], state: "minecraft:tuff_bricks"},
        {pos: [5, 0, 7], state: "minecraft:tuff_bricks"},
        {pos: [5, 0, 8], state: "minecraft:tuff_bricks"},
        {pos: [5, 0, 9], state: "minecraft:tuff_bricks"},
        {pos: [5, 0, 10], state: "minecraft:tuff_bricks"},
        {pos: [5, 0, 11], state: "minecraft:tuff_bricks"},
        {pos: [5, 0, 12], state: "minecraft:tuff_bricks"},
        {pos: [5, 0, 13], state: "minecraft:tuff_bricks"},
        {pos: [5, 0, 14], state: "minecraft:tuff_bricks"},
        {pos: [5, 0, 15], state: "minecraft:tuff_bricks"},
        {pos: [5, 0, 16], state: "minecraft:tuff_bricks"},
        {pos: [5, 0, 17], state: "minecraft:tuff_bricks"},
        {pos: [5, 0, 18], state: "minecraft:tuff_bricks"},
        {pos: [6, 0, 0], state: "minecraft:tuff_bricks"},
        {pos: [6, 0, 1], state: "minecraft:tuff_bricks"},
        {pos: [6, 0, 2], state: "minecraft:tuff_bricks"},
        {pos: [6, 0, 3], state: "minecraft:tuff_bricks"},
        {pos: [6, 0, 4], state: "minecraft:tuff_bricks"},
        {pos: [6, 0, 5], state: "minecraft:tuff_bricks"},
        {pos: [6, 0, 6], state: "minecraft:tuff_bricks"},
        {pos: [6, 0, 7], state: "minecraft:tuff_bricks"},
        {pos: [6, 0, 8], state: "minecraft:tuff_bricks"},
        {pos: [6, 0, 9], state: "minecraft:tuff_bricks"},
        {pos: [6, 0, 10], state: "minecraft:tuff_bricks"},
        {pos: [6, 0, 11], state: "minecraft:tuff_bricks"},
        {pos: [6, 0, 12], state: "minecraft:tuff_bricks"},
        {pos: [6, 0, 13], state: "minecraft:tuff_bricks"},
        {pos: [6, 0, 14], state: "minecraft:tuff_bricks"},
        {pos: [6, 0, 15], state: "minecraft:tuff_bricks"},
        {pos: [6, 0, 16], state: "minecraft:tuff_bricks"},
        {pos: [6, 0, 17], state: "minecraft:tuff_bricks"},
        {pos: [6, 0, 18], state: "minecraft:tuff_bricks"},
        {pos: [7, 0, 0], state: "minecraft:tuff_bricks"},
        {pos: [7, 0, 1], state: "minecraft:tuff_bricks"},
        {pos: [7, 0, 2], state: "minecraft:tuff_bricks"},
        {pos: [7, 0, 3], state: "minecraft:tuff_bricks"},
        {pos: [7, 0, 4], state: "minecraft:tuff_bricks"},
        {pos: [7, 0, 5], state: "minecraft:tuff_bricks"},
        {pos: [7, 0, 6], state: "minecraft:tuff_bricks"},
        {pos: [7, 0, 7], state: "minecraft:tuff_bricks"},
        {pos: [7, 0, 8], state: "minecraft:tuff_bricks"},
        {pos: [7, 0, 9], state: "minecraft:tuff_bricks"},
        {pos: [7, 0, 10], state: "minecraft:tuff_bricks"},
        {pos: [7, 0, 11], state: "minecraft:tuff_bricks"},
        {pos: [7, 0, 12], state: "minecraft:tuff_bricks"},
        {pos: [7, 0, 13], state: "minecraft:tuff_bricks"},
        {pos: [7, 0, 14], state: "minecraft:tuff_bricks"},
        {pos: [7, 0, 15], state: "minecraft:tuff_bricks"},
        {pos: [7, 0, 16], state: "minecraft:tuff_bricks"},
        {pos: [7, 0, 17], state: "minecraft:tuff_bricks"},
        {pos: [7, 0, 18], state: "minecraft:tuff_bricks"},
        {pos: [8, 0, 0], state: "minecraft:tuff_bricks"},
        {pos: [8, 0, 1], state: "minecraft:tuff_bricks"},
        {pos: [8, 0, 2], state: "minecraft:tuff_bricks"},
        {pos: [8, 0, 3], state: "minecraft:tuff_bricks"},
        {pos: [8, 0, 4], state: "minecraft:tuff_bricks"},
        {pos: [8, 0, 5], state: "minecraft:tuff_bricks"},
        {pos: [8, 0, 6], state: "minecraft:tuff_bricks"},
        {pos: [8, 0, 7], state: "minecraft:tuff_bricks"},
        {pos: [8, 0, 8], state: "minecraft:tuff_bricks"},
        {pos: [8, 0, 9], state: "minecraft:tuff_bricks"},
        {pos: [8, 0, 10], state: "minecraft:tuff_bricks"},
        {pos: [8, 0, 11], state: "minecraft:tuff_bricks"},
        {pos: [8, 0, 12], state: "minecraft:tuff_bricks"},
        {pos: [8, 0, 13], state: "minecraft:tuff_bricks"},
        {pos: [8, 0, 14], state: "minecraft:tuff_bricks"},
        {pos: [8, 0, 15], state: "minecraft:tuff_bricks"},
        {pos: [8, 0, 16], state: "minecraft:tuff_bricks"},
        {pos: [8, 0, 17], state: "minecraft:tuff_bricks"},
        {pos: [8, 0, 18], state: "minecraft:tuff_bricks"},
        {pos: [9, 0, 0], state: "minecraft:tuff_bricks"},
        {pos: [9, 0, 1], state: "minecraft:tuff_bricks"},
        {pos: [9, 0, 2], state: "minecraft:tuff_bricks"},
        {pos: [9, 0, 3], state: "minecraft:tuff_bricks"},
        {pos: [9, 0, 4], state: "minecraft:tuff_bricks"},
        {pos: [9, 0, 5], state: "minecraft:tuff_bricks"},
        {pos: [9, 0, 6], state: "minecraft:tuff_bricks"},
        {pos: [9, 0, 7], state: "minecraft:tuff_bricks"},
        {pos: [9, 0, 8], state: "minecraft:tuff_bricks"},
        {pos: [9, 0, 9], state: "minecraft:tuff_bricks"},
        {pos: [9, 0, 10], state: "minecraft:tuff_bricks"},
        {pos: [9, 0, 11], state: "minecraft:tuff_bricks"},
        {pos: [9, 0, 12], state: "minecraft:tuff_bricks"},
        {pos: [9, 0, 13], state: "minecraft:tuff_bricks"},
        {pos: [9, 0, 14], state: "minecraft:tuff_bricks"},
        {pos: [9, 0, 15], state: "minecraft:tuff_bricks"},
        {pos: [9, 0, 16], state: "minecraft:tuff_bricks"},
        {pos: [9, 0, 17], state: "minecraft:tuff_bricks"},
        {pos: [9, 0, 18], state: "minecraft:tuff_bricks"},
        {pos: [10, 0, 0], state: "minecraft:tuff_bricks"},
        {pos: [10, 0, 1], state: "minecraft:tuff_bricks"},
        {pos: [10, 0, 2], state: "minecraft:tuff_bricks"},
        {pos: [10, 0, 3], state: "minecraft:tuff_bricks"},
        {pos: [10, 0, 4], state: "minecraft:tuff_bricks"},
        {pos: [10, 0, 5], state: "minecraft:tuff_bricks"},
        {pos: [10, 0, 6], state: "minecraft:tuff_bricks"},
        {pos: [10, 0, 7], state: "minecraft:tuff_bricks"},
        {pos: [10, 0, 8], state: "minecraft:tuff_bricks"},
        {pos: [10, 0, 9], state: "minecraft:tuff_bricks"},
        {pos: [10, 0, 10], state: "minecraft:tuff_bricks"},
        {pos: [10, 0, 11], state: "minecraft:tuff_bricks"},
        {pos: [10, 0, 12], state: "minecraft:tuff_bricks"},
        {pos: [10, 0, 13], state: "minecraft:tuff_bricks"},
        {pos: [10, 0, 14], state: "minecraft:tuff_bricks"},
        {pos: [10, 0, 15], state: "minecraft:tuff_bricks"},
        {pos: [10, 0, 16], state: "minecraft:tuff_bricks"},
        {pos: [10, 0, 17], state: "minecraft:tuff_bricks"},
        {pos: [10, 0, 18], state: "minecraft:tuff_bricks"},
        {pos: [11, 0, 0], state: "minecraft:tuff_bricks"},
        {pos: [11, 0, 1], state: "minecraft:tuff_bricks"},
        {pos: [11, 0, 2], state: "minecraft:tuff_bricks"},
        {pos: [11, 0, 3], state: "minecraft:tuff_bricks"},
        {pos: [11, 0, 4], state: "minecraft:tuff_bricks"},
        {pos: [11, 0, 5], state: "minecraft:tuff_bricks"},
        {pos: [11, 0, 6], state: "minecraft:tuff_bricks"},
        {pos: [11, 0, 7], state: "minecraft:tuff_bricks"},
        {pos: [11, 0, 8], state: "minecraft:tuff_bricks"},
        {pos: [11, 0, 9], state: "minecraft:tuff_bricks"},
        {pos: [11, 0, 10], state: "minecraft:tuff_bricks"},
        {pos: [11, 0, 11], state: "minecraft:tuff_bricks"},
        {pos: [11, 0, 12], state: "minecraft:tuff_bricks"},
        {pos: [11, 0, 13], state: "minecraft:tuff_bricks"},
        {pos: [11, 0, 14], state: "minecraft:tuff_bricks"},
        {pos: [11, 0, 15], state: "minecraft:tuff_bricks"},
        {pos: [11, 0, 16], state: "minecraft:tuff_bricks"},
        {pos: [11, 0, 17], state: "minecraft:tuff_bricks"},
        {pos: [11, 0, 18], state: "minecraft:tuff_bricks"},
        {pos: [12, 0, 0], state: "minecraft:tuff_bricks"},
        {pos: [12, 0, 1], state: "minecraft:tuff_bricks"},
        {pos: [12, 0, 2], state: "minecraft:tuff_bricks"},
        {pos: [12, 0, 3], state: "minecraft:tuff_bricks"},
        {pos: [12, 0, 4], state: "minecraft:tuff_bricks"},
        {pos: [12, 0, 5], state: "minecraft:tuff_bricks"},
        {pos: [12, 0, 6], state: "minecraft:tuff_bricks"},
        {pos: [12, 0, 7], state: "minecraft:tuff_bricks"},
        {pos: [12, 0, 8], state: "minecraft:tuff_bricks"},
        {pos: [12, 0, 9], state: "minecraft:tuff_bricks"},
        {pos: [12, 0, 10], state: "minecraft:tuff_bricks"},
        {pos: [12, 0, 11], state: "minecraft:tuff_bricks"},
        {pos: [12, 0, 12], state: "minecraft:tuff_bricks"},
        {pos: [12, 0, 13], state: "minecraft:tuff_bricks"},
        {pos: [12, 0, 14], state: "minecraft:tuff_bricks"},
        {pos: [12, 0, 15], state: "minecraft:tuff_bricks"},
        {pos: [12, 0, 16], state: "minecraft:tuff_bricks"},
        {pos: [12, 0, 17], state: "minecraft:tuff_bricks"},
        {pos: [12, 0, 18], state: "minecraft:tuff_bricks"},
        {pos: [13, 0, 0], state: "minecraft:tuff_bricks"},
        {pos: [13, 0, 1], state: "minecraft:tuff_bricks"},
        {pos: [13, 0, 2], state: "minecraft:tuff_bricks"},
        {pos: [13, 0, 3], state: "minecraft:tuff_bricks"},
        {pos: [13, 0, 4], state: "minecraft:tuff_bricks"},
        {pos: [13, 0, 5], state: "minecraft:tuff_bricks"},
        {pos: [13, 0, 6], state: "minecraft:tuff_bricks"},
        {pos: [13, 0, 7], state: "minecraft:tuff_bricks"},
        {pos: [13, 0, 8], state: "minecraft:tuff_bricks"},
        {pos: [13, 0, 9], state: "minecraft:tuff_bricks"},
        {pos: [13, 0, 10], state: "minecraft:tuff_bricks"},
        {pos: [13, 0, 11], state: "minecraft:tuff_bricks"},
        {pos: [13, 0, 12], state: "minecraft:tuff_bricks"},
        {pos: [13, 0, 13], state: "minecraft:tuff_bricks"},
        {pos: [13, 0, 14], state: "minecraft:tuff_bricks"},
        {pos: [13, 0, 15], state: "minecraft:tuff_bricks"},
        {pos: [13, 0, 16], state: "minecraft:tuff_bricks"},
        {pos: [13, 0, 17], state: "minecraft:tuff_bricks"},
        {pos: [13, 0, 18], state: "minecraft:tuff_bricks"},
        {pos: [0, 1, 0], state: "minecraft:tuff_bricks"},
        {pos: [0, 1, 1], state: "minecraft:tuff_bricks"},
        {pos: [0, 1, 2], state: "minecraft:tuff_bricks"},
        {pos: [0, 1, 3], state: "minecraft:tuff_bricks"},
        {pos: [0, 1, 4], state: "minecraft:tuff_bricks"},
        {pos: [0, 1, 5], state: "minecraft:tuff_bricks"},
        {pos: [0, 1, 6], state: "minecraft:tuff_bricks"},
        {pos: [0, 1, 7], state: "minecraft:tuff_bricks"},
        {pos: [0, 1, 8], state: "minecraft:tuff_bricks"},
        {pos: [0, 1, 9], state: "minecraft:tuff_bricks"},
        {pos: [0, 1, 10], state: "minecraft:tuff_bricks"},
        {pos: [0, 1, 11], state: "minecraft:tuff_bricks"},
        {pos: [0, 1, 12], state: "minecraft:tuff_bricks"},
        {pos: [0, 1, 13], state: "minecraft:tuff_bricks"},
        {pos: [0, 1, 14], state: "minecraft:tuff_bricks"},
        {pos: [0, 1, 15], state: "minecraft:tuff_bricks"},
        {pos: [0, 1, 16], state: "minecraft:tuff_bricks"},
        {pos: [0, 1, 17], state: "minecraft:tuff_bricks"},
        {pos: [0, 1, 18], state: "minecraft:tuff_bricks"},
        {pos: [1, 1, 0], state: "minecraft:tuff_bricks"},
        {pos: [1, 1, 1], state: "minecraft:waxed_copper_block"},
        {pos: [1, 1, 2], state: "minecraft:waxed_copper_block"},
        {pos: [1, 1, 3], state: "minecraft:waxed_copper_block"},
        {pos: [1, 1, 4], state: "minecraft:waxed_copper_block"},
        {pos: [1, 1, 5], state: "minecraft:waxed_copper_block"},
        {pos: [1, 1, 6], state: "minecraft:waxed_copper_block"},
        {pos: [1, 1, 7], state: "minecraft:waxed_copper_block"},
        {pos: [1, 1, 8], state: "minecraft:waxed_copper_block"},
        {pos: [1, 1, 9], state: "minecraft:waxed_copper_block"},
        {pos: [1, 1, 10], state: "minecraft:waxed_copper_block"},
        {pos: [1, 1, 11], state: "minecraft:waxed_copper_block"},
        {pos: [1, 1, 12], state: "minecraft:waxed_copper_block"},
        {pos: [1, 1, 13], state: "minecraft:waxed_copper_block"},
        {pos: [1, 1, 14], state: "minecraft:waxed_copper_block"},
        {pos: [1, 1, 15], state: "minecraft:waxed_copper_block"},
        {pos: [1, 1, 16], state: "minecraft:waxed_copper_block"},
        {pos: [1, 1, 17], state: "minecraft:waxed_copper_block"},
        {pos: [1, 1, 18], state: "minecraft:tuff_bricks"},
        {pos: [2, 1, 0], state: "minecraft:tuff_bricks"},
        {pos: [2, 1, 1], state: "minecraft:waxed_copper_block"},
        {pos: [2, 1, 2], state: "minecraft:waxed_copper_block"},
        {pos: [2, 1, 6], state: "minecraft:waxed_copper_block"},
        {pos: [2, 1, 7], state: "minecraft:waxed_copper_block"},
        {pos: [2, 1, 11], state: "minecraft:waxed_copper_block"},
        {pos: [2, 1, 12], state: "minecraft:waxed_copper_block"},
        {pos: [2, 1, 16], state: "minecraft:waxed_copper_block"},
        {pos: [2, 1, 17], state: "minecraft:waxed_copper_block"},
        {pos: [2, 1, 18], state: "minecraft:tuff_bricks"},
        {pos: [3, 1, 0], state: "minecraft:tuff_bricks"},
        {pos: [3, 1, 1], state: "minecraft:waxed_copper_block"},
        {pos: [3, 1, 17], state: "minecraft:waxed_copper_block"},
        {pos: [3, 1, 18], state: "minecraft:tuff_bricks"},
        {pos: [4, 1, 0], state: "minecraft:tuff_bricks"},
        {pos: [4, 1, 1], state: "minecraft:waxed_copper_block"},
        {pos: [4, 1, 17], state: "minecraft:waxed_copper_block"},
        {pos: [4, 1, 18], state: "minecraft:tuff_bricks"},
        {pos: [5, 1, 0], state: "minecraft:tuff_bricks"},
        {pos: [5, 1, 1], state: "minecraft:waxed_copper_block"},
        {pos: [5, 1, 17], state: "minecraft:waxed_copper_block"},
        {pos: [5, 1, 18], state: "minecraft:tuff_bricks"},
        {pos: [6, 1, 0], state: "minecraft:tuff_bricks"},
        {pos: [6, 1, 1], state: "minecraft:waxed_copper_block"},
        {pos: [6, 1, 2], state: "minecraft:waxed_copper_block"},
        {pos: [6, 1, 6], state: "minecraft:waxed_copper_block"},
        {pos: [6, 1, 7], state: "minecraft:waxed_copper_block"},
        {pos: [6, 1, 11], state: "minecraft:waxed_copper_block"},
        {pos: [6, 1, 12], state: "minecraft:waxed_copper_block"},
        {pos: [6, 1, 16], state: "minecraft:waxed_copper_block"},
        {pos: [6, 1, 17], state: "minecraft:waxed_copper_block"},
        {pos: [6, 1, 18], state: "minecraft:tuff_bricks"},
        {pos: [7, 1, 0], state: "minecraft:tuff_bricks"},
        {pos: [7, 1, 1], state: "minecraft:waxed_copper_block"},
        {pos: [7, 1, 2], state: "minecraft:waxed_copper_block"},
        {pos: [7, 1, 6], state: "minecraft:waxed_copper_block"},
        {pos: [7, 1, 7], state: "minecraft:waxed_copper_block"},
        {pos: [7, 1, 8], state: "minecraft:waxed_copper_block"},
        {pos: [7, 1, 9], state: "minecraft:waxed_copper_block"},
        {pos: [7, 1, 10], state: "minecraft:waxed_copper_block"},
        {pos: [7, 1, 11], state: "minecraft:waxed_copper_block"},
        {pos: [7, 1, 12], state: "minecraft:waxed_copper_block"},
        {pos: [7, 1, 16], state: "minecraft:waxed_copper_block"},
        {pos: [7, 1, 17], state: "minecraft:waxed_copper_block"},
        {pos: [7, 1, 18], state: "minecraft:tuff_bricks"},
        {pos: [8, 1, 0], state: "minecraft:tuff_bricks"},
        {pos: [8, 1, 1], state: "minecraft:waxed_copper_block"},
        {pos: [8, 1, 7], state: "minecraft:waxed_copper_block"},
        {pos: [8, 1, 8], state: "minecraft:waxed_copper_block"},
        {pos: [8, 1, 9], state: "minecraft:waxed_copper_block"},
        {pos: [8, 1, 10], state: "minecraft:waxed_copper_block"},
        {pos: [8, 1, 11], state: "minecraft:waxed_copper_block"},
        {pos: [8, 1, 17], state: "minecraft:waxed_copper_block"},
        {pos: [8, 1, 18], state: "minecraft:tuff_bricks"},
        {pos: [9, 1, 0], state: "minecraft:tuff_bricks"},
        {pos: [9, 1, 1], state: "minecraft:waxed_copper_block"},
        {pos: [9, 1, 7], state: "minecraft:waxed_copper_block"},
        {pos: [9, 1, 8], state: "minecraft:waxed_copper_block"},
        {pos: [9, 1, 9], state: "minecraft:waxed_copper_block"},
        {pos: [9, 1, 10], state: "minecraft:waxed_copper_block"},
        {pos: [9, 1, 11], state: "minecraft:waxed_copper_block"},
        {pos: [9, 1, 17], state: "minecraft:waxed_copper_block"},
        {pos: [9, 1, 18], state: "minecraft:tuff_bricks"},
        {pos: [10, 1, 0], state: "minecraft:tuff_bricks"},
        {pos: [10, 1, 1], state: "minecraft:waxed_copper_block"},
        {pos: [10, 1, 7], state: "minecraft:waxed_copper_block"},
        {pos: [10, 1, 8], state: "minecraft:waxed_copper_block"},
        {pos: [10, 1, 9], state: "minecraft:waxed_copper_block"},
        {pos: [10, 1, 10], state: "minecraft:waxed_copper_block"},
        {pos: [10, 1, 11], state: "minecraft:waxed_copper_block"},
        {pos: [10, 1, 17], state: "minecraft:waxed_copper_block"},
        {pos: [10, 1, 18], state: "minecraft:tuff_bricks"},
        {pos: [11, 1, 0], state: "minecraft:tuff_bricks"},
        {pos: [11, 1, 1], state: "minecraft:waxed_copper_block"},
        {pos: [11, 1, 2], state: "minecraft:waxed_copper_block"},
        {pos: [11, 1, 6], state: "minecraft:waxed_copper_block"},
        {pos: [11, 1, 7], state: "minecraft:waxed_copper_block"},
        {pos: [11, 1, 8], state: "minecraft:waxed_copper_block"},
        {pos: [11, 1, 9], state: "minecraft:waxed_copper_block"},
        {pos: [11, 1, 10], state: "minecraft:waxed_copper_block"},
        {pos: [11, 1, 11], state: "minecraft:waxed_copper_block"},
        {pos: [11, 1, 12], state: "minecraft:waxed_copper_block"},
        {pos: [11, 1, 16], state: "minecraft:waxed_copper_block"},
        {pos: [11, 1, 17], state: "minecraft:waxed_copper_block"},
        {pos: [11, 1, 18], state: "minecraft:tuff_bricks"},
        {pos: [12, 1, 0], state: "minecraft:tuff_bricks"},
        {pos: [12, 1, 1], state: "minecraft:waxed_copper_block"},
        {pos: [12, 1, 2], state: "minecraft:waxed_copper_block"},
        {pos: [12, 1, 3], state: "minecraft:waxed_copper_block"},
        {pos: [12, 1, 4], state: "minecraft:waxed_copper_block"},
        {pos: [12, 1, 5], state: "minecraft:waxed_copper_block"},
        {pos: [12, 1, 6], state: "minecraft:waxed_copper_block"},
        {pos: [12, 1, 7], state: "minecraft:waxed_copper_block"},
        {pos: [12, 1, 8], state: "minecraft:waxed_copper_block"},
        {pos: [12, 1, 9], state: "minecraft:waxed_copper_block"},
        {pos: [12, 1, 10], state: "minecraft:waxed_copper_block"},
        {pos: [12, 1, 11], state: "minecraft:waxed_copper_block"},
        {pos: [12, 1, 12], state: "minecraft:waxed_copper_block"},
        {pos: [12, 1, 13], state: "minecraft:waxed_copper_block"},
        {pos: [12, 1, 14], state: "minecraft:waxed_copper_block"},
        {pos: [12, 1, 15], state: "minecraft:waxed_copper_block"},
        {pos: [12, 1, 16], state: "minecraft:waxed_copper_block"},
        {pos: [12, 1, 17], state: "minecraft:waxed_copper_block"},
        {pos: [12, 1, 18], state: "minecraft:tuff_bricks"},
        {pos: [13, 1, 0], state: "minecraft:tuff_bricks"},
        {pos: [13, 1, 1], state: "minecraft:tuff_bricks"},
        {pos: [13, 1, 2], state: "minecraft:tuff_bricks"},
        {pos: [13, 1, 3], state: "minecraft:tuff_bricks"},
        {pos: [13, 1, 4], state: "minecraft:tuff_bricks"},
        {pos: [13, 1, 5], state: "minecraft:tuff_bricks"},
        {pos: [13, 1, 6], state: "minecraft:tuff_bricks"},
        {pos: [13, 1, 7], state: "minecraft:tuff_bricks"},
        {pos: [13, 1, 8], state: "minecraft:tuff_bricks"},
        {pos: [13, 1, 9], state: "minecraft:tuff_bricks"},
        {pos: [13, 1, 10], state: "minecraft:tuff_bricks"},
        {pos: [13, 1, 11], state: "minecraft:tuff_bricks"},
        {pos: [13, 1, 12], state: "minecraft:tuff_bricks"},
        {pos: [13, 1, 13], state: "minecraft:tuff_bricks"},
        {pos: [13, 1, 14], state: "minecraft:tuff_bricks"},
        {pos: [13, 1, 15], state: "minecraft:tuff_bricks"},
        {pos: [13, 1, 16], state: "minecraft:tuff_bricks"},
        {pos: [13, 1, 17], state: "minecraft:tuff_bricks"},
        {pos: [13, 1, 18], state: "minecraft:tuff_bricks"},
        {pos: [0, 2, 0], state: "minecraft:tuff_bricks"},
        {pos: [0, 2, 1], state: "minecraft:tuff_bricks"},
        {pos: [0, 2, 2], state: "minecraft:tuff_bricks"},
        {pos: [0, 2, 3], state: "minecraft:tuff_bricks"},
        {pos: [0, 2, 4], state: "minecraft:tuff_bricks"},
        {pos: [0, 2, 5], state: "minecraft:tuff_bricks"},
        {pos: [0, 2, 6], state: "minecraft:tuff_bricks"},
        {pos: [0, 2, 7], state: "minecraft:tuff_bricks"},
        {pos: [0, 2, 8], state: "minecraft:tuff_bricks"},
        {pos: [0, 2, 9], state: "minecraft:tuff_bricks"},
        {pos: [0, 2, 10], state: "minecraft:tuff_bricks"},
        {pos: [0, 2, 11], state: "minecraft:tuff_bricks"},
        {pos: [0, 2, 12], state: "minecraft:tuff_bricks"},
        {pos: [0, 2, 13], state: "minecraft:tuff_bricks"},
        {pos: [0, 2, 14], state: "minecraft:tuff_bricks"},
        {pos: [0, 2, 15], state: "minecraft:tuff_bricks"},
        {pos: [0, 2, 16], state: "minecraft:tuff_bricks"},
        {pos: [0, 2, 17], state: "minecraft:tuff_bricks"},
        {pos: [0, 2, 18], state: "minecraft:tuff_bricks"},
        {pos: [1, 2, 0], state: "minecraft:tuff_bricks"},
        {pos: [1, 2, 1], state: "minecraft:tuff_bricks"},
        {pos: [1, 2, 2], state: "minecraft:tuff_bricks"},
        {pos: [1, 2, 3], state: "minecraft:tuff_bricks"},
        {pos: [1, 2, 4], state: "minecraft:waxed_copper_bulb{powered:false,lit:true}"},
        {pos: [1, 2, 5], state: "minecraft:tuff_bricks"},
        {pos: [1, 2, 6], state: "minecraft:tuff_bricks"},
        {pos: [1, 2, 7], state: "minecraft:tuff_bricks"},
        {pos: [1, 2, 8], state: "minecraft:tuff_bricks"},
        {pos: [1, 2, 9], state: "minecraft:waxed_copper_bulb{powered:false,lit:true}"},
        {pos: [1, 2, 10], state: "minecraft:tuff_bricks"},
        {pos: [1, 2, 11], state: "minecraft:tuff_bricks"},
        {pos: [1, 2, 12], state: "minecraft:tuff_bricks"},
        {pos: [1, 2, 13], state: "minecraft:tuff_bricks"},
        {pos: [1, 2, 14], state: "minecraft:waxed_copper_bulb{powered:false,lit:true}"},
        {pos: [1, 2, 15], state: "minecraft:tuff_bricks"},
        {pos: [1, 2, 16], state: "minecraft:tuff_bricks"},
        {pos: [1, 2, 17], state: "minecraft:tuff_bricks"},
        {pos: [1, 2, 18], state: "minecraft:tuff_bricks"},
        {pos: [2, 2, 0], state: "minecraft:tuff_bricks"},
        {pos: [2, 2, 1], state: "minecraft:tuff_bricks"},
        {pos: [2, 2, 2], state: "minecraft:tuff_bricks"},
        {pos: [2, 2, 6], state: "minecraft:tuff_bricks"},
        {pos: [2, 2, 7], state: "minecraft:tuff_bricks"},
        {pos: [2, 2, 11], state: "minecraft:tuff_bricks"},
        {pos: [2, 2, 12], state: "minecraft:tuff_bricks"},
        {pos: [2, 2, 16], state: "minecraft:tuff_bricks"},
        {pos: [2, 2, 17], state: "minecraft:tuff_bricks"},
        {pos: [2, 2, 18], state: "minecraft:tuff_bricks"},
        {pos: [3, 2, 0], state: "minecraft:tuff_bricks"},
        {pos: [3, 2, 1], state: "minecraft:tuff_bricks"},
        {pos: [3, 2, 17], state: "minecraft:tuff_bricks"},
        {pos: [3, 2, 18], state: "minecraft:tuff_bricks"},
        {pos: [4, 2, 0], state: "minecraft:tuff_bricks"},
        {pos: [4, 2, 1], state: "minecraft:waxed_copper_bulb{powered:false,lit:true}"},
        {pos: [4, 2, 17], state: "minecraft:waxed_copper_bulb{powered:false,lit:true}"},
        {pos: [4, 2, 18], state: "minecraft:tuff_bricks"},
        {pos: [5, 2, 0], state: "minecraft:tuff_bricks"},
        {pos: [5, 2, 1], state: "minecraft:tuff_bricks"},
        {pos: [5, 2, 17], state: "minecraft:tuff_bricks"},
        {pos: [5, 2, 18], state: "minecraft:tuff_bricks"},
        {pos: [6, 2, 0], state: "minecraft:tuff_bricks"},
        {pos: [6, 2, 1], state: "minecraft:tuff_bricks"},
        {pos: [6, 2, 2], state: "minecraft:tuff_bricks"},
        {pos: [6, 2, 6], state: "minecraft:tuff_bricks"},
        {pos: [6, 2, 7], state: "minecraft:tuff_bricks"},
        {pos: [6, 2, 11], state: "minecraft:tuff_bricks"},
        {pos: [6, 2, 12], state: "minecraft:tuff_bricks"},
        {pos: [6, 2, 16], state: "minecraft:tuff_bricks"},
        {pos: [6, 2, 17], state: "minecraft:tuff_bricks"},
        {pos: [6, 2, 18], state: "minecraft:tuff_bricks"},
        {pos: [7, 2, 0], state: "minecraft:tuff_bricks"},
        {pos: [7, 2, 1], state: "minecraft:tuff_bricks"},
        {pos: [7, 2, 2], state: "minecraft:tuff_bricks"},
        {pos: [7, 2, 6], state: "minecraft:tuff_bricks"},
        {pos: [7, 2, 7], state: "minecraft:tuff_bricks"},
        {pos: [7, 2, 8], state: "minecraft:tuff_bricks"},
        {pos: [7, 2, 9], state: "minecraft:waxed_copper_bulb{powered:false,lit:true}"},
        {pos: [7, 2, 10], state: "minecraft:tuff_bricks"},
        {pos: [7, 2, 11], state: "minecraft:tuff_bricks"},
        {pos: [7, 2, 12], state: "minecraft:tuff_bricks"},
        {pos: [7, 2, 16], state: "minecraft:tuff_bricks"},
        {pos: [7, 2, 17], state: "minecraft:tuff_bricks"},
        {pos: [7, 2, 18], state: "minecraft:tuff_bricks"},
        {pos: [8, 2, 0], state: "minecraft:tuff_bricks"},
        {pos: [8, 2, 1], state: "minecraft:tuff_bricks"},
        {pos: [8, 2, 7], state: "minecraft:tuff_bricks"},
        {pos: [8, 2, 8], state: "minecraft:tuff_bricks"},
        {pos: [8, 2, 9], state: "minecraft:waxed_copper_bulb{powered:false,lit:true}"},
        {pos: [8, 2, 10], state: "minecraft:tuff_bricks"},
        {pos: [8, 2, 11], state: "minecraft:tuff_bricks"},
        {pos: [8, 2, 17], state: "minecraft:tuff_bricks"},
        {pos: [8, 2, 18], state: "minecraft:tuff_bricks"},
        {pos: [9, 2, 0], state: "minecraft:tuff_bricks"},
        {pos: [9, 2, 1], state: "minecraft:waxed_copper_bulb{powered:false,lit:true}"},
        {pos: [9, 2, 7], state: "minecraft:tuff_bricks"},
        {pos: [9, 2, 8], state: "minecraft:tuff_bricks"},
        {pos: [9, 2, 9], state: "minecraft:waxed_copper_bulb{powered:false,lit:true}"},
        {pos: [9, 2, 10], state: "minecraft:tuff_bricks"},
        {pos: [9, 2, 11], state: "minecraft:waxed_copper_bulb{powered:false,lit:true}"},
        {pos: [9, 2, 17], state: "minecraft:waxed_copper_bulb{powered:false,lit:true}"},
        {pos: [9, 2, 18], state: "minecraft:tuff_bricks"},
        {pos: [10, 2, 0], state: "minecraft:tuff_bricks"},
        {pos: [10, 2, 1], state: "minecraft:tuff_bricks"},
        {pos: [10, 2, 7], state: "minecraft:tuff_bricks"},
        {pos: [10, 2, 8], state: "minecraft:tuff_bricks"},
        {pos: [10, 2, 9], state: "minecraft:waxed_copper_bulb{powered:false,lit:true}"},
        {pos: [10, 2, 10], state: "minecraft:tuff_bricks"},
        {pos: [10, 2, 11], state: "minecraft:tuff_bricks"},
        {pos: [10, 2, 17], state: "minecraft:tuff_bricks"},
        {pos: [10, 2, 18], state: "minecraft:tuff_bricks"},
        {pos: [11, 2, 0], state: "minecraft:tuff_bricks"},
        {pos: [11, 2, 1], state: "minecraft:tuff_bricks"},
        {pos: [11, 2, 2], state: "minecraft:tuff_bricks"},
        {pos: [11, 2, 6], state: "minecraft:tuff_bricks"},
        {pos: [11, 2, 7], state: "minecraft:tuff_bricks"},
        {pos: [11, 2, 8], state: "minecraft:tuff_bricks"},
        {pos: [11, 2, 9], state: "minecraft:waxed_copper_bulb{powered:false,lit:true}"},
        {pos: [11, 2, 10], state: "minecraft:tuff_bricks"},
        {pos: [11, 2, 11], state: "minecraft:tuff_bricks"},
        {pos: [11, 2, 12], state: "minecraft:tuff_bricks"},
        {pos: [11, 2, 16], state: "minecraft:tuff_bricks"},
        {pos: [11, 2, 17], state: "minecraft:tuff_bricks"},
        {pos: [11, 2, 18], state: "minecraft:tuff_bricks"},
        {pos: [12, 2, 0], state: "minecraft:tuff_bricks"},
        {pos: [12, 2, 1], state: "minecraft:tuff_bricks"},
        {pos: [12, 2, 2], state: "minecraft:tuff_bricks"},
        {pos: [12, 2, 3], state: "minecraft:tuff_bricks"},
        {pos: [12, 2, 4], state: "minecraft:waxed_copper_bulb{powered:false,lit:true}"},
        {pos: [12, 2, 5], state: "minecraft:tuff_bricks"},
        {pos: [12, 2, 6], state: "minecraft:tuff_bricks"},
        {pos: [12, 2, 7], state: "minecraft:tuff_bricks"},
        {pos: [12, 2, 8], state: "minecraft:tuff_bricks"},
        {pos: [12, 2, 9], state: "minecraft:waxed_copper_bulb{powered:false,lit:true}"},
        {pos: [12, 2, 10], state: "minecraft:tuff_bricks"},
        {pos: [12, 2, 11], state: "minecraft:tuff_bricks"},
        {pos: [12, 2, 12], state: "minecraft:tuff_bricks"},
        {pos: [12, 2, 13], state: "minecraft:tuff_bricks"},
        {pos: [12, 2, 14], state: "minecraft:waxed_copper_bulb{powered:false,lit:true}"},
        {pos: [12, 2, 15], state: "minecraft:tuff_bricks"},
        {pos: [12, 2, 16], state: "minecraft:tuff_bricks"},
        {pos: [12, 2, 17], state: "minecraft:tuff_bricks"},
        {pos: [12, 2, 18], state: "minecraft:tuff_bricks"},
        {pos: [13, 2, 0], state: "minecraft:tuff_bricks"},
        {pos: [13, 2, 1], state: "minecraft:tuff_bricks"},
        {pos: [13, 2, 2], state: "minecraft:tuff_bricks"},
        {pos: [13, 2, 3], state: "minecraft:tuff_bricks"},
        {pos: [13, 2, 4], state: "minecraft:tuff_bricks"},
        {pos: [13, 2, 5], state: "minecraft:tuff_bricks"},
        {pos: [13, 2, 6], state: "minecraft:tuff_bricks"},
        {pos: [13, 2, 7], state: "minecraft:tuff_bricks"},
        {pos: [13, 2, 8], state: "minecraft:tuff_bricks"},
        {pos: [13, 2, 9], state: "minecraft:tuff_bricks"},
        {pos: [13, 2, 10], state: "minecraft:tuff_bricks"},
        {pos: [13, 2, 11], state: "minecraft:tuff_bricks"},
        {pos: [13, 2, 12], state: "minecraft:tuff_bricks"},
        {pos: [13, 2, 13], state: "minecraft:tuff_bricks"},
        {pos: [13, 2, 14], state: "minecraft:tuff_bricks"},
        {pos: [13, 2, 15], state: "minecraft:tuff_bricks"},
        {pos: [13, 2, 16], state: "minecraft:tuff_bricks"},
        {pos: [13, 2, 17], state: "minecraft:tuff_bricks"},
        {pos: [13, 2, 18], state: "minecraft:tuff_bricks"},
        {pos: [0, 3, 0], state: "minecraft:tuff_bricks"},
        {pos: [0, 3, 1], state: "minecraft:tuff_bricks"},
        {pos: [0, 3, 2], state: "minecraft:tuff_bricks"},
        {pos: [0, 3, 3], state: "minecraft:tuff_bricks"},
        {pos: [0, 3, 4], state: "minecraft:tuff_bricks"},
        {pos: [0, 3, 5], state: "minecraft:tuff_bricks"},
        {pos: [0, 3, 6], state: "minecraft:tuff_bricks"},
        {pos: [0, 3, 7], state: "minecraft:tuff_bricks"},
        {pos: [0, 3, 8], state: "minecraft:tuff_bricks"},
        {pos: [0, 3, 9], state: "minecraft:tuff_bricks"},
        {pos: [0, 3, 10], state: "minecraft:tuff_bricks"},
        {pos: [0, 3, 11], state: "minecraft:tuff_bricks"},
        {pos: [0, 3, 12], state: "minecraft:tuff_bricks"},
        {pos: [0, 3, 13], state: "minecraft:tuff_bricks"},
        {pos: [0, 3, 14], state: "minecraft:tuff_bricks"},
        {pos: [0, 3, 15], state: "minecraft:tuff_bricks"},
        {pos: [0, 3, 16], state: "minecraft:tuff_bricks"},
        {pos: [0, 3, 17], state: "minecraft:tuff_bricks"},
        {pos: [0, 3, 18], state: "minecraft:tuff_bricks"},
        {pos: [1, 3, 0], state: "minecraft:tuff_bricks"},
        {pos: [1, 3, 1], state: "minecraft:chiseled_tuff_bricks"},
        {pos: [1, 3, 2], state: "minecraft:chiseled_tuff_bricks"},
        {pos: [1, 3, 3], state: "minecraft:chiseled_tuff_bricks"},
        {pos: [1, 3, 4], state: "minecraft:chiseled_tuff_bricks"},
        {pos: [1, 3, 5], state: "minecraft:chiseled_tuff_bricks"},
        {pos: [1, 3, 6], state: "minecraft:chiseled_tuff_bricks"},
        {pos: [1, 3, 7], state: "minecraft:chiseled_tuff_bricks"},
        {pos: [1, 3, 8], state: "minecraft:chiseled_tuff_bricks"},
        {pos: [1, 3, 9], state: "minecraft:chiseled_tuff_bricks"},
        {pos: [1, 3, 10], state: "minecraft:chiseled_tuff_bricks"},
        {pos: [1, 3, 11], state: "minecraft:chiseled_tuff_bricks"},
        {pos: [1, 3, 12], state: "minecraft:chiseled_tuff_bricks"},
        {pos: [1, 3, 13], state: "minecraft:chiseled_tuff_bricks"},
        {pos: [1, 3, 14], state: "minecraft:chiseled_tuff_bricks"},
        {pos: [1, 3, 15], state: "minecraft:chiseled_tuff_bricks"},
        {pos: [1, 3, 16], state: "minecraft:chiseled_tuff_bricks"},
        {pos: [1, 3, 17], state: "minecraft:chiseled_tuff_bricks"},
        {pos: [1, 3, 18], state: "minecraft:tuff_bricks"},
        {pos: [2, 3, 0], state: "minecraft:tuff_bricks"},
        {pos: [2, 3, 1], state: "minecraft:chiseled_tuff_bricks"},
        {pos: [2, 3, 2], state: "minecraft:chiseled_tuff_bricks"},
        {pos: [2, 3, 6], state: "minecraft:chiseled_tuff_bricks"},
        {pos: [2, 3, 7], state: "minecraft:chiseled_tuff_bricks"},
        {pos: [2, 3, 11], state: "minecraft:chiseled_tuff_bricks"},
        {pos: [2, 3, 12], state: "minecraft:chiseled_tuff_bricks"},
        {pos: [2, 3, 16], state: "minecraft:chiseled_tuff_bricks"},
        {pos: [2, 3, 17], state: "minecraft:chiseled_tuff_bricks"},
        {pos: [2, 3, 18], state: "minecraft:tuff_bricks"},
        {pos: [3, 3, 0], state: "minecraft:tuff_bricks"},
        {pos: [3, 3, 1], state: "minecraft:chiseled_tuff_bricks"},
        {pos: [3, 3, 17], state: "minecraft:chiseled_tuff_bricks"},
        {pos: [3, 3, 18], state: "minecraft:tuff_bricks"},
        {pos: [4, 3, 0], state: "minecraft:tuff_bricks"},
        {pos: [4, 3, 1], state: "minecraft:chiseled_tuff_bricks"},
        {pos: [4, 3, 17], state: "minecraft:chiseled_tuff_bricks"},
        {pos: [4, 3, 18], state: "minecraft:tuff_bricks"},
        {pos: [5, 3, 0], state: "minecraft:tuff_bricks"},
        {pos: [5, 3, 1], state: "minecraft:chiseled_tuff_bricks"},
        {pos: [5, 3, 17], state: "minecraft:chiseled_tuff_bricks"},
        {pos: [5, 3, 18], state: "minecraft:tuff_bricks"},
        {pos: [6, 3, 0], state: "minecraft:tuff_bricks"},
        {pos: [6, 3, 1], state: "minecraft:chiseled_tuff_bricks"},
        {pos: [6, 3, 2], state: "minecraft:chiseled_tuff_bricks"},
        {pos: [6, 3, 6], state: "minecraft:chiseled_tuff_bricks"},
        {pos: [6, 3, 7], state: "minecraft:chiseled_tuff_bricks"},
        {pos: [6, 3, 11], state: "minecraft:chiseled_tuff_bricks"},
        {pos: [6, 3, 12], state: "minecraft:chiseled_tuff_bricks"},
        {pos: [6, 3, 16], state: "minecraft:chiseled_tuff_bricks"},
        {pos: [6, 3, 17], state: "minecraft:chiseled_tuff_bricks"},
        {pos: [6, 3, 18], state: "minecraft:tuff_bricks"},
        {pos: [7, 3, 0], state: "minecraft:tuff_bricks"},
        {pos: [7, 3, 1], state: "minecraft:chiseled_tuff_bricks"},
        {pos: [7, 3, 2], state: "minecraft:chiseled_tuff_bricks"},
        {pos: [7, 3, 6], state: "minecraft:chiseled_tuff_bricks"},
        {pos: [7, 3, 7], state: "minecraft:chiseled_tuff_bricks"},
        {pos: [7, 3, 8], state: "minecraft:chiseled_tuff_bricks"},
        {pos: [7, 3, 9], state: "minecraft:chiseled_tuff_bricks"},
        {pos: [7, 3, 10], state: "minecraft:chiseled_tuff_bricks"},
        {pos: [7, 3, 11], state: "minecraft:chiseled_tuff_bricks"},
        {pos: [7, 3, 12], state: "minecraft:chiseled_tuff_bricks"},
        {pos: [7, 3, 16], state: "minecraft:chiseled_tuff_bricks"},
        {pos: [7, 3, 17], state: "minecraft:chiseled_tuff_bricks"},
        {pos: [7, 3, 18], state: "minecraft:tuff_bricks"},
        {pos: [8, 3, 0], state: "minecraft:tuff_bricks"},
        {pos: [8, 3, 1], state: "minecraft:chiseled_tuff_bricks"},
        {pos: [8, 3, 7], state: "minecraft:chiseled_tuff_bricks"},
        {pos: [8, 3, 8], state: "minecraft:chiseled_tuff_bricks"},
        {pos: [8, 3, 9], state: "minecraft:chiseled_tuff_bricks"},
        {pos: [8, 3, 10], state: "minecraft:chiseled_tuff_bricks"},
        {pos: [8, 3, 11], state: "minecraft:chiseled_tuff_bricks"},
        {pos: [8, 3, 17], state: "minecraft:chiseled_tuff_bricks"},
        {pos: [8, 3, 18], state: "minecraft:tuff_bricks"},
        {pos: [9, 3, 0], state: "minecraft:tuff_bricks"},
        {pos: [9, 3, 1], state: "minecraft:chiseled_tuff_bricks"},
        {pos: [9, 3, 7], state: "minecraft:chiseled_tuff_bricks"},
        {pos: [9, 3, 8], state: "minecraft:chiseled_tuff_bricks"},
        {pos: [9, 3, 9], state: "minecraft:chiseled_tuff_bricks"},
        {pos: [9, 3, 10], state: "minecraft:chiseled_tuff_bricks"},
        {pos: [9, 3, 11], state: "minecraft:chiseled_tuff_bricks"},
        {pos: [9, 3, 17], state: "minecraft:chiseled_tuff_bricks"},
        {pos: [9, 3, 18], state: "minecraft:tuff_bricks"},
        {pos: [10, 3, 0], state: "minecraft:tuff_bricks"},
        {pos: [10, 3, 1], state: "minecraft:chiseled_tuff_bricks"},
        {pos: [10, 3, 7], state: "minecraft:chiseled_tuff_bricks"},
        {pos: [10, 3, 8], state: "minecraft:chiseled_tuff_bricks"},
        {pos: [10, 3, 9], state: "minecraft:chiseled_tuff_bricks"},
        {pos: [10, 3, 10], state: "minecraft:chiseled_tuff_bricks"},
        {pos: [10, 3, 11], state: "minecraft:chiseled_tuff_bricks"},
        {pos: [10, 3, 17], state: "minecraft:chiseled_tuff_bricks"},
        {pos: [10, 3, 18], state: "minecraft:tuff_bricks"},
        {pos: [11, 3, 0], state: "minecraft:tuff_bricks"},
        {pos: [11, 3, 1], state: "minecraft:chiseled_tuff_bricks"},
        {pos: [11, 3, 2], state: "minecraft:chiseled_tuff_bricks"},
        {pos: [11, 3, 6], state: "minecraft:chiseled_tuff_bricks"},
        {pos: [11, 3, 7], state: "minecraft:chiseled_tuff_bricks"},
        {pos: [11, 3, 8], state: "minecraft:chiseled_tuff_bricks"},
        {pos: [11, 3, 9], state: "minecraft:chiseled_tuff_bricks"},
        {pos: [11, 3, 10], state: "minecraft:chiseled_tuff_bricks"},
        {pos: [11, 3, 11], state: "minecraft:chiseled_tuff_bricks"},
        {pos: [11, 3, 12], state: "minecraft:chiseled_tuff_bricks"},
        {pos: [11, 3, 16], state: "minecraft:chiseled_tuff_bricks"},
        {pos: [11, 3, 17], state: "minecraft:chiseled_tuff_bricks"},
        {pos: [11, 3, 18], state: "minecraft:tuff_bricks"},
        {pos: [12, 3, 0], state: "minecraft:tuff_bricks"},
        {pos: [12, 3, 1], state: "minecraft:chiseled_tuff_bricks"},
        {pos: [12, 3, 2], state: "minecraft:chiseled_tuff_bricks"},
        {pos: [12, 3, 3], state: "minecraft:chiseled_tuff_bricks"},
        {pos: [12, 3, 4], state: "minecraft:chiseled_tuff_bricks"},
        {pos: [12, 3, 5], state: "minecraft:chiseled_tuff_bricks"},
        {pos: [12, 3, 6], state: "minecraft:chiseled_tuff_bricks"},
        {pos: [12, 3, 7], state: "minecraft:chiseled_tuff_bricks"},
        {pos: [12, 3, 8], state: "minecraft:chiseled_tuff_bricks"},
        {pos: [12, 3, 9], state: "minecraft:chiseled_tuff_bricks"},
        {pos: [12, 3, 10], state: "minecraft:chiseled_tuff_bricks"},
        {pos: [12, 3, 11], state: "minecraft:chiseled_tuff_bricks"},
        {pos: [12, 3, 12], state: "minecraft:chiseled_tuff_bricks"},
        {pos: [12, 3, 13], state: "minecraft:chiseled_tuff_bricks"},
        {pos: [12, 3, 14], state: "minecraft:chiseled_tuff_bricks"},
        {pos: [12, 3, 15], state: "minecraft:chiseled_tuff_bricks"},
        {pos: [12, 3, 16], state: "minecraft:chiseled_tuff_bricks"},
        {pos: [12, 3, 17], state: "minecraft:chiseled_tuff_bricks"},
        {pos: [12, 3, 18], state: "minecraft:tuff_bricks"},
        {pos: [13, 3, 0], state: "minecraft:tuff_bricks"},
        {pos: [13, 3, 1], state: "minecraft:tuff_bricks"},
        {pos: [13, 3, 2], state: "minecraft:tuff_bricks"},
        {pos: [13, 3, 3], state: "minecraft:tuff_bricks"},
        {pos: [13, 3, 4], state: "minecraft:tuff_bricks"},
        {pos: [13, 3, 5], state: "minecraft:tuff_bricks"},
        {pos: [13, 3, 6], state: "minecraft:tuff_bricks"},
        {pos: [13, 3, 7], state: "minecraft:tuff_bricks"},
        {pos: [13, 3, 8], state: "minecraft:tuff_bricks"},
        {pos: [13, 3, 9], state: "minecraft:tuff_bricks"},
        {pos: [13, 3, 10], state: "minecraft:tuff_bricks"},
        {pos: [13, 3, 11], state: "minecraft:tuff_bricks"},
        {pos: [13, 3, 12], state: "minecraft:tuff_bricks"},
        {pos: [13, 3, 13], state: "minecraft:tuff_bricks"},
        {pos: [13, 3, 14], state: "minecraft:tuff_bricks"},
        {pos: [13, 3, 15], state: "minecraft:tuff_bricks"},
        {pos: [13, 3, 16], state: "minecraft:tuff_bricks"},
        {pos: [13, 3, 17], state: "minecraft:tuff_bricks"},
        {pos: [13, 3, 18], state: "minecraft:tuff_bricks"},
        {pos: [0, 4, 0], state: "minecraft:tuff_bricks"},
        {pos: [0, 4, 1], state: "minecraft:tuff_bricks"},
        {pos: [0, 4, 2], state: "minecraft:tuff_bricks"},
        {pos: [0, 4, 3], state: "minecraft:tuff_bricks"},
        {pos: [0, 4, 4], state: "minecraft:tuff_bricks"},
        {pos: [0, 4, 5], state: "minecraft:tuff_bricks"},
        {pos: [0, 4, 6], state: "minecraft:tuff_bricks"},
        {pos: [0, 4, 7], state: "minecraft:tuff_bricks"},
        {pos: [0, 4, 8], state: "minecraft:tuff_bricks"},
        {pos: [0, 4, 9], state: "minecraft:tuff_bricks"},
        {pos: [0, 4, 10], state: "minecraft:tuff_bricks"},
        {pos: [0, 4, 11], state: "minecraft:tuff_bricks"},
        {pos: [0, 4, 12], state: "minecraft:tuff_bricks"},
        {pos: [0, 4, 13], state: "minecraft:tuff_bricks"},
        {pos: [0, 4, 14], state: "minecraft:tuff_bricks"},
        {pos: [0, 4, 15], state: "minecraft:tuff_bricks"},
        {pos: [0, 4, 16], state: "minecraft:tuff_bricks"},
        {pos: [0, 4, 17], state: "minecraft:tuff_bricks"},
        {pos: [0, 4, 18], state: "minecraft:tuff_bricks"},
        {pos: [1, 4, 0], state: "minecraft:tuff_bricks"},
        {pos: [1, 4, 1], state: "minecraft:tuff_bricks"},
        {pos: [1, 4, 2], state: "minecraft:tuff_bricks"},
        {pos: [1, 4, 3], state: "minecraft:tuff_bricks"},
        {pos: [1, 4, 4], state: "minecraft:tuff_bricks"},
        {pos: [1, 4, 5], state: "minecraft:tuff_bricks"},
        {pos: [1, 4, 6], state: "minecraft:tuff_bricks"},
        {pos: [1, 4, 7], state: "minecraft:tuff_bricks"},
        {pos: [1, 4, 8], state: "minecraft:tuff_bricks"},
        {pos: [1, 4, 9], state: "minecraft:tuff_bricks"},
        {pos: [1, 4, 10], state: "minecraft:tuff_bricks"},
        {pos: [1, 4, 11], state: "minecraft:tuff_bricks"},
        {pos: [1, 4, 12], state: "minecraft:tuff_bricks"},
        {pos: [1, 4, 13], state: "minecraft:tuff_bricks"},
        {pos: [1, 4, 14], state: "minecraft:tuff_bricks"},
        {pos: [1, 4, 15], state: "minecraft:tuff_bricks"},
        {pos: [1, 4, 16], state: "minecraft:tuff_bricks"},
        {pos: [1, 4, 17], state: "minecraft:tuff_bricks"},
        {pos: [1, 4, 18], state: "minecraft:tuff_bricks"},
        {pos: [2, 4, 0], state: "minecraft:tuff_bricks"},
        {pos: [2, 4, 1], state: "minecraft:tuff_bricks"},
        {pos: [2, 4, 2], state: "minecraft:tuff_bricks"},
        {pos: [2, 4, 6], state: "minecraft:tuff_bricks"},
        {pos: [2, 4, 7], state: "minecraft:tuff_bricks"},
        {pos: [2, 4, 11], state: "minecraft:tuff_bricks"},
        {pos: [2, 4, 12], state: "minecraft:tuff_bricks"},
        {pos: [2, 4, 16], state: "minecraft:tuff_bricks"},
        {pos: [2, 4, 17], state: "minecraft:tuff_bricks"},
        {pos: [2, 4, 18], state: "minecraft:tuff_bricks"},
        {pos: [3, 4, 0], state: "minecraft:tuff_bricks"},
        {pos: [3, 4, 1], state: "minecraft:tuff_bricks"},
        {pos: [3, 4, 17], state: "minecraft:tuff_bricks"},
        {pos: [3, 4, 18], state: "minecraft:tuff_bricks"},
        {pos: [4, 4, 0], state: "minecraft:tuff_bricks"},
        {pos: [4, 4, 1], state: "minecraft:tuff_bricks"},
        {pos: [4, 4, 17], state: "minecraft:tuff_bricks"},
        {pos: [4, 4, 18], state: "minecraft:tuff_bricks"},
        {pos: [5, 4, 0], state: "minecraft:tuff_bricks"},
        {pos: [5, 4, 1], state: "minecraft:tuff_bricks"},
        {pos: [5, 4, 17], state: "minecraft:tuff_bricks"},
        {pos: [5, 4, 18], state: "minecraft:tuff_bricks"},
        {pos: [6, 4, 0], state: "minecraft:tuff_bricks"},
        {pos: [6, 4, 1], state: "minecraft:tuff_bricks"},
        {pos: [6, 4, 2], state: "minecraft:tuff_bricks"},
        {pos: [6, 4, 6], state: "minecraft:tuff_bricks"},
        {pos: [6, 4, 7], state: "minecraft:tuff_bricks"},
        {pos: [6, 4, 11], state: "minecraft:tuff_bricks"},
        {pos: [6, 4, 12], state: "minecraft:tuff_bricks"},
        {pos: [6, 4, 16], state: "minecraft:tuff_bricks"},
        {pos: [6, 4, 17], state: "minecraft:tuff_bricks"},
        {pos: [6, 4, 18], state: "minecraft:tuff_bricks"},
        {pos: [7, 4, 0], state: "minecraft:tuff_bricks"},
        {pos: [7, 4, 1], state: "minecraft:tuff_bricks"},
        {pos: [7, 4, 2], state: "minecraft:tuff_bricks"},
        {pos: [7, 4, 6], state: "minecraft:tuff_bricks"},
        {pos: [7, 4, 7], state: "minecraft:tuff_bricks"},
        {pos: [7, 4, 8], state: "minecraft:tuff_bricks"},
        {pos: [7, 4, 9], state: "minecraft:tuff_bricks"},
        {pos: [7, 4, 10], state: "minecraft:tuff_bricks"},
        {pos: [7, 4, 11], state: "minecraft:tuff_bricks"},
        {pos: [7, 4, 12], state: "minecraft:tuff_bricks"},
        {pos: [7, 4, 16], state: "minecraft:tuff_bricks"},
        {pos: [7, 4, 17], state: "minecraft:tuff_bricks"},
        {pos: [7, 4, 18], state: "minecraft:tuff_bricks"},
        {pos: [8, 4, 0], state: "minecraft:tuff_bricks"},
        {pos: [8, 4, 1], state: "minecraft:tuff_bricks"},
        {pos: [8, 4, 7], state: "minecraft:tuff_bricks"},
        {pos: [8, 4, 8], state: "minecraft:tuff_bricks"},
        {pos: [8, 4, 9], state: "minecraft:tuff_bricks"},
        {pos: [8, 4, 10], state: "minecraft:tuff_bricks"},
        {pos: [8, 4, 11], state: "minecraft:tuff_bricks"},
        {pos: [8, 4, 17], state: "minecraft:tuff_bricks"},
        {pos: [8, 4, 18], state: "minecraft:tuff_bricks"},
        {pos: [9, 4, 0], state: "minecraft:tuff_bricks"},
        {pos: [9, 4, 1], state: "minecraft:tuff_bricks"},
        {pos: [9, 4, 7], state: "minecraft:tuff_bricks"},
        {pos: [9, 4, 8], state: "minecraft:tuff_bricks"},
        {pos: [9, 4, 9], state: "minecraft:tuff_bricks"},
        {pos: [9, 4, 10], state: "minecraft:tuff_bricks"},
        {pos: [9, 4, 11], state: "minecraft:tuff_bricks"},
        {pos: [9, 4, 17], state: "minecraft:tuff_bricks"},
        {pos: [9, 4, 18], state: "minecraft:tuff_bricks"},
        {pos: [10, 4, 0], state: "minecraft:tuff_bricks"},
        {pos: [10, 4, 1], state: "minecraft:tuff_bricks"},
        {pos: [10, 4, 7], state: "minecraft:tuff_bricks"},
        {pos: [10, 4, 8], state: "minecraft:tuff_bricks"},
        {pos: [10, 4, 9], state: "minecraft:tuff_bricks"},
        {pos: [10, 4, 10], state: "minecraft:tuff_bricks"},
        {pos: [10, 4, 11], state: "minecraft:tuff_bricks"},
        {pos: [10, 4, 17], state: "minecraft:tuff_bricks"},
        {pos: [10, 4, 18], state: "minecraft:tuff_bricks"},
        {pos: [11, 4, 0], state: "minecraft:tuff_bricks"},
        {pos: [11, 4, 1], state: "minecraft:tuff_bricks"},
        {pos: [11, 4, 2], state: "minecraft:tuff_bricks"},
        {pos: [11, 4, 6], state: "minecraft:tuff_bricks"},
        {pos: [11, 4, 7], state: "minecraft:tuff_bricks"},
        {pos: [11, 4, 8], state: "minecraft:tuff_bricks"},
        {pos: [11, 4, 9], state: "minecraft:tuff_bricks"},
        {pos: [11, 4, 10], state: "minecraft:tuff_bricks"},
        {pos: [11, 4, 11], state: "minecraft:tuff_bricks"},
        {pos: [11, 4, 12], state: "minecraft:tuff_bricks"},
        {pos: [11, 4, 16], state: "minecraft:tuff_bricks"},
        {pos: [11, 4, 17], state: "minecraft:tuff_bricks"},
        {pos: [11, 4, 18], state: "minecraft:tuff_bricks"},
        {pos: [12, 4, 0], state: "minecraft:tuff_bricks"},
        {pos: [12, 4, 1], state: "minecraft:tuff_bricks"},
        {pos: [12, 4, 2], state: "minecraft:tuff_bricks"},
        {pos: [12, 4, 3], state: "minecraft:tuff_bricks"},
        {pos: [12, 4, 4], state: "minecraft:tuff_bricks"},
        {pos: [12, 4, 5], state: "minecraft:tuff_bricks"},
        {pos: [12, 4, 6], state: "minecraft:tuff_bricks"},
        {pos: [12, 4, 7], state: "minecraft:tuff_bricks"},
        {pos: [12, 4, 8], state: "minecraft:tuff_bricks"},
        {pos: [12, 4, 9], state: "minecraft:tuff_bricks"},
        {pos: [12, 4, 10], state: "minecraft:tuff_bricks"},
        {pos: [12, 4, 11], state: "minecraft:tuff_bricks"},
        {pos: [12, 4, 12], state: "minecraft:tuff_bricks"},
        {pos: [12, 4, 13], state: "minecraft:tuff_bricks"},
        {pos: [12, 4, 14], state: "minecraft:tuff_bricks"},
        {pos: [12, 4, 15], state: "minecraft:tuff_bricks"},
        {pos: [12, 4, 16], state: "minecraft:tuff_bricks"},
        {pos: [12, 4, 17], state: "minecraft:tuff_bricks"},
        {pos: [12, 4, 18], state: "minecraft:tuff_bricks"},
        {pos: [13, 4, 0], state: "minecraft:tuff_bricks"},
        {pos: [13, 4, 1], state: "minecraft:tuff_bricks"},
        {pos: [13, 4, 2], state: "minecraft:tuff_bricks"},
        {pos: [13, 4, 3], state: "minecraft:tuff_bricks"},
        {pos: [13, 4, 4], state: "minecraft:tuff_bricks"},
        {pos: [13, 4, 5], state: "minecraft:tuff_bricks"},
        {pos: [13, 4, 6], state: "minecraft:tuff_bricks"},
        {pos: [13, 4, 7], state: "minecraft:tuff_bricks"},
        {pos: [13, 4, 8], state: "minecraft:tuff_bricks"},
        {pos: [13, 4, 9], state: "minecraft:tuff_bricks"},
        {pos: [13, 4, 10], state: "minecraft:tuff_bricks"},
        {pos: [13, 4, 11], state: "minecraft:tuff_bricks"},
        {pos: [13, 4, 12], state: "minecraft:tuff_bricks"},
        {pos: [13, 4, 13], state: "minecraft:tuff_bricks"},
        {pos: [13, 4, 14], state: "minecraft:tuff_bricks"},
        {pos: [13, 4, 15], state: "minecraft:tuff_bricks"},
        {pos: [13, 4, 16], state: "minecraft:tuff_bricks"},
        {pos: [13, 4, 17], state: "minecraft:tuff_bricks"},
        {pos: [13, 4, 18], state: "minecraft:tuff_bricks"},
        {pos: [0, 5, 0], state: "minecraft:tuff_bricks"},
        {pos: [0, 5, 1], state: "minecraft:tuff_bricks"},
        {pos: [0, 5, 2], state: "minecraft:tuff_bricks"},
        {pos: [0, 5, 3], state: "minecraft:tuff_bricks"},
        {pos: [0, 5, 4], state: "minecraft:tuff_bricks"},
        {pos: [0, 5, 5], state: "minecraft:tuff_bricks"},
        {pos: [0, 5, 6], state: "minecraft:tuff_bricks"},
        {pos: [0, 5, 7], state: "minecraft:tuff_bricks"},
        {pos: [0, 5, 8], state: "minecraft:tuff_bricks"},
        {pos: [0, 5, 9], state: "minecraft:tuff_bricks"},
        {pos: [0, 5, 10], state: "minecraft:tuff_bricks"},
        {pos: [0, 5, 11], state: "minecraft:tuff_bricks"},
        {pos: [0, 5, 12], state: "minecraft:tuff_bricks"},
        {pos: [0, 5, 13], state: "minecraft:tuff_bricks"},
        {pos: [0, 5, 14], state: "minecraft:tuff_bricks"},
        {pos: [0, 5, 15], state: "minecraft:tuff_bricks"},
        {pos: [0, 5, 16], state: "minecraft:tuff_bricks"},
        {pos: [0, 5, 17], state: "minecraft:tuff_bricks"},
        {pos: [0, 5, 18], state: "minecraft:tuff_bricks"},
        {pos: [1, 5, 0], state: "minecraft:tuff_bricks"},
        {pos: [1, 5, 1], state: "minecraft:tuff_bricks"},
        {pos: [1, 5, 2], state: "minecraft:tuff_bricks"},
        {pos: [1, 5, 3], state: "minecraft:tuff_bricks"},
        {pos: [1, 5, 4], state: "minecraft:tuff_bricks"},
        {pos: [1, 5, 5], state: "minecraft:tuff_bricks"},
        {pos: [1, 5, 6], state: "minecraft:tuff_bricks"},
        {pos: [1, 5, 7], state: "minecraft:tuff_bricks"},
        {pos: [1, 5, 8], state: "minecraft:tuff_bricks"},
        {pos: [1, 5, 9], state: "minecraft:tuff_bricks"},
        {pos: [1, 5, 10], state: "minecraft:tuff_bricks"},
        {pos: [1, 5, 11], state: "minecraft:tuff_bricks"},
        {pos: [1, 5, 12], state: "minecraft:tuff_bricks"},
        {pos: [1, 5, 13], state: "minecraft:tuff_bricks"},
        {pos: [1, 5, 14], state: "minecraft:tuff_bricks"},
        {pos: [1, 5, 15], state: "minecraft:tuff_bricks"},
        {pos: [1, 5, 16], state: "minecraft:tuff_bricks"},
        {pos: [1, 5, 17], state: "minecraft:tuff_bricks"},
        {pos: [1, 5, 18], state: "minecraft:tuff_bricks"},
        {pos: [2, 5, 0], state: "minecraft:tuff_bricks"},
        {pos: [2, 5, 1], state: "minecraft:tuff_bricks"},
        {pos: [2, 5, 2], state: "minecraft:tuff_bricks"},
        {pos: [2, 5, 6], state: "minecraft:tuff_bricks"},
        {pos: [2, 5, 7], state: "minecraft:tuff_bricks"},
        {pos: [2, 5, 11], state: "minecraft:tuff_bricks"},
        {pos: [2, 5, 12], state: "minecraft:tuff_bricks"},
        {pos: [2, 5, 16], state: "minecraft:tuff_bricks"},
        {pos: [2, 5, 17], state: "minecraft:tuff_bricks"},
        {pos: [2, 5, 18], state: "minecraft:tuff_bricks"},
        {pos: [3, 5, 0], state: "minecraft:tuff_bricks"},
        {pos: [3, 5, 1], state: "minecraft:tuff_bricks"},
        {pos: [3, 5, 17], state: "minecraft:tuff_bricks"},
        {pos: [3, 5, 18], state: "minecraft:tuff_bricks"},
        {pos: [4, 5, 0], state: "minecraft:tuff_bricks"},
        {pos: [4, 5, 1], state: "minecraft:tuff_bricks"},
        {pos: [4, 5, 17], state: "minecraft:tuff_bricks"},
        {pos: [4, 5, 18], state: "minecraft:tuff_bricks"},
        {pos: [5, 5, 0], state: "minecraft:tuff_bricks"},
        {pos: [5, 5, 1], state: "minecraft:tuff_bricks"},
        {pos: [5, 5, 17], state: "minecraft:tuff_bricks"},
        {pos: [5, 5, 18], state: "minecraft:tuff_bricks"},
        {pos: [6, 5, 0], state: "minecraft:tuff_bricks"},
        {pos: [6, 5, 1], state: "minecraft:tuff_bricks"},
        {pos: [6, 5, 2], state: "minecraft:tuff_bricks"},
        {pos: [6, 5, 6], state: "minecraft:tuff_bricks"},
        {pos: [6, 5, 7], state: "minecraft:tuff_bricks"},
        {pos: [6, 5, 11], state: "minecraft:tuff_bricks"},
        {pos: [6, 5, 12], state: "minecraft:tuff_bricks"},
        {pos: [6, 5, 16], state: "minecraft:tuff_bricks"},
        {pos: [6, 5, 17], state: "minecraft:tuff_bricks"},
        {pos: [6, 5, 18], state: "minecraft:tuff_bricks"},
        {pos: [7, 5, 0], state: "minecraft:tuff_bricks"},
        {pos: [7, 5, 1], state: "minecraft:tuff_bricks"},
        {pos: [7, 5, 2], state: "minecraft:tuff_bricks"},
        {pos: [7, 5, 6], state: "minecraft:tuff_bricks"},
        {pos: [7, 5, 7], state: "minecraft:tuff_bricks"},
        {pos: [7, 5, 8], state: "minecraft:tuff_bricks"},
        {pos: [7, 5, 9], state: "minecraft:tuff_bricks"},
        {pos: [7, 5, 10], state: "minecraft:tuff_bricks"},
        {pos: [7, 5, 11], state: "minecraft:tuff_bricks"},
        {pos: [7, 5, 12], state: "minecraft:tuff_bricks"},
        {pos: [7, 5, 16], state: "minecraft:tuff_bricks"},
        {pos: [7, 5, 17], state: "minecraft:tuff_bricks"},
        {pos: [7, 5, 18], state: "minecraft:tuff_bricks"},
        {pos: [8, 5, 0], state: "minecraft:tuff_bricks"},
        {pos: [8, 5, 1], state: "minecraft:tuff_bricks"},
        {pos: [8, 5, 7], state: "minecraft:tuff_bricks"},
        {pos: [8, 5, 8], state: "minecraft:tuff_bricks"},
        {pos: [8, 5, 9], state: "minecraft:tuff_bricks"},
        {pos: [8, 5, 10], state: "minecraft:tuff_bricks"},
        {pos: [8, 5, 11], state: "minecraft:tuff_bricks"},
        {pos: [8, 5, 17], state: "minecraft:tuff_bricks"},
        {pos: [8, 5, 18], state: "minecraft:tuff_bricks"},
        {pos: [9, 5, 0], state: "minecraft:tuff_bricks"},
        {pos: [9, 5, 1], state: "minecraft:tuff_bricks"},
        {pos: [9, 5, 7], state: "minecraft:tuff_bricks"},
        {pos: [9, 5, 8], state: "minecraft:tuff_bricks"},
        {pos: [9, 5, 9], state: "minecraft:tuff_bricks"},
        {pos: [9, 5, 10], state: "minecraft:tuff_bricks"},
        {pos: [9, 5, 11], state: "minecraft:tuff_bricks"},
        {pos: [9, 5, 17], state: "minecraft:tuff_bricks"},
        {pos: [9, 5, 18], state: "minecraft:tuff_bricks"},
        {pos: [10, 5, 0], state: "minecraft:tuff_bricks"},
        {pos: [10, 5, 1], state: "minecraft:tuff_bricks"},
        {pos: [10, 5, 7], state: "minecraft:tuff_bricks"},
        {pos: [10, 5, 8], state: "minecraft:tuff_bricks"},
        {pos: [10, 5, 9], state: "minecraft:tuff_bricks"},
        {pos: [10, 5, 10], state: "minecraft:tuff_bricks"},
        {pos: [10, 5, 11], state: "minecraft:tuff_bricks"},
        {pos: [10, 5, 17], state: "minecraft:tuff_bricks"},
        {pos: [10, 5, 18], state: "minecraft:tuff_bricks"},
        {pos: [11, 5, 0], state: "minecraft:tuff_bricks"},
        {pos: [11, 5, 1], state: "minecraft:tuff_bricks"},
        {pos: [11, 5, 2], state: "minecraft:tuff_bricks"},
        {pos: [11, 5, 6], state: "minecraft:tuff_bricks"},
        {pos: [11, 5, 7], state: "minecraft:tuff_bricks"},
        {pos: [11, 5, 8], state: "minecraft:tuff_bricks"},
        {pos: [11, 5, 9], state: "minecraft:tuff_bricks"},
        {pos: [11, 5, 10], state: "minecraft:tuff_bricks"},
        {pos: [11, 5, 11], state: "minecraft:tuff_bricks"},
        {pos: [11, 5, 12], state: "minecraft:tuff_bricks"},
        {pos: [11, 5, 16], state: "minecraft:tuff_bricks"},
        {pos: [11, 5, 17], state: "minecraft:tuff_bricks"},
        {pos: [11, 5, 18], state: "minecraft:tuff_bricks"},
        {pos: [12, 5, 0], state: "minecraft:tuff_bricks"},
        {pos: [12, 5, 1], state: "minecraft:tuff_bricks"},
        {pos: [12, 5, 2], state: "minecraft:tuff_bricks"},
        {pos: [12, 5, 3], state: "minecraft:tuff_bricks"},
        {pos: [12, 5, 4], state: "minecraft:tuff_bricks"},
        {pos: [12, 5, 5], state: "minecraft:tuff_bricks"},
        {pos: [12, 5, 6], state: "minecraft:tuff_bricks"},
        {pos: [12, 5, 7], state: "minecraft:tuff_bricks"},
        {pos: [12, 5, 8], state: "minecraft:tuff_bricks"},
        {pos: [12, 5, 9], state: "minecraft:tuff_bricks"},
        {pos: [12, 5, 10], state: "minecraft:tuff_bricks"},
        {pos: [12, 5, 11], state: "minecraft:tuff_bricks"},
        {pos: [12, 5, 12], state: "minecraft:tuff_bricks"},
        {pos: [12, 5, 13], state: "minecraft:tuff_bricks"},
        {pos: [12, 5, 14], state: "minecraft:tuff_bricks"},
        {pos: [12, 5, 15], state: "minecraft:tuff_bricks"},
        {pos: [12, 5, 16], state: "minecraft:tuff_bricks"},
        {pos: [12, 5, 17], state: "minecraft:tuff_bricks"},
        {pos: [12, 5, 18], state: "minecraft:tuff_bricks"},
        {pos: [13, 5, 0], state: "minecraft:tuff_bricks"},
        {pos: [13, 5, 1], state: "minecraft:tuff_bricks"},
        {pos: [13, 5, 2], state: "minecraft:tuff_bricks"},
        {pos: [13, 5, 3], state: "minecraft:tuff_bricks"},
        {pos: [13, 5, 4], state: "minecraft:tuff_bricks"},
        {pos: [13, 5, 5], state: "minecraft:tuff_bricks"},
        {pos: [13, 5, 6], state: "minecraft:tuff_bricks"},
        {pos: [13, 5, 7], state: "minecraft:tuff_bricks"},
        {pos: [13, 5, 8], state: "minecraft:tuff_bricks"},
        {pos: [13, 5, 9], state: "minecraft:tuff_bricks"},
        {pos: [13, 5, 10], state: "minecraft:tuff_bricks"},
        {pos: [13, 5, 11], state: "minecraft:tuff_bricks"},
        {pos: [13, 5, 12], state: "minecraft:tuff_bricks"},
        {pos: [13, 5, 13], state: "minecraft:tuff_bricks"},
        {pos: [13, 5, 14], state: "minecraft:tuff_bricks"},
        {pos: [13, 5, 15], state: "minecraft:tuff_bricks"},
        {pos: [13, 5, 16], state: "minecraft:tuff_bricks"},
        {pos: [13, 5, 17], state: "minecraft:tuff_bricks"},
        {pos: [13, 5, 18], state: "minecraft:tuff_bricks"},
        {pos: [0, 6, 0], state: "minecraft:tuff_bricks"},
        {pos: [0, 6, 1], state: "minecraft:tuff_bricks"},
        {pos: [0, 6, 2], state: "minecraft:tuff_bricks"},
        {pos: [0, 6, 3], state: "minecraft:tuff_bricks"},
        {pos: [0, 6, 4], state: "minecraft:tuff_bricks"},
        {pos: [0, 6, 5], state: "minecraft:tuff_bricks"},
        {pos: [0, 6, 6], state: "minecraft:tuff_bricks"},
        {pos: [0, 6, 7], state: "minecraft:tuff_bricks"},
        {pos: [0, 6, 8], state: "minecraft:tuff_bricks"},
        {pos: [0, 6, 9], state: "minecraft:tuff_bricks"},
        {pos: [0, 6, 10], state: "minecraft:tuff_bricks"},
        {pos: [0, 6, 11], state: "minecraft:tuff_bricks"},
        {pos: [0, 6, 12], state: "minecraft:tuff_bricks"},
        {pos: [0, 6, 13], state: "minecraft:tuff_bricks"},
        {pos: [0, 6, 14], state: "minecraft:tuff_bricks"},
        {pos: [0, 6, 15], state: "minecraft:tuff_bricks"},
        {pos: [0, 6, 16], state: "minecraft:tuff_bricks"},
        {pos: [0, 6, 17], state: "minecraft:tuff_bricks"},
        {pos: [0, 6, 18], state: "minecraft:tuff_bricks"},
        {pos: [1, 6, 0], state: "minecraft:tuff_bricks"},
        {pos: [1, 6, 1], state: "minecraft:waxed_copper_block"},
        {pos: [1, 6, 2], state: "minecraft:waxed_copper_block"},
        {pos: [1, 6, 3], state: "minecraft:waxed_copper_block"},
        {pos: [1, 6, 4], state: "minecraft:waxed_copper_block"},
        {pos: [1, 6, 5], state: "minecraft:waxed_copper_block"},
        {pos: [1, 6, 6], state: "minecraft:waxed_copper_block"},
        {pos: [1, 6, 7], state: "minecraft:waxed_copper_block"},
        {pos: [1, 6, 8], state: "minecraft:waxed_copper_block"},
        {pos: [1, 6, 9], state: "minecraft:waxed_copper_block"},
        {pos: [1, 6, 10], state: "minecraft:waxed_copper_block"},
        {pos: [1, 6, 11], state: "minecraft:waxed_copper_block"},
        {pos: [1, 6, 12], state: "minecraft:waxed_copper_block"},
        {pos: [1, 6, 13], state: "minecraft:waxed_copper_block"},
        {pos: [1, 6, 14], state: "minecraft:waxed_copper_block"},
        {pos: [1, 6, 15], state: "minecraft:waxed_copper_block"},
        {pos: [1, 6, 16], state: "minecraft:waxed_copper_block"},
        {pos: [1, 6, 17], state: "minecraft:waxed_copper_block"},
        {pos: [1, 6, 18], state: "minecraft:tuff_bricks"},
        {pos: [2, 6, 0], state: "minecraft:tuff_bricks"},
        {pos: [2, 6, 1], state: "minecraft:waxed_copper_block"},
        {pos: [2, 6, 2], state: "minecraft:waxed_copper_block"},
        {pos: [2, 6, 6], state: "minecraft:waxed_copper_block"},
        {pos: [2, 6, 7], state: "minecraft:waxed_copper_block"},
        {pos: [2, 6, 11], state: "minecraft:waxed_copper_block"},
        {pos: [2, 6, 12], state: "minecraft:waxed_copper_block"},
        {pos: [2, 6, 16], state: "minecraft:waxed_copper_block"},
        {pos: [2, 6, 17], state: "minecraft:waxed_copper_block"},
        {pos: [2, 6, 18], state: "minecraft:tuff_bricks"},
        {pos: [3, 6, 0], state: "minecraft:tuff_bricks"},
        {pos: [3, 6, 1], state: "minecraft:waxed_copper_block"},
        {pos: [3, 6, 17], state: "minecraft:waxed_copper_block"},
        {pos: [3, 6, 18], state: "minecraft:tuff_bricks"},
        {pos: [4, 6, 0], state: "minecraft:tuff_bricks"},
        {pos: [4, 6, 1], state: "minecraft:waxed_copper_block"},
        {pos: [4, 6, 17], state: "minecraft:waxed_copper_block"},
        {pos: [4, 6, 18], state: "minecraft:tuff_bricks"},
        {pos: [5, 6, 0], state: "minecraft:tuff_bricks"},
        {pos: [5, 6, 1], state: "minecraft:waxed_copper_block"},
        {pos: [5, 6, 17], state: "minecraft:waxed_copper_block"},
        {pos: [5, 6, 18], state: "minecraft:tuff_bricks"},
        {pos: [6, 6, 0], state: "minecraft:tuff_bricks"},
        {pos: [6, 6, 1], state: "minecraft:waxed_copper_block"},
        {pos: [6, 6, 2], state: "minecraft:waxed_copper_block"},
        {pos: [6, 6, 6], state: "minecraft:waxed_copper_block"},
        {pos: [6, 6, 7], state: "minecraft:waxed_copper_block"},
        {pos: [6, 6, 11], state: "minecraft:waxed_copper_block"},
        {pos: [6, 6, 12], state: "minecraft:waxed_copper_block"},
        {pos: [6, 6, 16], state: "minecraft:waxed_copper_block"},
        {pos: [6, 6, 17], state: "minecraft:waxed_copper_block"},
        {pos: [6, 6, 18], state: "minecraft:tuff_bricks"},
        {pos: [7, 6, 0], state: "minecraft:tuff_bricks"},
        {pos: [7, 6, 1], state: "minecraft:waxed_copper_block"},
        {pos: [7, 6, 2], state: "minecraft:waxed_copper_block"},
        {pos: [7, 6, 6], state: "minecraft:waxed_copper_block"},
        {pos: [7, 6, 7], state: "minecraft:waxed_copper_block"},
        {pos: [7, 6, 8], state: "minecraft:waxed_copper_block"},
        {pos: [7, 6, 9], state: "minecraft:waxed_copper_block"},
        {pos: [7, 6, 10], state: "minecraft:waxed_copper_block"},
        {pos: [7, 6, 11], state: "minecraft:waxed_copper_block"},
        {pos: [7, 6, 12], state: "minecraft:waxed_copper_block"},
        {pos: [7, 6, 16], state: "minecraft:waxed_copper_block"},
        {pos: [7, 6, 17], state: "minecraft:waxed_copper_block"},
        {pos: [7, 6, 18], state: "minecraft:tuff_bricks"},
        {pos: [8, 6, 0], state: "minecraft:tuff_bricks"},
        {pos: [8, 6, 1], state: "minecraft:waxed_copper_block"},
        {pos: [8, 6, 7], state: "minecraft:waxed_copper_block"},
        {pos: [8, 6, 8], state: "minecraft:waxed_copper_block"},
        {pos: [8, 6, 9], state: "minecraft:waxed_copper_block"},
        {pos: [8, 6, 10], state: "minecraft:waxed_copper_block"},
        {pos: [8, 6, 11], state: "minecraft:waxed_copper_block"},
        {pos: [8, 6, 17], state: "minecraft:waxed_copper_block"},
        {pos: [8, 6, 18], state: "minecraft:tuff_bricks"},
        {pos: [9, 6, 0], state: "minecraft:tuff_bricks"},
        {pos: [9, 6, 1], state: "minecraft:waxed_copper_block"},
        {pos: [9, 6, 7], state: "minecraft:waxed_copper_block"},
        {pos: [9, 6, 8], state: "minecraft:waxed_copper_block"},
        {pos: [9, 6, 9], state: "minecraft:waxed_copper_block"},
        {pos: [9, 6, 10], state: "minecraft:waxed_copper_block"},
        {pos: [9, 6, 11], state: "minecraft:waxed_copper_block"},
        {pos: [9, 6, 17], state: "minecraft:waxed_copper_block"},
        {pos: [9, 6, 18], state: "minecraft:tuff_bricks"},
        {pos: [10, 6, 0], state: "minecraft:tuff_bricks"},
        {pos: [10, 6, 1], state: "minecraft:waxed_copper_block"},
        {pos: [10, 6, 7], state: "minecraft:waxed_copper_block"},
        {pos: [10, 6, 8], state: "minecraft:waxed_copper_block"},
        {pos: [10, 6, 9], state: "minecraft:waxed_copper_block"},
        {pos: [10, 6, 10], state: "minecraft:waxed_copper_block"},
        {pos: [10, 6, 11], state: "minecraft:waxed_copper_block"},
        {pos: [10, 6, 17], state: "minecraft:waxed_copper_block"},
        {pos: [10, 6, 18], state: "minecraft:tuff_bricks"},
        {pos: [11, 6, 0], state: "minecraft:tuff_bricks"},
        {pos: [11, 6, 1], state: "minecraft:waxed_copper_block"},
        {pos: [11, 6, 2], state: "minecraft:waxed_copper_block"},
        {pos: [11, 6, 6], state: "minecraft:waxed_copper_block"},
        {pos: [11, 6, 7], state: "minecraft:waxed_copper_block"},
        {pos: [11, 6, 8], state: "minecraft:waxed_copper_block"},
        {pos: [11, 6, 9], state: "minecraft:waxed_copper_block"},
        {pos: [11, 6, 10], state: "minecraft:waxed_copper_block"},
        {pos: [11, 6, 11], state: "minecraft:waxed_copper_block"},
        {pos: [11, 6, 12], state: "minecraft:waxed_copper_block"},
        {pos: [11, 6, 16], state: "minecraft:waxed_copper_block"},
        {pos: [11, 6, 17], state: "minecraft:waxed_copper_block"},
        {pos: [11, 6, 18], state: "minecraft:tuff_bricks"},
        {pos: [12, 6, 0], state: "minecraft:tuff_bricks"},
        {pos: [12, 6, 1], state: "minecraft:waxed_copper_block"},
        {pos: [12, 6, 2], state: "minecraft:waxed_copper_block"},
        {pos: [12, 6, 3], state: "minecraft:waxed_copper_block"},
        {pos: [12, 6, 4], state: "minecraft:waxed_copper_block"},
        {pos: [12, 6, 5], state: "minecraft:waxed_copper_block"},
        {pos: [12, 6, 6], state: "minecraft:waxed_copper_block"},
        {pos: [12, 6, 7], state: "minecraft:waxed_copper_block"},
        {pos: [12, 6, 8], state: "minecraft:waxed_copper_block"},
        {pos: [12, 6, 9], state: "minecraft:waxed_copper_block"},
        {pos: [12, 6, 10], state: "minecraft:waxed_copper_block"},
        {pos: [12, 6, 11], state: "minecraft:waxed_copper_block"},
        {pos: [12, 6, 12], state: "minecraft:waxed_copper_block"},
        {pos: [12, 6, 13], state: "minecraft:waxed_copper_block"},
        {pos: [12, 6, 14], state: "minecraft:waxed_copper_block"},
        {pos: [12, 6, 15], state: "minecraft:waxed_copper_block"},
        {pos: [12, 6, 16], state: "minecraft:waxed_copper_block"},
        {pos: [12, 6, 17], state: "minecraft:waxed_copper_block"},
        {pos: [12, 6, 18], state: "minecraft:tuff_bricks"},
        {pos: [13, 6, 0], state: "minecraft:tuff_bricks"},
        {pos: [13, 6, 1], state: "minecraft:tuff_bricks"},
        {pos: [13, 6, 2], state: "minecraft:tuff_bricks"},
        {pos: [13, 6, 3], state: "minecraft:tuff_bricks"},
        {pos: [13, 6, 4], state: "minecraft:tuff_bricks"},
        {pos: [13, 6, 5], state: "minecraft:tuff_bricks"},
        {pos: [13, 6, 6], state: "minecraft:tuff_bricks"},
        {pos: [13, 6, 7], state: "minecraft:tuff_bricks"},
        {pos: [13, 6, 8], state: "minecraft:tuff_bricks"},
        {pos: [13, 6, 9], state: "minecraft:tuff_bricks"},
        {pos: [13, 6, 10], state: "minecraft:tuff_bricks"},
        {pos: [13, 6, 11], state: "minecraft:tuff_bricks"},
        {pos: [13, 6, 12], state: "minecraft:tuff_bricks"},
        {pos: [13, 6, 13], state: "minecraft:tuff_bricks"},
        {pos: [13, 6, 14], state: "minecraft:tuff_bricks"},
        {pos: [13, 6, 15], state: "minecraft:tuff_bricks"},
        {pos: [13, 6, 16], state: "minecraft:tuff_bricks"},
        {pos: [13, 6, 17], state: "minecraft:tuff_bricks"},
        {pos: [13, 6, 18], state: "minecraft:tuff_bricks"},
        {pos: [0, 7, 0], state: "minecraft:tuff_bricks"},
        {pos: [0, 7, 1], state: "minecraft:tuff_bricks"},
        {pos: [0, 7, 2], state: "minecraft:tuff_bricks"},
        {pos: [0, 7, 3], state: "minecraft:tuff_bricks"},
        {pos: [0, 7, 4], state: "minecraft:tuff_bricks"},
        {pos: [0, 7, 5], state: "minecraft:tuff_bricks"},
        {pos: [0, 7, 6], state: "minecraft:tuff_bricks"},
        {pos: [0, 7, 7], state: "minecraft:tuff_bricks"},
        {pos: [0, 7, 8], state: "minecraft:tuff_bricks"},
        {pos: [0, 7, 9], state: "minecraft:tuff_bricks"},
        {pos: [0, 7, 10], state: "minecraft:tuff_bricks"},
        {pos: [0, 7, 11], state: "minecraft:tuff_bricks"},
        {pos: [0, 7, 12], state: "minecraft:tuff_bricks"},
        {pos: [0, 7, 13], state: "minecraft:tuff_bricks"},
        {pos: [0, 7, 14], state: "minecraft:tuff_bricks"},
        {pos: [0, 7, 15], state: "minecraft:tuff_bricks"},
        {pos: [0, 7, 16], state: "minecraft:tuff_bricks"},
        {pos: [0, 7, 17], state: "minecraft:tuff_bricks"},
        {pos: [0, 7, 18], state: "minecraft:tuff_bricks"},
        {pos: [1, 7, 0], state: "minecraft:tuff_bricks"},
        {pos: [1, 7, 1], state: "minecraft:tuff_bricks"},
        {pos: [1, 7, 2], state: "minecraft:tuff_bricks"},
        {pos: [1, 7, 3], state: "minecraft:tuff_bricks"},
        {pos: [1, 7, 4], state: "minecraft:waxed_copper_bulb{powered:false,lit:true}"},
        {pos: [1, 7, 5], state: "minecraft:tuff_bricks"},
        {pos: [1, 7, 6], state: "minecraft:tuff_bricks"},
        {pos: [1, 7, 7], state: "minecraft:tuff_bricks"},
        {pos: [1, 7, 8], state: "minecraft:tuff_bricks"},
        {pos: [1, 7, 9], state: "minecraft:waxed_copper_bulb{powered:false,lit:true}"},
        {pos: [1, 7, 10], state: "minecraft:tuff_bricks"},
        {pos: [1, 7, 11], state: "minecraft:tuff_bricks"},
        {pos: [1, 7, 12], state: "minecraft:tuff_bricks"},
        {pos: [1, 7, 13], state: "minecraft:tuff_bricks"},
        {pos: [1, 7, 14], state: "minecraft:waxed_copper_bulb{powered:false,lit:true}"},
        {pos: [1, 7, 15], state: "minecraft:tuff_bricks"},
        {pos: [1, 7, 16], state: "minecraft:tuff_bricks"},
        {pos: [1, 7, 17], state: "minecraft:tuff_bricks"},
        {pos: [1, 7, 18], state: "minecraft:tuff_bricks"},
        {pos: [2, 7, 0], state: "minecraft:tuff_bricks"},
        {pos: [2, 7, 1], state: "minecraft:tuff_bricks"},
        {pos: [2, 7, 2], state: "minecraft:tuff_bricks"},
        {pos: [2, 7, 6], state: "minecraft:tuff_bricks"},
        {pos: [2, 7, 7], state: "minecraft:tuff_bricks"},
        {pos: [2, 7, 11], state: "minecraft:tuff_bricks"},
        {pos: [2, 7, 12], state: "minecraft:tuff_bricks"},
        {pos: [2, 7, 16], state: "minecraft:tuff_bricks"},
        {pos: [2, 7, 17], state: "minecraft:tuff_bricks"},
        {pos: [2, 7, 18], state: "minecraft:tuff_bricks"},
        {pos: [3, 7, 0], state: "minecraft:tuff_bricks"},
        {pos: [3, 7, 1], state: "minecraft:tuff_bricks"},
        {pos: [3, 7, 17], state: "minecraft:tuff_bricks"},
        {pos: [3, 7, 18], state: "minecraft:tuff_bricks"},
        {pos: [4, 7, 0], state: "minecraft:tuff_bricks"},
        {pos: [4, 7, 1], state: "minecraft:waxed_copper_bulb{powered:false,lit:true}"},
        {pos: [4, 7, 17], state: "minecraft:waxed_copper_bulb{powered:false,lit:true}"},
        {pos: [4, 7, 18], state: "minecraft:tuff_bricks"},
        {pos: [5, 7, 0], state: "minecraft:tuff_bricks"},
        {pos: [5, 7, 1], state: "minecraft:tuff_bricks"},
        {pos: [5, 7, 17], state: "minecraft:tuff_bricks"},
        {pos: [5, 7, 18], state: "minecraft:tuff_bricks"},
        {pos: [6, 7, 0], state: "minecraft:tuff_bricks"},
        {pos: [6, 7, 1], state: "minecraft:tuff_bricks"},
        {pos: [6, 7, 2], state: "minecraft:tuff_bricks"},
        {pos: [6, 7, 6], state: "minecraft:tuff_bricks"},
        {pos: [6, 7, 7], state: "minecraft:tuff_bricks"},
        {pos: [6, 7, 11], state: "minecraft:tuff_bricks"},
        {pos: [6, 7, 12], state: "minecraft:tuff_bricks"},
        {pos: [6, 7, 16], state: "minecraft:tuff_bricks"},
        {pos: [6, 7, 17], state: "minecraft:tuff_bricks"},
        {pos: [6, 7, 18], state: "minecraft:tuff_bricks"},
        {pos: [7, 7, 0], state: "minecraft:tuff_bricks"},
        {pos: [7, 7, 1], state: "minecraft:tuff_bricks"},
        {pos: [7, 7, 2], state: "minecraft:tuff_bricks"},
        {pos: [7, 7, 6], state: "minecraft:tuff_bricks"},
        {pos: [7, 7, 7], state: "minecraft:tuff_bricks"},
        {pos: [7, 7, 8], state: "minecraft:tuff_bricks"},
        {pos: [7, 7, 9], state: "minecraft:waxed_copper_bulb{powered:false,lit:true}"},
        {pos: [7, 7, 10], state: "minecraft:tuff_bricks"},
        {pos: [7, 7, 11], state: "minecraft:tuff_bricks"},
        {pos: [7, 7, 12], state: "minecraft:tuff_bricks"},
        {pos: [7, 7, 16], state: "minecraft:tuff_bricks"},
        {pos: [7, 7, 17], state: "minecraft:tuff_bricks"},
        {pos: [7, 7, 18], state: "minecraft:tuff_bricks"},
        {pos: [8, 7, 0], state: "minecraft:tuff_bricks"},
        {pos: [8, 7, 1], state: "minecraft:tuff_bricks"},
        {pos: [8, 7, 7], state: "minecraft:tuff_bricks"},
        {pos: [8, 7, 8], state: "minecraft:tuff_bricks"},
        {pos: [8, 7, 9], state: "minecraft:waxed_copper_bulb{powered:false,lit:true}"},
        {pos: [8, 7, 10], state: "minecraft:tuff_bricks"},
        {pos: [8, 7, 11], state: "minecraft:tuff_bricks"},
        {pos: [8, 7, 17], state: "minecraft:tuff_bricks"},
        {pos: [8, 7, 18], state: "minecraft:tuff_bricks"},
        {pos: [9, 7, 0], state: "minecraft:tuff_bricks"},
        {pos: [9, 7, 1], state: "minecraft:waxed_copper_bulb{powered:false,lit:true}"},
        {pos: [9, 7, 7], state: "minecraft:tuff_bricks"},
        {pos: [9, 7, 8], state: "minecraft:tuff_bricks"},
        {pos: [9, 7, 9], state: "minecraft:waxed_copper_bulb{powered:false,lit:true}"},
        {pos: [9, 7, 10], state: "minecraft:tuff_bricks"},
        {pos: [9, 7, 11], state: "minecraft:waxed_copper_bulb{powered:false,lit:true}"},
        {pos: [9, 7, 17], state: "minecraft:waxed_copper_bulb{powered:false,lit:true}"},
        {pos: [9, 7, 18], state: "minecraft:tuff_bricks"},
        {pos: [10, 7, 0], state: "minecraft:tuff_bricks"},
        {pos: [10, 7, 1], state: "minecraft:tuff_bricks"},
        {pos: [10, 7, 7], state: "minecraft:tuff_bricks"},
        {pos: [10, 7, 8], state: "minecraft:tuff_bricks"},
        {pos: [10, 7, 9], state: "minecraft:waxed_copper_bulb{powered:false,lit:true}"},
        {pos: [10, 7, 10], state: "minecraft:tuff_bricks"},
        {pos: [10, 7, 11], state: "minecraft:tuff_bricks"},
        {pos: [10, 7, 17], state: "minecraft:tuff_bricks"},
        {pos: [10, 7, 18], state: "minecraft:tuff_bricks"},
        {pos: [11, 7, 0], state: "minecraft:tuff_bricks"},
        {pos: [11, 7, 1], state: "minecraft:tuff_bricks"},
        {pos: [11, 7, 2], state: "minecraft:tuff_bricks"},
        {pos: [11, 7, 6], state: "minecraft:tuff_bricks"},
        {pos: [11, 7, 7], state: "minecraft:tuff_bricks"},
        {pos: [11, 7, 8], state: "minecraft:tuff_bricks"},
        {pos: [11, 7, 9], state: "minecraft:waxed_copper_bulb{powered:false,lit:true}"},
        {pos: [11, 7, 10], state: "minecraft:tuff_bricks"},
        {pos: [11, 7, 11], state: "minecraft:tuff_bricks"},
        {pos: [11, 7, 12], state: "minecraft:tuff_bricks"},
        {pos: [11, 7, 16], state: "minecraft:tuff_bricks"},
        {pos: [11, 7, 17], state: "minecraft:tuff_bricks"},
        {pos: [11, 7, 18], state: "minecraft:tuff_bricks"},
        {pos: [12, 7, 0], state: "minecraft:tuff_bricks"},
        {pos: [12, 7, 1], state: "minecraft:tuff_bricks"},
        {pos: [12, 7, 2], state: "minecraft:tuff_bricks"},
        {pos: [12, 7, 3], state: "minecraft:tuff_bricks"},
        {pos: [12, 7, 4], state: "minecraft:waxed_copper_bulb{powered:false,lit:true}"},
        {pos: [12, 7, 5], state: "minecraft:tuff_bricks"},
        {pos: [12, 7, 6], state: "minecraft:tuff_bricks"},
        {pos: [12, 7, 7], state: "minecraft:tuff_bricks"},
        {pos: [12, 7, 8], state: "minecraft:tuff_bricks"},
        {pos: [12, 7, 9], state: "minecraft:waxed_copper_bulb{powered:false,lit:true}"},
        {pos: [12, 7, 10], state: "minecraft:tuff_bricks"},
        {pos: [12, 7, 11], state: "minecraft:tuff_bricks"},
        {pos: [12, 7, 12], state: "minecraft:tuff_bricks"},
        {pos: [12, 7, 13], state: "minecraft:tuff_bricks"},
        {pos: [12, 7, 14], state: "minecraft:waxed_copper_bulb{powered:false,lit:true}"},
        {pos: [12, 7, 15], state: "minecraft:tuff_bricks"},
        {pos: [12, 7, 16], state: "minecraft:tuff_bricks"},
        {pos: [12, 7, 17], state: "minecraft:tuff_bricks"},
        {pos: [12, 7, 18], state: "minecraft:tuff_bricks"},
        {pos: [13, 7, 0], state: "minecraft:tuff_bricks"},
        {pos: [13, 7, 1], state: "minecraft:tuff_bricks"},
        {pos: [13, 7, 2], state: "minecraft:tuff_bricks"},
        {pos: [13, 7, 3], state: "minecraft:tuff_bricks"},
        {pos: [13, 7, 4], state: "minecraft:tuff_bricks"},
        {pos: [13, 7, 5], state: "minecraft:tuff_bricks"},
        {pos: [13, 7, 6], state: "minecraft:tuff_bricks"},
        {pos: [13, 7, 7], state: "minecraft:tuff_bricks"},
        {pos: [13, 7, 8], state: "minecraft:tuff_bricks"},
        {pos: [13, 7, 9], state: "minecraft:tuff_bricks"},
        {pos: [13, 7, 10], state: "minecraft:tuff_bricks"},
        {pos: [13, 7, 11], state: "minecraft:tuff_bricks"},
        {pos: [13, 7, 12], state: "minecraft:tuff_bricks"},
        {pos: [13, 7, 13], state: "minecraft:tuff_bricks"},
        {pos: [13, 7, 14], state: "minecraft:tuff_bricks"},
        {pos: [13, 7, 15], state: "minecraft:tuff_bricks"},
        {pos: [13, 7, 16], state: "minecraft:tuff_bricks"},
        {pos: [13, 7, 17], state: "minecraft:tuff_bricks"},
        {pos: [13, 7, 18], state: "minecraft:tuff_bricks"},
        {pos: [0, 8, 0], state: "minecraft:tuff_bricks"},
        {pos: [0, 8, 1], state: "minecraft:tuff_bricks"},
        {pos: [0, 8, 2], state: "minecraft:tuff_bricks"},
        {pos: [0, 8, 3], state: "minecraft:tuff_bricks"},
        {pos: [0, 8, 4], state: "minecraft:tuff_bricks"},
        {pos: [0, 8, 5], state: "minecraft:tuff_bricks"},
        {pos: [0, 8, 6], state: "minecraft:tuff_bricks"},
        {pos: [0, 8, 7], state: "minecraft:tuff_bricks"},
        {pos: [0, 8, 8], state: "minecraft:tuff_bricks"},
        {pos: [0, 8, 9], state: "minecraft:tuff_bricks"},
        {pos: [0, 8, 10], state: "minecraft:tuff_bricks"},
        {pos: [0, 8, 11], state: "minecraft:tuff_bricks"},
        {pos: [0, 8, 12], state: "minecraft:tuff_bricks"},
        {pos: [0, 8, 13], state: "minecraft:tuff_bricks"},
        {pos: [0, 8, 14], state: "minecraft:tuff_bricks"},
        {pos: [0, 8, 15], state: "minecraft:tuff_bricks"},
        {pos: [0, 8, 16], state: "minecraft:tuff_bricks"},
        {pos: [0, 8, 17], state: "minecraft:tuff_bricks"},
        {pos: [0, 8, 18], state: "minecraft:tuff_bricks"},
        {pos: [1, 8, 0], state: "minecraft:tuff_bricks"},
        {pos: [1, 8, 1], state: "minecraft:chiseled_tuff_bricks"},
        {pos: [1, 8, 2], state: "minecraft:chiseled_tuff_bricks"},
        {pos: [1, 8, 3], state: "minecraft:chiseled_tuff_bricks"},
        {pos: [1, 8, 4], state: "minecraft:chiseled_tuff_bricks"},
        {pos: [1, 8, 5], state: "minecraft:chiseled_tuff_bricks"},
        {pos: [1, 8, 6], state: "minecraft:chiseled_tuff_bricks"},
        {pos: [1, 8, 7], state: "minecraft:chiseled_tuff_bricks"},
        {pos: [1, 8, 8], state: "minecraft:chiseled_tuff_bricks"},
        {pos: [1, 8, 9], state: "minecraft:chiseled_tuff_bricks"},
        {pos: [1, 8, 10], state: "minecraft:chiseled_tuff_bricks"},
        {pos: [1, 8, 11], state: "minecraft:chiseled_tuff_bricks"},
        {pos: [1, 8, 12], state: "minecraft:chiseled_tuff_bricks"},
        {pos: [1, 8, 13], state: "minecraft:chiseled_tuff_bricks"},
        {pos: [1, 8, 14], state: "minecraft:chiseled_tuff_bricks"},
        {pos: [1, 8, 15], state: "minecraft:chiseled_tuff_bricks"},
        {pos: [1, 8, 16], state: "minecraft:chiseled_tuff_bricks"},
        {pos: [1, 8, 17], state: "minecraft:chiseled_tuff_bricks"},
        {pos: [1, 8, 18], state: "minecraft:tuff_bricks"},
        {pos: [2, 8, 0], state: "minecraft:tuff_bricks"},
        {pos: [2, 8, 1], state: "minecraft:chiseled_tuff_bricks"},
        {pos: [2, 8, 2], state: "minecraft:chiseled_tuff_bricks"},
        {pos: [2, 8, 6], state: "minecraft:chiseled_tuff_bricks"},
        {pos: [2, 8, 7], state: "minecraft:chiseled_tuff_bricks"},
        {pos: [2, 8, 11], state: "minecraft:chiseled_tuff_bricks"},
        {pos: [2, 8, 12], state: "minecraft:chiseled_tuff_bricks"},
        {pos: [2, 8, 16], state: "minecraft:chiseled_tuff_bricks"},
        {pos: [2, 8, 17], state: "minecraft:chiseled_tuff_bricks"},
        {pos: [2, 8, 18], state: "minecraft:tuff_bricks"},
        {pos: [3, 8, 0], state: "minecraft:tuff_bricks"},
        {pos: [3, 8, 1], state: "minecraft:chiseled_tuff_bricks"},
        {pos: [3, 8, 17], state: "minecraft:chiseled_tuff_bricks"},
        {pos: [3, 8, 18], state: "minecraft:tuff_bricks"},
        {pos: [4, 8, 0], state: "minecraft:tuff_bricks"},
        {pos: [4, 8, 1], state: "minecraft:chiseled_tuff_bricks"},
        {pos: [4, 8, 17], state: "minecraft:chiseled_tuff_bricks"},
        {pos: [4, 8, 18], state: "minecraft:tuff_bricks"},
        {pos: [5, 8, 0], state: "minecraft:tuff_bricks"},
        {pos: [5, 8, 1], state: "minecraft:chiseled_tuff_bricks"},
        {pos: [5, 8, 17], state: "minecraft:chiseled_tuff_bricks"},
        {pos: [5, 8, 18], state: "minecraft:tuff_bricks"},
        {pos: [6, 8, 0], state: "minecraft:tuff_bricks"},
        {pos: [6, 8, 1], state: "minecraft:chiseled_tuff_bricks"},
        {pos: [6, 8, 2], state: "minecraft:chiseled_tuff_bricks"},
        {pos: [6, 8, 6], state: "minecraft:chiseled_tuff_bricks"},
        {pos: [6, 8, 7], state: "minecraft:chiseled_tuff_bricks"},
        {pos: [6, 8, 11], state: "minecraft:chiseled_tuff_bricks"},
        {pos: [6, 8, 12], state: "minecraft:chiseled_tuff_bricks"},
        {pos: [6, 8, 16], state: "minecraft:chiseled_tuff_bricks"},
        {pos: [6, 8, 17], state: "minecraft:chiseled_tuff_bricks"},
        {pos: [6, 8, 18], state: "minecraft:tuff_bricks"},
        {pos: [7, 8, 0], state: "minecraft:tuff_bricks"},
        {pos: [7, 8, 1], state: "minecraft:chiseled_tuff_bricks"},
        {pos: [7, 8, 2], state: "minecraft:chiseled_tuff_bricks"},
        {pos: [7, 8, 6], state: "minecraft:chiseled_tuff_bricks"},
        {pos: [7, 8, 7], state: "minecraft:chiseled_tuff_bricks"},
        {pos: [7, 8, 8], state: "minecraft:chiseled_tuff_bricks"},
        {pos: [7, 8, 9], state: "minecraft:chiseled_tuff_bricks"},
        {pos: [7, 8, 10], state: "minecraft:chiseled_tuff_bricks"},
        {pos: [7, 8, 11], state: "minecraft:chiseled_tuff_bricks"},
        {pos: [7, 8, 12], state: "minecraft:chiseled_tuff_bricks"},
        {pos: [7, 8, 16], state: "minecraft:chiseled_tuff_bricks"},
        {pos: [7, 8, 17], state: "minecraft:chiseled_tuff_bricks"},
        {pos: [7, 8, 18], state: "minecraft:tuff_bricks"},
        {pos: [8, 8, 0], state: "minecraft:tuff_bricks"},
        {pos: [8, 8, 1], state: "minecraft:chiseled_tuff_bricks"},
        {pos: [8, 8, 7], state: "minecraft:chiseled_tuff_bricks"},
        {pos: [8, 8, 8], state: "minecraft:chiseled_tuff_bricks"},
        {pos: [8, 8, 9], state: "minecraft:chiseled_tuff_bricks"},
        {pos: [8, 8, 10], state: "minecraft:chiseled_tuff_bricks"},
        {pos: [8, 8, 11], state: "minecraft:chiseled_tuff_bricks"},
        {pos: [8, 8, 17], state: "minecraft:chiseled_tuff_bricks"},
        {pos: [8, 8, 18], state: "minecraft:tuff_bricks"},
        {pos: [9, 8, 0], state: "minecraft:tuff_bricks"},
        {pos: [9, 8, 1], state: "minecraft:chiseled_tuff_bricks"},
        {pos: [9, 8, 7], state: "minecraft:chiseled_tuff_bricks"},
        {pos: [9, 8, 8], state: "minecraft:chiseled_tuff_bricks"},
        {pos: [9, 8, 9], state: "minecraft:chiseled_tuff_bricks"},
        {pos: [9, 8, 10], state: "minecraft:chiseled_tuff_bricks"},
        {pos: [9, 8, 11], state: "minecraft:chiseled_tuff_bricks"},
        {pos: [9, 8, 17], state: "minecraft:chiseled_tuff_bricks"},
        {pos: [9, 8, 18], state: "minecraft:tuff_bricks"},
        {pos: [10, 8, 0], state: "minecraft:tuff_bricks"},
        {pos: [10, 8, 1], state: "minecraft:chiseled_tuff_bricks"},
        {pos: [10, 8, 7], state: "minecraft:chiseled_tuff_bricks"},
        {pos: [10, 8, 8], state: "minecraft:chiseled_tuff_bricks"},
        {pos: [10, 8, 9], state: "minecraft:chiseled_tuff_bricks"},
        {pos: [10, 8, 10], state: "minecraft:chiseled_tuff_bricks"},
        {pos: [10, 8, 11], state: "minecraft:chiseled_tuff_bricks"},
        {pos: [10, 8, 13], state: "minecraft:waxed_copper_grate{waterlogged:false}"},
        {pos: [10, 8, 14], state: "minecraft:waxed_copper_grate{waterlogged:false}"},
        {pos: [10, 8, 15], state: "minecraft:waxed_copper_grate{waterlogged:false}"},
        {pos: [10, 8, 17], state: "minecraft:chiseled_tuff_bricks"},
        {pos: [10, 8, 18], state: "minecraft:tuff_bricks"},
        {pos: [11, 8, 0], state: "minecraft:tuff_bricks"},
        {pos: [11, 8, 1], state: "minecraft:chiseled_tuff_bricks"},
        {pos: [11, 8, 2], state: "minecraft:chiseled_tuff_bricks"},
        {pos: [11, 8, 6], state: "minecraft:chiseled_tuff_bricks"},
        {pos: [11, 8, 7], state: "minecraft:chiseled_tuff_bricks"},
        {pos: [11, 8, 8], state: "minecraft:chiseled_tuff_bricks"},
        {pos: [11, 8, 9], state: "minecraft:chiseled_tuff_bricks"},
        {pos: [11, 8, 10], state: "minecraft:chiseled_tuff_bricks"},
        {pos: [11, 8, 11], state: "minecraft:chiseled_tuff_bricks"},
        {pos: [11, 8, 12], state: "minecraft:chiseled_tuff_bricks"},
        {pos: [11, 8, 13], state: "minecraft:waxed_copper_grate{waterlogged:false}"},
        {pos: [11, 8, 14], state: "minecraft:waxed_copper_grate{waterlogged:false}"},
        {pos: [11, 8, 15], state: "minecraft:waxed_copper_grate{waterlogged:false}"},
        {pos: [11, 8, 16], state: "minecraft:chiseled_tuff_bricks"},
        {pos: [11, 8, 17], state: "minecraft:chiseled_tuff_bricks"},
        {pos: [11, 8, 18], state: "minecraft:tuff_bricks"},
        {pos: [12, 8, 0], state: "minecraft:tuff_bricks"},
        {pos: [12, 8, 1], state: "minecraft:chiseled_tuff_bricks"},
        {pos: [12, 8, 2], state: "minecraft:chiseled_tuff_bricks"},
        {pos: [12, 8, 3], state: "minecraft:chiseled_tuff_bricks"},
        {pos: [12, 8, 4], state: "minecraft:chiseled_tuff_bricks"},
        {pos: [12, 8, 5], state: "minecraft:chiseled_tuff_bricks"},
        {pos: [12, 8, 6], state: "minecraft:chiseled_tuff_bricks"},
        {pos: [12, 8, 7], state: "minecraft:chiseled_tuff_bricks"},
        {pos: [12, 8, 8], state: "minecraft:chiseled_tuff_bricks"},
        {pos: [12, 8, 9], state: "minecraft:chiseled_tuff_bricks"},
        {pos: [12, 8, 10], state: "minecraft:chiseled_tuff_bricks"},
        {pos: [12, 8, 11], state: "minecraft:chiseled_tuff_bricks"},
        {pos: [12, 8, 12], state: "minecraft:chiseled_tuff_bricks"},
        {pos: [12, 8, 13], state: "minecraft:waxed_oxidized_copper"},
        {pos: [12, 8, 14], state: "minecraft:waxed_oxidized_copper"},
        {pos: [12, 8, 15], state: "minecraft:waxed_oxidized_copper"},
        {pos: [12, 8, 16], state: "minecraft:chiseled_tuff_bricks"},
        {pos: [12, 8, 17], state: "minecraft:chiseled_tuff_bricks"},
        {pos: [12, 8, 18], state: "minecraft:tuff_bricks"},
        {pos: [13, 8, 0], state: "minecraft:tuff_bricks"},
        {pos: [13, 8, 1], state: "minecraft:tuff_bricks"},
        {pos: [13, 8, 2], state: "minecraft:tuff_bricks"},
        {pos: [13, 8, 3], state: "minecraft:tuff_bricks"},
        {pos: [13, 8, 4], state: "minecraft:tuff_bricks"},
        {pos: [13, 8, 5], state: "minecraft:tuff_bricks"},
        {pos: [13, 8, 6], state: "minecraft:tuff_bricks"},
        {pos: [13, 8, 7], state: "minecraft:tuff_bricks"},
        {pos: [13, 8, 8], state: "minecraft:tuff_bricks"},
        {pos: [13, 8, 9], state: "minecraft:tuff_bricks"},
        {pos: [13, 8, 10], state: "minecraft:tuff_bricks"},
        {pos: [13, 8, 11], state: "minecraft:tuff_bricks"},
        {pos: [13, 8, 12], state: "minecraft:tuff_bricks"},
        {pos: [13, 8, 13], state: "minecraft:waxed_oxidized_copper"},
        {pos: [13, 8, 14], state: "minecraft:waxed_oxidized_copper"},
        {pos: [13, 8, 15], state: "minecraft:waxed_oxidized_copper"},
        {pos: [13, 8, 16], state: "minecraft:tuff_bricks"},
        {pos: [13, 8, 17], state: "minecraft:tuff_bricks"},
        {pos: [13, 8, 18], state: "minecraft:tuff_bricks"},
        {pos: [0, 9, 0], state: "minecraft:tuff_bricks"},
        {pos: [0, 9, 1], state: "minecraft:tuff_bricks"},
        {pos: [0, 9, 2], state: "minecraft:tuff_bricks"},
        {pos: [0, 9, 3], state: "minecraft:tuff_bricks"},
        {pos: [0, 9, 4], state: "minecraft:tuff_bricks"},
        {pos: [0, 9, 5], state: "minecraft:tuff_bricks"},
        {pos: [0, 9, 6], state: "minecraft:tuff_bricks"},
        {pos: [0, 9, 7], state: "minecraft:tuff_bricks"},
        {pos: [0, 9, 8], state: "minecraft:tuff_bricks"},
        {pos: [0, 9, 9], state: "minecraft:tuff_bricks"},
        {pos: [0, 9, 10], state: "minecraft:tuff_bricks"},
        {pos: [0, 9, 11], state: "minecraft:tuff_bricks"},
        {pos: [0, 9, 12], state: "minecraft:tuff_bricks"},
        {pos: [0, 9, 13], state: "minecraft:tuff_bricks"},
        {pos: [0, 9, 14], state: "minecraft:tuff_bricks"},
        {pos: [0, 9, 15], state: "minecraft:tuff_bricks"},
        {pos: [0, 9, 16], state: "minecraft:tuff_bricks"},
        {pos: [0, 9, 17], state: "minecraft:tuff_bricks"},
        {pos: [0, 9, 18], state: "minecraft:tuff_bricks"},
        {pos: [1, 9, 0], state: "minecraft:tuff_bricks"},
        {pos: [1, 9, 1], state: "minecraft:waxed_copper_block"},
        {pos: [1, 9, 2], state: "minecraft:waxed_copper_block"},
        {pos: [1, 9, 3], state: "minecraft:waxed_copper_block"},
        {pos: [1, 9, 4], state: "minecraft:waxed_copper_block"},
        {pos: [1, 9, 5], state: "minecraft:waxed_copper_block"},
        {pos: [1, 9, 6], state: "minecraft:waxed_copper_block"},
        {pos: [1, 9, 7], state: "minecraft:waxed_copper_block"},
        {pos: [1, 9, 8], state: "minecraft:waxed_copper_block"},
        {pos: [1, 9, 9], state: "minecraft:waxed_copper_block"},
        {pos: [1, 9, 10], state: "minecraft:waxed_copper_block"},
        {pos: [1, 9, 11], state: "minecraft:waxed_copper_block"},
        {pos: [1, 9, 12], state: "minecraft:waxed_copper_block"},
        {pos: [1, 9, 13], state: "minecraft:waxed_copper_block"},
        {pos: [1, 9, 14], state: "minecraft:waxed_copper_block"},
        {pos: [1, 9, 15], state: "minecraft:waxed_copper_block"},
        {pos: [1, 9, 16], state: "minecraft:waxed_copper_block"},
        {pos: [1, 9, 17], state: "minecraft:waxed_copper_block"},
        {pos: [1, 9, 18], state: "minecraft:tuff_bricks"},
        {pos: [2, 9, 0], state: "minecraft:tuff_bricks"},
        {pos: [2, 9, 1], state: "minecraft:waxed_copper_block"},
        {pos: [2, 9, 2], state: "minecraft:waxed_copper_block"},
        {pos: [2, 9, 6], state: "minecraft:waxed_copper_block"},
        {pos: [2, 9, 7], state: "minecraft:waxed_copper_block"},
        {pos: [2, 9, 11], state: "minecraft:waxed_copper_block"},
        {pos: [2, 9, 12], state: "minecraft:waxed_copper_block"},
        {pos: [2, 9, 16], state: "minecraft:waxed_copper_block"},
        {pos: [2, 9, 17], state: "minecraft:waxed_copper_block"},
        {pos: [2, 9, 18], state: "minecraft:tuff_bricks"},
        {pos: [3, 9, 0], state: "minecraft:tuff_bricks"},
        {pos: [3, 9, 1], state: "minecraft:waxed_copper_block"},
        {pos: [3, 9, 17], state: "minecraft:waxed_copper_block"},
        {pos: [3, 9, 18], state: "minecraft:tuff_bricks"},
        {pos: [4, 9, 0], state: "minecraft:tuff_bricks"},
        {pos: [4, 9, 1], state: "minecraft:waxed_copper_block"},
        {pos: [4, 9, 17], state: "minecraft:waxed_copper_block"},
        {pos: [4, 9, 18], state: "minecraft:tuff_bricks"},
        {pos: [5, 9, 0], state: "minecraft:tuff_bricks"},
        {pos: [5, 9, 1], state: "minecraft:waxed_copper_block"},
        {pos: [5, 9, 17], state: "minecraft:waxed_copper_block"},
        {pos: [5, 9, 18], state: "minecraft:tuff_bricks"},
        {pos: [6, 9, 0], state: "minecraft:tuff_bricks"},
        {pos: [6, 9, 1], state: "minecraft:waxed_copper_block"},
