{
    size: [12, 11, 17],
    data: [
        {pos: [0, 0, 0], state: "minecraft:tuff_bricks"},
        {pos: [0, 0, 1], state: "minecraft:tuff_bricks"},
        {pos: [0, 0, 2], state: "minecraft:tuff_bricks"},
        {pos: [0, 0, 3], state: "minecraft:tuff_bricks"},
        {pos: [0, 0, 4], state: "minecraft:tuff_bricks"},
        {pos: [0, 0, 5], state: "minecraft:tuff_bricks"},
        {pos: [0, 0, 6], state: "minecraft:tuff_bricks"},
        {pos: [0, 0, 7], state: "minecraft:tuff_bricks"},
        {pos: [0, 0, 8], state: "minecraft:tuff_bricks"},
        {pos: [0, 0, 9], state: "minecraft:tuff_bricks"},
        {pos: [0, 0, 10], state: "minecraft:tuff_bricks"},
        {pos: [0, 0, 11], state: "minecraft:tuff_bricks"},
        {pos: [0, 0, 12], state: "minecraft:tuff_bricks"},
        {pos: [0, 0, 13], state: "minecraft:tuff_bricks"},
        {pos: [0, 0, 14], state: "minecraft:tuff_bricks"},
        {pos: [0, 0, 15], state: "minecraft:tuff_bricks"},
        {pos: [0, 0, 16], state: "minecraft:tuff_bricks"},
        {pos: [1, 0, 0], state: "minecraft:tuff_bricks"},
        {pos: [1, 0, 1], state: "minecraft:tuff_bricks"},
        {pos: [1, 0, 2], state: "minecraft:waxed_oxidized_cut_copper"},
        {pos: [1, 0, 3], state: "minecraft:waxed_oxidized_cut_copper"},
        {pos: [1, 0, 4], state: "minecraft:waxed_oxidized_cut_copper"},
        {pos: [1, 0, 5], state: "minecraft:tuff_bricks"},
        {pos: [1, 0, 6], state: "minecraft:tuff_bricks"},
        {pos: [1, 0, 7], state: "minecraft:waxed_oxidized_cut_copper"},
        {pos: [1, 0, 8], state: "minecraft:waxed_oxidized_cut_copper"},
        {pos: [1, 0, 9], state: "minecraft:waxed_oxidized_cut_copper"},
        {pos: [1, 0, 10], state: "minecraft:tuff_bricks"},
        {pos: [1, 0, 11], state: "minecraft:tuff_bricks"},
        {pos: [1, 0, 12], state: "minecraft:tuff_bricks"},
        {pos: [1, 0, 13], state: "minecraft:tuff_bricks"},
        {pos: [1, 0, 14], state: "minecraft:tuff_bricks"},
        {pos: [1, 0, 15], state: "minecraft:tuff_bricks"},
        {pos: [1, 0, 16], state: "minecraft:tuff_bricks"},
        {pos: [2, 0, 0], state: "minecraft:tuff_bricks"},
        {pos: [2, 0, 1], state: "minecraft:waxed_oxidized_cut_copper"},
        {pos: [2, 0, 2], state: "minecraft:waxed_oxidized_copper"},
        {pos: [2, 0, 3], state: "minecraft:waxed_oxidized_copper"},
        {pos: [2, 0, 4], state: "minecraft:waxed_oxidized_copper"},
        {pos: [2, 0, 5], state: "minecraft:waxed_oxidized_copper"},
        {pos: [2, 0, 6], state: "minecraft:tuff_bricks"},
        {pos: [2, 0, 7], state: "minecraft:tuff_bricks"},
        {pos: [2, 0, 8], state: "minecraft:tuff_bricks"},
        {pos: [2, 0, 9], state: "minecraft:tuff_bricks"},
        {pos: [2, 0, 10], state: "minecraft:tuff_bricks"},
        {pos: [2, 0, 11], state: "minecraft:tuff_bricks"},
        {pos: [2, 0, 12], state: "minecraft:tuff_bricks"},
        {pos: [2, 0, 13], state: "minecraft:tuff_bricks"},
        {pos: [2, 0, 14], state: "minecraft:tuff_bricks"},
        {pos: [2, 0, 15], state: "minecraft:tuff_bricks"},
        {pos: [2, 0, 16], state: "minecraft:tuff_bricks"},
        {pos: [3, 0, 0], state: "minecraft:tuff_bricks"},
        {pos: [3, 0, 1], state: "minecraft:waxed_oxidized_cut_copper"},
        {pos: [3, 0, 2], state: "minecraft:waxed_oxidized_copper"},
        {pos: [3, 0, 3], state: "minecraft:waxed_oxidized_copper"},
        {pos: [3, 0, 4], state: "minecraft:waxed_oxidized_copper"},
        {pos: [3, 0, 5], state: "minecraft:waxed_oxidized_copper"},
        {pos: [3, 0, 6], state: "minecraft:tuff_bricks"},
        {pos: [3, 0, 7], state: "minecraft:tuff_bricks"},
        {pos: [3, 0, 8], state: "minecraft:tuff_bricks"},
        {pos: [3, 0, 9], state: "minecraft:tuff_bricks"},
        {pos: [3, 0, 10], state: "minecraft:tuff_bricks"},
        {pos: [3, 0, 11], state: "minecraft:tuff_bricks"},
        {pos: [3, 0, 12], state: "minecraft:tuff_bricks"},
        {pos: [3, 0, 13], state: "minecraft:tuff_bricks"},
        {pos: [3, 0, 14], state: "minecraft:tuff_bricks"},
        {pos: [3, 0, 15], state: "minecraft:tuff_bricks"},
        {pos: [3, 0, 16], state: "minecraft:tuff_bricks"},
        {pos: [4, 0, 0], state: "minecraft:tuff_bricks"},
        {pos: [4, 0, 1], state: "minecraft:waxed_oxidized_cut_copper"},
        {pos: [4, 0, 2], state: "minecraft:waxed_oxidized_copper"},
        {pos: [4, 0, 3], state: "minecraft:waxed_oxidized_copper"},
        {pos: [4, 0, 4], state: "minecraft:waxed_oxidized_copper"},
        {pos: [4, 0, 5], state: "minecraft:waxed_oxidized_copper"},
        {pos: [4, 0, 6], state: "minecraft:tuff_bricks"},
        {pos: [4, 0, 7], state: "minecraft:tuff_bricks"},
        {pos: [4, 0, 8], state: "minecraft:tuff_bricks"},
        {pos: [4, 0, 9], state: "minecraft:tuff_bricks"},
        {pos: [4, 0, 10], state: "minecraft:tuff_bricks"},
        {pos: [4, 0, 11], state: "minecraft:tuff_bricks"},
        {pos: [4, 0, 12], state: "minecraft:tuff_bricks"},
        {pos: [4, 0, 13], state: "minecraft:tuff_bricks"},
        {pos: [4, 0, 14], state: "minecraft:tuff_bricks"},
        {pos: [4, 0, 15], state: "minecraft:tuff_bricks"},
        {pos: [4, 0, 16], state: "minecraft:tuff_bricks"},
        {pos: [5, 0, 0], state: "minecraft:tuff_bricks"},
        {pos: [5, 0, 1], state: "minecraft:tuff_bricks"},
        {pos: [5, 0, 2], state: "minecraft:waxed_oxidized_copper"},
        {pos: [5, 0, 3], state: "minecraft:waxed_oxidized_copper"},
        {pos: [5, 0, 4], state: "minecraft:waxed_oxidized_copper"},
        {pos: [5, 0, 5], state: "minecraft:tuff_bricks"},
        {pos: [5, 0, 6], state: "minecraft:tuff_bricks"},
        {pos: [5, 0, 7], state: "minecraft:tuff_bricks"},
        {pos: [5, 0, 8], state: "minecraft:tuff_bricks"},
        {pos: [5, 0, 9], state: "minecraft:tuff_bricks"},
        {pos: [5, 0, 10], state: "minecraft:tuff_bricks"},
        {pos: [5, 0, 11], state: "minecraft:tuff_bricks"},
        {pos: [5, 0, 12], state: "minecraft:tuff_bricks"},
        {pos: [5, 0, 13], state: "minecraft:tuff_bricks"},
        {pos: [5, 0, 14], state: "minecraft:tuff_bricks"},
        {pos: [5, 0, 15], state: "minecraft:tuff_bricks"},
        {pos: [5, 0, 16], state: "minecraft:tuff_bricks"},
        {pos: [6, 0, 0], state: "minecraft:tuff_bricks"},
        {pos: [6, 0, 1], state: "minecraft:waxed_oxidized_cut_copper"},
        {pos: [6, 0, 2], state: "minecraft:waxed_oxidized_copper"},
        {pos: [6, 0, 3], state: "minecraft:waxed_oxidized_copper"},
        {pos: [6, 0, 4], state: "minecraft:waxed_oxidized_copper"},
        {pos: [6, 0, 5], state: "minecraft:tuff_bricks"},
        {pos: [6, 0, 6], state: "minecraft:tuff_bricks"},
        {pos: [6, 0, 7], state: "minecraft:waxed_oxidized_cut_copper"},
        {pos: [6, 0, 8], state: "minecraft:waxed_oxidized_cut_copper"},
        {pos: [6, 0, 9], state: "minecraft:waxed_oxidized_cut_copper"},
        {pos: [6, 0, 10], state: "minecraft:tuff_bricks"},
        {pos: [6, 0, 11], state: "minecraft:tuff_bricks"},
        {pos: [6, 0, 12], state: "minecraft:waxed_oxidized_cut_copper"},
        {pos: [6, 0, 13], state: "minecraft:waxed_oxidized_cut_copper"},
        {pos: [6, 0, 14], state: "minecraft:waxed_oxidized_cut_copper"},
        {pos: [6, 0, 15], state: "minecraft:tuff_bricks"},
        {pos: [6, 0, 16], state: "minecraft:tuff_bricks"},
        {pos: [7, 0, 0], state: "minecraft:tuff_bricks"},
        {pos: [7, 0, 1], state: "minecraft:waxed_oxidized_cut_copper"},
        {pos: [7, 0, 2], state: "minecraft:waxed_oxidized_copper"},
        {pos: [7, 0, 3], state: "minecraft:waxed_oxidized_copper"},
        {pos: [7, 0, 4], state: "minecraft:waxed_oxidized_copper"},
        {pos: [7, 0, 5], state: "minecraft:waxed_oxidized_copper"},
        {pos: [7, 0, 6], state: "minecraft:waxed_oxidized_copper"},
        {pos: [7, 0, 7], state: "minecraft:waxed_oxidized_copper"},
        {pos: [7, 0, 8], state: "minecraft:waxed_oxidized_copper"},
        {pos: [7, 0, 9], state: "minecraft:waxed_oxidized_copper"},
        {pos: [7, 0, 10], state: "minecraft:waxed_oxidized_copper"},
        {pos: [7, 0, 11], state: "minecraft:waxed_oxidized_copper"},
        {pos: [7, 0, 12], state: "minecraft:waxed_oxidized_copper"},
        {pos: [7, 0, 13], state: "minecraft:waxed_oxidized_copper"},
        {pos: [7, 0, 14], state: "minecraft:waxed_oxidized_copper"},
        {pos: [7, 0, 15], state: "minecraft:tuff_bricks"},
        {pos: [7, 0, 16], state: "minecraft:tuff_bricks"},
        {pos: [8, 0, 0], state: "minecraft:tuff_bricks"},
        {pos: [8, 0, 1], state: "minecraft:waxed_oxidized_cut_copper"},
        {pos: [8, 0, 2], state: "minecraft:waxed_oxidized_copper"},
        {pos: [8, 0, 3], state: "minecraft:waxed_oxidized_copper"},
        {pos: [8, 0, 4], state: "minecraft:waxed_oxidized_copper"},
        {pos: [8, 0, 5], state: "minecraft:waxed_oxidized_copper"},
        {pos: [8, 0, 6], state: "minecraft:waxed_oxidized_copper"},
        {pos: [8, 0, 7], state: "minecraft:waxed_oxidized_copper"},
        {pos: [8, 0, 8], state: "minecraft:waxed_oxidized_copper"},
        {pos: [8, 0, 9], state: "minecraft:waxed_oxidized_copper"},
        {pos: [8, 0, 10], state: "minecraft:waxed_oxidized_copper"},
        {pos: [8, 0, 11], state: "minecraft:waxed_oxidized_copper"},
        {pos: [8, 0, 12], state: "minecraft:waxed_oxidized_copper"},
        {pos: [8, 0, 13], state: "minecraft:waxed_oxidized_copper"},
        {pos: [8, 0, 14], state: "minecraft:waxed_oxidized_copper"},
        {pos: [8, 0, 15], state: "minecraft:tuff_bricks"},
        {pos: [8, 0, 16], state: "minecraft:tuff_bricks"},
        {pos: [9, 0, 0], state: "minecraft:tuff_bricks"},
        {pos: [9, 0, 1], state: "minecraft:waxed_oxidized_cut_copper"},
        {pos: [9, 0, 2], state: "minecraft:waxed_oxidized_copper"},
        {pos: [9, 0, 3], state: "minecraft:waxed_oxidized_copper"},
        {pos: [9, 0, 4], state: "minecraft:waxed_oxidized_copper"},
        {pos: [9, 0, 5], state: "minecraft:waxed_oxidized_copper"},
        {pos: [9, 0, 6], state: "minecraft:waxed_oxidized_copper"},
        {pos: [9, 0, 7], state: "minecraft:waxed_oxidized_copper"},
        {pos: [9, 0, 8], state: "minecraft:waxed_oxidized_copper"},
        {pos: [9, 0, 9], state: "minecraft:waxed_oxidized_copper"},
        {pos: [9, 0, 10], state: "minecraft:waxed_oxidized_copper"},
        {pos: [9, 0, 11], state: "minecraft:waxed_oxidized_copper"},
        {pos: [9, 0, 12], state: "minecraft:waxed_oxidized_copper"},
        {pos: [9, 0, 13], state: "minecraft:waxed_oxidized_copper"},
        {pos: [9, 0, 14], state: "minecraft:waxed_oxidized_copper"},
        {pos: [9, 0, 15], state: "minecraft:tuff_bricks"},
        {pos: [9, 0, 16], state: "minecraft:tuff_bricks"},
        {pos: [10, 0, 0], state: "minecraft:tuff_bricks"},
        {pos: [10, 0, 1], state: "minecraft:tuff_bricks"},
        {pos: [10, 0, 2], state: "minecraft:waxed_oxidized_cut_copper"},
        {pos: [10, 0, 3], state: "minecraft:waxed_oxidized_cut_copper"},
        {pos: [10, 0, 4], state: "minecraft:waxed_oxidized_cut_copper"},
        {pos: [10, 0, 5], state: "minecraft:tuff_bricks"},
        {pos: [10, 0, 6], state: "minecraft:tuff_bricks"},
        {pos: [10, 0, 7], state: "minecraft:waxed_oxidized_cut_copper"},
        {pos: [10, 0, 8], state: "minecraft:waxed_oxidized_cut_copper"},
        {pos: [10, 0, 9], state: "minecraft:waxed_oxidized_cut_copper"},
        {pos: [10, 0, 10], state: "minecraft:tuff_bricks"},
        {pos: [10, 0, 11], state: "minecraft:tuff_bricks"},
        {pos: [10, 0, 12], state: "minecraft:waxed_oxidized_copper"},
        {pos: [10, 0, 13], state: "minecraft:waxed_oxidized_copper"},
        {pos: [10, 0, 14], state: "minecraft:waxed_oxidized_copper"},
        {pos: [10, 0, 15], state: "minecraft:tuff_bricks"},
        {pos: [10, 0, 16], state: "minecraft:tuff_bricks"},
        {pos: [11, 0, 0], state: "minecraft:tuff_bricks"},
        {pos: [11, 0, 1], state: "minecraft:tuff_bricks"},
        {pos: [11, 0, 2], state: "minecraft:tuff_bricks"},
        {pos: [11, 0, 3], state: "minecraft:tuff_bricks"},
        {pos: [11, 0, 4], state: "minecraft:tuff_bricks"},
        {pos: [11, 0, 5], state: "minecraft:tuff_bricks"},
        {pos: [11, 0, 6], state: "minecraft:tuff_bricks"},
        {pos: [11, 0, 7], state: "minecraft:tuff_bricks"},
        {pos: [11, 0, 8], state: "minecraft:tuff_bricks"},
        {pos: [11, 0, 9], state: "minecraft:tuff_bricks"},
        {pos: [11, 0, 10], state: "minecraft:tuff_bricks"},
        {pos: [11, 0, 11], state: "minecraft:tuff_bricks"},
        {pos: [11, 0, 12], state: "minecraft:waxed_oxidized_copper"},
        {pos: [11, 0, 13], state: "minecraft:waxed_oxidized_copper"},
        {pos: [11, 0, 14], state: "minecraft:waxed_oxidized_copper"},
        {pos: [11, 0, 15], state: "minecraft:tuff_bricks"},
        {pos: [11, 0, 16], state: "minecraft:tuff_bricks"},
        {pos: [0, 1, 0], state: "minecraft:waxed_copper_block"},
        {pos: [0, 1, 1], state: "minecraft:waxed_copper_block"},
        {pos: [0, 1, 2], state: "minecraft:waxed_copper_block"},
        {pos: [0, 1, 3], state: "minecraft:waxed_copper_block"},
        {pos: [0, 1, 4], state: "minecraft:waxed_copper_block"},
        {pos: [0, 1, 5], state: "minecraft:waxed_copper_block"},
        {pos: [0, 1, 6], state: "minecraft:waxed_copper_block"},
        {pos: [0, 1, 7], state: "minecraft:waxed_copper_block"},
        {pos: [0, 1, 8], state: "minecraft:waxed_copper_block"},
        {pos: [0, 1, 9], state: "minecraft:waxed_copper_block"},
        {pos: [0, 1, 10], state: "minecraft:waxed_copper_block"},
        {pos: [0, 1, 11], state: "minecraft:waxed_copper_block"},
        {pos: [0, 1, 12], state: "minecraft:tuff_bricks"},
        {pos: [0, 1, 13], state: "minecraft:tuff_bricks"},
        {pos: [0, 1, 14], state: "minecraft:tuff_bricks"},
        {pos: [0, 1, 15], state: "minecraft:tuff_bricks"},
        {pos: [0, 1, 16], state: "minecraft:tuff_bricks"},
        {pos: [1, 1, 0], state: "minecraft:waxed_copper_block"},
        {pos: [1, 1, 1], state: "minecraft:waxed_copper_block"},
        {pos: [1, 1, 5], state: "minecraft:waxed_copper_block"},
        {pos: [1, 1, 6], state: "minecraft:waxed_copper_block"},
        {pos: [1, 1, 10], state: "minecraft:waxed_copper_block"},
        {pos: [1, 1, 11], state: "minecraft:waxed_copper_block"},
        {pos: [1, 1, 12], state: "minecraft:tuff_bricks"},
        {pos: [1, 1, 13], state: "minecraft:tuff_bricks"},
        {pos: [1, 1, 14], state: "minecraft:tuff_bricks"},
        {pos: [1, 1, 15], state: "minecraft:tuff_bricks"},
        {pos: [1, 1, 16], state: "minecraft:tuff_bricks"},
        {pos: [2, 1, 0], state: "minecraft:waxed_copper_block"},
        {pos: [2, 1, 7], state: "minecraft:waxed_copper_block"},
        {pos: [2, 1, 8], state: "minecraft:waxed_copper_block"},
        {pos: [2, 1, 9], state: "minecraft:waxed_copper_block"},
        {pos: [2, 1, 10], state: "minecraft:waxed_copper_block"},
        {pos: [2, 1, 11], state: "minecraft:waxed_copper_block"},
        {pos: [2, 1, 12], state: "minecraft:tuff_bricks"},
        {pos: [2, 1, 13], state: "minecraft:tuff_bricks"},
        {pos: [2, 1, 14], state: "minecraft:tuff_bricks"},
        {pos: [2, 1, 15], state: "minecraft:tuff_bricks"},
        {pos: [2, 1, 16], state: "minecraft:tuff_bricks"},
        {pos: [3, 1, 0], state: "minecraft:waxed_copper_block"},
        {pos: [3, 1, 7], state: "minecraft:waxed_copper_block"},
        {pos: [3, 1, 8], state: "minecraft:waxed_copper_block"},
        {pos: [3, 1, 9], state: "minecraft:waxed_copper_block"},
        {pos: [3, 1, 10], state: "minecraft:waxed_copper_block"},
        {pos: [3, 1, 11], state: "minecraft:waxed_copper_block"},
        {pos: [3, 1, 12], state: "minecraft:tuff_bricks"},
        {pos: [3, 1, 13], state: "minecraft:tuff_bricks"},
        {pos: [3, 1, 14], state: "minecraft:tuff_bricks"},
        {pos: [3, 1, 15], state: "minecraft:tuff_bricks"},
        {pos: [3, 1, 16], state: "minecraft:tuff_bricks"},
        {pos: [4, 1, 0], state: "minecraft:waxed_copper_block"},
        {pos: [4, 1, 7], state: "minecraft:waxed_copper_block"},
        {pos: [4, 1, 8], state: "minecraft:waxed_copper_block"},
        {pos: [4, 1, 9], state: "minecraft:waxed_copper_block"},
        {pos: [4, 1, 10], state: "minecraft:waxed_copper_block"},
        {pos: [4, 1, 11], state: "minecraft:waxed_copper_block"},
        {pos: [4, 1, 12], state: "minecraft:tuff_bricks"},
        {pos: [4, 1, 13], state: "minecraft:tuff_bricks"},
        {pos: [4, 1, 14], state: "minecraft:tuff_bricks"},
        {pos: [4, 1, 15], state: "minecraft:tuff_bricks"},
        {pos: [4, 1, 16], state: "minecraft:tuff_bricks"},
        {pos: [5, 1, 0], state: "minecraft:waxed_copper_block"},
        {pos: [5, 1, 1], state: "minecraft:waxed_copper_block"},
        {pos: [5, 1, 5], state: "minecraft:waxed_copper_block"},
        {pos: [5, 1, 6], state: "minecraft:waxed_copper_block"},
        {pos: [5, 1, 7], state: "minecraft:waxed_copper_block"},
        {pos: [5, 1, 8], state: "minecraft:waxed_copper_block"},
        {pos: [5, 1, 9], state: "minecraft:waxed_copper_block"},
        {pos: [5, 1, 10], state: "minecraft:waxed_copper_block"},
        {pos: [5, 1, 11], state: "minecraft:waxed_copper_block"},
        {pos: [5, 1, 12], state: "minecraft:waxed_copper_block"},
        {pos: [5, 1, 13], state: "minecraft:waxed_copper_block"},
        {pos: [5, 1, 14], state: "minecraft:waxed_copper_block"},
        {pos: [5, 1, 15], state: "minecraft:waxed_copper_block"},
        {pos: [5, 1, 16], state: "minecraft:tuff_bricks"},
        {pos: [6, 1, 0], state: "minecraft:waxed_copper_block"},
        {pos: [6, 1, 1], state: "minecraft:waxed_copper_block"},
        {pos: [6, 1, 5], state: "minecraft:waxed_copper_block"},
        {pos: [6, 1, 6], state: "minecraft:waxed_copper_block"},
        {pos: [6, 1, 10], state: "minecraft:waxed_copper_block"},
        {pos: [6, 1, 11], state: "minecraft:waxed_copper_block"},
        {pos: [6, 1, 15], state: "minecraft:waxed_copper_block"},
        {pos: [6, 1, 16], state: "minecraft:tuff_bricks"},
        {pos: [7, 1, 0], state: "minecraft:waxed_copper_block"},
        {pos: [7, 1, 15], state: "minecraft:waxed_copper_block"},
        {pos: [7, 1, 16], state: "minecraft:tuff_bricks"},
        {pos: [8, 1, 0], state: "minecraft:waxed_copper_block"},
        {pos: [8, 1, 15], state: "minecraft:waxed_copper_block"},
        {pos: [8, 1, 16], state: "minecraft:tuff_bricks"},
        {pos: [9, 1, 0], state: "minecraft:waxed_copper_block"},
        {pos: [9, 1, 15], state: "minecraft:waxed_copper_block"},
        {pos: [9, 1, 16], state: "minecraft:tuff_bricks"},
        {pos: [10, 1, 0], state: "minecraft:waxed_copper_block"},
        {pos: [10, 1, 1], state: "minecraft:waxed_copper_block"},
        {pos: [10, 1, 5], state: "minecraft:waxed_copper_block"},
        {pos: [10, 1, 6], state: "minecraft:waxed_copper_block"},
        {pos: [10, 1, 10], state: "minecraft:waxed_copper_block"},
        {pos: [10, 1, 11], state: "minecraft:waxed_copper_block"},
        {pos: [10, 1, 15], state: "minecraft:waxed_copper_block"},
        {pos: [10, 1, 16], state: "minecraft:tuff_bricks"},
        {pos: [11, 1, 0], state: "minecraft:waxed_copper_block"},
        {pos: [11, 1, 1], state: "minecraft:waxed_copper_block"},
        {pos: [11, 1, 2], state: "minecraft:waxed_copper_block"},
        {pos: [11, 1, 3], state: "minecraft:waxed_copper_block"},
        {pos: [11, 1, 4], state: "minecraft:waxed_copper_block"},
        {pos: [11, 1, 5], state: "minecraft:waxed_copper_block"},
        {pos: [11, 1, 6], state: "minecraft:waxed_copper_block"},
        {pos: [11, 1, 7], state: "minecraft:waxed_copper_block"},
        {pos: [11, 1, 8], state: "minecraft:waxed_copper_block"},
        {pos: [11, 1, 9], state: "minecraft:waxed_copper_block"},
        {pos: [11, 1, 10], state: "minecraft:waxed_copper_block"},
        {pos: [11, 1, 11], state: "minecraft:waxed_copper_block"},
        {pos: [11, 1, 15], state: "minecraft:waxed_copper_block"},
        {pos: [11, 1, 16], state: "minecraft:tuff_bricks"},
        {pos: [0, 2, 0], state: "minecraft:tuff_bricks"},
        {pos: [0, 2, 1], state: "minecraft:tuff_bricks"},
        {pos: [0, 2, 2], state: "minecraft:tuff_bricks"},
        {pos: [0, 2, 3], state: "minecraft:waxed_copper_bulb{powered:false,lit:true}"},
        {pos: [0, 2, 4], state: "minecraft:tuff_bricks"},
        {pos: [0, 2, 5], state: "minecraft:tuff_bricks"},
        {pos: [0, 2, 6], state: "minecraft:tuff_bricks"},
        {pos: [0, 2, 7], state: "minecraft:tuff_bricks"},
        {pos: [0, 2, 8], state: "minecraft:waxed_copper_bulb{powered:false,lit:true}"},
        {pos: [0, 2, 9], state: "minecraft:tuff_bricks"},
        {pos: [0, 2, 10], state: "minecraft:tuff_bricks"},
        {pos: [0, 2, 11], state: "minecraft:tuff_bricks"},
        {pos: [0, 2, 12], state: "minecraft:tuff_bricks"},
        {pos: [0, 2, 13], state: "minecraft:tuff_bricks"},
        {pos: [0, 2, 14], state: "minecraft:tuff_bricks"},
        {pos: [0, 2, 15], state: "minecraft:tuff_bricks"},
        {pos: [0, 2, 16], state: "minecraft:tuff_bricks"},
        {pos: [1, 2, 0], state: "minecraft:tuff_bricks"},
        {pos: [1, 2, 1], state: "minecraft:tuff_bricks"},
        {pos: [1, 2, 5], state: "minecraft:tuff_bricks"},
        {pos: [1, 2, 6], state: "minecraft:tuff_bricks"},
        {pos: [1, 2, 10], state: "minecraft:tuff_bricks"},
        {pos: [1, 2, 11], state: "minecraft:tuff_bricks"},
        {pos: [1, 2, 12], state: "minecraft:tuff_bricks"},
        {pos: [1, 2, 13], state: "minecraft:tuff_bricks"},
        {pos: [1, 2, 14], state: "minecraft:tuff_bricks"},
        {pos: [1, 2, 15], state: "minecraft:tuff_bricks"},
        {pos: [1, 2, 16], state: "minecraft:tuff_bricks"},
        {pos: [2, 2, 0], state: "minecraft:tuff_bricks"},
        {pos: [2, 2, 8], state: "minecraft:waxed_oxidized_copper"},
        {pos: [2, 2, 9], state: "minecraft:tuff_bricks"},
        {pos: [2, 2, 10], state: "minecraft:tuff_bricks"},
        {pos: [2, 2, 11], state: "minecraft:tuff_bricks"},
        {pos: [2, 2, 12], state: "minecraft:tuff_bricks"},
        {pos: [2, 2, 13], state: "minecraft:tuff_bricks"},
        {pos: [2, 2, 14], state: "minecraft:tuff_bricks"},
        {pos: [2, 2, 15], state: "minecraft:tuff_bricks"},
        {pos: [2, 2, 16], state: "minecraft:tuff_bricks"},
        {pos: [3, 2, 0], state: "minecraft:waxed_copper_bulb{powered:false,lit:true}"},
        {pos: [3, 2, 8], state: "minecraft:waxed_oxidized_copper"},
        {pos: [3, 2, 9], state: "minecraft:tuff_bricks"},
        {pos: [3, 2, 10], state: "minecraft:tuff_bricks"},
        {pos: [3, 2, 11], state: "minecraft:tuff_bricks"},
        {pos: [3, 2, 12], state: "minecraft:tuff_bricks"},
        {pos: [3, 2, 13], state: "minecraft:tuff_bricks"},
        {pos: [3, 2, 14], state: "minecraft:tuff_bricks"},
        {pos: [3, 2, 15], state: "minecraft:tuff_bricks"},
        {pos: [3, 2, 16], state: "minecraft:tuff_bricks"},
        {pos: [4, 2, 0], state: "minecraft:tuff_bricks"},
        {pos: [4, 2, 8], state: "minecraft:waxed_oxidized_copper"},
        {pos: [4, 2, 9], state: "minecraft:tuff_bricks"},
        {pos: [4, 2, 10], state: "minecraft:tuff_bricks"},
        {pos: [4, 2, 11], state: "minecraft:tuff_bricks"},
        {pos: [4, 2, 12], state: "minecraft:tuff_bricks"},
        {pos: [4, 2, 13], state: "minecraft:tuff_bricks"},
        {pos: [4, 2, 14], state: "minecraft:tuff_bricks"},
        {pos: [4, 2, 15], state: "minecraft:tuff_bricks"},
        {pos: [4, 2, 16], state: "minecraft:tuff_bricks"},
        {pos: [5, 2, 0], state: "minecraft:tuff_bricks"},
        {pos: [5, 2, 1], state: "minecraft:tuff_bricks"},
        {pos: [5, 2, 5], state: "minecraft:tuff_bricks"},
        {pos: [5, 2, 6], state: "minecraft:tuff_bricks"},
        {pos: [5, 2, 7], state: "minecraft:tuff_bricks"},
        {pos: [5, 2, 8], state: "minecraft:waxed_copper_bulb{powered:false,lit:true}"},
        {pos: [5, 2, 9], state: "minecraft:tuff_bricks"},
        {pos: [5, 2, 10], state: "minecraft:tuff_bricks"},
        {pos: [5, 2, 11], state: "minecraft:tuff_bricks"},
        {pos: [5, 2, 12], state: "minecraft:tuff_bricks"},
        {pos: [5, 2, 13], state: "minecraft:waxed_copper_bulb{powered:false,lit:true}"},
        {pos: [5, 2, 14], state: "minecraft:tuff_bricks"},
        {pos: [5, 2, 15], state: "minecraft:tuff_bricks"},
        {pos: [5, 2, 16], state: "minecraft:tuff_bricks"},
        {pos: [6, 2, 0], state: "minecraft:tuff_bricks"},
        {pos: [6, 2, 1], state: "minecraft:tuff_bricks"},
        {pos: [6, 2, 5], state: "minecraft:tuff_bricks"},
        {pos: [6, 2, 6], state: "minecraft:tuff_bricks"},
        {pos: [6, 2, 10], state: "minecraft:tuff_bricks"},
        {pos: [6, 2, 11], state: "minecraft:tuff_bricks"},
        {pos: [6, 2, 15], state: "minecraft:tuff_bricks"},
        {pos: [6, 2, 16], state: "minecraft:tuff_bricks"},
        {pos: [7, 2, 0], state: "minecraft:tuff_bricks"},
        {pos: [7, 2, 15], state: "minecraft:waxed_copper_bulb{powered:false,lit:true}"},
        {pos: [7, 2, 16], state: "minecraft:tuff_bricks"},
        {pos: [8, 2, 0], state: "minecraft:waxed_copper_bulb{powered:false,lit:true}"},
        {pos: [8, 2, 15], state: "minecraft:tuff_bricks"},
        {pos: [8, 2, 16], state: "minecraft:tuff_bricks"},
        {pos: [9, 2, 0], state: "minecraft:tuff_bricks"},
        {pos: [9, 2, 15], state: "minecraft:tuff_bricks"},
        {pos: [9, 2, 16], state: "minecraft:tuff_bricks"},
        {pos: [10, 2, 0], state: "minecraft:tuff_bricks"},
        {pos: [10, 2, 1], state: "minecraft:tuff_bricks"},
        {pos: [10, 2, 5], state: "minecraft:tuff_bricks"},
        {pos: [10, 2, 6], state: "minecraft:tuff_bricks"},
        {pos: [10, 2, 10], state: "minecraft:tuff_bricks"},
        {pos: [10, 2, 11], state: "minecraft:tuff_bricks"},
        {pos: [10, 2, 15], state: "minecraft:tuff_bricks"},
        {pos: [10, 2, 16], state: "minecraft:tuff_bricks"},
        {pos: [11, 2, 0], state: "minecraft:tuff_bricks"},
        {pos: [11, 2, 1], state: "minecraft:tuff_bricks"},
        {pos: [11, 2, 2], state: "minecraft:tuff_bricks"},
        {pos: [11, 2, 3], state: "minecraft:waxed_copper_bulb{powered:false,lit:true}"},
        {pos: [11, 2, 4], state: "minecraft:tuff_bricks"},
        {pos: [11, 2, 5], state: "minecraft:tuff_bricks"},
        {pos: [11, 2, 6], state: "minecraft:tuff_bricks"},
        {pos: [11, 2, 7], state: "minecraft:tuff_bricks"},
        {pos: [11, 2, 8], state: "minecraft:waxed_copper_bulb{powered:false,lit:true}"},
        {pos: [11, 2, 9], state: "minecraft:tuff_bricks"},
        {pos: [11, 2, 10], state: "minecraft:tuff_bricks"},
        {pos: [11, 2, 11], state: "minecraft:tuff_bricks"},
        {pos: [11, 2, 15], state: "minecraft:tuff_bricks"},
        {pos: [11, 2, 16], state: "minecraft:tuff_bricks"},
        {pos: [0, 3, 0], state: "minecraft:chiseled_tuff_bricks"},
        {pos: [0, 3, 1], state: "minecraft:chiseled_tuff_bricks"},
        {pos: [0, 3, 2], state: "minecraft:chiseled_tuff_bricks"},
        {pos: [0, 3, 3], state: "minecraft:chiseled_tuff_bricks"},
        {pos: [0, 3, 4], state: "minecraft:chiseled_tuff_bricks"},
        {pos: [0, 3, 5], state: "minecraft:chiseled_tuff_bricks"},
        {pos: [0, 3, 6], state: "minecraft:chiseled_tuff_bricks"},
        {pos: [0, 3, 7], state: "minecraft:chiseled_tuff_bricks"},
        {pos: [0, 3, 8], state: "minecraft:chiseled_tuff_bricks"},
        {pos: [0, 3, 9], state: "minecraft:chiseled_tuff_bricks"},
        {pos: [0, 3, 10], state: "minecraft:chiseled_tuff_bricks"},
        {pos: [0, 3, 11], state: "minecraft:chiseled_tuff_bricks"},
        {pos: [0, 3, 12], state: "minecraft:tuff_bricks"},
        {pos: [0, 3, 13], state: "minecraft:tuff_bricks"},
        {pos: [0, 3, 14], state: "minecraft:tuff_bricks"},
        {pos: [0, 3, 15], state: "minecraft:tuff_bricks"},
        {pos: [0, 3, 16], state: "minecraft:tuff_bricks"},
        {pos: [1, 3, 0], state: "minecraft:chiseled_tuff_bricks"},
        {pos: [1, 3, 1], state: "minecraft:chiseled_tuff_bricks"},
        {pos: [1, 3, 5], state: "minecraft:chiseled_tuff_bricks"},
        {pos: [1, 3, 6], state: "minecraft:chiseled_tuff_bricks"},
        {pos: [1, 3, 10], state: "minecraft:chiseled_tuff_bricks"},
        {pos: [1, 3, 11], state: "minecraft:chiseled_tuff_bricks"},
        {pos: [1, 3, 12], state: "minecraft:tuff_bricks"},
        {pos: [1, 3, 13], state: "minecraft:tuff_bricks"},
        {pos: [1, 3, 14], state: "minecraft:tuff_bricks"},
        {pos: [1, 3, 15], state: "minecraft:tuff_bricks"},
        {pos: [1, 3, 16], state: "minecraft:tuff_bricks"},
        {pos: [2, 3, 0], state: "minecraft:chiseled_tuff_bricks"},
        {pos: [2, 3, 9], state: "minecraft:chiseled_tuff_bricks"},
        {pos: [2, 3, 10], state: "minecraft:chiseled_tuff_bricks"},
        {pos: [2, 3, 11], state: "minecraft:chiseled_tuff_bricks"},
        {pos: [2, 3, 12], state: "minecraft:tuff_bricks"},
        {pos: [2, 3, 13], state: "minecraft:tuff_bricks"},
        {pos: [2, 3, 14], state: "minecraft:tuff_bricks"},
        {pos: [2, 3, 15], state: "minecraft:tuff_bricks"},
        {pos: [2, 3, 16], state: "minecraft:tuff_bricks"},
        {pos: [3, 3, 0], state: "minecraft:chiseled_tuff_bricks"},
        {pos: [3, 3, 9], state: "minecraft:chiseled_tuff_bricks"},
        {pos: [3, 3, 10], state: "minecraft:chiseled_tuff_bricks"},
        {pos: [3, 3, 11], state: "minecraft:chiseled_tuff_bricks"},
        {pos: [3, 3, 12], state: "minecraft:tuff_bricks"},
        {pos: [3, 3, 13], state: "minecraft:tuff_bricks"},
        {pos: [3, 3, 14], state: "minecraft:tuff_bricks"},
        {pos: [3, 3, 15], state: "minecraft:tuff_bricks"},
        {pos: [3, 3, 16], state: "minecraft:tuff_bricks"},
        {pos: [4, 3, 0], state: "minecraft:chiseled_tuff_bricks"},
        {pos: [4, 3, 9], state: "minecraft:chiseled_tuff_bricks"},
        {pos: [4, 3, 10], state: "minecraft:chiseled_tuff_bricks"},
        {pos: [4, 3, 11], state: "minecraft:chiseled_tuff_bricks"},
        {pos: [4, 3, 12], state: "minecraft:tuff_bricks"},
        {pos: [4, 3, 13], state: "minecraft:tuff_bricks"},
        {pos: [4, 3, 14], state: "minecraft:tuff_bricks"},
        {pos: [4, 3, 15], state: "minecraft:tuff_bricks"},
        {pos: [4, 3, 16], state: "minecraft:tuff_bricks"},
        {pos: [5, 3, 0], state: "minecraft:chiseled_tuff_bricks"},
        {pos: [5, 3, 1], state: "minecraft:chiseled_tuff_bricks"},
        {pos: [5, 3, 5], state: "minecraft:chiseled_tuff_bricks"},
        {pos: [5, 3, 6], state: "minecraft:chiseled_tuff_bricks"},
        {pos: [5, 3, 7], state: "minecraft:chiseled_tuff_bricks"},
        {pos: [5, 3, 8], state: "minecraft:chiseled_tuff_bricks"},
        {pos: [5, 3, 9], state: "minecraft:chiseled_tuff_bricks"},
        {pos: [5, 3, 10], state: "minecraft:chiseled_tuff_bricks"},
        {pos: [5, 3, 11], state: "minecraft:chiseled_tuff_bricks"},
        {pos: [5, 3, 12], state: "minecraft:chiseled_tuff_bricks"},
        {pos: [5, 3, 13], state: "minecraft:chiseled_tuff_bricks"},
        {pos: [5, 3, 14], state: "minecraft:chiseled_tuff_bricks"},
        {pos: [5, 3, 15], state: "minecraft:chiseled_tuff_bricks"},
        {pos: [5, 3, 16], state: "minecraft:tuff_bricks"},
        {pos: [6, 3, 0], state: "minecraft:chiseled_tuff_bricks"},
        {pos: [6, 3, 1], state: "minecraft:chiseled_tuff_bricks"},
        {pos: [6, 3, 5], state: "minecraft:chiseled_tuff_bricks"},
        {pos: [6, 3, 6], state: "minecraft:chiseled_tuff_bricks"},
        {pos: [6, 3, 10], state: "minecraft:chiseled_tuff_bricks"},
        {pos: [6, 3, 11], state: "minecraft:chiseled_tuff_bricks"},
        {pos: [6, 3, 15], state: "minecraft:chiseled_tuff_bricks"},
        {pos: [6, 3, 16], state: "minecraft:tuff_bricks"},
        {pos: [7, 3, 0], state: "minecraft:chiseled_tuff_bricks"},
        {pos: [7, 3, 15], state: "minecraft:chiseled_tuff_bricks"},
        {pos: [7, 3, 16], state: "minecraft:tuff_bricks"},
        {pos: [8, 3, 0], state: "minecraft:chiseled_tuff_bricks"},
        {pos: [8, 3, 15], state: "minecraft:chiseled_tuff_bricks"},
        {pos: [8, 3, 16], state: "minecraft:tuff_bricks"},
        {pos: [9, 3, 0], state: "minecraft:chiseled_tuff_bricks"},
        {pos: [9, 3, 15], state: "minecraft:chiseled_tuff_bricks"},
        {pos: [9, 3, 16], state: "minecraft:tuff_bricks"},
        {pos: [10, 3, 0], state: "minecraft:chiseled_tuff_bricks"},
        {pos: [10, 3, 1], state: "minecraft:chiseled_tuff_bricks"},
        {pos: [10, 3, 5], state: "minecraft:chiseled_tuff_bricks"},
        {pos: [10, 3, 6], state: "minecraft:chiseled_tuff_bricks"},
        {pos: [10, 3, 10], state: "minecraft:chiseled_tuff_bricks"},
        {pos: [10, 3, 11], state: "minecraft:chiseled_tuff_bricks"},
        {pos: [10, 3, 15], state: "minecraft:chiseled_tuff_bricks"},
        {pos: [10, 3, 16], state: "minecraft:tuff_bricks"},
        {pos: [11, 3, 0], state: "minecraft:tuff_bricks"},
        {pos: [11, 3, 1], state: "minecraft:tuff_bricks"},
        {pos: [11, 3, 2], state: "minecraft:chiseled_tuff_bricks"},
        {pos: [11, 3, 3], state: "minecraft:chiseled_tuff_bricks"},
        {pos: [11, 3, 4], state: "minecraft:chiseled_tuff_bricks"},
        {pos: [11, 3, 5], state: "minecraft:chiseled_tuff_bricks"},
        {pos: [11, 3, 6], state: "minecraft:chiseled_tuff_bricks"},
        {pos: [11, 3, 7], state: "minecraft:chiseled_tuff_bricks"},
        {pos: [11, 3, 8], state: "minecraft:chiseled_tuff_bricks"},
        {pos: [11, 3, 9], state: "minecraft:chiseled_tuff_bricks"},
        {pos: [11, 3, 10], state: "minecraft:chiseled_tuff_bricks"},
        {pos: [11, 3, 11], state: "minecraft:chiseled_tuff_bricks"},
        {pos: [11, 3, 15], state: "minecraft:chiseled_tuff_bricks"},
        {pos: [11, 3, 16], state: "minecraft:tuff_bricks"},
        {pos: [0, 4, 0], state: "minecraft:tuff_bricks"},
        {pos: [0, 4, 1], state: "minecraft:tuff_bricks"},
        {pos: [0, 4, 2], state: "minecraft:tuff_bricks"},
        {pos: [0, 4, 3], state: "minecraft:tuff_bricks"},
        {pos: [0, 4, 4], state: "minecraft:tuff_bricks"},
        {pos: [0, 4, 5], state: "minecraft:tuff_bricks"},
        {pos: [0, 4, 6], state: "minecraft:tuff_bricks"},
        {pos: [0, 4, 7], state: "minecraft:tuff_bricks"},
        {pos: [0, 4, 8], state: "minecraft:tuff_bricks"},
        {pos: [0, 4, 9], state: "minecraft:tuff_bricks"},
        {pos: [0, 4, 10], state: "minecraft:tuff_bricks"},
        {pos: [0, 4, 11], state: "minecraft:tuff_bricks"},
        {pos: [0, 4, 12], state: "minecraft:tuff_bricks"},
        {pos: [0, 4, 13], state: "minecraft:tuff_bricks"},
        {pos: [0, 4, 14], state: "minecraft:tuff_bricks"},
        {pos: [0, 4, 15], state: "minecraft:tuff_bricks"},
        {pos: [0, 4, 16], state: "minecraft:tuff_bricks"},
        {pos: [1, 4, 0], state: "minecraft:tuff_bricks"},
        {pos: [1, 4, 1], state: "minecraft:tuff_bricks"},
        {pos: [1, 4, 5], state: "minecraft:tuff_bricks"},
        {pos: [1, 4, 6], state: "minecraft:tuff_bricks"},
        {pos: [1, 4, 10], state: "minecraft:tuff_bricks"},
        {pos: [1, 4, 11], state: "minecraft:tuff_bricks"},
        {pos: [1, 4, 12], state: "minecraft:tuff_bricks"},
        {pos: [1, 4, 13], state: "minecraft:tuff_bricks"},
        {pos: [1, 4, 14], state: "minecraft:tuff_bricks"},
        {pos: [1, 4, 15], state: "minecraft:tuff_bricks"},
        {pos: [1, 4, 16], state: "minecraft:tuff_bricks"},
        {pos: [2, 4, 0], state: "minecraft:tuff_bricks"},
        {pos: [2, 4, 10], state: "minecraft:waxed_oxidized_copper"},
        {pos: [2, 4, 11], state: "minecraft:tuff_bricks"},
        {pos: [2, 4, 12], state: "minecraft:tuff_bricks"},
        {pos: [2, 4, 13], state: "minecraft:tuff_bricks"},
        {pos: [2, 4, 14], state: "minecraft:tuff_bricks"},
        {pos: [2, 4, 15], state: "minecraft:tuff_bricks"},
        {pos: [2, 4, 16], state: "minecraft:tuff_bricks"},
        {pos: [3, 4, 0], state: "minecraft:tuff_bricks"},
        {pos: [3, 4, 10], state: "minecraft:waxed_oxidized_copper"},
        {pos: [3, 4, 11], state: "minecraft:tuff_bricks"},
        {pos: [3, 4, 12], state: "minecraft:tuff_bricks"},
        {pos: [3, 4, 13], state: "minecraft:tuff_bricks"},
        {pos: [3, 4, 14], state: "minecraft:tuff_bricks"},
        {pos: [3, 4, 15], state: "minecraft:tuff_bricks"},
        {pos: [3, 4, 16], state: "minecraft:tuff_bricks"},
        {pos: [4, 4, 0], state: "minecraft:tuff_bricks"},
        {pos: [4, 4, 10], state: "minecraft:waxed_oxidized_copper"},
        {pos: [4, 4, 11], state: "minecraft:tuff_bricks"},
        {pos: [4, 4, 12], state: "minecraft:tuff_bricks"},
        {pos: [4, 4, 13], state: "minecraft:tuff_bricks"},
        {pos: [4, 4, 14], state: "minecraft:tuff_bricks"},
        {pos: [4, 4, 15], state: "minecraft:tuff_bricks"},
        {pos: [4, 4, 16], state: "minecraft:tuff_bricks"},
        {pos: [5, 4, 0], state: "minecraft:tuff_bricks"},
        {pos: [5, 4, 1], state: "minecraft:tuff_bricks"},
        {pos: [5, 4, 5], state: "minecraft:tuff_bricks"},
        {pos: [5, 4, 6], state: "minecraft:tuff_bricks"},
        {pos: [5, 4, 7], state: "minecraft:waxed_copper_block"},
        {pos: [5, 4, 8], state: "minecraft:waxed_copper_block"},
        {pos: [5, 4, 9], state: "minecraft:waxed_copper_block"},
        {pos: [5, 4, 10], state: "minecraft:waxed_oxidized_copper"},
        {pos: [5, 4, 11], state: "minecraft:waxed_copper_block"},
        {pos: [5, 4, 12], state: "minecraft:tuff_bricks"},
        {pos: [5, 4, 13], state: "minecraft:tuff_bricks"},
        {pos: [5, 4, 14], state: "minecraft:tuff_bricks"},
        {pos: [5, 4, 15], state: "minecraft:tuff_bricks"},
        {pos: [5, 4, 16], state: "minecraft:tuff_bricks"},
        {pos: [6, 4, 0], state: "minecraft:tuff_bricks"},
        {pos: [6, 4, 1], state: "minecraft:tuff_bricks"},
        {pos: [6, 4, 5], state: "minecraft:tuff_bricks"},
        {pos: [6, 4, 6], state: "minecraft:tuff_bricks"},
        {pos: [6, 4, 7], state: "minecraft:polished_tuff"},
        {pos: [6, 4, 8], state: "minecraft:polished_tuff"},
        {pos: [6, 4, 9], state: "minecraft:polished_tuff"},
        {pos: [6, 4, 10], state: "minecraft:polished_tuff"},
        {pos: [6, 4, 11], state: "minecraft:tuff_bricks"},
        {pos: [6, 4, 12], state: "minecraft:polished_tuff"},
        {pos: [6, 4, 13], state: "minecraft:polished_tuff"},
        {pos: [6, 4, 14], state: "minecraft:polished_tuff"},
        {pos: [6, 4, 15], state: "minecraft:tuff_bricks"},
        {pos: [6, 4, 16], state: "minecraft:tuff_bricks"},
        {pos: [7, 4, 0], state: "minecraft:tuff_bricks"},
        {pos: [7, 4, 6], state: "minecraft:polished_tuff"},
        {pos: [7, 4, 7], state: "minecraft:polished_tuff"},
        {pos: [7, 4, 8], state: "minecraft:polished_tuff"},
        {pos: [7, 4, 9], state: "minecraft:polished_tuff"},
        {pos: [7, 4, 10], state: "minecraft:polished_tuff"},
        {pos: [7, 4, 11], state: "minecraft:polished_tuff"},
        {pos: [7, 4, 12], state: "minecraft:polished_tuff"},
        {pos: [7, 4, 13], state: "minecraft:polished_tuff"},
        {pos: [7, 4, 14], state: "minecraft:polished_tuff"},
        {pos: [7, 4, 15], state: "minecraft:tuff_bricks"},
        {pos: [7, 4, 16], state: "minecraft:tuff_bricks"},
        {pos: [8, 4, 0], state: "minecraft:tuff_bricks"},
        {pos: [8, 4, 6], state: "minecraft:polished_tuff"},
        {pos: [8, 4, 7], state: "minecraft:polished_tuff"},
        {pos: [8, 4, 8], state: "minecraft:polished_tuff"},
        {pos: [8, 4, 9], state: "minecraft:polished_tuff"},
        {pos: [8, 4, 10], state: "minecraft:polished_tuff"},
        {pos: [8, 4, 11], state: "minecraft:polished_tuff"},
        {pos: [8, 4, 12], state: "minecraft:polished_tuff"},
        {pos: [8, 4, 13], state: "minecraft:polished_tuff"},
        {pos: [8, 4, 14], state: "minecraft:polished_tuff"},
        {pos: [8, 4, 15], state: "minecraft:tuff_bricks"},
        {pos: [8, 4, 16], state: "minecraft:tuff_bricks"},
        {pos: [9, 4, 0], state: "minecraft:tuff_bricks"},
        {pos: [9, 4, 6], state: "minecraft:polished_tuff"},
        {pos: [9, 4, 7], state: "minecraft:polished_tuff"},
        {pos: [9, 4, 8], state: "minecraft:polished_tuff"},
        {pos: [9, 4, 9], state: "minecraft:polished_tuff"},
        {pos: [9, 4, 10], state: "minecraft:polished_tuff"},
        {pos: [9, 4, 11], state: "minecraft:polished_tuff"},
        {pos: [9, 4, 12], state: "minecraft:polished_tuff"},
        {pos: [9, 4, 13], state: "minecraft:polished_tuff"},
        {pos: [9, 4, 14], state: "minecraft:polished_tuff"},
        {pos: [9, 4, 15], state: "minecraft:tuff_bricks"},
        {pos: [9, 4, 16], state: "minecraft:tuff_bricks"},
        {pos: [10, 4, 0], state: "minecraft:tuff_bricks"},
        {pos: [10, 4, 1], state: "minecraft:tuff_bricks"},
        {pos: [10, 4, 5], state: "minecraft:tuff_bricks"},
        {pos: [10, 4, 6], state: "minecraft:tuff_bricks"},
        {pos: [10, 4, 7], state: "minecraft:polished_tuff"},
        {pos: [10, 4, 8], state: "minecraft:polished_tuff"},
        {pos: [10, 4, 9], state: "minecraft:polished_tuff"},
        {pos: [10, 4, 10], state: "minecraft:tuff_bricks"},
        {pos: [10, 4, 11], state: "minecraft:tuff_bricks"},
        {pos: [10, 4, 12], state: "minecraft:polished_tuff"},
        {pos: [10, 4, 13], state: "minecraft:polished_tuff"},
        {pos: [10, 4, 14], state: "minecraft:polished_tuff"},
        {pos: [10, 4, 15], state: "minecraft:tuff_bricks"},
        {pos: [10, 4, 16], state: "minecraft:tuff_bricks"},
        {pos: [11, 4, 0], state: "minecraft:tuff_bricks"},
        {pos: [11, 4, 1], state: "minecraft:tuff_bricks"},
        {pos: [11, 4, 2], state: "minecraft:tuff_bricks"},
        {pos: [11, 4, 3], state: "minecraft:tuff_bricks"},
        {pos: [11, 4, 4], state: "minecraft:tuff_bricks"},
        {pos: [11, 4, 5], state: "minecraft:tuff_bricks"},
        {pos: [11, 4, 6], state: "minecraft:tuff_bricks"},
        {pos: [11, 4, 7], state: "minecraft:tuff_bricks"},
        {pos: [11, 4, 8], state: "minecraft:tuff_bricks"},
        {pos: [11, 4, 9], state: "minecraft:tuff_bricks"},
        {pos: [11, 4, 10], state: "minecraft:tuff_bricks"},
        {pos: [11, 4, 11], state: "minecraft:tuff_bricks"},
        {pos: [11, 4, 12], state: "minecraft:polished_tuff"},
        {pos: [11, 4, 13], state: "minecraft:polished_tuff"},
        {pos: [11, 4, 14], state: "minecraft:polished_tuff"},
        {pos: [11, 4, 15], state: "minecraft:tuff_bricks"},
        {pos: [11, 4, 16], state: "minecraft:tuff_bricks"},
        {pos: [0, 5, 0], state: "minecraft:tuff_bricks"},
        {pos: [0, 5, 1], state: "minecraft:tuff_bricks"},
        {pos: [0, 5, 2], state: "minecraft:tuff_bricks"},
        {pos: [0, 5, 3], state: "minecraft:tuff_bricks"},
        {pos: [0, 5, 4], state: "minecraft:tuff_bricks"},
        {pos: [0, 5, 5], state: "minecraft:tuff_bricks"},
        {pos: [0, 5, 6], state: "minecraft:tuff_bricks"},
        {pos: [0, 5, 7], state: "minecraft:tuff_bricks"},
        {pos: [0, 5, 8], state: "minecraft:tuff_bricks"},
        {pos: [0, 5, 9], state: "minecraft:tuff_bricks"},
        {pos: [0, 5, 10], state: "minecraft:tuff_bricks"},
        {pos: [0, 5, 11], state: "minecraft:tuff_bricks"},
        {pos: [0, 5, 12], state: "minecraft:waxed_oxidized_copper"},
        {pos: [0, 5, 13], state: "minecraft:waxed_oxidized_copper"},
        {pos: [0, 5, 14], state: "minecraft:waxed_oxidized_copper"},
        {pos: [0, 5, 15], state: "minecraft:tuff_bricks"},
        {pos: [0, 5, 16], state: "minecraft:tuff_bricks"},
        {pos: [1, 5, 0], state: "minecraft:tuff_bricks"},
        {pos: [1, 5, 1], state: "minecraft:tuff_bricks"},
        {pos: [1, 5, 5], state: "minecraft:tuff_bricks"},
        {pos: [1, 5, 6], state: "minecraft:tuff_bricks"},
        {pos: [1, 5, 10], state: "minecraft:tuff_bricks"},
        {pos: [1, 5, 11], state: "minecraft:tuff_bricks"},
        {pos: [1, 5, 12], state: "minecraft:waxed_oxidized_copper"},
        {pos: [1, 5, 13], state: "minecraft:waxed_oxidized_copper"},
        {pos: [1, 5, 14], state: "minecraft:waxed_oxidized_copper"},
        {pos: [1, 5, 15], state: "minecraft:waxed_oxidized_copper"},
        {pos: [1, 5, 16], state: "minecraft:tuff_bricks"},
        {pos: [2, 5, 0], state: "minecraft:tuff_bricks"},
        {pos: [2, 5, 11], state: "minecraft:waxed_oxidized_copper"},
        {pos: [2, 5, 12], state: "minecraft:waxed_oxidized_copper"},
        {pos: [2, 5, 13], state: "minecraft:waxed_oxidized_copper"},
        {pos: [2, 5, 14], state: "minecraft:waxed_oxidized_copper"},
        {pos: [2, 5, 15], state: "minecraft:waxed_oxidized_cut_copper"},
        {pos: [2, 5, 16], state: "minecraft:tuff_bricks"},
        {pos: [3, 5, 0], state: "minecraft:tuff_bricks"},
        {pos: [3, 5, 11], state: "minecraft:waxed_oxidized_copper"},
        {pos: [3, 5, 12], state: "minecraft:waxed_oxidized_copper"},
        {pos: [3, 5, 13], state: "minecraft:waxed_oxidized_copper"},
        {pos: [3, 5, 14], state: "minecraft:waxed_oxidized_copper"},
        {pos: [3, 5, 15], state: "minecraft:waxed_oxidized_cut_copper"},
        {pos: [3, 5, 16], state: "minecraft:tuff_bricks"},
        {pos: [4, 5, 0], state: "minecraft:tuff_bricks"},
        {pos: [4, 5, 11], state: "minecraft:waxed_oxidized_copper"},
        {pos: [4, 5, 12], state: "minecraft:waxed_oxidized_copper"},
        {pos: [4, 5, 13], state: "minecraft:waxed_oxidized_copper"},
        {pos: [4, 5, 14], state: "minecraft:waxed_oxidized_copper"},
        {pos: [4, 5, 15], state: "minecraft:waxed_oxidized_cut_copper"},
        {pos: [4, 5, 16], state: "minecraft:tuff_bricks"},
        {pos: [5, 5, 0], state: "minecraft:tuff_bricks"},
        {pos: [5, 5, 1], state: "minecraft:tuff_bricks"},
        {pos: [5, 5, 5], state: "minecraft:tuff_bricks"},
        {pos: [5, 5, 6], state: "minecraft:tuff_bricks"},
        {pos: [5, 5, 7], state: "minecraft:waxed_copper_block"},
        {pos: [5, 5, 8], state: "minecraft:waxed_copper_block"},
        {pos: [5, 5, 9], state: "minecraft:waxed_copper_block"},
        {pos: [5, 5, 10], state: "minecraft:waxed_copper_block"},
        {pos: [5, 5, 11], state: "minecraft:waxed_oxidized_copper"},
        {pos: [5, 5, 12], state: "minecraft:waxed_oxidized_copper"},
        {pos: [5, 5, 13], state: "minecraft:waxed_oxidized_copper"},
        {pos: [5, 5, 14], state: "minecraft:waxed_oxidized_copper"},
        {pos: [5, 5, 15], state: "minecraft:tuff_bricks"},
        {pos: [5, 5, 16], state: "minecraft:tuff_bricks"},
        {pos: [6, 5, 0], state: "minecraft:tuff_bricks"},
        {pos: [6, 5, 1], state: "minecraft:tuff_bricks"},
        {pos: [6, 5, 5], state: "minecraft:tuff_bricks"},
        {pos: [6, 5, 6], state: "minecraft:tuff_bricks"},
        {pos: [6, 5, 7], state: "minecraft:waxed_oxidized_copper"},
        {pos: [6, 5, 8], state: "minecraft:waxed_oxidized_copper"},
        {pos: [6, 5, 9], state: "minecraft:waxed_oxidized_copper"},
        {pos: [6, 5, 10], state: "minecraft:waxed_oxidized_copper"},
        {pos: [6, 5, 11], state: "minecraft:waxed_oxidized_copper"},
        {pos: [6, 5, 12], state: "minecraft:waxed_oxidized_copper"},
        {pos: [6, 5, 13], state: "minecraft:waxed_oxidized_copper"},
        {pos: [6, 5, 14], state: "minecraft:waxed_oxidized_copper"},
        {pos: [6, 5, 15], state: "minecraft:waxed_oxidized_copper"},
        {pos: [6, 5, 16], state: "minecraft:tuff_bricks"},
        {pos: [7, 5, 0], state: "minecraft:tuff_bricks"},
        {pos: [7, 5, 6], state: "minecraft:waxed_copper_block"},
        {pos: [7, 5, 7], state: "minecraft:waxed_oxidized_copper"},
        {pos: [7, 5, 8], state: "minecraft:waxed_oxidized_copper"},
        {pos: [7, 5, 9], state: "minecraft:waxed_oxidized_copper"},
        {pos: [7, 5, 10], state: "minecraft:waxed_oxidized_copper"},
        {pos: [7, 5, 11], state: "minecraft:waxed_oxidized_copper"},
        {pos: [7, 5, 12], state: "minecraft:waxed_oxidized_copper"},
        {pos: [7, 5, 13], state: "minecraft:waxed_oxidized_copper"},
        {pos: [7, 5, 14], state: "minecraft:waxed_oxidized_copper"},
        {pos: [7, 5, 15], state: "minecraft:waxed_oxidized_cut_copper"},
        {pos: [7, 5, 16], state: "minecraft:tuff_bricks"},
        {pos: [8, 5, 0], state: "minecraft:tuff_bricks"},
        {pos: [8, 5, 6], state: "minecraft:waxed_copper_block"},
        {pos: [8, 5, 7], state: "minecraft:waxed_oxidized_copper"},
        {pos: [8, 5, 8], state: "minecraft:waxed_oxidized_copper"},
        {pos: [8, 5, 9], state: "minecraft:waxed_oxidized_copper"},
        {pos: [8, 5, 10], state: "minecraft:waxed_oxidized_copper"},
        {pos: [8, 5, 11], state: "minecraft:waxed_oxidized_copper"},
        {pos: [8, 5, 12], state: "minecraft:waxed_oxidized_copper"},
        {pos: [8, 5, 13], state: "minecraft:waxed_oxidized_copper"},
        {pos: [8, 5, 14], state: "minecraft:waxed_oxidized_copper"},
        {pos: [8, 5, 15], state: "minecraft:waxed_oxidized_cut_copper"},
        {pos: [8, 5, 16], state: "minecraft:tuff_bricks"},
        {pos: [9, 5, 0], state: "minecraft:tuff_bricks"},
        {pos: [9, 5, 6], state: "minecraft:waxed_copper_block"},
        {pos: [9, 5, 7], state: "minecraft:waxed_oxidized_copper"},
        {pos: [9, 5, 8], state: "minecraft:waxed_oxidized_copper"},
        {pos: [9, 5, 9], state: "minecraft:waxed_oxidized_copper"},
        {pos: [9, 5, 10], state: "minecraft:waxed_oxidized_copper"},
        {pos: [9, 5, 11], state: "minecraft:waxed_oxidized_copper"},
        {pos: [9, 5, 12], state: "minecraft:waxed_oxidized_copper"},
        {pos: [9, 5, 13], state: "minecraft:waxed_oxidized_copper"},
        {pos: [9, 5, 14], state: "minecraft:waxed_oxidized_copper"},
        {pos: [9, 5, 15], state: "minecraft:waxed_oxidized_cut_copper"},
        {pos: [9, 5, 16], state: "minecraft:tuff_bricks"},
        {pos: [10, 5, 0], state: "minecraft:tuff_bricks"},
        {pos: [10, 5, 1], state: "minecraft:tuff_bricks"},
        {pos: [10, 5, 5], state: "minecraft:tuff_bricks"},
        {pos: [10, 5, 6], state: "minecraft:tuff_bricks"},
        {pos: [10, 5, 7], state: "minecraft:waxed_oxidized_cut_copper"},
        {pos: [10, 5, 8], state: "minecraft:waxed_oxidized_cut_copper"},
        {pos: [10, 5, 9], state: "minecraft:waxed_oxidized_cut_copper"},
        {pos: [10, 5, 10], state: "minecraft:tuff_bricks"},
        {pos: [10, 5, 11], state: "minecraft:tuff_bricks"},
        {pos: [10, 5, 12], state: "minecraft:waxed_oxidized_cut_copper"},
        {pos: [10, 5, 13], state: "minecraft:waxed_oxidized_cut_copper"},
        {pos: [10, 5, 14], state: "minecraft:waxed_oxidized_cut_copper"},
        {pos: [10, 5, 15], state: "minecraft:tuff_bricks"},
        {pos: [10, 5, 16], state: "minecraft:tuff_bricks"},
        {pos: [11, 5, 0], state: "minecraft:tuff_bricks"},
        {pos: [11, 5, 1], state: "minecraft:tuff_bricks"},
        {pos: [11, 5, 2], state: "minecraft:tuff_bricks"},
        {pos: [11, 5, 3], state: "minecraft:tuff_bricks"},
        {pos: [11, 5, 4], state: "minecraft:tuff_bricks"},
        {pos: [11, 5, 5], state: "minecraft:tuff_bricks"},
        {pos: [11, 5, 6], state: "minecraft:tuff_bricks"},
        {pos: [11, 5, 7], state: "minecraft:tuff_bricks"},
        {pos: [11, 5, 8], state: "minecraft:tuff_bricks"},
        {pos: [11, 5, 9], state: "minecraft:tuff_bricks"},
        {pos: [11, 5, 10], state: "minecraft:tuff_bricks"},
        {pos: [11, 5, 11], state: "minecraft:tuff_bricks"},
        {pos: [11, 5, 12], state: "minecraft:tuff_bricks"},
        {pos: [11, 5, 13], state: "minecraft:tuff_bricks"},
        {pos: [11, 5, 14], state: "minecraft:tuff_bricks"},
        {pos: [11, 5, 15], state: "minecraft:tuff_bricks"},
        {pos: [11, 5, 16], state: "minecraft:tuff_bricks"},
        {pos: [0, 6, 0], state: "minecraft:waxed_copper_block"},
        {pos: [0, 6, 1], state: "minecraft:waxed_copper_block"},
        {pos: [0, 6, 2], state: "minecraft:waxed_copper_block"},
        {pos: [0, 6, 3], state: "minecraft:waxed_copper_block"},
        {pos: [0, 6, 4], state: "minecraft:waxed_copper_block"},
        {pos: [0, 6, 5], state: "minecraft:waxed_copper_block"},
        {pos: [0, 6, 6], state: "minecraft:waxed_copper_block"},
        {pos: [0, 6, 7], state: "minecraft:waxed_copper_block"},
        {pos: [0, 6, 8], state: "minecraft:waxed_copper_block"},
        {pos: [0, 6, 9], state: "minecraft:waxed_copper_block"},
        {pos: [0, 6, 10], state: "minecraft:waxed_copper_block"},
        {pos: [0, 6, 11], state: "minecraft:waxed_copper_block"},
        {pos: [0, 6, 15], state: "minecraft:waxed_copper_block"},
        {pos: [0, 6, 16], state: "minecraft:waxed_copper_block"},
        {pos: [1, 6, 0], state: "minecraft:waxed_copper_block"},
        {pos: [1, 6, 1], state: "minecraft:waxed_copper_block"},
        {pos: [1, 6, 5], state: "minecraft:waxed_copper_block"},
        {pos: [1, 6, 6], state: "minecraft:waxed_copper_block"},
        {pos: [1, 6, 10], state: "minecraft:waxed_copper_block"},
        {pos: [1, 6, 11], state: "minecraft:waxed_copper_block"},
        {pos: [1, 6, 15], state: "minecraft:waxed_copper_block"},
        {pos: [1, 6, 16], state: "minecraft:waxed_copper_block"},
        {pos: [2, 6, 0], state: "minecraft:waxed_copper_block"},
        {pos: [2, 6, 16], state: "minecraft:waxed_copper_block"},
        {pos: [3, 6, 0], state: "minecraft:waxed_copper_block"},
        {pos: [3, 6, 16], state: "minecraft:waxed_copper_block"},
        {pos: [4, 6, 0], state: "minecraft:waxed_copper_block"},
        {pos: [4, 6, 16], state: "minecraft:waxed_copper_block"},
        {pos: [5, 6, 0], state: "minecraft:waxed_copper_block"},
        {pos: [5, 6, 1], state: "minecraft:waxed_copper_block"},
        {pos: [5, 6, 5], state: "minecraft:waxed_copper_block"},
        {pos: [5, 6, 6], state: "minecraft:waxed_copper_block"},
        {pos: [5, 6, 15], state: "minecraft:waxed_copper_block"},
        {pos: [5, 6, 16], state: "minecraft:waxed_copper_block"},
        {pos: [6, 6, 0], state: "minecraft:waxed_copper_block"},
        {pos: [6, 6, 1], state: "minecraft:waxed_copper_block"},
        {pos: [6, 6, 5], state: "minecraft:waxed_copper_block"},
        {pos: [6, 6, 6], state: "minecraft:waxed_copper_block"},
        {pos: [6, 6, 15], state: "minecraft:waxed_copper_block"},
        {pos: [6, 6, 16], state: "minecraft:waxed_copper_block"},
        {pos: [7, 6, 0], state: "minecraft:waxed_copper_block"},
        {pos: [7, 6, 16], state: "minecraft:waxed_copper_block"},
        {pos: [8, 6, 0], state: "minecraft:waxed_copper_block"},
        {pos: [8, 6, 16], state: "minecraft:waxed_copper_block"},
        {pos: [9, 6, 0], state: "minecraft:waxed_copper_block"},
        {pos: [9, 6, 16], state: "minecraft:waxed_copper_block"},
        {pos: [10, 6, 0], state: "minecraft:waxed_copper_block"},
        {pos: [10, 6, 1], state: "minecraft:waxed_copper_block"},
        {pos: [10, 6, 5], state: "minecraft:waxed_copper_block"},
        {pos: [10, 6, 6], state: "minecraft:waxed_copper_block"},
        {pos: [10, 6, 10], state: "minecraft:waxed_copper_block"},
        {pos: [10, 6, 11], state: "minecraft:waxed_copper_block"},
        {pos: [10, 6, 15], state: "minecraft:waxed_copper_block"},
        {pos: [10, 6, 16], state: "minecraft:waxed_copper_block"},
        {pos: [11, 6, 0], state: "minecraft:waxed_copper_block"},
        {pos: [11, 6, 1], state: "minecraft:waxed_copper_block"},
        {pos: [11, 6, 2], state: "minecraft:waxed_copper_block"},
        {pos: [11, 6, 3], state: "minecraft:waxed_copper_block"},
        {pos: [11, 6, 4], state: "minecraft:waxed_copper_block"},
        {pos: [11, 6, 5], state: "minecraft:waxed_copper_block"},
        {pos: [11, 6, 6], state: "minecraft:waxed_copper_block"},
        {pos: [11, 6, 7], state: "minecraft:waxed_copper_block"},
        {pos: [11, 6, 8], state: "minecraft:waxed_copper_block"},
        {pos: [11, 6, 9], state: "minecraft:waxed_copper_block"},
        {pos: [11, 6, 10], state: "minecraft:waxed_copper_block"},
        {pos: [11, 6, 11], state: "minecraft:waxed_copper_block"},
        {pos: [11, 6, 12], state: "minecraft:waxed_copper_block"},
        {pos: [11, 6, 13], state: "minecraft:waxed_copper_block"},
        {pos: [11, 6, 14], state: "minecraft:waxed_copper_block"},
        {pos: [11, 6, 15], state: "minecraft:waxed_copper_block"},
        {pos: [11, 6, 16], state: "minecraft:waxed_copper_block"},
        {pos: [0, 7, 0], state: "minecraft:tuff_bricks"},
        {pos: [0, 7, 1], state: "minecraft:tuff_bricks"},
        {pos: [0, 7, 2], state: "minecraft:tuff_bricks"},
        {pos: [0, 7, 3], state: "minecraft:waxed_copper_bulb{powered:false,lit:true}"},
        {pos: [0, 7, 4], state: "minecraft:tuff_bricks"},
        {pos: [0, 7, 5], state: "minecraft:tuff_bricks"},
        {pos: [0, 7, 6], state: "minecraft:tuff_bricks"},
        {pos: [0, 7, 7], state: "minecraft:tuff_bricks"},
        {pos: [0, 7, 8], state: "minecraft:waxed_copper_bulb{powered:false,lit:true}"},
        {pos: [0, 7, 9], state: "minecraft:tuff_bricks"},
        {pos: [0, 7, 10], state: "minecraft:tuff_bricks"},
        {pos: [0, 7, 11], state: "minecraft:tuff_bricks"},
        {pos: [0, 7, 15], state: "minecraft:tuff_bricks"},
        {pos: [0, 7, 16], state: "minecraft:tuff_bricks"},
        {pos: [1, 7, 0], state: "minecraft:tuff_bricks"},
        {pos: [1, 7, 1], state: "minecraft:tuff_bricks"},
        {pos: [1, 7, 5], state: "minecraft:tuff_bricks"},
        {pos: [1, 7, 6], state: "minecraft:tuff_bricks"},
        {pos: [1, 7, 10], state: "minecraft:tuff_bricks"},
        {pos: [1, 7, 11], state: "minecraft:tuff_bricks"},
        {pos: [1, 7, 15], state: "minecraft:tuff_bricks"},
        {pos: [1, 7, 16], state: "minecraft:tuff_bricks"},
        {pos: [2, 7, 0], state: "minecraft:tuff_bricks"},
        {pos: [2, 7, 16], state: "minecraft:tuff_bricks"},
        {pos: [3, 7, 0], state: "minecraft:waxed_copper_bulb{powered:false,lit:true}"},
        {pos: [3, 7, 16], state: "minecraft:waxed_copper_bulb{powered:false,lit:true}"},
        {pos: [4, 7, 0], state: "minecraft:tuff_bricks"},
        {pos: [4, 7, 16], state: "minecraft:tuff_bricks"},
        {pos: [5, 7, 0], state: "minecraft:tuff_bricks"},
        {pos: [5, 7, 1], state: "minecraft:tuff_bricks"},
        {pos: [5, 7, 5], state: "minecraft:tuff_bricks"},
        {pos: [5, 7, 6], state: "minecraft:tuff_bricks"},
        {pos: [5, 7, 15], state: "minecraft:tuff_bricks"},
        {pos: [5, 7, 16], state: "minecraft:tuff_bricks"},
        {pos: [6, 7, 0], state: "minecraft:tuff_bricks"},
        {pos: [6, 7, 1], state: "minecraft:tuff_bricks"},
        {pos: [6, 7, 5], state: "minecraft:tuff_bricks"},
        {pos: [6, 7, 6], state: "minecraft:tuff_bricks"},
        {pos: [6, 7, 15], state: "minecraft:tuff_bricks"},
        {pos: [6, 7, 16], state: "minecraft:tuff_bricks"},
        {pos: [7, 7, 0], state: "minecraft:tuff_bricks"},
        {pos: [7, 7, 16], state: "minecraft:tuff_bricks"},
        {pos: [8, 7, 0], state: "minecraft:waxed_copper_bulb{powered:false,lit:true}"},
        {pos: [8, 7, 16], state: "minecraft:waxed_copper_bulb{powered:false,lit:true}"},
        {pos: [9, 7, 0], state: "minecraft:tuff_bricks"},
        {pos: [9, 7, 16], state: "minecraft:tuff_bricks"},
        {pos: [10, 7, 0], state: "minecraft:tuff_bricks"},
        {pos: [10, 7, 1], state: "minecraft:tuff_bricks"},
        {pos: [10, 7, 5], state: "minecraft:tuff_bricks"},
        {pos: [10, 7, 6], state: "minecraft:tuff_bricks"},
        {pos: [10, 7, 10], state: "minecraft:tuff_bricks"},
        {pos: [10, 7, 11], state: "minecraft:tuff_bricks"},
        {pos: [10, 7, 15], state: "minecraft:tuff_bricks"},
        {pos: [10, 7, 16], state: "minecraft:tuff_bricks"},
        {pos: [11, 7, 0], state: "minecraft:tuff_bricks"},
        {pos: [11, 7, 1], state: "minecraft:tuff_bricks"},
        {pos: [11, 7, 2], state: "minecraft:tuff_bricks"},
        {pos: [11, 7, 3], state: "minecraft:waxed_copper_bulb{powered:false,lit:true}"},
        {pos: [11, 7, 4], state: "minecraft:tuff_bricks"},
        {pos: [11, 7, 5], state: "minecraft:tuff_bricks"},
        {pos: [11, 7, 6], state: "minecraft:tuff_bricks"},
        {pos: [11, 7, 7], state: "minecraft:tuff_bricks"},
        {pos: [11, 7, 8], state: "minecraft:waxed_copper_bulb{powered:false,lit:true}"},
        {pos: [11, 7, 9], state: "minecraft:tuff_bricks"},
        {pos: [11, 7, 10], state: "minecraft:tuff_bricks"},
        {pos: [11, 7, 11], state: "minecraft:tuff_bricks"},
        {pos: [11, 7, 12], state: "minecraft:tuff_bricks"},
        {pos: [11, 7, 13], state: "minecraft:waxed_copper_bulb{powered:false,lit:true}"},
        {pos: [11, 7, 14], state: "minecraft:tuff_bricks"},
        {pos: [11, 7, 15], state: "minecraft:tuff_bricks"},
        {pos: [11, 7, 16], state: "minecraft:tuff_bricks"},
        {pos: [0, 8, 0], state: "minecraft:chiseled_tuff_bricks"},
        {pos: [0, 8, 1], state: "minecraft:chiseled_tuff_bricks"},
        {pos: [0, 8, 2], state: "minecraft:chiseled_tuff_bricks"},
        {pos: [0, 8, 3], state: "minecraft:chiseled_tuff_bricks"},
        {pos: [0, 8, 4], state: "minecraft:chiseled_tuff_bricks"},
        {pos: [0, 8, 5], state: "minecraft:chiseled_tuff_bricks"},
        {pos: [0, 8, 6], state: "minecraft:chiseled_tuff_bricks"},
        {pos: [0, 8, 7], state: "minecraft:chiseled_tuff_bricks"},
        {pos: [0, 8, 8], state: "minecraft:chiseled_tuff_bricks"},
        {pos: [0, 8, 9], state: "minecraft:chiseled_tuff_bricks"},
        {pos: [0, 8, 10], state: "minecraft:chiseled_tuff_bricks"},
        {pos: [0, 8, 11], state: "minecraft:chiseled_tuff_bricks"},
        {pos: [0, 8, 15], state: "minecraft:chiseled_tuff_bricks"},
        {pos: [0, 8, 16], state: "minecraft:chiseled_tuff_bricks"},
        {pos: [1, 8, 0], state: "minecraft:chiseled_tuff_bricks"},
        {pos: [1, 8, 1], state: "minecraft:chiseled_tuff_bricks"},
        {pos: [1, 8, 5], state: "minecraft:chiseled_tuff_bricks"},
        {pos: [1, 8, 6], state: "minecraft:chiseled_tuff_bricks"},
        {pos: [1, 8, 10], state: "minecraft:chiseled_tuff_bricks"},
        {pos: [1, 8, 11], state: "minecraft:chiseled_tuff_bricks"},
        {pos: [1, 8, 15], state: "minecraft:chiseled_tuff_bricks"},
        {pos: [1, 8, 16], state: "minecraft:chiseled_tuff_bricks"},
        {pos: [2, 8, 0], state: "minecraft:chiseled_tuff_bricks"},
        {pos: [2, 8, 16], state: "minecraft:chiseled_tuff_bricks"},
        {pos: [3, 8, 0], state: "minecraft:chiseled_tuff_bricks"},
        {pos: [3, 8, 16], state: "minecraft:chiseled_tuff_bricks"},
        {pos: [4, 8, 0], state: "minecraft:chiseled_tuff_bricks"},
        {pos: [4, 8, 16], state: "minecraft:chiseled_tuff_bricks"},
        {pos: [5, 8, 0], state: "minecraft:chiseled_tuff_bricks"},
        {pos: [5, 8, 1], state: "minecraft:chiseled_tuff_bricks"},
        {pos: [5, 8, 5], state: "minecraft:chiseled_tuff_bricks"},
        {pos: [5, 8, 6], state: "minecraft:chiseled_tuff_bricks"},
        {pos: [5, 8, 15], state: "minecraft:chiseled_tuff_bricks"},
        {pos: [5, 8, 16], state: "minecraft:chiseled_tuff_bricks"},
        {pos: [6, 8, 0], state: "minecraft:chiseled_tuff_bricks"},
        {pos: [6, 8, 1], state: "minecraft:chiseled_tuff_bricks"},
        {pos: [6, 8, 5], state: "minecraft:chiseled_tuff_bricks"},
        {pos: [6, 8, 6], state: "minecraft:chiseled_tuff_bricks"},
        {pos: [6, 8, 15], state: "minecraft:chiseled_tuff_bricks"},
        {pos: [6, 8, 16], state: "minecraft:chiseled_tuff_bricks"},
        {pos: [7, 8, 0], state: "minecraft:chiseled_tuff_bricks"},
        {pos: [7, 8, 16], state: "minecraft:chiseled_tuff_bricks"},
        {pos: [8, 8, 0], state: "minecraft:chiseled_tuff_bricks"},
        {pos: [8, 8, 16], state: "minecraft:chiseled_tuff_bricks"},
        {pos: [9, 8, 0], state: "minecraft:chiseled_tuff_bricks"},
        {pos: [9, 8, 16], state: "minecraft:chiseled_tuff_bricks"},
        {pos: [10, 8, 0], state: "minecraft:chiseled_tuff_bricks"},
        {pos: [10, 8, 1], state: "minecraft:chiseled_tuff_bricks"},
        {pos: [10, 8, 5], state: "minecraft:chiseled_tuff_bricks"},
        {pos: [10, 8, 6], state: "minecraft:chiseled_tuff_bricks"},
        {pos: [10, 8, 10], state: "minecraft:chiseled_tuff_bricks"},
        {pos: [10, 8, 11], state: "minecraft:chiseled_tuff_bricks"},
        {pos: [10, 8, 15], state: "minecraft:chiseled_tuff_bricks"},
        {pos: [10, 8, 16], state: "minecraft:chiseled_tuff_bricks"},
        {pos: [11, 8, 0], state: "minecraft:chiseled_tuff_bricks"},
        {pos: [11, 8, 1], state: "minecraft:chiseled_tuff_bricks"},
        {pos: [11, 8, 2], state: "minecraft:chiseled_tuff_bricks"},
        {pos: [11, 8, 3], state: "minecraft:chiseled_tuff_bricks"},
        {pos: [11, 8, 4], state: "minecraft:chiseled_tuff_bricks"},
        {pos: [11, 8, 5], state: "minecraft:chiseled_tuff_bricks"},
        {pos: [11, 8, 6], state: "minecraft:chiseled_tuff_bricks"},
        {pos: [11, 8, 7], state: "minecraft:chiseled_tuff_bricks"},
        {pos: [11, 8, 8], state: "minecraft:chiseled_tuff_bricks"},
        {pos: [11, 8, 9], state: "minecraft:chiseled_tuff_bricks"},
        {pos: [11, 8, 10], state: "minecraft:chiseled_tuff_bricks"},
        {pos: [11, 8, 11], state: "minecraft:chiseled_tuff_bricks"},
        {pos: [11, 8, 12], state: "minecraft:chiseled_tuff_bricks"},
        {pos: [11, 8, 13], state: "minecraft:chiseled_tuff_bricks"},
        {pos: [11, 8, 14], state: "minecraft:chiseled_tuff_bricks"},
        {pos: [11, 8, 15], state: "minecraft:chiseled_tuff_bricks"},
        {pos: [11, 8, 16], state: "minecraft:chiseled_tuff_bricks"},
        {pos: [0, 9, 0], state: "minecraft:tuff_bricks"},
        {pos: [0, 9, 1], state: "minecraft:tuff_bricks"},
        {pos: [0, 9, 2], state: "minecraft:polished_tuff"},
        {pos: [0, 9, 3], state: "minecraft:polished_tuff"},
        {pos: [0, 9, 4], state: "minecraft:polished_tuff"},
        {pos: [0, 9, 5], state: "minecraft:tuff_bricks"},
        {pos: [0, 9, 6], state: "minecraft:tuff_bricks"},
        {pos: [0, 9, 7], state: "minecraft:polished_tuff"},
        {pos: [0, 9, 8], state: "minecraft:polished_tuff"},
        {pos: [0, 9, 9], state: "minecraft:polished_tuff"},
        {pos: [0, 9, 10], state: "minecraft:tuff_bricks"},
        {pos: [0, 9, 11], state: "minecraft:tuff_bricks"},
        {pos: [0, 9, 12], state: "minecraft:polished_tuff"},
        {pos: [0, 9, 13], state: "minecraft:polished_tuff"},
        {pos: [0, 9, 14], state: "minecraft:polished_tuff"},
        {pos: [0, 9, 15], state: "minecraft:tuff_bricks"},
        {pos: [0, 9, 16], state: "minecraft:tuff_bricks"},
        {pos: [1, 9, 0], state: "minecraft:tuff_bricks"},
        {pos: [1, 9, 1], state: "minecraft:polished_tuff"},
        {pos: [1, 9, 2], state: "minecraft:polished_tuff"},
        {pos: [1, 9, 3], state: "minecraft:polished_tuff"},
        {pos: [1, 9, 4], state: "minecraft:polished_tuff"},
        {pos: [1, 9, 5], state: "minecraft:polished_tuff"},
        {pos: [1, 9, 6], state: "minecraft:polished_tuff"},
        {pos: [1, 9, 7], state: "minecraft:polished_tuff"},
        {pos: [1, 9, 8], state: "minecraft:polished_tuff"},
        {pos: [1, 9, 9], state: "minecraft:polished_tuff"},
        {pos: [1, 9, 10], state: "minecraft:polished_tuff"},
        {pos: [1, 9, 11], state: "minecraft:polished_tuff"},
        {pos: [1, 9, 12], state: "minecraft:polished_tuff"},
        {pos: [1, 9, 13], state: "minecraft:polished_tuff"},
        {pos: [1, 9, 14], state: "minecraft:polished_tuff"},
        {pos: [1, 9, 15], state: "minecraft:polished_tuff"},
        {pos: [1, 9, 16], state: "minecraft:tuff_bricks"},
        {pos: [2, 9, 0], state: "minecraft:tuff_bricks"},
        {pos: [2, 9, 1], state: "minecraft:polished_tuff"},
        {pos: [2, 9, 2], state: "minecraft:polished_tuff"},
        {pos: [2, 9, 3], state: "minecraft:polished_tuff"},
        {pos: [2, 9, 4], state: "minecraft:polished_tuff"},
        {pos: [2, 9, 5], state: "minecraft:polished_tuff"},
        {pos: [2, 9, 6], state: "minecraft:polished_tuff"},
        {pos: [2, 9, 7], state: "minecraft:polished_tuff"},
        {pos: [2, 9, 8], state: "minecraft:polished_tuff"},
        {pos: [2, 9, 9], state: "minecraft:polished_tuff"},
        {pos: [2, 9, 10], state: "minecraft:polished_tuff"},
        {pos: [2, 9, 11], state: "minecraft:polished_tuff"},
        {pos: [2, 9, 12], state: "minecraft:polished_tuff"},
        {pos: [2, 9, 13], state: "minecraft:polished_tuff"},
        {pos: [2, 9, 14], state: "minecraft:polished_tuff"},
        {pos: [2, 9, 15], state: "minecraft:polished_tuff"},
        {pos: [2, 9, 16], state: "minecraft:tuff_bricks"},
        {pos: [3, 9, 0], state: "minecraft:tuff_bricks"},
        {pos: [3, 9, 1], state: "minecraft:polished_tuff"},
        {pos: [3, 9, 2], state: "minecraft:polished_tuff"},
        {pos: [3, 9, 3], state: "minecraft:polished_tuff"},
        {pos: [3, 9, 4], state: "minecraft:polished_tuff"},
        {pos: [3, 9, 5], state: "minecraft:polished_tuff"},
        {pos: [3, 9, 6], state: "minecraft:polished_tuff"},
        {pos: [3, 9, 7], state: "minecraft:polished_tuff"},
        {pos: [3, 9, 8], state: "minecraft:polished_tuff"},
        {pos: [3, 9, 9], state: "minecraft:polished_tuff"},
        {pos: [3, 9, 10], state: "minecraft:polished_tuff"},
        {pos: [3, 9, 11], state: "minecraft:polished_tuff"},
        {pos: [3, 9, 12], state: "minecraft:polished_tuff"},
        {pos: [3, 9, 13], state: "minecraft:polished_tuff"},
        {pos: [3, 9, 14], state: "minecraft:polished_tuff"},
        {pos: [3, 9, 15], state: "minecraft:polished_tuff"},
        {pos: [3, 9, 16], state: "minecraft:tuff_bricks"},
        {pos: [4, 9, 0], state: "minecraft:tuff_bricks"},
        {pos: [4, 9, 1], state: "minecraft:tuff_bricks"},
        {pos: [4, 9, 2], state: "minecraft:polished_tuff"},
        {pos: [4, 9, 3], state: "minecraft:polished_tuff"},
        {pos: [4, 9, 4], state: "minecraft:polished_tuff"},
        {pos: [4, 9, 5], state: "minecraft:polished_tuff"},
        {pos: [4, 9, 6], state: "minecraft:polished_tuff"},
        {pos: [4, 9, 7], state: "minecraft:polished_tuff"},
        {pos: [4, 9, 8], state: "minecraft:polished_tuff"},
        {pos: [4, 9, 9], state: "minecraft:polished_tuff"},
        {pos: [4, 9, 10], state: "minecraft:polished_tuff"},
        {pos: [4, 9, 11], state: "minecraft:polished_tuff"},
        {pos: [4, 9, 12], state: "minecraft:polished_tuff"},
        {pos: [4, 9, 13], state: "minecraft:polished_tuff"},
        {pos: [4, 9, 14], state: "minecraft:polished_tuff"},
        {pos: [4, 9, 15], state: "minecraft:tuff_bricks"},
        {pos: [4, 9, 16], state: "minecraft:tuff_bricks"},
        {pos: [5, 9, 0], state: "minecraft:tuff_bricks"},
        {pos: [5, 9, 1], state: "minecraft:tuff_bricks"},
        {pos: [5, 9, 2], state: "minecraft:polished_tuff"},
        {pos: [5, 9, 3], state: "minecraft:polished_tuff"},
        {pos: [5, 9, 4], state: "minecraft:polished_tuff"},
        {pos: [5, 9, 5], state: "minecraft:tuff_bricks"},
        {pos: [5, 9, 6], state: "minecraft:tuff_bricks"},
        {pos: [5, 9, 7], state: "minecraft:polished_tuff"},
        {pos: [5, 9, 8], state: "minecraft:polished_tuff"},
        {pos: [5, 9, 9], state: "minecraft:polished_tuff"},
        {pos: [5, 9, 10], state: "minecraft:polished_tuff"},
        {pos: [5, 9, 11], state: "minecraft:polished_tuff"},
        {pos: [5, 9, 12], state: "minecraft:polished_tuff"},
        {pos: [5, 9, 13], state: "minecraft:polished_tuff"},
        {pos: [5, 9, 14], state: "minecraft:polished_tuff"},
        {pos: [5, 9, 15], state: "minecraft:tuff_bricks"},
        {pos: [5, 9, 16], state: "minecraft:tuff_bricks"},
        {pos: [6, 9, 0], state: "minecraft:tuff_bricks"},
        {pos: [6, 9, 1], state: "minecraft:polished_tuff"},
        {pos: [6, 9, 2], state: "minecraft:polished_tuff"},
        {pos: [6, 9, 3], state: "minecraft:polished_tuff"},
        {pos: [6, 9, 4], state: "minecraft:polished_tuff"},
        {pos: [6, 9, 5], state: "minecraft:tuff_bricks"},
        {pos: [6, 9, 6], state: "minecraft:tuff_bricks"},
        {pos: [6, 9, 7], state: "minecraft:polished_tuff"},
        {pos: [6, 9, 8], state: "minecraft:polished_tuff"},
        {pos: [6, 9, 9], state: "minecraft:polished_tuff"},
        {pos: [6, 9, 10], state: "minecraft:polished_tuff"},
        {pos: [6, 9, 11], state: "minecraft:polished_tuff"},
        {pos: [6, 9, 12], state: "minecraft:polished_tuff"},
        {pos: [6, 9, 13], state: "minecraft:polished_tuff"},
        {pos: [6, 9, 14], state: "minecraft:polished_tuff"},
        {pos: [6, 9, 15], state: "minecraft:polished_tuff"},
        {pos: [6, 9, 16], state: "minecraft:tuff_bricks"},
        {pos: [7, 9, 0], state: "minecraft:tuff_bricks"},
        {pos: [7, 9, 1], state: "minecraft:polished_tuff"},
        {pos: [7, 9, 2], state: "minecraft:polished_tuff"},
        {pos: [7, 9, 3], state: "minecraft:polished_tuff"},
        {pos: [7, 9, 4], state: "minecraft:polished_tuff"},
        {pos: [7, 9, 5], state: "minecraft:polished_tuff"},
        {pos: [7, 9, 6], state: "minecraft:polished_tuff"},
        {pos: [7, 9, 7], state: "minecraft:polished_tuff"},
        {pos: [7, 9, 8], state: "minecraft:polished_tuff"},
        {pos: [7, 9, 9], state: "minecraft:polished_tuff"},
        {pos: [7, 9, 10], state: "minecraft:polished_tuff"},
        {pos: [7, 9, 11], state: "minecraft:polished_tuff"},
        {pos: [7, 9, 12], state: "minecraft:polished_tuff"},
        {pos: [7, 9, 13], state: "minecraft:polished_tuff"},
        {pos: [7, 9, 14], state: "minecraft:polished_tuff"},
        {pos: [7, 9, 15], state: "minecraft:polished_tuff"},
        {pos: [7, 9, 16], state: "minecraft:tuff_bricks"},
        {pos: [8, 9, 0], state: "minecraft:tuff_bricks"},
        {pos: [8, 9, 1], state: "minecraft:polished_tuff"},
        {pos: [8, 9, 2], state: "minecraft:polished_tuff"},
        {pos: [8, 9, 3], state: "minecraft:polished_tuff"},
        {pos: [8, 9, 4], state: "minecraft:polished_tuff"},
        {pos: [8, 9, 5], state: "minecraft:polished_tuff"},
        {pos: [8, 9, 6], state: "minecraft:polished_tuff"},
        {pos: [8, 9, 7], state: "minecraft:polished_tuff"},
        {pos: [8, 9, 8], state: "minecraft:polished_tuff"},
        {pos: [8, 9, 9], state: "minecraft:polished_tuff"},
        {pos: [8, 9, 10], state: "minecraft:polished_tuff"},
        {pos: [8, 9, 11], state: "minecraft:polished_tuff"},
        {pos: [8, 9, 12], state: "minecraft:polished_tuff"},
        {pos: [8, 9, 13], state: "minecraft:polished_tuff"},
        {pos: [8, 9, 14], state: "minecraft:polished_tuff"},
        {pos: [8, 9, 15], state: "minecraft:polished_tuff"},
        {pos: [8, 9, 16], state: "minecraft:tuff_bricks"},
        {pos: [9, 9, 0], state: "minecraft:tuff_bricks"},
        {pos: [9, 9, 1], state: "minecraft:polished_tuff"},
        {pos: [9, 9, 2], state: "minecraft:polished_tuff"},
        {pos: [9, 9, 3], state: "minecraft:polished_tuff"},
        {pos: [9, 9, 4], state: "minecraft:polished_tuff"},
        {pos: [9, 9, 5], state: "minecraft:polished_tuff"},
        {pos: [9, 9, 6], state: "minecraft:polished_tuff"},
        {pos: [9, 9, 7], state: "minecraft:polished_tuff"},
        {pos: [9, 9, 8], state: "minecraft:polished_tuff"},
        {pos: [9, 9, 9], state: "minecraft:polished_tuff"},
        {pos: [9, 9, 10], state: "minecraft:polished_tuff"},
        {pos: [9, 9, 11], state: "minecraft:polished_tuff"},
        {pos: [9, 9, 12], state: "minecraft:polished_tuff"},
        {pos: [9, 9, 13], state: "minecraft:polished_tuff"},
        {pos: [9, 9, 14], state: "minecraft:polished_tuff"},
        {pos: [9, 9, 15], state: "minecraft:polished_tuff"},
        {pos: [9, 9, 16], state: "minecraft:tuff_bricks"},
        {pos: [10, 9, 0], state: "minecraft:tuff_bricks"},
        {pos: [10, 9, 1], state: "minecraft:tuff_bricks"},
        {pos: [10, 9, 2], state: "minecraft:polished_tuff"},
        {pos: [10, 9, 3], state: "minecraft:polished_tuff"},
        {pos: [10, 9, 4], state: "minecraft:polished_tuff"},
        {pos: [10, 9, 5], state: "minecraft:tuff_bricks"},
        {pos: [10, 9, 6], state: "minecraft:tuff_bricks"},
        {pos: [10, 9, 7], state: "minecraft:polished_tuff"},
        {pos: [10, 9, 8], state: "minecraft:polished_tuff"},
        {pos: [10, 9, 9], state: "minecraft:polished_tuff"},
        {pos: [10, 9, 10], state: "minecraft:tuff_bricks"},
        {pos: [10, 9, 11], state: "minecraft:tuff_bricks"},
        {pos: [10, 9, 12], state: "minecraft:polished_tuff"},
        {pos: [10, 9, 13], state: "minecraft:polished_tuff"},
        {pos: [10, 9, 14], state: "minecraft:polished_tuff"},
        {pos: [10, 9, 15], state: "minecraft:tuff_bricks"},
        {pos: [10, 9, 16], state: "minecraft:tuff_bricks"},
        {pos: [11, 9, 0], state: "minecraft:tuff_bricks"},
        {pos: [11, 9, 1], state: "minecraft:tuff_bricks"},
        {pos: [11, 9, 2], state: "minecraft:tuff_bricks"},
        {pos: [11, 9, 3], state: "minecraft:tuff_bricks"},
        {pos: [11, 9, 4], state: "minecraft:tuff_bricks"},
        {pos: [11, 9, 5], state: "minecraft:tuff_bricks"},
        {pos: [11, 9, 6], state: "minecraft:tuff_bricks"},
        {pos: [11, 9, 7], state: "minecraft:tuff_bricks"},
        {pos: [11, 9, 8], state: "minecraft:tuff_bricks"},
        {pos: [11, 9, 9], state: "minecraft:tuff_bricks"},
        {pos: [11, 9, 10], state: "minecraft:tuff_bricks"},
        {pos: [11, 9, 11], state: "minecraft:tuff_bricks"},
        {pos: [11, 9, 12], state: "minecraft:tuff_bricks"},
        {pos: [11, 9, 13], state: "minecraft:tuff_bricks"},
        {pos: [11, 9, 14], state: "minecraft:tuff_bricks"},
        {pos: [11, 9, 15], state: "minecraft:tuff_bricks"},
        {pos: [11, 9, 16], state: "minecraft:tuff_bricks"},
        {pos: [0, 10, 0], state: "minecraft:tuff_bricks"},
        {pos: [0, 10, 1], state: "minecraft:tuff_bricks"},
        {pos: [0, 10, 2], state: "minecraft:tuff_bricks"},
        {pos: [0, 10, 3], state: "minecraft:tuff_bricks"},
        {pos: [0, 10, 4], state: "minecraft:tuff_bricks"},
        {pos: [0, 10, 5], state: "minecraft:tuff_bricks"},
        {pos: [0, 10, 6], state: "minecraft:tuff_bricks"},
        {pos: [0, 10, 7], state: "minecraft:tuff_bricks"},
        {pos: [0, 10, 8], state: "minecraft:tuff_bricks"},
        {pos: [0, 10, 9], state: "minecraft:tuff_bricks"},
        {pos: [0, 10, 10], state: "minecraft:tuff_bricks"},
        {pos: [0, 10, 11], state: "minecraft:tuff_bricks"},
        {pos: [0, 10, 12], state: "minecraft:tuff_bricks"},
        {pos: [0, 10, 13], state: "minecraft:tuff_bricks"},
        {pos: [0, 10, 14], state: "minecraft:tuff_bricks"},
        {pos: [0, 10, 15], state: "minecraft:tuff_bricks"},
        {pos: [0, 10, 16], state: "minecraft:tuff_bricks"},
        {pos: [1, 10, 0], state: "minecraft:tuff_bricks"},
        {pos: [1, 10, 1], state: "minecraft:tuff_bricks"},
        {pos: [1, 10, 2], state: "minecraft:tuff_bricks"},
        {pos: [1, 10, 3], state: "minecraft:tuff_bricks"},
        {pos: [1, 10, 4], state: "minecraft:tuff_bricks"},
        {pos: [1, 10, 5], state: "minecraft:tuff_bricks"},
        {pos: [1, 10, 6], state: "minecraft:tuff_bricks"},
        {pos: [1, 10, 7], state: "minecraft:tuff_bricks"},
        {pos: [1, 10, 8], state: "minecraft:tuff_bricks"},
        {pos: [1, 10, 9], state: "minecraft:tuff_bricks"},
        {pos: [1, 10, 10], state: "minecraft:tuff_bricks"},
        {pos: [1, 10, 11], state: "minecraft:tuff_bricks"},
        {pos: [1, 10, 12], state: "minecraft:tuff_bricks"},
        {pos: [1, 10, 13], state: "minecraft:tuff_bricks"},
        {pos: [1, 10, 14], state: "minecraft:tuff_bricks"},
        {pos: [1, 10, 15], state: "minecraft:tuff_bricks"},
        {pos: [1, 10, 16], state: "minecraft:tuff_bricks"},
        {pos: [2, 10, 0], state: "minecraft:tuff_bricks"},
        {pos: [2, 10, 1], state: "minecraft:tuff_bricks"},
        {pos: [2, 10, 2], state: "minecraft:tuff_bricks"},
        {pos: [2, 10, 3], state: "minecraft:tuff_bricks"},
        {pos: [2, 10, 4], state: "minecraft:tuff_bricks"},
        {pos: [2, 10, 5], state: "minecraft:tuff_bricks"},
        {pos: [2, 10, 6], state: "minecraft:tuff_bricks"},
        {pos: [2, 10, 7], state: "minecraft:tuff_bricks"},
        {pos: [2, 10, 8], state: "minecraft:tuff_bricks"},
        {pos: [2, 10, 9], state: "minecraft:tuff_bricks"},
        {pos: [2, 10, 10], state: "minecraft:tuff_bricks"},
        {pos: [2, 10, 11], state: "minecraft:tuff_bricks"},
        {pos: [2, 10, 12], state: "minecraft:tuff_bricks"},
        {pos: [2, 10, 13], state: "minecraft:tuff_bricks"},
        {pos: [2, 10, 14], state: "minecraft:tuff_bricks"},
        {pos: [2, 10, 15], state: "minecraft:tuff_bricks"},
        {pos: [2, 10, 16], state: "minecraft:tuff_bricks"},
        {pos: [3, 10, 0], state: "minecraft:tuff_bricks"},
        {pos: [3, 10, 1], state: "minecraft:tuff_bricks"},
        {pos: [3, 10, 2], state: "minecraft:tuff_bricks"},
        {pos: [3, 10, 3], state: "minecraft:tuff_bricks"},
        {pos: [3, 10, 4], state: "minecraft:tuff_bricks"},
        {pos: [3, 10, 5], state: "minecraft:tuff_bricks"},
        {pos: [3, 10, 6], state: "minecraft:tuff_bricks"},
        {pos: [3, 10, 7], state: "minecraft:tuff_bricks"},
        {pos: [3, 10, 8], state: "minecraft:tuff_bricks"},
        {pos: [3, 10, 9], state: "minecraft:tuff_bricks"},
        {pos: [3, 10, 10], state: "minecraft:tuff_bricks"},
        {pos: [3, 10, 11], state: "minecraft:tuff_bricks"},
        {pos: [3, 10, 12], state: "minecraft:tuff_bricks"},
        {pos: [3, 10, 13], state: "minecraft:tuff_bricks"},
        {pos: [3, 10, 14], state: "minecraft:tuff_bricks"},
        {pos: [3, 10, 15], state: "minecraft:tuff_bricks"},
        {pos: [3, 10, 16], state: "minecraft:tuff_bricks"},
        {pos: [4, 10, 0], state: "minecraft:tuff_bricks"},
        {pos: [4, 10, 1], state: "minecraft:tuff_bricks"},
        {pos: [4, 10, 2], state: "minecraft:tuff_bricks"},
        {pos: [4, 10, 3], state: "minecraft:tuff_bricks"},
        {pos: [4, 10, 4], state: "minecraft:tuff_bricks"},
        {pos: [4, 10, 5], state: "minecraft:tuff_bricks"},
        {pos: [4, 10, 6], state: "minecraft:tuff_bricks"},
        {pos: [4, 10, 7], state: "minecraft:tuff_bricks"},
        {pos: [4, 10, 8], state: "minecraft:tuff_bricks"},
        {pos: [4, 10, 9], state: "minecraft:tuff_bricks"},
        {pos: [4, 10, 10], state: "minecraft:tuff_bricks"},
        {pos: [4, 10, 11], state: "minecraft:tuff_bricks"},
        {pos: [4, 10, 12], state: "minecraft:tuff_bricks"},
        {pos: [4, 10, 13], state: "minecraft:tuff_bricks"},
        {pos: [4, 10, 14], state: "minecraft:tuff_bricks"},
        {pos: [4, 10, 15], state: "minecraft:tuff_bricks"},
        {pos: [4, 10, 16], state: "minecraft:tuff_bricks"},
        {pos: [5, 10, 0], state: "minecraft:tuff_bricks"},
        {pos: [5, 10, 1], state: "minecraft:tuff_bricks"},
        {pos: [5, 10, 2], state: "minecraft:tuff_bricks"},
        {pos: [5, 10, 3], state: "minecraft:tuff_bricks"},
        {pos: [5, 10, 4], state: "minecraft:tuff_bricks"},
        {pos: [5, 10, 5], state: "minecraft:tuff_bricks"},
        {pos: [5, 10, 6], state: "minecraft:tuff_bricks"},
        {pos: [5, 10, 7], state: "minecraft:tuff_bricks"},
        {pos: [5, 10, 8], state: "minecraft:tuff_bricks"},
        {pos: [5, 10, 9], state: "minecraft:tuff_bricks"},
        {pos: [5, 10, 10], state: "minecraft:tuff_bricks"},
        {pos: [5, 10, 11], state: "minecraft:tuff_bricks"},
        {pos: [5, 10, 12], state: "minecraft:tuff_bricks"},
        {pos: [5, 10, 13], state: "minecraft:tuff_bricks"},
        {pos: [5, 10, 14], state: "minecraft:tuff_bricks"},
        {pos: [5, 10, 15], state: "minecraft:tuff_bricks"},
        {pos: [5, 10, 16], state: "minecraft:tuff_bricks"},
        {pos: [6, 10, 0], state: "minecraft:tuff_bricks"},
        {pos: [6, 10, 1], state: "minecraft:tuff_bricks"},
        {pos: [6, 10, 2], state: "minecraft:tuff_bricks"},
        {pos: [6, 10, 3], state: "minecraft:tuff_bricks"},
        {pos: [6, 10, 4], state: "minecraft:tuff_bricks"},
        {pos: [6, 10, 5], state: "minecraft:tuff_bricks"},
        {pos: [6, 10, 6], state: "minecraft:tuff_bricks"},
        {pos: [6, 10, 7], state: "minecraft:tuff_bricks"},
        {pos: [6, 10, 8], state: "minecraft:tuff_bricks"},
        {pos: [6, 10, 9], state: "minecraft:tuff_bricks"},
        {pos: [6, 10, 10], state: "minecraft:tuff_bricks"},
        {pos: [6, 10, 11], state: "minecraft:tuff_bricks"},
        {pos: [6, 10, 12], state: "minecraft:tuff_bricks"},
        {pos: [6, 10, 13], state: "minecraft:tuff_bricks"},
        {pos: [6, 10, 14], state: "minecraft:tuff_bricks"},
        {pos: [6, 10, 15], state: "minecraft:tuff_bricks"},
        {pos: [6, 10, 16], state: "minecraft:tuff_bricks"},
        {pos: [7, 10, 0], state: "minecraft:tuff_bricks"},
        {pos: [7, 10, 1], state: "minecraft:tuff_bricks"},
        {pos: [7, 10, 2], state: "minecraft:tuff_bricks"},
        {pos: [7, 10, 3], state: "minecraft:tuff_bricks"},
        {pos: [7, 10, 4], state: "minecraft:tuff_bricks"},
        {pos: [7, 10, 5], state: "minecraft:tuff_bricks"},
        {pos: [7, 10, 6], state: "minecraft:tuff_bricks"},
        {pos: [7, 10, 7], state: "minecraft:tuff_bricks"},
        {pos: [7, 10, 8], state: "minecraft:tuff_bricks"},
        {pos: [7, 10, 9], state: "minecraft:tuff_bricks"},
        {pos: [7, 10, 10], state: "minecraft:tuff_bricks"},
        {pos: [7, 10, 11], state: "minecraft:tuff_bricks"},
        {pos: [7, 10, 12], state: "minecraft:tuff_bricks"},
        {pos: [7, 10, 13], state: "minecraft:tuff_bricks"},
        {pos: [7, 10, 14], state: "minecraft:tuff_bricks"},
        {pos: [7, 10, 15], state: "minecraft:tuff_bricks"},
        {pos: [7, 10, 16], state: "minecraft:tuff_bricks"},
        {pos: [8, 10, 0], state: "minecraft:tuff_bricks"},
        {pos: [8, 10, 1], state: "minecraft:tuff_bricks"},
        {pos: [8, 10, 2], state: "minecraft:tuff_bricks"},
        {pos: [8, 10, 3], state: "minecraft:tuff_bricks"},
        {pos: [8, 10, 4], state: "minecraft:tuff_bricks"},
        {pos: [8, 10, 5], state: "minecraft:tuff_bricks"},
        {pos: [8, 10, 6], state: "minecraft:tuff_bricks"},
        {pos: [8, 10, 7], state: "minecraft:tuff_bricks"},
        {pos: [8, 10, 8], state: "minecraft:tuff_bricks"},
        {pos: [8, 10, 9], state: "minecraft:tuff_bricks"},
        {pos: [8, 10, 10], state: "minecraft:tuff_bricks"},
        {pos: [8, 10, 11], state: "minecraft:tuff_bricks"},
        {pos: [8, 10, 12], state: "minecraft:tuff_bricks"},
        {pos: [8, 10, 13], state: "minecraft:tuff_bricks"},
        {pos: [8, 10, 14], state: "minecraft:tuff_bricks"},
        {pos: [8, 10, 15], state: "minecraft:tuff_bricks"},
        {pos: [8, 10, 16], state: "minecraft:tuff_bricks"},
        {pos: [9, 10, 0], state: "minecraft:tuff_bricks"},
        {pos: [9, 10, 1], state: "minecraft:tuff_bricks"},
        {pos: [9, 10, 2], state: "minecraft:tuff_bricks"},
        {pos: [9, 10, 3], state: "minecraft:tuff_bricks"},
        {pos: [9, 10, 4], state: "minecraft:tuff_bricks"},
        {pos: [9, 10, 5], state: "minecraft:tuff_bricks"},
        {pos: [9, 10, 6], state: "minecraft:tuff_bricks"},
        {pos: [9, 10, 7], state: "minecraft:tuff_bricks"},
        {pos: [9, 10, 8], state: "minecraft:tuff_bricks"},
        {pos: [9, 10, 9], state: "minecraft:tuff_bricks"},
        {pos: [9, 10, 10], state: "minecraft:tuff_bricks"},
        {pos: [9, 10, 11], state: "minecraft:tuff_bricks"},
        {pos: [9, 10, 12], state: "minecraft:tuff_bricks"},
        {pos: [9, 10, 13], state: "minecraft:tuff_bricks"},
        {pos: [9, 10, 14], state: "minecraft:tuff_bricks"},
        {pos: [9, 10, 15], state: "minecraft:tuff_bricks"},
        {pos: [9, 10, 16], state: "minecraft:tuff_bricks"},
        {pos: [10, 10, 0], state: "minecraft:tuff_bricks"},
        {pos: [10, 10, 1], state: "minecraft:tuff_bricks"},
        {pos: [10, 10, 2], state: "minecraft:tuff_bricks"},
        {pos: [10, 10, 3], state: "minecraft:tuff_bricks"},
        {pos: [10, 10, 4], state: "minecraft:tuff_bricks"},
        {pos: [10, 10, 5], state: "minecraft:tuff_bricks"},
        {pos: [10, 10, 6], state: "minecraft:tuff_bricks"},
        {pos: [10, 10, 7], state: "minecraft:tuff_bricks"},
        {pos: [10, 10, 8], state: "minecraft:tuff_bricks"},
        {pos: [10, 10, 9], state: "minecraft:tuff_bricks"},
        {pos: [10, 10, 10], state: "minecraft:tuff_bricks"},
        {pos: [10, 10, 11], state: "minecraft:tuff_bricks"},
        {pos: [10, 10, 12], state: "minecraft:tuff_bricks"},
        {pos: [10, 10, 13], state: "minecraft:tuff_bricks"},
        {pos: [10, 10, 14], state: "minecraft:tuff_bricks"},
        {pos: [10, 10, 15], state: "minecraft:tuff_bricks"},
        {pos: [10, 10, 16], state: "minecraft:tuff_bricks"},
        {pos: [11, 10, 0], state: "minecraft:tuff_bricks"},
        {pos: [11, 10, 1], state: "minecraft:tuff_bricks"},
        {pos: [11, 10, 2], state: "minecraft:tuff_bricks"},
        {pos: [11, 10, 3], state: "minecraft:tuff_bricks"},
        {pos: [11, 10, 4], state: "minecraft:tuff_bricks"},
        {pos: [11, 10, 5], state: "minecraft:tuff_bricks"},
        {pos: [11, 10, 6], state: "minecraft:tuff_bricks"},
        {pos: [11, 10, 7], state: "minecraft:tuff_bricks"},
        {pos: [11, 10, 8], state: "minecraft:tuff_bricks"},
        {pos: [11, 10, 9], state: "minecraft:tuff_bricks"},
        {pos: [11, 10, 10], state: "minecraft:tuff_bricks"},
        {pos: [11, 10, 11], state: "minecraft:tuff_bricks"},
        {pos: [11, 10, 12], state: "minecraft:tuff_bricks"},
        {pos: [11, 10, 13], state: "minecraft:tuff_bricks"},
        {pos: [11, 10, 14], state: "minecraft:tuff_bricks"},
        {pos: [11, 10, 15], state: "minecraft:tuff_bricks"},
        {pos: [11, 10, 16], state: "minecraft:tuff_bricks"},
        {pos: [1, 1, 2], state: "minecraft:air"},
        {pos: [1, 1, 3], state: "minecraft:air"},
        {pos: [1, 1, 4], state: "minecraft:air"},
        {pos: [1, 1, 7], state: "minecraft:air"},
        {pos: [1, 1, 8], state: "minecraft:air"},
        {pos: [1, 1, 9], state: "minecraft:air"},
        {pos: [2, 1, 1], state: "minecraft:air"},
        {pos: [2, 1, 2], state: "minecraft:air"},
        {pos: [2, 1, 3], state: "minecraft:air"},
        {pos: [2, 1, 4], state: "minecraft:air"},
        {pos: [2, 1, 5], state: "minecraft:air"},
        {pos: [2, 1, 6], state: "minecraft:waxed_oxidized_cut_copper_stairs{half:bottom,waterlogged:false,shape:straight,facing:south}"},
        {pos: [3, 1, 1], state: "minecraft:air"},
        {pos: [3, 1, 2], state: "minecraft:air"},
        {pos: [3, 1, 3], state: "minecraft:air"},
        {pos: [3, 1, 4], state: "minecraft:air"},
        {pos: [3, 1, 5], state: "minecraft:air"},
        {pos: [3, 1, 6], state: "minecraft:waxed_oxidized_cut_copper_stairs{half:bottom,waterlogged:false,shape:straight,facing:south}"},
        {pos: [4, 1, 1], state: "minecraft:air"},
        {pos: [4, 1, 2], state: "minecraft:air"},
        {pos: [4, 1, 3], state: "minecraft:air"},
        {pos: [4, 1, 4], state: "minecraft:air"},
        {pos: [4, 1, 5], state: "minecraft:air"},
        {pos: [4, 1, 6], state: "minecraft:waxed_oxidized_cut_copper_stairs{half:bottom,waterlogged:false,shape:straight,facing:south}"},
        {pos: [5, 1, 2], state: "minecraft:air"},
        {pos: [5, 1, 3], state: "minecraft:air"},
        {pos: [5, 1, 4], state: "minecraft:air"},
        {pos: [6, 1, 2], state: "minecraft:air"},
        {pos: [6, 1, 3], state: "minecraft:air"},
        {pos: [6, 1, 4], state: "minecraft:air"},
        {pos: [6, 1, 7], state: "minecraft:air"},
        {pos: [6, 1, 8], state: "minecraft:air"},
        {pos: [6, 1, 9], state: "minecraft:air"},
        {pos: [6, 1, 12], state: "minecraft:air"},
        {pos: [6, 1, 13], state: "minecraft:air"},
        {pos: [6, 1, 14], state: "minecraft:air"},
        {pos: [7, 1, 1], state: "minecraft:air"},
        {pos: [7, 1, 2], state: "minecraft:air"},
        {pos: [7, 1, 3], state: "minecraft:air"},
        {pos: [7, 1, 4], state: "minecraft:air"},
        {pos: [7, 1, 5], state: "minecraft:air"},
        {pos: [7, 1, 6], state: "minecraft:air"},
        {pos: [7, 1, 7], state: "minecraft:air"},
        {pos: [7, 1, 8], state: "minecraft:air"},
        {pos: [7, 1, 9], state: "minecraft:air"},
        {pos: [7, 1, 10], state: "minecraft:air"},
        {pos: [7, 1, 11], state: "minecraft:air"},
        {pos: [7, 1, 12], state: "minecraft:air"},
        {pos: [7, 1, 13], state: "minecraft:air"},
        {pos: [7, 1, 14], state: "minecraft:air"},
        {pos: [8, 1, 1], state: "minecraft:air"},
        {pos: [8, 1, 2], state: "minecraft:air"},
        {pos: [8, 1, 3], state: "minecraft:air"},
        {pos: [8, 1, 4], state: "minecraft:air"},
        {pos: [8, 1, 5], state: "minecraft:air"},
        {pos: [8, 1, 6], state: "minecraft:air"},
        {pos: [8, 1, 7], state: "minecraft:air"},
        {pos: [8, 1, 8], state: "minecraft:air"},
        {pos: [8, 1, 9], state: "minecraft:air"},
        {pos: [8, 1, 10], state: "minecraft:air"},
        {pos: [8, 1, 11], state: "minecraft:air"},
        {pos: [8, 1, 12], state: "minecraft:air"},
        {pos: [8, 1, 13], state: "minecraft:air"},
        {pos: [8, 1, 14], state: "minecraft:air"},
        {pos: [9, 1, 1], state: "minecraft:air"},
        {pos: [9, 1, 2], state: "minecraft:air"},
        {pos: [9, 1, 3], state: "minecraft:air"},
        {pos: [9, 1, 4], state: "minecraft:air"},
        {pos: [9, 1, 5], state: "minecraft:air"},
        {pos: [9, 1, 6], state: "minecraft:air"},
        {pos: [9, 1, 7], state: "minecraft:air"},
        {pos: [9, 1, 8], state: "minecraft:air"},
        {pos: [9, 1, 9], state: "minecraft:air"},
        {pos: [9, 1, 10], state: "minecraft:air"},
        {pos: [9, 1, 11], state: "minecraft:air"},
        {pos: [9, 1, 12], state: "minecraft:air"},
        {pos: [9, 1, 13], state: "minecraft:air"},
        {pos: [9, 1, 14], state: "minecraft:air"},
        {pos: [10, 1, 2], state: "minecraft:air"},
        {pos: [10, 1, 3], state: "minecraft:air"},
        {pos: [10, 1, 4], state: "minecraft:air"},
        {pos: [10, 1, 7], state: "minecraft:air"},
        {pos: [10, 1, 8], state: "minecraft:air"},
        {pos: [10, 1, 9], state: "minecraft:air"},
        {pos: [10, 1, 12], state: "minecraft:air"},
        {pos: [10, 1, 13], state: "minecraft:air"},
        {pos: [10, 1, 14], state: "minecraft:air"},
        {pos: [11, 1, 12], state: "minecraft:air"},
        {pos: [11, 1, 13], state: "minecraft:air"},
        {pos: [11, 1, 14], state: "minecraft:air"},
        {pos: [1, 2, 2], state: "minecraft:air"},
        {pos: [1, 2, 3], state: "minecraft:air"},
        {pos: [1, 2, 4], state: "minecraft:air"},
        {pos: [1, 2, 7], state: "minecraft:air"},
        {pos: [1, 2, 8], state: "minecraft:air"},
        {pos: [1, 2, 9], state: "minecraft:air"},
        {pos: [2, 2, 1], state: "minecraft:air"},
        {pos: [2, 2, 2], state: "minecraft:air"},
        {pos: [2, 2, 3], state: "minecraft:air"},
        {pos: [2, 2, 4], state: "minecraft:air"},
        {pos: [2, 2, 5], state: "minecraft:air"},
        {pos: [2, 2, 6], state: "minecraft:air"},
        {pos: [2, 2, 7], state: "minecraft:waxed_oxidized_cut_copper_stairs{half:bottom,waterlogged:false,shape:straight,facing:south}"},
        {pos: [3, 2, 1], state: "minecraft:air"},
        {pos: [3, 2, 2], state: "minecraft:air"},
        {pos: [3, 2, 3], state: "minecraft:air"},
        {pos: [3, 2, 4], state: "minecraft:air"},
        {pos: [3, 2, 5], state: "minecraft:air"},
        {pos: [3, 2, 6], state: "minecraft:air"},
        {pos: [3, 2, 7], state: "minecraft:waxed_oxidized_cut_copper_stairs{half:bottom,waterlogged:false,shape:straight,facing:south}"},
        {pos: [4, 2, 1], state: "minecraft:air"},
        {pos: [4, 2, 2], state: "minecraft:air"},
        {pos: [4, 2, 3], state: "minecraft:air"},
        {pos: [4, 2, 4], state: "minecraft:air"},
        {pos: [4, 2, 5], state: "minecraft:air"},
        {pos: [4, 2, 6], state: "minecraft:air"},
        {pos: [4, 2, 7], state: "minecraft:waxed_oxidized_cut_copper_stairs{half:bottom,waterlogged:false,shape:straight,facing:south}"},
        {pos: [5, 2, 2], state: "minecraft:air"},
        {pos: [5, 2, 3], state: "minecraft:air"},
        {pos: [5, 2, 4], state: "minecraft:air"},
        {pos: [6, 2, 2], state: "minecraft:air"},
        {pos: [6, 2, 3], state: "minecraft:air"},
        {pos: [6, 2, 4], state: "minecraft:air"},
        {pos: [6, 2, 7], state: "minecraft:air"},
        {pos: [6, 2, 8], state: "minecraft:air"},
        {pos: [6, 2, 9], state: "minecraft:air"},
        {pos: [6, 2, 12], state: "minecraft:air"},
        {pos: [6, 2, 13], state: "minecraft:air"},
        {pos: [6, 2, 14], state: "minecraft:air"},
        {pos: [7, 2, 1], state: "minecraft:air"},
        {pos: [7, 2, 2], state: "minecraft:air"},
        {pos: [7, 2, 3], state: "minecraft:air"},
        {pos: [7, 2, 4], state: "minecraft:air"},
        {pos: [7, 2, 5], state: "minecraft:air"},
        {pos: [7, 2, 6], state: "minecraft:air"},
        {pos: [7, 2, 7], state: "minecraft:air"},
        {pos: [7, 2, 8], state: "minecraft:air"},
        {pos: [7, 2, 9], state: "minecraft:air"},
        {pos: [7, 2, 10], state: "minecraft:air"},
        {pos: [7, 2, 11], state: "minecraft:air"},
        {pos: [7, 2, 12], state: "minecraft:air"},
        {pos: [7, 2, 13], state: "minecraft:air"},
        {pos: [7, 2, 14], state: "minecraft:air"},
        {pos: [8, 2, 1], state: "minecraft:air"},
        {pos: [8, 2, 2], state: "minecraft:air"},
        {pos: [8, 2, 3], state: "minecraft:air"},
        {pos: [8, 2, 4], state: "minecraft:air"},
        {pos: [8, 2, 5], state: "minecraft:air"},
        {pos: [8, 2, 6], state: "minecraft:air"},
        {pos: [8, 2, 7], state: "minecraft:air"},
        {pos: [8, 2, 8], state: "minecraft:air"},
        {pos: [8, 2, 9], state: "minecraft:air"},
        {pos: [8, 2, 10], state: "minecraft:air"},
        {pos: [8, 2, 11], state: "minecraft:air"},
        {pos: [8, 2, 12], state: "minecraft:air"},
        {pos: [8, 2, 13], state: "minecraft:air"},
        {pos: [8, 2, 14], state: "minecraft:air"},
        {pos: [9, 2, 1], state: "minecraft:air"},
        {pos: [9, 2, 2], state: "minecraft:air"},
        {pos: [9, 2, 3], state: "minecraft:air"},
        {pos: [9, 2, 4], state: "minecraft:air"},
        {pos: [9, 2, 5], state: "minecraft:air"},
        {pos: [9, 2, 6], state: "minecraft:air"},
        {pos: [9, 2, 7], state: "minecraft:air"},
        {pos: [9, 2, 8], state: "minecraft:air"},
        {pos: [9, 2, 9], state: "minecraft:air"},
        {pos: [9, 2, 10], state: "minecraft:air"},
        {pos: [9, 2, 11], state: "minecraft:air"},
        {pos: [9, 2, 12], state: "minecraft:air"},
        {pos: [9, 2, 13], state: "minecraft:air"},
        {pos: [9, 2, 14], state: "minecraft:air"},
        {pos: [10, 2, 2], state: "minecraft:air"},
        {pos: [10, 2, 3], state: "minecraft:air"},
        {pos: [10, 2, 4], state: "minecraft:air"},
        {pos: [10, 2, 7], state: "minecraft:air"},
        {pos: [10, 2, 8], state: "minecraft:air"},
        {pos: [10, 2, 9], state: "minecraft:air"},
        {pos: [10, 2, 12], state: "minecraft:air"},
        {pos: [10, 2, 13], state: "minecraft:air"},
