{
    size: [11, 17, 5],
    data: [
        {pos: [0, 0, 0], state: "minecraft:tuff_bricks"},
        {pos: [0, 0, 1], state: "minecraft:tuff_bricks"},
        {pos: [0, 0, 2], state: "minecraft:tuff_bricks"},
        {pos: [0, 0, 3], state: "minecraft:tuff_bricks"},
        {pos: [0, 0, 4], state: "minecraft:tuff_bricks"},
        {pos: [1, 0, 0], state: "minecraft:tuff_bricks"},
        {pos: [1, 0, 1], state: "minecraft:tuff_bricks"},
        {pos: [1, 0, 2], state: "minecraft:tuff_bricks"},
        {pos: [1, 0, 3], state: "minecraft:tuff_bricks"},
        {pos: [1, 0, 4], state: "minecraft:tuff_bricks"},
        {pos: [2, 0, 0], state: "minecraft:tuff_bricks"},
        {pos: [2, 0, 1], state: "minecraft:tuff_bricks"},
        {pos: [2, 0, 2], state: "minecraft:tuff_bricks"},
        {pos: [2, 0, 3], state: "minecraft:tuff_bricks"},
        {pos: [2, 0, 4], state: "minecraft:tuff_bricks"},
        {pos: [3, 0, 0], state: "minecraft:tuff_bricks"},
        {pos: [3, 0, 1], state: "minecraft:tuff_bricks"},
        {pos: [3, 0, 2], state: "minecraft:tuff_bricks"},
        {pos: [3, 0, 3], state: "minecraft:tuff_bricks"},
        {pos: [3, 0, 4], state: "minecraft:tuff_bricks"},
        {pos: [4, 0, 0], state: "minecraft:tuff_bricks"},
        {pos: [4, 0, 1], state: "minecraft:tuff_bricks"},
        {pos: [4, 0, 2], state: "minecraft:tuff_bricks"},
        {pos: [4, 0, 3], state: "minecraft:tuff_bricks"},
        {pos: [4, 0, 4], state: "minecraft:tuff_bricks"},
        {pos: [5, 0, 0], state: "minecraft:tuff_bricks"},
        {pos: [5, 0, 1], state: "minecraft:tuff_bricks"},
        {pos: [5, 0, 2], state: "minecraft:tuff_bricks"},
        {pos: [5, 0, 3], state: "minecraft:tuff_bricks"},
        {pos: [5, 0, 4], state: "minecraft:tuff_bricks"},
        {pos: [6, 0, 0], state: "minecraft:tuff_bricks"},
        {pos: [6, 0, 1], state: "minecraft:tuff_bricks"},
        {pos: [6, 0, 2], state: "minecraft:tuff_bricks"},
        {pos: [6, 0, 3], state: "minecraft:tuff_bricks"},
        {pos: [6, 0, 4], state: "minecraft:tuff_bricks"},
        {pos: [7, 0, 0], state: "minecraft:tuff_bricks"},
        {pos: [7, 0, 1], state: "minecraft:tuff_bricks"},
        {pos: [7, 0, 2], state: "minecraft:tuff_bricks"},
        {pos: [7, 0, 3], state: "minecraft:tuff_bricks"},
        {pos: [7, 0, 4], state: "minecraft:tuff_bricks"},
        {pos: [8, 0, 0], state: "minecraft:tuff_bricks"},
        {pos: [8, 0, 1], state: "minecraft:tuff_bricks"},
        {pos: [8, 0, 2], state: "minecraft:tuff_bricks"},
        {pos: [8, 0, 3], state: "minecraft:tuff_bricks"},
        {pos: [8, 0, 4], state: "minecraft:tuff_bricks"},
        {pos: [9, 0, 0], state: "minecraft:tuff_bricks"},
        {pos: [9, 0, 1], state: "minecraft:tuff_bricks"},
        {pos: [9, 0, 2], state: "minecraft:tuff_bricks"},
        {pos: [9, 0, 3], state: "minecraft:tuff_bricks"},
        {pos: [9, 0, 4], state: "minecraft:tuff_bricks"},
        {pos: [10, 0, 0], state: "minecraft:tuff_bricks"},
        {pos: [10, 0, 1], state: "minecraft:tuff_bricks"},
        {pos: [10, 0, 2], state: "minecraft:tuff_bricks"},
        {pos: [10, 0, 3], state: "minecraft:tuff_bricks"},
        {pos: [10, 0, 4], state: "minecraft:tuff_bricks"},
        {pos: [0, 1, 0], state: "minecraft:tuff_bricks"},
        {pos: [0, 1, 1], state: "minecraft:tuff_bricks"},
        {pos: [0, 1, 2], state: "minecraft:tuff_bricks"},
        {pos: [0, 1, 3], state: "minecraft:tuff_bricks"},
        {pos: [0, 1, 4], state: "minecraft:tuff_bricks"},
        {pos: [1, 1, 0], state: "minecraft:tuff_bricks"},
        {pos: [1, 1, 1], state: "minecraft:tuff_bricks"},
        {pos: [1, 1, 2], state: "minecraft:tuff_bricks"},
        {pos: [1, 1, 3], state: "minecraft:tuff_bricks"},
        {pos: [1, 1, 4], state: "minecraft:tuff_bricks"},
        {pos: [2, 1, 0], state: "minecraft:tuff_bricks"},
        {pos: [2, 1, 1], state: "minecraft:tuff_bricks"},
        {pos: [2, 1, 2], state: "minecraft:tuff_bricks"},
        {pos: [2, 1, 3], state: "minecraft:tuff_bricks"},
        {pos: [2, 1, 4], state: "minecraft:tuff_bricks"},
        {pos: [3, 1, 0], state: "minecraft:tuff_bricks"},
        {pos: [3, 1, 1], state: "minecraft:waxed_oxidized_copper"},
        {pos: [3, 1, 2], state: "minecraft:waxed_oxidized_copper"},
        {pos: [3, 1, 3], state: "minecraft:waxed_oxidized_cut_copper"},
        {pos: [3, 1, 4], state: "minecraft:tuff_bricks"},
        {pos: [4, 1, 0], state: "minecraft:tuff_bricks"},
        {pos: [4, 1, 1], state: "minecraft:waxed_oxidized_copper"},
        {pos: [4, 1, 2], state: "minecraft:waxed_oxidized_cut_copper"},
        {pos: [4, 1, 3], state: "minecraft:waxed_oxidized_cut_copper"},
        {pos: [4, 1, 4], state: "minecraft:tuff_bricks"},
        {pos: [5, 1, 0], state: "minecraft:tuff_bricks"},
        {pos: [5, 1, 1], state: "minecraft:waxed_oxidized_cut_copper"},
        {pos: [5, 1, 2], state: "minecraft:waxed_oxidized_cut_copper"},
        {pos: [5, 1, 3], state: "minecraft:waxed_oxidized_cut_copper"},
        {pos: [5, 1, 4], state: "minecraft:tuff_bricks"},
        {pos: [6, 1, 0], state: "minecraft:tuff_bricks"},
        {pos: [6, 1, 1], state: "minecraft:waxed_oxidized_copper"},
        {pos: [6, 1, 2], state: "minecraft:waxed_oxidized_copper"},
        {pos: [6, 1, 3], state: "minecraft:waxed_oxidized_copper"},
        {pos: [6, 1, 4], state: "minecraft:tuff_bricks"},
        {pos: [7, 1, 0], state: "minecraft:tuff_bricks"},
        {pos: [7, 1, 1], state: "minecraft:waxed_oxidized_copper"},
        {pos: [7, 1, 2], state: "minecraft:waxed_oxidized_copper"},
        {pos: [7, 1, 3], state: "minecraft:waxed_oxidized_copper"},
        {pos: [7, 1, 4], state: "minecraft:tuff_bricks"},
        {pos: [8, 1, 0], state: "minecraft:tuff_bricks"},
        {pos: [8, 1, 1], state: "minecraft:waxed_oxidized_copper"},
        {pos: [8, 1, 2], state: "minecraft:waxed_oxidized_copper"},
        {pos: [8, 1, 3], state: "minecraft:waxed_oxidized_copper"},
        {pos: [8, 1, 4], state: "minecraft:tuff_bricks"},
        {pos: [9, 1, 0], state: "minecraft:tuff_bricks"},
        {pos: [9, 1, 1], state: "minecraft:waxed_oxidized_copper"},
        {pos: [9, 1, 2], state: "minecraft:waxed_oxidized_copper"},
        {pos: [9, 1, 3], state: "minecraft:waxed_oxidized_copper"},
        {pos: [9, 1, 4], state: "minecraft:tuff_bricks"},
        {pos: [10, 1, 0], state: "minecraft:tuff_bricks"},
        {pos: [10, 1, 1], state: "minecraft:waxed_oxidized_copper"},
        {pos: [10, 1, 2], state: "minecraft:waxed_oxidized_copper"},
        {pos: [10, 1, 3], state: "minecraft:waxed_oxidized_copper"},
        {pos: [10, 1, 4], state: "minecraft:tuff_bricks"},
        {pos: [0, 2, 0], state: "minecraft:tuff_bricks"},
        {pos: [0, 2, 1], state: "minecraft:tuff_bricks"},
        {pos: [0, 2, 2], state: "minecraft:tuff_bricks"},
        {pos: [0, 2, 3], state: "minecraft:tuff_bricks"},
        {pos: [0, 2, 4], state: "minecraft:tuff_bricks"},
        {pos: [1, 2, 0], state: "minecraft:tuff_bricks"},
        {pos: [1, 2, 1], state: "minecraft:tuff_bricks"},
        {pos: [1, 2, 2], state: "minecraft:tuff_bricks"},
        {pos: [1, 2, 3], state: "minecraft:tuff_bricks"},
        {pos: [1, 2, 4], state: "minecraft:tuff_bricks"},
        {pos: [2, 2, 0], state: "minecraft:waxed_copper_block"},
        {pos: [2, 2, 1], state: "minecraft:waxed_copper_block"},
        {pos: [2, 2, 2], state: "minecraft:waxed_copper_block"},
        {pos: [2, 2, 3], state: "minecraft:waxed_copper_block"},
        {pos: [2, 2, 4], state: "minecraft:waxed_copper_block"},
        {pos: [3, 2, 0], state: "minecraft:waxed_copper_block"},
        {pos: [3, 2, 1], state: "minecraft:waxed_oxidized_copper"},
        {pos: [3, 2, 4], state: "minecraft:waxed_copper_block"},
        {pos: [4, 2, 0], state: "minecraft:waxed_copper_block"},
        {pos: [4, 2, 1], state: "minecraft:waxed_oxidized_copper"},
        {pos: [4, 2, 4], state: "minecraft:waxed_copper_block"},
        {pos: [5, 2, 0], state: "minecraft:waxed_copper_block"},
        {pos: [5, 2, 4], state: "minecraft:waxed_copper_block"},
        {pos: [6, 2, 0], state: "minecraft:waxed_copper_block"},
        {pos: [6, 2, 4], state: "minecraft:waxed_copper_block"},
        {pos: [7, 2, 0], state: "minecraft:waxed_copper_block"},
        {pos: [7, 2, 4], state: "minecraft:waxed_copper_block"},
        {pos: [8, 2, 0], state: "minecraft:waxed_copper_block"},
        {pos: [8, 2, 4], state: "minecraft:waxed_copper_block"},
        {pos: [9, 2, 0], state: "minecraft:waxed_copper_block"},
        {pos: [9, 2, 4], state: "minecraft:waxed_copper_block"},
        {pos: [10, 2, 0], state: "minecraft:waxed_copper_block"},
        {pos: [10, 2, 4], state: "minecraft:waxed_copper_block"},
        {pos: [0, 3, 0], state: "minecraft:tuff_bricks"},
        {pos: [0, 3, 1], state: "minecraft:tuff_bricks"},
        {pos: [0, 3, 2], state: "minecraft:tuff_bricks"},
        {pos: [0, 3, 3], state: "minecraft:tuff_bricks"},
        {pos: [0, 3, 4], state: "minecraft:tuff_bricks"},
        {pos: [1, 3, 0], state: "minecraft:tuff_bricks"},
        {pos: [1, 3, 1], state: "minecraft:tuff_bricks"},
        {pos: [1, 3, 2], state: "minecraft:tuff_bricks"},
        {pos: [1, 3, 3], state: "minecraft:tuff_bricks"},
        {pos: [1, 3, 4], state: "minecraft:tuff_bricks"},
        {pos: [2, 3, 0], state: "minecraft:tuff_bricks"},
        {pos: [2, 3, 1], state: "minecraft:tuff_bricks"},
        {pos: [2, 3, 2], state: "minecraft:tuff_bricks"},
        {pos: [2, 3, 3], state: "minecraft:tuff_bricks"},
        {pos: [2, 3, 4], state: "minecraft:tuff_bricks"},
        {pos: [3, 3, 0], state: "minecraft:tuff_bricks"},
        {pos: [3, 3, 4], state: "minecraft:tuff_bricks"},
        {pos: [4, 3, 0], state: "minecraft:tuff_bricks"},
        {pos: [4, 3, 4], state: "minecraft:tuff_bricks"},
        {pos: [5, 3, 0], state: "minecraft:tuff_bricks"},
        {pos: [5, 3, 1], state: "minecraft:waxed_oxidized_copper"},
        {pos: [5, 3, 2], state: "minecraft:waxed_oxidized_copper"},
        {pos: [5, 3, 4], state: "minecraft:tuff_bricks"},
        {pos: [6, 3, 0], state: "minecraft:tuff_bricks"},
        {pos: [6, 3, 4], state: "minecraft:tuff_bricks"},
        {pos: [7, 3, 0], state: "minecraft:waxed_copper_bulb{powered:false,lit:true}"},
        {pos: [7, 3, 4], state: "minecraft:tuff_bricks"},
        {pos: [8, 3, 0], state: "minecraft:tuff_bricks"},
        {pos: [8, 3, 4], state: "minecraft:tuff_bricks"},
        {pos: [9, 3, 0], state: "minecraft:tuff_bricks"},
        {pos: [9, 3, 4], state: "minecraft:tuff_bricks"},
        {pos: [10, 3, 0], state: "minecraft:tuff_bricks"},
        {pos: [10, 3, 4], state: "minecraft:tuff_bricks"},
        {pos: [0, 4, 0], state: "minecraft:tuff_bricks"},
        {pos: [0, 4, 1], state: "minecraft:tuff_bricks"},
        {pos: [0, 4, 2], state: "minecraft:tuff_bricks"},
        {pos: [0, 4, 3], state: "minecraft:tuff_bricks"},
        {pos: [0, 4, 4], state: "minecraft:tuff_bricks"},
        {pos: [1, 4, 0], state: "minecraft:tuff_bricks"},
        {pos: [1, 4, 1], state: "minecraft:tuff_bricks"},
        {pos: [1, 4, 2], state: "minecraft:tuff_bricks"},
        {pos: [1, 4, 3], state: "minecraft:tuff_bricks"},
        {pos: [1, 4, 4], state: "minecraft:tuff_bricks"},
        {pos: [2, 4, 0], state: "minecraft:chiseled_tuff_bricks"},
        {pos: [2, 4, 1], state: "minecraft:chiseled_tuff_bricks"},
        {pos: [2, 4, 2], state: "minecraft:chiseled_tuff_bricks"},
        {pos: [2, 4, 3], state: "minecraft:chiseled_tuff_bricks"},
        {pos: [2, 4, 4], state: "minecraft:chiseled_tuff_bricks"},
        {pos: [3, 4, 0], state: "minecraft:chiseled_tuff_bricks"},
        {pos: [3, 4, 4], state: "minecraft:chiseled_tuff_bricks"},
        {pos: [4, 4, 0], state: "minecraft:chiseled_tuff_bricks"},
        {pos: [4, 4, 3], state: "minecraft:waxed_oxidized_copper"},
        {pos: [4, 4, 4], state: "minecraft:chiseled_tuff_bricks"},
        {pos: [5, 4, 0], state: "minecraft:chiseled_tuff_bricks"},
        {pos: [5, 4, 3], state: "minecraft:waxed_oxidized_copper"},
        {pos: [5, 4, 4], state: "minecraft:chiseled_tuff_bricks"},
        {pos: [6, 4, 0], state: "minecraft:chiseled_tuff_bricks"},
        {pos: [6, 4, 4], state: "minecraft:chiseled_tuff_bricks"},
        {pos: [7, 4, 0], state: "minecraft:chiseled_tuff_bricks"},
        {pos: [7, 4, 4], state: "minecraft:chiseled_tuff_bricks"},
        {pos: [8, 4, 0], state: "minecraft:chiseled_tuff_bricks"},
        {pos: [8, 4, 4], state: "minecraft:chiseled_tuff_bricks"},
        {pos: [9, 4, 0], state: "minecraft:chiseled_tuff_bricks"},
        {pos: [9, 4, 4], state: "minecraft:chiseled_tuff_bricks"},
        {pos: [10, 4, 0], state: "minecraft:chiseled_tuff_bricks"},
        {pos: [10, 4, 4], state: "minecraft:chiseled_tuff_bricks"},
        {pos: [0, 5, 0], state: "minecraft:tuff_bricks"},
        {pos: [0, 5, 1], state: "minecraft:tuff_bricks"},
        {pos: [0, 5, 2], state: "minecraft:tuff_bricks"},
        {pos: [0, 5, 3], state: "minecraft:tuff_bricks"},
        {pos: [0, 5, 4], state: "minecraft:tuff_bricks"},
        {pos: [1, 5, 0], state: "minecraft:tuff_bricks"},
        {pos: [1, 5, 1], state: "minecraft:tuff_bricks"},
        {pos: [1, 5, 2], state: "minecraft:tuff_bricks"},
        {pos: [1, 5, 3], state: "minecraft:tuff_bricks"},
        {pos: [1, 5, 4], state: "minecraft:tuff_bricks"},
        {pos: [2, 5, 0], state: "minecraft:tuff_bricks"},
        {pos: [2, 5, 1], state: "minecraft:tuff_bricks"},
        {pos: [2, 5, 2], state: "minecraft:tuff_bricks"},
        {pos: [2, 5, 3], state: "minecraft:tuff_bricks"},
        {pos: [2, 5, 4], state: "minecraft:tuff_bricks"},
        {pos: [3, 5, 0], state: "minecraft:tuff_bricks"},
        {pos: [3, 5, 2], state: "minecraft:waxed_oxidized_copper"},
        {pos: [3, 5, 3], state: "minecraft:waxed_oxidized_copper"},
        {pos: [3, 5, 4], state: "minecraft:tuff_bricks"},
        {pos: [4, 5, 0], state: "minecraft:tuff_bricks"},
        {pos: [4, 5, 4], state: "minecraft:tuff_bricks"},
        {pos: [5, 5, 0], state: "minecraft:tuff_bricks"},
        {pos: [5, 5, 4], state: "minecraft:tuff_bricks"},
        {pos: [6, 5, 0], state: "minecraft:tuff_bricks"},
        {pos: [6, 5, 4], state: "minecraft:tuff_bricks"},
        {pos: [7, 5, 0], state: "minecraft:tuff_bricks"},
        {pos: [7, 5, 4], state: "minecraft:tuff_bricks"},
        {pos: [8, 5, 0], state: "minecraft:tuff_bricks"},
        {pos: [8, 5, 4], state: "minecraft:tuff_bricks"},
        {pos: [9, 5, 0], state: "minecraft:tuff_bricks"},
        {pos: [9, 5, 4], state: "minecraft:tuff_bricks"},
        {pos: [10, 5, 0], state: "minecraft:tuff_bricks"},
        {pos: [10, 5, 4], state: "minecraft:tuff_bricks"},
        {pos: [0, 6, 0], state: "minecraft:tuff_bricks"},
        {pos: [0, 6, 1], state: "minecraft:tuff_bricks"},
        {pos: [0, 6, 2], state: "minecraft:tuff_bricks"},
        {pos: [0, 6, 3], state: "minecraft:tuff_bricks"},
        {pos: [0, 6, 4], state: "minecraft:tuff_bricks"},
        {pos: [1, 6, 0], state: "minecraft:tuff_bricks"},
        {pos: [1, 6, 1], state: "minecraft:tuff_bricks"},
        {pos: [1, 6, 2], state: "minecraft:tuff_bricks"},
        {pos: [1, 6, 3], state: "minecraft:tuff_bricks"},
        {pos: [1, 6, 4], state: "minecraft:tuff_bricks"},
        {pos: [2, 6, 0], state: "minecraft:tuff_bricks"},
        {pos: [2, 6, 1], state: "minecraft:polished_tuff"},
        {pos: [2, 6, 2], state: "minecraft:polished_tuff"},
        {pos: [2, 6, 3], state: "minecraft:polished_tuff"},
        {pos: [2, 6, 4], state: "minecraft:tuff_bricks"},
        {pos: [3, 6, 0], state: "minecraft:tuff_bricks"},
        {pos: [3, 6, 1], state: "minecraft:waxed_oxidized_copper"},
        {pos: [3, 6, 4], state: "minecraft:tuff_bricks"},
        {pos: [4, 6, 0], state: "minecraft:tuff_bricks"},
        {pos: [4, 6, 1], state: "minecraft:waxed_oxidized_copper"},
        {pos: [4, 6, 4], state: "minecraft:tuff_bricks"},
        {pos: [5, 6, 0], state: "minecraft:tuff_bricks"},
        {pos: [5, 6, 4], state: "minecraft:tuff_bricks"},
        {pos: [6, 6, 0], state: "minecraft:tuff_bricks"},
        {pos: [6, 6, 4], state: "minecraft:tuff_bricks"},
        {pos: [7, 6, 0], state: "minecraft:tuff_bricks"},
        {pos: [7, 6, 4], state: "minecraft:tuff_bricks"},
        {pos: [8, 6, 0], state: "minecraft:tuff_bricks"},
        {pos: [8, 6, 1], state: "minecraft:polished_tuff"},
        {pos: [8, 6, 2], state: "minecraft:polished_tuff"},
        {pos: [8, 6, 3], state: "minecraft:polished_tuff"},
        {pos: [8, 6, 4], state: "minecraft:tuff_bricks"},
        {pos: [9, 6, 0], state: "minecraft:tuff_bricks"},
        {pos: [9, 6, 1], state: "minecraft:polished_tuff"},
        {pos: [9, 6, 2], state: "minecraft:polished_tuff"},
        {pos: [9, 6, 3], state: "minecraft:polished_tuff"},
        {pos: [9, 6, 4], state: "minecraft:tuff_bricks"},
        {pos: [10, 6, 0], state: "minecraft:tuff_bricks"},
        {pos: [10, 6, 1], state: "minecraft:polished_tuff"},
        {pos: [10, 6, 2], state: "minecraft:polished_tuff"},
        {pos: [10, 6, 3], state: "minecraft:polished_tuff"},
        {pos: [10, 6, 4], state: "minecraft:tuff_bricks"},
        {pos: [0, 7, 0], state: "minecraft:tuff_bricks"},
        {pos: [0, 7, 1], state: "minecraft:tuff_bricks"},
        {pos: [0, 7, 2], state: "minecraft:tuff_bricks"},
        {pos: [0, 7, 3], state: "minecraft:tuff_bricks"},
        {pos: [0, 7, 4], state: "minecraft:tuff_bricks"},
        {pos: [1, 7, 0], state: "minecraft:tuff_bricks"},
        {pos: [1, 7, 1], state: "minecraft:tuff_bricks"},
        {pos: [1, 7, 2], state: "minecraft:tuff_bricks"},
        {pos: [1, 7, 3], state: "minecraft:tuff_bricks"},
        {pos: [1, 7, 4], state: "minecraft:tuff_bricks"},
        {pos: [2, 7, 0], state: "minecraft:tuff_bricks"},
        {pos: [2, 7, 1], state: "minecraft:tuff_bricks"},
        {pos: [2, 7, 2], state: "minecraft:tuff_bricks"},
        {pos: [2, 7, 3], state: "minecraft:tuff_bricks"},
        {pos: [2, 7, 4], state: "minecraft:tuff_bricks"},
        {pos: [3, 7, 0], state: "minecraft:tuff_bricks"},
        {pos: [3, 7, 4], state: "minecraft:tuff_bricks"},
        {pos: [4, 7, 0], state: "minecraft:tuff_bricks"},
        {pos: [4, 7, 4], state: "minecraft:tuff_bricks"},
        {pos: [5, 7, 0], state: "minecraft:tuff_bricks"},
        {pos: [5, 7, 1], state: "minecraft:waxed_oxidized_copper"},
        {pos: [5, 7, 2], state: "minecraft:waxed_oxidized_copper"},
        {pos: [5, 7, 4], state: "minecraft:tuff_bricks"},
        {pos: [6, 7, 0], state: "minecraft:tuff_bricks"},
        {pos: [6, 7, 1], state: "minecraft:polished_tuff"},
        {pos: [6, 7, 2], state: "minecraft:polished_tuff"},
        {pos: [6, 7, 3], state: "minecraft:polished_tuff"},
        {pos: [6, 7, 4], state: "minecraft:tuff_bricks"},
        {pos: [7, 7, 0], state: "minecraft:tuff_bricks"},
        {pos: [7, 7, 1], state: "minecraft:polished_tuff"},
        {pos: [7, 7, 2], state: "minecraft:polished_tuff"},
        {pos: [7, 7, 3], state: "minecraft:polished_tuff"},
        {pos: [7, 7, 4], state: "minecraft:tuff_bricks"},
        {pos: [8, 7, 0], state: "minecraft:tuff_bricks"},
        {pos: [8, 7, 1], state: "minecraft:tuff_bricks"},
        {pos: [8, 7, 2], state: "minecraft:tuff_bricks"},
        {pos: [8, 7, 3], state: "minecraft:tuff_bricks"},
        {pos: [8, 7, 4], state: "minecraft:tuff_bricks"},
        {pos: [9, 7, 0], state: "minecraft:tuff_bricks"},
        {pos: [9, 7, 1], state: "minecraft:tuff_bricks"},
        {pos: [9, 7, 2], state: "minecraft:tuff_bricks"},
        {pos: [9, 7, 3], state: "minecraft:tuff_bricks"},
        {pos: [9, 7, 4], state: "minecraft:tuff_bricks"},
        {pos: [10, 7, 0], state: "minecraft:tuff_bricks"},
        {pos: [10, 7, 1], state: "minecraft:tuff_bricks"},
        {pos: [10, 7, 2], state: "minecraft:tuff_bricks"},
        {pos: [10, 7, 3], state: "minecraft:tuff_bricks"},
        {pos: [10, 7, 4], state: "minecraft:tuff_bricks"},
        {pos: [0, 8, 0], state: "minecraft:tuff_bricks"},
        {pos: [0, 8, 1], state: "minecraft:tuff_bricks"},
        {pos: [0, 8, 2], state: "minecraft:tuff_bricks"},
        {pos: [0, 8, 3], state: "minecraft:tuff_bricks"},
        {pos: [0, 8, 4], state: "minecraft:tuff_bricks"},
        {pos: [1, 8, 0], state: "minecraft:tuff_bricks"},
        {pos: [1, 8, 1], state: "minecraft:tuff_bricks"},
        {pos: [1, 8, 2], state: "minecraft:tuff_bricks"},
        {pos: [1, 8, 3], state: "minecraft:tuff_bricks"},
        {pos: [1, 8, 4], state: "minecraft:tuff_bricks"},
        {pos: [2, 8, 0], state: "minecraft:tuff_bricks"},
        {pos: [2, 8, 1], state: "minecraft:tuff_bricks"},
        {pos: [2, 8, 2], state: "minecraft:tuff_bricks"},
        {pos: [2, 8, 3], state: "minecraft:tuff_bricks"},
        {pos: [2, 8, 4], state: "minecraft:tuff_bricks"},
        {pos: [3, 8, 0], state: "minecraft:tuff_bricks"},
        {pos: [3, 8, 4], state: "minecraft:tuff_bricks"},
        {pos: [4, 8, 0], state: "minecraft:tuff_bricks"},
        {pos: [4, 8, 3], state: "minecraft:waxed_oxidized_copper"},
        {pos: [4, 8, 4], state: "minecraft:tuff_bricks"},
        {pos: [5, 8, 0], state: "minecraft:tuff_bricks"},
        {pos: [5, 8, 3], state: "minecraft:waxed_oxidized_copper"},
        {pos: [5, 8, 4], state: "minecraft:tuff_bricks"},
        {pos: [6, 8, 0], state: "minecraft:tuff_bricks"},
        {pos: [6, 8, 1], state: "minecraft:tuff_bricks"},
        {pos: [6, 8, 2], state: "minecraft:tuff_bricks"},
        {pos: [6, 8, 3], state: "minecraft:tuff_bricks"},
        {pos: [6, 8, 4], state: "minecraft:tuff_bricks"},
        {pos: [7, 8, 0], state: "minecraft:tuff_bricks"},
        {pos: [7, 8, 1], state: "minecraft:tuff_bricks"},
        {pos: [7, 8, 2], state: "minecraft:tuff_bricks"},
        {pos: [7, 8, 3], state: "minecraft:tuff_bricks"},
        {pos: [7, 8, 4], state: "minecraft:tuff_bricks"},
        {pos: [8, 8, 0], state: "minecraft:tuff_bricks"},
        {pos: [8, 8, 1], state: "minecraft:tuff_bricks"},
        {pos: [8, 8, 2], state: "minecraft:tuff_bricks"},
        {pos: [8, 8, 3], state: "minecraft:tuff_bricks"},
        {pos: [8, 8, 4], state: "minecraft:tuff_bricks"},
        {pos: [9, 8, 0], state: "minecraft:tuff_bricks"},
        {pos: [9, 8, 1], state: "minecraft:tuff_bricks"},
        {pos: [9, 8, 2], state: "minecraft:tuff_bricks"},
        {pos: [9, 8, 3], state: "minecraft:tuff_bricks"},
        {pos: [9, 8, 4], state: "minecraft:tuff_bricks"},
        {pos: [10, 8, 0], state: "minecraft:tuff_bricks"},
        {pos: [10, 8, 1], state: "minecraft:tuff_bricks"},
        {pos: [10, 8, 2], state: "minecraft:tuff_bricks"},
        {pos: [10, 8, 3], state: "minecraft:tuff_bricks"},
        {pos: [10, 8, 4], state: "minecraft:tuff_bricks"},
        {pos: [0, 9, 0], state: "minecraft:tuff_bricks"},
        {pos: [0, 9, 1], state: "minecraft:tuff_bricks"},
        {pos: [0, 9, 2], state: "minecraft:tuff_bricks"},
        {pos: [0, 9, 3], state: "minecraft:tuff_bricks"},
        {pos: [0, 9, 4], state: "minecraft:tuff_bricks"},
        {pos: [1, 9, 0], state: "minecraft:tuff_bricks"},
        {pos: [1, 9, 1], state: "minecraft:tuff_bricks"},
        {pos: [1, 9, 2], state: "minecraft:tuff_bricks"},
        {pos: [1, 9, 3], state: "minecraft:tuff_bricks"},
        {pos: [1, 9, 4], state: "minecraft:tuff_bricks"},
        {pos: [2, 9, 0], state: "minecraft:tuff_bricks"},
        {pos: [2, 9, 1], state: "minecraft:tuff_bricks"},
        {pos: [2, 9, 2], state: "minecraft:tuff_bricks"},
        {pos: [2, 9, 3], state: "minecraft:tuff_bricks"},
        {pos: [2, 9, 4], state: "minecraft:tuff_bricks"},
        {pos: [3, 9, 0], state: "minecraft:tuff_bricks"},
        {pos: [3, 9, 2], state: "minecraft:waxed_oxidized_copper"},
        {pos: [3, 9, 3], state: "minecraft:waxed_oxidized_copper"},
        {pos: [3, 9, 4], state: "minecraft:tuff_bricks"},
        {pos: [4, 9, 0], state: "minecraft:tuff_bricks"},
        {pos: [4, 9, 4], state: "minecraft:tuff_bricks"},
        {pos: [5, 9, 0], state: "minecraft:tuff_bricks"},
        {pos: [5, 9, 4], state: "minecraft:tuff_bricks"},
        {pos: [6, 9, 0], state: "minecraft:tuff_bricks"},
        {pos: [6, 9, 1], state: "minecraft:tuff_bricks"},
        {pos: [6, 9, 2], state: "minecraft:tuff_bricks"},
        {pos: [6, 9, 3], state: "minecraft:tuff_bricks"},
        {pos: [6, 9, 4], state: "minecraft:tuff_bricks"},
        {pos: [7, 9, 0], state: "minecraft:tuff_bricks"},
        {pos: [7, 9, 1], state: "minecraft:tuff_bricks"},
        {pos: [7, 9, 2], state: "minecraft:tuff_bricks"},
        {pos: [7, 9, 3], state: "minecraft:tuff_bricks"},
        {pos: [7, 9, 4], state: "minecraft:tuff_bricks"},
        {pos: [8, 9, 0], state: "minecraft:tuff_bricks"},
        {pos: [8, 9, 1], state: "minecraft:tuff_bricks"},
        {pos: [8, 9, 2], state: "minecraft:tuff_bricks"},
        {pos: [8, 9, 3], state: "minecraft:tuff_bricks"},
        {pos: [8, 9, 4], state: "minecraft:tuff_bricks"},
        {pos: [9, 9, 0], state: "minecraft:tuff_bricks"},
        {pos: [9, 9, 1], state: "minecraft:tuff_bricks"},
        {pos: [9, 9, 2], state: "minecraft:tuff_bricks"},
        {pos: [9, 9, 3], state: "minecraft:tuff_bricks"},
        {pos: [9, 9, 4], state: "minecraft:tuff_bricks"},
        {pos: [10, 9, 0], state: "minecraft:tuff_bricks"},
        {pos: [10, 9, 1], state: "minecraft:tuff_bricks"},
        {pos: [10, 9, 2], state: "minecraft:tuff_bricks"},
        {pos: [10, 9, 3], state: "minecraft:tuff_bricks"},
        {pos: [10, 9, 4], state: "minecraft:tuff_bricks"},
        {pos: [0, 10, 0], state: "minecraft:tuff_bricks"},
        {pos: [0, 10, 1], state: "minecraft:tuff_bricks"},
        {pos: [0, 10, 2], state: "minecraft:tuff_bricks"},
        {pos: [0, 10, 3], state: "minecraft:tuff_bricks"},
        {pos: [0, 10, 4], state: "minecraft:tuff_bricks"},
        {pos: [1, 10, 0], state: "minecraft:tuff_bricks"},
        {pos: [1, 10, 1], state: "minecraft:tuff_bricks"},
        {pos: [1, 10, 2], state: "minecraft:tuff_bricks"},
        {pos: [1, 10, 3], state: "minecraft:tuff_bricks"},
        {pos: [1, 10, 4], state: "minecraft:tuff_bricks"},
        {pos: [2, 10, 0], state: "minecraft:tuff_bricks"},
        {pos: [2, 10, 1], state: "minecraft:tuff_bricks"},
        {pos: [2, 10, 2], state: "minecraft:tuff_bricks"},
        {pos: [2, 10, 3], state: "minecraft:tuff_bricks"},
        {pos: [2, 10, 4], state: "minecraft:tuff_bricks"},
        {pos: [3, 10, 0], state: "minecraft:tuff_bricks"},
        {pos: [3, 10, 1], state: "minecraft:waxed_oxidized_copper"},
        {pos: [3, 10, 4], state: "minecraft:tuff_bricks"},
        {pos: [4, 10, 0], state: "minecraft:tuff_bricks"},
        {pos: [4, 10, 1], state: "minecraft:waxed_oxidized_copper"},
        {pos: [4, 10, 4], state: "minecraft:tuff_bricks"},
        {pos: [5, 10, 0], state: "minecraft:tuff_bricks"},
        {pos: [5, 10, 4], state: "minecraft:tuff_bricks"},
        {pos: [6, 10, 0], state: "minecraft:tuff_bricks"},
        {pos: [6, 10, 1], state: "minecraft:polished_tuff"},
        {pos: [6, 10, 2], state: "minecraft:polished_tuff"},
        {pos: [6, 10, 3], state: "minecraft:polished_tuff"},
        {pos: [6, 10, 4], state: "minecraft:tuff_bricks"},
        {pos: [7, 10, 0], state: "minecraft:tuff_bricks"},
        {pos: [7, 10, 1], state: "minecraft:polished_tuff"},
        {pos: [7, 10, 2], state: "minecraft:polished_tuff"},
        {pos: [7, 10, 3], state: "minecraft:polished_tuff"},
        {pos: [7, 10, 4], state: "minecraft:tuff_bricks"},
        {pos: [8, 10, 0], state: "minecraft:tuff_bricks"},
        {pos: [8, 10, 1], state: "minecraft:tuff_bricks"},
        {pos: [8, 10, 2], state: "minecraft:tuff_bricks"},
        {pos: [8, 10, 3], state: "minecraft:tuff_bricks"},
        {pos: [8, 10, 4], state: "minecraft:tuff_bricks"},
        {pos: [9, 10, 0], state: "minecraft:tuff_bricks"},
        {pos: [9, 10, 1], state: "minecraft:tuff_bricks"},
        {pos: [9, 10, 2], state: "minecraft:tuff_bricks"},
        {pos: [9, 10, 3], state: "minecraft:tuff_bricks"},
        {pos: [9, 10, 4], state: "minecraft:tuff_bricks"},
        {pos: [10, 10, 0], state: "minecraft:tuff_bricks"},
        {pos: [10, 10, 1], state: "minecraft:tuff_bricks"},
        {pos: [10, 10, 2], state: "minecraft:tuff_bricks"},
        {pos: [10, 10, 3], state: "minecraft:tuff_bricks"},
        {pos: [10, 10, 4], state: "minecraft:tuff_bricks"},
        {pos: [0, 11, 0], state: "minecraft:tuff_bricks"},
        {pos: [0, 11, 1], state: "minecraft:tuff_bricks"},
        {pos: [0, 11, 2], state: "minecraft:tuff_bricks"},
        {pos: [0, 11, 3], state: "minecraft:tuff_bricks"},
        {pos: [0, 11, 4], state: "minecraft:tuff_bricks"},
        {pos: [1, 11, 0], state: "minecraft:tuff_bricks"},
        {pos: [1, 11, 1], state: "minecraft:tuff_bricks"},
        {pos: [1, 11, 2], state: "minecraft:tuff_bricks"},
        {pos: [1, 11, 3], state: "minecraft:tuff_bricks"},
        {pos: [1, 11, 4], state: "minecraft:tuff_bricks"},
        {pos: [2, 11, 0], state: "minecraft:tuff_bricks"},
        {pos: [2, 11, 1], state: "minecraft:tuff_bricks"},
        {pos: [2, 11, 2], state: "minecraft:tuff_bricks"},
        {pos: [2, 11, 3], state: "minecraft:tuff_bricks"},
        {pos: [2, 11, 4], state: "minecraft:tuff_bricks"},
        {pos: [3, 11, 0], state: "minecraft:tuff_bricks"},
        {pos: [3, 11, 4], state: "minecraft:tuff_bricks"},
        {pos: [4, 11, 0], state: "minecraft:tuff_bricks"},
        {pos: [4, 11, 4], state: "minecraft:tuff_bricks"},
        {pos: [5, 11, 0], state: "minecraft:tuff_bricks"},
        {pos: [5, 11, 1], state: "minecraft:waxed_oxidized_copper"},
        {pos: [5, 11, 2], state: "minecraft:waxed_oxidized_copper"},
        {pos: [5, 11, 4], state: "minecraft:tuff_bricks"},
        {pos: [6, 11, 0], state: "minecraft:tuff_bricks"},
        {pos: [6, 11, 1], state: "minecraft:waxed_oxidized_copper"},
        {pos: [6, 11, 2], state: "minecraft:waxed_oxidized_copper"},
        {pos: [6, 11, 3], state: "minecraft:waxed_copper_block"},
        {pos: [6, 11, 4], state: "minecraft:waxed_copper_block"},
        {pos: [7, 11, 0], state: "minecraft:tuff_bricks"},
        {pos: [7, 11, 1], state: "minecraft:waxed_oxidized_copper"},
        {pos: [7, 11, 2], state: "minecraft:waxed_oxidized_copper"},
        {pos: [7, 11, 3], state: "minecraft:waxed_oxidized_copper"},
        {pos: [7, 11, 4], state: "minecraft:tuff_bricks"},
        {pos: [8, 11, 0], state: "minecraft:tuff_bricks"},
        {pos: [8, 11, 1], state: "minecraft:waxed_oxidized_copper"},
        {pos: [8, 11, 2], state: "minecraft:waxed_oxidized_copper"},
        {pos: [8, 11, 3], state: "minecraft:waxed_oxidized_copper"},
        {pos: [8, 11, 4], state: "minecraft:tuff_bricks"},
        {pos: [9, 11, 0], state: "minecraft:tuff_bricks"},
        {pos: [9, 11, 1], state: "minecraft:waxed_oxidized_copper"},
        {pos: [9, 11, 2], state: "minecraft:waxed_oxidized_copper"},
        {pos: [9, 11, 3], state: "minecraft:waxed_oxidized_copper"},
        {pos: [9, 11, 4], state: "minecraft:tuff_bricks"},
        {pos: [10, 11, 0], state: "minecraft:tuff_bricks"},
        {pos: [10, 11, 1], state: "minecraft:waxed_oxidized_copper"},
        {pos: [10, 11, 2], state: "minecraft:waxed_oxidized_copper"},
        {pos: [10, 11, 3], state: "minecraft:waxed_oxidized_copper"},
        {pos: [10, 11, 4], state: "minecraft:tuff_bricks"},
        {pos: [0, 12, 0], state: "minecraft:tuff_bricks"},
        {pos: [0, 12, 1], state: "minecraft:tuff_bricks"},
        {pos: [0, 12, 2], state: "minecraft:tuff_bricks"},
        {pos: [0, 12, 3], state: "minecraft:tuff_bricks"},
        {pos: [0, 12, 4], state: "minecraft:tuff_bricks"},
        {pos: [1, 12, 0], state: "minecraft:tuff_bricks"},
        {pos: [1, 12, 1], state: "minecraft:tuff_bricks"},
        {pos: [1, 12, 2], state: "minecraft:tuff_bricks"},
        {pos: [1, 12, 3], state: "minecraft:tuff_bricks"},
        {pos: [1, 12, 4], state: "minecraft:tuff_bricks"},
        {pos: [2, 12, 0], state: "minecraft:waxed_copper_block"},
        {pos: [2, 12, 1], state: "minecraft:waxed_copper_block"},
        {pos: [2, 12, 2], state: "minecraft:waxed_copper_block"},
        {pos: [2, 12, 3], state: "minecraft:waxed_copper_block"},
        {pos: [2, 12, 4], state: "minecraft:waxed_copper_block"},
        {pos: [3, 12, 0], state: "minecraft:waxed_copper_block"},
        {pos: [3, 12, 4], state: "minecraft:waxed_copper_block"},
        {pos: [4, 12, 0], state: "minecraft:waxed_copper_block"},
        {pos: [4, 12, 4], state: "minecraft:waxed_copper_block"},
        {pos: [5, 12, 0], state: "minecraft:waxed_copper_block"},
        {pos: [5, 12, 4], state: "minecraft:waxed_copper_block"},
        {pos: [6, 12, 0], state: "minecraft:waxed_copper_block"},
        {pos: [6, 12, 4], state: "minecraft:waxed_copper_block"},
        {pos: [7, 12, 0], state: "minecraft:waxed_copper_block"},
        {pos: [7, 12, 4], state: "minecraft:waxed_copper_block"},
        {pos: [8, 12, 0], state: "minecraft:waxed_copper_block"},
        {pos: [8, 12, 4], state: "minecraft:waxed_copper_block"},
        {pos: [9, 12, 0], state: "minecraft:waxed_copper_block"},
        {pos: [9, 12, 4], state: "minecraft:waxed_copper_block"},
        {pos: [10, 12, 0], state: "minecraft:waxed_copper_block"},
        {pos: [10, 12, 4], state: "minecraft:waxed_copper_block"},
        {pos: [0, 13, 0], state: "minecraft:tuff_bricks"},
        {pos: [0, 13, 1], state: "minecraft:tuff_bricks"},
        {pos: [0, 13, 2], state: "minecraft:tuff_bricks"},
        {pos: [0, 13, 3], state: "minecraft:tuff_bricks"},
        {pos: [0, 13, 4], state: "minecraft:tuff_bricks"},
        {pos: [1, 13, 0], state: "minecraft:tuff_bricks"},
        {pos: [1, 13, 1], state: "minecraft:tuff_bricks"},
        {pos: [1, 13, 2], state: "minecraft:tuff_bricks"},
        {pos: [1, 13, 3], state: "minecraft:tuff_bricks"},
        {pos: [1, 13, 4], state: "minecraft:tuff_bricks"},
        {pos: [2, 13, 0], state: "minecraft:tuff_bricks"},
        {pos: [2, 13, 1], state: "minecraft:tuff_bricks"},
        {pos: [2, 13, 2], state: "minecraft:waxed_copper_bulb{powered:false,lit:true}"},
        {pos: [2, 13, 3], state: "minecraft:tuff_bricks"},
        {pos: [2, 13, 4], state: "minecraft:tuff_bricks"},
        {pos: [3, 13, 0], state: "minecraft:tuff_bricks"},
        {pos: [3, 13, 4], state: "minecraft:tuff_bricks"},
        {pos: [4, 13, 0], state: "minecraft:tuff_bricks"},
        {pos: [4, 13, 4], state: "minecraft:tuff_bricks"},
        {pos: [5, 13, 0], state: "minecraft:tuff_bricks"},
        {pos: [5, 13, 4], state: "minecraft:tuff_bricks"},
        {pos: [6, 13, 0], state: "minecraft:tuff_bricks"},
        {pos: [6, 13, 4], state: "minecraft:waxed_copper_bulb{powered:false,lit:true}"},
        {pos: [7, 13, 0], state: "minecraft:tuff_bricks"},
        {pos: [7, 13, 4], state: "minecraft:tuff_bricks"},
        {pos: [8, 13, 0], state: "minecraft:tuff_bricks"},
        {pos: [8, 13, 4], state: "minecraft:tuff_bricks"},
        {pos: [9, 13, 0], state: "minecraft:tuff_bricks"},
        {pos: [9, 13, 4], state: "minecraft:tuff_bricks"},
        {pos: [10, 13, 0], state: "minecraft:tuff_bricks"},
        {pos: [10, 13, 4], state: "minecraft:tuff_bricks"},
        {pos: [0, 14, 0], state: "minecraft:tuff_bricks"},
        {pos: [0, 14, 1], state: "minecraft:tuff_bricks"},
        {pos: [0, 14, 2], state: "minecraft:tuff_bricks"},
        {pos: [0, 14, 3], state: "minecraft:tuff_bricks"},
        {pos: [0, 14, 4], state: "minecraft:tuff_bricks"},
        {pos: [1, 14, 0], state: "minecraft:tuff_bricks"},
        {pos: [1, 14, 1], state: "minecraft:tuff_bricks"},
        {pos: [1, 14, 2], state: "minecraft:tuff_bricks"},
        {pos: [1, 14, 3], state: "minecraft:tuff_bricks"},
        {pos: [1, 14, 4], state: "minecraft:tuff_bricks"},
        {pos: [2, 14, 0], state: "minecraft:chiseled_tuff_bricks"},
        {pos: [2, 14, 1], state: "minecraft:chiseled_tuff_bricks"},
        {pos: [2, 14, 2], state: "minecraft:chiseled_tuff_bricks"},
        {pos: [2, 14, 3], state: "minecraft:chiseled_tuff_bricks"},
        {pos: [2, 14, 4], state: "minecraft:chiseled_tuff_bricks"},
        {pos: [3, 14, 0], state: "minecraft:chiseled_tuff_bricks"},
        {pos: [3, 14, 4], state: "minecraft:chiseled_tuff_bricks"},
        {pos: [4, 14, 0], state: "minecraft:chiseled_tuff_bricks"},
        {pos: [4, 14, 4], state: "minecraft:chiseled_tuff_bricks"},
        {pos: [5, 14, 0], state: "minecraft:chiseled_tuff_bricks"},
        {pos: [5, 14, 4], state: "minecraft:chiseled_tuff_bricks"},
        {pos: [6, 14, 0], state: "minecraft:chiseled_tuff_bricks"},
        {pos: [6, 14, 4], state: "minecraft:chiseled_tuff_bricks"},
        {pos: [7, 14, 0], state: "minecraft:chiseled_tuff_bricks"},
        {pos: [7, 14, 4], state: "minecraft:chiseled_tuff_bricks"},
        {pos: [8, 14, 0], state: "minecraft:chiseled_tuff_bricks"},
        {pos: [8, 14, 4], state: "minecraft:chiseled_tuff_bricks"},
        {pos: [9, 14, 0], state: "minecraft:chiseled_tuff_bricks"},
        {pos: [9, 14, 4], state: "minecraft:chiseled_tuff_bricks"},
        {pos: [10, 14, 0], state: "minecraft:chiseled_tuff_bricks"},
        {pos: [10, 14, 4], state: "minecraft:chiseled_tuff_bricks"},
        {pos: [0, 15, 0], state: "minecraft:tuff_bricks"},
        {pos: [0, 15, 1], state: "minecraft:tuff_bricks"},
        {pos: [0, 15, 2], state: "minecraft:tuff_bricks"},
        {pos: [0, 15, 3], state: "minecraft:tuff_bricks"},
        {pos: [0, 15, 4], state: "minecraft:tuff_bricks"},
        {pos: [1, 15, 0], state: "minecraft:tuff_bricks"},
        {pos: [1, 15, 1], state: "minecraft:tuff_bricks"},
        {pos: [1, 15, 2], state: "minecraft:tuff_bricks"},
        {pos: [1, 15, 3], state: "minecraft:tuff_bricks"},
        {pos: [1, 15, 4], state: "minecraft:tuff_bricks"},
        {pos: [2, 15, 0], state: "minecraft:tuff_bricks"},
        {pos: [2, 15, 1], state: "minecraft:tuff_bricks"},
        {pos: [2, 15, 2], state: "minecraft:tuff_bricks"},
        {pos: [2, 15, 3], state: "minecraft:tuff_bricks"},
        {pos: [2, 15, 4], state: "minecraft:tuff_bricks"},
        {pos: [3, 15, 0], state: "minecraft:tuff_bricks"},
        {pos: [3, 15, 1], state: "minecraft:polished_tuff"},
        {pos: [3, 15, 2], state: "minecraft:polished_tuff"},
        {pos: [3, 15, 3], state: "minecraft:polished_tuff"},
        {pos: [3, 15, 4], state: "minecraft:tuff_bricks"},
        {pos: [4, 15, 0], state: "minecraft:tuff_bricks"},
        {pos: [4, 15, 1], state: "minecraft:polished_tuff"},
        {pos: [4, 15, 2], state: "minecraft:polished_tuff"},
        {pos: [4, 15, 3], state: "minecraft:polished_tuff"},
        {pos: [4, 15, 4], state: "minecraft:tuff_bricks"},
        {pos: [5, 15, 0], state: "minecraft:tuff_bricks"},
        {pos: [5, 15, 1], state: "minecraft:polished_tuff"},
        {pos: [5, 15, 2], state: "minecraft:polished_tuff"},
        {pos: [5, 15, 3], state: "minecraft:polished_tuff"},
        {pos: [5, 15, 4], state: "minecraft:tuff_bricks"},
        {pos: [6, 15, 0], state: "minecraft:tuff_bricks"},
        {pos: [6, 15, 1], state: "minecraft:polished_tuff"},
        {pos: [6, 15, 2], state: "minecraft:polished_tuff"},
        {pos: [6, 15, 3], state: "minecraft:polished_tuff"},
        {pos: [6, 15, 4], state: "minecraft:tuff_bricks"},
        {pos: [7, 15, 0], state: "minecraft:tuff_bricks"},
        {pos: [7, 15, 1], state: "minecraft:polished_tuff"},
        {pos: [7, 15, 2], state: "minecraft:polished_tuff"},
        {pos: [7, 15, 3], state: "minecraft:polished_tuff"},
        {pos: [7, 15, 4], state: "minecraft:tuff_bricks"},
        {pos: [8, 15, 0], state: "minecraft:tuff_bricks"},
        {pos: [8, 15, 1], state: "minecraft:polished_tuff"},
        {pos: [8, 15, 2], state: "minecraft:polished_tuff"},
        {pos: [8, 15, 3], state: "minecraft:polished_tuff"},
        {pos: [8, 15, 4], state: "minecraft:tuff_bricks"},
        {pos: [9, 15, 0], state: "minecraft:tuff_bricks"},
        {pos: [9, 15, 1], state: "minecraft:polished_tuff"},
        {pos: [9, 15, 2], state: "minecraft:polished_tuff"},
        {pos: [9, 15, 3], state: "minecraft:polished_tuff"},
        {pos: [9, 15, 4], state: "minecraft:tuff_bricks"},
        {pos: [10, 15, 0], state: "minecraft:tuff_bricks"},
        {pos: [10, 15, 1], state: "minecraft:polished_tuff"},
        {pos: [10, 15, 2], state: "minecraft:polished_tuff"},
        {pos: [10, 15, 3], state: "minecraft:polished_tuff"},
        {pos: [10, 15, 4], state: "minecraft:tuff_bricks"},
        {pos: [0, 16, 0], state: "minecraft:tuff_bricks"},
        {pos: [0, 16, 1], state: "minecraft:tuff_bricks"},
        {pos: [0, 16, 2], state: "minecraft:tuff_bricks"},
        {pos: [0, 16, 3], state: "minecraft:tuff_bricks"},
        {pos: [0, 16, 4], state: "minecraft:tuff_bricks"},
        {pos: [1, 16, 0], state: "minecraft:tuff_bricks"},
        {pos: [1, 16, 1], state: "minecraft:tuff_bricks"},
        {pos: [1, 16, 2], state: "minecraft:tuff_bricks"},
        {pos: [1, 16, 3], state: "minecraft:tuff_bricks"},
        {pos: [1, 16, 4], state: "minecraft:tuff_bricks"},
        {pos: [2, 16, 0], state: "minecraft:tuff_bricks"},
        {pos: [2, 16, 1], state: "minecraft:tuff_bricks"},
        {pos: [2, 16, 2], state: "minecraft:tuff_bricks"},
        {pos: [2, 16, 3], state: "minecraft:tuff_bricks"},
        {pos: [2, 16, 4], state: "minecraft:tuff_bricks"},
        {pos: [3, 16, 0], state: "minecraft:tuff_bricks"},
        {pos: [3, 16, 1], state: "minecraft:tuff_bricks"},
        {pos: [3, 16, 2], state: "minecraft:tuff_bricks"},
        {pos: [3, 16, 3], state: "minecraft:tuff_bricks"},
        {pos: [3, 16, 4], state: "minecraft:tuff_bricks"},
        {pos: [4, 16, 0], state: "minecraft:tuff_bricks"},
        {pos: [4, 16, 1], state: "minecraft:tuff_bricks"},
        {pos: [4, 16, 2], state: "minecraft:tuff_bricks"},
        {pos: [4, 16, 3], state: "minecraft:tuff_bricks"},
        {pos: [4, 16, 4], state: "minecraft:tuff_bricks"},
        {pos: [5, 16, 0], state: "minecraft:tuff_bricks"},
        {pos: [5, 16, 1], state: "minecraft:tuff_bricks"},
        {pos: [5, 16, 2], state: "minecraft:tuff_bricks"},
        {pos: [5, 16, 3], state: "minecraft:tuff_bricks"},
        {pos: [5, 16, 4], state: "minecraft:tuff_bricks"},
        {pos: [6, 16, 0], state: "minecraft:tuff_bricks"},
        {pos: [6, 16, 1], state: "minecraft:tuff_bricks"},
        {pos: [6, 16, 2], state: "minecraft:tuff_bricks"},
        {pos: [6, 16, 3], state: "minecraft:tuff_bricks"},
        {pos: [6, 16, 4], state: "minecraft:tuff_bricks"},
        {pos: [7, 16, 0], state: "minecraft:tuff_bricks"},
        {pos: [7, 16, 1], state: "minecraft:tuff_bricks"},
        {pos: [7, 16, 2], state: "minecraft:tuff_bricks"},
        {pos: [7, 16, 3], state: "minecraft:tuff_bricks"},
        {pos: [7, 16, 4], state: "minecraft:tuff_bricks"},
        {pos: [8, 16, 0], state: "minecraft:tuff_bricks"},
        {pos: [8, 16, 1], state: "minecraft:tuff_bricks"},
        {pos: [8, 16, 2], state: "minecraft:tuff_bricks"},
        {pos: [8, 16, 3], state: "minecraft:tuff_bricks"},
        {pos: [8, 16, 4], state: "minecraft:tuff_bricks"},
        {pos: [9, 16, 0], state: "minecraft:tuff_bricks"},
        {pos: [9, 16, 1], state: "minecraft:tuff_bricks"},
        {pos: [9, 16, 2], state: "minecraft:tuff_bricks"},
        {pos: [9, 16, 3], state: "minecraft:tuff_bricks"},
        {pos: [9, 16, 4], state: "minecraft:tuff_bricks"},
        {pos: [10, 16, 0], state: "minecraft:tuff_bricks"},
        {pos: [10, 16, 1], state: "minecraft:tuff_bricks"},
        {pos: [10, 16, 2], state: "minecraft:tuff_bricks"},
        {pos: [10, 16, 3], state: "minecraft:tuff_bricks"},
        {pos: [10, 16, 4], state: "minecraft:tuff_bricks"},
        {pos: [3, 2, 2], state: "minecraft:waxed_oxidized_cut_copper_stairs{half:bottom,waterlogged:false,shape:straight,facing:north}"},
        {pos: [3, 2, 3], state: "minecraft:air"},
        {pos: [4, 2, 2], state: "minecraft:air"},
        {pos: [4, 2, 3], state: "minecraft:air"},
        {pos: [5, 2, 1], state: "minecraft:air"},
        {pos: [5, 2, 2], state: "minecraft:air"},
        {pos: [5, 2, 3], state: "minecraft:air"},
        {pos: [6, 2, 1], state: "minecraft:air"},
        {pos: [6, 2, 2], state: "minecraft:air"},
        {pos: [6, 2, 3], state: "minecraft:air"},
        {pos: [7, 2, 1], state: "minecraft:air"},
        {pos: [7, 2, 2], state: "minecraft:air"},
        {pos: [7, 2, 3], state: "minecraft:air"},
        {pos: [8, 2, 1], state: "minecraft:air"},
        {pos: [8, 2, 2], state: "minecraft:air"},
        {pos: [8, 2, 3], state: "minecraft:air"},
        {pos: [9, 2, 1], state: "minecraft:air"},
        {pos: [9, 2, 2], state: "minecraft:air"},
        {pos: [9, 2, 3], state: "minecraft:air"},
        {pos: [10, 2, 1], state: "minecraft:air"},
        {pos: [10, 2, 2], state: "minecraft:air"},
        {pos: [10, 2, 3], state: "minecraft:air"},
        {pos: [3, 3, 1], state: "minecraft:air"},
        {pos: [3, 3, 2], state: "minecraft:air"},
        {pos: [3, 3, 3], state: "minecraft:air"},
        {pos: [4, 3, 1], state: "minecraft:waxed_oxidized_cut_copper_stairs{half:bottom,waterlogged:false,shape:straight,facing:east}"},
        {pos: [4, 3, 2], state: "minecraft:air"},
        {pos: [4, 3, 3], state: "minecraft:air"},
        {pos: [5, 3, 3], state: "minecraft:air"},
        {pos: [6, 3, 1], state: "minecraft:air"},
        {pos: [6, 3, 2], state: "minecraft:air"},
        {pos: [6, 3, 3], state: "minecraft:air"},
        {pos: [7, 3, 1], state: "minecraft:air"},
        {pos: [7, 3, 2], state: "minecraft:air"},
        {pos: [7, 3, 3], state: "minecraft:air"},
        {pos: [8, 3, 1], state: "minecraft:air"},
        {pos: [8, 3, 2], state: "minecraft:air"},
        {pos: [8, 3, 3], state: "minecraft:air"},
        {pos: [9, 3, 1], state: "minecraft:air"},
        {pos: [9, 3, 2], state: "minecraft:air"},
        {pos: [9, 3, 3], state: "minecraft:air"},
        {pos: [10, 3, 1], state: "minecraft:air"},
        {pos: [10, 3, 3], state: "minecraft:air"},
        {pos: [3, 4, 1], state: "minecraft:air"},
        {pos: [3, 4, 2], state: "minecraft:air"},
        {pos: [3, 4, 3], state: "minecraft:air"},
        {pos: [4, 4, 1], state: "minecraft:air"},
        {pos: [4, 4, 2], state: "minecraft:air"},
        {pos: [5, 4, 1], state: "minecraft:air"},
        {pos: [5, 4, 2], state: "minecraft:waxed_oxidized_cut_copper_stairs{half:bottom,waterlogged:false,shape:straight,facing:south}"},
        {pos: [6, 4, 1], state: "minecraft:air"},
        {pos: [6, 4, 2], state: "minecraft:air"},
        {pos: [6, 4, 3], state: "minecraft:air"},
        {pos: [7, 4, 1], state: "minecraft:air"},
        {pos: [7, 4, 2], state: "minecraft:air"},
        {pos: [7, 4, 3], state: "minecraft:air"},
        {pos: [8, 4, 1], state: "minecraft:air"},
        {pos: [8, 4, 2], state: "minecraft:air"},
        {pos: [8, 4, 3], state: "minecraft:air"},
        {pos: [9, 4, 1], state: "minecraft:air"},
        {pos: [9, 4, 2], state: "minecraft:air"},
        {pos: [9, 4, 3], state: "minecraft:air"},
        {pos: [10, 4, 1], state: "minecraft:air"},
        {pos: [10, 4, 2], state: "minecraft:air"},
        {pos: [10, 4, 3], state: "minecraft:air"},
        {pos: [3, 5, 1], state: "minecraft:air"},
        {pos: [4, 5, 1], state: "minecraft:air"},
        {pos: [4, 5, 2], state: "minecraft:air"},
        {pos: [4, 5, 3], state: "minecraft:waxed_oxidized_cut_copper_stairs{half:bottom,waterlogged:false,shape:straight,facing:west}"},
        {pos: [5, 5, 1], state: "minecraft:air"},
        {pos: [5, 5, 2], state: "minecraft:air"},
        {pos: [5, 5, 3], state: "minecraft:air"},
        {pos: [6, 5, 1], state: "minecraft:air"},
        {pos: [6, 5, 2], state: "minecraft:air"},
        {pos: [6, 5, 3], state: "minecraft:air"},
        {pos: [7, 5, 1], state: "minecraft:air"},
        {pos: [7, 5, 2], state: "minecraft:air"},
        {pos: [7, 5, 3], state: "minecraft:air"},
        {pos: [8, 5, 1], state: "minecraft:air"},
        {pos: [8, 5, 2], state: "minecraft:air"},
        {pos: [8, 5, 3], state: "minecraft:air"},
        {pos: [9, 5, 1], state: "minecraft:air"},
        {pos: [9, 5, 2], state: "minecraft:air"},
        {pos: [9, 5, 3], state: "minecraft:air"},
        {pos: [10, 5, 1], state: "minecraft:air"},
        {pos: [10, 5, 2], state: "minecraft:air"},
        {pos: [10, 5, 3], state: "minecraft:air"},
        {pos: [3, 6, 2], state: "minecraft:waxed_oxidized_cut_copper_stairs{half:bottom,waterlogged:false,shape:straight,facing:north}"},
        {pos: [3, 6, 3], state: "minecraft:air"},
        {pos: [4, 6, 2], state: "minecraft:air"},
        {pos: [4, 6, 3], state: "minecraft:air"},
        {pos: [5, 6, 1], state: "minecraft:air"},
        {pos: [5, 6, 2], state: "minecraft:air"},
        {pos: [5, 6, 3], state: "minecraft:air"},
        {pos: [6, 6, 1], state: "minecraft:air"},
        {pos: [6, 6, 2], state: "minecraft:air"},
        {pos: [6, 6, 3], state: "minecraft:air"},
        {pos: [7, 6, 1], state: "minecraft:air"},
        {pos: [7, 6, 2], state: "minecraft:air"},
        {pos: [7, 6, 3], state: "minecraft:air"},
        {pos: [3, 7, 1], state: "minecraft:air"},
        {pos: [3, 7, 2], state: "minecraft:air"},
        {pos: [3, 7, 3], state: "minecraft:air"},
        {pos: [4, 7, 1], state: "minecraft:waxed_oxidized_cut_copper_stairs{half:bottom,waterlogged:false,shape:straight,facing:east}"},
        {pos: [4, 7, 2], state: "minecraft:air"},
        {pos: [4, 7, 3], state: "minecraft:air"},
        {pos: [5, 7, 3], state: "minecraft:air"},
        {pos: [3, 8, 1], state: "minecraft:air"},
        {pos: [3, 8, 2], state: "minecraft:air"},
        {pos: [3, 8, 3], state: "minecraft:air"},
        {pos: [4, 8, 1], state: "minecraft:air"},
        {pos: [4, 8, 2], state: "minecraft:air"},
        {pos: [5, 8, 1], state: "minecraft:air"},
        {pos: [5, 8, 2], state: "minecraft:waxed_oxidized_cut_copper_stairs{half:bottom,waterlogged:false,shape:straight,facing:south}"},
        {pos: [3, 9, 1], state: "minecraft:air"},
        {pos: [4, 9, 1], state: "minecraft:air"},
        {pos: [4, 9, 2], state: "minecraft:air"},
        {pos: [4, 9, 3], state: "minecraft:waxed_oxidized_cut_copper_stairs{half:bottom,waterlogged:false,shape:straight,facing:west}"},
        {pos: [5, 9, 1], state: "minecraft:air"},
        {pos: [5, 9, 2], state: "minecraft:air"},
        {pos: [5, 9, 3], state: "minecraft:air"},
        {pos: [3, 10, 2], state: "minecraft:waxed_oxidized_cut_copper_stairs{half:bottom,waterlogged:false,shape:straight,facing:north}"},
        {pos: [3, 10, 3], state: "minecraft:air"},
        {pos: [4, 10, 2], state: "minecraft:air"},
        {pos: [4, 10, 3], state: "minecraft:air"},
        {pos: [5, 10, 1], state: "minecraft:air"},
        {pos: [5, 10, 2], state: "minecraft:air"},
        {pos: [5, 10, 3], state: "minecraft:air"},
        {pos: [3, 11, 1], state: "minecraft:air"},
        {pos: [3, 11, 2], state: "minecraft:air"},
        {pos: [3, 11, 3], state: "minecraft:air"},
        {pos: [4, 11, 1], state: "minecraft:waxed_oxidized_cut_copper_stairs{half:bottom,waterlogged:false,shape:straight,facing:east}"},
        {pos: [4, 11, 2], state: "minecraft:air"},
        {pos: [4, 11, 3], state: "minecraft:air"},
        {pos: [5, 11, 3], state: "minecraft:air"},
        {pos: [3, 12, 1], state: "minecraft:air"},
        {pos: [3, 12, 2], state: "minecraft:air"},
        {pos: [3, 12, 3], state: "minecraft:air"},
        {pos: [4, 12, 1], state: "minecraft:air"},
        {pos: [4, 12, 2], state: "minecraft:air"},
        {pos: [4, 12, 3], state: "minecraft:air"},
        {pos: [5, 12, 1], state: "minecraft:air"},
        {pos: [5, 12, 2], state: "minecraft:air"},
        {pos: [5, 12, 3], state: "minecraft:air"},
        {pos: [6, 12, 1], state: "minecraft:air"},
        {pos: [6, 12, 2], state: "minecraft:air"},
        {pos: [6, 12, 3], state: "minecraft:air"},
        {pos: [7, 12, 1], state: "minecraft:air"},
        {pos: [7, 12, 2], state: "minecraft:air"},
        {pos: [7, 12, 3], state: "minecraft:air"},
        {pos: [8, 12, 1], state: "minecraft:air"},
        {pos: [8, 12, 2], state: "minecraft:air"},
        {pos: [8, 12, 3], state: "minecraft:air"},
        {pos: [9, 12, 1], state: "minecraft:air"},
        {pos: [9, 12, 2], state: "minecraft:air"},
        {pos: [9, 12, 3], state: "minecraft:air"},
        {pos: [10, 12, 1], state: "minecraft:air"},
        {pos: [10, 12, 2], state: "minecraft:air"},
        {pos: [10, 12, 3], state: "minecraft:air"},
        {pos: [3, 13, 1], state: "minecraft:air"},
        {pos: [3, 13, 2], state: "minecraft:air"},
        {pos: [3, 13, 3], state: "minecraft:air"},
        {pos: [4, 13, 1], state: "minecraft:air"},
        {pos: [4, 13, 2], state: "minecraft:air"},
        {pos: [4, 13, 3], state: "minecraft:air"},
        {pos: [5, 13, 1], state: "minecraft:air"},
        {pos: [5, 13, 2], state: "minecraft:air"},
        {pos: [5, 13, 3], state: "minecraft:air"},
        {pos: [6, 13, 1], state: "minecraft:air"},
        {pos: [6, 13, 2], state: "minecraft:air"},
        {pos: [6, 13, 3], state: "minecraft:air"},
        {pos: [7, 13, 1], state: "minecraft:air"},
        {pos: [7, 13, 2], state: "minecraft:air"},
        {pos: [7, 13, 3], state: "minecraft:air"},
        {pos: [8, 13, 1], state: "minecraft:air"},
        {pos: [8, 13, 2], state: "minecraft:air"},
        {pos: [8, 13, 3], state: "minecraft:air"},
        {pos: [9, 13, 1], state: "minecraft:air"},
        {pos: [9, 13, 2], state: "minecraft:air"},
        {pos: [9, 13, 3], state: "minecraft:air"},
        {pos: [10, 13, 1], state: "minecraft:air"},
        {pos: [10, 13, 3], state: "minecraft:air"},
        {pos: [3, 14, 1], state: "minecraft:air"},
        {pos: [3, 14, 2], state: "minecraft:air"},
        {pos: [3, 14, 3], state: "minecraft:air"},
        {pos: [4, 14, 1], state: "minecraft:air"},
        {pos: [4, 14, 2], state: "minecraft:air"},
        {pos: [4, 14, 3], state: "minecraft:air"},
        {pos: [5, 14, 1], state: "minecraft:air"},
        {pos: [5, 14, 2], state: "minecraft:air"},
        {pos: [5, 14, 3], state: "minecraft:air"},
        {pos: [6, 14, 1], state: "minecraft:air"},
        {pos: [6, 14, 2], state: "minecraft:air"},
        {pos: [6, 14, 3], state: "minecraft:air"},
        {pos: [7, 14, 1], state: "minecraft:air"},
        {pos: [7, 14, 2], state: "minecraft:air"},
        {pos: [7, 14, 3], state: "minecraft:air"},
        {pos: [8, 14, 1], state: "minecraft:air"},
        {pos: [8, 14, 2], state: "minecraft:air"},
        {pos: [8, 14, 3], state: "minecraft:air"},
        {pos: [9, 14, 1], state: "minecraft:air"},
        {pos: [9, 14, 2], state: "minecraft:air"},
        {pos: [9, 14, 3], state: "minecraft:air"},
        {pos: [10, 14, 1], state: "minecraft:air"},
        {pos: [10, 14, 2], state: "minecraft:air"},
        {pos: [10, 14, 3], state: "minecraft:air"},
        {pos: [10, 3, 2], state: "minecraft:jigsaw{orientation:east_up}", nbt: {final_state: "minecraft:air", id: "minecraft:jigsaw", joint: "rollable", name: "minecraft:empty", placement_priority: 0, pool: "minecraft:trial_chambers/hallway", selection_priority: 0, target: "minecraft:in_connector"}},
        {pos: [10, 13, 2], state: "minecraft:jigsaw{orientation:east_up}", nbt: {final_state: "minecraft:air", id: "minecraft:jigsaw", joint: "rollable", name: "minecraft:lower_corridor_connector", placement_priority: 0, pool: "minecraft:empty", selection_priority: 0, target: "minecraft:empty"}}
    ],
    entities: [],
    palette: [
        "minecraft:tuff_bricks",
        "minecraft:waxed_oxidized_copper",
        "minecraft:waxed_oxidized_cut_copper",
        "minecraft:waxed_copper_block",
        "minecraft:waxed_copper_bulb{powered:false,lit:true}",
        "minecraft:chiseled_tuff_bricks",
        "minecraft:polished_tuff",
        "minecraft:waxed_oxidized_cut_copper_stairs{half:bottom,waterlogged:false,shape:straight,facing:north}",
        "minecraft:air",
        "minecraft:waxed_oxidized_cut_copper_stairs{half:bottom,waterlogged:false,shape:straight,facing:east}",
        "minecraft:waxed_oxidized_cut_copper_stairs{half:bottom,waterlogged:false,shape:straight,facing:south}",
        "minecraft:waxed_oxidized_cut_copper_stairs{half:bottom,waterlogged:false,shape:straight,facing:west}",
        "minecraft:jigsaw{orientation:east_up}"
    ]
}