{
    size: [5, 7, 5],
    data: [
        {pos: [0, 0, 0], state: "minecraft:tuff_bricks"},
        {pos: [0, 0, 1], state: "minecraft:tuff_bricks"},
        {pos: [0, 0, 2], state: "minecraft:tuff_bricks"},
        {pos: [0, 0, 3], state: "minecraft:tuff_bricks"},
        {pos: [0, 0, 4], state: "minecraft:tuff_bricks"},
        {pos: [1, 0, 0], state: "minecraft:tuff_bricks"},
        {pos: [1, 0, 1], state: "minecraft:tuff_bricks"},
        {pos: [1, 0, 2], state: "minecraft:tuff_bricks"},
        {pos: [1, 0, 3], state: "minecraft:tuff_bricks"},
        {pos: [1, 0, 4], state: "minecraft:tuff_bricks"},
        {pos: [2, 0, 0], state: "minecraft:tuff_bricks"},
        {pos: [2, 0, 1], state: "minecraft:tuff_bricks"},
        {pos: [2, 0, 2], state: "minecraft:tuff_bricks"},
        {pos: [2, 0, 3], state: "minecraft:tuff_bricks"},
        {pos: [2, 0, 4], state: "minecraft:tuff_bricks"},
        {pos: [3, 0, 0], state: "minecraft:tuff_bricks"},
        {pos: [3, 0, 1], state: "minecraft:tuff_bricks"},
        {pos: [3, 0, 2], state: "minecraft:tuff_bricks"},
        {pos: [3, 0, 3], state: "minecraft:tuff_bricks"},
        {pos: [3, 0, 4], state: "minecraft:tuff_bricks"},
        {pos: [4, 0, 0], state: "minecraft:tuff_bricks"},
        {pos: [4, 0, 1], state: "minecraft:tuff_bricks"},
        {pos: [4, 0, 2], state: "minecraft:tuff_bricks"},
        {pos: [4, 0, 3], state: "minecraft:tuff_bricks"},
        {pos: [4, 0, 4], state: "minecraft:tuff_bricks"},
        {pos: [0, 1, 0], state: "minecraft:tuff_bricks"},
        {pos: [0, 1, 1], state: "minecraft:waxed_oxidized_copper"},
        {pos: [0, 1, 2], state: "minecraft:waxed_oxidized_copper"},
        {pos: [0, 1, 3], state: "minecraft:waxed_oxidized_copper"},
        {pos: [0, 1, 4], state: "minecraft:tuff_bricks"},
        {pos: [1, 1, 0], state: "minecraft:waxed_oxidized_copper"},
        {pos: [1, 1, 1], state: "minecraft:waxed_oxidized_copper"},
        {pos: [1, 1, 2], state: "minecraft:waxed_oxidized_copper"},
        {pos: [1, 1, 3], state: "minecraft:waxed_oxidized_copper"},
        {pos: [1, 1, 4], state: "minecraft:tuff_bricks"},
        {pos: [2, 1, 0], state: "minecraft:waxed_oxidized_copper"},
        {pos: [2, 1, 1], state: "minecraft:waxed_oxidized_copper"},
        {pos: [2, 1, 2], state: "minecraft:waxed_oxidized_copper"},
        {pos: [2, 1, 3], state: "minecraft:waxed_oxidized_copper"},
        {pos: [2, 1, 4], state: "minecraft:tuff_bricks"},
        {pos: [3, 1, 0], state: "minecraft:waxed_oxidized_copper"},
        {pos: [3, 1, 1], state: "minecraft:waxed_oxidized_copper"},
        {pos: [3, 1, 2], state: "minecraft:waxed_oxidized_copper"},
        {pos: [3, 1, 3], state: "minecraft:waxed_oxidized_copper"},
        {pos: [3, 1, 4], state: "minecraft:tuff_bricks"},
        {pos: [4, 1, 0], state: "minecraft:tuff_bricks"},
        {pos: [4, 1, 1], state: "minecraft:tuff_bricks"},
        {pos: [4, 1, 2], state: "minecraft:tuff_bricks"},
        {pos: [4, 1, 3], state: "minecraft:tuff_bricks"},
        {pos: [4, 1, 4], state: "minecraft:tuff_bricks"},
        {pos: [0, 2, 0], state: "minecraft:waxed_copper_block"},
        {pos: [0, 2, 4], state: "minecraft:waxed_copper_block"},
        {pos: [1, 2, 4], state: "minecraft:waxed_copper_block"},
        {pos: [2, 2, 4], state: "minecraft:waxed_copper_block"},
        {pos: [3, 2, 4], state: "minecraft:waxed_copper_block"},
        {pos: [4, 2, 0], state: "minecraft:waxed_copper_block"},
        {pos: [4, 2, 1], state: "minecraft:waxed_copper_block"},
        {pos: [4, 2, 2], state: "minecraft:waxed_copper_block"},
        {pos: [4, 2, 3], state: "minecraft:waxed_copper_block"},
        {pos: [4, 2, 4], state: "minecraft:waxed_copper_block"},
        {pos: [0, 3, 0], state: "minecraft:tuff_bricks"},
        {pos: [0, 3, 4], state: "minecraft:tuff_bricks"},
        {pos: [1, 3, 4], state: "minecraft:tuff_bricks"},
        {pos: [2, 3, 4], state: "minecraft:waxed_copper_bulb{powered:false,lit:true}"},
        {pos: [3, 3, 4], state: "minecraft:tuff_bricks"},
        {pos: [4, 3, 0], state: "minecraft:tuff_bricks"},
        {pos: [4, 3, 1], state: "minecraft:tuff_bricks"},
        {pos: [4, 3, 2], state: "minecraft:waxed_copper_bulb{powered:false,lit:true}"},
        {pos: [4, 3, 3], state: "minecraft:tuff_bricks"},
        {pos: [4, 3, 4], state: "minecraft:tuff_bricks"},
        {pos: [0, 4, 0], state: "minecraft:chiseled_tuff_bricks"},
        {pos: [0, 4, 4], state: "minecraft:chiseled_tuff_bricks"},
        {pos: [1, 4, 4], state: "minecraft:chiseled_tuff_bricks"},
        {pos: [2, 4, 4], state: "minecraft:chiseled_tuff_bricks"},
        {pos: [3, 4, 4], state: "minecraft:chiseled_tuff_bricks"},
        {pos: [4, 4, 0], state: "minecraft:chiseled_tuff_bricks"},
        {pos: [4, 4, 1], state: "minecraft:chiseled_tuff_bricks"},
        {pos: [4, 4, 2], state: "minecraft:chiseled_tuff_bricks"},
        {pos: [4, 4, 3], state: "minecraft:chiseled_tuff_bricks"},
        {pos: [4, 4, 4], state: "minecraft:chiseled_tuff_bricks"},
        {pos: [0, 5, 0], state: "minecraft:tuff_bricks"},
        {pos: [0, 5, 1], state: "minecraft:polished_tuff"},
        {pos: [0, 5, 2], state: "minecraft:polished_tuff"},
        {pos: [0, 5, 3], state: "minecraft:polished_tuff"},
        {pos: [0, 5, 4], state: "minecraft:tuff_bricks"},
        {pos: [1, 5, 0], state: "minecraft:polished_tuff"},
        {pos: [1, 5, 1], state: "minecraft:polished_tuff"},
        {pos: [1, 5, 2], state: "minecraft:polished_tuff"},
        {pos: [1, 5, 3], state: "minecraft:polished_tuff"},
        {pos: [1, 5, 4], state: "minecraft:tuff_bricks"},
        {pos: [2, 5, 0], state: "minecraft:polished_tuff"},
        {pos: [2, 5, 1], state: "minecraft:polished_tuff"},
        {pos: [2, 5, 2], state: "minecraft:polished_tuff"},
        {pos: [2, 5, 3], state: "minecraft:polished_tuff"},
        {pos: [2, 5, 4], state: "minecraft:tuff_bricks"},
        {pos: [3, 5, 0], state: "minecraft:polished_tuff"},
        {pos: [3, 5, 1], state: "minecraft:polished_tuff"},
        {pos: [3, 5, 2], state: "minecraft:polished_tuff"},
        {pos: [3, 5, 3], state: "minecraft:polished_tuff"},
        {pos: [3, 5, 4], state: "minecraft:tuff_bricks"},
        {pos: [4, 5, 0], state: "minecraft:tuff_bricks"},
        {pos: [4, 5, 1], state: "minecraft:tuff_bricks"},
        {pos: [4, 5, 2], state: "minecraft:tuff_bricks"},
        {pos: [4, 5, 3], state: "minecraft:tuff_bricks"},
        {pos: [4, 5, 4], state: "minecraft:tuff_bricks"},
        {pos: [0, 6, 0], state: "minecraft:tuff_bricks"},
        {pos: [0, 6, 1], state: "minecraft:tuff_bricks"},
        {pos: [0, 6, 2], state: "minecraft:tuff_bricks"},
        {pos: [0, 6, 3], state: "minecraft:tuff_bricks"},
        {pos: [0, 6, 4], state: "minecraft:tuff_bricks"},
        {pos: [1, 6, 0], state: "minecraft:tuff_bricks"},
        {pos: [1, 6, 1], state: "minecraft:tuff_bricks"},
        {pos: [1, 6, 2], state: "minecraft:tuff_bricks"},
        {pos: [1, 6, 3], state: "minecraft:tuff_bricks"},
        {pos: [1, 6, 4], state: "minecraft:tuff_bricks"},
        {pos: [2, 6, 0], state: "minecraft:tuff_bricks"},
        {pos: [2, 6, 1], state: "minecraft:tuff_bricks"},
        {pos: [2, 6, 2], state: "minecraft:tuff_bricks"},
        {pos: [2, 6, 3], state: "minecraft:tuff_bricks"},
        {pos: [2, 6, 4], state: "minecraft:tuff_bricks"},
        {pos: [3, 6, 0], state: "minecraft:tuff_bricks"},
        {pos: [3, 6, 1], state: "minecraft:tuff_bricks"},
        {pos: [3, 6, 2], state: "minecraft:tuff_bricks"},
        {pos: [3, 6, 3], state: "minecraft:tuff_bricks"},
        {pos: [3, 6, 4], state: "minecraft:tuff_bricks"},
        {pos: [4, 6, 0], state: "minecraft:tuff_bricks"},
        {pos: [4, 6, 1], state: "minecraft:tuff_bricks"},
        {pos: [4, 6, 2], state: "minecraft:tuff_bricks"},
        {pos: [4, 6, 3], state: "minecraft:tuff_bricks"},
        {pos: [4, 6, 4], state: "minecraft:tuff_bricks"},
        {pos: [0, 2, 1], state: "minecraft:air"},
        {pos: [0, 2, 2], state: "minecraft:air"},
        {pos: [0, 2, 3], state: "minecraft:air"},
        {pos: [1, 2, 0], state: "minecraft:air"},
        {pos: [1, 2, 1], state: "minecraft:air"},
        {pos: [1, 2, 2], state: "minecraft:air"},
        {pos: [1, 2, 3], state: "minecraft:air"},
        {pos: [2, 2, 0], state: "minecraft:air"},
        {pos: [2, 2, 1], state: "minecraft:air"},
        {pos: [2, 2, 2], state: "minecraft:air"},
        {pos: [2, 2, 3], state: "minecraft:air"},
        {pos: [3, 2, 0], state: "minecraft:air"},
        {pos: [3, 2, 1], state: "minecraft:air"},
        {pos: [3, 2, 2], state: "minecraft:air"},
        {pos: [3, 2, 3], state: "minecraft:air"},
        {pos: [0, 3, 1], state: "minecraft:air"},
        {pos: [0, 3, 3], state: "minecraft:air"},
        {pos: [1, 3, 0], state: "minecraft:air"},
        {pos: [1, 3, 1], state: "minecraft:air"},
        {pos: [1, 3, 2], state: "minecraft:air"},
        {pos: [1, 3, 3], state: "minecraft:air"},
        {pos: [2, 3, 1], state: "minecraft:air"},
        {pos: [2, 3, 2], state: "minecraft:air"},
        {pos: [2, 3, 3], state: "minecraft:air"},
        {pos: [3, 3, 0], state: "minecraft:air"},
        {pos: [3, 3, 1], state: "minecraft:air"},
        {pos: [3, 3, 2], state: "minecraft:air"},
        {pos: [3, 3, 3], state: "minecraft:air"},
        {pos: [0, 4, 1], state: "minecraft:air"},
        {pos: [0, 4, 2], state: "minecraft:air"},
        {pos: [0, 4, 3], state: "minecraft:air"},
        {pos: [1, 4, 0], state: "minecraft:air"},
        {pos: [1, 4, 1], state: "minecraft:air"},
        {pos: [1, 4, 2], state: "minecraft:air"},
        {pos: [1, 4, 3], state: "minecraft:air"},
        {pos: [2, 4, 0], state: "minecraft:air"},
        {pos: [2, 4, 1], state: "minecraft:air"},
        {pos: [2, 4, 2], state: "minecraft:air"},
        {pos: [2, 4, 3], state: "minecraft:air"},
        {pos: [3, 4, 0], state: "minecraft:air"},
        {pos: [3, 4, 1], state: "minecraft:air"},
        {pos: [3, 4, 2], state: "minecraft:air"},
        {pos: [3, 4, 3], state: "minecraft:air"},
        {pos: [0, 3, 2], state: "minecraft:jigsaw{orientation:west_up}", nbt: {final_state: "minecraft:air", id: "minecraft:jigsaw", joint: "rollable", name: "minecraft:empty", placement_priority: 0, pool: "minecraft:trial_chambers/hallway", selection_priority: 0, target: "minecraft:in_connector"}},
        {pos: [2, 3, 0], state: "minecraft:jigsaw{orientation:north_up}", nbt: {final_state: "minecraft:air", id: "minecraft:jigsaw", joint: "rollable", name: "minecraft:in_connector", placement_priority: 0, pool: "minecraft:empty", selection_priority: 0, target: "minecraft:empty"}}
    ],
    entities: [],
    palette: [
        "minecraft:tuff_bricks",
        "minecraft:waxed_oxidized_copper",
        "minecraft:waxed_copper_block",
        "minecraft:waxed_copper_bulb{powered:false,lit:true}",
        "minecraft:chiseled_tuff_bricks",
        "minecraft:polished_tuff",
        "minecraft:air",
        "minecraft:jigsaw{orientation:west_up}",
        "minecraft:jigsaw{orientation:north_up}"
    ]
}