{
    size: [35, 15, 39],
    data: [
        {pos: [0, 0, 17], state: "minecraft:polished_deepslate"},
        {pos: [0, 0, 18], state: "minecraft:polished_deepslate"},
        {pos: [0, 0, 19], state: "minecraft:polished_deepslate"},
        {pos: [0, 0, 20], state: "minecraft:polished_deepslate"},
        {pos: [0, 0, 21], state: "minecraft:polished_deepslate"},
        {pos: [1, 0, 16], state: "minecraft:polished_deepslate"},
        {pos: [1, 0, 17], state: "minecraft:deepslate_tiles"},
        {pos: [1, 0, 18], state: "minecraft:deepslate_tiles"},
        {pos: [1, 0, 19], state: "minecraft:deepslate_tiles"},
        {pos: [1, 0, 20], state: "minecraft:deepslate_tiles"},
        {pos: [1, 0, 21], state: "minecraft:deepslate_tiles"},
        {pos: [1, 0, 22], state: "minecraft:polished_deepslate"},
        {pos: [2, 0, 15], state: "minecraft:polished_deepslate"},
        {pos: [2, 0, 16], state: "minecraft:deepslate_tiles"},
        {pos: [2, 0, 17], state: "minecraft:deepslate_tiles"},
        {pos: [2, 0, 18], state: "minecraft:deepslate_tiles"},
        {pos: [2, 0, 19], state: "minecraft:deepslate_tiles"},
        {pos: [2, 0, 20], state: "minecraft:deepslate_tiles"},
        {pos: [2, 0, 21], state: "minecraft:deepslate_tiles"},
        {pos: [2, 0, 22], state: "minecraft:deepslate_tiles"},
        {pos: [2, 0, 23], state: "minecraft:polished_deepslate"},
        {pos: [3, 0, 15], state: "minecraft:polished_deepslate"},
        {pos: [3, 0, 16], state: "minecraft:deepslate_tiles"},
        {pos: [3, 0, 17], state: "minecraft:deepslate_tiles"},
        {pos: [3, 0, 18], state: "minecraft:deepslate_tiles"},
        {pos: [3, 0, 19], state: "minecraft:deepslate_tiles"},
        {pos: [3, 0, 20], state: "minecraft:deepslate_tiles"},
        {pos: [3, 0, 21], state: "minecraft:deepslate_tiles"},
        {pos: [3, 0, 22], state: "minecraft:deepslate_tiles"},
        {pos: [3, 0, 23], state: "minecraft:polished_deepslate"},
        {pos: [4, 0, 15], state: "minecraft:polished_deepslate"},
        {pos: [4, 0, 16], state: "minecraft:deepslate_tiles"},
        {pos: [4, 0, 17], state: "minecraft:deepslate_tiles"},
        {pos: [4, 0, 18], state: "minecraft:deepslate_tiles"},
        {pos: [4, 0, 19], state: "minecraft:deepslate_tiles"},
        {pos: [4, 0, 20], state: "minecraft:deepslate_tiles"},
        {pos: [4, 0, 21], state: "minecraft:deepslate_tiles"},
        {pos: [4, 0, 22], state: "minecraft:deepslate_tiles"},
        {pos: [4, 0, 23], state: "minecraft:polished_deepslate"},
        {pos: [5, 0, 15], state: "minecraft:polished_deepslate"},
        {pos: [5, 0, 16], state: "minecraft:deepslate_tiles"},
        {pos: [5, 0, 17], state: "minecraft:deepslate_tiles"},
        {pos: [5, 0, 18], state: "minecraft:deepslate_tiles"},
        {pos: [5, 0, 19], state: "minecraft:deepslate_tiles"},
        {pos: [5, 0, 20], state: "minecraft:deepslate_tiles"},
        {pos: [5, 0, 21], state: "minecraft:deepslate_tiles"},
        {pos: [5, 0, 22], state: "minecraft:deepslate_tiles"},
        {pos: [5, 0, 23], state: "minecraft:polished_deepslate"},
        {pos: [6, 0, 15], state: "minecraft:deepslate_tiles"},
        {pos: [6, 0, 16], state: "minecraft:deepslate_tiles"},
        {pos: [6, 0, 17], state: "minecraft:deepslate_tiles"},
        {pos: [6, 0, 18], state: "minecraft:deepslate_tiles"},
        {pos: [6, 0, 19], state: "minecraft:deepslate_tiles"},
        {pos: [6, 0, 20], state: "minecraft:deepslate_tiles"},
        {pos: [6, 0, 21], state: "minecraft:deepslate_tiles"},
        {pos: [6, 0, 22], state: "minecraft:deepslate_tiles"},
        {pos: [6, 0, 23], state: "minecraft:deepslate_tiles"},
        {pos: [7, 0, 15], state: "minecraft:deepslate_tiles"},
        {pos: [7, 0, 16], state: "minecraft:deepslate_tiles"},
        {pos: [7, 0, 17], state: "minecraft:deepslate_tiles"},
        {pos: [7, 0, 18], state: "minecraft:deepslate_tiles"},
        {pos: [7, 0, 19], state: "minecraft:deepslate_tiles"},
        {pos: [7, 0, 20], state: "minecraft:deepslate_tiles"},
        {pos: [7, 0, 21], state: "minecraft:deepslate_tiles"},
        {pos: [7, 0, 22], state: "minecraft:deepslate_tiles"},
        {pos: [7, 0, 23], state: "minecraft:deepslate_tiles"},
        {pos: [8, 0, 15], state: "minecraft:deepslate_tiles"},
        {pos: [8, 0, 16], state: "minecraft:deepslate_tiles"},
        {pos: [8, 0, 17], state: "minecraft:deepslate_tiles"},
        {pos: [8, 0, 18], state: "minecraft:deepslate_tiles"},
        {pos: [8, 0, 19], state: "minecraft:deepslate_tiles"},
        {pos: [8, 0, 20], state: "minecraft:deepslate_tiles"},
        {pos: [8, 0, 21], state: "minecraft:deepslate_tiles"},
        {pos: [8, 0, 22], state: "minecraft:deepslate_tiles"},
        {pos: [8, 0, 23], state: "minecraft:deepslate_tiles"},
        {pos: [9, 0, 0], state: "minecraft:polished_basalt{axis:y}"},
        {pos: [9, 0, 1], state: "minecraft:polished_basalt{axis:z}"},
        {pos: [9, 0, 2], state: "minecraft:polished_basalt{axis:z}"},
        {pos: [9, 0, 3], state: "minecraft:polished_basalt{axis:z}"},
        {pos: [9, 0, 4], state: "minecraft:polished_basalt{axis:z}"},
        {pos: [9, 0, 5], state: "minecraft:polished_basalt{axis:z}"},
        {pos: [9, 0, 6], state: "minecraft:polished_basalt{axis:z}"},
        {pos: [9, 0, 7], state: "minecraft:polished_basalt{axis:z}"},
        {pos: [9, 0, 8], state: "minecraft:polished_basalt{axis:y}"},
        {pos: [9, 0, 15], state: "minecraft:deepslate_tiles"},
        {pos: [9, 0, 16], state: "minecraft:deepslate_tiles"},
        {pos: [9, 0, 17], state: "minecraft:deepslate_tiles"},
        {pos: [9, 0, 18], state: "minecraft:deepslate_tiles"},
        {pos: [9, 0, 19], state: "minecraft:deepslate_tiles"},
        {pos: [9, 0, 20], state: "minecraft:deepslate_tiles"},
        {pos: [9, 0, 21], state: "minecraft:deepslate_tiles"},
        {pos: [9, 0, 22], state: "minecraft:deepslate_tiles"},
        {pos: [9, 0, 23], state: "minecraft:deepslate_tiles"},
        {pos: [9, 0, 30], state: "minecraft:polished_basalt{axis:y}"},
        {pos: [9, 0, 31], state: "minecraft:polished_basalt{axis:z}"},
        {pos: [9, 0, 32], state: "minecraft:polished_basalt{axis:z}"},
        {pos: [9, 0, 33], state: "minecraft:polished_basalt{axis:z}"},
        {pos: [9, 0, 34], state: "minecraft:polished_basalt{axis:z}"},
        {pos: [9, 0, 35], state: "minecraft:polished_basalt{axis:z}"},
        {pos: [9, 0, 36], state: "minecraft:polished_basalt{axis:z}"},
        {pos: [9, 0, 37], state: "minecraft:polished_basalt{axis:z}"},
        {pos: [9, 0, 38], state: "minecraft:polished_basalt{axis:y}"},
        {pos: [10, 0, 0], state: "minecraft:polished_basalt{axis:x}"},
        {pos: [10, 0, 1], state: "minecraft:deepslate{axis:y}"},
        {pos: [10, 0, 2], state: "minecraft:deepslate{axis:y}"},
        {pos: [10, 0, 3], state: "minecraft:deepslate{axis:y}"},
        {pos: [10, 0, 4], state: "minecraft:deepslate{axis:y}"},
        {pos: [10, 0, 5], state: "minecraft:deepslate{axis:y}"},
        {pos: [10, 0, 6], state: "minecraft:deepslate{axis:y}"},
        {pos: [10, 0, 7], state: "minecraft:deepslate{axis:y}"},
        {pos: [10, 0, 8], state: "minecraft:polished_basalt{axis:x}"},
        {pos: [10, 0, 15], state: "minecraft:deepslate_tiles"},
        {pos: [10, 0, 16], state: "minecraft:deepslate_tiles"},
        {pos: [10, 0, 17], state: "minecraft:deepslate_tiles"},
        {pos: [10, 0, 18], state: "minecraft:deepslate_tiles"},
        {pos: [10, 0, 19], state: "minecraft:deepslate_tiles"},
        {pos: [10, 0, 20], state: "minecraft:deepslate_tiles"},
        {pos: [10, 0, 21], state: "minecraft:deepslate_tiles"},
        {pos: [10, 0, 22], state: "minecraft:deepslate_tiles"},
        {pos: [10, 0, 23], state: "minecraft:deepslate_tiles"},
        {pos: [10, 0, 30], state: "minecraft:polished_basalt{axis:x}"},
        {pos: [10, 0, 31], state: "minecraft:deepslate{axis:y}"},
        {pos: [10, 0, 32], state: "minecraft:deepslate{axis:y}"},
        {pos: [10, 0, 33], state: "minecraft:deepslate{axis:y}"},
        {pos: [10, 0, 34], state: "minecraft:deepslate{axis:y}"},
        {pos: [10, 0, 35], state: "minecraft:deepslate{axis:y}"},
        {pos: [10, 0, 36], state: "minecraft:deepslate{axis:y}"},
        {pos: [10, 0, 37], state: "minecraft:deepslate{axis:y}"},
        {pos: [10, 0, 38], state: "minecraft:polished_basalt{axis:x}"},
        {pos: [11, 0, 0], state: "minecraft:polished_basalt{axis:x}"},
        {pos: [11, 0, 1], state: "minecraft:deepslate{axis:y}"},
        {pos: [11, 0, 2], state: "minecraft:deepslate{axis:y}"},
        {pos: [11, 0, 3], state: "minecraft:deepslate{axis:y}"},
        {pos: [11, 0, 4], state: "minecraft:deepslate{axis:y}"},
        {pos: [11, 0, 5], state: "minecraft:deepslate{axis:y}"},
        {pos: [11, 0, 6], state: "minecraft:deepslate{axis:y}"},
        {pos: [11, 0, 7], state: "minecraft:deepslate{axis:y}"},
        {pos: [11, 0, 8], state: "minecraft:polished_basalt{axis:x}"},
        {pos: [11, 0, 15], state: "minecraft:deepslate_tiles"},
        {pos: [11, 0, 16], state: "minecraft:deepslate_tiles"},
        {pos: [11, 0, 17], state: "minecraft:deepslate_tiles"},
        {pos: [11, 0, 18], state: "minecraft:deepslate_tiles"},
        {pos: [11, 0, 19], state: "minecraft:deepslate_tiles"},
        {pos: [11, 0, 20], state: "minecraft:deepslate_tiles"},
        {pos: [11, 0, 21], state: "minecraft:deepslate_tiles"},
        {pos: [11, 0, 22], state: "minecraft:deepslate_tiles"},
        {pos: [11, 0, 23], state: "minecraft:deepslate_tiles"},
        {pos: [11, 0, 30], state: "minecraft:polished_basalt{axis:x}"},
        {pos: [11, 0, 31], state: "minecraft:deepslate{axis:y}"},
        {pos: [11, 0, 32], state: "minecraft:deepslate{axis:y}"},
        {pos: [11, 0, 33], state: "minecraft:deepslate{axis:y}"},
        {pos: [11, 0, 34], state: "minecraft:deepslate{axis:y}"},
        {pos: [11, 0, 35], state: "minecraft:deepslate{axis:y}"},
        {pos: [11, 0, 36], state: "minecraft:deepslate{axis:y}"},
        {pos: [11, 0, 37], state: "minecraft:deepslate{axis:y}"},
        {pos: [11, 0, 38], state: "minecraft:polished_basalt{axis:x}"},
        {pos: [12, 0, 0], state: "minecraft:deepslate{axis:y}"},
        {pos: [12, 0, 1], state: "minecraft:deepslate{axis:y}"},
        {pos: [12, 0, 2], state: "minecraft:deepslate{axis:y}"},
        {pos: [12, 0, 3], state: "minecraft:deepslate{axis:y}"},
        {pos: [12, 0, 4], state: "minecraft:deepslate{axis:y}"},
        {pos: [12, 0, 5], state: "minecraft:deepslate{axis:y}"},
        {pos: [12, 0, 6], state: "minecraft:deepslate{axis:y}"},
        {pos: [12, 0, 7], state: "minecraft:deepslate{axis:y}"},
        {pos: [12, 0, 8], state: "minecraft:polished_basalt{axis:x}"},
        {pos: [12, 0, 15], state: "minecraft:deepslate_tiles"},
        {pos: [12, 0, 16], state: "minecraft:deepslate_tiles"},
        {pos: [12, 0, 17], state: "minecraft:deepslate_tiles"},
        {pos: [12, 0, 18], state: "minecraft:deepslate_tiles"},
        {pos: [12, 0, 19], state: "minecraft:deepslate_tiles"},
        {pos: [12, 0, 20], state: "minecraft:deepslate_tiles"},
        {pos: [12, 0, 21], state: "minecraft:deepslate_tiles"},
        {pos: [12, 0, 22], state: "minecraft:deepslate_tiles"},
        {pos: [12, 0, 23], state: "minecraft:deepslate_tiles"},
        {pos: [12, 0, 30], state: "minecraft:polished_basalt{axis:x}"},
        {pos: [12, 0, 31], state: "minecraft:deepslate{axis:y}"},
        {pos: [12, 0, 32], state: "minecraft:deepslate{axis:y}"},
        {pos: [12, 0, 33], state: "minecraft:deepslate{axis:y}"},
        {pos: [12, 0, 34], state: "minecraft:deepslate{axis:y}"},
        {pos: [12, 0, 35], state: "minecraft:deepslate{axis:y}"},
        {pos: [12, 0, 36], state: "minecraft:deepslate{axis:y}"},
        {pos: [12, 0, 37], state: "minecraft:deepslate{axis:y}"},
        {pos: [12, 0, 38], state: "minecraft:deepslate{axis:y}"},
        {pos: [13, 0, 0], state: "minecraft:deepslate{axis:y}"},
        {pos: [13, 0, 1], state: "minecraft:deepslate{axis:y}"},
        {pos: [13, 0, 2], state: "minecraft:deepslate{axis:y}"},
        {pos: [13, 0, 3], state: "minecraft:deepslate{axis:y}"},
        {pos: [13, 0, 4], state: "minecraft:deepslate{axis:y}"},
        {pos: [13, 0, 5], state: "minecraft:deepslate{axis:y}"},
        {pos: [13, 0, 6], state: "minecraft:deepslate{axis:y}"},
        {pos: [13, 0, 7], state: "minecraft:deepslate{axis:y}"},
        {pos: [13, 0, 8], state: "minecraft:polished_basalt{axis:y}"},
        {pos: [13, 0, 9], state: "minecraft:polished_basalt{axis:z}"},
        {pos: [13, 0, 10], state: "minecraft:polished_basalt{axis:z}"},
        {pos: [13, 0, 11], state: "minecraft:polished_basalt{axis:z}"},
        {pos: [13, 0, 12], state: "minecraft:polished_basalt{axis:z}"},
        {pos: [13, 0, 13], state: "minecraft:polished_basalt{axis:z}"},
        {pos: [13, 0, 14], state: "minecraft:polished_basalt{axis:z}"},
        {pos: [13, 0, 15], state: "minecraft:deepslate_tiles"},
        {pos: [13, 0, 16], state: "minecraft:deepslate_tiles"},
        {pos: [13, 0, 17], state: "minecraft:deepslate_tiles"},
        {pos: [13, 0, 18], state: "minecraft:deepslate_tiles"},
        {pos: [13, 0, 19], state: "minecraft:deepslate_tiles"},
        {pos: [13, 0, 20], state: "minecraft:deepslate_tiles"},
        {pos: [13, 0, 21], state: "minecraft:deepslate_tiles"},
        {pos: [13, 0, 22], state: "minecraft:deepslate_tiles"},
        {pos: [13, 0, 23], state: "minecraft:deepslate_tiles"},
        {pos: [13, 0, 24], state: "minecraft:polished_basalt{axis:z}"},
        {pos: [13, 0, 25], state: "minecraft:polished_basalt{axis:z}"},
        {pos: [13, 0, 26], state: "minecraft:polished_basalt{axis:z}"},
        {pos: [13, 0, 27], state: "minecraft:polished_basalt{axis:z}"},
        {pos: [13, 0, 28], state: "minecraft:polished_basalt{axis:z}"},
        {pos: [13, 0, 29], state: "minecraft:polished_basalt{axis:z}"},
        {pos: [13, 0, 30], state: "minecraft:polished_basalt{axis:y}"},
        {pos: [13, 0, 31], state: "minecraft:deepslate{axis:y}"},
        {pos: [13, 0, 32], state: "minecraft:deepslate{axis:y}"},
        {pos: [13, 0, 33], state: "minecraft:deepslate{axis:y}"},
        {pos: [13, 0, 34], state: "minecraft:deepslate{axis:y}"},
        {pos: [13, 0, 35], state: "minecraft:deepslate{axis:y}"},
        {pos: [13, 0, 36], state: "minecraft:deepslate{axis:y}"},
        {pos: [13, 0, 37], state: "minecraft:deepslate{axis:y}"},
        {pos: [13, 0, 38], state: "minecraft:deepslate{axis:y}"},
        {pos: [14, 0, 1], state: "minecraft:deepslate{axis:y}"},
        {pos: [14, 0, 2], state: "minecraft:deepslate{axis:y}"},
        {pos: [14, 0, 3], state: "minecraft:deepslate{axis:y}"},
        {pos: [14, 0, 4], state: "minecraft:deepslate{axis:y}"},
        {pos: [14, 0, 5], state: "minecraft:deepslate{axis:y}"},
        {pos: [14, 0, 6], state: "minecraft:deepslate{axis:y}"},
        {pos: [14, 0, 7], state: "minecraft:deepslate{axis:y}"},
        {pos: [14, 0, 8], state: "minecraft:deepslate{axis:y}"},
        {pos: [14, 0, 9], state: "minecraft:deepslate{axis:y}"},
        {pos: [14, 0, 10], state: "minecraft:deepslate{axis:y}"},
        {pos: [14, 0, 11], state: "minecraft:deepslate{axis:y}"},
        {pos: [14, 0, 12], state: "minecraft:deepslate{axis:y}"},
        {pos: [14, 0, 13], state: "minecraft:deepslate{axis:y}"},
        {pos: [14, 0, 14], state: "minecraft:deepslate{axis:y}"},
        {pos: [14, 0, 15], state: "minecraft:deepslate{axis:y}"},
        {pos: [14, 0, 16], state: "minecraft:deepslate{axis:y}"},
        {pos: [14, 0, 17], state: "minecraft:deepslate_tiles"},
        {pos: [14, 0, 18], state: "minecraft:deepslate_tiles"},
        {pos: [14, 0, 19], state: "minecraft:deepslate_tiles"},
        {pos: [14, 0, 20], state: "minecraft:deepslate_tiles"},
        {pos: [14, 0, 21], state: "minecraft:deepslate_tiles"},
        {pos: [14, 0, 22], state: "minecraft:deepslate{axis:y}"},
        {pos: [14, 0, 23], state: "minecraft:deepslate{axis:y}"},
        {pos: [14, 0, 24], state: "minecraft:deepslate{axis:y}"},
        {pos: [14, 0, 25], state: "minecraft:deepslate{axis:y}"},
        {pos: [14, 0, 26], state: "minecraft:deepslate{axis:y}"},
        {pos: [14, 0, 27], state: "minecraft:deepslate{axis:y}"},
        {pos: [14, 0, 28], state: "minecraft:deepslate{axis:y}"},
        {pos: [14, 0, 29], state: "minecraft:deepslate{axis:y}"},
        {pos: [14, 0, 30], state: "minecraft:deepslate{axis:y}"},
        {pos: [14, 0, 31], state: "minecraft:deepslate{axis:y}"},
        {pos: [14, 0, 32], state: "minecraft:deepslate{axis:y}"},
        {pos: [14, 0, 33], state: "minecraft:deepslate{axis:y}"},
        {pos: [14, 0, 34], state: "minecraft:deepslate{axis:y}"},
        {pos: [14, 0, 35], state: "minecraft:deepslate{axis:y}"},
        {pos: [14, 0, 36], state: "minecraft:deepslate{axis:y}"},
        {pos: [14, 0, 37], state: "minecraft:deepslate{axis:y}"},
        {pos: [15, 0, 0], state: "minecraft:deepslate{axis:y}"},
        {pos: [15, 0, 1], state: "minecraft:deepslate{axis:y}"},
        {pos: [15, 0, 2], state: "minecraft:deepslate{axis:y}"},
        {pos: [15, 0, 3], state: "minecraft:deepslate{axis:y}"},
        {pos: [15, 0, 4], state: "minecraft:deepslate{axis:y}"},
        {pos: [15, 0, 5], state: "minecraft:deepslate{axis:y}"},
        {pos: [15, 0, 6], state: "minecraft:deepslate{axis:y}"},
        {pos: [15, 0, 7], state: "minecraft:deepslate{axis:y}"},
        {pos: [15, 0, 8], state: "minecraft:deepslate{axis:y}"},
        {pos: [15, 0, 9], state: "minecraft:deepslate{axis:y}"},
        {pos: [15, 0, 10], state: "minecraft:deepslate{axis:y}"},
        {pos: [15, 0, 11], state: "minecraft:deepslate{axis:y}"},
        {pos: [15, 0, 12], state: "minecraft:deepslate{axis:y}"},
        {pos: [15, 0, 13], state: "minecraft:deepslate{axis:y}"},
        {pos: [15, 0, 14], state: "minecraft:deepslate{axis:y}"},
        {pos: [15, 0, 15], state: "minecraft:deepslate{axis:y}"},
        {pos: [15, 0, 16], state: "minecraft:deepslate{axis:y}"},
        {pos: [15, 0, 17], state: "minecraft:deepslate_tiles"},
        {pos: [15, 0, 18], state: "minecraft:deepslate_tiles"},
        {pos: [15, 0, 19], state: "minecraft:deepslate_tiles"},
        {pos: [15, 0, 20], state: "minecraft:deepslate_tiles"},
        {pos: [15, 0, 21], state: "minecraft:deepslate_tiles"},
        {pos: [15, 0, 22], state: "minecraft:deepslate{axis:y}"},
        {pos: [15, 0, 23], state: "minecraft:deepslate{axis:y}"},
        {pos: [15, 0, 24], state: "minecraft:deepslate{axis:y}"},
        {pos: [15, 0, 25], state: "minecraft:deepslate{axis:y}"},
        {pos: [15, 0, 26], state: "minecraft:deepslate{axis:y}"},
        {pos: [15, 0, 27], state: "minecraft:deepslate{axis:y}"},
        {pos: [15, 0, 28], state: "minecraft:deepslate{axis:y}"},
        {pos: [15, 0, 29], state: "minecraft:deepslate{axis:y}"},
        {pos: [15, 0, 30], state: "minecraft:deepslate{axis:y}"},
        {pos: [15, 0, 31], state: "minecraft:deepslate{axis:y}"},
        {pos: [15, 0, 32], state: "minecraft:deepslate{axis:y}"},
        {pos: [15, 0, 33], state: "minecraft:deepslate{axis:y}"},
        {pos: [15, 0, 34], state: "minecraft:deepslate{axis:y}"},
        {pos: [15, 0, 35], state: "minecraft:deepslate{axis:y}"},
        {pos: [15, 0, 36], state: "minecraft:deepslate{axis:y}"},
        {pos: [15, 0, 37], state: "minecraft:deepslate{axis:y}"},
        {pos: [15, 0, 38], state: "minecraft:deepslate{axis:y}"},
        {pos: [16, 0, 0], state: "minecraft:deepslate{axis:y}"},
        {pos: [16, 0, 1], state: "minecraft:deepslate{axis:y}"},
        {pos: [16, 0, 2], state: "minecraft:deepslate{axis:y}"},
        {pos: [16, 0, 3], state: "minecraft:deepslate{axis:y}"},
        {pos: [16, 0, 4], state: "minecraft:deepslate{axis:y}"},
        {pos: [16, 0, 5], state: "minecraft:deepslate{axis:y}"},
        {pos: [16, 0, 6], state: "minecraft:deepslate{axis:y}"},
        {pos: [16, 0, 7], state: "minecraft:deepslate{axis:y}"},
        {pos: [16, 0, 8], state: "minecraft:polished_basalt{axis:y}"},
        {pos: [16, 0, 9], state: "minecraft:polished_basalt{axis:z}"},
        {pos: [16, 0, 10], state: "minecraft:polished_basalt{axis:z}"},
        {pos: [16, 0, 11], state: "minecraft:polished_basalt{axis:z}"},
        {pos: [16, 0, 12], state: "minecraft:polished_basalt{axis:z}"},
        {pos: [16, 0, 13], state: "minecraft:polished_basalt{axis:z}"},
        {pos: [16, 0, 14], state: "minecraft:polished_basalt{axis:z}"},
        {pos: [16, 0, 15], state: "minecraft:deepslate_tiles"},
        {pos: [16, 0, 16], state: "minecraft:deepslate_tiles"},
        {pos: [16, 0, 17], state: "minecraft:deepslate_tiles"},
        {pos: [16, 0, 18], state: "minecraft:deepslate_tiles"},
        {pos: [16, 0, 19], state: "minecraft:deepslate_tiles"},
        {pos: [16, 0, 20], state: "minecraft:deepslate_tiles"},
        {pos: [16, 0, 21], state: "minecraft:deepslate_tiles"},
        {pos: [16, 0, 22], state: "minecraft:deepslate_tiles"},
        {pos: [16, 0, 23], state: "minecraft:deepslate_tiles"},
        {pos: [16, 0, 24], state: "minecraft:polished_basalt{axis:z}"},
        {pos: [16, 0, 25], state: "minecraft:polished_basalt{axis:z}"},
        {pos: [16, 0, 26], state: "minecraft:polished_basalt{axis:z}"},
        {pos: [16, 0, 27], state: "minecraft:polished_basalt{axis:z}"},
        {pos: [16, 0, 28], state: "minecraft:polished_basalt{axis:z}"},
        {pos: [16, 0, 29], state: "minecraft:polished_basalt{axis:z}"},
        {pos: [16, 0, 30], state: "minecraft:polished_basalt{axis:y}"},
        {pos: [16, 0, 31], state: "minecraft:deepslate{axis:y}"},
        {pos: [16, 0, 32], state: "minecraft:deepslate{axis:y}"},
        {pos: [16, 0, 33], state: "minecraft:deepslate{axis:y}"},
        {pos: [16, 0, 34], state: "minecraft:deepslate{axis:y}"},
        {pos: [16, 0, 35], state: "minecraft:deepslate{axis:y}"},
        {pos: [16, 0, 36], state: "minecraft:deepslate{axis:y}"},
        {pos: [16, 0, 37], state: "minecraft:deepslate{axis:y}"},
        {pos: [16, 0, 38], state: "minecraft:deepslate{axis:y}"},
        {pos: [17, 0, 0], state: "minecraft:deepslate{axis:y}"},
        {pos: [17, 0, 1], state: "minecraft:deepslate{axis:y}"},
        {pos: [17, 0, 2], state: "minecraft:deepslate{axis:y}"},
        {pos: [17, 0, 3], state: "minecraft:deepslate{axis:y}"},
        {pos: [17, 0, 4], state: "minecraft:deepslate{axis:y}"},
        {pos: [17, 0, 5], state: "minecraft:deepslate{axis:y}"},
        {pos: [17, 0, 6], state: "minecraft:deepslate{axis:y}"},
        {pos: [17, 0, 7], state: "minecraft:deepslate{axis:y}"},
        {pos: [17, 0, 8], state: "minecraft:polished_basalt{axis:x}"},
        {pos: [17, 0, 15], state: "minecraft:deepslate_tiles"},
        {pos: [17, 0, 16], state: "minecraft:deepslate_tiles"},
        {pos: [17, 0, 17], state: "minecraft:deepslate_tiles"},
        {pos: [17, 0, 18], state: "minecraft:deepslate_tiles"},
        {pos: [17, 0, 19], state: "minecraft:deepslate_tiles"},
        {pos: [17, 0, 20], state: "minecraft:deepslate_tiles"},
        {pos: [17, 0, 21], state: "minecraft:deepslate_tiles"},
        {pos: [17, 0, 22], state: "minecraft:deepslate_tiles"},
        {pos: [17, 0, 23], state: "minecraft:deepslate_tiles"},
        {pos: [17, 0, 30], state: "minecraft:polished_basalt{axis:x}"},
        {pos: [17, 0, 31], state: "minecraft:deepslate{axis:y}"},
        {pos: [17, 0, 32], state: "minecraft:deepslate{axis:y}"},
        {pos: [17, 0, 33], state: "minecraft:deepslate{axis:y}"},
        {pos: [17, 0, 34], state: "minecraft:deepslate{axis:y}"},
        {pos: [17, 0, 35], state: "minecraft:deepslate{axis:y}"},
        {pos: [17, 0, 36], state: "minecraft:deepslate{axis:y}"},
        {pos: [17, 0, 37], state: "minecraft:deepslate{axis:y}"},
        {pos: [17, 0, 38], state: "minecraft:deepslate{axis:y}"},
        {pos: [18, 0, 0], state: "minecraft:polished_basalt{axis:x}"},
        {pos: [18, 0, 1], state: "minecraft:deepslate{axis:y}"},
        {pos: [18, 0, 2], state: "minecraft:deepslate{axis:y}"},
        {pos: [18, 0, 3], state: "minecraft:deepslate{axis:y}"},
        {pos: [18, 0, 4], state: "minecraft:deepslate{axis:y}"},
        {pos: [18, 0, 5], state: "minecraft:deepslate{axis:y}"},
        {pos: [18, 0, 6], state: "minecraft:deepslate{axis:y}"},
        {pos: [18, 0, 7], state: "minecraft:deepslate{axis:y}"},
        {pos: [18, 0, 8], state: "minecraft:polished_basalt{axis:x}"},
        {pos: [18, 0, 15], state: "minecraft:deepslate_tiles"},
        {pos: [18, 0, 16], state: "minecraft:deepslate_tiles"},
        {pos: [18, 0, 17], state: "minecraft:deepslate_tiles"},
        {pos: [18, 0, 18], state: "minecraft:deepslate_tiles"},
        {pos: [18, 0, 19], state: "minecraft:deepslate_tiles"},
        {pos: [18, 0, 20], state: "minecraft:deepslate_tiles"},
        {pos: [18, 0, 21], state: "minecraft:deepslate_tiles"},
        {pos: [18, 0, 22], state: "minecraft:deepslate_tiles"},
        {pos: [18, 0, 23], state: "minecraft:deepslate_tiles"},
        {pos: [18, 0, 30], state: "minecraft:polished_basalt{axis:x}"},
        {pos: [18, 0, 31], state: "minecraft:deepslate{axis:y}"},
        {pos: [18, 0, 32], state: "minecraft:deepslate{axis:y}"},
        {pos: [18, 0, 33], state: "minecraft:deepslate{axis:y}"},
        {pos: [18, 0, 34], state: "minecraft:deepslate{axis:y}"},
        {pos: [18, 0, 35], state: "minecraft:deepslate{axis:y}"},
        {pos: [18, 0, 36], state: "minecraft:deepslate{axis:y}"},
        {pos: [18, 0, 37], state: "minecraft:deepslate{axis:y}"},
        {pos: [18, 0, 38], state: "minecraft:polished_basalt{axis:x}"},
        {pos: [19, 0, 0], state: "minecraft:polished_basalt{axis:x}"},
        {pos: [19, 0, 1], state: "minecraft:deepslate{axis:y}"},
        {pos: [19, 0, 2], state: "minecraft:deepslate{axis:y}"},
        {pos: [19, 0, 3], state: "minecraft:deepslate{axis:y}"},
        {pos: [19, 0, 4], state: "minecraft:deepslate{axis:y}"},
        {pos: [19, 0, 5], state: "minecraft:deepslate{axis:y}"},
        {pos: [19, 0, 6], state: "minecraft:deepslate{axis:y}"},
        {pos: [19, 0, 7], state: "minecraft:deepslate{axis:y}"},
        {pos: [19, 0, 8], state: "minecraft:polished_basalt{axis:x}"},
        {pos: [19, 0, 15], state: "minecraft:deepslate_tiles"},
        {pos: [19, 0, 16], state: "minecraft:deepslate_tiles"},
        {pos: [19, 0, 17], state: "minecraft:deepslate_tiles"},
        {pos: [19, 0, 18], state: "minecraft:deepslate_tiles"},
        {pos: [19, 0, 19], state: "minecraft:deepslate_tiles"},
        {pos: [19, 0, 20], state: "minecraft:deepslate_tiles"},
        {pos: [19, 0, 21], state: "minecraft:deepslate_tiles"},
        {pos: [19, 0, 22], state: "minecraft:deepslate_tiles"},
        {pos: [19, 0, 23], state: "minecraft:deepslate_tiles"},
        {pos: [19, 0, 30], state: "minecraft:polished_basalt{axis:x}"},
        {pos: [19, 0, 31], state: "minecraft:deepslate{axis:y}"},
        {pos: [19, 0, 32], state: "minecraft:deepslate{axis:y}"},
        {pos: [19, 0, 33], state: "minecraft:deepslate{axis:y}"},
        {pos: [19, 0, 34], state: "minecraft:deepslate{axis:y}"},
        {pos: [19, 0, 35], state: "minecraft:deepslate{axis:y}"},
        {pos: [19, 0, 36], state: "minecraft:deepslate{axis:y}"},
        {pos: [19, 0, 37], state: "minecraft:deepslate{axis:y}"},
        {pos: [19, 0, 38], state: "minecraft:polished_basalt{axis:x}"},
        {pos: [20, 0, 0], state: "minecraft:polished_basalt{axis:x}"},
        {pos: [20, 0, 1], state: "minecraft:deepslate{axis:y}"},
        {pos: [20, 0, 2], state: "minecraft:deepslate{axis:y}"},
        {pos: [20, 0, 3], state: "minecraft:deepslate{axis:y}"},
        {pos: [20, 0, 4], state: "minecraft:deepslate{axis:y}"},
        {pos: [20, 0, 5], state: "minecraft:deepslate{axis:y}"},
        {pos: [20, 0, 6], state: "minecraft:deepslate{axis:y}"},
        {pos: [20, 0, 7], state: "minecraft:deepslate{axis:y}"},
        {pos: [20, 0, 8], state: "minecraft:polished_basalt{axis:x}"},
        {pos: [20, 0, 15], state: "minecraft:deepslate_tiles"},
        {pos: [20, 0, 16], state: "minecraft:deepslate_tiles"},
        {pos: [20, 0, 17], state: "minecraft:deepslate_tiles"},
        {pos: [20, 0, 18], state: "minecraft:deepslate_tiles"},
        {pos: [20, 0, 19], state: "minecraft:deepslate_tiles"},
        {pos: [20, 0, 20], state: "minecraft:deepslate_tiles"},
        {pos: [20, 0, 21], state: "minecraft:deepslate_tiles"},
        {pos: [20, 0, 22], state: "minecraft:deepslate_tiles"},
        {pos: [20, 0, 23], state: "minecraft:deepslate_tiles"},
        {pos: [20, 0, 30], state: "minecraft:polished_basalt{axis:x}"},
        {pos: [20, 0, 31], state: "minecraft:deepslate{axis:y}"},
        {pos: [20, 0, 32], state: "minecraft:deepslate{axis:y}"},
        {pos: [20, 0, 33], state: "minecraft:deepslate{axis:y}"},
        {pos: [20, 0, 34], state: "minecraft:deepslate{axis:y}"},
        {pos: [20, 0, 35], state: "minecraft:deepslate{axis:y}"},
        {pos: [20, 0, 36], state: "minecraft:deepslate{axis:y}"},
        {pos: [20, 0, 37], state: "minecraft:deepslate{axis:y}"},
        {pos: [20, 0, 38], state: "minecraft:polished_basalt{axis:x}"},
        {pos: [21, 0, 0], state: "minecraft:polished_basalt{axis:x}"},
        {pos: [21, 0, 1], state: "minecraft:deepslate{axis:y}"},
        {pos: [21, 0, 2], state: "minecraft:deepslate{axis:y}"},
        {pos: [21, 0, 3], state: "minecraft:deepslate{axis:y}"},
        {pos: [21, 0, 4], state: "minecraft:deepslate{axis:y}"},
        {pos: [21, 0, 5], state: "minecraft:deepslate{axis:y}"},
        {pos: [21, 0, 6], state: "minecraft:deepslate{axis:y}"},
        {pos: [21, 0, 7], state: "minecraft:deepslate{axis:y}"},
        {pos: [21, 0, 8], state: "minecraft:polished_basalt{axis:x}"},
        {pos: [21, 0, 15], state: "minecraft:deepslate_tiles"},
        {pos: [21, 0, 16], state: "minecraft:deepslate_tiles"},
        {pos: [21, 0, 17], state: "minecraft:deepslate_tiles"},
        {pos: [21, 0, 18], state: "minecraft:deepslate_tiles"},
        {pos: [21, 0, 19], state: "minecraft:deepslate_tiles"},
        {pos: [21, 0, 20], state: "minecraft:deepslate_tiles"},
        {pos: [21, 0, 21], state: "minecraft:deepslate_tiles"},
        {pos: [21, 0, 22], state: "minecraft:deepslate_tiles"},
        {pos: [21, 0, 23], state: "minecraft:deepslate_tiles"},
        {pos: [21, 0, 30], state: "minecraft:polished_basalt{axis:x}"},
        {pos: [21, 0, 31], state: "minecraft:deepslate{axis:y}"},
        {pos: [21, 0, 32], state: "minecraft:deepslate{axis:y}"},
        {pos: [21, 0, 33], state: "minecraft:deepslate{axis:y}"},
        {pos: [21, 0, 34], state: "minecraft:deepslate{axis:y}"},
        {pos: [21, 0, 35], state: "minecraft:deepslate{axis:y}"},
        {pos: [21, 0, 36], state: "minecraft:deepslate{axis:y}"},
        {pos: [21, 0, 37], state: "minecraft:deepslate{axis:y}"},
        {pos: [21, 0, 38], state: "minecraft:polished_basalt{axis:x}"},
        {pos: [22, 0, 0], state: "minecraft:deepslate{axis:y}"},
        {pos: [22, 0, 1], state: "minecraft:deepslate{axis:y}"},
        {pos: [22, 0, 2], state: "minecraft:deepslate{axis:y}"},
        {pos: [22, 0, 3], state: "minecraft:deepslate{axis:y}"},
        {pos: [22, 0, 4], state: "minecraft:deepslate{axis:y}"},
        {pos: [22, 0, 5], state: "minecraft:deepslate{axis:y}"},
        {pos: [22, 0, 6], state: "minecraft:deepslate{axis:y}"},
        {pos: [22, 0, 7], state: "minecraft:deepslate{axis:y}"},
        {pos: [22, 0, 8], state: "minecraft:polished_basalt{axis:x}"},
        {pos: [22, 0, 15], state: "minecraft:deepslate_tiles"},
        {pos: [22, 0, 16], state: "minecraft:deepslate_tiles"},
        {pos: [22, 0, 17], state: "minecraft:deepslate_tiles"},
        {pos: [22, 0, 18], state: "minecraft:deepslate_tiles"},
        {pos: [22, 0, 19], state: "minecraft:deepslate_tiles"},
        {pos: [22, 0, 20], state: "minecraft:deepslate_tiles"},
        {pos: [22, 0, 21], state: "minecraft:deepslate_tiles"},
        {pos: [22, 0, 22], state: "minecraft:deepslate_tiles"},
        {pos: [22, 0, 23], state: "minecraft:deepslate_tiles"},
        {pos: [22, 0, 30], state: "minecraft:polished_basalt{axis:x}"},
        {pos: [22, 0, 31], state: "minecraft:deepslate{axis:y}"},
        {pos: [22, 0, 32], state: "minecraft:deepslate{axis:y}"},
        {pos: [22, 0, 33], state: "minecraft:deepslate{axis:y}"},
        {pos: [22, 0, 34], state: "minecraft:deepslate{axis:y}"},
        {pos: [22, 0, 35], state: "minecraft:deepslate{axis:y}"},
        {pos: [22, 0, 36], state: "minecraft:deepslate{axis:y}"},
        {pos: [22, 0, 37], state: "minecraft:deepslate{axis:y}"},
        {pos: [22, 0, 38], state: "minecraft:deepslate{axis:y}"},
        {pos: [23, 0, 0], state: "minecraft:deepslate{axis:y}"},
        {pos: [23, 0, 1], state: "minecraft:deepslate{axis:y}"},
        {pos: [23, 0, 2], state: "minecraft:deepslate{axis:y}"},
        {pos: [23, 0, 3], state: "minecraft:deepslate{axis:y}"},
        {pos: [23, 0, 4], state: "minecraft:deepslate{axis:y}"},
        {pos: [23, 0, 5], state: "minecraft:deepslate{axis:y}"},
        {pos: [23, 0, 6], state: "minecraft:deepslate{axis:y}"},
        {pos: [23, 0, 7], state: "minecraft:deepslate{axis:y}"},
        {pos: [23, 0, 8], state: "minecraft:polished_basalt{axis:y}"},
        {pos: [23, 0, 9], state: "minecraft:polished_basalt{axis:z}"},
        {pos: [23, 0, 10], state: "minecraft:polished_basalt{axis:z}"},
        {pos: [23, 0, 11], state: "minecraft:polished_basalt{axis:z}"},
        {pos: [23, 0, 12], state: "minecraft:polished_basalt{axis:z}"},
        {pos: [23, 0, 13], state: "minecraft:polished_basalt{axis:z}"},
        {pos: [23, 0, 14], state: "minecraft:polished_basalt{axis:z}"},
        {pos: [23, 0, 15], state: "minecraft:deepslate_tiles"},
        {pos: [23, 0, 16], state: "minecraft:deepslate_tiles"},
        {pos: [23, 0, 17], state: "minecraft:deepslate_tiles"},
        {pos: [23, 0, 18], state: "minecraft:deepslate_tiles"},
        {pos: [23, 0, 19], state: "minecraft:deepslate_tiles"},
        {pos: [23, 0, 20], state: "minecraft:deepslate_tiles"},
        {pos: [23, 0, 21], state: "minecraft:deepslate_tiles"},
        {pos: [23, 0, 22], state: "minecraft:deepslate_tiles"},
        {pos: [23, 0, 23], state: "minecraft:deepslate_tiles"},
        {pos: [23, 0, 24], state: "minecraft:polished_basalt{axis:z}"},
        {pos: [23, 0, 25], state: "minecraft:polished_basalt{axis:z}"},
        {pos: [23, 0, 26], state: "minecraft:polished_basalt{axis:z}"},
        {pos: [23, 0, 27], state: "minecraft:polished_basalt{axis:z}"},
        {pos: [23, 0, 28], state: "minecraft:polished_basalt{axis:z}"},
        {pos: [23, 0, 29], state: "minecraft:polished_basalt{axis:z}"},
        {pos: [23, 0, 30], state: "minecraft:polished_basalt{axis:y}"},
        {pos: [23, 0, 31], state: "minecraft:deepslate{axis:y}"},
        {pos: [23, 0, 32], state: "minecraft:deepslate{axis:y}"},
        {pos: [23, 0, 33], state: "minecraft:deepslate{axis:y}"},
        {pos: [23, 0, 34], state: "minecraft:deepslate{axis:y}"},
        {pos: [23, 0, 35], state: "minecraft:deepslate{axis:y}"},
        {pos: [23, 0, 36], state: "minecraft:deepslate{axis:y}"},
        {pos: [23, 0, 37], state: "minecraft:deepslate{axis:y}"},
        {pos: [23, 0, 38], state: "minecraft:deepslate{axis:y}"},
        {pos: [24, 0, 0], state: "minecraft:deepslate{axis:y}"},
        {pos: [24, 0, 1], state: "minecraft:deepslate{axis:y}"},
        {pos: [24, 0, 2], state: "minecraft:deepslate{axis:y}"},
        {pos: [24, 0, 3], state: "minecraft:deepslate{axis:y}"},
        {pos: [24, 0, 4], state: "minecraft:deepslate{axis:y}"},
        {pos: [24, 0, 5], state: "minecraft:deepslate{axis:y}"},
        {pos: [24, 0, 6], state: "minecraft:deepslate{axis:y}"},
        {pos: [24, 0, 7], state: "minecraft:deepslate{axis:y}"},
        {pos: [24, 0, 8], state: "minecraft:deepslate{axis:y}"},
        {pos: [24, 0, 9], state: "minecraft:deepslate{axis:y}"},
        {pos: [24, 0, 10], state: "minecraft:deepslate{axis:y}"},
        {pos: [24, 0, 11], state: "minecraft:deepslate{axis:y}"},
        {pos: [24, 0, 12], state: "minecraft:deepslate{axis:y}"},
        {pos: [24, 0, 13], state: "minecraft:deepslate{axis:y}"},
        {pos: [24, 0, 14], state: "minecraft:deepslate{axis:y}"},
        {pos: [24, 0, 15], state: "minecraft:deepslate{axis:y}"},
        {pos: [24, 0, 16], state: "minecraft:deepslate{axis:y}"},
        {pos: [24, 0, 17], state: "minecraft:deepslate_tiles"},
        {pos: [24, 0, 18], state: "minecraft:deepslate_tiles"},
        {pos: [24, 0, 19], state: "minecraft:deepslate_tiles"},
        {pos: [24, 0, 20], state: "minecraft:deepslate_tiles"},
        {pos: [24, 0, 21], state: "minecraft:deepslate_tiles"},
        {pos: [24, 0, 22], state: "minecraft:deepslate{axis:y}"},
        {pos: [24, 0, 23], state: "minecraft:deepslate{axis:y}"},
        {pos: [24, 0, 24], state: "minecraft:deepslate{axis:y}"},
        {pos: [24, 0, 25], state: "minecraft:deepslate{axis:y}"},
        {pos: [24, 0, 26], state: "minecraft:deepslate{axis:y}"},
        {pos: [24, 0, 27], state: "minecraft:deepslate{axis:y}"},
        {pos: [24, 0, 28], state: "minecraft:deepslate{axis:y}"},
        {pos: [24, 0, 29], state: "minecraft:deepslate{axis:y}"},
        {pos: [24, 0, 30], state: "minecraft:deepslate{axis:y}"},
        {pos: [24, 0, 31], state: "minecraft:deepslate{axis:y}"},
        {pos: [24, 0, 32], state: "minecraft:deepslate{axis:y}"},
        {pos: [24, 0, 33], state: "minecraft:deepslate{axis:y}"},
        {pos: [24, 0, 34], state: "minecraft:deepslate{axis:y}"},
        {pos: [24, 0, 35], state: "minecraft:deepslate{axis:y}"},
        {pos: [24, 0, 36], state: "minecraft:deepslate{axis:y}"},
        {pos: [24, 0, 37], state: "minecraft:deepslate{axis:y}"},
        {pos: [24, 0, 38], state: "minecraft:deepslate{axis:y}"},
        {pos: [25, 0, 0], state: "minecraft:deepslate{axis:y}"},
        {pos: [25, 0, 1], state: "minecraft:deepslate{axis:y}"},
        {pos: [25, 0, 2], state: "minecraft:deepslate{axis:y}"},
        {pos: [25, 0, 3], state: "minecraft:deepslate{axis:y}"},
        {pos: [25, 0, 4], state: "minecraft:deepslate{axis:y}"},
        {pos: [25, 0, 5], state: "minecraft:deepslate{axis:y}"},
        {pos: [25, 0, 6], state: "minecraft:deepslate{axis:y}"},
        {pos: [25, 0, 7], state: "minecraft:deepslate{axis:y}"},
        {pos: [25, 0, 8], state: "minecraft:deepslate{axis:y}"},
        {pos: [25, 0, 9], state: "minecraft:deepslate{axis:y}"},
        {pos: [25, 0, 10], state: "minecraft:deepslate{axis:y}"},
        {pos: [25, 0, 11], state: "minecraft:deepslate{axis:y}"},
        {pos: [25, 0, 12], state: "minecraft:deepslate{axis:y}"},
        {pos: [25, 0, 13], state: "minecraft:deepslate{axis:y}"},
        {pos: [25, 0, 14], state: "minecraft:deepslate{axis:y}"},
        {pos: [25, 0, 15], state: "minecraft:deepslate{axis:y}"},
        {pos: [25, 0, 16], state: "minecraft:deepslate{axis:y}"},
        {pos: [25, 0, 17], state: "minecraft:deepslate_tiles"},
        {pos: [25, 0, 18], state: "minecraft:deepslate_tiles"},
        {pos: [25, 0, 19], state: "minecraft:deepslate_tiles"},
        {pos: [25, 0, 20], state: "minecraft:deepslate_tiles"},
        {pos: [25, 0, 21], state: "minecraft:deepslate_tiles"},
        {pos: [25, 0, 22], state: "minecraft:deepslate{axis:y}"},
        {pos: [25, 0, 23], state: "minecraft:deepslate{axis:y}"},
        {pos: [25, 0, 24], state: "minecraft:deepslate{axis:y}"},
        {pos: [25, 0, 25], state: "minecraft:deepslate{axis:y}"},
        {pos: [25, 0, 26], state: "minecraft:deepslate{axis:y}"},
        {pos: [25, 0, 27], state: "minecraft:deepslate{axis:y}"},
        {pos: [25, 0, 28], state: "minecraft:deepslate{axis:y}"},
        {pos: [25, 0, 29], state: "minecraft:deepslate{axis:y}"},
        {pos: [25, 0, 30], state: "minecraft:deepslate{axis:y}"},
        {pos: [25, 0, 31], state: "minecraft:deepslate{axis:y}"},
        {pos: [25, 0, 32], state: "minecraft:deepslate{axis:y}"},
        {pos: [25, 0, 33], state: "minecraft:deepslate{axis:y}"},
        {pos: [25, 0, 34], state: "minecraft:deepslate{axis:y}"},
        {pos: [25, 0, 35], state: "minecraft:deepslate{axis:y}"},
        {pos: [25, 0, 36], state: "minecraft:deepslate{axis:y}"},
        {pos: [25, 0, 37], state: "minecraft:deepslate{axis:y}"},
        {pos: [25, 0, 38], state: "minecraft:deepslate{axis:y}"},
        {pos: [26, 0, 0], state: "minecraft:deepslate{axis:y}"},
        {pos: [26, 0, 1], state: "minecraft:deepslate{axis:y}"},
        {pos: [26, 0, 2], state: "minecraft:deepslate{axis:y}"},
        {pos: [26, 0, 3], state: "minecraft:deepslate{axis:y}"},
        {pos: [26, 0, 4], state: "minecraft:deepslate{axis:y}"},
        {pos: [26, 0, 5], state: "minecraft:deepslate{axis:y}"},
        {pos: [26, 0, 6], state: "minecraft:deepslate{axis:y}"},
        {pos: [26, 0, 7], state: "minecraft:deepslate{axis:y}"},
        {pos: [26, 0, 8], state: "minecraft:polished_basalt{axis:y}"},
        {pos: [26, 0, 9], state: "minecraft:polished_basalt{axis:z}"},
        {pos: [26, 0, 10], state: "minecraft:polished_basalt{axis:z}"},
        {pos: [26, 0, 11], state: "minecraft:polished_basalt{axis:z}"},
        {pos: [26, 0, 12], state: "minecraft:polished_basalt{axis:z}"},
        {pos: [26, 0, 13], state: "minecraft:polished_basalt{axis:z}"},
        {pos: [26, 0, 14], state: "minecraft:polished_basalt{axis:z}"},
        {pos: [26, 0, 15], state: "minecraft:deepslate_tiles"},
        {pos: [26, 0, 16], state: "minecraft:deepslate_tiles"},
        {pos: [26, 0, 17], state: "minecraft:deepslate_tiles"},
        {pos: [26, 0, 18], state: "minecraft:deepslate_tiles"},
        {pos: [26, 0, 19], state: "minecraft:deepslate_tiles"},
        {pos: [26, 0, 20], state: "minecraft:deepslate_tiles"},
        {pos: [26, 0, 21], state: "minecraft:deepslate_tiles"},
        {pos: [26, 0, 22], state: "minecraft:deepslate_tiles"},
        {pos: [26, 0, 23], state: "minecraft:deepslate_tiles"},
        {pos: [26, 0, 24], state: "minecraft:polished_basalt{axis:z}"},
        {pos: [26, 0, 25], state: "minecraft:polished_basalt{axis:z}"},
        {pos: [26, 0, 26], state: "minecraft:polished_basalt{axis:z}"},
        {pos: [26, 0, 27], state: "minecraft:polished_basalt{axis:z}"},
        {pos: [26, 0, 28], state: "minecraft:polished_basalt{axis:z}"},
        {pos: [26, 0, 29], state: "minecraft:polished_basalt{axis:z}"},
        {pos: [26, 0, 30], state: "minecraft:polished_basalt{axis:y}"},
        {pos: [26, 0, 31], state: "minecraft:deepslate{axis:y}"},
        {pos: [26, 0, 32], state: "minecraft:deepslate{axis:y}"},
        {pos: [26, 0, 33], state: "minecraft:deepslate{axis:y}"},
        {pos: [26, 0, 34], state: "minecraft:deepslate{axis:y}"},
        {pos: [26, 0, 35], state: "minecraft:deepslate{axis:y}"},
        {pos: [26, 0, 36], state: "minecraft:deepslate{axis:y}"},
        {pos: [26, 0, 37], state: "minecraft:deepslate{axis:y}"},
        {pos: [26, 0, 38], state: "minecraft:deepslate{axis:y}"},
        {pos: [27, 0, 0], state: "minecraft:deepslate{axis:y}"},
        {pos: [27, 0, 1], state: "minecraft:deepslate{axis:y}"},
        {pos: [27, 0, 2], state: "minecraft:deepslate{axis:y}"},
        {pos: [27, 0, 3], state: "minecraft:deepslate{axis:y}"},
        {pos: [27, 0, 4], state: "minecraft:deepslate{axis:y}"},
        {pos: [27, 0, 5], state: "minecraft:deepslate{axis:y}"},
        {pos: [27, 0, 6], state: "minecraft:deepslate{axis:y}"},
        {pos: [27, 0, 7], state: "minecraft:deepslate{axis:y}"},
        {pos: [27, 0, 8], state: "minecraft:polished_basalt{axis:x}"},
        {pos: [27, 0, 15], state: "minecraft:deepslate_tiles"},
        {pos: [27, 0, 16], state: "minecraft:deepslate_tiles"},
        {pos: [27, 0, 17], state: "minecraft:deepslate_tiles"},
        {pos: [27, 0, 18], state: "minecraft:deepslate_tiles"},
        {pos: [27, 0, 19], state: "minecraft:deepslate_tiles"},
        {pos: [27, 0, 20], state: "minecraft:deepslate_tiles"},
        {pos: [27, 0, 21], state: "minecraft:deepslate_tiles"},
        {pos: [27, 0, 22], state: "minecraft:deepslate_tiles"},
        {pos: [27, 0, 23], state: "minecraft:deepslate_tiles"},
        {pos: [27, 0, 30], state: "minecraft:polished_basalt{axis:x}"},
        {pos: [27, 0, 31], state: "minecraft:deepslate{axis:y}"},
        {pos: [27, 0, 32], state: "minecraft:deepslate{axis:y}"},
        {pos: [27, 0, 33], state: "minecraft:deepslate{axis:y}"},
        {pos: [27, 0, 34], state: "minecraft:deepslate{axis:y}"},
        {pos: [27, 0, 35], state: "minecraft:deepslate{axis:y}"},
        {pos: [27, 0, 36], state: "minecraft:deepslate{axis:y}"},
        {pos: [27, 0, 37], state: "minecraft:deepslate{axis:y}"},
        {pos: [27, 0, 38], state: "minecraft:deepslate{axis:y}"},
        {pos: [28, 0, 0], state: "minecraft:polished_basalt{axis:x}"},
        {pos: [28, 0, 1], state: "minecraft:deepslate{axis:y}"},
        {pos: [28, 0, 2], state: "minecraft:deepslate{axis:y}"},
        {pos: [28, 0, 3], state: "minecraft:deepslate{axis:y}"},
        {pos: [28, 0, 4], state: "minecraft:deepslate{axis:y}"},
        {pos: [28, 0, 5], state: "minecraft:deepslate{axis:y}"},
        {pos: [28, 0, 6], state: "minecraft:deepslate{axis:y}"},
        {pos: [28, 0, 7], state: "minecraft:deepslate{axis:y}"},
        {pos: [28, 0, 8], state: "minecraft:polished_basalt{axis:x}"},
        {pos: [28, 0, 15], state: "minecraft:deepslate_tiles"},
        {pos: [28, 0, 16], state: "minecraft:deepslate_tiles"},
        {pos: [28, 0, 17], state: "minecraft:deepslate_tiles"},
        {pos: [28, 0, 18], state: "minecraft:deepslate_tiles"},
        {pos: [28, 0, 19], state: "minecraft:deepslate_tiles"},
        {pos: [28, 0, 20], state: "minecraft:deepslate_tiles"},
        {pos: [28, 0, 21], state: "minecraft:deepslate_tiles"},
        {pos: [28, 0, 22], state: "minecraft:deepslate_tiles"},
        {pos: [28, 0, 23], state: "minecraft:deepslate_tiles"},
        {pos: [28, 0, 30], state: "minecraft:polished_basalt{axis:x}"},
        {pos: [28, 0, 31], state: "minecraft:deepslate{axis:y}"},
        {pos: [28, 0, 32], state: "minecraft:deepslate{axis:y}"},
        {pos: [28, 0, 33], state: "minecraft:deepslate{axis:y}"},
        {pos: [28, 0, 34], state: "minecraft:deepslate{axis:y}"},
        {pos: [28, 0, 35], state: "minecraft:deepslate{axis:y}"},
        {pos: [28, 0, 36], state: "minecraft:deepslate{axis:y}"},
        {pos: [28, 0, 37], state: "minecraft:deepslate{axis:y}"},
        {pos: [28, 0, 38], state: "minecraft:polished_basalt{axis:x}"},
        {pos: [29, 0, 0], state: "minecraft:polished_basalt{axis:x}"},
        {pos: [29, 0, 1], state: "minecraft:deepslate{axis:y}"},
        {pos: [29, 0, 2], state: "minecraft:deepslate{axis:y}"},
        {pos: [29, 0, 3], state: "minecraft:deepslate{axis:y}"},
        {pos: [29, 0, 4], state: "minecraft:deepslate{axis:y}"},
        {pos: [29, 0, 5], state: "minecraft:deepslate{axis:y}"},
        {pos: [29, 0, 6], state: "minecraft:deepslate{axis:y}"},
        {pos: [29, 0, 7], state: "minecraft:deepslate{axis:y}"},
        {pos: [29, 0, 8], state: "minecraft:polished_basalt{axis:x}"},
        {pos: [29, 0, 15], state: "minecraft:deepslate_tiles"},
        {pos: [29, 0, 16], state: "minecraft:deepslate_tiles"},
        {pos: [29, 0, 17], state: "minecraft:deepslate_tiles"},
        {pos: [29, 0, 18], state: "minecraft:deepslate_tiles"},
        {pos: [29, 0, 19], state: "minecraft:deepslate_tiles"},
        {pos: [29, 0, 20], state: "minecraft:deepslate_tiles"},
        {pos: [29, 0, 21], state: "minecraft:deepslate_tiles"},
        {pos: [29, 0, 22], state: "minecraft:deepslate_tiles"},
        {pos: [29, 0, 23], state: "minecraft:deepslate_tiles"},
        {pos: [29, 0, 30], state: "minecraft:polished_basalt{axis:x}"},
        {pos: [29, 0, 31], state: "minecraft:deepslate{axis:y}"},
        {pos: [29, 0, 32], state: "minecraft:deepslate{axis:y}"},
        {pos: [29, 0, 33], state: "minecraft:deepslate{axis:y}"},
        {pos: [29, 0, 34], state: "minecraft:deepslate{axis:y}"},
        {pos: [29, 0, 35], state: "minecraft:deepslate{axis:y}"},
        {pos: [29, 0, 36], state: "minecraft:deepslate{axis:y}"},
        {pos: [29, 0, 37], state: "minecraft:deepslate{axis:y}"},
        {pos: [29, 0, 38], state: "minecraft:polished_basalt{axis:x}"},
        {pos: [30, 0, 0], state: "minecraft:polished_basalt{axis:x}"},
        {pos: [30, 0, 1], state: "minecraft:deepslate{axis:y}"},
        {pos: [30, 0, 2], state: "minecraft:deepslate{axis:y}"},
        {pos: [30, 0, 3], state: "minecraft:deepslate{axis:y}"},
        {pos: [30, 0, 4], state: "minecraft:deepslate{axis:y}"},
        {pos: [30, 0, 5], state: "minecraft:deepslate{axis:y}"},
        {pos: [30, 0, 6], state: "minecraft:deepslate{axis:y}"},
        {pos: [30, 0, 7], state: "minecraft:deepslate{axis:y}"},
        {pos: [30, 0, 8], state: "minecraft:polished_basalt{axis:x}"},
        {pos: [30, 0, 15], state: "minecraft:deepslate_tiles"},
        {pos: [30, 0, 16], state: "minecraft:deepslate_tiles"},
        {pos: [30, 0, 17], state: "minecraft:deepslate_tiles"},
        {pos: [30, 0, 18], state: "minecraft:deepslate_tiles"},
        {pos: [30, 0, 19], state: "minecraft:deepslate_tiles"},
        {pos: [30, 0, 20], state: "minecraft:deepslate_tiles"},
        {pos: [30, 0, 21], state: "minecraft:deepslate_tiles"},
        {pos: [30, 0, 22], state: "minecraft:deepslate_tiles"},
        {pos: [30, 0, 23], state: "minecraft:deepslate_tiles"},
        {pos: [30, 0, 30], state: "minecraft:polished_basalt{axis:x}"},
        {pos: [30, 0, 31], state: "minecraft:deepslate{axis:y}"},
        {pos: [30, 0, 32], state: "minecraft:deepslate{axis:y}"},
        {pos: [30, 0, 33], state: "minecraft:deepslate{axis:y}"},
        {pos: [30, 0, 34], state: "minecraft:deepslate{axis:y}"},
        {pos: [30, 0, 35], state: "minecraft:deepslate{axis:y}"},
        {pos: [30, 0, 36], state: "minecraft:deepslate{axis:y}"},
        {pos: [30, 0, 37], state: "minecraft:deepslate{axis:y}"},
        {pos: [30, 0, 38], state: "minecraft:polished_basalt{axis:x}"},
        {pos: [31, 0, 0], state: "minecraft:polished_basalt{axis:x}"},
        {pos: [31, 0, 1], state: "minecraft:deepslate{axis:y}"},
        {pos: [31, 0, 2], state: "minecraft:deepslate{axis:y}"},
        {pos: [31, 0, 3], state: "minecraft:deepslate{axis:y}"},
        {pos: [31, 0, 4], state: "minecraft:deepslate{axis:y}"},
        {pos: [31, 0, 5], state: "minecraft:deepslate{axis:y}"},
        {pos: [31, 0, 6], state: "minecraft:deepslate{axis:y}"},
        {pos: [31, 0, 7], state: "minecraft:deepslate{axis:y}"},
        {pos: [31, 0, 8], state: "minecraft:polished_basalt{axis:x}"},
        {pos: [31, 0, 15], state: "minecraft:deepslate_tiles"},
        {pos: [31, 0, 16], state: "minecraft:deepslate_tiles"},
        {pos: [31, 0, 17], state: "minecraft:deepslate_tiles"},
        {pos: [31, 0, 18], state: "minecraft:deepslate_tiles"},
        {pos: [31, 0, 19], state: "minecraft:deepslate_tiles"},
        {pos: [31, 0, 20], state: "minecraft:deepslate_tiles"},
        {pos: [31, 0, 21], state: "minecraft:deepslate_tiles"},
        {pos: [31, 0, 22], state: "minecraft:deepslate_tiles"},
        {pos: [31, 0, 23], state: "minecraft:deepslate_tiles"},
        {pos: [31, 0, 30], state: "minecraft:polished_basalt{axis:x}"},
        {pos: [31, 0, 31], state: "minecraft:deepslate{axis:y}"},
        {pos: [31, 0, 32], state: "minecraft:deepslate{axis:y}"},
        {pos: [31, 0, 33], state: "minecraft:deepslate{axis:y}"},
        {pos: [31, 0, 34], state: "minecraft:deepslate{axis:y}"},
        {pos: [31, 0, 35], state: "minecraft:deepslate{axis:y}"},
        {pos: [31, 0, 36], state: "minecraft:deepslate{axis:y}"},
        {pos: [31, 0, 37], state: "minecraft:deepslate{axis:y}"},
        {pos: [31, 0, 38], state: "minecraft:polished_basalt{axis:x}"},
        {pos: [32, 0, 0], state: "minecraft:deepslate{axis:y}"},
        {pos: [32, 0, 1], state: "minecraft:deepslate{axis:y}"},
        {pos: [32, 0, 2], state: "minecraft:deepslate{axis:y}"},
        {pos: [32, 0, 3], state: "minecraft:deepslate{axis:y}"},
        {pos: [32, 0, 4], state: "minecraft:deepslate{axis:y}"},
        {pos: [32, 0, 5], state: "minecraft:deepslate{axis:y}"},
        {pos: [32, 0, 6], state: "minecraft:deepslate{axis:y}"},
        {pos: [32, 0, 7], state: "minecraft:deepslate{axis:y}"},
        {pos: [32, 0, 8], state: "minecraft:polished_basalt{axis:x}"},
        {pos: [32, 0, 15], state: "minecraft:deepslate_tiles"},
        {pos: [32, 0, 16], state: "minecraft:deepslate_tiles"},
        {pos: [32, 0, 17], state: "minecraft:deepslate_tiles"},
        {pos: [32, 0, 18], state: "minecraft:deepslate_tiles"},
        {pos: [32, 0, 19], state: "minecraft:deepslate_tiles"},
        {pos: [32, 0, 20], state: "minecraft:deepslate_tiles"},
        {pos: [32, 0, 21], state: "minecraft:deepslate_tiles"},
        {pos: [32, 0, 22], state: "minecraft:deepslate_tiles"},
        {pos: [32, 0, 23], state: "minecraft:deepslate_tiles"},
        {pos: [32, 0, 30], state: "minecraft:polished_basalt{axis:x}"},
        {pos: [32, 0, 31], state: "minecraft:deepslate{axis:y}"},
        {pos: [32, 0, 32], state: "minecraft:deepslate{axis:y}"},
        {pos: [32, 0, 33], state: "minecraft:deepslate{axis:y}"},
        {pos: [32, 0, 34], state: "minecraft:deepslate{axis:y}"},
        {pos: [32, 0, 35], state: "minecraft:deepslate{axis:y}"},
        {pos: [32, 0, 36], state: "minecraft:deepslate{axis:y}"},
        {pos: [32, 0, 37], state: "minecraft:deepslate{axis:y}"},
        {pos: [32, 0, 38], state: "minecraft:deepslate{axis:y}"},
        {pos: [33, 0, 0], state: "minecraft:deepslate{axis:y}"},
        {pos: [33, 0, 1], state: "minecraft:deepslate{axis:y}"},
        {pos: [33, 0, 2], state: "minecraft:deepslate{axis:y}"},
        {pos: [33, 0, 3], state: "minecraft:deepslate{axis:y}"},
        {pos: [33, 0, 4], state: "minecraft:deepslate{axis:y}"},
        {pos: [33, 0, 5], state: "minecraft:deepslate{axis:y}"},
        {pos: [33, 0, 6], state: "minecraft:deepslate{axis:y}"},
        {pos: [33, 0, 7], state: "minecraft:deepslate{axis:y}"},
        {pos: [33, 0, 8], state: "minecraft:polished_basalt{axis:y}"},
        {pos: [33, 0, 9], state: "minecraft:polished_basalt{axis:z}"},
        {pos: [33, 0, 10], state: "minecraft:polished_basalt{axis:z}"},
        {pos: [33, 0, 11], state: "minecraft:polished_basalt{axis:z}"},
        {pos: [33, 0, 12], state: "minecraft:polished_basalt{axis:z}"},
        {pos: [33, 0, 13], state: "minecraft:polished_basalt{axis:z}"},
        {pos: [33, 0, 14], state: "minecraft:polished_basalt{axis:z}"},
        {pos: [33, 0, 15], state: "minecraft:deepslate_tiles"},
        {pos: [33, 0, 16], state: "minecraft:deepslate_tiles"},
        {pos: [33, 0, 17], state: "minecraft:deepslate_tiles"},
        {pos: [33, 0, 18], state: "minecraft:deepslate_tiles"},
        {pos: [33, 0, 19], state: "minecraft:deepslate_tiles"},
        {pos: [33, 0, 20], state: "minecraft:deepslate_tiles"},
        {pos: [33, 0, 21], state: "minecraft:deepslate_tiles"},
        {pos: [33, 0, 22], state: "minecraft:deepslate_tiles"},
        {pos: [33, 0, 23], state: "minecraft:deepslate_tiles"},
        {pos: [33, 0, 24], state: "minecraft:polished_basalt{axis:z}"},
        {pos: [33, 0, 25], state: "minecraft:polished_basalt{axis:z}"},
        {pos: [33, 0, 26], state: "minecraft:polished_basalt{axis:z}"},
        {pos: [33, 0, 27], state: "minecraft:polished_basalt{axis:z}"},
        {pos: [33, 0, 28], state: "minecraft:polished_basalt{axis:z}"},
        {pos: [33, 0, 29], state: "minecraft:polished_basalt{axis:z}"},
        {pos: [33, 0, 30], state: "minecraft:polished_basalt{axis:y}"},
        {pos: [33, 0, 31], state: "minecraft:deepslate{axis:y}"},
        {pos: [33, 0, 32], state: "minecraft:deepslate{axis:y}"},
        {pos: [33, 0, 33], state: "minecraft:deepslate{axis:y}"},
        {pos: [33, 0, 34], state: "minecraft:deepslate{axis:y}"},
        {pos: [33, 0, 35], state: "minecraft:deepslate{axis:y}"},
        {pos: [33, 0, 36], state: "minecraft:deepslate{axis:y}"},
        {pos: [33, 0, 37], state: "minecraft:deepslate{axis:y}"},
        {pos: [33, 0, 38], state: "minecraft:deepslate{axis:y}"},
        {pos: [34, 0, 0], state: "minecraft:deepslate{axis:y}"},
        {pos: [34, 0, 1], state: "minecraft:deepslate{axis:y}"},
        {pos: [34, 0, 2], state: "minecraft:deepslate{axis:y}"},
        {pos: [34, 0, 3], state: "minecraft:deepslate{axis:y}"},
        {pos: [34, 0, 4], state: "minecraft:deepslate{axis:y}"},
        {pos: [34, 0, 5], state: "minecraft:deepslate{axis:y}"},
        {pos: [34, 0, 6], state: "minecraft:deepslate{axis:y}"},
        {pos: [34, 0, 7], state: "minecraft:deepslate{axis:y}"},
        {pos: [34, 0, 8], state: "minecraft:deepslate{axis:y}"},
        {pos: [34, 0, 9], state: "minecraft:deepslate{axis:y}"},
        {pos: [34, 0, 10], state: "minecraft:deepslate{axis:y}"},
        {pos: [34, 0, 11], state: "minecraft:deepslate{axis:y}"},
        {pos: [34, 0, 12], state: "minecraft:deepslate{axis:y}"},
        {pos: [34, 0, 13], state: "minecraft:deepslate{axis:y}"},
        {pos: [34, 0, 14], state: "minecraft:deepslate{axis:y}"},
        {pos: [34, 0, 15], state: "minecraft:deepslate{axis:y}"},
        {pos: [34, 0, 16], state: "minecraft:deepslate{axis:y}"},
        {pos: [34, 0, 17], state: "minecraft:deepslate_tiles"},
        {pos: [34, 0, 18], state: "minecraft:deepslate_tiles"},
        {pos: [34, 0, 20], state: "minecraft:deepslate_tiles"},
        {pos: [34, 0, 21], state: "minecraft:deepslate_tiles"},
        {pos: [34, 0, 22], state: "minecraft:deepslate{axis:y}"},
        {pos: [34, 0, 23], state: "minecraft:deepslate{axis:y}"},
        {pos: [34, 0, 24], state: "minecraft:deepslate{axis:y}"},
        {pos: [34, 0, 25], state: "minecraft:deepslate{axis:y}"},
        {pos: [34, 0, 26], state: "minecraft:deepslate{axis:y}"},
        {pos: [34, 0, 27], state: "minecraft:deepslate{axis:y}"},
        {pos: [34, 0, 28], state: "minecraft:deepslate{axis:y}"},
        {pos: [34, 0, 29], state: "minecraft:deepslate{axis:y}"},
        {pos: [34, 0, 30], state: "minecraft:deepslate{axis:y}"},
        {pos: [34, 0, 31], state: "minecraft:deepslate{axis:y}"},
        {pos: [34, 0, 32], state: "minecraft:deepslate{axis:y}"},
        {pos: [34, 0, 33], state: "minecraft:deepslate{axis:y}"},
        {pos: [34, 0, 34], state: "minecraft:deepslate{axis:y}"},
        {pos: [34, 0, 35], state: "minecraft:deepslate{axis:y}"},
        {pos: [34, 0, 36], state: "minecraft:deepslate{axis:y}"},
        {pos: [34, 0, 37], state: "minecraft:deepslate{axis:y}"},
        {pos: [34, 0, 38], state: "minecraft:deepslate{axis:y}"},
        {pos: [4, 1, 18], state: "minecraft:deepslate_tiles"},
        {pos: [4, 1, 19], state: "minecraft:deepslate_tiles"},
        {pos: [4, 1, 20], state: "minecraft:deepslate_tiles"},
        {pos: [5, 1, 18], state: "minecraft:deepslate_tiles"},
        {pos: [5, 1, 19], state: "minecraft:deepslate_tiles"},
        {pos: [5, 1, 20], state: "minecraft:deepslate_tiles"},
        {pos: [6, 1, 15], state: "minecraft:deepslate_tiles"},
        {pos: [6, 1, 16], state: "minecraft:deepslate_tiles"},
        {pos: [6, 1, 17], state: "minecraft:smooth_basalt"},
        {pos: [6, 1, 18], state: "minecraft:deepslate_tiles"},
        {pos: [6, 1, 19], state: "minecraft:deepslate_tiles"},
        {pos: [6, 1, 20], state: "minecraft:deepslate_tiles"},
        {pos: [6, 1, 21], state: "minecraft:smooth_basalt"},
        {pos: [6, 1, 22], state: "minecraft:deepslate_tiles"},
        {pos: [6, 1, 23], state: "minecraft:deepslate_tiles"},
        {pos: [7, 1, 15], state: "minecraft:deepslate_tiles"},
        {pos: [7, 1, 16], state: "minecraft:deepslate_tiles"},
        {pos: [7, 1, 17], state: "minecraft:polished_deepslate"},
        {pos: [7, 1, 18], state: "minecraft:deepslate_tiles"},
        {pos: [7, 1, 19], state: "minecraft:deepslate_tiles"},
        {pos: [7, 1, 20], state: "minecraft:deepslate_tiles"},
        {pos: [7, 1, 21], state: "minecraft:polished_deepslate"},
        {pos: [7, 1, 22], state: "minecraft:deepslate_tiles"},
        {pos: [7, 1, 23], state: "minecraft:deepslate_tiles"},
        {pos: [8, 1, 15], state: "minecraft:deepslate_tiles"},
        {pos: [8, 1, 16], state: "minecraft:deepslate_tiles"},
        {pos: [8, 1, 17], state: "minecraft:smooth_basalt"},
        {pos: [8, 1, 18], state: "minecraft:deepslate_tiles"},
        {pos: [8, 1, 19], state: "minecraft:deepslate_tiles"},
        {pos: [8, 1, 20], state: "minecraft:deepslate_tiles"},
        {pos: [8, 1, 21], state: "minecraft:smooth_basalt"},
        {pos: [8, 1, 22], state: "minecraft:deepslate_tiles"},
        {pos: [8, 1, 23], state: "minecraft:deepslate_tiles"},
        {pos: [9, 1, 18], state: "minecraft:deepslate_tiles"},
        {pos: [9, 1, 19], state: "minecraft:deepslate_tiles"},
        {pos: [9, 1, 20], state: "minecraft:deepslate_tiles"},
        {pos: [10, 1, 18], state: "minecraft:deepslate_tiles"},
        {pos: [10, 1, 19], state: "minecraft:deepslate_tiles"},
        {pos: [10, 1, 20], state: "minecraft:deepslate_tiles"},
        {pos: [11, 1, 15], state: "minecraft:deepslate_tiles"},
        {pos: [11, 1, 16], state: "minecraft:deepslate_tiles"},
        {pos: [11, 1, 17], state: "minecraft:smooth_basalt"},
        {pos: [11, 1, 18], state: "minecraft:deepslate_tiles"},
        {pos: [11, 1, 19], state: "minecraft:deepslate_tiles"},
        {pos: [11, 1, 20], state: "minecraft:deepslate_tiles"},
        {pos: [11, 1, 21], state: "minecraft:smooth_basalt"},
        {pos: [11, 1, 22], state: "minecraft:deepslate_tiles"},
        {pos: [11, 1, 23], state: "minecraft:deepslate_tiles"},
        {pos: [12, 1, 0], state: "minecraft:deepslate_tiles"},
        {pos: [12, 1, 15], state: "minecraft:deepslate_tiles"},
        {pos: [12, 1, 16], state: "minecraft:deepslate_tiles"},
        {pos: [12, 1, 17], state: "minecraft:polished_deepslate"},
        {pos: [12, 1, 18], state: "minecraft:deepslate_tiles"},
        {pos: [12, 1, 19], state: "minecraft:deepslate_tiles"},
        {pos: [12, 1, 20], state: "minecraft:deepslate_tiles"},
        {pos: [12, 1, 21], state: "minecraft:polished_deepslate"},
        {pos: [12, 1, 22], state: "minecraft:deepslate_tiles"},
        {pos: [12, 1, 23], state: "minecraft:deepslate_tiles"},
        {pos: [12, 1, 38], state: "minecraft:deepslate_tiles"},
        {pos: [13, 1, 0], state: "minecraft:deepslate_tiles"},
        {pos: [13, 1, 1], state: "minecraft:deepslate{axis:y}"},
        {pos: [13, 1, 2], state: "minecraft:deepslate{axis:y}"},
        {pos: [13, 1, 3], state: "minecraft:deepslate{axis:y}"},
        {pos: [13, 1, 4], state: "minecraft:deepslate{axis:y}"},
        {pos: [13, 1, 15], state: "minecraft:deepslate_tiles"},
        {pos: [13, 1, 16], state: "minecraft:deepslate_tiles"},
        {pos: [13, 1, 17], state: "minecraft:smooth_basalt"},
        {pos: [13, 1, 18], state: "minecraft:deepslate_tiles"},
        {pos: [13, 1, 19], state: "minecraft:deepslate_tiles"},
        {pos: [13, 1, 20], state: "minecraft:deepslate_tiles"},
        {pos: [13, 1, 21], state: "minecraft:smooth_basalt"},
        {pos: [13, 1, 22], state: "minecraft:deepslate_tiles"},
        {pos: [13, 1, 23], state: "minecraft:deepslate_tiles"},
        {pos: [13, 1, 34], state: "minecraft:deepslate{axis:y}"},
        {pos: [13, 1, 35], state: "minecraft:deepslate{axis:y}"},
        {pos: [13, 1, 36], state: "minecraft:deepslate{axis:y}"},
        {pos: [13, 1, 37], state: "minecraft:deepslate{axis:y}"},
        {pos: [13, 1, 38], state: "minecraft:deepslate_tiles"},
        {pos: [14, 1, 0], state: "minecraft:deepslate_tiles"},
        {pos: [14, 1, 1], state: "minecraft:deepslate{axis:y}"},
        {pos: [14, 1, 2], state: "minecraft:deepslate{axis:y}"},
        {pos: [14, 1, 3], state: "minecraft:deepslate{axis:y}"},
        {pos: [14, 1, 4], state: "minecraft:deepslate{axis:y}"},
        {pos: [14, 1, 18], state: "minecraft:deepslate_tiles"},
        {pos: [14, 1, 19], state: "minecraft:deepslate_tiles"},
        {pos: [14, 1, 20], state: "minecraft:deepslate_tiles"},
        {pos: [14, 1, 34], state: "minecraft:deepslate{axis:y}"},
        {pos: [14, 1, 35], state: "minecraft:deepslate{axis:y}"},
        {pos: [14, 1, 36], state: "minecraft:deepslate{axis:y}"},
        {pos: [14, 1, 37], state: "minecraft:deepslate{axis:y}"},
        {pos: [14, 1, 38], state: "minecraft:deepslate_tiles"},
        {pos: [15, 1, 0], state: "minecraft:deepslate_tiles"},
        {pos: [15, 1, 1], state: "minecraft:deepslate{axis:y}"},
        {pos: [15, 1, 2], state: "minecraft:deepslate{axis:y}"},
        {pos: [15, 1, 3], state: "minecraft:deepslate{axis:y}"},
        {pos: [15, 1, 4], state: "minecraft:deepslate{axis:y}"},
        {pos: [15, 1, 18], state: "minecraft:deepslate_tiles"},
        {pos: [15, 1, 19], state: "minecraft:deepslate_tiles"},
        {pos: [15, 1, 20], state: "minecraft:deepslate_tiles"},
        {pos: [15, 1, 34], state: "minecraft:deepslate{axis:y}"},
        {pos: [15, 1, 35], state: "minecraft:deepslate{axis:y}"},
        {pos: [15, 1, 36], state: "minecraft:deepslate{axis:y}"},
        {pos: [15, 1, 37], state: "minecraft:deepslate{axis:y}"},
        {pos: [15, 1, 38], state: "minecraft:deepslate_tiles"},
        {pos: [16, 1, 0], state: "minecraft:deepslate_tiles"},
        {pos: [16, 1, 1], state: "minecraft:deepslate{axis:y}"},
        {pos: [16, 1, 2], state: "minecraft:deepslate{axis:y}"},
        {pos: [16, 1, 3], state: "minecraft:deepslate{axis:y}"},
        {pos: [16, 1, 4], state: "minecraft:deepslate{axis:y}"},
        {pos: [16, 1, 15], state: "minecraft:deepslate_tiles"},
        {pos: [16, 1, 16], state: "minecraft:deepslate_tiles"},
        {pos: [16, 1, 17], state: "minecraft:smooth_basalt"},
        {pos: [16, 1, 18], state: "minecraft:deepslate_tiles"},
        {pos: [16, 1, 19], state: "minecraft:deepslate_tiles"},
        {pos: [16, 1, 20], state: "minecraft:deepslate_tiles"},
        {pos: [16, 1, 21], state: "minecraft:smooth_basalt"},
        {pos: [16, 1, 22], state: "minecraft:deepslate_tiles"},
        {pos: [16, 1, 23], state: "minecraft:deepslate_tiles"},
        {pos: [16, 1, 34], state: "minecraft:deepslate{axis:y}"},
        {pos: [16, 1, 35], state: "minecraft:deepslate{axis:y}"},
        {pos: [16, 1, 36], state: "minecraft:deepslate{axis:y}"},
        {pos: [16, 1, 37], state: "minecraft:deepslate{axis:y}"},
        {pos: [16, 1, 38], state: "minecraft:deepslate_tiles"},
        {pos: [17, 1, 15], state: "minecraft:deepslate_tiles"},
        {pos: [17, 1, 16], state: "minecraft:deepslate_tiles"},
        {pos: [17, 1, 17], state: "minecraft:polished_deepslate"},
        {pos: [17, 1, 18], state: "minecraft:deepslate_tiles"},
        {pos: [17, 1, 19], state: "minecraft:deepslate_tiles"},
        {pos: [17, 1, 20], state: "minecraft:deepslate_tiles"},
        {pos: [17, 1, 21], state: "minecraft:polished_deepslate"},
        {pos: [17, 1, 22], state: "minecraft:deepslate_tiles"},
        {pos: [17, 1, 23], state: "minecraft:deepslate_tiles"},
        {pos: [18, 1, 15], state: "minecraft:deepslate_tiles"},
        {pos: [18, 1, 16], state: "minecraft:deepslate_tiles"},
        {pos: [18, 1, 17], state: "minecraft:smooth_basalt"},
        {pos: [18, 1, 18], state: "minecraft:deepslate_tiles"},
        {pos: [18, 1, 19], state: "minecraft:deepslate_tiles"},
        {pos: [18, 1, 20], state: "minecraft:deepslate_tiles"},
        {pos: [18, 1, 21], state: "minecraft:smooth_basalt"},
        {pos: [18, 1, 22], state: "minecraft:deepslate_tiles"},
        {pos: [18, 1, 23], state: "minecraft:deepslate_tiles"},
        {pos: [19, 1, 18], state: "minecraft:deepslate_tiles"},
        {pos: [19, 1, 19], state: "minecraft:deepslate_tiles"},
        {pos: [19, 1, 20], state: "minecraft:deepslate_tiles"},
        {pos: [20, 1, 18], state: "minecraft:deepslate_tiles"},
        {pos: [20, 1, 19], state: "minecraft:deepslate_tiles"},
        {pos: [20, 1, 20], state: "minecraft:deepslate_tiles"},
        {pos: [21, 1, 15], state: "minecraft:deepslate_tiles"},
        {pos: [21, 1, 16], state: "minecraft:deepslate_tiles"},
        {pos: [21, 1, 17], state: "minecraft:smooth_basalt"},
        {pos: [21, 1, 18], state: "minecraft:deepslate_tiles"},
        {pos: [21, 1, 19], state: "minecraft:deepslate_tiles"},
        {pos: [21, 1, 20], state: "minecraft:deepslate_tiles"},
        {pos: [21, 1, 21], state: "minecraft:smooth_basalt"},
        {pos: [21, 1, 22], state: "minecraft:deepslate_tiles"},
        {pos: [21, 1, 23], state: "minecraft:deepslate_tiles"},
        {pos: [22, 1, 15], state: "minecraft:deepslate_tiles"},
        {pos: [22, 1, 16], state: "minecraft:deepslate_tiles"},
        {pos: [22, 1, 17], state: "minecraft:polished_deepslate"},
        {pos: [22, 1, 18], state: "minecraft:deepslate_tiles"},
        {pos: [22, 1, 19], state: "minecraft:deepslate_tiles"},
        {pos: [22, 1, 20], state: "minecraft:deepslate_tiles"},
        {pos: [22, 1, 21], state: "minecraft:polished_deepslate"},
        {pos: [22, 1, 22], state: "minecraft:deepslate_tiles"},
        {pos: [22, 1, 23], state: "minecraft:deepslate_tiles"},
        {pos: [23, 1, 0], state: "minecraft:deepslate_tiles"},
        {pos: [23, 1, 1], state: "minecraft:deepslate{axis:y}"},
        {pos: [23, 1, 2], state: "minecraft:deepslate{axis:y}"},
        {pos: [23, 1, 3], state: "minecraft:deepslate{axis:y}"},
        {pos: [23, 1, 4], state: "minecraft:deepslate{axis:y}"},
        {pos: [23, 1, 15], state: "minecraft:deepslate_tiles"},
        {pos: [23, 1, 16], state: "minecraft:deepslate_tiles"},
        {pos: [23, 1, 17], state: "minecraft:smooth_basalt"},
        {pos: [23, 1, 18], state: "minecraft:deepslate_tiles"},
        {pos: [23, 1, 19], state: "minecraft:deepslate_tiles"},
        {pos: [23, 1, 20], state: "minecraft:deepslate_tiles"},
        {pos: [23, 1, 21], state: "minecraft:smooth_basalt"},
        {pos: [23, 1, 22], state: "minecraft:deepslate_tiles"},
        {pos: [23, 1, 23], state: "minecraft:deepslate_tiles"},
        {pos: [23, 1, 35], state: "minecraft:deepslate{axis:y}"},
        {pos: [23, 1, 36], state: "minecraft:deepslate{axis:y}"},
        {pos: [23, 1, 37], state: "minecraft:deepslate{axis:y}"},
        {pos: [23, 1, 38], state: "minecraft:deepslate_tiles"},
        {pos: [24, 1, 0], state: "minecraft:deepslate_tiles"},
        {pos: [24, 1, 1], state: "minecraft:deepslate{axis:y}"},
        {pos: [24, 1, 2], state: "minecraft:deepslate{axis:y}"},
        {pos: [24, 1, 3], state: "minecraft:deepslate{axis:y}"},
        {pos: [24, 1, 4], state: "minecraft:deepslate{axis:y}"},
        {pos: [24, 1, 18], state: "minecraft:deepslate_tiles"},
        {pos: [24, 1, 19], state: "minecraft:deepslate_tiles"},
        {pos: [24, 1, 20], state: "minecraft:deepslate_tiles"},
        {pos: [24, 1, 35], state: "minecraft:deepslate{axis:y}"},
        {pos: [24, 1, 36], state: "minecraft:deepslate{axis:y}"},
        {pos: [24, 1, 37], state: "minecraft:deepslate{axis:y}"},
        {pos: [24, 1, 38], state: "minecraft:deepslate_tiles"},
        {pos: [25, 1, 0], state: "minecraft:deepslate_tiles"},
        {pos: [25, 1, 1], state: "minecraft:deepslate{axis:y}"},
        {pos: [25, 1, 2], state: "minecraft:deepslate{axis:y}"},
        {pos: [25, 1, 3], state: "minecraft:deepslate{axis:y}"},
        {pos: [25, 1, 4], state: "minecraft:deepslate{axis:y}"},
        {pos: [25, 1, 18], state: "minecraft:deepslate_tiles"},
        {pos: [25, 1, 19], state: "minecraft:deepslate_tiles"},
        {pos: [25, 1, 20], state: "minecraft:deepslate_tiles"},
        {pos: [25, 1, 34], state: "minecraft:deepslate{axis:y}"},
        {pos: [25, 1, 35], state: "minecraft:deepslate{axis:y}"},
        {pos: [25, 1, 36], state: "minecraft:deepslate{axis:y}"},
        {pos: [25, 1, 37], state: "minecraft:deepslate{axis:y}"},
        {pos: [25, 1, 38], state: "minecraft:deepslate_tiles"},
        {pos: [26, 1, 0], state: "minecraft:deepslate_tiles"},
        {pos: [26, 1, 1], state: "minecraft:deepslate{axis:y}"},
        {pos: [26, 1, 2], state: "minecraft:deepslate{axis:y}"},
        {pos: [26, 1, 3], state: "minecraft:deepslate{axis:y}"},
        {pos: [26, 1, 4], state: "minecraft:deepslate{axis:y}"},
        {pos: [26, 1, 15], state: "minecraft:deepslate_tiles"},
        {pos: [26, 1, 16], state: "minecraft:deepslate_tiles"},
        {pos: [26, 1, 17], state: "minecraft:smooth_basalt"},
        {pos: [26, 1, 18], state: "minecraft:deepslate_tiles"},
        {pos: [26, 1, 19], state: "minecraft:deepslate_tiles"},
        {pos: [26, 1, 20], state: "minecraft:deepslate_tiles"},
        {pos: [26, 1, 21], state: "minecraft:smooth_basalt"},
        {pos: [26, 1, 22], state: "minecraft:deepslate_tiles"},
        {pos: [26, 1, 23], state: "minecraft:deepslate_tiles"},
        {pos: [26, 1, 34], state: "minecraft:deepslate{axis:y}"},
        {pos: [26, 1, 35], state: "minecraft:deepslate{axis:y}"},
        {pos: [26, 1, 36], state: "minecraft:deepslate{axis:y}"},
        {pos: [26, 1, 37], state: "minecraft:deepslate{axis:y}"},
        {pos: [26, 1, 38], state: "minecraft:deepslate_tiles"},
        {pos: [27, 1, 0], state: "minecraft:deepslate_tiles"},
        {pos: [27, 1, 15], state: "minecraft:deepslate_tiles"},
        {pos: [27, 1, 16], state: "minecraft:deepslate_tiles"},
        {pos: [27, 1, 17], state: "minecraft:polished_deepslate"},
        {pos: [27, 1, 18], state: "minecraft:deepslate_tiles"},
        {pos: [27, 1, 19], state: "minecraft:deepslate_tiles"},
        {pos: [27, 1, 20], state: "minecraft:deepslate_tiles"},
        {pos: [27, 1, 21], state: "minecraft:polished_deepslate"},
        {pos: [27, 1, 22], state: "minecraft:deepslate_tiles"},
        {pos: [27, 1, 23], state: "minecraft:deepslate_tiles"},
        {pos: [27, 1, 38], state: "minecraft:deepslate_tiles"},
        {pos: [28, 1, 15], state: "minecraft:deepslate_tiles"},
        {pos: [28, 1, 16], state: "minecraft:deepslate_tiles"},
        {pos: [28, 1, 17], state: "minecraft:smooth_basalt"},
        {pos: [28, 1, 18], state: "minecraft:deepslate_tiles"},
        {pos: [28, 1, 19], state: "minecraft:deepslate_tiles"},
        {pos: [28, 1, 20], state: "minecraft:deepslate_tiles"},
        {pos: [28, 1, 21], state: "minecraft:smooth_basalt"},
        {pos: [28, 1, 22], state: "minecraft:deepslate_tiles"},
        {pos: [28, 1, 23], state: "minecraft:deepslate_tiles"},
        {pos: [29, 1, 18], state: "minecraft:deepslate_tiles"},
        {pos: [29, 1, 19], state: "minecraft:deepslate_tiles"},
        {pos: [29, 1, 20], state: "minecraft:deepslate_tiles"},
        {pos: [30, 1, 18], state: "minecraft:deepslate_tiles"},
        {pos: [30, 1, 19], state: "minecraft:deepslate_tiles"},
        {pos: [30, 1, 20], state: "minecraft:deepslate_tiles"},
        {pos: [31, 1, 15], state: "minecraft:deepslate_tiles"},
        {pos: [31, 1, 16], state: "minecraft:deepslate_tiles"},
        {pos: [31, 1, 17], state: "minecraft:smooth_basalt"},
        {pos: [31, 1, 18], state: "minecraft:deepslate_tiles"},
        {pos: [31, 1, 19], state: "minecraft:deepslate_tiles"},
        {pos: [31, 1, 20], state: "minecraft:deepslate_tiles"},
        {pos: [31, 1, 21], state: "minecraft:smooth_basalt"},
        {pos: [31, 1, 22], state: "minecraft:deepslate_tiles"},
        {pos: [31, 1, 23], state: "minecraft:deepslate_tiles"},
        {pos: [32, 1, 0], state: "minecraft:deepslate_tiles"},
        {pos: [32, 1, 15], state: "minecraft:deepslate_tiles"},
        {pos: [32, 1, 16], state: "minecraft:deepslate_tiles"},
        {pos: [32, 1, 17], state: "minecraft:polished_deepslate"},
        {pos: [32, 1, 18], state: "minecraft:deepslate_tiles"},
        {pos: [32, 1, 19], state: "minecraft:deepslate_tiles"},
        {pos: [32, 1, 20], state: "minecraft:deepslate_tiles"},
        {pos: [32, 1, 21], state: "minecraft:polished_deepslate"},
        {pos: [32, 1, 22], state: "minecraft:deepslate_tiles"},
        {pos: [32, 1, 23], state: "minecraft:deepslate_tiles"},
        {pos: [32, 1, 38], state: "minecraft:deepslate_tiles"},
        {pos: [33, 1, 0], state: "minecraft:deepslate_tiles"},
        {pos: [33, 1, 1], state: "minecraft:deepslate{axis:y}"},
        {pos: [33, 1, 2], state: "minecraft:deepslate{axis:y}"},
        {pos: [33, 1, 3], state: "minecraft:deepslate{axis:y}"},
        {pos: [33, 1, 4], state: "minecraft:deepslate{axis:y}"},
        {pos: [33, 1, 15], state: "minecraft:deepslate_tiles"},
        {pos: [33, 1, 16], state: "minecraft:deepslate_tiles"},
        {pos: [33, 1, 17], state: "minecraft:smooth_basalt"},
        {pos: [33, 1, 18], state: "minecraft:deepslate_tiles"},
        {pos: [33, 1, 19], state: "minecraft:deepslate_tiles"},
        {pos: [33, 1, 20], state: "minecraft:deepslate_tiles"},
        {pos: [33, 1, 21], state: "minecraft:smooth_basalt"},
        {pos: [33, 1, 22], state: "minecraft:deepslate_tiles"},
        {pos: [33, 1, 23], state: "minecraft:deepslate_tiles"},
        {pos: [33, 1, 34], state: "minecraft:deepslate{axis:y}"},
        {pos: [33, 1, 35], state: "minecraft:deepslate{axis:y}"},
        {pos: [33, 1, 36], state: "minecraft:deepslate{axis:y}"},
        {pos: [33, 1, 37], state: "minecraft:deepslate{axis:y}"},
        {pos: [33, 1, 38], state: "minecraft:deepslate_tiles"},
        {pos: [34, 1, 0], state: "minecraft:deepslate_tiles"},
        {pos: [34, 1, 1], state: "minecraft:deepslate{axis:y}"},
        {pos: [34, 1, 2], state: "minecraft:deepslate{axis:y}"},
        {pos: [34, 1, 3], state: "minecraft:deepslate{axis:y}"},
        {pos: [34, 1, 4], state: "minecraft:deepslate{axis:y}"},
        {pos: [34, 1, 18], state: "minecraft:deepslate_tiles"},
        {pos: [34, 1, 19], state: "minecraft:deepslate_tiles"},
        {pos: [34, 1, 20], state: "minecraft:deepslate_tiles"},
        {pos: [34, 1, 35], state: "minecraft:deepslate{axis:y}"},
        {pos: [34, 1, 36], state: "minecraft:deepslate{axis:y}"},
        {pos: [34, 1, 37], state: "minecraft:deepslate{axis:y}"},
        {pos: [34, 1, 38], state: "minecraft:deepslate_tiles"},
        {pos: [6, 2, 15], state: "minecraft:deepslate_tiles"},
        {pos: [6, 2, 16], state: "minecraft:smooth_basalt"},
        {pos: [6, 2, 22], state: "minecraft:smooth_basalt"},
        {pos: [6, 2, 23], state: "minecraft:deepslate_tiles"},
        {pos: [7, 2, 15], state: "minecraft:deepslate_tiles"},
        {pos: [7, 2, 16], state: "minecraft:polished_deepslate"},
        {pos: [7, 2, 22], state: "minecraft:polished_deepslate"},
        {pos: [7, 2, 23], state: "minecraft:deepslate_tiles"},
        {pos: [8, 2, 15], state: "minecraft:deepslate_tiles"},
        {pos: [8, 2, 16], state: "minecraft:smooth_basalt"},
        {pos: [8, 2, 22], state: "minecraft:smooth_basalt"},
        {pos: [8, 2, 23], state: "minecraft:deepslate_tiles"},
        {pos: [11, 2, 15], state: "minecraft:deepslate_tiles"},
        {pos: [11, 2, 16], state: "minecraft:smooth_basalt"},
        {pos: [11, 2, 22], state: "minecraft:smooth_basalt"},
        {pos: [11, 2, 23], state: "minecraft:deepslate_tiles"},
        {pos: [12, 2, 15], state: "minecraft:deepslate_tiles"},
        {pos: [12, 2, 16], state: "minecraft:polished_deepslate"},
        {pos: [12, 2, 22], state: "minecraft:polished_deepslate"},
        {pos: [12, 2, 23], state: "minecraft:deepslate_tiles"},
        {pos: [13, 2, 0], state: "minecraft:deepslate_bricks"},
        {pos: [13, 2, 1], state: "minecraft:deepslate{axis:y}"},
        {pos: [13, 2, 2], state: "minecraft:deepslate{axis:y}"},
        {pos: [13, 2, 3], state: "minecraft:deepslate{axis:y}"},
        {pos: [13, 2, 4], state: "minecraft:deepslate{axis:y}"},
        {pos: [13, 2, 15], state: "minecraft:deepslate_tiles"},
        {pos: [13, 2, 16], state: "minecraft:smooth_basalt"},
        {pos: [13, 2, 22], state: "minecraft:smooth_basalt"},
        {pos: [13, 2, 23], state: "minecraft:deepslate_tiles"},
        {pos: [13, 2, 36], state: "minecraft:deepslate{axis:y}"},
        {pos: [13, 2, 37], state: "minecraft:deepslate{axis:y}"},
        {pos: [13, 2, 38], state: "minecraft:deepslate_bricks"},
        {pos: [14, 2, 0], state: "minecraft:deepslate_bricks"},
        {pos: [14, 2, 1], state: "minecraft:deepslate{axis:y}"},
        {pos: [14, 2, 2], state: "minecraft:deepslate{axis:y}"},
        {pos: [14, 2, 3], state: "minecraft:deepslate{axis:y}"},
        {pos: [14, 2, 4], state: "minecraft:deepslate{axis:y}"},
        {pos: [14, 2, 34], state: "minecraft:deepslate{axis:y}"},
        {pos: [14, 2, 35], state: "minecraft:deepslate{axis:y}"},
        {pos: [14, 2, 36], state: "minecraft:deepslate{axis:y}"},
        {pos: [14, 2, 37], state: "minecraft:deepslate{axis:y}"},
        {pos: [14, 2, 38], state: "minecraft:deepslate_bricks"},
        {pos: [15, 2, 0], state: "minecraft:deepslate_bricks"},
        {pos: [15, 2, 1], state: "minecraft:deepslate{axis:y}"},
        {pos: [15, 2, 2], state: "minecraft:deepslate{axis:y}"},
        {pos: [15, 2, 3], state: "minecraft:deepslate{axis:y}"},
        {pos: [15, 2, 4], state: "minecraft:deepslate{axis:y}"},
        {pos: [15, 2, 34], state: "minecraft:deepslate{axis:y}"},
        {pos: [15, 2, 35], state: "minecraft:deepslate{axis:y}"},
        {pos: [15, 2, 36], state: "minecraft:deepslate{axis:y}"},
        {pos: [15, 2, 37], state: "minecraft:deepslate{axis:y}"},
        {pos: [15, 2, 38], state: "minecraft:deepslate_bricks"},
        {pos: [16, 2, 0], state: "minecraft:deepslate_bricks"},
        {pos: [16, 2, 1], state: "minecraft:deepslate{axis:y}"},
        {pos: [16, 2, 2], state: "minecraft:deepslate{axis:y}"},
        {pos: [16, 2, 3], state: "minecraft:deepslate{axis:y}"},
        {pos: [16, 2, 4], state: "minecraft:deepslate{axis:y}"},
        {pos: [16, 2, 15], state: "minecraft:deepslate_tiles"},
        {pos: [16, 2, 16], state: "minecraft:smooth_basalt"},
        {pos: [16, 2, 18], state: "minecraft:deepslate_tiles"},
        {pos: [16, 2, 22], state: "minecraft:smooth_basalt"},
        {pos: [16, 2, 23], state: "minecraft:deepslate_tiles"},
        {pos: [16, 2, 34], state: "minecraft:deepslate{axis:y}"},
        {pos: [16, 2, 35], state: "minecraft:deepslate{axis:y}"},
        {pos: [16, 2, 36], state: "minecraft:deepslate{axis:y}"},
        {pos: [16, 2, 37], state: "minecraft:deepslate{axis:y}"},
        {pos: [16, 2, 38], state: "minecraft:deepslate_bricks"},
        {pos: [17, 2, 15], state: "minecraft:deepslate_tiles"},
        {pos: [17, 2, 16], state: "minecraft:polished_deepslate"},
        {pos: [17, 2, 18], state: "minecraft:deepslate_tiles"},
        {pos: [17, 2, 22], state: "minecraft:polished_deepslate"},
        {pos: [17, 2, 23], state: "minecraft:deepslate_tiles"},
        {pos: [18, 2, 15], state: "minecraft:deepslate_tiles"},
        {pos: [18, 2, 16], state: "minecraft:smooth_basalt"},
        {pos: [18, 2, 22], state: "minecraft:smooth_basalt"},
        {pos: [18, 2, 23], state: "minecraft:deepslate_tiles"},
        {pos: [21, 2, 15], state: "minecraft:deepslate_tiles"},
        {pos: [21, 2, 16], state: "minecraft:smooth_basalt"},
        {pos: [21, 2, 22], state: "minecraft:smooth_basalt"},
        {pos: [21, 2, 23], state: "minecraft:deepslate_tiles"},
        {pos: [22, 2, 15], state: "minecraft:deepslate_tiles"},
        {pos: [22, 2, 16], state: "minecraft:polished_deepslate"},
        {pos: [22, 2, 22], state: "minecraft:polished_deepslate"},
        {pos: [22, 2, 23], state: "minecraft:deepslate_tiles"},
        {pos: [23, 2, 0], state: "minecraft:deepslate_bricks"},
        {pos: [23, 2, 1], state: "minecraft:deepslate{axis:y}"},
        {pos: [23, 2, 2], state: "minecraft:deepslate{axis:y}"},
        {pos: [23, 2, 3], state: "minecraft:deepslate{axis:y}"},
        {pos: [23, 2, 4], state: "minecraft:deepslate{axis:y}"},
        {pos: [23, 2, 15], state: "minecraft:deepslate_tiles"},
        {pos: [23, 2, 16], state: "minecraft:smooth_basalt"},
        {pos: [23, 2, 22], state: "minecraft:smooth_basalt"},
        {pos: [23, 2, 23], state: "minecraft:deepslate_tiles"},
        {pos: [23, 2, 36], state: "minecraft:deepslate{axis:y}"},
        {pos: [23, 2, 37], state: "minecraft:deepslate{axis:y}"},
        {pos: [23, 2, 38], state: "minecraft:deepslate_bricks"},
        {pos: [24, 2, 0], state: "minecraft:deepslate_bricks"},
        {pos: [24, 2, 1], state: "minecraft:deepslate{axis:y}"},
        {pos: [24, 2, 2], state: "minecraft:deepslate{axis:y}"},
        {pos: [24, 2, 3], state: "minecraft:deepslate{axis:y}"},
        {pos: [24, 2, 4], state: "minecraft:deepslate{axis:y}"},
        {pos: [24, 2, 36], state: "minecraft:deepslate{axis:y}"},
        {pos: [24, 2, 37], state: "minecraft:deepslate{axis:y}"},
        {pos: [24, 2, 38], state: "minecraft:deepslate_bricks"},
        {pos: [25, 2, 0], state: "minecraft:deepslate_bricks"},
        {pos: [25, 2, 1], state: "minecraft:deepslate{axis:y}"},
        {pos: [25, 2, 2], state: "minecraft:deepslate{axis:y}"},
        {pos: [25, 2, 3], state: "minecraft:deepslate{axis:y}"},
        {pos: [25, 2, 4], state: "minecraft:deepslate{axis:y}"},
        {pos: [25, 2, 34], state: "minecraft:deepslate{axis:y}"},
        {pos: [25, 2, 35], state: "minecraft:deepslate{axis:y}"},
        {pos: [25, 2, 36], state: "minecraft:deepslate{axis:y}"},
        {pos: [25, 2, 37], state: "minecraft:deepslate{axis:y}"},
        {pos: [25, 2, 38], state: "minecraft:deepslate_bricks"},
        {pos: [26, 2, 0], state: "minecraft:deepslate_bricks"},
        {pos: [26, 2, 1], state: "minecraft:deepslate{axis:y}"},
        {pos: [26, 2, 2], state: "minecraft:deepslate{axis:y}"},
        {pos: [26, 2, 3], state: "minecraft:deepslate{axis:y}"},
        {pos: [26, 2, 4], state: "minecraft:deepslate{axis:y}"},
        {pos: [26, 2, 15], state: "minecraft:deepslate_tiles"},
        {pos: [26, 2, 16], state: "minecraft:smooth_basalt"},
        {pos: [26, 2, 22], state: "minecraft:smooth_basalt"},
        {pos: [26, 2, 23], state: "minecraft:deepslate_tiles"},
        {pos: [26, 2, 34], state: "minecraft:deepslate{axis:y}"},
        {pos: [26, 2, 35], state: "minecraft:deepslate{axis:y}"},
        {pos: [26, 2, 36], state: "minecraft:deepslate{axis:y}"},
        {pos: [26, 2, 37], state: "minecraft:deepslate{axis:y}"},
        {pos: [26, 2, 38], state: "minecraft:deepslate_bricks"},
        {pos: [27, 2, 15], state: "minecraft:deepslate_tiles"},
        {pos: [27, 2, 16], state: "minecraft:polished_deepslate"},
        {pos: [27, 2, 22], state: "minecraft:polished_deepslate"},
        {pos: [27, 2, 23], state: "minecraft:deepslate_tiles"},
        {pos: [28, 2, 15], state: "minecraft:deepslate_tiles"},
        {pos: [28, 2, 16], state: "minecraft:smooth_basalt"},
        {pos: [28, 2, 22], state: "minecraft:smooth_basalt"},
        {pos: [28, 2, 23], state: "minecraft:deepslate_tiles"},
        {pos: [31, 2, 15], state: "minecraft:deepslate_tiles"},
        {pos: [31, 2, 16], state: "minecraft:smooth_basalt"},
        {pos: [31, 2, 22], state: "minecraft:smooth_basalt"},
        {pos: [31, 2, 23], state: "minecraft:deepslate_tiles"},
        {pos: [32, 2, 15], state: "minecraft:deepslate_tiles"},
        {pos: [32, 2, 16], state: "minecraft:polished_deepslate"},
        {pos: [32, 2, 22], state: "minecraft:polished_deepslate"},
        {pos: [32, 2, 23], state: "minecraft:deepslate_tiles"},
        {pos: [33, 2, 0], state: "minecraft:deepslate_bricks"},
        {pos: [33, 2, 1], state: "minecraft:deepslate{axis:y}"},
        {pos: [33, 2, 2], state: "minecraft:deepslate{axis:y}"},
        {pos: [33, 2, 3], state: "minecraft:deepslate{axis:y}"},
        {pos: [33, 2, 15], state: "minecraft:deepslate_tiles"},
        {pos: [33, 2, 16], state: "minecraft:smooth_basalt"},
        {pos: [33, 2, 22], state: "minecraft:smooth_basalt"},
        {pos: [33, 2, 23], state: "minecraft:deepslate_tiles"},
        {pos: [33, 2, 35], state: "minecraft:deepslate{axis:y}"},
        {pos: [33, 2, 36], state: "minecraft:deepslate{axis:y}"},
        {pos: [33, 2, 37], state: "minecraft:deepslate{axis:y}"},
        {pos: [33, 2, 38], state: "minecraft:deepslate_bricks"},
        {pos: [34, 2, 0], state: "minecraft:deepslate_bricks"},
        {pos: [34, 2, 1], state: "minecraft:deepslate{axis:y}"},
        {pos: [34, 2, 2], state: "minecraft:deepslate{axis:y}"},
        {pos: [34, 2, 3], state: "minecraft:deepslate{axis:y}"},
        {pos: [34, 2, 4], state: "minecraft:deepslate{axis:y}"},
        {pos: [34, 2, 36], state: "minecraft:deepslate{axis:y}"},
        {pos: [34, 2, 37], state: "minecraft:deepslate{axis:y}"},
        {pos: [34, 2, 38], state: "minecraft:deepslate_bricks"},
        {pos: [6, 3, 15], state: "minecraft:polished_deepslate"},
        {pos: [6, 3, 23], state: "minecraft:polished_deepslate"},
        {pos: [8, 3, 15], state: "minecraft:polished_deepslate"},
        {pos: [8, 3, 23], state: "minecraft:polished_deepslate"},
        {pos: [11, 3, 15], state: "minecraft:polished_deepslate"},
        {pos: [11, 3, 23], state: "minecraft:polished_deepslate"},
        {pos: [13, 3, 15], state: "minecraft:polished_deepslate"},
        {pos: [13, 3, 23], state: "minecraft:polished_deepslate"},
        {pos: [14, 3, 2], state: "minecraft:polished_deepslate"},
        {pos: [14, 3, 3], state: "minecraft:polished_deepslate"},
        {pos: [14, 3, 35], state: "minecraft:polished_deepslate"},
        {pos: [14, 3, 36], state: "minecraft:polished_deepslate"},
        {pos: [15, 3, 2], state: "minecraft:polished_deepslate"},
        {pos: [15, 3, 3], state: "minecraft:polished_deepslate"},
        {pos: [15, 3, 35], state: "minecraft:polished_deepslate"},
        {pos: [15, 3, 36], state: "minecraft:polished_deepslate"},
        {pos: [16, 3, 15], state: "minecraft:polished_deepslate"},
        {pos: [16, 3, 23], state: "minecraft:polished_deepslate"},
        {pos: [18, 3, 15], state: "minecraft:polished_deepslate"},
        {pos: [18, 3, 23], state: "minecraft:polished_deepslate"},
        {pos: [21, 3, 15], state: "minecraft:polished_deepslate"},
        {pos: [21, 3, 23], state: "minecraft:polished_deepslate"},
        {pos: [23, 3, 15], state: "minecraft:polished_deepslate"},
        {pos: [23, 3, 23], state: "minecraft:polished_deepslate"},
        {pos: [24, 3, 2], state: "minecraft:polished_deepslate"},
        {pos: [24, 3, 3], state: "minecraft:polished_deepslate"},
        {pos: [24, 3, 36], state: "minecraft:polished_deepslate"},
        {pos: [25, 3, 2], state: "minecraft:polished_deepslate"},
        {pos: [25, 3, 3], state: "minecraft:polished_deepslate"},
        {pos: [25, 3, 35], state: "minecraft:polished_deepslate"},
        {pos: [25, 3, 36], state: "minecraft:polished_deepslate"},
        {pos: [26, 3, 15], state: "minecraft:polished_deepslate"},
        {pos: [26, 3, 23], state: "minecraft:polished_deepslate"},
        {pos: [28, 3, 15], state: "minecraft:polished_deepslate"},
        {pos: [28, 3, 23], state: "minecraft:polished_deepslate"},
        {pos: [31, 3, 15], state: "minecraft:polished_deepslate"},
        {pos: [31, 3, 23], state: "minecraft:polished_deepslate"},
        {pos: [33, 3, 23], state: "minecraft:polished_deepslate"},
        {pos: [34, 3, 2], state: "minecraft:polished_deepslate"},
        {pos: [34, 3, 3], state: "minecraft:polished_deepslate"},
        {pos: [34, 3, 35], state: "minecraft:polished_deepslate"},
        {pos: [34, 3, 36], state: "minecraft:polished_deepslate"},
        {pos: [6, 4, 23], state: "minecraft:deepslate_bricks"},
        {pos: [7, 4, 15], state: "minecraft:chiseled_deepslate"},
        {pos: [7, 4, 23], state: "minecraft:chiseled_deepslate"},
        {pos: [8, 4, 15], state: "minecraft:deepslate_bricks"},
        {pos: [11, 4, 15], state: "minecraft:deepslate_bricks"},
        {pos: [11, 4, 23], state: "minecraft:deepslate_bricks"},
        {pos: [12, 4, 15], state: "minecraft:chiseled_deepslate"},
        {pos: [12, 4, 23], state: "minecraft:chiseled_deepslate"},
        {pos: [13, 4, 1], state: "minecraft:polished_deepslate"},
        {pos: [13, 4, 2], state: "minecraft:polished_deepslate"},
        {pos: [13, 4, 3], state: "minecraft:polished_deepslate"},
        {pos: [13, 4, 4], state: "minecraft:polished_deepslate"},
        {pos: [13, 4, 15], state: "minecraft:deepslate_bricks"},
        {pos: [13, 4, 23], state: "minecraft:deepslate_bricks"},
        {pos: [13, 4, 36], state: "minecraft:polished_deepslate"},
        {pos: [13, 4, 37], state: "minecraft:polished_deepslate"},
        {pos: [14, 4, 1], state: "minecraft:polished_deepslate"},
        {pos: [14, 4, 2], state: "minecraft:polished_deepslate"},
        {pos: [14, 4, 3], state: "minecraft:polished_deepslate"},
        {pos: [14, 4, 4], state: "minecraft:polished_deepslate"},
        {pos: [14, 4, 35], state: "minecraft:polished_deepslate"},
        {pos: [14, 4, 36], state: "minecraft:polished_deepslate"},
        {pos: [14, 4, 37], state: "minecraft:polished_deepslate"},
        {pos: [15, 4, 1], state: "minecraft:polished_deepslate"},
        {pos: [15, 4, 2], state: "minecraft:polished_deepslate"},
        {pos: [15, 4, 3], state: "minecraft:polished_deepslate"},
        {pos: [15, 4, 4], state: "minecraft:polished_deepslate"},
        {pos: [15, 4, 34], state: "minecraft:polished_deepslate"},
        {pos: [15, 4, 35], state: "minecraft:polished_deepslate"},
        {pos: [15, 4, 36], state: "minecraft:polished_deepslate"},
        {pos: [15, 4, 37], state: "minecraft:polished_deepslate"},
        {pos: [16, 4, 1], state: "minecraft:polished_deepslate"},
        {pos: [16, 4, 2], state: "minecraft:polished_deepslate"},
        {pos: [16, 4, 3], state: "minecraft:polished_deepslate"},
        {pos: [16, 4, 4], state: "minecraft:polished_deepslate"},
        {pos: [16, 4, 15], state: "minecraft:deepslate_bricks"},
        {pos: [16, 4, 23], state: "minecraft:deepslate_bricks"},
        {pos: [16, 4, 34], state: "minecraft:polished_deepslate"},
        {pos: [16, 4, 35], state: "minecraft:polished_deepslate"},
        {pos: [16, 4, 36], state: "minecraft:polished_deepslate"},
        {pos: [16, 4, 37], state: "minecraft:polished_deepslate"},
        {pos: [17, 4, 15], state: "minecraft:chiseled_deepslate"},
        {pos: [17, 4, 23], state: "minecraft:chiseled_deepslate"},
        {pos: [18, 4, 15], state: "minecraft:deepslate_bricks"},
        {pos: [18, 4, 23], state: "minecraft:deepslate_bricks"},
        {pos: [21, 4, 15], state: "minecraft:deepslate_bricks"},
        {pos: [21, 4, 23], state: "minecraft:deepslate_bricks"},
        {pos: [22, 4, 15], state: "minecraft:chiseled_deepslate"},
        {pos: [22, 4, 23], state: "minecraft:chiseled_deepslate"},
        {pos: [23, 4, 1], state: "minecraft:polished_deepslate"},
        {pos: [23, 4, 2], state: "minecraft:polished_deepslate"},
        {pos: [23, 4, 3], state: "minecraft:polished_deepslate"},
        {pos: [23, 4, 4], state: "minecraft:polished_deepslate"},
        {pos: [23, 4, 15], state: "minecraft:deepslate_bricks"},
        {pos: [23, 4, 23], state: "minecraft:deepslate_bricks"},
        {pos: [23, 4, 37], state: "minecraft:polished_deepslate"},
        {pos: [24, 4, 1], state: "minecraft:polished_deepslate"},
        {pos: [24, 4, 2], state: "minecraft:polished_deepslate"},
        {pos: [24, 4, 3], state: "minecraft:polished_deepslate"},
        {pos: [24, 4, 4], state: "minecraft:polished_deepslate"},
        {pos: [24, 4, 36], state: "minecraft:polished_deepslate"},
        {pos: [24, 4, 37], state: "minecraft:polished_deepslate"},
        {pos: [25, 4, 1], state: "minecraft:polished_deepslate"},
        {pos: [25, 4, 2], state: "minecraft:polished_deepslate"},
        {pos: [25, 4, 3], state: "minecraft:polished_deepslate"},
        {pos: [25, 4, 4], state: "minecraft:polished_deepslate"},
        {pos: [25, 4, 34], state: "minecraft:polished_deepslate"},
        {pos: [25, 4, 35], state: "minecraft:polished_deepslate"},
        {pos: [25, 4, 36], state: "minecraft:polished_deepslate"},
        {pos: [25, 4, 37], state: "minecraft:polished_deepslate"},
        {pos: [26, 4, 1], state: "minecraft:polished_deepslate"},
        {pos: [26, 4, 2], state: "minecraft:polished_deepslate"},
        {pos: [26, 4, 3], state: "minecraft:polished_deepslate"},
        {pos: [26, 4, 4], state: "minecraft:polished_deepslate"},
        {pos: [26, 4, 15], state: "minecraft:deepslate_bricks"},
        {pos: [26, 4, 23], state: "minecraft:deepslate_bricks"},
        {pos: [26, 4, 34], state: "minecraft:polished_deepslate"},
        {pos: [26, 4, 35], state: "minecraft:polished_deepslate"},
        {pos: [26, 4, 36], state: "minecraft:polished_deepslate"},
        {pos: [26, 4, 37], state: "minecraft:polished_deepslate"},
        {pos: [27, 4, 15], state: "minecraft:chiseled_deepslate"},
        {pos: [27, 4, 23], state: "minecraft:chiseled_deepslate"},
        {pos: [28, 4, 15], state: "minecraft:deepslate_bricks"},
        {pos: [28, 4, 23], state: "minecraft:deepslate_bricks"},
        {pos: [31, 4, 15], state: "minecraft:deepslate_bricks"},
        {pos: [31, 4, 23], state: "minecraft:deepslate_bricks"},
        {pos: [32, 4, 15], state: "minecraft:chiseled_deepslate"},
        {pos: [32, 4, 23], state: "minecraft:chiseled_deepslate"},
        {pos: [33, 4, 1], state: "minecraft:polished_deepslate"},
        {pos: [33, 4, 2], state: "minecraft:polished_deepslate"},
        {pos: [33, 4, 3], state: "minecraft:polished_deepslate"},
        {pos: [33, 4, 4], state: "minecraft:polished_deepslate"},
        {pos: [33, 4, 23], state: "minecraft:deepslate_bricks"},
        {pos: [33, 4, 35], state: "minecraft:polished_deepslate"},
        {pos: [33, 4, 36], state: "minecraft:polished_deepslate"},
        {pos: [33, 4, 37], state: "minecraft:polished_deepslate"},
        {pos: [34, 4, 1], state: "minecraft:polished_deepslate"},
        {pos: [34, 4, 2], state: "minecraft:polished_deepslate"},
        {pos: [34, 4, 3], state: "minecraft:polished_deepslate"},
        {pos: [34, 4, 4], state: "minecraft:polished_deepslate"},
        {pos: [34, 4, 35], state: "minecraft:polished_deepslate"},
        {pos: [34, 4, 36], state: "minecraft:polished_deepslate"},
        {pos: [34, 4, 37], state: "minecraft:polished_deepslate"},
        {pos: [6, 5, 22], state: "minecraft:deepslate_tiles"},
        {pos: [6, 5, 23], state: "minecraft:deepslate_tiles"},
        {pos: [7, 5, 15], state: "minecraft:deepslate_tiles"},
        {pos: [7, 5, 16], state: "minecraft:deepslate_tiles"},
        {pos: [7, 5, 22], state: "minecraft:deepslate_tiles"},
        {pos: [8, 5, 15], state: "minecraft:deepslate_tiles"},
        {pos: [8, 5, 16], state: "minecraft:deepslate_tiles"},
        {pos: [11, 5, 15], state: "minecraft:deepslate_tiles"},
        {pos: [11, 5, 16], state: "minecraft:deepslate_tiles"},
        {pos: [11, 5, 22], state: "minecraft:deepslate_tiles"},
        {pos: [12, 5, 15], state: "minecraft:deepslate_tiles"},
        {pos: [12, 5, 16], state: "minecraft:deepslate_tiles"},
        {pos: [12, 5, 22], state: "minecraft:deepslate_tiles"},
        {pos: [13, 5, 2], state: "minecraft:deepslate_tiles"},
        {pos: [13, 5, 3], state: "minecraft:deepslate_tiles"},
        {pos: [13, 5, 4], state: "minecraft:chiseled_deepslate"},
        {pos: [13, 5, 15], state: "minecraft:deepslate_tiles"},
        {pos: [13, 5, 16], state: "minecraft:deepslate_tiles"},
        {pos: [13, 5, 22], state: "minecraft:deepslate_tiles"},
        {pos: [13, 5, 23], state: "minecraft:deepslate_tiles"},
