{
    size: [30, 15, 39],
    data: [
        {pos: [0, 0, 0], state: "minecraft:deepslate{axis:y}"},
        {pos: [0, 0, 1], state: "minecraft:deepslate{axis:y}"},
        {pos: [0, 0, 2], state: "minecraft:deepslate{axis:y}"},
        {pos: [0, 0, 3], state: "minecraft:deepslate{axis:y}"},
        {pos: [0, 0, 4], state: "minecraft:deepslate{axis:y}"},
        {pos: [0, 0, 5], state: "minecraft:deepslate{axis:y}"},
        {pos: [0, 0, 6], state: "minecraft:deepslate{axis:y}"},
        {pos: [0, 0, 7], state: "minecraft:deepslate{axis:y}"},
        {pos: [0, 0, 8], state: "minecraft:deepslate{axis:y}"},
        {pos: [0, 0, 9], state: "minecraft:deepslate{axis:y}"},
        {pos: [0, 0, 10], state: "minecraft:deepslate{axis:y}"},
        {pos: [0, 0, 11], state: "minecraft:deepslate{axis:y}"},
        {pos: [0, 0, 12], state: "minecraft:deepslate{axis:y}"},
        {pos: [0, 0, 13], state: "minecraft:deepslate{axis:y}"},
        {pos: [0, 0, 14], state: "minecraft:deepslate{axis:y}"},
        {pos: [0, 0, 15], state: "minecraft:deepslate{axis:y}"},
        {pos: [0, 0, 16], state: "minecraft:deepslate{axis:y}"},
        {pos: [0, 0, 17], state: "minecraft:deepslate_tiles"},
        {pos: [0, 0, 18], state: "minecraft:deepslate_tiles"},
        {pos: [0, 0, 20], state: "minecraft:deepslate_tiles"},
        {pos: [0, 0, 21], state: "minecraft:deepslate_tiles"},
        {pos: [0, 0, 22], state: "minecraft:deepslate{axis:y}"},
        {pos: [0, 0, 23], state: "minecraft:deepslate{axis:y}"},
        {pos: [0, 0, 24], state: "minecraft:deepslate{axis:y}"},
        {pos: [0, 0, 25], state: "minecraft:deepslate{axis:y}"},
        {pos: [0, 0, 26], state: "minecraft:deepslate{axis:y}"},
        {pos: [0, 0, 27], state: "minecraft:deepslate{axis:y}"},
        {pos: [0, 0, 28], state: "minecraft:deepslate{axis:y}"},
        {pos: [0, 0, 29], state: "minecraft:deepslate{axis:y}"},
        {pos: [0, 0, 30], state: "minecraft:deepslate{axis:y}"},
        {pos: [0, 0, 31], state: "minecraft:deepslate{axis:y}"},
        {pos: [0, 0, 32], state: "minecraft:deepslate{axis:y}"},
        {pos: [0, 0, 33], state: "minecraft:deepslate{axis:y}"},
        {pos: [0, 0, 34], state: "minecraft:deepslate{axis:y}"},
        {pos: [0, 0, 35], state: "minecraft:deepslate{axis:y}"},
        {pos: [0, 0, 36], state: "minecraft:deepslate{axis:y}"},
        {pos: [0, 0, 37], state: "minecraft:deepslate{axis:y}"},
        {pos: [0, 0, 38], state: "minecraft:deepslate{axis:y}"},
        {pos: [1, 0, 0], state: "minecraft:deepslate{axis:y}"},
        {pos: [1, 0, 1], state: "minecraft:deepslate{axis:y}"},
        {pos: [1, 0, 2], state: "minecraft:deepslate{axis:y}"},
        {pos: [1, 0, 3], state: "minecraft:deepslate{axis:y}"},
        {pos: [1, 0, 4], state: "minecraft:deepslate{axis:y}"},
        {pos: [1, 0, 5], state: "minecraft:deepslate{axis:y}"},
        {pos: [1, 0, 6], state: "minecraft:deepslate{axis:y}"},
        {pos: [1, 0, 7], state: "minecraft:deepslate{axis:y}"},
        {pos: [1, 0, 8], state: "minecraft:polished_basalt{axis:y}"},
        {pos: [1, 0, 9], state: "minecraft:polished_basalt{axis:z}"},
        {pos: [1, 0, 10], state: "minecraft:polished_basalt{axis:z}"},
        {pos: [1, 0, 11], state: "minecraft:polished_basalt{axis:z}"},
        {pos: [1, 0, 12], state: "minecraft:polished_basalt{axis:z}"},
        {pos: [1, 0, 13], state: "minecraft:polished_basalt{axis:z}"},
        {pos: [1, 0, 14], state: "minecraft:polished_basalt{axis:z}"},
        {pos: [1, 0, 15], state: "minecraft:deepslate_tiles"},
        {pos: [1, 0, 16], state: "minecraft:deepslate_tiles"},
        {pos: [1, 0, 17], state: "minecraft:deepslate_tiles"},
        {pos: [1, 0, 18], state: "minecraft:deepslate_tiles"},
        {pos: [1, 0, 19], state: "minecraft:deepslate_tiles"},
        {pos: [1, 0, 20], state: "minecraft:deepslate_tiles"},
        {pos: [1, 0, 21], state: "minecraft:deepslate_tiles"},
        {pos: [1, 0, 22], state: "minecraft:deepslate_tiles"},
        {pos: [1, 0, 23], state: "minecraft:deepslate_tiles"},
        {pos: [1, 0, 24], state: "minecraft:polished_basalt{axis:z}"},
        {pos: [1, 0, 25], state: "minecraft:polished_basalt{axis:z}"},
        {pos: [1, 0, 26], state: "minecraft:polished_basalt{axis:z}"},
        {pos: [1, 0, 27], state: "minecraft:polished_basalt{axis:z}"},
        {pos: [1, 0, 28], state: "minecraft:polished_basalt{axis:z}"},
        {pos: [1, 0, 29], state: "minecraft:polished_basalt{axis:z}"},
        {pos: [1, 0, 30], state: "minecraft:polished_basalt{axis:y}"},
        {pos: [1, 0, 31], state: "minecraft:deepslate{axis:y}"},
        {pos: [1, 0, 32], state: "minecraft:deepslate{axis:y}"},
        {pos: [1, 0, 33], state: "minecraft:deepslate{axis:y}"},
        {pos: [1, 0, 34], state: "minecraft:deepslate{axis:y}"},
        {pos: [1, 0, 35], state: "minecraft:deepslate{axis:y}"},
        {pos: [1, 0, 36], state: "minecraft:deepslate{axis:y}"},
        {pos: [1, 0, 37], state: "minecraft:deepslate{axis:y}"},
        {pos: [1, 0, 38], state: "minecraft:deepslate{axis:y}"},
        {pos: [2, 0, 0], state: "minecraft:deepslate{axis:y}"},
        {pos: [2, 0, 1], state: "minecraft:deepslate{axis:y}"},
        {pos: [2, 0, 2], state: "minecraft:deepslate{axis:y}"},
        {pos: [2, 0, 3], state: "minecraft:deepslate{axis:y}"},
        {pos: [2, 0, 4], state: "minecraft:deepslate{axis:y}"},
        {pos: [2, 0, 5], state: "minecraft:deepslate{axis:y}"},
        {pos: [2, 0, 6], state: "minecraft:deepslate{axis:y}"},
        {pos: [2, 0, 7], state: "minecraft:deepslate{axis:y}"},
        {pos: [2, 0, 8], state: "minecraft:polished_basalt{axis:x}"},
        {pos: [2, 0, 15], state: "minecraft:deepslate_tiles"},
        {pos: [2, 0, 16], state: "minecraft:deepslate_tiles"},
        {pos: [2, 0, 17], state: "minecraft:deepslate_tiles"},
        {pos: [2, 0, 18], state: "minecraft:deepslate_tiles"},
        {pos: [2, 0, 19], state: "minecraft:deepslate_tiles"},
        {pos: [2, 0, 20], state: "minecraft:deepslate_tiles"},
        {pos: [2, 0, 21], state: "minecraft:deepslate_tiles"},
        {pos: [2, 0, 22], state: "minecraft:deepslate_tiles"},
        {pos: [2, 0, 23], state: "minecraft:deepslate_tiles"},
        {pos: [2, 0, 30], state: "minecraft:polished_basalt{axis:x}"},
        {pos: [2, 0, 31], state: "minecraft:deepslate{axis:y}"},
        {pos: [2, 0, 32], state: "minecraft:deepslate{axis:y}"},
        {pos: [2, 0, 33], state: "minecraft:deepslate{axis:y}"},
        {pos: [2, 0, 34], state: "minecraft:deepslate{axis:y}"},
        {pos: [2, 0, 35], state: "minecraft:deepslate{axis:y}"},
        {pos: [2, 0, 36], state: "minecraft:deepslate{axis:y}"},
        {pos: [2, 0, 37], state: "minecraft:deepslate{axis:y}"},
        {pos: [2, 0, 38], state: "minecraft:deepslate{axis:y}"},
        {pos: [3, 0, 0], state: "minecraft:polished_basalt{axis:x}"},
        {pos: [3, 0, 1], state: "minecraft:deepslate{axis:y}"},
        {pos: [3, 0, 2], state: "minecraft:deepslate{axis:y}"},
        {pos: [3, 0, 3], state: "minecraft:deepslate{axis:y}"},
        {pos: [3, 0, 4], state: "minecraft:deepslate{axis:y}"},
        {pos: [3, 0, 5], state: "minecraft:deepslate{axis:y}"},
        {pos: [3, 0, 6], state: "minecraft:deepslate{axis:y}"},
        {pos: [3, 0, 7], state: "minecraft:deepslate{axis:y}"},
        {pos: [3, 0, 8], state: "minecraft:polished_basalt{axis:x}"},
        {pos: [3, 0, 15], state: "minecraft:deepslate_tiles"},
        {pos: [3, 0, 16], state: "minecraft:deepslate_tiles"},
        {pos: [3, 0, 17], state: "minecraft:deepslate_tiles"},
        {pos: [3, 0, 18], state: "minecraft:deepslate_tiles"},
        {pos: [3, 0, 19], state: "minecraft:deepslate_tiles"},
        {pos: [3, 0, 20], state: "minecraft:deepslate_tiles"},
        {pos: [3, 0, 21], state: "minecraft:deepslate_tiles"},
        {pos: [3, 0, 22], state: "minecraft:deepslate_tiles"},
        {pos: [3, 0, 23], state: "minecraft:deepslate_tiles"},
        {pos: [3, 0, 30], state: "minecraft:polished_basalt{axis:x}"},
        {pos: [3, 0, 31], state: "minecraft:deepslate{axis:y}"},
        {pos: [3, 0, 32], state: "minecraft:deepslate{axis:y}"},
        {pos: [3, 0, 33], state: "minecraft:deepslate{axis:y}"},
        {pos: [3, 0, 34], state: "minecraft:deepslate{axis:y}"},
        {pos: [3, 0, 35], state: "minecraft:deepslate{axis:y}"},
        {pos: [3, 0, 36], state: "minecraft:deepslate{axis:y}"},
        {pos: [3, 0, 37], state: "minecraft:deepslate{axis:y}"},
        {pos: [3, 0, 38], state: "minecraft:polished_basalt{axis:x}"},
        {pos: [4, 0, 0], state: "minecraft:polished_basalt{axis:x}"},
        {pos: [4, 0, 1], state: "minecraft:deepslate{axis:y}"},
        {pos: [4, 0, 2], state: "minecraft:deepslate{axis:y}"},
        {pos: [4, 0, 3], state: "minecraft:deepslate{axis:y}"},
        {pos: [4, 0, 4], state: "minecraft:deepslate{axis:y}"},
        {pos: [4, 0, 5], state: "minecraft:deepslate{axis:y}"},
        {pos: [4, 0, 6], state: "minecraft:deepslate{axis:y}"},
        {pos: [4, 0, 7], state: "minecraft:deepslate{axis:y}"},
        {pos: [4, 0, 8], state: "minecraft:polished_basalt{axis:x}"},
        {pos: [4, 0, 15], state: "minecraft:deepslate_tiles"},
        {pos: [4, 0, 16], state: "minecraft:deepslate_tiles"},
        {pos: [4, 0, 17], state: "minecraft:deepslate_tiles"},
        {pos: [4, 0, 18], state: "minecraft:deepslate_tiles"},
        {pos: [4, 0, 19], state: "minecraft:deepslate_tiles"},
        {pos: [4, 0, 20], state: "minecraft:deepslate_tiles"},
        {pos: [4, 0, 21], state: "minecraft:deepslate_tiles"},
        {pos: [4, 0, 22], state: "minecraft:deepslate_tiles"},
        {pos: [4, 0, 23], state: "minecraft:deepslate_tiles"},
        {pos: [4, 0, 30], state: "minecraft:polished_basalt{axis:x}"},
        {pos: [4, 0, 31], state: "minecraft:deepslate{axis:y}"},
        {pos: [4, 0, 32], state: "minecraft:deepslate{axis:y}"},
        {pos: [4, 0, 33], state: "minecraft:deepslate{axis:y}"},
        {pos: [4, 0, 34], state: "minecraft:deepslate{axis:y}"},
        {pos: [4, 0, 35], state: "minecraft:deepslate{axis:y}"},
        {pos: [4, 0, 36], state: "minecraft:deepslate{axis:y}"},
        {pos: [4, 0, 37], state: "minecraft:deepslate{axis:y}"},
        {pos: [4, 0, 38], state: "minecraft:polished_basalt{axis:x}"},
        {pos: [5, 0, 0], state: "minecraft:polished_basalt{axis:x}"},
        {pos: [5, 0, 1], state: "minecraft:deepslate{axis:y}"},
        {pos: [5, 0, 2], state: "minecraft:deepslate{axis:y}"},
        {pos: [5, 0, 3], state: "minecraft:deepslate{axis:y}"},
        {pos: [5, 0, 4], state: "minecraft:deepslate{axis:y}"},
        {pos: [5, 0, 5], state: "minecraft:deepslate{axis:y}"},
        {pos: [5, 0, 6], state: "minecraft:deepslate{axis:y}"},
        {pos: [5, 0, 7], state: "minecraft:deepslate{axis:y}"},
        {pos: [5, 0, 8], state: "minecraft:polished_basalt{axis:x}"},
        {pos: [5, 0, 15], state: "minecraft:deepslate_tiles"},
        {pos: [5, 0, 16], state: "minecraft:deepslate_tiles"},
        {pos: [5, 0, 17], state: "minecraft:deepslate_tiles"},
        {pos: [5, 0, 18], state: "minecraft:deepslate_tiles"},
        {pos: [5, 0, 19], state: "minecraft:deepslate_tiles"},
        {pos: [5, 0, 20], state: "minecraft:deepslate_tiles"},
        {pos: [5, 0, 21], state: "minecraft:deepslate_tiles"},
        {pos: [5, 0, 22], state: "minecraft:deepslate_tiles"},
        {pos: [5, 0, 23], state: "minecraft:deepslate_tiles"},
        {pos: [5, 0, 30], state: "minecraft:polished_basalt{axis:x}"},
        {pos: [5, 0, 31], state: "minecraft:deepslate{axis:y}"},
        {pos: [5, 0, 32], state: "minecraft:deepslate{axis:y}"},
        {pos: [5, 0, 33], state: "minecraft:deepslate{axis:y}"},
        {pos: [5, 0, 34], state: "minecraft:deepslate{axis:y}"},
        {pos: [5, 0, 35], state: "minecraft:deepslate{axis:y}"},
        {pos: [5, 0, 36], state: "minecraft:deepslate{axis:y}"},
        {pos: [5, 0, 37], state: "minecraft:deepslate{axis:y}"},
        {pos: [5, 0, 38], state: "minecraft:polished_basalt{axis:x}"},
        {pos: [6, 0, 0], state: "minecraft:polished_basalt{axis:x}"},
        {pos: [6, 0, 1], state: "minecraft:deepslate{axis:y}"},
        {pos: [6, 0, 2], state: "minecraft:deepslate{axis:y}"},
        {pos: [6, 0, 3], state: "minecraft:deepslate{axis:y}"},
        {pos: [6, 0, 4], state: "minecraft:deepslate{axis:y}"},
        {pos: [6, 0, 5], state: "minecraft:deepslate{axis:y}"},
        {pos: [6, 0, 6], state: "minecraft:deepslate{axis:y}"},
        {pos: [6, 0, 7], state: "minecraft:deepslate{axis:y}"},
        {pos: [6, 0, 8], state: "minecraft:polished_basalt{axis:x}"},
        {pos: [6, 0, 15], state: "minecraft:deepslate_tiles"},
        {pos: [6, 0, 16], state: "minecraft:deepslate_tiles"},
        {pos: [6, 0, 17], state: "minecraft:deepslate_tiles"},
        {pos: [6, 0, 18], state: "minecraft:deepslate_tiles"},
        {pos: [6, 0, 19], state: "minecraft:deepslate_tiles"},
        {pos: [6, 0, 20], state: "minecraft:deepslate_tiles"},
        {pos: [6, 0, 21], state: "minecraft:deepslate_tiles"},
        {pos: [6, 0, 22], state: "minecraft:deepslate_tiles"},
        {pos: [6, 0, 23], state: "minecraft:deepslate_tiles"},
        {pos: [6, 0, 30], state: "minecraft:polished_basalt{axis:x}"},
        {pos: [6, 0, 31], state: "minecraft:deepslate{axis:y}"},
        {pos: [6, 0, 32], state: "minecraft:deepslate{axis:y}"},
        {pos: [6, 0, 33], state: "minecraft:deepslate{axis:y}"},
        {pos: [6, 0, 34], state: "minecraft:deepslate{axis:y}"},
        {pos: [6, 0, 35], state: "minecraft:deepslate{axis:y}"},
        {pos: [6, 0, 36], state: "minecraft:deepslate{axis:y}"},
        {pos: [6, 0, 37], state: "minecraft:deepslate{axis:y}"},
        {pos: [6, 0, 38], state: "minecraft:polished_basalt{axis:x}"},
        {pos: [7, 0, 0], state: "minecraft:deepslate{axis:y}"},
        {pos: [7, 0, 1], state: "minecraft:deepslate{axis:y}"},
        {pos: [7, 0, 2], state: "minecraft:deepslate{axis:y}"},
        {pos: [7, 0, 3], state: "minecraft:deepslate{axis:y}"},
        {pos: [7, 0, 4], state: "minecraft:deepslate{axis:y}"},
        {pos: [7, 0, 5], state: "minecraft:deepslate{axis:y}"},
        {pos: [7, 0, 6], state: "minecraft:deepslate{axis:y}"},
        {pos: [7, 0, 7], state: "minecraft:deepslate{axis:y}"},
        {pos: [7, 0, 8], state: "minecraft:polished_basalt{axis:x}"},
        {pos: [7, 0, 15], state: "minecraft:deepslate_tiles"},
        {pos: [7, 0, 16], state: "minecraft:deepslate_tiles"},
        {pos: [7, 0, 17], state: "minecraft:deepslate_tiles"},
        {pos: [7, 0, 18], state: "minecraft:deepslate_tiles"},
        {pos: [7, 0, 19], state: "minecraft:deepslate_tiles"},
        {pos: [7, 0, 20], state: "minecraft:deepslate_tiles"},
        {pos: [7, 0, 21], state: "minecraft:deepslate_tiles"},
        {pos: [7, 0, 22], state: "minecraft:deepslate_tiles"},
        {pos: [7, 0, 23], state: "minecraft:deepslate_tiles"},
        {pos: [7, 0, 30], state: "minecraft:polished_basalt{axis:x}"},
        {pos: [7, 0, 31], state: "minecraft:deepslate{axis:y}"},
        {pos: [7, 0, 32], state: "minecraft:deepslate{axis:y}"},
        {pos: [7, 0, 33], state: "minecraft:deepslate{axis:y}"},
        {pos: [7, 0, 34], state: "minecraft:deepslate{axis:y}"},
        {pos: [7, 0, 35], state: "minecraft:deepslate{axis:y}"},
        {pos: [7, 0, 36], state: "minecraft:deepslate{axis:y}"},
        {pos: [7, 0, 37], state: "minecraft:deepslate{axis:y}"},
        {pos: [7, 0, 38], state: "minecraft:deepslate{axis:y}"},
        {pos: [8, 0, 0], state: "minecraft:deepslate{axis:y}"},
        {pos: [8, 0, 1], state: "minecraft:deepslate{axis:y}"},
        {pos: [8, 0, 2], state: "minecraft:deepslate{axis:y}"},
        {pos: [8, 0, 3], state: "minecraft:deepslate{axis:y}"},
        {pos: [8, 0, 4], state: "minecraft:deepslate{axis:y}"},
        {pos: [8, 0, 5], state: "minecraft:deepslate{axis:y}"},
        {pos: [8, 0, 6], state: "minecraft:deepslate{axis:y}"},
        {pos: [8, 0, 7], state: "minecraft:deepslate{axis:y}"},
        {pos: [8, 0, 8], state: "minecraft:polished_basalt{axis:y}"},
        {pos: [8, 0, 9], state: "minecraft:polished_basalt{axis:z}"},
        {pos: [8, 0, 10], state: "minecraft:polished_basalt{axis:z}"},
        {pos: [8, 0, 11], state: "minecraft:polished_basalt{axis:z}"},
        {pos: [8, 0, 12], state: "minecraft:polished_basalt{axis:z}"},
        {pos: [8, 0, 13], state: "minecraft:polished_basalt{axis:z}"},
        {pos: [8, 0, 14], state: "minecraft:polished_basalt{axis:z}"},
        {pos: [8, 0, 15], state: "minecraft:deepslate_tiles"},
        {pos: [8, 0, 16], state: "minecraft:deepslate_tiles"},
        {pos: [8, 0, 17], state: "minecraft:deepslate_tiles"},
        {pos: [8, 0, 18], state: "minecraft:deepslate_tiles"},
        {pos: [8, 0, 19], state: "minecraft:deepslate_tiles"},
        {pos: [8, 0, 20], state: "minecraft:deepslate_tiles"},
        {pos: [8, 0, 21], state: "minecraft:deepslate_tiles"},
        {pos: [8, 0, 22], state: "minecraft:deepslate_tiles"},
        {pos: [8, 0, 23], state: "minecraft:deepslate_tiles"},
        {pos: [8, 0, 24], state: "minecraft:polished_basalt{axis:z}"},
        {pos: [8, 0, 25], state: "minecraft:polished_basalt{axis:z}"},
        {pos: [8, 0, 26], state: "minecraft:polished_basalt{axis:z}"},
        {pos: [8, 0, 27], state: "minecraft:polished_basalt{axis:z}"},
        {pos: [8, 0, 28], state: "minecraft:polished_basalt{axis:z}"},
        {pos: [8, 0, 29], state: "minecraft:polished_basalt{axis:z}"},
        {pos: [8, 0, 30], state: "minecraft:polished_basalt{axis:y}"},
        {pos: [8, 0, 31], state: "minecraft:deepslate{axis:y}"},
        {pos: [8, 0, 32], state: "minecraft:deepslate{axis:y}"},
        {pos: [8, 0, 33], state: "minecraft:deepslate{axis:y}"},
        {pos: [8, 0, 34], state: "minecraft:deepslate{axis:y}"},
        {pos: [8, 0, 35], state: "minecraft:deepslate{axis:y}"},
        {pos: [8, 0, 36], state: "minecraft:deepslate{axis:y}"},
        {pos: [8, 0, 37], state: "minecraft:deepslate{axis:y}"},
        {pos: [8, 0, 38], state: "minecraft:deepslate{axis:y}"},
        {pos: [9, 0, 0], state: "minecraft:deepslate{axis:y}"},
        {pos: [9, 0, 1], state: "minecraft:deepslate{axis:y}"},
        {pos: [9, 0, 2], state: "minecraft:deepslate{axis:y}"},
        {pos: [9, 0, 3], state: "minecraft:deepslate{axis:y}"},
        {pos: [9, 0, 4], state: "minecraft:deepslate{axis:y}"},
        {pos: [9, 0, 5], state: "minecraft:deepslate{axis:y}"},
        {pos: [9, 0, 6], state: "minecraft:deepslate{axis:y}"},
        {pos: [9, 0, 7], state: "minecraft:deepslate{axis:y}"},
        {pos: [9, 0, 8], state: "minecraft:deepslate{axis:y}"},
        {pos: [9, 0, 9], state: "minecraft:deepslate{axis:y}"},
        {pos: [9, 0, 10], state: "minecraft:deepslate{axis:y}"},
        {pos: [9, 0, 11], state: "minecraft:deepslate{axis:y}"},
        {pos: [9, 0, 12], state: "minecraft:deepslate{axis:y}"},
        {pos: [9, 0, 13], state: "minecraft:deepslate{axis:y}"},
        {pos: [9, 0, 14], state: "minecraft:deepslate{axis:y}"},
        {pos: [9, 0, 15], state: "minecraft:deepslate{axis:y}"},
        {pos: [9, 0, 16], state: "minecraft:deepslate{axis:y}"},
        {pos: [9, 0, 17], state: "minecraft:deepslate_tiles"},
        {pos: [9, 0, 18], state: "minecraft:deepslate_tiles"},
        {pos: [9, 0, 19], state: "minecraft:deepslate_tiles"},
        {pos: [9, 0, 20], state: "minecraft:deepslate_tiles"},
        {pos: [9, 0, 21], state: "minecraft:deepslate_tiles"},
        {pos: [9, 0, 22], state: "minecraft:deepslate{axis:y}"},
        {pos: [9, 0, 23], state: "minecraft:deepslate{axis:y}"},
        {pos: [9, 0, 24], state: "minecraft:deepslate{axis:y}"},
        {pos: [9, 0, 25], state: "minecraft:deepslate{axis:y}"},
        {pos: [9, 0, 26], state: "minecraft:deepslate{axis:y}"},
        {pos: [9, 0, 27], state: "minecraft:deepslate{axis:y}"},
        {pos: [9, 0, 28], state: "minecraft:deepslate{axis:y}"},
        {pos: [9, 0, 29], state: "minecraft:deepslate{axis:y}"},
        {pos: [9, 0, 30], state: "minecraft:deepslate{axis:y}"},
        {pos: [9, 0, 31], state: "minecraft:deepslate{axis:y}"},
        {pos: [9, 0, 32], state: "minecraft:deepslate{axis:y}"},
        {pos: [9, 0, 33], state: "minecraft:deepslate{axis:y}"},
        {pos: [9, 0, 34], state: "minecraft:deepslate{axis:y}"},
        {pos: [9, 0, 35], state: "minecraft:deepslate{axis:y}"},
        {pos: [9, 0, 36], state: "minecraft:deepslate{axis:y}"},
        {pos: [9, 0, 37], state: "minecraft:deepslate{axis:y}"},
        {pos: [9, 0, 38], state: "minecraft:deepslate{axis:y}"},
        {pos: [10, 0, 0], state: "minecraft:deepslate{axis:y}"},
        {pos: [10, 0, 1], state: "minecraft:deepslate{axis:y}"},
        {pos: [10, 0, 2], state: "minecraft:deepslate{axis:y}"},
        {pos: [10, 0, 3], state: "minecraft:deepslate{axis:y}"},
        {pos: [10, 0, 4], state: "minecraft:deepslate{axis:y}"},
        {pos: [10, 0, 5], state: "minecraft:deepslate{axis:y}"},
        {pos: [10, 0, 6], state: "minecraft:deepslate{axis:y}"},
        {pos: [10, 0, 7], state: "minecraft:deepslate{axis:y}"},
        {pos: [10, 0, 8], state: "minecraft:deepslate{axis:y}"},
        {pos: [10, 0, 9], state: "minecraft:deepslate{axis:y}"},
        {pos: [10, 0, 10], state: "minecraft:deepslate{axis:y}"},
        {pos: [10, 0, 11], state: "minecraft:deepslate{axis:y}"},
        {pos: [10, 0, 12], state: "minecraft:deepslate{axis:y}"},
        {pos: [10, 0, 13], state: "minecraft:deepslate{axis:y}"},
        {pos: [10, 0, 14], state: "minecraft:deepslate{axis:y}"},
        {pos: [10, 0, 15], state: "minecraft:deepslate{axis:y}"},
        {pos: [10, 0, 16], state: "minecraft:deepslate{axis:y}"},
        {pos: [10, 0, 17], state: "minecraft:deepslate_tiles"},
        {pos: [10, 0, 18], state: "minecraft:deepslate_tiles"},
        {pos: [10, 0, 19], state: "minecraft:deepslate_tiles"},
        {pos: [10, 0, 20], state: "minecraft:deepslate_tiles"},
        {pos: [10, 0, 21], state: "minecraft:deepslate_tiles"},
        {pos: [10, 0, 22], state: "minecraft:deepslate{axis:y}"},
        {pos: [10, 0, 23], state: "minecraft:deepslate{axis:y}"},
        {pos: [10, 0, 24], state: "minecraft:deepslate{axis:y}"},
        {pos: [10, 0, 25], state: "minecraft:deepslate{axis:y}"},
        {pos: [10, 0, 26], state: "minecraft:deepslate{axis:y}"},
        {pos: [10, 0, 27], state: "minecraft:deepslate{axis:y}"},
        {pos: [10, 0, 28], state: "minecraft:deepslate{axis:y}"},
        {pos: [10, 0, 29], state: "minecraft:deepslate{axis:y}"},
        {pos: [10, 0, 30], state: "minecraft:deepslate{axis:y}"},
        {pos: [10, 0, 31], state: "minecraft:deepslate{axis:y}"},
        {pos: [10, 0, 32], state: "minecraft:deepslate{axis:y}"},
        {pos: [10, 0, 33], state: "minecraft:deepslate{axis:y}"},
        {pos: [10, 0, 34], state: "minecraft:deepslate{axis:y}"},
        {pos: [10, 0, 35], state: "minecraft:deepslate{axis:y}"},
        {pos: [10, 0, 36], state: "minecraft:deepslate{axis:y}"},
        {pos: [10, 0, 37], state: "minecraft:deepslate{axis:y}"},
        {pos: [10, 0, 38], state: "minecraft:deepslate{axis:y}"},
        {pos: [11, 0, 0], state: "minecraft:deepslate{axis:y}"},
        {pos: [11, 0, 1], state: "minecraft:deepslate{axis:y}"},
        {pos: [11, 0, 2], state: "minecraft:deepslate{axis:y}"},
        {pos: [11, 0, 3], state: "minecraft:deepslate{axis:y}"},
        {pos: [11, 0, 4], state: "minecraft:deepslate{axis:y}"},
        {pos: [11, 0, 5], state: "minecraft:deepslate{axis:y}"},
        {pos: [11, 0, 6], state: "minecraft:deepslate{axis:y}"},
        {pos: [11, 0, 7], state: "minecraft:deepslate{axis:y}"},
        {pos: [11, 0, 8], state: "minecraft:polished_basalt{axis:y}"},
        {pos: [11, 0, 9], state: "minecraft:polished_basalt{axis:z}"},
        {pos: [11, 0, 10], state: "minecraft:polished_basalt{axis:z}"},
        {pos: [11, 0, 11], state: "minecraft:polished_basalt{axis:z}"},
        {pos: [11, 0, 12], state: "minecraft:polished_basalt{axis:z}"},
        {pos: [11, 0, 13], state: "minecraft:polished_basalt{axis:z}"},
        {pos: [11, 0, 14], state: "minecraft:polished_basalt{axis:z}"},
        {pos: [11, 0, 15], state: "minecraft:deepslate_tiles"},
        {pos: [11, 0, 16], state: "minecraft:deepslate_tiles"},
        {pos: [11, 0, 17], state: "minecraft:deepslate_tiles"},
        {pos: [11, 0, 18], state: "minecraft:deepslate_tiles"},
        {pos: [11, 0, 19], state: "minecraft:deepslate_tiles"},
        {pos: [11, 0, 20], state: "minecraft:deepslate_tiles"},
        {pos: [11, 0, 21], state: "minecraft:deepslate_tiles"},
        {pos: [11, 0, 22], state: "minecraft:deepslate_tiles"},
        {pos: [11, 0, 23], state: "minecraft:deepslate_tiles"},
        {pos: [11, 0, 24], state: "minecraft:polished_basalt{axis:z}"},
        {pos: [11, 0, 25], state: "minecraft:polished_basalt{axis:z}"},
        {pos: [11, 0, 26], state: "minecraft:polished_basalt{axis:z}"},
        {pos: [11, 0, 27], state: "minecraft:polished_basalt{axis:z}"},
        {pos: [11, 0, 28], state: "minecraft:polished_basalt{axis:z}"},
        {pos: [11, 0, 29], state: "minecraft:polished_basalt{axis:z}"},
        {pos: [11, 0, 30], state: "minecraft:polished_basalt{axis:y}"},
        {pos: [11, 0, 31], state: "minecraft:deepslate{axis:y}"},
        {pos: [11, 0, 32], state: "minecraft:deepslate{axis:y}"},
        {pos: [11, 0, 33], state: "minecraft:deepslate{axis:y}"},
        {pos: [11, 0, 34], state: "minecraft:deepslate{axis:y}"},
        {pos: [11, 0, 35], state: "minecraft:deepslate{axis:y}"},
        {pos: [11, 0, 36], state: "minecraft:deepslate{axis:y}"},
        {pos: [11, 0, 37], state: "minecraft:deepslate{axis:y}"},
        {pos: [11, 0, 38], state: "minecraft:deepslate{axis:y}"},
        {pos: [12, 0, 0], state: "minecraft:deepslate{axis:y}"},
        {pos: [12, 0, 1], state: "minecraft:deepslate{axis:y}"},
        {pos: [12, 0, 2], state: "minecraft:deepslate{axis:y}"},
        {pos: [12, 0, 3], state: "minecraft:deepslate{axis:y}"},
        {pos: [12, 0, 4], state: "minecraft:deepslate{axis:y}"},
        {pos: [12, 0, 5], state: "minecraft:deepslate{axis:y}"},
        {pos: [12, 0, 6], state: "minecraft:deepslate{axis:y}"},
        {pos: [12, 0, 7], state: "minecraft:deepslate{axis:y}"},
        {pos: [12, 0, 8], state: "minecraft:polished_basalt{axis:x}"},
        {pos: [12, 0, 15], state: "minecraft:deepslate_tiles"},
        {pos: [12, 0, 16], state: "minecraft:deepslate_tiles"},
        {pos: [12, 0, 17], state: "minecraft:deepslate_tiles"},
        {pos: [12, 0, 18], state: "minecraft:deepslate_tiles"},
        {pos: [12, 0, 19], state: "minecraft:deepslate_tiles"},
        {pos: [12, 0, 20], state: "minecraft:deepslate_tiles"},
        {pos: [12, 0, 21], state: "minecraft:deepslate_tiles"},
        {pos: [12, 0, 22], state: "minecraft:deepslate_tiles"},
        {pos: [12, 0, 23], state: "minecraft:deepslate_tiles"},
        {pos: [12, 0, 30], state: "minecraft:polished_basalt{axis:x}"},
        {pos: [12, 0, 31], state: "minecraft:deepslate{axis:y}"},
        {pos: [12, 0, 32], state: "minecraft:deepslate{axis:y}"},
        {pos: [12, 0, 33], state: "minecraft:deepslate{axis:y}"},
        {pos: [12, 0, 34], state: "minecraft:deepslate{axis:y}"},
        {pos: [12, 0, 35], state: "minecraft:deepslate{axis:y}"},
        {pos: [12, 0, 36], state: "minecraft:deepslate{axis:y}"},
        {pos: [12, 0, 37], state: "minecraft:deepslate{axis:y}"},
        {pos: [12, 0, 38], state: "minecraft:deepslate{axis:y}"},
        {pos: [13, 0, 0], state: "minecraft:polished_basalt{axis:x}"},
        {pos: [13, 0, 1], state: "minecraft:deepslate{axis:y}"},
        {pos: [13, 0, 2], state: "minecraft:deepslate{axis:y}"},
        {pos: [13, 0, 3], state: "minecraft:deepslate{axis:y}"},
        {pos: [13, 0, 4], state: "minecraft:deepslate{axis:y}"},
        {pos: [13, 0, 5], state: "minecraft:deepslate{axis:y}"},
        {pos: [13, 0, 6], state: "minecraft:deepslate{axis:y}"},
        {pos: [13, 0, 7], state: "minecraft:deepslate{axis:y}"},
        {pos: [13, 0, 8], state: "minecraft:polished_basalt{axis:x}"},
        {pos: [13, 0, 15], state: "minecraft:deepslate_tiles"},
        {pos: [13, 0, 16], state: "minecraft:deepslate_tiles"},
        {pos: [13, 0, 17], state: "minecraft:deepslate_tiles"},
        {pos: [13, 0, 18], state: "minecraft:deepslate_tiles"},
        {pos: [13, 0, 19], state: "minecraft:deepslate_tiles"},
        {pos: [13, 0, 20], state: "minecraft:deepslate_tiles"},
        {pos: [13, 0, 21], state: "minecraft:deepslate_tiles"},
        {pos: [13, 0, 22], state: "minecraft:deepslate_tiles"},
        {pos: [13, 0, 23], state: "minecraft:deepslate_tiles"},
        {pos: [13, 0, 30], state: "minecraft:polished_basalt{axis:x}"},
        {pos: [13, 0, 31], state: "minecraft:deepslate{axis:y}"},
        {pos: [13, 0, 32], state: "minecraft:deepslate{axis:y}"},
        {pos: [13, 0, 33], state: "minecraft:deepslate{axis:y}"},
        {pos: [13, 0, 34], state: "minecraft:deepslate{axis:y}"},
        {pos: [13, 0, 35], state: "minecraft:deepslate{axis:y}"},
        {pos: [13, 0, 36], state: "minecraft:deepslate{axis:y}"},
        {pos: [13, 0, 37], state: "minecraft:deepslate{axis:y}"},
        {pos: [13, 0, 38], state: "minecraft:polished_basalt{axis:x}"},
        {pos: [14, 0, 0], state: "minecraft:polished_basalt{axis:x}"},
        {pos: [14, 0, 1], state: "minecraft:deepslate{axis:y}"},
        {pos: [14, 0, 2], state: "minecraft:deepslate{axis:y}"},
        {pos: [14, 0, 3], state: "minecraft:deepslate{axis:y}"},
        {pos: [14, 0, 4], state: "minecraft:deepslate{axis:y}"},
        {pos: [14, 0, 5], state: "minecraft:deepslate{axis:y}"},
        {pos: [14, 0, 6], state: "minecraft:deepslate{axis:y}"},
        {pos: [14, 0, 7], state: "minecraft:deepslate{axis:y}"},
        {pos: [14, 0, 8], state: "minecraft:polished_basalt{axis:x}"},
        {pos: [14, 0, 15], state: "minecraft:deepslate_tiles"},
        {pos: [14, 0, 16], state: "minecraft:deepslate_tiles"},
        {pos: [14, 0, 17], state: "minecraft:deepslate_tiles"},
        {pos: [14, 0, 18], state: "minecraft:deepslate_tiles"},
        {pos: [14, 0, 19], state: "minecraft:deepslate_tiles"},
        {pos: [14, 0, 20], state: "minecraft:deepslate_tiles"},
        {pos: [14, 0, 21], state: "minecraft:deepslate_tiles"},
        {pos: [14, 0, 22], state: "minecraft:deepslate_tiles"},
        {pos: [14, 0, 23], state: "minecraft:deepslate_tiles"},
        {pos: [14, 0, 30], state: "minecraft:polished_basalt{axis:x}"},
        {pos: [14, 0, 31], state: "minecraft:deepslate{axis:y}"},
        {pos: [14, 0, 32], state: "minecraft:deepslate{axis:y}"},
        {pos: [14, 0, 33], state: "minecraft:deepslate{axis:y}"},
        {pos: [14, 0, 34], state: "minecraft:deepslate{axis:y}"},
        {pos: [14, 0, 35], state: "minecraft:deepslate{axis:y}"},
        {pos: [14, 0, 36], state: "minecraft:deepslate{axis:y}"},
        {pos: [14, 0, 37], state: "minecraft:deepslate{axis:y}"},
        {pos: [14, 0, 38], state: "minecraft:polished_basalt{axis:x}"},
        {pos: [15, 0, 0], state: "minecraft:polished_basalt{axis:x}"},
        {pos: [15, 0, 1], state: "minecraft:deepslate{axis:y}"},
        {pos: [15, 0, 2], state: "minecraft:deepslate{axis:y}"},
        {pos: [15, 0, 3], state: "minecraft:deepslate{axis:y}"},
        {pos: [15, 0, 4], state: "minecraft:deepslate{axis:y}"},
        {pos: [15, 0, 5], state: "minecraft:deepslate{axis:y}"},
        {pos: [15, 0, 6], state: "minecraft:deepslate{axis:y}"},
        {pos: [15, 0, 7], state: "minecraft:deepslate{axis:y}"},
        {pos: [15, 0, 8], state: "minecraft:polished_basalt{axis:x}"},
        {pos: [15, 0, 15], state: "minecraft:deepslate_tiles"},
        {pos: [15, 0, 16], state: "minecraft:deepslate_tiles"},
        {pos: [15, 0, 17], state: "minecraft:deepslate_tiles"},
        {pos: [15, 0, 18], state: "minecraft:deepslate_tiles"},
        {pos: [15, 0, 19], state: "minecraft:deepslate_tiles"},
        {pos: [15, 0, 20], state: "minecraft:deepslate_tiles"},
        {pos: [15, 0, 21], state: "minecraft:deepslate_tiles"},
        {pos: [15, 0, 22], state: "minecraft:deepslate_tiles"},
        {pos: [15, 0, 23], state: "minecraft:deepslate_tiles"},
        {pos: [15, 0, 30], state: "minecraft:polished_basalt{axis:x}"},
        {pos: [15, 0, 31], state: "minecraft:deepslate{axis:y}"},
        {pos: [15, 0, 32], state: "minecraft:deepslate{axis:y}"},
        {pos: [15, 0, 33], state: "minecraft:deepslate{axis:y}"},
        {pos: [15, 0, 34], state: "minecraft:deepslate{axis:y}"},
        {pos: [15, 0, 35], state: "minecraft:deepslate{axis:y}"},
        {pos: [15, 0, 36], state: "minecraft:deepslate{axis:y}"},
        {pos: [15, 0, 37], state: "minecraft:deepslate{axis:y}"},
        {pos: [15, 0, 38], state: "minecraft:polished_basalt{axis:x}"},
        {pos: [16, 0, 0], state: "minecraft:polished_basalt{axis:x}"},
        {pos: [16, 0, 1], state: "minecraft:deepslate{axis:y}"},
        {pos: [16, 0, 2], state: "minecraft:deepslate{axis:y}"},
        {pos: [16, 0, 3], state: "minecraft:deepslate{axis:y}"},
        {pos: [16, 0, 4], state: "minecraft:deepslate{axis:y}"},
        {pos: [16, 0, 5], state: "minecraft:deepslate{axis:y}"},
        {pos: [16, 0, 6], state: "minecraft:deepslate{axis:y}"},
        {pos: [16, 0, 7], state: "minecraft:deepslate{axis:y}"},
        {pos: [16, 0, 8], state: "minecraft:polished_basalt{axis:x}"},
        {pos: [16, 0, 15], state: "minecraft:deepslate_tiles"},
        {pos: [16, 0, 16], state: "minecraft:deepslate_tiles"},
        {pos: [16, 0, 17], state: "minecraft:deepslate_tiles"},
        {pos: [16, 0, 18], state: "minecraft:deepslate_tiles"},
        {pos: [16, 0, 19], state: "minecraft:deepslate_tiles"},
        {pos: [16, 0, 20], state: "minecraft:deepslate_tiles"},
        {pos: [16, 0, 21], state: "minecraft:deepslate_tiles"},
        {pos: [16, 0, 22], state: "minecraft:deepslate_tiles"},
        {pos: [16, 0, 23], state: "minecraft:deepslate_tiles"},
        {pos: [16, 0, 30], state: "minecraft:polished_basalt{axis:x}"},
        {pos: [16, 0, 31], state: "minecraft:deepslate{axis:y}"},
        {pos: [16, 0, 32], state: "minecraft:deepslate{axis:y}"},
        {pos: [16, 0, 33], state: "minecraft:deepslate{axis:y}"},
        {pos: [16, 0, 34], state: "minecraft:deepslate{axis:y}"},
        {pos: [16, 0, 35], state: "minecraft:deepslate{axis:y}"},
        {pos: [16, 0, 36], state: "minecraft:deepslate{axis:y}"},
        {pos: [16, 0, 37], state: "minecraft:deepslate{axis:y}"},
        {pos: [16, 0, 38], state: "minecraft:polished_basalt{axis:x}"},
        {pos: [17, 0, 0], state: "minecraft:deepslate{axis:y}"},
        {pos: [17, 0, 1], state: "minecraft:deepslate{axis:y}"},
        {pos: [17, 0, 2], state: "minecraft:deepslate{axis:y}"},
        {pos: [17, 0, 3], state: "minecraft:deepslate{axis:y}"},
        {pos: [17, 0, 4], state: "minecraft:deepslate{axis:y}"},
        {pos: [17, 0, 5], state: "minecraft:deepslate{axis:y}"},
        {pos: [17, 0, 6], state: "minecraft:deepslate{axis:y}"},
        {pos: [17, 0, 7], state: "minecraft:deepslate{axis:y}"},
        {pos: [17, 0, 8], state: "minecraft:polished_basalt{axis:x}"},
        {pos: [17, 0, 15], state: "minecraft:deepslate_tiles"},
        {pos: [17, 0, 16], state: "minecraft:deepslate_tiles"},
        {pos: [17, 0, 17], state: "minecraft:deepslate_tiles"},
        {pos: [17, 0, 18], state: "minecraft:deepslate_tiles"},
        {pos: [17, 0, 19], state: "minecraft:deepslate_tiles"},
        {pos: [17, 0, 20], state: "minecraft:deepslate_tiles"},
        {pos: [17, 0, 21], state: "minecraft:deepslate_tiles"},
        {pos: [17, 0, 22], state: "minecraft:deepslate_tiles"},
        {pos: [17, 0, 23], state: "minecraft:deepslate_tiles"},
        {pos: [17, 0, 30], state: "minecraft:polished_basalt{axis:x}"},
        {pos: [17, 0, 31], state: "minecraft:deepslate{axis:y}"},
        {pos: [17, 0, 32], state: "minecraft:deepslate{axis:y}"},
        {pos: [17, 0, 33], state: "minecraft:deepslate{axis:y}"},
        {pos: [17, 0, 34], state: "minecraft:deepslate{axis:y}"},
        {pos: [17, 0, 35], state: "minecraft:deepslate{axis:y}"},
        {pos: [17, 0, 36], state: "minecraft:deepslate{axis:y}"},
        {pos: [17, 0, 37], state: "minecraft:deepslate{axis:y}"},
        {pos: [17, 0, 38], state: "minecraft:deepslate{axis:y}"},
        {pos: [18, 0, 0], state: "minecraft:deepslate{axis:y}"},
        {pos: [18, 0, 1], state: "minecraft:deepslate{axis:y}"},
        {pos: [18, 0, 2], state: "minecraft:deepslate{axis:y}"},
        {pos: [18, 0, 3], state: "minecraft:deepslate{axis:y}"},
        {pos: [18, 0, 4], state: "minecraft:deepslate{axis:y}"},
        {pos: [18, 0, 5], state: "minecraft:deepslate{axis:y}"},
        {pos: [18, 0, 6], state: "minecraft:deepslate{axis:y}"},
        {pos: [18, 0, 7], state: "minecraft:deepslate{axis:y}"},
        {pos: [18, 0, 8], state: "minecraft:polished_basalt{axis:y}"},
        {pos: [18, 0, 9], state: "minecraft:polished_basalt{axis:z}"},
        {pos: [18, 0, 10], state: "minecraft:polished_basalt{axis:z}"},
        {pos: [18, 0, 11], state: "minecraft:polished_basalt{axis:z}"},
        {pos: [18, 0, 12], state: "minecraft:polished_basalt{axis:z}"},
        {pos: [18, 0, 13], state: "minecraft:polished_basalt{axis:z}"},
        {pos: [18, 0, 14], state: "minecraft:polished_basalt{axis:z}"},
        {pos: [18, 0, 15], state: "minecraft:deepslate_tiles"},
        {pos: [18, 0, 16], state: "minecraft:deepslate_tiles"},
        {pos: [18, 0, 17], state: "minecraft:deepslate_tiles"},
        {pos: [18, 0, 18], state: "minecraft:deepslate_tiles"},
        {pos: [18, 0, 19], state: "minecraft:deepslate_tiles"},
        {pos: [18, 0, 20], state: "minecraft:deepslate_tiles"},
        {pos: [18, 0, 21], state: "minecraft:deepslate_tiles"},
        {pos: [18, 0, 22], state: "minecraft:deepslate_tiles"},
        {pos: [18, 0, 23], state: "minecraft:deepslate_tiles"},
        {pos: [18, 0, 24], state: "minecraft:polished_basalt{axis:z}"},
        {pos: [18, 0, 25], state: "minecraft:polished_basalt{axis:z}"},
        {pos: [18, 0, 26], state: "minecraft:polished_basalt{axis:z}"},
        {pos: [18, 0, 27], state: "minecraft:polished_basalt{axis:z}"},
        {pos: [18, 0, 28], state: "minecraft:polished_basalt{axis:z}"},
        {pos: [18, 0, 29], state: "minecraft:polished_basalt{axis:z}"},
        {pos: [18, 0, 30], state: "minecraft:polished_basalt{axis:y}"},
        {pos: [18, 0, 31], state: "minecraft:deepslate{axis:y}"},
        {pos: [18, 0, 32], state: "minecraft:deepslate{axis:y}"},
        {pos: [18, 0, 33], state: "minecraft:deepslate{axis:y}"},
        {pos: [18, 0, 34], state: "minecraft:deepslate{axis:y}"},
        {pos: [18, 0, 35], state: "minecraft:deepslate{axis:y}"},
        {pos: [18, 0, 36], state: "minecraft:deepslate{axis:y}"},
        {pos: [18, 0, 37], state: "minecraft:deepslate{axis:y}"},
        {pos: [18, 0, 38], state: "minecraft:deepslate{axis:y}"},
        {pos: [19, 0, 1], state: "minecraft:deepslate{axis:y}"},
        {pos: [19, 0, 2], state: "minecraft:deepslate{axis:y}"},
        {pos: [19, 0, 3], state: "minecraft:deepslate{axis:y}"},
        {pos: [19, 0, 4], state: "minecraft:deepslate{axis:y}"},
        {pos: [19, 0, 5], state: "minecraft:deepslate{axis:y}"},
        {pos: [19, 0, 6], state: "minecraft:deepslate{axis:y}"},
        {pos: [19, 0, 7], state: "minecraft:deepslate{axis:y}"},
        {pos: [19, 0, 8], state: "minecraft:deepslate{axis:y}"},
        {pos: [19, 0, 9], state: "minecraft:deepslate{axis:y}"},
        {pos: [19, 0, 10], state: "minecraft:deepslate{axis:y}"},
        {pos: [19, 0, 11], state: "minecraft:deepslate{axis:y}"},
        {pos: [19, 0, 12], state: "minecraft:deepslate{axis:y}"},
        {pos: [19, 0, 13], state: "minecraft:deepslate{axis:y}"},
        {pos: [19, 0, 14], state: "minecraft:deepslate{axis:y}"},
        {pos: [19, 0, 15], state: "minecraft:deepslate{axis:y}"},
        {pos: [19, 0, 16], state: "minecraft:deepslate{axis:y}"},
        {pos: [19, 0, 17], state: "minecraft:deepslate_tiles"},
        {pos: [19, 0, 18], state: "minecraft:deepslate_tiles"},
        {pos: [19, 0, 19], state: "minecraft:deepslate_tiles"},
        {pos: [19, 0, 20], state: "minecraft:deepslate_tiles"},
        {pos: [19, 0, 21], state: "minecraft:deepslate_tiles"},
        {pos: [19, 0, 22], state: "minecraft:deepslate{axis:y}"},
        {pos: [19, 0, 23], state: "minecraft:deepslate{axis:y}"},
        {pos: [19, 0, 24], state: "minecraft:deepslate{axis:y}"},
        {pos: [19, 0, 25], state: "minecraft:deepslate{axis:y}"},
        {pos: [19, 0, 26], state: "minecraft:deepslate{axis:y}"},
        {pos: [19, 0, 27], state: "minecraft:deepslate{axis:y}"},
        {pos: [19, 0, 28], state: "minecraft:deepslate{axis:y}"},
        {pos: [19, 0, 29], state: "minecraft:deepslate{axis:y}"},
        {pos: [19, 0, 30], state: "minecraft:deepslate{axis:y}"},
        {pos: [19, 0, 31], state: "minecraft:deepslate{axis:y}"},
        {pos: [19, 0, 32], state: "minecraft:deepslate{axis:y}"},
        {pos: [19, 0, 33], state: "minecraft:deepslate{axis:y}"},
        {pos: [19, 0, 34], state: "minecraft:deepslate{axis:y}"},
        {pos: [19, 0, 35], state: "minecraft:deepslate{axis:y}"},
        {pos: [19, 0, 36], state: "minecraft:deepslate{axis:y}"},
        {pos: [19, 0, 37], state: "minecraft:deepslate{axis:y}"},
        {pos: [20, 0, 0], state: "minecraft:deepslate{axis:y}"},
        {pos: [20, 0, 1], state: "minecraft:deepslate{axis:y}"},
        {pos: [20, 0, 2], state: "minecraft:deepslate{axis:y}"},
        {pos: [20, 0, 3], state: "minecraft:deepslate{axis:y}"},
        {pos: [20, 0, 4], state: "minecraft:deepslate{axis:y}"},
        {pos: [20, 0, 5], state: "minecraft:deepslate{axis:y}"},
        {pos: [20, 0, 6], state: "minecraft:deepslate{axis:y}"},
        {pos: [20, 0, 7], state: "minecraft:deepslate{axis:y}"},
        {pos: [20, 0, 8], state: "minecraft:deepslate{axis:y}"},
        {pos: [20, 0, 9], state: "minecraft:deepslate{axis:y}"},
        {pos: [20, 0, 10], state: "minecraft:deepslate{axis:y}"},
        {pos: [20, 0, 11], state: "minecraft:deepslate{axis:y}"},
        {pos: [20, 0, 12], state: "minecraft:deepslate{axis:y}"},
        {pos: [20, 0, 13], state: "minecraft:deepslate{axis:y}"},
        {pos: [20, 0, 14], state: "minecraft:deepslate{axis:y}"},
        {pos: [20, 0, 15], state: "minecraft:deepslate{axis:y}"},
        {pos: [20, 0, 16], state: "minecraft:deepslate{axis:y}"},
        {pos: [20, 0, 17], state: "minecraft:deepslate_tiles"},
        {pos: [20, 0, 18], state: "minecraft:deepslate_tiles"},
        {pos: [20, 0, 19], state: "minecraft:deepslate_tiles"},
        {pos: [20, 0, 20], state: "minecraft:deepslate_tiles"},
        {pos: [20, 0, 21], state: "minecraft:deepslate_tiles"},
        {pos: [20, 0, 22], state: "minecraft:deepslate{axis:y}"},
        {pos: [20, 0, 23], state: "minecraft:deepslate{axis:y}"},
        {pos: [20, 0, 24], state: "minecraft:deepslate{axis:y}"},
        {pos: [20, 0, 25], state: "minecraft:deepslate{axis:y}"},
        {pos: [20, 0, 26], state: "minecraft:deepslate{axis:y}"},
        {pos: [20, 0, 27], state: "minecraft:deepslate{axis:y}"},
        {pos: [20, 0, 28], state: "minecraft:deepslate{axis:y}"},
        {pos: [20, 0, 29], state: "minecraft:deepslate{axis:y}"},
        {pos: [20, 0, 30], state: "minecraft:deepslate{axis:y}"},
        {pos: [20, 0, 31], state: "minecraft:deepslate{axis:y}"},
        {pos: [20, 0, 32], state: "minecraft:deepslate{axis:y}"},
        {pos: [20, 0, 33], state: "minecraft:deepslate{axis:y}"},
        {pos: [20, 0, 34], state: "minecraft:deepslate{axis:y}"},
        {pos: [20, 0, 35], state: "minecraft:deepslate{axis:y}"},
        {pos: [20, 0, 36], state: "minecraft:deepslate{axis:y}"},
        {pos: [20, 0, 37], state: "minecraft:deepslate{axis:y}"},
        {pos: [20, 0, 38], state: "minecraft:deepslate{axis:y}"},
        {pos: [21, 0, 0], state: "minecraft:deepslate{axis:y}"},
        {pos: [21, 0, 1], state: "minecraft:deepslate{axis:y}"},
        {pos: [21, 0, 2], state: "minecraft:deepslate{axis:y}"},
        {pos: [21, 0, 3], state: "minecraft:deepslate{axis:y}"},
        {pos: [21, 0, 4], state: "minecraft:deepslate{axis:y}"},
        {pos: [21, 0, 5], state: "minecraft:deepslate{axis:y}"},
        {pos: [21, 0, 6], state: "minecraft:deepslate{axis:y}"},
        {pos: [21, 0, 7], state: "minecraft:deepslate{axis:y}"},
        {pos: [21, 0, 8], state: "minecraft:polished_basalt{axis:y}"},
        {pos: [21, 0, 9], state: "minecraft:polished_basalt{axis:z}"},
        {pos: [21, 0, 10], state: "minecraft:polished_basalt{axis:z}"},
        {pos: [21, 0, 11], state: "minecraft:polished_basalt{axis:z}"},
        {pos: [21, 0, 12], state: "minecraft:polished_basalt{axis:z}"},
        {pos: [21, 0, 13], state: "minecraft:polished_basalt{axis:z}"},
        {pos: [21, 0, 14], state: "minecraft:polished_basalt{axis:z}"},
        {pos: [21, 0, 15], state: "minecraft:deepslate_tiles"},
        {pos: [21, 0, 16], state: "minecraft:deepslate_tiles"},
        {pos: [21, 0, 17], state: "minecraft:deepslate_tiles"},
        {pos: [21, 0, 18], state: "minecraft:deepslate_tiles"},
        {pos: [21, 0, 19], state: "minecraft:deepslate_tiles"},
        {pos: [21, 0, 20], state: "minecraft:deepslate_tiles"},
        {pos: [21, 0, 21], state: "minecraft:deepslate_tiles"},
        {pos: [21, 0, 22], state: "minecraft:deepslate_tiles"},
        {pos: [21, 0, 23], state: "minecraft:deepslate_tiles"},
        {pos: [21, 0, 24], state: "minecraft:polished_basalt{axis:z}"},
        {pos: [21, 0, 25], state: "minecraft:polished_basalt{axis:z}"},
        {pos: [21, 0, 26], state: "minecraft:polished_basalt{axis:z}"},
        {pos: [21, 0, 27], state: "minecraft:polished_basalt{axis:z}"},
        {pos: [21, 0, 28], state: "minecraft:polished_basalt{axis:z}"},
        {pos: [21, 0, 29], state: "minecraft:polished_basalt{axis:z}"},
        {pos: [21, 0, 30], state: "minecraft:polished_basalt{axis:y}"},
        {pos: [21, 0, 31], state: "minecraft:deepslate{axis:y}"},
        {pos: [21, 0, 32], state: "minecraft:deepslate{axis:y}"},
        {pos: [21, 0, 33], state: "minecraft:deepslate{axis:y}"},
        {pos: [21, 0, 34], state: "minecraft:deepslate{axis:y}"},
        {pos: [21, 0, 35], state: "minecraft:deepslate{axis:y}"},
        {pos: [21, 0, 36], state: "minecraft:deepslate{axis:y}"},
        {pos: [21, 0, 37], state: "minecraft:deepslate{axis:y}"},
        {pos: [21, 0, 38], state: "minecraft:deepslate{axis:y}"},
        {pos: [22, 0, 0], state: "minecraft:deepslate{axis:y}"},
        {pos: [22, 0, 1], state: "minecraft:deepslate{axis:y}"},
        {pos: [22, 0, 2], state: "minecraft:deepslate{axis:y}"},
        {pos: [22, 0, 3], state: "minecraft:deepslate{axis:y}"},
        {pos: [22, 0, 4], state: "minecraft:deepslate{axis:y}"},
        {pos: [22, 0, 5], state: "minecraft:deepslate{axis:y}"},
        {pos: [22, 0, 6], state: "minecraft:deepslate{axis:y}"},
        {pos: [22, 0, 7], state: "minecraft:deepslate{axis:y}"},
        {pos: [22, 0, 8], state: "minecraft:polished_basalt{axis:x}"},
        {pos: [22, 0, 15], state: "minecraft:deepslate_tiles"},
        {pos: [22, 0, 16], state: "minecraft:deepslate_tiles"},
        {pos: [22, 0, 17], state: "minecraft:deepslate_tiles"},
        {pos: [22, 0, 18], state: "minecraft:deepslate_tiles"},
        {pos: [22, 0, 19], state: "minecraft:deepslate_tiles"},
        {pos: [22, 0, 20], state: "minecraft:deepslate_tiles"},
        {pos: [22, 0, 21], state: "minecraft:deepslate_tiles"},
        {pos: [22, 0, 22], state: "minecraft:deepslate_tiles"},
        {pos: [22, 0, 23], state: "minecraft:deepslate_tiles"},
        {pos: [22, 0, 30], state: "minecraft:polished_basalt{axis:x}"},
        {pos: [22, 0, 31], state: "minecraft:deepslate{axis:y}"},
        {pos: [22, 0, 32], state: "minecraft:deepslate{axis:y}"},
        {pos: [22, 0, 33], state: "minecraft:deepslate{axis:y}"},
        {pos: [22, 0, 34], state: "minecraft:deepslate{axis:y}"},
        {pos: [22, 0, 35], state: "minecraft:deepslate{axis:y}"},
        {pos: [22, 0, 36], state: "minecraft:deepslate{axis:y}"},
        {pos: [22, 0, 37], state: "minecraft:deepslate{axis:y}"},
        {pos: [22, 0, 38], state: "minecraft:deepslate{axis:y}"},
        {pos: [23, 0, 0], state: "minecraft:polished_basalt{axis:x}"},
        {pos: [23, 0, 1], state: "minecraft:deepslate{axis:y}"},
        {pos: [23, 0, 2], state: "minecraft:deepslate{axis:y}"},
        {pos: [23, 0, 3], state: "minecraft:deepslate{axis:y}"},
        {pos: [23, 0, 4], state: "minecraft:deepslate{axis:y}"},
        {pos: [23, 0, 5], state: "minecraft:deepslate{axis:y}"},
        {pos: [23, 0, 6], state: "minecraft:deepslate{axis:y}"},
        {pos: [23, 0, 7], state: "minecraft:deepslate{axis:y}"},
        {pos: [23, 0, 8], state: "minecraft:polished_basalt{axis:x}"},
        {pos: [23, 0, 15], state: "minecraft:deepslate_tiles"},
        {pos: [23, 0, 16], state: "minecraft:deepslate_tiles"},
        {pos: [23, 0, 17], state: "minecraft:deepslate_tiles"},
        {pos: [23, 0, 18], state: "minecraft:deepslate_tiles"},
        {pos: [23, 0, 19], state: "minecraft:deepslate_tiles"},
        {pos: [23, 0, 20], state: "minecraft:deepslate_tiles"},
        {pos: [23, 0, 21], state: "minecraft:deepslate_tiles"},
        {pos: [23, 0, 22], state: "minecraft:deepslate_tiles"},
        {pos: [23, 0, 23], state: "minecraft:deepslate_tiles"},
        {pos: [23, 0, 30], state: "minecraft:polished_basalt{axis:x}"},
        {pos: [23, 0, 31], state: "minecraft:deepslate{axis:y}"},
        {pos: [23, 0, 32], state: "minecraft:deepslate{axis:y}"},
        {pos: [23, 0, 33], state: "minecraft:deepslate{axis:y}"},
        {pos: [23, 0, 34], state: "minecraft:deepslate{axis:y}"},
        {pos: [23, 0, 35], state: "minecraft:deepslate{axis:y}"},
        {pos: [23, 0, 36], state: "minecraft:deepslate{axis:y}"},
        {pos: [23, 0, 37], state: "minecraft:deepslate{axis:y}"},
        {pos: [23, 0, 38], state: "minecraft:polished_basalt{axis:x}"},
        {pos: [24, 0, 0], state: "minecraft:polished_basalt{axis:x}"},
        {pos: [24, 0, 1], state: "minecraft:deepslate{axis:y}"},
        {pos: [24, 0, 2], state: "minecraft:deepslate{axis:y}"},
        {pos: [24, 0, 3], state: "minecraft:deepslate{axis:y}"},
        {pos: [24, 0, 4], state: "minecraft:deepslate{axis:y}"},
        {pos: [24, 0, 5], state: "minecraft:deepslate{axis:y}"},
        {pos: [24, 0, 6], state: "minecraft:deepslate{axis:y}"},
        {pos: [24, 0, 7], state: "minecraft:deepslate{axis:y}"},
        {pos: [24, 0, 8], state: "minecraft:polished_basalt{axis:x}"},
        {pos: [24, 0, 17], state: "minecraft:deepslate_tiles"},
        {pos: [24, 0, 18], state: "minecraft:deepslate_tiles"},
        {pos: [24, 0, 19], state: "minecraft:deepslate_tiles"},
        {pos: [24, 0, 20], state: "minecraft:deepslate_tiles"},
        {pos: [24, 0, 21], state: "minecraft:deepslate_tiles"},
        {pos: [24, 0, 30], state: "minecraft:polished_basalt{axis:x}"},
        {pos: [24, 0, 31], state: "minecraft:deepslate{axis:y}"},
        {pos: [24, 0, 32], state: "minecraft:deepslate{axis:y}"},
        {pos: [24, 0, 33], state: "minecraft:deepslate{axis:y}"},
        {pos: [24, 0, 34], state: "minecraft:deepslate{axis:y}"},
        {pos: [24, 0, 35], state: "minecraft:deepslate{axis:y}"},
        {pos: [24, 0, 36], state: "minecraft:deepslate{axis:y}"},
        {pos: [24, 0, 37], state: "minecraft:deepslate{axis:y}"},
        {pos: [24, 0, 38], state: "minecraft:polished_basalt{axis:x}"},
        {pos: [25, 0, 0], state: "minecraft:polished_basalt{axis:y}"},
        {pos: [25, 0, 1], state: "minecraft:polished_basalt{axis:z}"},
        {pos: [25, 0, 2], state: "minecraft:polished_basalt{axis:z}"},
        {pos: [25, 0, 3], state: "minecraft:polished_basalt{axis:z}"},
        {pos: [25, 0, 4], state: "minecraft:polished_basalt{axis:z}"},
        {pos: [25, 0, 5], state: "minecraft:polished_basalt{axis:z}"},
        {pos: [25, 0, 6], state: "minecraft:polished_basalt{axis:z}"},
        {pos: [25, 0, 7], state: "minecraft:polished_basalt{axis:z}"},
        {pos: [25, 0, 8], state: "minecraft:polished_basalt{axis:y}"},
        {pos: [25, 0, 17], state: "minecraft:deepslate_tiles"},
        {pos: [25, 0, 18], state: "minecraft:deepslate_tiles"},
        {pos: [25, 0, 19], state: "minecraft:deepslate_tiles"},
        {pos: [25, 0, 20], state: "minecraft:deepslate_tiles"},
        {pos: [25, 0, 21], state: "minecraft:deepslate_tiles"},
        {pos: [25, 0, 30], state: "minecraft:polished_basalt{axis:y}"},
        {pos: [25, 0, 31], state: "minecraft:polished_basalt{axis:z}"},
        {pos: [25, 0, 32], state: "minecraft:polished_basalt{axis:z}"},
        {pos: [25, 0, 33], state: "minecraft:polished_basalt{axis:z}"},
        {pos: [25, 0, 34], state: "minecraft:polished_basalt{axis:z}"},
        {pos: [25, 0, 35], state: "minecraft:polished_basalt{axis:z}"},
        {pos: [25, 0, 36], state: "minecraft:polished_basalt{axis:z}"},
        {pos: [25, 0, 37], state: "minecraft:polished_basalt{axis:z}"},
        {pos: [25, 0, 38], state: "minecraft:polished_basalt{axis:y}"},
        {pos: [26, 0, 17], state: "minecraft:deepslate_tiles"},
        {pos: [26, 0, 18], state: "minecraft:deepslate_tiles"},
        {pos: [26, 0, 19], state: "minecraft:deepslate_tiles"},
        {pos: [26, 0, 20], state: "minecraft:deepslate_tiles"},
        {pos: [26, 0, 21], state: "minecraft:deepslate_tiles"},
        {pos: [27, 0, 17], state: "minecraft:deepslate_tiles"},
        {pos: [27, 0, 18], state: "minecraft:deepslate_tiles"},
        {pos: [27, 0, 19], state: "minecraft:deepslate_tiles"},
        {pos: [27, 0, 20], state: "minecraft:deepslate_tiles"},
        {pos: [27, 0, 21], state: "minecraft:deepslate_tiles"},
        {pos: [28, 0, 17], state: "minecraft:deepslate_tiles"},
        {pos: [28, 0, 18], state: "minecraft:deepslate_tiles"},
        {pos: [28, 0, 19], state: "minecraft:deepslate_tiles"},
        {pos: [28, 0, 20], state: "minecraft:deepslate_tiles"},
        {pos: [28, 0, 21], state: "minecraft:deepslate_tiles"},
        {pos: [29, 0, 17], state: "minecraft:deepslate_tiles"},
        {pos: [29, 0, 18], state: "minecraft:deepslate_tiles"},
        {pos: [29, 0, 20], state: "minecraft:deepslate_tiles"},
        {pos: [29, 0, 21], state: "minecraft:deepslate_tiles"},
        {pos: [0, 1, 0], state: "minecraft:deepslate_tiles"},
        {pos: [0, 1, 1], state: "minecraft:deepslate{axis:y}"},
        {pos: [0, 1, 2], state: "minecraft:deepslate{axis:y}"},
        {pos: [0, 1, 3], state: "minecraft:deepslate{axis:y}"},
        {pos: [0, 1, 4], state: "minecraft:deepslate{axis:y}"},
        {pos: [0, 1, 18], state: "minecraft:deepslate_tiles"},
        {pos: [0, 1, 19], state: "minecraft:deepslate_tiles"},
        {pos: [0, 1, 20], state: "minecraft:deepslate_tiles"},
        {pos: [0, 1, 34], state: "minecraft:deepslate{axis:y}"},
        {pos: [0, 1, 35], state: "minecraft:deepslate{axis:y}"},
        {pos: [0, 1, 36], state: "minecraft:deepslate{axis:y}"},
        {pos: [0, 1, 37], state: "minecraft:deepslate{axis:y}"},
        {pos: [0, 1, 38], state: "minecraft:deepslate_tiles"},
        {pos: [1, 1, 0], state: "minecraft:deepslate_tiles"},
        {pos: [1, 1, 1], state: "minecraft:deepslate{axis:y}"},
        {pos: [1, 1, 2], state: "minecraft:deepslate{axis:y}"},
        {pos: [1, 1, 3], state: "minecraft:deepslate{axis:y}"},
        {pos: [1, 1, 4], state: "minecraft:deepslate{axis:y}"},
        {pos: [1, 1, 15], state: "minecraft:deepslate_tiles"},
        {pos: [1, 1, 16], state: "minecraft:deepslate_tiles"},
        {pos: [1, 1, 17], state: "minecraft:smooth_basalt"},
        {pos: [1, 1, 18], state: "minecraft:deepslate_tiles"},
        {pos: [1, 1, 19], state: "minecraft:deepslate_tiles"},
        {pos: [1, 1, 20], state: "minecraft:deepslate_tiles"},
        {pos: [1, 1, 21], state: "minecraft:smooth_basalt"},
        {pos: [1, 1, 22], state: "minecraft:deepslate_tiles"},
        {pos: [1, 1, 23], state: "minecraft:deepslate_tiles"},
        {pos: [1, 1, 34], state: "minecraft:deepslate{axis:y}"},
        {pos: [1, 1, 35], state: "minecraft:deepslate{axis:y}"},
        {pos: [1, 1, 36], state: "minecraft:deepslate{axis:y}"},
        {pos: [1, 1, 37], state: "minecraft:deepslate{axis:y}"},
        {pos: [1, 1, 38], state: "minecraft:deepslate_tiles"},
        {pos: [2, 1, 15], state: "minecraft:deepslate_tiles"},
        {pos: [2, 1, 16], state: "minecraft:deepslate_tiles"},
        {pos: [2, 1, 17], state: "minecraft:polished_deepslate"},
        {pos: [2, 1, 18], state: "minecraft:deepslate_tiles"},
        {pos: [2, 1, 19], state: "minecraft:deepslate_tiles"},
        {pos: [2, 1, 20], state: "minecraft:deepslate_tiles"},
        {pos: [2, 1, 21], state: "minecraft:polished_deepslate"},
        {pos: [2, 1, 22], state: "minecraft:deepslate_tiles"},
        {pos: [2, 1, 23], state: "minecraft:deepslate_tiles"},
        {pos: [3, 1, 15], state: "minecraft:deepslate_tiles"},
        {pos: [3, 1, 16], state: "minecraft:deepslate_tiles"},
        {pos: [3, 1, 17], state: "minecraft:smooth_basalt"},
        {pos: [3, 1, 18], state: "minecraft:deepslate_tiles"},
        {pos: [3, 1, 19], state: "minecraft:deepslate_tiles"},
        {pos: [3, 1, 20], state: "minecraft:deepslate_tiles"},
        {pos: [3, 1, 21], state: "minecraft:smooth_basalt"},
        {pos: [3, 1, 22], state: "minecraft:deepslate_tiles"},
        {pos: [3, 1, 23], state: "minecraft:deepslate_tiles"},
        {pos: [4, 1, 18], state: "minecraft:deepslate_tiles"},
        {pos: [4, 1, 19], state: "minecraft:deepslate_tiles"},
        {pos: [4, 1, 20], state: "minecraft:deepslate_tiles"},
        {pos: [5, 1, 18], state: "minecraft:deepslate_tiles"},
        {pos: [5, 1, 19], state: "minecraft:deepslate_tiles"},
        {pos: [5, 1, 20], state: "minecraft:deepslate_tiles"},
        {pos: [6, 1, 15], state: "minecraft:deepslate_tiles"},
        {pos: [6, 1, 16], state: "minecraft:deepslate_tiles"},
        {pos: [6, 1, 17], state: "minecraft:smooth_basalt"},
        {pos: [6, 1, 18], state: "minecraft:deepslate_tiles"},
        {pos: [6, 1, 19], state: "minecraft:deepslate_tiles"},
        {pos: [6, 1, 20], state: "minecraft:deepslate_tiles"},
        {pos: [6, 1, 21], state: "minecraft:smooth_basalt"},
        {pos: [6, 1, 22], state: "minecraft:deepslate_tiles"},
        {pos: [6, 1, 23], state: "minecraft:deepslate_tiles"},
        {pos: [7, 1, 15], state: "minecraft:deepslate_tiles"},
        {pos: [7, 1, 16], state: "minecraft:deepslate_tiles"},
        {pos: [7, 1, 17], state: "minecraft:polished_deepslate"},
        {pos: [7, 1, 18], state: "minecraft:deepslate_tiles"},
        {pos: [7, 1, 19], state: "minecraft:deepslate_tiles"},
        {pos: [7, 1, 20], state: "minecraft:deepslate_tiles"},
        {pos: [7, 1, 21], state: "minecraft:polished_deepslate"},
        {pos: [7, 1, 22], state: "minecraft:deepslate_tiles"},
        {pos: [7, 1, 23], state: "minecraft:deepslate_tiles"},
        {pos: [8, 1, 0], state: "minecraft:deepslate_tiles"},
        {pos: [8, 1, 1], state: "minecraft:deepslate{axis:y}"},
        {pos: [8, 1, 2], state: "minecraft:deepslate{axis:y}"},
        {pos: [8, 1, 3], state: "minecraft:deepslate{axis:y}"},
        {pos: [8, 1, 15], state: "minecraft:deepslate_tiles"},
        {pos: [8, 1, 16], state: "minecraft:deepslate_tiles"},
        {pos: [8, 1, 17], state: "minecraft:smooth_basalt"},
        {pos: [8, 1, 18], state: "minecraft:deepslate_tiles"},
        {pos: [8, 1, 19], state: "minecraft:deepslate_tiles"},
        {pos: [8, 1, 20], state: "minecraft:deepslate_tiles"},
        {pos: [8, 1, 21], state: "minecraft:smooth_basalt"},
        {pos: [8, 1, 22], state: "minecraft:deepslate_tiles"},
        {pos: [8, 1, 23], state: "minecraft:deepslate_tiles"},
        {pos: [8, 1, 34], state: "minecraft:deepslate{axis:y}"},
        {pos: [8, 1, 35], state: "minecraft:deepslate{axis:y}"},
        {pos: [8, 1, 36], state: "minecraft:deepslate{axis:y}"},
        {pos: [8, 1, 37], state: "minecraft:deepslate{axis:y}"},
        {pos: [8, 1, 38], state: "minecraft:deepslate_tiles"},
        {pos: [9, 1, 0], state: "minecraft:deepslate_tiles"},
        {pos: [9, 1, 1], state: "minecraft:deepslate{axis:y}"},
        {pos: [9, 1, 2], state: "minecraft:deepslate{axis:y}"},
        {pos: [9, 1, 3], state: "minecraft:deepslate{axis:y}"},
        {pos: [9, 1, 4], state: "minecraft:deepslate{axis:y}"},
        {pos: [9, 1, 18], state: "minecraft:deepslate_tiles"},
        {pos: [9, 1, 19], state: "minecraft:deepslate_tiles"},
        {pos: [9, 1, 20], state: "minecraft:deepslate_tiles"},
        {pos: [9, 1, 34], state: "minecraft:deepslate{axis:y}"},
        {pos: [9, 1, 35], state: "minecraft:deepslate{axis:y}"},
        {pos: [9, 1, 36], state: "minecraft:deepslate{axis:y}"},
        {pos: [9, 1, 37], state: "minecraft:deepslate{axis:y}"},
        {pos: [9, 1, 38], state: "minecraft:deepslate_tiles"},
        {pos: [10, 1, 0], state: "minecraft:deepslate_tiles"},
        {pos: [10, 1, 1], state: "minecraft:deepslate{axis:y}"},
        {pos: [10, 1, 2], state: "minecraft:deepslate{axis:y}"},
        {pos: [10, 1, 3], state: "minecraft:deepslate{axis:y}"},
        {pos: [10, 1, 4], state: "minecraft:deepslate{axis:y}"},
        {pos: [10, 1, 18], state: "minecraft:deepslate_tiles"},
        {pos: [10, 1, 19], state: "minecraft:deepslate_tiles"},
        {pos: [10, 1, 20], state: "minecraft:deepslate_tiles"},
        {pos: [10, 1, 34], state: "minecraft:deepslate{axis:y}"},
        {pos: [10, 1, 35], state: "minecraft:deepslate{axis:y}"},
        {pos: [10, 1, 36], state: "minecraft:deepslate{axis:y}"},
        {pos: [10, 1, 37], state: "minecraft:deepslate{axis:y}"},
        {pos: [10, 1, 38], state: "minecraft:deepslate_tiles"},
        {pos: [11, 1, 0], state: "minecraft:deepslate_tiles"},
        {pos: [11, 1, 1], state: "minecraft:deepslate{axis:y}"},
        {pos: [11, 1, 2], state: "minecraft:deepslate{axis:y}"},
        {pos: [11, 1, 3], state: "minecraft:deepslate{axis:y}"},
        {pos: [11, 1, 4], state: "minecraft:deepslate{axis:y}"},
        {pos: [11, 1, 15], state: "minecraft:deepslate_tiles"},
        {pos: [11, 1, 16], state: "minecraft:deepslate_tiles"},
        {pos: [11, 1, 17], state: "minecraft:smooth_basalt"},
        {pos: [11, 1, 18], state: "minecraft:deepslate_tiles"},
        {pos: [11, 1, 19], state: "minecraft:deepslate_tiles"},
        {pos: [11, 1, 20], state: "minecraft:deepslate_tiles"},
        {pos: [11, 1, 21], state: "minecraft:smooth_basalt"},
        {pos: [11, 1, 22], state: "minecraft:deepslate_tiles"},
        {pos: [11, 1, 23], state: "minecraft:deepslate_tiles"},
        {pos: [11, 1, 35], state: "minecraft:deepslate{axis:y}"},
        {pos: [11, 1, 36], state: "minecraft:deepslate{axis:y}"},
        {pos: [11, 1, 37], state: "minecraft:deepslate{axis:y}"},
        {pos: [11, 1, 38], state: "minecraft:deepslate_tiles"},
        {pos: [12, 1, 0], state: "minecraft:deepslate_tiles"},
        {pos: [12, 1, 15], state: "minecraft:deepslate_tiles"},
        {pos: [12, 1, 16], state: "minecraft:deepslate_tiles"},
        {pos: [12, 1, 17], state: "minecraft:polished_deepslate"},
        {pos: [12, 1, 18], state: "minecraft:deepslate_tiles"},
        {pos: [12, 1, 19], state: "minecraft:deepslate_tiles"},
        {pos: [12, 1, 20], state: "minecraft:deepslate_tiles"},
        {pos: [12, 1, 21], state: "minecraft:polished_deepslate"},
        {pos: [12, 1, 22], state: "minecraft:deepslate_tiles"},
        {pos: [12, 1, 23], state: "minecraft:deepslate_tiles"},
        {pos: [12, 1, 38], state: "minecraft:deepslate_tiles"},
        {pos: [13, 1, 15], state: "minecraft:deepslate_tiles"},
        {pos: [13, 1, 16], state: "minecraft:deepslate_tiles"},
        {pos: [13, 1, 17], state: "minecraft:smooth_basalt"},
        {pos: [13, 1, 18], state: "minecraft:deepslate_tiles"},
        {pos: [13, 1, 19], state: "minecraft:deepslate_tiles"},
        {pos: [13, 1, 20], state: "minecraft:deepslate_tiles"},
        {pos: [13, 1, 21], state: "minecraft:smooth_basalt"},
        {pos: [13, 1, 22], state: "minecraft:deepslate_tiles"},
        {pos: [13, 1, 23], state: "minecraft:deepslate_tiles"},
        {pos: [14, 1, 18], state: "minecraft:deepslate_tiles"},
        {pos: [14, 1, 19], state: "minecraft:deepslate_tiles"},
        {pos: [14, 1, 20], state: "minecraft:deepslate_tiles"},
        {pos: [15, 1, 18], state: "minecraft:deepslate_tiles"},
        {pos: [15, 1, 19], state: "minecraft:deepslate_tiles"},
        {pos: [15, 1, 20], state: "minecraft:deepslate_tiles"},
        {pos: [16, 1, 15], state: "minecraft:deepslate_tiles"},
        {pos: [16, 1, 16], state: "minecraft:deepslate_tiles"},
        {pos: [16, 1, 17], state: "minecraft:smooth_basalt"},
        {pos: [16, 1, 18], state: "minecraft:deepslate_tiles"},
        {pos: [16, 1, 19], state: "minecraft:deepslate_tiles"},
        {pos: [16, 1, 20], state: "minecraft:deepslate_tiles"},
        {pos: [16, 1, 21], state: "minecraft:smooth_basalt"},
        {pos: [16, 1, 22], state: "minecraft:deepslate_tiles"},
        {pos: [16, 1, 23], state: "minecraft:deepslate_tiles"},
        {pos: [17, 1, 0], state: "minecraft:deepslate_tiles"},
        {pos: [17, 1, 15], state: "minecraft:deepslate_tiles"},
        {pos: [17, 1, 16], state: "minecraft:deepslate_tiles"},
        {pos: [17, 1, 17], state: "minecraft:polished_deepslate"},
        {pos: [17, 1, 18], state: "minecraft:deepslate_tiles"},
        {pos: [17, 1, 19], state: "minecraft:deepslate_tiles"},
        {pos: [17, 1, 20], state: "minecraft:deepslate_tiles"},
        {pos: [17, 1, 21], state: "minecraft:polished_deepslate"},
        {pos: [17, 1, 22], state: "minecraft:deepslate_tiles"},
        {pos: [17, 1, 23], state: "minecraft:deepslate_tiles"},
        {pos: [17, 1, 38], state: "minecraft:deepslate_tiles"},
        {pos: [18, 1, 0], state: "minecraft:deepslate_tiles"},
        {pos: [18, 1, 1], state: "minecraft:deepslate{axis:y}"},
        {pos: [18, 1, 2], state: "minecraft:deepslate{axis:y}"},
        {pos: [18, 1, 3], state: "minecraft:deepslate{axis:y}"},
        {pos: [18, 1, 4], state: "minecraft:deepslate{axis:y}"},
        {pos: [18, 1, 15], state: "minecraft:deepslate_tiles"},
        {pos: [18, 1, 16], state: "minecraft:deepslate_tiles"},
        {pos: [18, 1, 17], state: "minecraft:smooth_basalt"},
        {pos: [18, 1, 18], state: "minecraft:deepslate_tiles"},
        {pos: [18, 1, 19], state: "minecraft:deepslate_tiles"},
        {pos: [18, 1, 20], state: "minecraft:deepslate_tiles"},
        {pos: [18, 1, 21], state: "minecraft:smooth_basalt"},
        {pos: [18, 1, 22], state: "minecraft:deepslate_tiles"},
        {pos: [18, 1, 23], state: "minecraft:deepslate_tiles"},
        {pos: [18, 1, 34], state: "minecraft:deepslate{axis:y}"},
        {pos: [18, 1, 35], state: "minecraft:deepslate{axis:y}"},
        {pos: [18, 1, 36], state: "minecraft:deepslate{axis:y}"},
        {pos: [18, 1, 37], state: "minecraft:deepslate{axis:y}"},
        {pos: [18, 1, 38], state: "minecraft:deepslate_tiles"},
        {pos: [19, 1, 0], state: "minecraft:deepslate_tiles"},
        {pos: [19, 1, 1], state: "minecraft:deepslate{axis:y}"},
        {pos: [19, 1, 2], state: "minecraft:deepslate{axis:y}"},
        {pos: [19, 1, 3], state: "minecraft:deepslate{axis:y}"},
        {pos: [19, 1, 4], state: "minecraft:deepslate{axis:y}"},
        {pos: [19, 1, 18], state: "minecraft:deepslate_tiles"},
        {pos: [19, 1, 19], state: "minecraft:deepslate_tiles"},
        {pos: [19, 1, 20], state: "minecraft:deepslate_tiles"},
        {pos: [19, 1, 34], state: "minecraft:deepslate{axis:y}"},
        {pos: [19, 1, 35], state: "minecraft:deepslate{axis:y}"},
        {pos: [19, 1, 36], state: "minecraft:deepslate{axis:y}"},
        {pos: [19, 1, 37], state: "minecraft:deepslate{axis:y}"},
        {pos: [19, 1, 38], state: "minecraft:deepslate_tiles"},
        {pos: [20, 1, 0], state: "minecraft:deepslate_tiles"},
        {pos: [20, 1, 1], state: "minecraft:deepslate{axis:y}"},
        {pos: [20, 1, 2], state: "minecraft:deepslate{axis:y}"},
        {pos: [20, 1, 3], state: "minecraft:deepslate{axis:y}"},
        {pos: [20, 1, 4], state: "minecraft:deepslate{axis:y}"},
        {pos: [20, 1, 18], state: "minecraft:deepslate_tiles"},
        {pos: [20, 1, 19], state: "minecraft:deepslate_tiles"},
        {pos: [20, 1, 20], state: "minecraft:deepslate_tiles"},
        {pos: [20, 1, 34], state: "minecraft:deepslate{axis:y}"},
        {pos: [20, 1, 35], state: "minecraft:deepslate{axis:y}"},
        {pos: [20, 1, 36], state: "minecraft:deepslate{axis:y}"},
        {pos: [20, 1, 37], state: "minecraft:deepslate{axis:y}"},
        {pos: [20, 1, 38], state: "minecraft:deepslate_tiles"},
        {pos: [21, 1, 0], state: "minecraft:deepslate_tiles"},
        {pos: [21, 1, 1], state: "minecraft:deepslate{axis:y}"},
        {pos: [21, 1, 2], state: "minecraft:deepslate{axis:y}"},
        {pos: [21, 1, 3], state: "minecraft:deepslate{axis:y}"},
        {pos: [21, 1, 4], state: "minecraft:deepslate{axis:y}"},
        {pos: [21, 1, 15], state: "minecraft:deepslate_tiles"},
        {pos: [21, 1, 16], state: "minecraft:deepslate_tiles"},
        {pos: [21, 1, 17], state: "minecraft:smooth_basalt"},
        {pos: [21, 1, 18], state: "minecraft:deepslate_tiles"},
        {pos: [21, 1, 19], state: "minecraft:deepslate_tiles"},
        {pos: [21, 1, 20], state: "minecraft:deepslate_tiles"},
        {pos: [21, 1, 21], state: "minecraft:smooth_basalt"},
        {pos: [21, 1, 22], state: "minecraft:deepslate_tiles"},
        {pos: [21, 1, 23], state: "minecraft:deepslate_tiles"},
        {pos: [21, 1, 34], state: "minecraft:deepslate{axis:y}"},
        {pos: [21, 1, 35], state: "minecraft:deepslate{axis:y}"},
        {pos: [21, 1, 36], state: "minecraft:deepslate{axis:y}"},
        {pos: [21, 1, 37], state: "minecraft:deepslate{axis:y}"},
        {pos: [21, 1, 38], state: "minecraft:deepslate_tiles"},
        {pos: [22, 1, 15], state: "minecraft:deepslate_tiles"},
        {pos: [22, 1, 16], state: "minecraft:deepslate_tiles"},
        {pos: [22, 1, 17], state: "minecraft:polished_deepslate"},
        {pos: [22, 1, 18], state: "minecraft:deepslate_tiles"},
        {pos: [22, 1, 19], state: "minecraft:deepslate_tiles"},
        {pos: [22, 1, 20], state: "minecraft:deepslate_tiles"},
        {pos: [22, 1, 21], state: "minecraft:polished_deepslate"},
        {pos: [22, 1, 22], state: "minecraft:deepslate_tiles"},
        {pos: [22, 1, 23], state: "minecraft:deepslate_tiles"},
        {pos: [23, 1, 15], state: "minecraft:deepslate_tiles"},
        {pos: [23, 1, 16], state: "minecraft:deepslate_tiles"},
        {pos: [23, 1, 17], state: "minecraft:smooth_basalt"},
        {pos: [23, 1, 18], state: "minecraft:deepslate_tiles"},
        {pos: [23, 1, 19], state: "minecraft:deepslate_tiles"},
        {pos: [23, 1, 20], state: "minecraft:deepslate_tiles"},
        {pos: [23, 1, 21], state: "minecraft:smooth_basalt"},
        {pos: [23, 1, 22], state: "minecraft:deepslate_tiles"},
        {pos: [23, 1, 23], state: "minecraft:deepslate_tiles"},
        {pos: [24, 1, 17], state: "minecraft:polished_deepslate"},
        {pos: [24, 1, 18], state: "minecraft:deepslate_tiles"},
        {pos: [24, 1, 19], state: "minecraft:deepslate_tiles"},
        {pos: [24, 1, 20], state: "minecraft:deepslate_tiles"},
        {pos: [24, 1, 21], state: "minecraft:polished_deepslate"},
        {pos: [25, 1, 17], state: "minecraft:deepslate_bricks"},
        {pos: [25, 1, 18], state: "minecraft:deepslate_bricks"},
        {pos: [25, 1, 19], state: "minecraft:deepslate_bricks"},
        {pos: [25, 1, 20], state: "minecraft:deepslate_bricks"},
        {pos: [25, 1, 21], state: "minecraft:deepslate_bricks"},
        {pos: [26, 1, 17], state: "minecraft:deepslate_bricks"},
        {pos: [26, 1, 18], state: "minecraft:deepslate_bricks"},
        {pos: [26, 1, 19], state: "minecraft:deepslate_bricks"},
        {pos: [26, 1, 20], state: "minecraft:deepslate_bricks"},
        {pos: [26, 1, 21], state: "minecraft:deepslate_bricks"},
        {pos: [0, 2, 0], state: "minecraft:deepslate_bricks"},
        {pos: [0, 2, 1], state: "minecraft:deepslate{axis:y}"},
        {pos: [0, 2, 2], state: "minecraft:deepslate{axis:y}"},
        {pos: [0, 2, 3], state: "minecraft:deepslate{axis:y}"},
        {pos: [0, 2, 4], state: "minecraft:deepslate{axis:y}"},
        {pos: [0, 2, 34], state: "minecraft:deepslate{axis:y}"},
        {pos: [0, 2, 35], state: "minecraft:deepslate{axis:y}"},
        {pos: [0, 2, 36], state: "minecraft:deepslate{axis:y}"},
        {pos: [0, 2, 37], state: "minecraft:deepslate{axis:y}"},
        {pos: [0, 2, 38], state: "minecraft:deepslate_bricks"},
        {pos: [1, 2, 0], state: "minecraft:deepslate_bricks"},
        {pos: [1, 2, 1], state: "minecraft:deepslate{axis:y}"},
        {pos: [1, 2, 2], state: "minecraft:deepslate{axis:y}"},
        {pos: [1, 2, 3], state: "minecraft:deepslate{axis:y}"},
        {pos: [1, 2, 15], state: "minecraft:deepslate_tiles"},
        {pos: [1, 2, 16], state: "minecraft:smooth_basalt"},
        {pos: [1, 2, 22], state: "minecraft:smooth_basalt"},
        {pos: [1, 2, 23], state: "minecraft:deepslate_tiles"},
        {pos: [1, 2, 34], state: "minecraft:deepslate{axis:y}"},
        {pos: [1, 2, 35], state: "minecraft:deepslate{axis:y}"},
        {pos: [1, 2, 36], state: "minecraft:deepslate{axis:y}"},
        {pos: [1, 2, 37], state: "minecraft:deepslate{axis:y}"},
        {pos: [1, 2, 38], state: "minecraft:deepslate_bricks"},
        {pos: [2, 2, 15], state: "minecraft:deepslate_tiles"},
        {pos: [2, 2, 16], state: "minecraft:polished_deepslate"},
        {pos: [2, 2, 22], state: "minecraft:polished_deepslate"},
        {pos: [2, 2, 23], state: "minecraft:deepslate_tiles"},
        {pos: [3, 2, 15], state: "minecraft:deepslate_tiles"},
        {pos: [3, 2, 16], state: "minecraft:smooth_basalt"},
        {pos: [3, 2, 22], state: "minecraft:smooth_basalt"},
        {pos: [3, 2, 23], state: "minecraft:deepslate_tiles"},
        {pos: [6, 2, 15], state: "minecraft:deepslate_tiles"},
        {pos: [6, 2, 16], state: "minecraft:smooth_basalt"},
        {pos: [6, 2, 22], state: "minecraft:smooth_basalt"},
        {pos: [6, 2, 23], state: "minecraft:deepslate_tiles"},
        {pos: [7, 2, 15], state: "minecraft:deepslate_tiles"},
        {pos: [7, 2, 16], state: "minecraft:polished_deepslate"},
        {pos: [7, 2, 22], state: "minecraft:polished_deepslate"},
        {pos: [7, 2, 23], state: "minecraft:deepslate_tiles"},
        {pos: [8, 2, 0], state: "minecraft:deepslate_bricks"},
        {pos: [8, 2, 1], state: "minecraft:deepslate{axis:y}"},
        {pos: [8, 2, 2], state: "minecraft:deepslate{axis:y}"},
        {pos: [8, 2, 15], state: "minecraft:deepslate_tiles"},
        {pos: [8, 2, 16], state: "minecraft:smooth_basalt"},
        {pos: [8, 2, 22], state: "minecraft:smooth_basalt"},
        {pos: [8, 2, 23], state: "minecraft:deepslate_tiles"},
        {pos: [8, 2, 34], state: "minecraft:deepslate{axis:y}"},
        {pos: [8, 2, 35], state: "minecraft:deepslate{axis:y}"},
        {pos: [8, 2, 36], state: "minecraft:deepslate{axis:y}"},
        {pos: [8, 2, 37], state: "minecraft:deepslate{axis:y}"},
        {pos: [8, 2, 38], state: "minecraft:deepslate_bricks"},
        {pos: [9, 2, 0], state: "minecraft:deepslate_bricks"},
        {pos: [9, 2, 1], state: "minecraft:deepslate{axis:y}"},
        {pos: [9, 2, 2], state: "minecraft:deepslate{axis:y}"},
        {pos: [9, 2, 3], state: "minecraft:deepslate{axis:y}"},
        {pos: [9, 2, 4], state: "minecraft:deepslate{axis:y}"},
        {pos: [9, 2, 36], state: "minecraft:deepslate{axis:y}"},
        {pos: [9, 2, 37], state: "minecraft:deepslate{axis:y}"},
        {pos: [9, 2, 38], state: "minecraft:deepslate_bricks"},
        {pos: [10, 2, 0], state: "minecraft:deepslate_bricks"},
        {pos: [10, 2, 1], state: "minecraft:deepslate{axis:y}"},
        {pos: [10, 2, 2], state: "minecraft:deepslate{axis:y}"},
        {pos: [10, 2, 3], state: "minecraft:deepslate{axis:y}"},
        {pos: [10, 2, 4], state: "minecraft:deepslate{axis:y}"},
        {pos: [10, 2, 35], state: "minecraft:deepslate{axis:y}"},
        {pos: [10, 2, 36], state: "minecraft:deepslate{axis:y}"},
        {pos: [10, 2, 37], state: "minecraft:deepslate{axis:y}"},
        {pos: [10, 2, 38], state: "minecraft:deepslate_bricks"},
        {pos: [11, 2, 0], state: "minecraft:deepslate_bricks"},
        {pos: [11, 2, 1], state: "minecraft:deepslate{axis:y}"},
        {pos: [11, 2, 2], state: "minecraft:deepslate{axis:y}"},
        {pos: [11, 2, 3], state: "minecraft:deepslate{axis:y}"},
        {pos: [11, 2, 4], state: "minecraft:deepslate{axis:y}"},
        {pos: [11, 2, 15], state: "minecraft:deepslate_tiles"},
        {pos: [11, 2, 16], state: "minecraft:smooth_basalt"},
        {pos: [11, 2, 22], state: "minecraft:smooth_basalt"},
        {pos: [11, 2, 23], state: "minecraft:deepslate_tiles"},
        {pos: [11, 2, 36], state: "minecraft:deepslate{axis:y}"},
        {pos: [11, 2, 37], state: "minecraft:deepslate{axis:y}"},
        {pos: [11, 2, 38], state: "minecraft:deepslate_bricks"},
        {pos: [12, 2, 15], state: "minecraft:deepslate_tiles"},
        {pos: [12, 2, 16], state: "minecraft:polished_deepslate"},
        {pos: [12, 2, 22], state: "minecraft:polished_deepslate"},
        {pos: [12, 2, 23], state: "minecraft:deepslate_tiles"},
        {pos: [13, 2, 15], state: "minecraft:deepslate_tiles"},
        {pos: [13, 2, 16], state: "minecraft:smooth_basalt"},
        {pos: [13, 2, 22], state: "minecraft:smooth_basalt"},
        {pos: [13, 2, 23], state: "minecraft:deepslate_tiles"},
        {pos: [16, 2, 15], state: "minecraft:deepslate_tiles"},
        {pos: [16, 2, 16], state: "minecraft:smooth_basalt"},
        {pos: [16, 2, 22], state: "minecraft:smooth_basalt"},
        {pos: [16, 2, 23], state: "minecraft:deepslate_tiles"},
        {pos: [17, 2, 15], state: "minecraft:deepslate_tiles"},
        {pos: [17, 2, 16], state: "minecraft:polished_deepslate"},
        {pos: [17, 2, 22], state: "minecraft:polished_deepslate"},
        {pos: [17, 2, 23], state: "minecraft:deepslate_tiles"},
        {pos: [18, 2, 0], state: "minecraft:deepslate_bricks"},
        {pos: [18, 2, 1], state: "minecraft:deepslate{axis:y}"},
        {pos: [18, 2, 2], state: "minecraft:deepslate{axis:y}"},
        {pos: [18, 2, 3], state: "minecraft:deepslate{axis:y}"},
        {pos: [18, 2, 4], state: "minecraft:deepslate{axis:y}"},
        {pos: [18, 2, 15], state: "minecraft:deepslate_tiles"},
        {pos: [18, 2, 16], state: "minecraft:smooth_basalt"},
        {pos: [18, 2, 22], state: "minecraft:smooth_basalt"},
        {pos: [18, 2, 23], state: "minecraft:deepslate_tiles"},
        {pos: [18, 2, 36], state: "minecraft:deepslate{axis:y}"},
        {pos: [18, 2, 37], state: "minecraft:deepslate{axis:y}"},
        {pos: [18, 2, 38], state: "minecraft:deepslate_bricks"},
        {pos: [19, 2, 0], state: "minecraft:deepslate_bricks"},
        {pos: [19, 2, 1], state: "minecraft:deepslate{axis:y}"},
        {pos: [19, 2, 2], state: "minecraft:deepslate{axis:y}"},
        {pos: [19, 2, 3], state: "minecraft:deepslate{axis:y}"},
        {pos: [19, 2, 4], state: "minecraft:deepslate{axis:y}"},
        {pos: [19, 2, 34], state: "minecraft:deepslate{axis:y}"},
        {pos: [19, 2, 35], state: "minecraft:deepslate{axis:y}"},
        {pos: [19, 2, 36], state: "minecraft:deepslate{axis:y}"},
        {pos: [19, 2, 37], state: "minecraft:deepslate{axis:y}"},
        {pos: [19, 2, 38], state: "minecraft:deepslate_bricks"},
        {pos: [20, 2, 0], state: "minecraft:deepslate_bricks"},
        {pos: [20, 2, 1], state: "minecraft:deepslate{axis:y}"},
        {pos: [20, 2, 2], state: "minecraft:deepslate{axis:y}"},
        {pos: [20, 2, 3], state: "minecraft:deepslate{axis:y}"},
        {pos: [20, 2, 4], state: "minecraft:deepslate{axis:y}"},
        {pos: [20, 2, 34], state: "minecraft:deepslate{axis:y}"},
        {pos: [20, 2, 35], state: "minecraft:deepslate{axis:y}"},
        {pos: [20, 2, 36], state: "minecraft:deepslate{axis:y}"},
        {pos: [20, 2, 37], state: "minecraft:deepslate{axis:y}"},
        {pos: [20, 2, 38], state: "minecraft:deepslate_bricks"},
        {pos: [21, 2, 0], state: "minecraft:deepslate_bricks"},
        {pos: [21, 2, 1], state: "minecraft:deepslate{axis:y}"},
        {pos: [21, 2, 2], state: "minecraft:deepslate{axis:y}"},
        {pos: [21, 2, 3], state: "minecraft:deepslate{axis:y}"},
        {pos: [21, 2, 15], state: "minecraft:deepslate_tiles"},
        {pos: [21, 2, 16], state: "minecraft:smooth_basalt"},
        {pos: [21, 2, 22], state: "minecraft:smooth_basalt"},
        {pos: [21, 2, 23], state: "minecraft:deepslate_tiles"},
        {pos: [21, 2, 34], state: "minecraft:deepslate{axis:y}"},
        {pos: [21, 2, 35], state: "minecraft:deepslate{axis:y}"},
        {pos: [21, 2, 36], state: "minecraft:deepslate{axis:y}"},
        {pos: [21, 2, 37], state: "minecraft:deepslate{axis:y}"},
        {pos: [21, 2, 38], state: "minecraft:deepslate_bricks"},
        {pos: [22, 2, 15], state: "minecraft:deepslate_tiles"},
        {pos: [22, 2, 16], state: "minecraft:polished_deepslate"},
        {pos: [22, 2, 22], state: "minecraft:polished_deepslate"},
        {pos: [22, 2, 23], state: "minecraft:deepslate_tiles"},
        {pos: [23, 2, 15], state: "minecraft:deepslate_tiles"},
        {pos: [23, 2, 16], state: "minecraft:smooth_basalt"},
        {pos: [23, 2, 22], state: "minecraft:smooth_basalt"},
        {pos: [23, 2, 23], state: "minecraft:deepslate_tiles"},
        {pos: [24, 2, 17], state: "minecraft:polished_deepslate"},
        {pos: [24, 2, 18], state: "minecraft:deepslate_bricks"},
        {pos: [24, 2, 19], state: "minecraft:deepslate_bricks"},
        {pos: [24, 2, 20], state: "minecraft:deepslate_bricks"},
        {pos: [24, 2, 21], state: "minecraft:polished_deepslate"},
        {pos: [25, 2, 17], state: "minecraft:deepslate_bricks"},
        {pos: [25, 2, 18], state: "minecraft:deepslate_bricks"},
        {pos: [25, 2, 19], state: "minecraft:deepslate_bricks"},
        {pos: [25, 2, 20], state: "minecraft:deepslate_bricks"},
        {pos: [25, 2, 21], state: "minecraft:deepslate_bricks"},
        {pos: [26, 2, 17], state: "minecraft:deepslate_bricks"},
        {pos: [26, 2, 18], state: "minecraft:deepslate_bricks"},
        {pos: [26, 2, 19], state: "minecraft:deepslate_bricks"},
        {pos: [26, 2, 20], state: "minecraft:deepslate_bricks"},
        {pos: [26, 2, 21], state: "minecraft:deepslate_bricks"},
        {pos: [0, 3, 2], state: "minecraft:polished_deepslate"},
        {pos: [0, 3, 3], state: "minecraft:polished_deepslate"},
        {pos: [0, 3, 35], state: "minecraft:polished_deepslate"},
        {pos: [0, 3, 36], state: "minecraft:polished_deepslate"},
        {pos: [1, 3, 15], state: "minecraft:polished_deepslate"},
        {pos: [1, 3, 23], state: "minecraft:polished_deepslate"},
        {pos: [3, 3, 15], state: "minecraft:polished_deepslate"},
        {pos: [3, 3, 23], state: "minecraft:polished_deepslate"},
        {pos: [6, 3, 15], state: "minecraft:polished_deepslate"},
        {pos: [6, 3, 23], state: "minecraft:polished_deepslate"},
        {pos: [8, 3, 15], state: "minecraft:polished_deepslate"},
        {pos: [8, 3, 23], state: "minecraft:polished_deepslate"},
        {pos: [9, 3, 2], state: "minecraft:polished_deepslate"},
        {pos: [9, 3, 3], state: "minecraft:polished_deepslate"},
        {pos: [9, 3, 35], state: "minecraft:polished_deepslate"},
        {pos: [9, 3, 36], state: "minecraft:polished_deepslate"},
        {pos: [10, 3, 2], state: "minecraft:polished_deepslate"},
        {pos: [10, 3, 3], state: "minecraft:polished_deepslate"},
        {pos: [10, 3, 35], state: "minecraft:polished_deepslate"},
        {pos: [10, 3, 36], state: "minecraft:polished_deepslate"},
        {pos: [11, 3, 15], state: "minecraft:polished_deepslate"},
        {pos: [11, 3, 23], state: "minecraft:polished_deepslate"},
        {pos: [13, 3, 15], state: "minecraft:polished_deepslate"},
        {pos: [13, 3, 23], state: "minecraft:polished_deepslate"},
        {pos: [16, 3, 15], state: "minecraft:polished_deepslate"},
        {pos: [16, 3, 23], state: "minecraft:polished_deepslate"},
        {pos: [18, 3, 15], state: "minecraft:polished_deepslate"},
        {pos: [18, 3, 23], state: "minecraft:polished_deepslate"},
        {pos: [19, 3, 2], state: "minecraft:polished_deepslate"},
        {pos: [19, 3, 3], state: "minecraft:polished_deepslate"},
        {pos: [19, 3, 35], state: "minecraft:polished_deepslate"},
        {pos: [19, 3, 36], state: "minecraft:polished_deepslate"},
        {pos: [20, 3, 2], state: "minecraft:polished_deepslate"},
        {pos: [20, 3, 3], state: "minecraft:polished_deepslate"},
        {pos: [20, 3, 35], state: "minecraft:polished_deepslate"},
        {pos: [20, 3, 36], state: "minecraft:polished_deepslate"},
        {pos: [21, 3, 15], state: "minecraft:polished_deepslate"},
        {pos: [21, 3, 23], state: "minecraft:polished_deepslate"},
        {pos: [23, 3, 15], state: "minecraft:polished_deepslate"},
        {pos: [23, 3, 23], state: "minecraft:polished_deepslate"},
        {pos: [25, 3, 17], state: "minecraft:deepslate_bricks"},
        {pos: [25, 3, 18], state: "minecraft:deepslate_bricks"},
        {pos: [25, 3, 19], state: "minecraft:deepslate_bricks"},
        {pos: [25, 3, 20], state: "minecraft:deepslate_bricks"},
        {pos: [25, 3, 21], state: "minecraft:deepslate_bricks"},
        {pos: [26, 3, 17], state: "minecraft:deepslate_bricks"},
        {pos: [26, 3, 18], state: "minecraft:deepslate_bricks"},
        {pos: [26, 3, 19], state: "minecraft:deepslate_bricks"},
        {pos: [26, 3, 20], state: "minecraft:deepslate_bricks"},
        {pos: [26, 3, 21], state: "minecraft:deepslate_bricks"},
        {pos: [0, 4, 1], state: "minecraft:polished_deepslate"},
        {pos: [0, 4, 2], state: "minecraft:polished_deepslate"},
        {pos: [0, 4, 3], state: "minecraft:polished_deepslate"},
        {pos: [0, 4, 4], state: "minecraft:polished_deepslate"},
        {pos: [0, 4, 34], state: "minecraft:polished_deepslate"},
        {pos: [0, 4, 35], state: "minecraft:polished_deepslate"},
        {pos: [0, 4, 36], state: "minecraft:polished_deepslate"},
        {pos: [0, 4, 37], state: "minecraft:polished_deepslate"},
        {pos: [1, 4, 1], state: "minecraft:polished_deepslate"},
        {pos: [1, 4, 2], state: "minecraft:polished_deepslate"},
        {pos: [1, 4, 3], state: "minecraft:polished_deepslate"},
        {pos: [1, 4, 15], state: "minecraft:deepslate_bricks"},
        {pos: [1, 4, 23], state: "minecraft:deepslate_bricks"},
        {pos: [1, 4, 34], state: "minecraft:polished_deepslate"},
        {pos: [1, 4, 35], state: "minecraft:polished_deepslate"},
        {pos: [1, 4, 36], state: "minecraft:polished_deepslate"},
        {pos: [1, 4, 37], state: "minecraft:polished_deepslate"},
        {pos: [2, 4, 15], state: "minecraft:chiseled_deepslate"},
        {pos: [2, 4, 23], state: "minecraft:chiseled_deepslate"},
        {pos: [3, 4, 15], state: "minecraft:deepslate_bricks"},
        {pos: [3, 4, 23], state: "minecraft:deepslate_bricks"},
        {pos: [6, 4, 23], state: "minecraft:deepslate_bricks"},
        {pos: [7, 4, 15], state: "minecraft:chiseled_deepslate"},
        {pos: [7, 4, 23], state: "minecraft:chiseled_deepslate"},
        {pos: [8, 4, 1], state: "minecraft:polished_deepslate"},
        {pos: [8, 4, 2], state: "minecraft:polished_deepslate"},
        {pos: [8, 4, 3], state: "minecraft:polished_deepslate"},
        {pos: [8, 4, 15], state: "minecraft:deepslate_bricks"},
        {pos: [8, 4, 23], state: "minecraft:deepslate_bricks"},
        {pos: [8, 4, 34], state: "minecraft:polished_deepslate"},
        {pos: [8, 4, 35], state: "minecraft:polished_deepslate"},
        {pos: [8, 4, 36], state: "minecraft:polished_deepslate"},
        {pos: [8, 4, 37], state: "minecraft:polished_deepslate"},
        {pos: [9, 4, 1], state: "minecraft:polished_deepslate"},
        {pos: [9, 4, 2], state: "minecraft:polished_deepslate"},
        {pos: [9, 4, 3], state: "minecraft:polished_deepslate"},
        {pos: [9, 4, 4], state: "minecraft:polished_deepslate"},
        {pos: [9, 4, 34], state: "minecraft:polished_deepslate"},
        {pos: [9, 4, 35], state: "minecraft:polished_deepslate"},
        {pos: [9, 4, 36], state: "minecraft:polished_deepslate"},
        {pos: [9, 4, 37], state: "minecraft:polished_deepslate"},
        {pos: [10, 4, 1], state: "minecraft:polished_deepslate"},
        {pos: [10, 4, 2], state: "minecraft:polished_deepslate"},
        {pos: [10, 4, 3], state: "minecraft:polished_deepslate"},
        {pos: [10, 4, 4], state: "minecraft:polished_deepslate"},
        {pos: [10, 4, 34], state: "minecraft:polished_deepslate"},
        {pos: [10, 4, 35], state: "minecraft:polished_deepslate"},
        {pos: [10, 4, 36], state: "minecraft:polished_deepslate"},
        {pos: [10, 4, 37], state: "minecraft:polished_deepslate"},
        {pos: [11, 4, 1], state: "minecraft:polished_deepslate"},
        {pos: [11, 4, 2], state: "minecraft:polished_deepslate"},
        {pos: [11, 4, 3], state: "minecraft:polished_deepslate"},
        {pos: [11, 4, 4], state: "minecraft:polished_deepslate"},
        {pos: [11, 4, 15], state: "minecraft:deepslate_bricks"},
        {pos: [11, 4, 23], state: "minecraft:deepslate_bricks"},
        {pos: [11, 4, 34], state: "minecraft:polished_deepslate"},
        {pos: [11, 4, 35], state: "minecraft:polished_deepslate"},
        {pos: [11, 4, 36], state: "minecraft:polished_deepslate"},
        {pos: [11, 4, 37], state: "minecraft:polished_deepslate"},
        {pos: [12, 4, 15], state: "minecraft:chiseled_deepslate"},
        {pos: [12, 4, 23], state: "minecraft:chiseled_deepslate"},
        {pos: [13, 4, 23], state: "minecraft:deepslate_bricks"},
        {pos: [16, 4, 15], state: "minecraft:deepslate_bricks"},
        {pos: [16, 4, 23], state: "minecraft:deepslate_bricks"},
        {pos: [17, 4, 15], state: "minecraft:chiseled_deepslate"},
        {pos: [17, 4, 23], state: "minecraft:chiseled_deepslate"},
        {pos: [18, 4, 1], state: "minecraft:polished_deepslate"},
        {pos: [18, 4, 2], state: "minecraft:polished_deepslate"},
        {pos: [18, 4, 3], state: "minecraft:polished_deepslate"},
        {pos: [18, 4, 4], state: "minecraft:polished_deepslate"},
        {pos: [18, 4, 15], state: "minecraft:deepslate_bricks"},
        {pos: [18, 4, 23], state: "minecraft:deepslate_bricks"},
        {pos: [18, 4, 36], state: "minecraft:polished_deepslate"},
        {pos: [18, 4, 37], state: "minecraft:polished_deepslate"},
        {pos: [19, 4, 1], state: "minecraft:polished_deepslate"},
        {pos: [19, 4, 2], state: "minecraft:polished_deepslate"},
        {pos: [19, 4, 3], state: "minecraft:polished_deepslate"},
        {pos: [19, 4, 4], state: "minecraft:polished_deepslate"},
        {pos: [19, 4, 36], state: "minecraft:polished_deepslate"},
        {pos: [19, 4, 37], state: "minecraft:polished_deepslate"},
        {pos: [20, 4, 1], state: "minecraft:polished_deepslate"},
        {pos: [20, 4, 2], state: "minecraft:polished_deepslate"},
        {pos: [20, 4, 3], state: "minecraft:polished_deepslate"},
        {pos: [20, 4, 4], state: "minecraft:polished_deepslate"},
        {pos: [20, 4, 34], state: "minecraft:polished_deepslate"},
        {pos: [20, 4, 35], state: "minecraft:polished_deepslate"},
        {pos: [20, 4, 36], state: "minecraft:polished_deepslate"},
        {pos: [20, 4, 37], state: "minecraft:polished_deepslate"},
        {pos: [21, 4, 1], state: "minecraft:polished_deepslate"},
        {pos: [21, 4, 2], state: "minecraft:polished_deepslate"},
        {pos: [21, 4, 3], state: "minecraft:polished_deepslate"},
        {pos: [21, 4, 4], state: "minecraft:polished_deepslate"},
        {pos: [21, 4, 15], state: "minecraft:deepslate_bricks"},
        {pos: [21, 4, 23], state: "minecraft:deepslate_bricks"},
        {pos: [21, 4, 34], state: "minecraft:polished_deepslate"},
        {pos: [21, 4, 35], state: "minecraft:polished_deepslate"},
        {pos: [21, 4, 36], state: "minecraft:polished_deepslate"},
        {pos: [22, 4, 15], state: "minecraft:chiseled_deepslate"},
        {pos: [22, 4, 23], state: "minecraft:chiseled_deepslate"},
        {pos: [23, 4, 23], state: "minecraft:deepslate_bricks"},
        {pos: [26, 4, 17], state: "minecraft:deepslate_bricks"},
        {pos: [26, 4, 18], state: "minecraft:deepslate_bricks"},
        {pos: [26, 4, 19], state: "minecraft:deepslate_bricks"},
        {pos: [26, 4, 20], state: "minecraft:deepslate_bricks"},
        {pos: [26, 4, 21], state: "minecraft:deepslate_bricks"},
        {pos: [27, 4, 17], state: "minecraft:deepslate_bricks"},
        {pos: [27, 4, 18], state: "minecraft:deepslate_bricks"},
        {pos: [27, 4, 19], state: "minecraft:deepslate_bricks"},
        {pos: [27, 4, 20], state: "minecraft:deepslate_bricks"},
        {pos: [27, 4, 21], state: "minecraft:deepslate_bricks"},
        {pos: [28, 4, 17], state: "minecraft:deepslate_bricks"},
        {pos: [28, 4, 18], state: "minecraft:deepslate_bricks"},
        {pos: [28, 4, 19], state: "minecraft:deepslate_bricks"},
        {pos: [28, 4, 20], state: "minecraft:deepslate_bricks"},
        {pos: [28, 4, 21], state: "minecraft:deepslate_bricks"},
        {pos: [29, 4, 17], state: "minecraft:deepslate_bricks"},
        {pos: [29, 4, 18], state: "minecraft:deepslate_bricks"},
        {pos: [29, 4, 19], state: "minecraft:deepslate_bricks"},
        {pos: [29, 4, 20], state: "minecraft:deepslate_bricks"},
        {pos: [29, 4, 21], state: "minecraft:deepslate_bricks"},
        {pos: [0, 5, 1], state: "minecraft:deepslate_tiles"},
        {pos: [0, 5, 2], state: "minecraft:polished_deepslate"},
        {pos: [0, 5, 3], state: "minecraft:polished_deepslate"},
        {pos: [0, 5, 4], state: "minecraft:deepslate_tiles"},
        {pos: [0, 5, 34], state: "minecraft:deepslate_tiles"},
        {pos: [0, 5, 35], state: "minecraft:polished_deepslate"},
        {pos: [0, 5, 36], state: "minecraft:polished_deepslate"},
        {pos: [0, 5, 37], state: "minecraft:deepslate_tiles"},
        {pos: [1, 5, 1], state: "minecraft:chiseled_deepslate"},
        {pos: [1, 5, 2], state: "minecraft:deepslate_tiles"},
        {pos: [1, 5, 3], state: "minecraft:deepslate_tiles"},
        {pos: [1, 5, 4], state: "minecraft:chiseled_deepslate"},
        {pos: [1, 5, 15], state: "minecraft:deepslate_tiles"},
        {pos: [1, 5, 16], state: "minecraft:deepslate_tiles"},
        {pos: [1, 5, 22], state: "minecraft:deepslate_tiles"},
        {pos: [1, 5, 23], state: "minecraft:deepslate_tiles"},
        {pos: [1, 5, 34], state: "minecraft:chiseled_deepslate"},
        {pos: [1, 5, 35], state: "minecraft:deepslate_tiles"},
        {pos: [1, 5, 36], state: "minecraft:deepslate_tiles"},
        {pos: [1, 5, 37], state: "minecraft:chiseled_deepslate"},
        {pos: [2, 5, 15], state: "minecraft:deepslate_tiles"},
        {pos: [2, 5, 16], state: "minecraft:deepslate_tiles"},
        {pos: [2, 5, 22], state: "minecraft:deepslate_tiles"},
        {pos: [2, 5, 23], state: "minecraft:deepslate_tiles"},
        {pos: [3, 5, 15], state: "minecraft:deepslate_tiles"},
        {pos: [3, 5, 16], state: "minecraft:deepslate_tiles"},
        {pos: [3, 5, 22], state: "minecraft:deepslate_tiles"},
        {pos: [3, 5, 23], state: "minecraft:deepslate_tiles"},
        {pos: [6, 5, 22], state: "minecraft:deepslate_tiles"},
        {pos: [7, 5, 15], state: "minecraft:deepslate_tiles"},
        {pos: [7, 5, 22], state: "minecraft:deepslate_tiles"},
        {pos: [7, 5, 23], state: "minecraft:deepslate_tiles"},
        {pos: [8, 5, 1], state: "minecraft:chiseled_deepslate"},
        {pos: [8, 5, 2], state: "minecraft:deepslate_tiles"},
        {pos: [8, 5, 3], state: "minecraft:deepslate_tiles"},
        {pos: [8, 5, 4], state: "minecraft:chiseled_deepslate"},
        {pos: [8, 5, 15], state: "minecraft:deepslate_tiles"},
        {pos: [8, 5, 22], state: "minecraft:deepslate_tiles"},
        {pos: [8, 5, 23], state: "minecraft:deepslate_tiles"},
        {pos: [8, 5, 34], state: "minecraft:chiseled_deepslate"},
        {pos: [8, 5, 35], state: "minecraft:deepslate_tiles"},
        {pos: [8, 5, 36], state: "minecraft:deepslate_tiles"},
        {pos: [8, 5, 37], state: "minecraft:chiseled_deepslate"},
        {pos: [9, 5, 1], state: "minecraft:deepslate_tiles"},
        {pos: [9, 5, 2], state: "minecraft:polished_deepslate"},
        {pos: [9, 5, 3], state: "minecraft:polished_deepslate"},
        {pos: [9, 5, 34], state: "minecraft:deepslate_tiles"},
        {pos: [9, 5, 35], state: "minecraft:polished_deepslate"},
        {pos: [9, 5, 36], state: "minecraft:polished_deepslate"},
        {pos: [9, 5, 37], state: "minecraft:deepslate_tiles"},
        {pos: [10, 5, 1], state: "minecraft:deepslate_tiles"},
        {pos: [10, 5, 2], state: "minecraft:polished_deepslate"},
        {pos: [10, 5, 3], state: "minecraft:polished_deepslate"},
        {pos: [10, 5, 4], state: "minecraft:deepslate_tiles"},
        {pos: [10, 5, 34], state: "minecraft:deepslate_tiles"},
        {pos: [10, 5, 35], state: "minecraft:polished_deepslate"},
        {pos: [10, 5, 36], state: "minecraft:polished_deepslate"},
        {pos: [10, 5, 37], state: "minecraft:deepslate_tiles"},
        {pos: [11, 5, 1], state: "minecraft:chiseled_deepslate"},
        {pos: [11, 5, 2], state: "minecraft:deepslate_tiles"},
        {pos: [11, 5, 3], state: "minecraft:deepslate_tiles"},
        {pos: [11, 5, 4], state: "minecraft:chiseled_deepslate"},
        {pos: [11, 5, 15], state: "minecraft:deepslate_tiles"},
        {pos: [11, 5, 34], state: "minecraft:chiseled_deepslate"},
        {pos: [11, 5, 35], state: "minecraft:deepslate_tiles"},
        {pos: [11, 5, 36], state: "minecraft:deepslate_tiles"},
        {pos: [12, 5, 15], state: "minecraft:deepslate_tiles"},
        {pos: [12, 5, 16], state: "minecraft:deepslate_tiles"},
        {pos: [12, 5, 22], state: "minecraft:deepslate_tiles"},
        {pos: [12, 5, 23], state: "minecraft:deepslate_tiles"},
        {pos: [13, 5, 15], state: "minecraft:deepslate_tiles"},
        {pos: [13, 5, 16], state: "minecraft:deepslate_tiles"},
        {pos: [13, 5, 22], state: "minecraft:deepslate_tiles"},
        {pos: [13, 5, 23], state: "minecraft:deepslate_tiles"},
        {pos: [16, 5, 15], state: "minecraft:deepslate_tiles"},
        {pos: [16, 5, 16], state: "minecraft:deepslate_tiles"},
        {pos: [16, 5, 22], state: "minecraft:deepslate_tiles"},
        {pos: [16, 5, 23], state: "minecraft:deepslate_tiles"},
        {pos: [17, 5, 15], state: "minecraft:deepslate_tiles"},
        {pos: [17, 5, 16], state: "minecraft:deepslate_tiles"},
        {pos: [17, 5, 22], state: "minecraft:deepslate_tiles"},
        {pos: [17, 5, 23], state: "minecraft:deepslate_tiles"},
        {pos: [18, 5, 1], state: "minecraft:chiseled_deepslate"},
        {pos: [18, 5, 2], state: "minecraft:deepslate_tiles"},
        {pos: [18, 5, 3], state: "minecraft:deepslate_tiles"},
        {pos: [18, 5, 4], state: "minecraft:chiseled_deepslate"},
        {pos: [18, 5, 15], state: "minecraft:deepslate_tiles"},
        {pos: [18, 5, 16], state: "minecraft:deepslate_tiles"},
        {pos: [18, 5, 22], state: "minecraft:deepslate_tiles"},
