{
    size: [11, 12, 11],
    data: [
        {pos: [0, 0, 0], state: "minecraft:magma_block"},
        {pos: [0, 0, 1], state: "minecraft:magma_block"},
        {pos: [0, 0, 2], state: "minecraft:magma_block"},
        {pos: [0, 0, 3], state: "minecraft:waxed_oxidized_cut_copper"},
        {pos: [0, 0, 4], state: "minecraft:waxed_oxidized_copper"},
        {pos: [0, 0, 5], state: "minecraft:waxed_oxidized_copper"},
        {pos: [0, 0, 6], state: "minecraft:waxed_oxidized_copper"},
        {pos: [0, 0, 7], state: "minecraft:waxed_oxidized_copper"},
        {pos: [0, 0, 8], state: "minecraft:waxed_oxidized_cut_copper"},
        {pos: [0, 0, 9], state: "minecraft:tuff_bricks"},
        {pos: [0, 0, 10], state: "minecraft:tuff_bricks"},
        {pos: [1, 0, 0], state: "minecraft:magma_block"},
        {pos: [1, 0, 1], state: "minecraft:magma_block"},
        {pos: [1, 0, 2], state: "minecraft:magma_block"},
        {pos: [1, 0, 3], state: "minecraft:waxed_oxidized_cut_copper"},
        {pos: [1, 0, 4], state: "minecraft:waxed_oxidized_copper"},
        {pos: [1, 0, 5], state: "minecraft:waxed_oxidized_copper"},
        {pos: [1, 0, 6], state: "minecraft:waxed_oxidized_copper"},
        {pos: [1, 0, 7], state: "minecraft:waxed_oxidized_cut_copper"},
        {pos: [1, 0, 8], state: "minecraft:waxed_oxidized_copper"},
        {pos: [1, 0, 9], state: "minecraft:waxed_oxidized_copper"},
        {pos: [1, 0, 10], state: "minecraft:tuff_bricks"},
        {pos: [2, 0, 0], state: "minecraft:magma_block"},
        {pos: [2, 0, 1], state: "minecraft:magma_block"},
        {pos: [2, 0, 2], state: "minecraft:waxed_oxidized_cut_copper"},
        {pos: [2, 0, 3], state: "minecraft:waxed_oxidized_copper"},
        {pos: [2, 0, 4], state: "minecraft:waxed_oxidized_copper"},
        {pos: [2, 0, 5], state: "minecraft:waxed_oxidized_copper"},
        {pos: [2, 0, 6], state: "minecraft:waxed_oxidized_cut_copper"},
        {pos: [2, 0, 7], state: "minecraft:waxed_oxidized_copper"},
        {pos: [2, 0, 8], state: "minecraft:waxed_oxidized_copper"},
        {pos: [2, 0, 9], state: "minecraft:waxed_oxidized_copper"},
        {pos: [2, 0, 10], state: "minecraft:tuff_bricks"},
        {pos: [3, 0, 0], state: "minecraft:waxed_oxidized_cut_copper"},
        {pos: [3, 0, 1], state: "minecraft:waxed_oxidized_cut_copper"},
        {pos: [3, 0, 2], state: "minecraft:waxed_oxidized_copper"},
        {pos: [3, 0, 3], state: "minecraft:waxed_oxidized_copper"},
        {pos: [3, 0, 4], state: "minecraft:waxed_oxidized_copper"},
        {pos: [3, 0, 5], state: "minecraft:waxed_oxidized_cut_copper"},
        {pos: [3, 0, 6], state: "minecraft:waxed_oxidized_copper"},
        {pos: [3, 0, 7], state: "minecraft:waxed_oxidized_copper"},
        {pos: [3, 0, 8], state: "minecraft:waxed_oxidized_copper"},
        {pos: [3, 0, 9], state: "minecraft:waxed_oxidized_copper"},
        {pos: [3, 0, 10], state: "minecraft:tuff_bricks"},
        {pos: [4, 0, 0], state: "minecraft:waxed_oxidized_copper"},
        {pos: [4, 0, 1], state: "minecraft:waxed_oxidized_copper"},
        {pos: [4, 0, 2], state: "minecraft:waxed_oxidized_copper"},
        {pos: [4, 0, 3], state: "minecraft:waxed_oxidized_copper"},
        {pos: [4, 0, 4], state: "minecraft:waxed_oxidized_cut_copper"},
        {pos: [4, 0, 5], state: "minecraft:waxed_oxidized_copper"},
        {pos: [4, 0, 6], state: "minecraft:waxed_oxidized_copper"},
        {pos: [4, 0, 7], state: "minecraft:waxed_oxidized_copper"},
        {pos: [4, 0, 8], state: "minecraft:waxed_oxidized_copper"},
        {pos: [4, 0, 9], state: "minecraft:tuff_bricks"},
        {pos: [4, 0, 10], state: "minecraft:tuff_bricks"},
        {pos: [5, 0, 0], state: "minecraft:waxed_oxidized_copper"},
        {pos: [5, 0, 1], state: "minecraft:waxed_oxidized_copper"},
        {pos: [5, 0, 2], state: "minecraft:waxed_oxidized_copper"},
        {pos: [5, 0, 3], state: "minecraft:waxed_oxidized_cut_copper"},
        {pos: [5, 0, 4], state: "minecraft:waxed_oxidized_copper"},
        {pos: [5, 0, 5], state: "minecraft:waxed_oxidized_copper"},
        {pos: [5, 0, 6], state: "minecraft:waxed_oxidized_copper"},
        {pos: [5, 0, 7], state: "minecraft:waxed_oxidized_copper"},
        {pos: [5, 0, 8], state: "minecraft:waxed_oxidized_copper"},
        {pos: [5, 0, 9], state: "minecraft:tuff_bricks"},
        {pos: [5, 0, 10], state: "minecraft:tuff_bricks"},
        {pos: [6, 0, 0], state: "minecraft:waxed_oxidized_copper"},
        {pos: [6, 0, 1], state: "minecraft:waxed_oxidized_copper"},
        {pos: [6, 0, 2], state: "minecraft:waxed_oxidized_cut_copper"},
        {pos: [6, 0, 3], state: "minecraft:waxed_oxidized_copper"},
        {pos: [6, 0, 4], state: "minecraft:waxed_oxidized_copper"},
        {pos: [6, 0, 5], state: "minecraft:waxed_oxidized_copper"},
        {pos: [6, 0, 6], state: "minecraft:waxed_oxidized_copper"},
        {pos: [6, 0, 7], state: "minecraft:waxed_oxidized_copper"},
        {pos: [6, 0, 8], state: "minecraft:tuff_bricks"},
        {pos: [6, 0, 9], state: "minecraft:tuff_bricks"},
        {pos: [6, 0, 10], state: "minecraft:tuff_bricks"},
        {pos: [7, 0, 0], state: "minecraft:waxed_oxidized_cut_copper"},
        {pos: [7, 0, 1], state: "minecraft:waxed_oxidized_cut_copper"},
        {pos: [7, 0, 2], state: "minecraft:waxed_oxidized_copper"},
        {pos: [7, 0, 3], state: "minecraft:waxed_oxidized_copper"},
        {pos: [7, 0, 4], state: "minecraft:waxed_oxidized_copper"},
        {pos: [7, 0, 5], state: "minecraft:waxed_oxidized_copper"},
        {pos: [7, 0, 6], state: "minecraft:waxed_oxidized_copper"},
        {pos: [7, 0, 7], state: "minecraft:waxed_oxidized_copper"},
        {pos: [7, 0, 8], state: "minecraft:tuff_bricks"},
        {pos: [7, 0, 9], state: "minecraft:tuff_bricks"},
        {pos: [7, 0, 10], state: "minecraft:tuff_bricks"},
        {pos: [8, 0, 0], state: "minecraft:waxed_oxidized_cut_copper"},
        {pos: [8, 0, 1], state: "minecraft:waxed_oxidized_copper"},
        {pos: [8, 0, 2], state: "minecraft:waxed_oxidized_copper"},
        {pos: [8, 0, 3], state: "minecraft:waxed_oxidized_copper"},
        {pos: [8, 0, 4], state: "minecraft:waxed_oxidized_copper"},
        {pos: [8, 0, 5], state: "minecraft:waxed_oxidized_copper"},
        {pos: [8, 0, 6], state: "minecraft:tuff_bricks"},
        {pos: [8, 0, 7], state: "minecraft:tuff_bricks"},
        {pos: [8, 0, 8], state: "minecraft:tuff_bricks"},
        {pos: [8, 0, 9], state: "minecraft:tuff_bricks"},
        {pos: [9, 0, 0], state: "minecraft:tuff_bricks"},
        {pos: [9, 0, 1], state: "minecraft:waxed_oxidized_copper"},
        {pos: [9, 0, 2], state: "minecraft:waxed_oxidized_copper"},
        {pos: [9, 0, 3], state: "minecraft:waxed_oxidized_copper"},
        {pos: [9, 0, 4], state: "minecraft:tuff_bricks"},
        {pos: [9, 0, 5], state: "minecraft:tuff_bricks"},
        {pos: [9, 0, 6], state: "minecraft:tuff_bricks"},
        {pos: [9, 0, 7], state: "minecraft:tuff_bricks"},
        {pos: [9, 0, 8], state: "minecraft:tuff_bricks"},
        {pos: [10, 0, 0], state: "minecraft:tuff_bricks"},
        {pos: [10, 0, 1], state: "minecraft:tuff_bricks"},
        {pos: [10, 0, 2], state: "minecraft:tuff_bricks"},
        {pos: [10, 0, 3], state: "minecraft:tuff_bricks"},
        {pos: [10, 0, 4], state: "minecraft:tuff_bricks"},
        {pos: [10, 0, 5], state: "minecraft:tuff_bricks"},
        {pos: [10, 0, 6], state: "minecraft:tuff_bricks"},
        {pos: [10, 0, 7], state: "minecraft:tuff_bricks"},
        {pos: [0, 1, 0], state: "minecraft:waxed_copper_grate{waterlogged:false}"},
        {pos: [0, 1, 9], state: "minecraft:waxed_copper_block"},
        {pos: [0, 1, 10], state: "minecraft:waxed_copper_block"},
        {pos: [1, 1, 10], state: "minecraft:waxed_copper_block"},
        {pos: [2, 1, 10], state: "minecraft:waxed_copper_block"},
        {pos: [3, 1, 10], state: "minecraft:waxed_copper_block"},
        {pos: [4, 1, 9], state: "minecraft:waxed_copper_block"},
        {pos: [4, 1, 10], state: "minecraft:waxed_copper_block"},
        {pos: [5, 1, 9], state: "minecraft:waxed_copper_block"},
        {pos: [5, 1, 10], state: "minecraft:tuff_bricks"},
        {pos: [6, 1, 8], state: "minecraft:waxed_copper_block"},
        {pos: [6, 1, 9], state: "minecraft:waxed_copper_block"},
        {pos: [6, 1, 10], state: "minecraft:tuff_bricks"},
        {pos: [7, 1, 7], state: "minecraft:waxed_copper_block"},
        {pos: [7, 1, 8], state: "minecraft:waxed_copper_block"},
        {pos: [7, 1, 9], state: "minecraft:tuff_bricks"},
        {pos: [7, 1, 10], state: "minecraft:tuff_bricks"},
        {pos: [8, 1, 6], state: "minecraft:waxed_copper_block"},
        {pos: [8, 1, 7], state: "minecraft:waxed_copper_block"},
        {pos: [8, 1, 8], state: "minecraft:tuff_bricks"},
        {pos: [8, 1, 9], state: "minecraft:tuff_bricks"},
        {pos: [9, 1, 0], state: "minecraft:waxed_copper_block"},
        {pos: [9, 1, 4], state: "minecraft:waxed_copper_block"},
        {pos: [9, 1, 5], state: "minecraft:waxed_copper_block"},
        {pos: [9, 1, 6], state: "minecraft:waxed_copper_block"},
        {pos: [9, 1, 7], state: "minecraft:tuff_bricks"},
        {pos: [9, 1, 8], state: "minecraft:tuff_bricks"},
        {pos: [10, 1, 0], state: "minecraft:waxed_copper_block"},
        {pos: [10, 1, 1], state: "minecraft:waxed_copper_block"},
        {pos: [10, 1, 2], state: "minecraft:waxed_copper_block"},
        {pos: [10, 1, 3], state: "minecraft:waxed_copper_block"},
        {pos: [10, 1, 4], state: "minecraft:waxed_copper_block"},
        {pos: [10, 1, 5], state: "minecraft:tuff_bricks"},
        {pos: [10, 1, 6], state: "minecraft:tuff_bricks"},
        {pos: [10, 1, 7], state: "minecraft:tuff_bricks"},
        {pos: [0, 2, 0], state: "minecraft:tuff_bricks"},
        {pos: [0, 2, 9], state: "minecraft:tuff_bricks"},
        {pos: [0, 2, 10], state: "minecraft:tuff_bricks"},
        {pos: [1, 2, 10], state: "minecraft:tuff_bricks"},
        {pos: [2, 2, 10], state: "minecraft:waxed_copper_bulb{powered:false,lit:true}"},
        {pos: [3, 2, 10], state: "minecraft:tuff_bricks"},
        {pos: [4, 2, 9], state: "minecraft:tuff_bricks"},
        {pos: [4, 2, 10], state: "minecraft:tuff_bricks"},
        {pos: [5, 2, 9], state: "minecraft:tuff_bricks"},
        {pos: [5, 2, 10], state: "minecraft:tuff_bricks"},
        {pos: [6, 2, 8], state: "minecraft:tuff_bricks"},
        {pos: [6, 2, 9], state: "minecraft:tuff_bricks"},
        {pos: [6, 2, 10], state: "minecraft:tuff_bricks"},
        {pos: [7, 2, 7], state: "minecraft:tuff_bricks"},
        {pos: [7, 2, 8], state: "minecraft:tuff_bricks"},
        {pos: [7, 2, 9], state: "minecraft:tuff_bricks"},
        {pos: [7, 2, 10], state: "minecraft:tuff_bricks"},
        {pos: [8, 2, 6], state: "minecraft:tuff_bricks"},
        {pos: [8, 2, 7], state: "minecraft:tuff_bricks"},
        {pos: [8, 2, 8], state: "minecraft:tuff_bricks"},
        {pos: [8, 2, 9], state: "minecraft:tuff_bricks"},
        {pos: [9, 2, 0], state: "minecraft:tuff_bricks"},
        {pos: [9, 2, 4], state: "minecraft:tuff_bricks"},
        {pos: [9, 2, 5], state: "minecraft:tuff_bricks"},
        {pos: [9, 2, 6], state: "minecraft:tuff_bricks"},
        {pos: [9, 2, 7], state: "minecraft:tuff_bricks"},
        {pos: [9, 2, 8], state: "minecraft:tuff_bricks"},
        {pos: [10, 2, 0], state: "minecraft:tuff_bricks"},
        {pos: [10, 2, 1], state: "minecraft:tuff_bricks"},
        {pos: [10, 2, 2], state: "minecraft:waxed_copper_bulb{powered:false,lit:true}"},
        {pos: [10, 2, 3], state: "minecraft:tuff_bricks"},
        {pos: [10, 2, 4], state: "minecraft:tuff_bricks"},
        {pos: [10, 2, 5], state: "minecraft:tuff_bricks"},
        {pos: [10, 2, 6], state: "minecraft:tuff_bricks"},
        {pos: [10, 2, 7], state: "minecraft:tuff_bricks"},
        {pos: [0, 3, 0], state: "minecraft:waxed_copper_block"},
        {pos: [0, 3, 9], state: "minecraft:chiseled_tuff_bricks"},
        {pos: [0, 3, 10], state: "minecraft:chiseled_tuff_bricks"},
        {pos: [1, 3, 10], state: "minecraft:chiseled_tuff_bricks"},
        {pos: [2, 3, 10], state: "minecraft:chiseled_tuff_bricks"},
        {pos: [3, 3, 10], state: "minecraft:chiseled_tuff_bricks"},
        {pos: [4, 3, 9], state: "minecraft:chiseled_tuff_bricks"},
        {pos: [4, 3, 10], state: "minecraft:chiseled_tuff_bricks"},
        {pos: [5, 3, 9], state: "minecraft:chiseled_tuff_bricks"},
        {pos: [5, 3, 10], state: "minecraft:tuff_bricks"},
        {pos: [6, 3, 8], state: "minecraft:chiseled_tuff_bricks"},
        {pos: [6, 3, 9], state: "minecraft:chiseled_tuff_bricks"},
        {pos: [6, 3, 10], state: "minecraft:tuff_bricks"},
        {pos: [7, 3, 7], state: "minecraft:chiseled_tuff_bricks"},
        {pos: [7, 3, 8], state: "minecraft:chiseled_tuff_bricks"},
        {pos: [7, 3, 9], state: "minecraft:tuff_bricks"},
        {pos: [7, 3, 10], state: "minecraft:tuff_bricks"},
        {pos: [8, 3, 6], state: "minecraft:chiseled_tuff_bricks"},
        {pos: [8, 3, 7], state: "minecraft:chiseled_tuff_bricks"},
        {pos: [8, 3, 8], state: "minecraft:tuff_bricks"},
        {pos: [8, 3, 9], state: "minecraft:tuff_bricks"},
        {pos: [9, 3, 0], state: "minecraft:chiseled_tuff_bricks"},
        {pos: [9, 3, 4], state: "minecraft:chiseled_tuff_bricks"},
        {pos: [9, 3, 5], state: "minecraft:chiseled_tuff_bricks"},
        {pos: [9, 3, 6], state: "minecraft:chiseled_tuff_bricks"},
        {pos: [9, 3, 7], state: "minecraft:tuff_bricks"},
        {pos: [9, 3, 8], state: "minecraft:tuff_bricks"},
        {pos: [10, 3, 0], state: "minecraft:chiseled_tuff_bricks"},
        {pos: [10, 3, 1], state: "minecraft:chiseled_tuff_bricks"},
        {pos: [10, 3, 2], state: "minecraft:chiseled_tuff_bricks"},
        {pos: [10, 3, 3], state: "minecraft:chiseled_tuff_bricks"},
        {pos: [10, 3, 4], state: "minecraft:chiseled_tuff_bricks"},
        {pos: [10, 3, 5], state: "minecraft:tuff_bricks"},
        {pos: [10, 3, 6], state: "minecraft:tuff_bricks"},
        {pos: [10, 3, 7], state: "minecraft:tuff_bricks"},
        {pos: [0, 4, 1], state: "minecraft:polished_tuff"},
        {pos: [0, 4, 2], state: "minecraft:polished_tuff"},
        {pos: [0, 4, 3], state: "minecraft:polished_tuff"},
        {pos: [0, 4, 4], state: "minecraft:polished_tuff"},
        {pos: [0, 4, 9], state: "minecraft:tuff_bricks"},
        {pos: [0, 4, 10], state: "minecraft:tuff_bricks"},
        {pos: [1, 4, 0], state: "minecraft:waxed_copper_block"},
        {pos: [1, 4, 1], state: "minecraft:polished_tuff"},
        {pos: [1, 4, 2], state: "minecraft:polished_tuff"},
        {pos: [1, 4, 3], state: "minecraft:polished_tuff"},
        {pos: [1, 4, 4], state: "minecraft:polished_tuff"},
        {pos: [1, 4, 8], state: "minecraft:polished_tuff"},
        {pos: [1, 4, 9], state: "minecraft:polished_tuff"},
        {pos: [1, 4, 10], state: "minecraft:tuff_bricks"},
        {pos: [2, 4, 0], state: "minecraft:polished_tuff"},
        {pos: [2, 4, 1], state: "minecraft:polished_tuff"},
        {pos: [2, 4, 2], state: "minecraft:polished_tuff"},
        {pos: [2, 4, 3], state: "minecraft:polished_tuff"},
        {pos: [2, 4, 4], state: "minecraft:polished_tuff"},
        {pos: [2, 4, 8], state: "minecraft:polished_tuff"},
        {pos: [2, 4, 9], state: "minecraft:polished_tuff"},
        {pos: [2, 4, 10], state: "minecraft:tuff_bricks"},
        {pos: [3, 4, 0], state: "minecraft:polished_tuff"},
        {pos: [3, 4, 1], state: "minecraft:polished_tuff"},
        {pos: [3, 4, 2], state: "minecraft:polished_tuff"},
        {pos: [3, 4, 3], state: "minecraft:polished_tuff"},
        {pos: [3, 4, 4], state: "minecraft:polished_tuff"},
        {pos: [3, 4, 8], state: "minecraft:polished_tuff"},
        {pos: [3, 4, 9], state: "minecraft:polished_tuff"},
        {pos: [3, 4, 10], state: "minecraft:tuff_bricks"},
        {pos: [4, 4, 0], state: "minecraft:polished_tuff"},
        {pos: [4, 4, 1], state: "minecraft:polished_tuff"},
        {pos: [4, 4, 2], state: "minecraft:polished_tuff"},
        {pos: [4, 4, 3], state: "minecraft:polished_tuff"},
        {pos: [4, 4, 4], state: "minecraft:polished_tuff"},
        {pos: [4, 4, 5], state: "minecraft:polished_tuff"},
        {pos: [4, 4, 6], state: "minecraft:polished_tuff"},
        {pos: [4, 4, 7], state: "minecraft:polished_tuff"},
        {pos: [4, 4, 8], state: "minecraft:polished_tuff"},
        {pos: [4, 4, 9], state: "minecraft:tuff_bricks"},
        {pos: [4, 4, 10], state: "minecraft:tuff_bricks"},
        {pos: [5, 4, 1], state: "minecraft:polished_tuff"},
        {pos: [5, 4, 2], state: "minecraft:polished_tuff"},
        {pos: [5, 4, 3], state: "minecraft:polished_tuff"},
        {pos: [5, 4, 4], state: "minecraft:polished_tuff"},
        {pos: [5, 4, 5], state: "minecraft:polished_tuff"},
        {pos: [5, 4, 6], state: "minecraft:polished_tuff"},
        {pos: [5, 4, 7], state: "minecraft:polished_tuff"},
        {pos: [5, 4, 8], state: "minecraft:polished_tuff"},
        {pos: [5, 4, 9], state: "minecraft:tuff_bricks"},
        {pos: [5, 4, 10], state: "minecraft:tuff_bricks"},
        {pos: [6, 4, 1], state: "minecraft:polished_tuff"},
        {pos: [6, 4, 2], state: "minecraft:polished_tuff"},
        {pos: [6, 4, 3], state: "minecraft:polished_tuff"},
        {pos: [6, 4, 4], state: "minecraft:polished_tuff"},
        {pos: [6, 4, 5], state: "minecraft:polished_tuff"},
        {pos: [6, 4, 6], state: "minecraft:polished_tuff"},
        {pos: [6, 4, 7], state: "minecraft:polished_tuff"},
        {pos: [6, 4, 8], state: "minecraft:tuff_bricks"},
        {pos: [6, 4, 9], state: "minecraft:tuff_bricks"},
        {pos: [6, 4, 10], state: "minecraft:tuff_bricks"},
        {pos: [7, 4, 1], state: "minecraft:polished_tuff"},
        {pos: [7, 4, 2], state: "minecraft:polished_tuff"},
        {pos: [7, 4, 3], state: "minecraft:polished_tuff"},
        {pos: [7, 4, 4], state: "minecraft:polished_tuff"},
        {pos: [7, 4, 5], state: "minecraft:polished_tuff"},
        {pos: [7, 4, 6], state: "minecraft:polished_tuff"},
        {pos: [7, 4, 7], state: "minecraft:tuff_bricks"},
        {pos: [7, 4, 8], state: "minecraft:tuff_bricks"},
        {pos: [7, 4, 9], state: "minecraft:tuff_bricks"},
        {pos: [7, 4, 10], state: "minecraft:tuff_bricks"},
        {pos: [8, 4, 1], state: "minecraft:polished_tuff"},
        {pos: [8, 4, 2], state: "minecraft:polished_tuff"},
        {pos: [8, 4, 3], state: "minecraft:polished_tuff"},
        {pos: [8, 4, 4], state: "minecraft:polished_tuff"},
        {pos: [8, 4, 5], state: "minecraft:polished_tuff"},
        {pos: [8, 4, 6], state: "minecraft:tuff_bricks"},
        {pos: [8, 4, 7], state: "minecraft:tuff_bricks"},
        {pos: [8, 4, 8], state: "minecraft:tuff_bricks"},
        {pos: [8, 4, 9], state: "minecraft:tuff_bricks"},
        {pos: [9, 4, 0], state: "minecraft:tuff_bricks"},
        {pos: [9, 4, 1], state: "minecraft:polished_tuff"},
        {pos: [9, 4, 2], state: "minecraft:polished_tuff"},
        {pos: [9, 4, 3], state: "minecraft:polished_tuff"},
        {pos: [9, 4, 4], state: "minecraft:tuff_bricks"},
        {pos: [9, 4, 5], state: "minecraft:tuff_bricks"},
        {pos: [9, 4, 6], state: "minecraft:tuff_bricks"},
        {pos: [9, 4, 7], state: "minecraft:tuff_bricks"},
        {pos: [9, 4, 8], state: "minecraft:tuff_bricks"},
        {pos: [10, 4, 0], state: "minecraft:tuff_bricks"},
        {pos: [10, 4, 1], state: "minecraft:tuff_bricks"},
        {pos: [10, 4, 2], state: "minecraft:tuff_bricks"},
        {pos: [10, 4, 3], state: "minecraft:tuff_bricks"},
        {pos: [10, 4, 4], state: "minecraft:tuff_bricks"},
        {pos: [10, 4, 5], state: "minecraft:tuff_bricks"},
        {pos: [10, 4, 6], state: "minecraft:tuff_bricks"},
        {pos: [10, 4, 7], state: "minecraft:tuff_bricks"},
        {pos: [0, 5, 2], state: "minecraft:waxed_copper_block"},
        {pos: [0, 5, 3], state: "minecraft:waxed_copper_block"},
        {pos: [0, 5, 4], state: "minecraft:waxed_copper_block"},
        {pos: [0, 5, 9], state: "minecraft:waxed_copper_block"},
        {pos: [0, 5, 10], state: "minecraft:waxed_copper_block"},
        {pos: [1, 5, 1], state: "minecraft:waxed_oxidized_copper"},
        {pos: [1, 5, 2], state: "minecraft:waxed_oxidized_copper"},
        {pos: [1, 5, 3], state: "minecraft:waxed_oxidized_copper"},
        {pos: [1, 5, 4], state: "minecraft:waxed_copper_block"},
        {pos: [1, 5, 8], state: "minecraft:waxed_copper_block"},
        {pos: [1, 5, 9], state: "minecraft:waxed_oxidized_copper"},
        {pos: [1, 5, 10], state: "minecraft:waxed_copper_block"},
        {pos: [2, 5, 0], state: "minecraft:waxed_oxidized_copper"},
        {pos: [2, 5, 1], state: "minecraft:waxed_oxidized_copper"},
        {pos: [2, 5, 2], state: "minecraft:waxed_oxidized_copper"},
        {pos: [2, 5, 3], state: "minecraft:waxed_oxidized_copper"},
        {pos: [2, 5, 4], state: "minecraft:waxed_copper_block"},
        {pos: [2, 5, 8], state: "minecraft:waxed_copper_block"},
        {pos: [2, 5, 9], state: "minecraft:waxed_oxidized_copper"},
        {pos: [2, 5, 10], state: "minecraft:waxed_copper_block"},
        {pos: [3, 5, 0], state: "minecraft:waxed_oxidized_copper"},
        {pos: [3, 5, 1], state: "minecraft:waxed_oxidized_copper"},
        {pos: [3, 5, 2], state: "minecraft:waxed_oxidized_copper"},
        {pos: [3, 5, 3], state: "minecraft:waxed_oxidized_copper"},
        {pos: [3, 5, 4], state: "minecraft:waxed_copper_block"},
        {pos: [3, 5, 8], state: "minecraft:waxed_copper_block"},
        {pos: [3, 5, 9], state: "minecraft:waxed_oxidized_copper"},
        {pos: [3, 5, 10], state: "minecraft:waxed_copper_block"},
        {pos: [4, 5, 0], state: "minecraft:waxed_oxidized_copper"},
        {pos: [4, 5, 1], state: "minecraft:waxed_oxidized_copper"},
        {pos: [4, 5, 2], state: "minecraft:waxed_oxidized_copper"},
        {pos: [4, 5, 3], state: "minecraft:waxed_oxidized_copper"},
        {pos: [4, 5, 4], state: "minecraft:waxed_copper_block"},
        {pos: [4, 5, 5], state: "minecraft:waxed_copper_block"},
        {pos: [4, 5, 6], state: "minecraft:waxed_copper_block"},
        {pos: [4, 5, 7], state: "minecraft:waxed_copper_block"},
        {pos: [4, 5, 8], state: "minecraft:waxed_copper_block"},
        {pos: [4, 5, 9], state: "minecraft:waxed_copper_block"},
        {pos: [4, 5, 10], state: "minecraft:waxed_copper_block"},
        {pos: [5, 5, 1], state: "minecraft:waxed_copper_block"},
        {pos: [5, 5, 2], state: "minecraft:waxed_oxidized_copper"},
        {pos: [5, 5, 3], state: "minecraft:waxed_oxidized_copper"},
        {pos: [5, 5, 4], state: "minecraft:waxed_oxidized_copper"},
        {pos: [5, 5, 5], state: "minecraft:waxed_oxidized_copper"},
        {pos: [5, 5, 6], state: "minecraft:waxed_oxidized_copper"},
        {pos: [5, 5, 7], state: "minecraft:waxed_oxidized_copper"},
        {pos: [5, 5, 8], state: "minecraft:waxed_oxidized_copper"},
        {pos: [5, 5, 9], state: "minecraft:waxed_copper_block"},
        {pos: [5, 5, 10], state: "minecraft:tuff_bricks"},
        {pos: [6, 5, 1], state: "minecraft:waxed_copper_block"},
        {pos: [6, 5, 2], state: "minecraft:tuff_bricks"},
        {pos: [6, 5, 3], state: "minecraft:tuff_bricks"},
        {pos: [6, 5, 4], state: "minecraft:waxed_oxidized_copper"},
        {pos: [6, 5, 5], state: "minecraft:waxed_oxidized_copper"},
        {pos: [6, 5, 6], state: "minecraft:waxed_oxidized_copper"},
        {pos: [6, 5, 7], state: "minecraft:waxed_oxidized_copper"},
        {pos: [6, 5, 8], state: "minecraft:tuff_bricks"},
        {pos: [6, 5, 9], state: "minecraft:waxed_copper_block"},
        {pos: [6, 5, 10], state: "minecraft:tuff_bricks"},
        {pos: [7, 5, 1], state: "minecraft:waxed_copper_block"},
        {pos: [7, 5, 2], state: "minecraft:tuff_bricks"},
        {pos: [7, 5, 3], state: "minecraft:tuff_bricks"},
        {pos: [7, 5, 4], state: "minecraft:tuff_bricks"},
        {pos: [7, 5, 5], state: "minecraft:tuff_bricks"},
        {pos: [7, 5, 6], state: "minecraft:tuff_bricks"},
        {pos: [7, 5, 7], state: "minecraft:tuff_bricks"},
        {pos: [7, 5, 8], state: "minecraft:tuff_bricks"},
        {pos: [7, 5, 9], state: "minecraft:tuff_bricks"},
        {pos: [7, 5, 10], state: "minecraft:tuff_bricks"},
        {pos: [8, 5, 1], state: "minecraft:waxed_copper_block"},
        {pos: [8, 5, 2], state: "minecraft:tuff_bricks"},
        {pos: [8, 5, 3], state: "minecraft:tuff_bricks"},
        {pos: [8, 5, 4], state: "minecraft:tuff_bricks"},
        {pos: [8, 5, 5], state: "minecraft:tuff_bricks"},
        {pos: [8, 5, 6], state: "minecraft:tuff_bricks"},
        {pos: [8, 5, 7], state: "minecraft:tuff_bricks"},
        {pos: [8, 5, 8], state: "minecraft:tuff_bricks"},
        {pos: [8, 5, 9], state: "minecraft:tuff_bricks"},
        {pos: [9, 5, 0], state: "minecraft:waxed_copper_block"},
        {pos: [9, 5, 1], state: "minecraft:tuff_bricks"},
        {pos: [9, 5, 2], state: "minecraft:tuff_bricks"},
        {pos: [9, 5, 3], state: "minecraft:tuff_bricks"},
        {pos: [9, 5, 4], state: "minecraft:tuff_bricks"},
        {pos: [9, 5, 5], state: "minecraft:tuff_bricks"},
        {pos: [9, 5, 6], state: "minecraft:tuff_bricks"},
        {pos: [9, 5, 7], state: "minecraft:tuff_bricks"},
        {pos: [9, 5, 8], state: "minecraft:tuff_bricks"},
        {pos: [10, 5, 0], state: "minecraft:waxed_copper_block"},
        {pos: [10, 5, 1], state: "minecraft:tuff_bricks"},
        {pos: [10, 5, 2], state: "minecraft:tuff_bricks"},
        {pos: [10, 5, 3], state: "minecraft:tuff_bricks"},
        {pos: [10, 5, 4], state: "minecraft:tuff_bricks"},
        {pos: [10, 5, 5], state: "minecraft:tuff_bricks"},
        {pos: [10, 5, 6], state: "minecraft:tuff_bricks"},
        {pos: [10, 5, 7], state: "minecraft:tuff_bricks"},
        {pos: [0, 6, 9], state: "minecraft:tuff_bricks"},
        {pos: [0, 6, 10], state: "minecraft:tuff_bricks"},
        {pos: [1, 6, 10], state: "minecraft:tuff_bricks"},
        {pos: [2, 6, 10], state: "minecraft:tuff_bricks"},
        {pos: [3, 6, 10], state: "minecraft:tuff_bricks"},
        {pos: [4, 6, 9], state: "minecraft:tuff_bricks"},
        {pos: [4, 6, 10], state: "minecraft:tuff_bricks"},
        {pos: [5, 6, 9], state: "minecraft:tuff_bricks"},
        {pos: [5, 6, 10], state: "minecraft:tuff_bricks"},
        {pos: [6, 6, 1], state: "minecraft:tuff_bricks"},
        {pos: [6, 6, 2], state: "minecraft:tuff_bricks"},
        {pos: [6, 6, 3], state: "minecraft:tuff_bricks"},
        {pos: [6, 6, 8], state: "minecraft:tuff_bricks"},
        {pos: [6, 6, 9], state: "minecraft:tuff_bricks"},
        {pos: [6, 6, 10], state: "minecraft:tuff_bricks"},
        {pos: [7, 6, 1], state: "minecraft:tuff_bricks"},
        {pos: [7, 6, 2], state: "minecraft:tuff_bricks"},
        {pos: [7, 6, 3], state: "minecraft:tuff_bricks"},
        {pos: [7, 6, 4], state: "minecraft:tuff_bricks"},
        {pos: [7, 6, 5], state: "minecraft:tuff_bricks"},
        {pos: [7, 6, 6], state: "minecraft:tuff_bricks"},
        {pos: [7, 6, 7], state: "minecraft:tuff_bricks"},
        {pos: [7, 6, 8], state: "minecraft:tuff_bricks"},
        {pos: [7, 6, 9], state: "minecraft:tuff_bricks"},
        {pos: [7, 6, 10], state: "minecraft:tuff_bricks"},
        {pos: [8, 6, 1], state: "minecraft:tuff_bricks"},
        {pos: [8, 6, 2], state: "minecraft:tuff_bricks"},
        {pos: [8, 6, 3], state: "minecraft:tuff_bricks"},
        {pos: [8, 6, 4], state: "minecraft:tuff_bricks"},
        {pos: [8, 6, 5], state: "minecraft:tuff_bricks"},
        {pos: [8, 6, 6], state: "minecraft:tuff_bricks"},
        {pos: [8, 6, 7], state: "minecraft:tuff_bricks"},
        {pos: [8, 6, 8], state: "minecraft:tuff_bricks"},
        {pos: [8, 6, 9], state: "minecraft:tuff_bricks"},
        {pos: [9, 6, 0], state: "minecraft:tuff_bricks"},
        {pos: [9, 6, 1], state: "minecraft:tuff_bricks"},
        {pos: [9, 6, 2], state: "minecraft:tuff_bricks"},
        {pos: [9, 6, 3], state: "minecraft:tuff_bricks"},
        {pos: [9, 6, 4], state: "minecraft:tuff_bricks"},
        {pos: [9, 6, 5], state: "minecraft:tuff_bricks"},
        {pos: [9, 6, 6], state: "minecraft:tuff_bricks"},
        {pos: [9, 6, 7], state: "minecraft:tuff_bricks"},
        {pos: [9, 6, 8], state: "minecraft:tuff_bricks"},
        {pos: [10, 6, 0], state: "minecraft:tuff_bricks"},
        {pos: [10, 6, 1], state: "minecraft:tuff_bricks"},
        {pos: [10, 6, 2], state: "minecraft:tuff_bricks"},
        {pos: [10, 6, 3], state: "minecraft:tuff_bricks"},
        {pos: [10, 6, 4], state: "minecraft:tuff_bricks"},
        {pos: [10, 6, 5], state: "minecraft:tuff_bricks"},
        {pos: [10, 6, 6], state: "minecraft:tuff_bricks"},
        {pos: [10, 6, 7], state: "minecraft:tuff_bricks"},
        {pos: [0, 7, 9], state: "minecraft:tuff_bricks"},
        {pos: [0, 7, 10], state: "minecraft:tuff_bricks"},
        {pos: [1, 7, 10], state: "minecraft:tuff_bricks"},
        {pos: [2, 7, 10], state: "minecraft:tuff_bricks"},
        {pos: [3, 7, 10], state: "minecraft:tuff_bricks"},
        {pos: [4, 7, 9], state: "minecraft:tuff_bricks"},
        {pos: [4, 7, 10], state: "minecraft:tuff_bricks"},
        {pos: [5, 7, 9], state: "minecraft:tuff_bricks"},
        {pos: [5, 7, 10], state: "minecraft:tuff_bricks"},
        {pos: [6, 7, 8], state: "minecraft:tuff_bricks"},
        {pos: [6, 7, 9], state: "minecraft:tuff_bricks"},
        {pos: [6, 7, 10], state: "minecraft:tuff_bricks"},
        {pos: [7, 7, 1], state: "minecraft:waxed_oxidized_copper"},
        {pos: [7, 7, 2], state: "minecraft:waxed_oxidized_copper"},
        {pos: [7, 7, 3], state: "minecraft:waxed_oxidized_copper"},
        {pos: [7, 7, 4], state: "minecraft:waxed_copper_block"},
        {pos: [7, 7, 5], state: "minecraft:waxed_copper_block"},
        {pos: [7, 7, 6], state: "minecraft:waxed_copper_block"},
        {pos: [7, 7, 7], state: "minecraft:tuff_bricks"},
        {pos: [7, 7, 8], state: "minecraft:tuff_bricks"},
        {pos: [7, 7, 9], state: "minecraft:tuff_bricks"},
        {pos: [7, 7, 10], state: "minecraft:tuff_bricks"},
        {pos: [8, 7, 1], state: "minecraft:waxed_oxidized_copper"},
        {pos: [8, 7, 2], state: "minecraft:waxed_oxidized_copper"},
        {pos: [8, 7, 3], state: "minecraft:waxed_oxidized_copper"},
        {pos: [8, 7, 4], state: "minecraft:waxed_oxidized_copper"},
        {pos: [8, 7, 5], state: "minecraft:waxed_oxidized_copper"},
        {pos: [8, 7, 6], state: "minecraft:tuff_bricks"},
        {pos: [8, 7, 7], state: "minecraft:tuff_bricks"},
        {pos: [8, 7, 8], state: "minecraft:tuff_bricks"},
        {pos: [8, 7, 9], state: "minecraft:tuff_bricks"},
        {pos: [9, 7, 0], state: "minecraft:tuff_bricks"},
        {pos: [9, 7, 1], state: "minecraft:waxed_oxidized_copper"},
        {pos: [9, 7, 2], state: "minecraft:waxed_oxidized_copper"},
        {pos: [9, 7, 3], state: "minecraft:waxed_oxidized_copper"},
        {pos: [9, 7, 4], state: "minecraft:tuff_bricks"},
        {pos: [9, 7, 5], state: "minecraft:tuff_bricks"},
        {pos: [9, 7, 6], state: "minecraft:tuff_bricks"},
        {pos: [9, 7, 7], state: "minecraft:tuff_bricks"},
        {pos: [9, 7, 8], state: "minecraft:tuff_bricks"},
        {pos: [10, 7, 0], state: "minecraft:tuff_bricks"},
        {pos: [10, 7, 1], state: "minecraft:tuff_bricks"},
        {pos: [10, 7, 2], state: "minecraft:tuff_bricks"},
        {pos: [10, 7, 3], state: "minecraft:tuff_bricks"},
        {pos: [10, 7, 4], state: "minecraft:tuff_bricks"},
        {pos: [10, 7, 5], state: "minecraft:tuff_bricks"},
        {pos: [10, 7, 6], state: "minecraft:tuff_bricks"},
        {pos: [10, 7, 7], state: "minecraft:tuff_bricks"},
        {pos: [0, 8, 9], state: "minecraft:chiseled_tuff_bricks"},
        {pos: [0, 8, 10], state: "minecraft:chiseled_tuff_bricks"},
        {pos: [1, 8, 10], state: "minecraft:chiseled_tuff_bricks"},
        {pos: [2, 8, 10], state: "minecraft:chiseled_tuff_bricks"},
        {pos: [3, 8, 10], state: "minecraft:chiseled_tuff_bricks"},
        {pos: [4, 8, 9], state: "minecraft:chiseled_tuff_bricks"},
        {pos: [4, 8, 10], state: "minecraft:chiseled_tuff_bricks"},
        {pos: [5, 8, 9], state: "minecraft:chiseled_tuff_bricks"},
        {pos: [5, 8, 10], state: "minecraft:tuff_bricks"},
        {pos: [6, 8, 8], state: "minecraft:chiseled_tuff_bricks"},
        {pos: [6, 8, 9], state: "minecraft:chiseled_tuff_bricks"},
        {pos: [6, 8, 10], state: "minecraft:tuff_bricks"},
        {pos: [7, 8, 7], state: "minecraft:chiseled_tuff_bricks"},
        {pos: [7, 8, 8], state: "minecraft:chiseled_tuff_bricks"},
        {pos: [7, 8, 9], state: "minecraft:tuff_bricks"},
        {pos: [7, 8, 10], state: "minecraft:tuff_bricks"},
        {pos: [8, 8, 6], state: "minecraft:chiseled_tuff_bricks"},
        {pos: [8, 8, 7], state: "minecraft:chiseled_tuff_bricks"},
        {pos: [8, 8, 8], state: "minecraft:tuff_bricks"},
        {pos: [8, 8, 9], state: "minecraft:tuff_bricks"},
        {pos: [9, 8, 0], state: "minecraft:chiseled_tuff_bricks"},
        {pos: [9, 8, 4], state: "minecraft:chiseled_tuff_bricks"},
        {pos: [9, 8, 5], state: "minecraft:chiseled_tuff_bricks"},
        {pos: [9, 8, 6], state: "minecraft:chiseled_tuff_bricks"},
        {pos: [9, 8, 7], state: "minecraft:tuff_bricks"},
        {pos: [9, 8, 8], state: "minecraft:tuff_bricks"},
        {pos: [10, 8, 0], state: "minecraft:chiseled_tuff_bricks"},
        {pos: [10, 8, 1], state: "minecraft:chiseled_tuff_bricks"},
        {pos: [10, 8, 2], state: "minecraft:chiseled_tuff_bricks"},
        {pos: [10, 8, 3], state: "minecraft:chiseled_tuff_bricks"},
        {pos: [10, 8, 4], state: "minecraft:chiseled_tuff_bricks"},
        {pos: [10, 8, 5], state: "minecraft:tuff_bricks"},
        {pos: [10, 8, 6], state: "minecraft:tuff_bricks"},
        {pos: [10, 8, 7], state: "minecraft:tuff_bricks"},
        {pos: [0, 9, 9], state: "minecraft:tuff_bricks"},
        {pos: [0, 9, 10], state: "minecraft:tuff_bricks"},
        {pos: [1, 9, 10], state: "minecraft:tuff_bricks"},
        {pos: [2, 9, 10], state: "minecraft:waxed_copper_bulb{powered:false,lit:true}"},
        {pos: [3, 9, 10], state: "minecraft:tuff_bricks"},
        {pos: [4, 9, 9], state: "minecraft:tuff_bricks"},
        {pos: [4, 9, 10], state: "minecraft:tuff_bricks"},
        {pos: [5, 9, 9], state: "minecraft:tuff_bricks"},
        {pos: [5, 9, 10], state: "minecraft:tuff_bricks"},
        {pos: [6, 9, 8], state: "minecraft:tuff_bricks"},
        {pos: [6, 9, 9], state: "minecraft:tuff_bricks"},
        {pos: [6, 9, 10], state: "minecraft:tuff_bricks"},
        {pos: [7, 9, 7], state: "minecraft:waxed_copper_bulb{powered:false,lit:true}"},
        {pos: [7, 9, 8], state: "minecraft:tuff_bricks"},
        {pos: [7, 9, 9], state: "minecraft:tuff_bricks"},
        {pos: [7, 9, 10], state: "minecraft:tuff_bricks"},
        {pos: [8, 9, 6], state: "minecraft:tuff_bricks"},
        {pos: [8, 9, 7], state: "minecraft:tuff_bricks"},
        {pos: [8, 9, 8], state: "minecraft:tuff_bricks"},
        {pos: [8, 9, 9], state: "minecraft:tuff_bricks"},
        {pos: [9, 9, 0], state: "minecraft:tuff_bricks"},
        {pos: [9, 9, 4], state: "minecraft:tuff_bricks"},
        {pos: [9, 9, 5], state: "minecraft:tuff_bricks"},
        {pos: [9, 9, 6], state: "minecraft:tuff_bricks"},
        {pos: [9, 9, 7], state: "minecraft:tuff_bricks"},
        {pos: [9, 9, 8], state: "minecraft:tuff_bricks"},
        {pos: [10, 9, 0], state: "minecraft:tuff_bricks"},
        {pos: [10, 9, 1], state: "minecraft:tuff_bricks"},
        {pos: [10, 9, 2], state: "minecraft:waxed_copper_bulb{powered:false,lit:true}"},
        {pos: [10, 9, 3], state: "minecraft:tuff_bricks"},
        {pos: [10, 9, 4], state: "minecraft:tuff_bricks"},
        {pos: [10, 9, 5], state: "minecraft:tuff_bricks"},
        {pos: [10, 9, 6], state: "minecraft:tuff_bricks"},
        {pos: [10, 9, 7], state: "minecraft:tuff_bricks"},
        {pos: [0, 10, 9], state: "minecraft:waxed_copper_block"},
        {pos: [0, 10, 10], state: "minecraft:waxed_copper_block"},
        {pos: [1, 10, 10], state: "minecraft:waxed_copper_block"},
        {pos: [2, 10, 10], state: "minecraft:waxed_copper_block"},
        {pos: [3, 10, 10], state: "minecraft:waxed_copper_block"},
        {pos: [4, 10, 9], state: "minecraft:waxed_copper_block"},
        {pos: [4, 10, 10], state: "minecraft:waxed_copper_block"},
        {pos: [5, 10, 9], state: "minecraft:waxed_copper_block"},
        {pos: [5, 10, 10], state: "minecraft:tuff_bricks"},
        {pos: [6, 10, 8], state: "minecraft:waxed_copper_block"},
        {pos: [6, 10, 9], state: "minecraft:waxed_copper_block"},
        {pos: [6, 10, 10], state: "minecraft:tuff_bricks"},
        {pos: [7, 10, 7], state: "minecraft:waxed_copper_block"},
        {pos: [7, 10, 8], state: "minecraft:waxed_copper_block"},
        {pos: [7, 10, 9], state: "minecraft:tuff_bricks"},
        {pos: [7, 10, 10], state: "minecraft:tuff_bricks"},
        {pos: [8, 10, 6], state: "minecraft:waxed_copper_block"},
        {pos: [8, 10, 7], state: "minecraft:waxed_copper_block"},
        {pos: [8, 10, 8], state: "minecraft:tuff_bricks"},
        {pos: [8, 10, 9], state: "minecraft:tuff_bricks"},
        {pos: [9, 10, 0], state: "minecraft:waxed_copper_block"},
        {pos: [9, 10, 4], state: "minecraft:waxed_copper_block"},
        {pos: [9, 10, 5], state: "minecraft:waxed_copper_block"},
        {pos: [9, 10, 6], state: "minecraft:waxed_copper_block"},
        {pos: [9, 10, 7], state: "minecraft:tuff_bricks"},
        {pos: [9, 10, 8], state: "minecraft:tuff_bricks"},
        {pos: [10, 10, 0], state: "minecraft:waxed_copper_block"},
        {pos: [10, 10, 1], state: "minecraft:waxed_copper_block"},
        {pos: [10, 10, 2], state: "minecraft:waxed_copper_block"},
        {pos: [10, 10, 3], state: "minecraft:waxed_copper_block"},
        {pos: [10, 10, 4], state: "minecraft:waxed_copper_block"},
        {pos: [10, 10, 5], state: "minecraft:tuff_bricks"},
        {pos: [10, 10, 6], state: "minecraft:tuff_bricks"},
        {pos: [10, 10, 7], state: "minecraft:tuff_bricks"},
        {pos: [0, 11, 0], state: "minecraft:polished_tuff"},
        {pos: [0, 11, 1], state: "minecraft:polished_tuff"},
        {pos: [0, 11, 2], state: "minecraft:polished_tuff"},
        {pos: [0, 11, 3], state: "minecraft:polished_tuff"},
        {pos: [0, 11, 4], state: "minecraft:polished_tuff"},
        {pos: [0, 11, 5], state: "minecraft:polished_tuff"},
        {pos: [0, 11, 6], state: "minecraft:polished_tuff"},
        {pos: [0, 11, 7], state: "minecraft:polished_tuff"},
        {pos: [0, 11, 8], state: "minecraft:polished_tuff"},
        {pos: [0, 11, 9], state: "minecraft:tuff_bricks"},
        {pos: [0, 11, 10], state: "minecraft:tuff_bricks"},
        {pos: [1, 11, 0], state: "minecraft:polished_tuff"},
        {pos: [1, 11, 1], state: "minecraft:polished_tuff"},
        {pos: [1, 11, 2], state: "minecraft:polished_tuff"},
        {pos: [1, 11, 3], state: "minecraft:polished_tuff"},
        {pos: [1, 11, 4], state: "minecraft:polished_tuff"},
        {pos: [1, 11, 5], state: "minecraft:polished_tuff"},
        {pos: [1, 11, 6], state: "minecraft:polished_tuff"},
        {pos: [1, 11, 7], state: "minecraft:polished_tuff"},
        {pos: [1, 11, 8], state: "minecraft:polished_tuff"},
        {pos: [1, 11, 9], state: "minecraft:polished_tuff"},
        {pos: [1, 11, 10], state: "minecraft:tuff_bricks"},
        {pos: [2, 11, 0], state: "minecraft:polished_tuff"},
        {pos: [2, 11, 1], state: "minecraft:polished_tuff"},
        {pos: [2, 11, 2], state: "minecraft:polished_tuff"},
        {pos: [2, 11, 3], state: "minecraft:polished_tuff"},
        {pos: [2, 11, 4], state: "minecraft:polished_tuff"},
        {pos: [2, 11, 5], state: "minecraft:polished_tuff"},
        {pos: [2, 11, 6], state: "minecraft:polished_tuff"},
        {pos: [2, 11, 7], state: "minecraft:polished_tuff"},
        {pos: [2, 11, 8], state: "minecraft:polished_tuff"},
        {pos: [2, 11, 9], state: "minecraft:polished_tuff"},
        {pos: [2, 11, 10], state: "minecraft:tuff_bricks"},
        {pos: [3, 11, 0], state: "minecraft:polished_tuff"},
        {pos: [3, 11, 1], state: "minecraft:polished_tuff"},
        {pos: [3, 11, 2], state: "minecraft:polished_tuff"},
        {pos: [3, 11, 3], state: "minecraft:polished_tuff"},
        {pos: [3, 11, 4], state: "minecraft:polished_tuff"},
        {pos: [3, 11, 5], state: "minecraft:polished_tuff"},
        {pos: [3, 11, 6], state: "minecraft:polished_tuff"},
        {pos: [3, 11, 7], state: "minecraft:polished_tuff"},
        {pos: [3, 11, 8], state: "minecraft:polished_tuff"},
        {pos: [3, 11, 9], state: "minecraft:polished_tuff"},
        {pos: [3, 11, 10], state: "minecraft:tuff_bricks"},
        {pos: [4, 11, 0], state: "minecraft:polished_tuff"},
        {pos: [4, 11, 1], state: "minecraft:polished_tuff"},
        {pos: [4, 11, 2], state: "minecraft:polished_tuff"},
        {pos: [4, 11, 3], state: "minecraft:polished_tuff"},
        {pos: [4, 11, 4], state: "minecraft:polished_tuff"},
        {pos: [4, 11, 5], state: "minecraft:polished_tuff"},
        {pos: [4, 11, 6], state: "minecraft:polished_tuff"},
        {pos: [4, 11, 7], state: "minecraft:polished_tuff"},
        {pos: [4, 11, 8], state: "minecraft:polished_tuff"},
        {pos: [4, 11, 9], state: "minecraft:tuff_bricks"},
        {pos: [4, 11, 10], state: "minecraft:tuff_bricks"},
        {pos: [5, 11, 0], state: "minecraft:polished_tuff"},
        {pos: [5, 11, 1], state: "minecraft:polished_tuff"},
        {pos: [5, 11, 2], state: "minecraft:polished_tuff"},
        {pos: [5, 11, 3], state: "minecraft:polished_tuff"},
        {pos: [5, 11, 4], state: "minecraft:polished_tuff"},
        {pos: [5, 11, 5], state: "minecraft:polished_tuff"},
        {pos: [5, 11, 6], state: "minecraft:polished_tuff"},
        {pos: [5, 11, 7], state: "minecraft:polished_tuff"},
        {pos: [5, 11, 8], state: "minecraft:polished_tuff"},
        {pos: [5, 11, 9], state: "minecraft:tuff_bricks"},
        {pos: [5, 11, 10], state: "minecraft:tuff_bricks"},
        {pos: [6, 11, 0], state: "minecraft:polished_tuff"},
        {pos: [6, 11, 1], state: "minecraft:polished_tuff"},
        {pos: [6, 11, 2], state: "minecraft:polished_tuff"},
        {pos: [6, 11, 3], state: "minecraft:polished_tuff"},
        {pos: [6, 11, 4], state: "minecraft:polished_tuff"},
        {pos: [6, 11, 5], state: "minecraft:polished_tuff"},
        {pos: [6, 11, 6], state: "minecraft:polished_tuff"},
        {pos: [6, 11, 7], state: "minecraft:polished_tuff"},
        {pos: [6, 11, 8], state: "minecraft:tuff_bricks"},
        {pos: [6, 11, 9], state: "minecraft:tuff_bricks"},
        {pos: [6, 11, 10], state: "minecraft:tuff_bricks"},
        {pos: [7, 11, 0], state: "minecraft:polished_tuff"},
        {pos: [7, 11, 1], state: "minecraft:polished_tuff"},
        {pos: [7, 11, 2], state: "minecraft:polished_tuff"},
        {pos: [7, 11, 3], state: "minecraft:polished_tuff"},
        {pos: [7, 11, 4], state: "minecraft:polished_tuff"},
        {pos: [7, 11, 5], state: "minecraft:polished_tuff"},
        {pos: [7, 11, 6], state: "minecraft:polished_tuff"},
        {pos: [7, 11, 7], state: "minecraft:tuff_bricks"},
        {pos: [7, 11, 8], state: "minecraft:tuff_bricks"},
        {pos: [7, 11, 9], state: "minecraft:tuff_bricks"},
        {pos: [7, 11, 10], state: "minecraft:tuff_bricks"},
        {pos: [8, 11, 0], state: "minecraft:polished_tuff"},
        {pos: [8, 11, 1], state: "minecraft:polished_tuff"},
        {pos: [8, 11, 2], state: "minecraft:polished_tuff"},
        {pos: [8, 11, 3], state: "minecraft:polished_tuff"},
        {pos: [8, 11, 4], state: "minecraft:polished_tuff"},
        {pos: [8, 11, 5], state: "minecraft:polished_tuff"},
        {pos: [8, 11, 6], state: "minecraft:tuff_bricks"},
        {pos: [8, 11, 7], state: "minecraft:tuff_bricks"},
        {pos: [8, 11, 8], state: "minecraft:tuff_bricks"},
        {pos: [8, 11, 9], state: "minecraft:tuff_bricks"},
        {pos: [9, 11, 0], state: "minecraft:tuff_bricks"},
        {pos: [9, 11, 1], state: "minecraft:polished_tuff"},
        {pos: [9, 11, 2], state: "minecraft:polished_tuff"},
        {pos: [9, 11, 3], state: "minecraft:polished_tuff"},
        {pos: [9, 11, 4], state: "minecraft:tuff_bricks"},
        {pos: [9, 11, 5], state: "minecraft:tuff_bricks"},
        {pos: [9, 11, 6], state: "minecraft:tuff_bricks"},
        {pos: [9, 11, 7], state: "minecraft:tuff_bricks"},
        {pos: [9, 11, 8], state: "minecraft:tuff_bricks"},
        {pos: [10, 11, 0], state: "minecraft:tuff_bricks"},
        {pos: [10, 11, 1], state: "minecraft:tuff_bricks"},
        {pos: [10, 11, 2], state: "minecraft:tuff_bricks"},
        {pos: [10, 11, 3], state: "minecraft:tuff_bricks"},
        {pos: [10, 11, 4], state: "minecraft:tuff_bricks"},
        {pos: [10, 11, 5], state: "minecraft:tuff_bricks"},
        {pos: [10, 11, 6], state: "minecraft:tuff_bricks"},
        {pos: [10, 11, 7], state: "minecraft:tuff_bricks"},
        {pos: [0, 1, 1], state: "minecraft:air"},
        {pos: [0, 1, 2], state: "minecraft:air"},
        {pos: [0, 1, 3], state: "minecraft:air"},
        {pos: [0, 1, 4], state: "minecraft:air"},
        {pos: [0, 1, 5], state: "minecraft:air"},
        {pos: [0, 1, 6], state: "minecraft:air"},
        {pos: [0, 1, 7], state: "minecraft:air"},
        {pos: [0, 1, 8], state: "minecraft:air"},
        {pos: [1, 1, 0], state: "minecraft:air"},
        {pos: [1, 1, 1], state: "minecraft:air"},
        {pos: [1, 1, 2], state: "minecraft:air"},
        {pos: [1, 1, 3], state: "minecraft:air"},
        {pos: [1, 1, 4], state: "minecraft:air"},
        {pos: [1, 1, 5], state: "minecraft:air"},
        {pos: [1, 1, 6], state: "minecraft:air"},
        {pos: [1, 1, 7], state: "minecraft:air"},
        {pos: [1, 1, 8], state: "minecraft:air"},
        {pos: [1, 1, 9], state: "minecraft:air"},
        {pos: [2, 1, 0], state: "minecraft:air"},
        {pos: [2, 1, 1], state: "minecraft:air"},
        {pos: [2, 1, 2], state: "minecraft:air"},
        {pos: [2, 1, 3], state: "minecraft:air"},
        {pos: [2, 1, 4], state: "minecraft:air"},
        {pos: [2, 1, 5], state: "minecraft:air"},
        {pos: [2, 1, 6], state: "minecraft:air"},
        {pos: [2, 1, 7], state: "minecraft:air"},
        {pos: [2, 1, 8], state: "minecraft:air"},
        {pos: [2, 1, 9], state: "minecraft:air"},
        {pos: [3, 1, 0], state: "minecraft:air"},
        {pos: [3, 1, 1], state: "minecraft:air"},
        {pos: [3, 1, 2], state: "minecraft:air"},
        {pos: [3, 1, 3], state: "minecraft:air"},
        {pos: [3, 1, 4], state: "minecraft:air"},
        {pos: [3, 1, 5], state: "minecraft:air"},
        {pos: [3, 1, 6], state: "minecraft:air"},
        {pos: [3, 1, 7], state: "minecraft:air"},
        {pos: [3, 1, 8], state: "minecraft:air"},
        {pos: [3, 1, 9], state: "minecraft:air"},
        {pos: [4, 1, 0], state: "minecraft:air"},
        {pos: [4, 1, 1], state: "minecraft:air"},
        {pos: [4, 1, 2], state: "minecraft:air"},
        {pos: [4, 1, 3], state: "minecraft:air"},
        {pos: [4, 1, 4], state: "minecraft:air"},
        {pos: [4, 1, 5], state: "minecraft:air"},
        {pos: [4, 1, 6], state: "minecraft:air"},
        {pos: [4, 1, 7], state: "minecraft:air"},
        {pos: [4, 1, 8], state: "minecraft:air"},
        {pos: [5, 1, 0], state: "minecraft:air"},
        {pos: [5, 1, 1], state: "minecraft:air"},
        {pos: [5, 1, 2], state: "minecraft:air"},
        {pos: [5, 1, 3], state: "minecraft:air"},
        {pos: [5, 1, 4], state: "minecraft:air"},
        {pos: [5, 1, 5], state: "minecraft:air"},
        {pos: [5, 1, 6], state: "minecraft:air"},
        {pos: [5, 1, 7], state: "minecraft:air"},
        {pos: [5, 1, 8], state: "minecraft:air"},
        {pos: [6, 1, 0], state: "minecraft:air"},
        {pos: [6, 1, 1], state: "minecraft:air"},
        {pos: [6, 1, 2], state: "minecraft:air"},
        {pos: [6, 1, 3], state: "minecraft:air"},
        {pos: [6, 1, 4], state: "minecraft:air"},
        {pos: [6, 1, 5], state: "minecraft:air"},
        {pos: [6, 1, 6], state: "minecraft:air"},
        {pos: [6, 1, 7], state: "minecraft:air"},
        {pos: [7, 1, 0], state: "minecraft:air"},
        {pos: [7, 1, 1], state: "minecraft:air"},
        {pos: [7, 1, 2], state: "minecraft:air"},
        {pos: [7, 1, 3], state: "minecraft:air"},
        {pos: [7, 1, 4], state: "minecraft:air"},
        {pos: [7, 1, 5], state: "minecraft:air"},
        {pos: [7, 1, 6], state: "minecraft:air"},
        {pos: [8, 1, 0], state: "minecraft:air"},
        {pos: [8, 1, 1], state: "minecraft:air"},
        {pos: [8, 1, 2], state: "minecraft:air"},
        {pos: [8, 1, 3], state: "minecraft:air"},
        {pos: [8, 1, 4], state: "minecraft:air"},
        {pos: [8, 1, 5], state: "minecraft:air"},
        {pos: [9, 1, 1], state: "minecraft:air"},
        {pos: [9, 1, 2], state: "minecraft:air"},
        {pos: [9, 1, 3], state: "minecraft:air"},
        {pos: [0, 2, 1], state: "minecraft:air"},
        {pos: [0, 2, 2], state: "minecraft:air"},
        {pos: [0, 2, 3], state: "minecraft:air"},
        {pos: [0, 2, 4], state: "minecraft:air"},
        {pos: [0, 2, 5], state: "minecraft:air"},
        {pos: [0, 2, 6], state: "minecraft:air"},
        {pos: [0, 2, 7], state: "minecraft:air"},
        {pos: [0, 2, 8], state: "minecraft:air"},
        {pos: [1, 2, 0], state: "minecraft:air"},
        {pos: [1, 2, 1], state: "minecraft:air"},
        {pos: [1, 2, 2], state: "minecraft:air"},
        {pos: [1, 2, 3], state: "minecraft:air"},
        {pos: [1, 2, 4], state: "minecraft:air"},
        {pos: [1, 2, 5], state: "minecraft:air"},
        {pos: [1, 2, 6], state: "minecraft:air"},
        {pos: [1, 2, 7], state: "minecraft:air"},
        {pos: [1, 2, 8], state: "minecraft:air"},
        {pos: [1, 2, 9], state: "minecraft:air"},
        {pos: [2, 2, 0], state: "minecraft:air"},
        {pos: [2, 2, 1], state: "minecraft:air"},
        {pos: [2, 2, 2], state: "minecraft:air"},
        {pos: [2, 2, 3], state: "minecraft:air"},
        {pos: [2, 2, 4], state: "minecraft:air"},
        {pos: [2, 2, 5], state: "minecraft:air"},
        {pos: [2, 2, 6], state: "minecraft:air"},
        {pos: [2, 2, 7], state: "minecraft:air"},
        {pos: [2, 2, 8], state: "minecraft:air"},
        {pos: [2, 2, 9], state: "minecraft:air"},
        {pos: [3, 2, 0], state: "minecraft:air"},
        {pos: [3, 2, 1], state: "minecraft:air"},
        {pos: [3, 2, 2], state: "minecraft:air"},
        {pos: [3, 2, 3], state: "minecraft:air"},
        {pos: [3, 2, 4], state: "minecraft:air"},
        {pos: [3, 2, 5], state: "minecraft:air"},
        {pos: [3, 2, 6], state: "minecraft:air"},
        {pos: [3, 2, 7], state: "minecraft:air"},
        {pos: [3, 2, 8], state: "minecraft:air"},
        {pos: [3, 2, 9], state: "minecraft:air"},
        {pos: [4, 2, 0], state: "minecraft:air"},
        {pos: [4, 2, 1], state: "minecraft:air"},
        {pos: [4, 2, 2], state: "minecraft:air"},
        {pos: [4, 2, 3], state: "minecraft:air"},
        {pos: [4, 2, 4], state: "minecraft:air"},
        {pos: [4, 2, 5], state: "minecraft:air"},
        {pos: [4, 2, 6], state: "minecraft:air"},
        {pos: [4, 2, 7], state: "minecraft:air"},
        {pos: [4, 2, 8], state: "minecraft:air"},
        {pos: [5, 2, 0], state: "minecraft:air"},
        {pos: [5, 2, 1], state: "minecraft:air"},
        {pos: [5, 2, 2], state: "minecraft:air"},
        {pos: [5, 2, 3], state: "minecraft:air"},
        {pos: [5, 2, 4], state: "minecraft:air"},
        {pos: [5, 2, 5], state: "minecraft:air"},
        {pos: [5, 2, 6], state: "minecraft:air"},
        {pos: [5, 2, 7], state: "minecraft:air"},
        {pos: [5, 2, 8], state: "minecraft:air"},
        {pos: [6, 2, 0], state: "minecraft:air"},
        {pos: [6, 2, 1], state: "minecraft:air"},
        {pos: [6, 2, 2], state: "minecraft:air"},
        {pos: [6, 2, 3], state: "minecraft:air"},
        {pos: [6, 2, 4], state: "minecraft:air"},
        {pos: [6, 2, 5], state: "minecraft:air"},
        {pos: [6, 2, 6], state: "minecraft:air"},
        {pos: [6, 2, 7], state: "minecraft:air"},
        {pos: [7, 2, 0], state: "minecraft:air"},
        {pos: [7, 2, 1], state: "minecraft:air"},
        {pos: [7, 2, 2], state: "minecraft:air"},
        {pos: [7, 2, 3], state: "minecraft:air"},
        {pos: [7, 2, 4], state: "minecraft:air"},
        {pos: [7, 2, 5], state: "minecraft:air"},
        {pos: [7, 2, 6], state: "minecraft:air"},
        {pos: [8, 2, 0], state: "minecraft:air"},
        {pos: [8, 2, 1], state: "minecraft:air"},
        {pos: [8, 2, 2], state: "minecraft:air"},
        {pos: [8, 2, 3], state: "minecraft:air"},
        {pos: [8, 2, 4], state: "minecraft:air"},
        {pos: [8, 2, 5], state: "minecraft:air"},
        {pos: [9, 2, 1], state: "minecraft:air"},
        {pos: [9, 2, 2], state: "minecraft:air"},
        {pos: [9, 2, 3], state: "minecraft:air"},
        {pos: [0, 3, 1], state: "minecraft:air"},
        {pos: [0, 3, 2], state: "minecraft:air"},
        {pos: [0, 3, 3], state: "minecraft:air"},
        {pos: [0, 3, 4], state: "minecraft:air"},
        {pos: [0, 3, 5], state: "minecraft:air"},
        {pos: [0, 3, 6], state: "minecraft:air"},
        {pos: [0, 3, 7], state: "minecraft:air"},
        {pos: [0, 3, 8], state: "minecraft:air"},
        {pos: [1, 3, 0], state: "minecraft:air"},
        {pos: [1, 3, 1], state: "minecraft:air"},
        {pos: [1, 3, 2], state: "minecraft:air"},
        {pos: [1, 3, 3], state: "minecraft:air"},
        {pos: [1, 3, 4], state: "minecraft:air"},
        {pos: [1, 3, 5], state: "minecraft:air"},
        {pos: [1, 3, 6], state: "minecraft:air"},
        {pos: [1, 3, 7], state: "minecraft:air"},
        {pos: [1, 3, 8], state: "minecraft:air"},
        {pos: [1, 3, 9], state: "minecraft:air"},
        {pos: [2, 3, 0], state: "minecraft:air"},
        {pos: [2, 3, 1], state: "minecraft:air"},
        {pos: [2, 3, 2], state: "minecraft:air"},
        {pos: [2, 3, 3], state: "minecraft:air"},
        {pos: [2, 3, 4], state: "minecraft:air"},
        {pos: [2, 3, 5], state: "minecraft:air"},
        {pos: [2, 3, 6], state: "minecraft:air"},
        {pos: [2, 3, 7], state: "minecraft:air"},
        {pos: [2, 3, 8], state: "minecraft:air"},
        {pos: [2, 3, 9], state: "minecraft:air"},
        {pos: [3, 3, 0], state: "minecraft:air"},
        {pos: [3, 3, 1], state: "minecraft:air"},
        {pos: [3, 3, 2], state: "minecraft:air"},
        {pos: [3, 3, 3], state: "minecraft:air"},
        {pos: [3, 3, 4], state: "minecraft:air"},
        {pos: [3, 3, 5], state: "minecraft:air"},
        {pos: [3, 3, 6], state: "minecraft:air"},
        {pos: [3, 3, 7], state: "minecraft:air"},
        {pos: [3, 3, 8], state: "minecraft:air"},
        {pos: [3, 3, 9], state: "minecraft:air"},
        {pos: [4, 3, 0], state: "minecraft:air"},
        {pos: [4, 3, 1], state: "minecraft:air"},
        {pos: [4, 3, 2], state: "minecraft:air"},
        {pos: [4, 3, 3], state: "minecraft:air"},
        {pos: [4, 3, 4], state: "minecraft:air"},
        {pos: [4, 3, 5], state: "minecraft:air"},
        {pos: [4, 3, 6], state: "minecraft:air"},
        {pos: [4, 3, 7], state: "minecraft:air"},
        {pos: [4, 3, 8], state: "minecraft:air"},
        {pos: [5, 3, 0], state: "minecraft:air"},
        {pos: [5, 3, 1], state: "minecraft:air"},
        {pos: [5, 3, 2], state: "minecraft:air"},
        {pos: [5, 3, 3], state: "minecraft:air"},
        {pos: [5, 3, 4], state: "minecraft:air"},
        {pos: [5, 3, 5], state: "minecraft:air"},
        {pos: [5, 3, 6], state: "minecraft:air"},
        {pos: [5, 3, 7], state: "minecraft:air"},
        {pos: [5, 3, 8], state: "minecraft:air"},
        {pos: [6, 3, 0], state: "minecraft:air"},
        {pos: [6, 3, 1], state: "minecraft:air"},
        {pos: [6, 3, 2], state: "minecraft:air"},
        {pos: [6, 3, 3], state: "minecraft:air"},
        {pos: [6, 3, 4], state: "minecraft:air"},
        {pos: [6, 3, 5], state: "minecraft:air"},
        {pos: [6, 3, 6], state: "minecraft:air"},
        {pos: [6, 3, 7], state: "minecraft:air"},
        {pos: [7, 3, 0], state: "minecraft:air"},
        {pos: [7, 3, 1], state: "minecraft:air"},
        {pos: [7, 3, 2], state: "minecraft:air"},
        {pos: [7, 3, 3], state: "minecraft:air"},
        {pos: [7, 3, 4], state: "minecraft:air"},
        {pos: [7, 3, 5], state: "minecraft:air"},
        {pos: [7, 3, 6], state: "minecraft:air"},
        {pos: [8, 3, 0], state: "minecraft:air"},
        {pos: [8, 3, 1], state: "minecraft:air"},
        {pos: [8, 3, 2], state: "minecraft:air"},
        {pos: [8, 3, 3], state: "minecraft:air"},
        {pos: [8, 3, 4], state: "minecraft:air"},
        {pos: [8, 3, 5], state: "minecraft:air"},
        {pos: [9, 3, 1], state: "minecraft:air"},
        {pos: [9, 3, 2], state: "minecraft:air"},
        {pos: [9, 3, 3], state: "minecraft:air"},
        {pos: [0, 4, 0], state: "minecraft:waxed_cut_copper_stairs{half:bottom,waterlogged:false,shape:straight,facing:east}"},
        {pos: [0, 4, 5], state: "minecraft:air"},
        {pos: [0, 4, 6], state: "minecraft:air"},
        {pos: [0, 4, 7], state: "minecraft:air"},
        {pos: [0, 4, 8], state: "minecraft:air"},
        {pos: [1, 4, 5], state: "minecraft:air"},
        {pos: [1, 4, 6], state: "minecraft:air"},
        {pos: [1, 4, 7], state: "minecraft:air"},
        {pos: [2, 4, 5], state: "minecraft:air"},
        {pos: [2, 4, 6], state: "minecraft:air"},
        {pos: [2, 4, 7], state: "minecraft:air"},
        {pos: [3, 4, 5], state: "minecraft:air"},
        {pos: [3, 4, 6], state: "minecraft:air"},
        {pos: [3, 4, 7], state: "minecraft:air"},
        {pos: [5, 4, 0], state: "minecraft:air"},
        {pos: [6, 4, 0], state: "minecraft:air"},
        {pos: [7, 4, 0], state: "minecraft:air"},
        {pos: [8, 4, 0], state: "minecraft:air"},
        {pos: [0, 5, 0], state: "minecraft:air"},
        {pos: [0, 5, 5], state: "minecraft:air"},
        {pos: [0, 5, 6], state: "minecraft:air"},
        {pos: [0, 5, 7], state: "minecraft:air"},
        {pos: [0, 5, 8], state: "minecraft:air"},
        {pos: [1, 5, 0], state: "minecraft:waxed_cut_copper_stairs{half:bottom,waterlogged:false,shape:straight,facing:east}"},
        {pos: [1, 5, 5], state: "minecraft:air"},
        {pos: [1, 5, 6], state: "minecraft:air"},
        {pos: [1, 5, 7], state: "minecraft:air"},
        {pos: [2, 5, 5], state: "minecraft:air"},
        {pos: [2, 5, 6], state: "minecraft:air"},
        {pos: [2, 5, 7], state: "minecraft:air"},
        {pos: [3, 5, 5], state: "minecraft:air"},
        {pos: [3, 5, 6], state: "minecraft:air"},
        {pos: [3, 5, 7], state: "minecraft:air"},
        {pos: [5, 5, 0], state: "minecraft:air"},
        {pos: [6, 5, 0], state: "minecraft:air"},
        {pos: [7, 5, 0], state: "minecraft:air"},
        {pos: [8, 5, 0], state: "minecraft:air"},
        {pos: [0, 6, 0], state: "minecraft:air"},
        {pos: [0, 6, 1], state: "minecraft:air"},
        {pos: [0, 6, 2], state: "minecraft:air"},
        {pos: [0, 6, 3], state: "minecraft:air"},
        {pos: [0, 6, 4], state: "minecraft:air"},
        {pos: [0, 6, 5], state: "minecraft:air"},
        {pos: [0, 6, 6], state: "minecraft:air"},
        {pos: [0, 6, 7], state: "minecraft:air"},
        {pos: [0, 6, 8], state: "minecraft:air"},
        {pos: [1, 6, 0], state: "minecraft:air"},
        {pos: [1, 6, 1], state: "minecraft:air"},
        {pos: [1, 6, 2], state: "minecraft:air"},
        {pos: [1, 6, 3], state: "minecraft:air"},
        {pos: [1, 6, 4], state: "minecraft:air"},
        {pos: [1, 6, 5], state: "minecraft:air"},
        {pos: [1, 6, 6], state: "minecraft:air"},
        {pos: [1, 6, 7], state: "minecraft:air"},
        {pos: [1, 6, 8], state: "minecraft:air"},
        {pos: [1, 6, 9], state: "minecraft:air"},
        {pos: [2, 6, 0], state: "minecraft:air"},
        {pos: [2, 6, 1], state: "minecraft:air"},
        {pos: [2, 6, 2], state: "minecraft:air"},
        {pos: [2, 6, 3], state: "minecraft:air"},
        {pos: [2, 6, 4], state: "minecraft:air"},
        {pos: [2, 6, 5], state: "minecraft:air"},
        {pos: [2, 6, 6], state: "minecraft:air"},
        {pos: [2, 6, 7], state: "minecraft:air"},
        {pos: [2, 6, 8], state: "minecraft:air"},
        {pos: [2, 6, 9], state: "minecraft:air"},
        {pos: [3, 6, 0], state: "minecraft:air"},
        {pos: [3, 6, 1], state: "minecraft:air"},
        {pos: [3, 6, 2], state: "minecraft:air"},
        {pos: [3, 6, 3], state: "minecraft:air"},
        {pos: [3, 6, 4], state: "minecraft:air"},
        {pos: [3, 6, 5], state: "minecraft:air"},
        {pos: [3, 6, 6], state: "minecraft:air"},
        {pos: [3, 6, 7], state: "minecraft:air"},
        {pos: [3, 6, 8], state: "minecraft:air"},
        {pos: [3, 6, 9], state: "minecraft:air"},
        {pos: [4, 6, 0], state: "minecraft:air"},
        {pos: [4, 6, 1], state: "minecraft:air"},
        {pos: [4, 6, 2], state: "minecraft:air"},
        {pos: [4, 6, 3], state: "minecraft:air"},
        {pos: [4, 6, 4], state: "minecraft:air"},
        {pos: [4, 6, 5], state: "minecraft:air"},
        {pos: [4, 6, 6], state: "minecraft:air"},
        {pos: [4, 6, 7], state: "minecraft:air"},
        {pos: [4, 6, 8], state: "minecraft:air"},
        {pos: [5, 6, 0], state: "minecraft:air"},
        {pos: [5, 6, 1], state: "minecraft:waxed_oxidized_cut_copper_stairs{half:bottom,waterlogged:false,shape:straight,facing:east}"},
        {pos: [5, 6, 2], state: "minecraft:waxed_oxidized_cut_copper_stairs{half:bottom,waterlogged:false,shape:straight,facing:east}"},
        {pos: [5, 6, 3], state: "minecraft:waxed_oxidized_cut_copper_stairs{half:bottom,waterlogged:false,shape:straight,facing:east}"},
        {pos: [5, 6, 4], state: "minecraft:air"},
        {pos: [5, 6, 5], state: "minecraft:air"},
        {pos: [5, 6, 6], state: "minecraft:air"},
        {pos: [5, 6, 7], state: "minecraft:air"},
        {pos: [5, 6, 8], state: "minecraft:air"},
        {pos: [6, 6, 0], state: "minecraft:air"},
        {pos: [6, 6, 4], state: "minecraft:air"},
        {pos: [6, 6, 5], state: "minecraft:air"},
        {pos: [6, 6, 6], state: "minecraft:air"},
        {pos: [6, 6, 7], state: "minecraft:air"},
        {pos: [7, 6, 0], state: "minecraft:air"},
        {pos: [8, 6, 0], state: "minecraft:air"},
        {pos: [0, 7, 0], state: "minecraft:air"},
        {pos: [0, 7, 1], state: "minecraft:air"},
        {pos: [0, 7, 2], state: "minecraft:air"},
        {pos: [0, 7, 3], state: "minecraft:air"},
        {pos: [0, 7, 4], state: "minecraft:air"},
        {pos: [0, 7, 5], state: "minecraft:air"},
        {pos: [0, 7, 6], state: "minecraft:air"},
        {pos: [0, 7, 7], state: "minecraft:air"},
        {pos: [0, 7, 8], state: "minecraft:air"},
        {pos: [1, 7, 0], state: "minecraft:air"},
        {pos: [1, 7, 1], state: "minecraft:air"},
        {pos: [1, 7, 2], state: "minecraft:air"},
        {pos: [1, 7, 3], state: "minecraft:air"},
        {pos: [1, 7, 4], state: "minecraft:air"},
        {pos: [1, 7, 5], state: "minecraft:air"},
        {pos: [1, 7, 6], state: "minecraft:air"},
        {pos: [1, 7, 7], state: "minecraft:air"},
        {pos: [1, 7, 8], state: "minecraft:air"},
        {pos: [1, 7, 9], state: "minecraft:air"},
        {pos: [2, 7, 0], state: "minecraft:air"},
        {pos: [2, 7, 1], state: "minecraft:air"},
        {pos: [2, 7, 2], state: "minecraft:air"},
        {pos: [2, 7, 3], state: "minecraft:air"},
        {pos: [2, 7, 4], state: "minecraft:air"},
        {pos: [2, 7, 5], state: "minecraft:air"},
        {pos: [2, 7, 6], state: "minecraft:air"},
        {pos: [2, 7, 7], state: "minecraft:air"},
        {pos: [2, 7, 8], state: "minecraft:air"},
        {pos: [2, 7, 9], state: "minecraft:air"},
        {pos: [3, 7, 0], state: "minecraft:air"},
        {pos: [3, 7, 1], state: "minecraft:air"},
        {pos: [3, 7, 2], state: "minecraft:air"},
        {pos: [3, 7, 3], state: "minecraft:air"},
        {pos: [3, 7, 4], state: "minecraft:air"},
        {pos: [3, 7, 5], state: "minecraft:air"},
        {pos: [3, 7, 6], state: "minecraft:air"},
        {pos: [3, 7, 7], state: "minecraft:air"},
        {pos: [3, 7, 8], state: "minecraft:air"},
        {pos: [3, 7, 9], state: "minecraft:air"},
        {pos: [4, 7, 0], state: "minecraft:air"},
        {pos: [4, 7, 1], state: "minecraft:air"},
        {pos: [4, 7, 2], state: "minecraft:air"},
        {pos: [4, 7, 3], state: "minecraft:air"},
        {pos: [4, 7, 4], state: "minecraft:air"},
        {pos: [4, 7, 5], state: "minecraft:air"},
        {pos: [4, 7, 6], state: "minecraft:air"},
        {pos: [4, 7, 7], state: "minecraft:air"},
        {pos: [4, 7, 8], state: "minecraft:air"},
        {pos: [5, 7, 0], state: "minecraft:air"},
        {pos: [5, 7, 1], state: "minecraft:air"},
        {pos: [5, 7, 2], state: "minecraft:air"},
        {pos: [5, 7, 3], state: "minecraft:air"},
        {pos: [5, 7, 4], state: "minecraft:air"},
        {pos: [5, 7, 5], state: "minecraft:air"},
        {pos: [5, 7, 6], state: "minecraft:air"},
        {pos: [5, 7, 7], state: "minecraft:air"},
        {pos: [5, 7, 8], state: "minecraft:air"},
        {pos: [6, 7, 0], state: "minecraft:air"},
        {pos: [6, 7, 1], state: "minecraft:waxed_oxidized_cut_copper_stairs{half:bottom,waterlogged:false,shape:straight,facing:east}"},
        {pos: [6, 7, 2], state: "minecraft:waxed_oxidized_cut_copper_stairs{half:bottom,waterlogged:false,shape:straight,facing:east}"},
        {pos: [6, 7, 3], state: "minecraft:waxed_oxidized_cut_copper_stairs{half:bottom,waterlogged:false,shape:straight,facing:east}"},
        {pos: [6, 7, 4], state: "minecraft:air"},
        {pos: [6, 7, 5], state: "minecraft:air"},
        {pos: [6, 7, 6], state: "minecraft:air"},
        {pos: [6, 7, 7], state: "minecraft:air"},
        {pos: [7, 7, 0], state: "minecraft:air"},
        {pos: [8, 7, 0], state: "minecraft:air"},
        {pos: [0, 8, 0], state: "minecraft:air"},
        {pos: [0, 8, 1], state: "minecraft:air"},
        {pos: [0, 8, 2], state: "minecraft:air"},
        {pos: [0, 8, 3], state: "minecraft:air"},
        {pos: [0, 8, 4], state: "minecraft:air"},
        {pos: [0, 8, 5], state: "minecraft:air"},
        {pos: [0, 8, 6], state: "minecraft:air"},
        {pos: [0, 8, 7], state: "minecraft:air"},
        {pos: [0, 8, 8], state: "minecraft:air"},
        {pos: [1, 8, 0], state: "minecraft:air"},
        {pos: [1, 8, 1], state: "minecraft:air"},
        {pos: [1, 8, 2], state: "minecraft:air"},
        {pos: [1, 8, 3], state: "minecraft:air"},
        {pos: [1, 8, 4], state: "minecraft:air"},
        {pos: [1, 8, 5], state: "minecraft:air"},
        {pos: [1, 8, 6], state: "minecraft:air"},
        {pos: [1, 8, 7], state: "minecraft:air"},
        {pos: [1, 8, 8], state: "minecraft:air"},
        {pos: [1, 8, 9], state: "minecraft:air"},
        {pos: [2, 8, 0], state: "minecraft:air"},
        {pos: [2, 8, 1], state: "minecraft:air"},
        {pos: [2, 8, 2], state: "minecraft:air"},
        {pos: [2, 8, 3], state: "minecraft:air"},
        {pos: [2, 8, 4], state: "minecraft:air"},
        {pos: [2, 8, 5], state: "minecraft:air"},
        {pos: [2, 8, 6], state: "minecraft:air"},
        {pos: [2, 8, 7], state: "minecraft:air"},
        {pos: [2, 8, 8], state: "minecraft:air"},
        {pos: [2, 8, 9], state: "minecraft:air"},
        {pos: [3, 8, 0], state: "minecraft:air"},
        {pos: [3, 8, 1], state: "minecraft:air"},
        {pos: [3, 8, 2], state: "minecraft:air"},
        {pos: [3, 8, 3], state: "minecraft:air"},
        {pos: [3, 8, 4], state: "minecraft:air"},
        {pos: [3, 8, 5], state: "minecraft:air"},
        {pos: [3, 8, 6], state: "minecraft:air"},
        {pos: [3, 8, 7], state: "minecraft:air"},
        {pos: [3, 8, 8], state: "minecraft:air"},
        {pos: [3, 8, 9], state: "minecraft:air"},
        {pos: [4, 8, 0], state: "minecraft:air"},
        {pos: [4, 8, 1], state: "minecraft:air"},
        {pos: [4, 8, 2], state: "minecraft:air"},
        {pos: [4, 8, 3], state: "minecraft:air"},
        {pos: [4, 8, 4], state: "minecraft:air"},
        {pos: [4, 8, 5], state: "minecraft:air"},
        {pos: [4, 8, 6], state: "minecraft:air"},
        {pos: [4, 8, 7], state: "minecraft:air"},
        {pos: [4, 8, 8], state: "minecraft:air"},
        {pos: [5, 8, 0], state: "minecraft:air"},
        {pos: [5, 8, 1], state: "minecraft:air"},
        {pos: [5, 8, 2], state: "minecraft:air"},
        {pos: [5, 8, 3], state: "minecraft:air"},
        {pos: [5, 8, 4], state: "minecraft:air"},
        {pos: [5, 8, 5], state: "minecraft:air"},
        {pos: [5, 8, 6], state: "minecraft:air"},
        {pos: [5, 8, 7], state: "minecraft:air"},
        {pos: [5, 8, 8], state: "minecraft:air"},
        {pos: [6, 8, 0], state: "minecraft:air"},
        {pos: [6, 8, 1], state: "minecraft:air"},
        {pos: [6, 8, 2], state: "minecraft:air"},
        {pos: [6, 8, 3], state: "minecraft:air"},
        {pos: [6, 8, 4], state: "minecraft:air"},
        {pos: [6, 8, 5], state: "minecraft:air"},
        {pos: [6, 8, 6], state: "minecraft:air"},
        {pos: [6, 8, 7], state: "minecraft:air"},
        {pos: [7, 8, 0], state: "minecraft:air"},
        {pos: [7, 8, 1], state: "minecraft:air"},
        {pos: [7, 8, 2], state: "minecraft:air"},
        {pos: [7, 8, 3], state: "minecraft:air"},
        {pos: [7, 8, 4], state: "minecraft:air"},
        {pos: [7, 8, 5], state: "minecraft:air"},
        {pos: [7, 8, 6], state: "minecraft:air"},
        {pos: [8, 8, 0], state: "minecraft:air"},
        {pos: [8, 8, 1], state: "minecraft:air"},
        {pos: [8, 8, 2], state: "minecraft:air"},
        {pos: [8, 8, 3], state: "minecraft:air"},
        {pos: [8, 8, 4], state: "minecraft:air"},
        {pos: [8, 8, 5], state: "minecraft:air"},
        {pos: [9, 8, 1], state: "minecraft:air"},
        {pos: [9, 8, 2], state: "minecraft:air"},
        {pos: [9, 8, 3], state: "minecraft:air"},
        {pos: [0, 9, 0], state: "minecraft:air"},
        {pos: [0, 9, 1], state: "minecraft:air"},
        {pos: [0, 9, 2], state: "minecraft:air"},
        {pos: [0, 9, 3], state: "minecraft:air"},
        {pos: [0, 9, 4], state: "minecraft:air"},
        {pos: [0, 9, 5], state: "minecraft:air"},
        {pos: [0, 9, 6], state: "minecraft:air"},
        {pos: [0, 9, 7], state: "minecraft:air"},
        {pos: [0, 9, 8], state: "minecraft:air"},
        {pos: [1, 9, 0], state: "minecraft:air"},
        {pos: [1, 9, 1], state: "minecraft:air"},
        {pos: [1, 9, 2], state: "minecraft:air"},
        {pos: [1, 9, 3], state: "minecraft:air"},
        {pos: [1, 9, 4], state: "minecraft:air"},
        {pos: [1, 9, 5], state: "minecraft:air"},
        {pos: [1, 9, 6], state: "minecraft:air"},
        {pos: [1, 9, 7], state: "minecraft:air"},
        {pos: [1, 9, 8], state: "minecraft:air"},
        {pos: [1, 9, 9], state: "minecraft:air"},
        {pos: [2, 9, 0], state: "minecraft:air"},
        {pos: [2, 9, 1], state: "minecraft:air"},
        {pos: [2, 9, 2], state: "minecraft:air"},
        {pos: [2, 9, 3], state: "minecraft:air"},
        {pos: [2, 9, 4], state: "minecraft:air"},
        {pos: [2, 9, 5], state: "minecraft:air"},
        {pos: [2, 9, 6], state: "minecraft:air"},
        {pos: [2, 9, 7], state: "minecraft:air"},
        {pos: [2, 9, 8], state: "minecraft:air"},
        {pos: [2, 9, 9], state: "minecraft:air"},
        {pos: [3, 9, 0], state: "minecraft:air"},
        {pos: [3, 9, 1], state: "minecraft:air"},
        {pos: [3, 9, 2], state: "minecraft:air"},
        {pos: [3, 9, 3], state: "minecraft:air"},
        {pos: [3, 9, 4], state: "minecraft:air"},
        {pos: [3, 9, 5], state: "minecraft:air"},
        {pos: [3, 9, 6], state: "minecraft:air"},
        {pos: [3, 9, 7], state: "minecraft:air"},
        {pos: [3, 9, 8], state: "minecraft:air"},
        {pos: [3, 9, 9], state: "minecraft:air"},
        {pos: [4, 9, 0], state: "minecraft:air"},
        {pos: [4, 9, 1], state: "minecraft:air"},
        {pos: [4, 9, 2], state: "minecraft:air"},
        {pos: [4, 9, 3], state: "minecraft:air"},
        {pos: [4, 9, 4], state: "minecraft:air"},
        {pos: [4, 9, 5], state: "minecraft:air"},
        {pos: [4, 9, 6], state: "minecraft:air"},
        {pos: [4, 9, 7], state: "minecraft:air"},
        {pos: [4, 9, 8], state: "minecraft:air"},
        {pos: [5, 9, 0], state: "minecraft:air"},
        {pos: [5, 9, 1], state: "minecraft:air"},
        {pos: [5, 9, 2], state: "minecraft:air"},
        {pos: [5, 9, 3], state: "minecraft:air"},
        {pos: [5, 9, 4], state: "minecraft:air"},
        {pos: [5, 9, 5], state: "minecraft:air"},
        {pos: [5, 9, 6], state: "minecraft:air"},
        {pos: [5, 9, 7], state: "minecraft:air"},
        {pos: [5, 9, 8], state: "minecraft:air"},
        {pos: [6, 9, 0], state: "minecraft:air"},
        {pos: [6, 9, 1], state: "minecraft:air"},
        {pos: [6, 9, 2], state: "minecraft:air"},
        {pos: [6, 9, 3], state: "minecraft:air"},
        {pos: [6, 9, 4], state: "minecraft:air"},
        {pos: [6, 9, 5], state: "minecraft:air"},
        {pos: [6, 9, 6], state: "minecraft:air"},
        {pos: [6, 9, 7], state: "minecraft:air"},
        {pos: [7, 9, 0], state: "minecraft:air"},
        {pos: [7, 9, 1], state: "minecraft:air"},
        {pos: [7, 9, 3], state: "minecraft:air"},
        {pos: [7, 9, 4], state: "minecraft:air"},
        {pos: [7, 9, 5], state: "minecraft:air"},
        {pos: [7, 9, 6], state: "minecraft:air"},
        {pos: [8, 9, 0], state: "minecraft:air"},
        {pos: [8, 9, 1], state: "minecraft:air"},
        {pos: [8, 9, 2], state: "minecraft:air"},
        {pos: [8, 9, 3], state: "minecraft:air"},
        {pos: [8, 9, 4], state: "minecraft:air"},
        {pos: [8, 9, 5], state: "minecraft:air"},
        {pos: [9, 9, 1], state: "minecraft:air"},
        {pos: [9, 9, 2], state: "minecraft:air"},
        {pos: [9, 9, 3], state: "minecraft:air"},
        {pos: [0, 10, 0], state: "minecraft:air"},
        {pos: [0, 10, 1], state: "minecraft:air"},
        {pos: [0, 10, 2], state: "minecraft:air"},
        {pos: [0, 10, 3], state: "minecraft:air"},
        {pos: [0, 10, 4], state: "minecraft:air"},
        {pos: [0, 10, 5], state: "minecraft:air"},
        {pos: [0, 10, 6], state: "minecraft:air"},
        {pos: [0, 10, 7], state: "minecraft:air"},
        {pos: [0, 10, 8], state: "minecraft:air"},
        {pos: [1, 10, 0], state: "minecraft:air"},
        {pos: [1, 10, 1], state: "minecraft:air"},
        {pos: [1, 10, 2], state: "minecraft:air"},
        {pos: [1, 10, 3], state: "minecraft:air"},
        {pos: [1, 10, 4], state: "minecraft:air"},
        {pos: [1, 10, 5], state: "minecraft:air"},
        {pos: [1, 10, 6], state: "minecraft:air"},
        {pos: [1, 10, 7], state: "minecraft:air"},
        {pos: [1, 10, 8], state: "minecraft:air"},
        {pos: [1, 10, 9], state: "minecraft:air"},
        {pos: [2, 10, 0], state: "minecraft:air"},
        {pos: [2, 10, 1], state: "minecraft:air"},
        {pos: [2, 10, 2], state: "minecraft:air"},
        {pos: [2, 10, 3], state: "minecraft:air"},
        {pos: [2, 10, 4], state: "minecraft:air"},
        {pos: [2, 10, 5], state: "minecraft:air"},
        {pos: [2, 10, 6], state: "minecraft:air"},
        {pos: [2, 10, 7], state: "minecraft:air"},
        {pos: [2, 10, 8], state: "minecraft:air"},
        {pos: [2, 10, 9], state: "minecraft:air"},
        {pos: [3, 10, 0], state: "minecraft:air"},
        {pos: [3, 10, 1], state: "minecraft:air"},
        {pos: [3, 10, 2], state: "minecraft:air"},
        {pos: [3, 10, 3], state: "minecraft:air"},
        {pos: [3, 10, 4], state: "minecraft:air"},
        {pos: [3, 10, 5], state: "minecraft:air"},
        {pos: [3, 10, 6], state: "minecraft:air"},
        {pos: [3, 10, 7], state: "minecraft:air"},
        {pos: [3, 10, 8], state: "minecraft:air"},
        {pos: [3, 10, 9], state: "minecraft:air"},
        {pos: [4, 10, 0], state: "minecraft:air"},
        {pos: [4, 10, 1], state: "minecraft:air"},
        {pos: [4, 10, 2], state: "minecraft:air"},
        {pos: [4, 10, 3], state: "minecraft:air"},
        {pos: [4, 10, 4], state: "minecraft:air"},
        {pos: [4, 10, 5], state: "minecraft:air"},
        {pos: [4, 10, 6], state: "minecraft:air"},
        {pos: [4, 10, 7], state: "minecraft:air"},
        {pos: [4, 10, 8], state: "minecraft:air"},
        {pos: [5, 10, 0], state: "minecraft:air"},
        {pos: [5, 10, 1], state: "minecraft:air"},
        {pos: [5, 10, 2], state: "minecraft:air"},
        {pos: [5, 10, 3], state: "minecraft:air"},
        {pos: [5, 10, 4], state: "minecraft:air"},
        {pos: [5, 10, 5], state: "minecraft:air"},
        {pos: [5, 10, 6], state: "minecraft:air"},
        {pos: [5, 10, 7], state: "minecraft:air"},
        {pos: [5, 10, 8], state: "minecraft:air"},
        {pos: [6, 10, 0], state: "minecraft:air"},
        {pos: [6, 10, 1], state: "minecraft:air"},
        {pos: [6, 10, 2], state: "minecraft:air"},
        {pos: [6, 10, 3], state: "minecraft:air"},
        {pos: [6, 10, 4], state: "minecraft:air"},
        {pos: [6, 10, 5], state: "minecraft:air"},
        {pos: [6, 10, 6], state: "minecraft:air"},
        {pos: [6, 10, 7], state: "minecraft:air"},
        {pos: [7, 10, 0], state: "minecraft:air"},
        {pos: [7, 10, 1], state: "minecraft:air"},
        {pos: [7, 10, 2], state: "minecraft:air"},
        {pos: [7, 10, 3], state: "minecraft:air"},
        {pos: [7, 10, 4], state: "minecraft:air"},
        {pos: [7, 10, 5], state: "minecraft:air"},
        {pos: [7, 10, 6], state: "minecraft:air"},
        {pos: [8, 10, 0], state: "minecraft:air"},
        {pos: [8, 10, 1], state: "minecraft:air"},
        {pos: [8, 10, 2], state: "minecraft:air"},
        {pos: [8, 10, 3], state: "minecraft:air"},
        {pos: [8, 10, 4], state: "minecraft:air"},
        {pos: [8, 10, 5], state: "minecraft:air"},
        {pos: [9, 10, 1], state: "minecraft:air"},
        {pos: [9, 10, 2], state: "minecraft:air"},
        {pos: [9, 10, 3], state: "minecraft:air"},
        {pos: [0, 5, 1], state: "minecraft:jigsaw{orientation:west_up}", nbt: {final_state: "minecraft:waxed_copper_block", id: "minecraft:jigsaw", joint: "rollable", name: "minecraft:quadrant", placement_priority: 0, pool: "minecraft:empty", selection_priority: 0, target: "minecraft:empty"}},
        {pos: [7, 9, 2], state: "minecraft:jigsaw{orientation:east_up}", nbt: {final_state: "minecraft:air", id: "minecraft:jigsaw", joint: "aligned", name: "minecraft:empty", placement_priority: 0, pool: "minecraft:trial_chambers/reward/all", selection_priority: 0, target: "minecraft:reward_connector"}}
    ],
    entities: [],
    palette: [
        "minecraft:magma_block",
        "minecraft:waxed_oxidized_cut_copper",
        "minecraft:waxed_oxidized_copper",
        "minecraft:tuff_bricks",
        "minecraft:waxed_copper_grate{waterlogged:false}",
        "minecraft:waxed_copper_block",
        "minecraft:waxed_copper_bulb{powered:false,lit:true}",
        "minecraft:chiseled_tuff_bricks",
        "minecraft:polished_tuff",
        "minecraft:air",
        "minecraft:waxed_cut_copper_stairs{half:bottom,waterlogged:false,shape:straight,facing:east}",
        "minecraft:waxed_oxidized_cut_copper_stairs{half:bottom,waterlogged:false,shape:straight,facing:east}",
        "minecraft:jigsaw{orientation:west_up}",
        "minecraft:jigsaw{orientation:east_up}"
    ]
}