{
    size: [31, 19, 16],
    data: [
        {pos: [6, 0, 1], state: "minecraft:polished_blackstone_bricks"},
        {pos: [6, 0, 2], state: "minecraft:polished_blackstone_bricks"},
        {pos: [6, 0, 3], state: "minecraft:polished_blackstone_bricks"},
        {pos: [6, 0, 4], state: "minecraft:polished_blackstone_bricks"},
        {pos: [6, 0, 5], state: "minecraft:polished_blackstone_bricks"},
        {pos: [6, 0, 6], state: "minecraft:polished_blackstone_bricks"},
        {pos: [6, 0, 7], state: "minecraft:polished_blackstone_bricks"},
        {pos: [6, 0, 9], state: "minecraft:polished_blackstone_bricks"},
        {pos: [6, 0, 10], state: "minecraft:polished_blackstone_bricks"},
        {pos: [6, 0, 11], state: "minecraft:polished_blackstone_bricks"},
        {pos: [6, 0, 12], state: "minecraft:polished_blackstone_bricks"},
        {pos: [6, 0, 13], state: "minecraft:polished_blackstone_bricks"},
        {pos: [7, 0, 1], state: "minecraft:polished_blackstone_bricks"},
        {pos: [7, 0, 2], state: "minecraft:polished_blackstone_bricks"},
        {pos: [7, 0, 3], state: "minecraft:polished_blackstone_bricks"},
        {pos: [7, 0, 4], state: "minecraft:polished_blackstone_bricks"},
        {pos: [7, 0, 5], state: "minecraft:polished_blackstone_bricks"},
        {pos: [7, 0, 6], state: "minecraft:polished_blackstone_bricks"},
        {pos: [7, 0, 7], state: "minecraft:polished_blackstone_bricks"},
        {pos: [7, 0, 8], state: "minecraft:polished_blackstone_bricks"},
        {pos: [7, 0, 9], state: "minecraft:polished_blackstone_bricks"},
        {pos: [7, 0, 10], state: "minecraft:polished_blackstone_bricks"},
        {pos: [7, 0, 11], state: "minecraft:polished_blackstone_bricks"},
        {pos: [7, 0, 12], state: "minecraft:polished_blackstone_bricks"},
        {pos: [7, 0, 13], state: "minecraft:polished_blackstone_bricks"},
        {pos: [8, 0, 1], state: "minecraft:polished_blackstone_bricks"},
        {pos: [8, 0, 2], state: "minecraft:polished_blackstone_bricks"},
        {pos: [8, 0, 3], state: "minecraft:polished_blackstone_bricks"},
        {pos: [8, 0, 4], state: "minecraft:polished_blackstone_bricks"},
        {pos: [8, 0, 5], state: "minecraft:polished_blackstone_bricks"},
        {pos: [8, 0, 6], state: "minecraft:polished_blackstone_bricks"},
        {pos: [8, 0, 7], state: "minecraft:polished_blackstone_bricks"},
        {pos: [8, 0, 8], state: "minecraft:polished_blackstone_bricks"},
        {pos: [8, 0, 9], state: "minecraft:polished_blackstone_bricks"},
        {pos: [8, 0, 10], state: "minecraft:polished_blackstone_bricks"},
        {pos: [8, 0, 11], state: "minecraft:polished_blackstone_bricks"},
        {pos: [8, 0, 12], state: "minecraft:polished_blackstone_bricks"},
        {pos: [8, 0, 13], state: "minecraft:polished_blackstone_bricks"},
        {pos: [24, 0, 7], state: "minecraft:polished_blackstone_bricks"},
        {pos: [24, 0, 9], state: "minecraft:blackstone"},
        {pos: [24, 0, 10], state: "minecraft:blackstone"},
        {pos: [24, 0, 11], state: "minecraft:polished_blackstone_bricks"},
        {pos: [24, 0, 12], state: "minecraft:polished_blackstone_bricks"},
        {pos: [24, 0, 13], state: "minecraft:polished_blackstone_bricks"},
        {pos: [24, 0, 14], state: "minecraft:polished_blackstone_bricks"},
        {pos: [25, 0, 3], state: "minecraft:polished_blackstone_bricks"},
        {pos: [25, 0, 4], state: "minecraft:blackstone"},
        {pos: [25, 0, 5], state: "minecraft:blackstone"},
        {pos: [25, 0, 7], state: "minecraft:polished_blackstone_bricks"},
        {pos: [25, 0, 8], state: "minecraft:polished_blackstone_bricks"},
        {pos: [25, 0, 9], state: "minecraft:polished_blackstone_bricks"},
        {pos: [25, 0, 10], state: "minecraft:polished_blackstone_bricks"},
        {pos: [25, 0, 11], state: "minecraft:polished_blackstone_bricks"},
        {pos: [25, 0, 12], state: "minecraft:polished_blackstone_bricks"},
        {pos: [25, 0, 13], state: "minecraft:polished_blackstone_bricks"},
        {pos: [25, 0, 14], state: "minecraft:polished_blackstone_bricks"},
        {pos: [26, 0, 3], state: "minecraft:polished_blackstone_bricks"},
        {pos: [26, 0, 4], state: "minecraft:polished_blackstone_bricks"},
        {pos: [26, 0, 5], state: "minecraft:polished_blackstone_bricks"},
        {pos: [26, 0, 6], state: "minecraft:polished_blackstone_bricks"},
        {pos: [26, 0, 7], state: "minecraft:polished_blackstone_bricks"},
        {pos: [26, 0, 8], state: "minecraft:polished_blackstone_bricks"},
        {pos: [26, 0, 9], state: "minecraft:polished_blackstone_bricks"},
        {pos: [26, 0, 10], state: "minecraft:polished_blackstone_bricks"},
        {pos: [26, 0, 11], state: "minecraft:polished_blackstone_bricks"},
        {pos: [26, 0, 12], state: "minecraft:polished_blackstone_bricks"},
        {pos: [26, 0, 13], state: "minecraft:polished_blackstone_bricks"},
        {pos: [26, 0, 14], state: "minecraft:polished_blackstone_bricks"},
        {pos: [26, 0, 15], state: "minecraft:polished_blackstone_bricks"},
        {pos: [6, 1, 1], state: "minecraft:polished_blackstone_bricks"},
        {pos: [6, 1, 2], state: "minecraft:polished_blackstone_bricks"},
        {pos: [6, 1, 3], state: "minecraft:polished_blackstone_bricks"},
        {pos: [6, 1, 4], state: "minecraft:polished_blackstone_bricks"},
        {pos: [6, 1, 6], state: "minecraft:blackstone"},
        {pos: [6, 1, 7], state: "minecraft:blackstone"},
        {pos: [6, 1, 8], state: "minecraft:blackstone"},
        {pos: [6, 1, 10], state: "minecraft:blackstone"},
        {pos: [6, 1, 11], state: "minecraft:blackstone"},
        {pos: [6, 1, 12], state: "minecraft:blackstone"},
        {pos: [7, 1, 1], state: "minecraft:polished_blackstone_bricks"},
        {pos: [7, 1, 2], state: "minecraft:polished_blackstone_bricks"},
        {pos: [7, 1, 3], state: "minecraft:blackstone"},
        {pos: [7, 1, 4], state: "minecraft:polished_blackstone_bricks"},
        {pos: [7, 1, 5], state: "minecraft:polished_blackstone_bricks"},
        {pos: [7, 1, 6], state: "minecraft:polished_blackstone_bricks"},
        {pos: [7, 1, 7], state: "minecraft:blackstone"},
        {pos: [7, 1, 8], state: "minecraft:blackstone"},
        {pos: [7, 1, 9], state: "minecraft:polished_blackstone_bricks"},
        {pos: [8, 1, 1], state: "minecraft:polished_blackstone_bricks"},
        {pos: [8, 1, 2], state: "minecraft:polished_blackstone_bricks"},
        {pos: [8, 1, 3], state: "minecraft:blackstone"},
        {pos: [8, 1, 4], state: "minecraft:polished_blackstone_bricks"},
        {pos: [8, 1, 5], state: "minecraft:blackstone"},
        {pos: [8, 1, 6], state: "minecraft:polished_blackstone_bricks"},
        {pos: [8, 1, 7], state: "minecraft:blackstone"},
        {pos: [8, 1, 8], state: "minecraft:blackstone"},
        {pos: [8, 1, 9], state: "minecraft:polished_blackstone_bricks"},
        {pos: [8, 1, 10], state: "minecraft:polished_blackstone_bricks"},
        {pos: [8, 1, 12], state: "minecraft:polished_blackstone_bricks"},
        {pos: [24, 1, 7], state: "minecraft:blackstone"},
        {pos: [24, 1, 8], state: "minecraft:blackstone"},
        {pos: [24, 1, 9], state: "minecraft:blackstone"},
        {pos: [24, 1, 10], state: "minecraft:blackstone"},
        {pos: [24, 1, 11], state: "minecraft:polished_blackstone_bricks"},
        {pos: [24, 1, 12], state: "minecraft:polished_blackstone_bricks"},
        {pos: [24, 1, 13], state: "minecraft:polished_blackstone_bricks"},
        {pos: [24, 1, 14], state: "minecraft:polished_blackstone_bricks"},
        {pos: [25, 1, 4], state: "minecraft:blackstone"},
        {pos: [25, 1, 5], state: "minecraft:blackstone"},
        {pos: [25, 1, 6], state: "minecraft:blackstone"},
        {pos: [25, 1, 7], state: "minecraft:polished_blackstone_bricks"},
        {pos: [25, 1, 8], state: "minecraft:polished_blackstone_bricks"},
        {pos: [25, 1, 9], state: "minecraft:polished_blackstone_bricks"},
        {pos: [25, 1, 10], state: "minecraft:polished_blackstone_bricks"},
        {pos: [25, 1, 11], state: "minecraft:polished_blackstone_bricks"},
        {pos: [25, 1, 12], state: "minecraft:polished_blackstone_bricks"},
        {pos: [25, 1, 13], state: "minecraft:polished_blackstone_bricks"},
        {pos: [25, 1, 14], state: "minecraft:polished_blackstone_bricks"},
        {pos: [26, 1, 2], state: "minecraft:polished_blackstone_bricks"},
        {pos: [26, 1, 3], state: "minecraft:polished_blackstone_bricks"},
        {pos: [26, 1, 4], state: "minecraft:polished_blackstone_bricks"},
        {pos: [26, 1, 5], state: "minecraft:polished_blackstone_bricks"},
        {pos: [26, 1, 6], state: "minecraft:polished_blackstone_bricks"},
        {pos: [26, 1, 7], state: "minecraft:polished_blackstone_bricks"},
        {pos: [26, 1, 8], state: "minecraft:polished_blackstone_bricks"},
        {pos: [26, 1, 9], state: "minecraft:polished_blackstone_bricks"},
        {pos: [26, 1, 10], state: "minecraft:polished_blackstone_bricks"},
        {pos: [26, 1, 11], state: "minecraft:polished_blackstone_bricks"},
        {pos: [26, 1, 12], state: "minecraft:polished_blackstone_bricks"},
        {pos: [26, 1, 13], state: "minecraft:polished_blackstone_bricks"},
        {pos: [26, 1, 14], state: "minecraft:polished_blackstone_bricks"},
        {pos: [6, 2, 1], state: "minecraft:polished_blackstone_bricks"},
        {pos: [6, 2, 2], state: "minecraft:polished_blackstone_bricks"},
        {pos: [6, 2, 3], state: "minecraft:polished_blackstone_bricks"},
        {pos: [6, 2, 4], state: "minecraft:polished_blackstone_bricks"},
        {pos: [6, 2, 5], state: "minecraft:polished_blackstone_bricks"},
        {pos: [7, 2, 1], state: "minecraft:polished_blackstone_bricks"},
        {pos: [7, 2, 2], state: "minecraft:polished_blackstone_bricks"},
        {pos: [7, 2, 3], state: "minecraft:polished_blackstone_bricks"},
        {pos: [7, 2, 4], state: "minecraft:blackstone"},
        {pos: [7, 2, 5], state: "minecraft:blackstone"},
        {pos: [7, 2, 7], state: "minecraft:blackstone"},
        {pos: [7, 2, 8], state: "minecraft:blackstone"},
        {pos: [7, 2, 9], state: "minecraft:blackstone"},
        {pos: [8, 2, 1], state: "minecraft:polished_blackstone_bricks"},
        {pos: [8, 2, 2], state: "minecraft:polished_blackstone_bricks"},
        {pos: [8, 2, 3], state: "minecraft:blackstone"},
        {pos: [8, 2, 5], state: "minecraft:blackstone"},
        {pos: [8, 2, 6], state: "minecraft:blackstone"},
        {pos: [8, 2, 7], state: "minecraft:blackstone"},
        {pos: [8, 2, 8], state: "minecraft:blackstone"},
        {pos: [8, 2, 11], state: "minecraft:polished_blackstone_bricks"},
        {pos: [9, 2, 7], state: "minecraft:blackstone"},
        {pos: [22, 2, 10], state: "minecraft:blackstone"},
        {pos: [24, 2, 3], state: "minecraft:blackstone"},
        {pos: [24, 2, 4], state: "minecraft:blackstone"},
        {pos: [24, 2, 6], state: "minecraft:blackstone"},
        {pos: [24, 2, 7], state: "minecraft:blackstone"},
        {pos: [24, 2, 8], state: "minecraft:blackstone"},
        {pos: [24, 2, 9], state: "minecraft:blackstone"},
        {pos: [24, 2, 10], state: "minecraft:blackstone"},
        {pos: [24, 2, 11], state: "minecraft:polished_blackstone_bricks"},
        {pos: [24, 2, 12], state: "minecraft:polished_blackstone_bricks"},
        {pos: [24, 2, 13], state: "minecraft:polished_blackstone_bricks"},
        {pos: [24, 2, 14], state: "minecraft:polished_blackstone_bricks"},
        {pos: [25, 2, 1], state: "minecraft:polished_blackstone_bricks"},
        {pos: [25, 2, 3], state: "minecraft:polished_blackstone_bricks"},
        {pos: [25, 2, 4], state: "minecraft:polished_blackstone_bricks"},
        {pos: [25, 2, 5], state: "minecraft:blackstone"},
        {pos: [25, 2, 6], state: "minecraft:blackstone"},
        {pos: [25, 2, 7], state: "minecraft:polished_blackstone_bricks"},
        {pos: [25, 2, 8], state: "minecraft:polished_blackstone_bricks"},
        {pos: [25, 2, 9], state: "minecraft:polished_blackstone_bricks"},
        {pos: [25, 2, 10], state: "minecraft:polished_blackstone_bricks"},
        {pos: [25, 2, 11], state: "minecraft:polished_blackstone_bricks"},
        {pos: [25, 2, 12], state: "minecraft:polished_blackstone_bricks"},
        {pos: [25, 2, 13], state: "minecraft:polished_blackstone_bricks"},
        {pos: [25, 2, 14], state: "minecraft:polished_blackstone_bricks"},
        {pos: [25, 2, 15], state: "minecraft:polished_blackstone_bricks"},
        {pos: [26, 2, 1], state: "minecraft:polished_blackstone_bricks"},
        {pos: [26, 2, 2], state: "minecraft:polished_blackstone_bricks"},
        {pos: [26, 2, 3], state: "minecraft:polished_blackstone_bricks"},
        {pos: [26, 2, 4], state: "minecraft:polished_blackstone_bricks"},
        {pos: [26, 2, 5], state: "minecraft:polished_blackstone_bricks"},
        {pos: [26, 2, 6], state: "minecraft:polished_blackstone_bricks"},
        {pos: [26, 2, 7], state: "minecraft:polished_blackstone_bricks"},
        {pos: [26, 2, 8], state: "minecraft:polished_blackstone_bricks"},
        {pos: [26, 2, 9], state: "minecraft:polished_blackstone_bricks"},
        {pos: [26, 2, 10], state: "minecraft:polished_blackstone_bricks"},
        {pos: [26, 2, 11], state: "minecraft:polished_blackstone_bricks"},
        {pos: [26, 2, 12], state: "minecraft:polished_blackstone_bricks"},
        {pos: [26, 2, 13], state: "minecraft:polished_blackstone_bricks"},
        {pos: [26, 2, 14], state: "minecraft:polished_blackstone_bricks"},
        {pos: [26, 2, 15], state: "minecraft:polished_blackstone_bricks"},
        {pos: [0, 3, 6], state: "minecraft:polished_blackstone_bricks"},
        {pos: [0, 3, 7], state: "minecraft:polished_blackstone_bricks"},
        {pos: [0, 3, 8], state: "minecraft:polished_blackstone_bricks"},
        {pos: [0, 3, 9], state: "minecraft:polished_blackstone_bricks"},
        {pos: [0, 3, 10], state: "minecraft:polished_blackstone_bricks"},
        {pos: [0, 3, 11], state: "minecraft:polished_blackstone_bricks"},
        {pos: [0, 3, 12], state: "minecraft:polished_blackstone_bricks"},
        {pos: [1, 3, 5], state: "minecraft:polished_blackstone_bricks"},
        {pos: [1, 3, 6], state: "minecraft:polished_blackstone_bricks"},
        {pos: [1, 3, 7], state: "minecraft:polished_blackstone_bricks"},
        {pos: [1, 3, 8], state: "minecraft:polished_blackstone_bricks"},
        {pos: [1, 3, 9], state: "minecraft:polished_blackstone_bricks"},
        {pos: [1, 3, 10], state: "minecraft:polished_blackstone_bricks"},
        {pos: [1, 3, 11], state: "minecraft:polished_blackstone_bricks"},
        {pos: [1, 3, 12], state: "minecraft:polished_blackstone_bricks"},
        {pos: [2, 3, 5], state: "minecraft:polished_blackstone_bricks"},
        {pos: [2, 3, 6], state: "minecraft:polished_blackstone_bricks"},
        {pos: [2, 3, 7], state: "minecraft:polished_blackstone_bricks"},
        {pos: [2, 3, 8], state: "minecraft:polished_blackstone_bricks"},
        {pos: [2, 3, 9], state: "minecraft:polished_blackstone_bricks"},
        {pos: [2, 3, 10], state: "minecraft:polished_blackstone_bricks"},
        {pos: [2, 3, 11], state: "minecraft:polished_blackstone_bricks"},
        {pos: [2, 3, 12], state: "minecraft:polished_blackstone_bricks"},
        {pos: [3, 3, 5], state: "minecraft:polished_blackstone_bricks"},
        {pos: [3, 3, 6], state: "minecraft:polished_blackstone_bricks"},
        {pos: [3, 3, 7], state: "minecraft:polished_blackstone_bricks"},
        {pos: [3, 3, 8], state: "minecraft:polished_blackstone_bricks"},
        {pos: [3, 3, 9], state: "minecraft:polished_blackstone_bricks"},
        {pos: [3, 3, 10], state: "minecraft:polished_blackstone_bricks"},
        {pos: [3, 3, 11], state: "minecraft:polished_blackstone_bricks"},
        {pos: [3, 3, 12], state: "minecraft:polished_blackstone_bricks"},
        {pos: [4, 3, 5], state: "minecraft:polished_blackstone_bricks"},
        {pos: [4, 3, 6], state: "minecraft:polished_blackstone_bricks"},
        {pos: [4, 3, 7], state: "minecraft:polished_blackstone_bricks"},
        {pos: [5, 3, 5], state: "minecraft:polished_blackstone_bricks"},
        {pos: [5, 3, 6], state: "minecraft:polished_blackstone_bricks"},
        {pos: [5, 3, 7], state: "minecraft:polished_blackstone_bricks"},
        {pos: [6, 3, 1], state: "minecraft:polished_blackstone_bricks"},
        {pos: [6, 3, 2], state: "minecraft:polished_blackstone_bricks"},
        {pos: [6, 3, 3], state: "minecraft:polished_blackstone_bricks"},
        {pos: [6, 3, 5], state: "minecraft:polished_blackstone_bricks"},
        {pos: [6, 3, 6], state: "minecraft:polished_blackstone_bricks"},
        {pos: [6, 3, 7], state: "minecraft:polished_blackstone_bricks"},
        {pos: [6, 3, 8], state: "minecraft:polished_blackstone_bricks"},
        {pos: [6, 3, 9], state: "minecraft:polished_blackstone_bricks"},
        {pos: [6, 3, 10], state: "minecraft:polished_blackstone_bricks"},
        {pos: [6, 3, 11], state: "minecraft:polished_blackstone_bricks"},
        {pos: [7, 3, 1], state: "minecraft:polished_blackstone_bricks"},
        {pos: [7, 3, 2], state: "minecraft:polished_blackstone_bricks"},
        {pos: [7, 3, 3], state: "minecraft:polished_blackstone_bricks"},
        {pos: [7, 3, 6], state: "minecraft:polished_blackstone_bricks"},
        {pos: [7, 3, 7], state: "minecraft:polished_blackstone_bricks"},
        {pos: [7, 3, 8], state: "minecraft:polished_blackstone_bricks"},
        {pos: [7, 3, 9], state: "minecraft:polished_blackstone_bricks"},
        {pos: [7, 3, 10], state: "minecraft:polished_blackstone_bricks"},
        {pos: [8, 3, 1], state: "minecraft:polished_blackstone_bricks"},
        {pos: [8, 3, 2], state: "minecraft:polished_blackstone_bricks"},
        {pos: [8, 3, 3], state: "minecraft:blackstone"},
        {pos: [8, 3, 6], state: "minecraft:blackstone"},
        {pos: [8, 3, 7], state: "minecraft:polished_blackstone_bricks"},
        {pos: [8, 3, 8], state: "minecraft:polished_blackstone_bricks"},
        {pos: [8, 3, 9], state: "minecraft:polished_blackstone_bricks"},
        {pos: [8, 3, 10], state: "minecraft:polished_blackstone_bricks"},
        {pos: [9, 3, 7], state: "minecraft:polished_blackstone_bricks"},
        {pos: [9, 3, 8], state: "minecraft:polished_blackstone_bricks"},
        {pos: [9, 3, 10], state: "minecraft:polished_blackstone_bricks"},
        {pos: [9, 3, 11], state: "minecraft:polished_blackstone_bricks"},
        {pos: [10, 3, 7], state: "minecraft:polished_blackstone_bricks"},
        {pos: [10, 3, 8], state: "minecraft:polished_blackstone_bricks"},
        {pos: [10, 3, 11], state: "minecraft:polished_blackstone_bricks"},
        {pos: [10, 3, 12], state: "minecraft:polished_blackstone_bricks"},
        {pos: [11, 3, 7], state: "minecraft:polished_blackstone_bricks"},
        {pos: [11, 3, 11], state: "minecraft:polished_blackstone_bricks"},
        {pos: [11, 3, 12], state: "minecraft:polished_blackstone_bricks"},
        {pos: [12, 3, 7], state: "minecraft:polished_blackstone_bricks"},
        {pos: [12, 3, 8], state: "minecraft:polished_blackstone_bricks"},
        {pos: [12, 3, 9], state: "minecraft:polished_blackstone_bricks"},
        {pos: [12, 3, 10], state: "minecraft:polished_blackstone_bricks"},
        {pos: [12, 3, 11], state: "minecraft:polished_blackstone_bricks"},
        {pos: [12, 3, 12], state: "minecraft:polished_blackstone_bricks"},
        {pos: [13, 3, 7], state: "minecraft:polished_blackstone_bricks"},
        {pos: [13, 3, 8], state: "minecraft:polished_blackstone_bricks"},
        {pos: [13, 3, 9], state: "minecraft:polished_blackstone_bricks"},
        {pos: [13, 3, 10], state: "minecraft:polished_blackstone_bricks"},
        {pos: [13, 3, 11], state: "minecraft:polished_blackstone_bricks"},
        {pos: [13, 3, 12], state: "minecraft:polished_blackstone_bricks"},
        {pos: [14, 3, 7], state: "minecraft:blackstone"},
        {pos: [14, 3, 8], state: "minecraft:polished_blackstone_bricks"},
        {pos: [14, 3, 9], state: "minecraft:polished_blackstone_bricks"},
        {pos: [14, 3, 10], state: "minecraft:polished_blackstone_bricks"},
        {pos: [14, 3, 11], state: "minecraft:polished_blackstone_bricks"},
        {pos: [15, 3, 6], state: "minecraft:polished_blackstone_bricks"},
        {pos: [15, 3, 7], state: "minecraft:blackstone"},
        {pos: [15, 3, 8], state: "minecraft:blackstone"},
        {pos: [15, 3, 9], state: "minecraft:polished_blackstone_bricks"},
        {pos: [15, 3, 10], state: "minecraft:polished_blackstone_bricks"},
        {pos: [16, 3, 5], state: "minecraft:polished_blackstone_bricks"},
        {pos: [16, 3, 6], state: "minecraft:polished_blackstone_bricks"},
        {pos: [16, 3, 7], state: "minecraft:blackstone"},
        {pos: [16, 3, 8], state: "minecraft:blackstone"},
        {pos: [16, 3, 9], state: "minecraft:polished_blackstone_bricks"},
        {pos: [17, 3, 5], state: "minecraft:polished_blackstone_bricks"},
        {pos: [17, 3, 6], state: "minecraft:polished_blackstone_bricks"},
        {pos: [17, 3, 7], state: "minecraft:blackstone"},
        {pos: [17, 3, 8], state: "minecraft:blackstone"},
        {pos: [17, 3, 9], state: "minecraft:polished_blackstone_bricks"},
        {pos: [18, 3, 6], state: "minecraft:polished_blackstone_bricks"},
        {pos: [18, 3, 7], state: "minecraft:blackstone"},
        {pos: [18, 3, 8], state: "minecraft:blackstone"},
        {pos: [18, 3, 9], state: "minecraft:blackstone"},
        {pos: [19, 3, 8], state: "minecraft:blackstone"},
        {pos: [19, 3, 9], state: "minecraft:blackstone"},
        {pos: [20, 3, 8], state: "minecraft:blackstone"},
        {pos: [20, 3, 9], state: "minecraft:blackstone"},
        {pos: [20, 3, 10], state: "minecraft:polished_blackstone_bricks"},
        {pos: [21, 3, 9], state: "minecraft:blackstone"},
        {pos: [21, 3, 10], state: "minecraft:polished_blackstone_bricks"},
        {pos: [22, 3, 7], state: "minecraft:polished_blackstone_bricks"},
        {pos: [22, 3, 9], state: "minecraft:blackstone"},
        {pos: [22, 3, 10], state: "minecraft:polished_blackstone_bricks"},
        {pos: [22, 3, 11], state: "minecraft:polished_blackstone_bricks"},
        {pos: [23, 3, 5], state: "minecraft:polished_blackstone_bricks"},
        {pos: [23, 3, 6], state: "minecraft:polished_blackstone_bricks"},
        {pos: [23, 3, 7], state: "minecraft:polished_blackstone_bricks"},
        {pos: [23, 3, 8], state: "minecraft:polished_blackstone_bricks"},
        {pos: [23, 3, 9], state: "minecraft:blackstone"},
        {pos: [23, 3, 10], state: "minecraft:blackstone"},
        {pos: [23, 3, 11], state: "minecraft:polished_blackstone_bricks"},
        {pos: [23, 3, 12], state: "minecraft:polished_blackstone_bricks"},
        {pos: [24, 3, 2], state: "minecraft:blackstone"},
        {pos: [24, 3, 3], state: "minecraft:polished_blackstone_bricks"},
        {pos: [24, 3, 5], state: "minecraft:polished_blackstone_bricks"},
        {pos: [24, 3, 6], state: "minecraft:polished_blackstone_bricks"},
        {pos: [24, 3, 7], state: "minecraft:polished_blackstone_bricks"},
        {pos: [24, 3, 8], state: "minecraft:polished_blackstone_bricks"},
        {pos: [24, 3, 9], state: "minecraft:polished_blackstone_bricks"},
        {pos: [24, 3, 10], state: "minecraft:polished_blackstone_bricks"},
        {pos: [24, 3, 11], state: "minecraft:polished_blackstone_bricks"},
        {pos: [24, 3, 12], state: "minecraft:polished_blackstone_bricks"},
        {pos: [24, 3, 14], state: "minecraft:polished_blackstone_bricks"},
        {pos: [24, 3, 15], state: "minecraft:polished_blackstone_bricks"},
        {pos: [25, 3, 1], state: "minecraft:polished_blackstone_bricks"},
        {pos: [25, 3, 2], state: "minecraft:polished_blackstone_bricks"},
        {pos: [25, 3, 3], state: "minecraft:polished_blackstone_bricks"},
        {pos: [25, 3, 5], state: "minecraft:polished_blackstone_bricks"},
        {pos: [25, 3, 6], state: "minecraft:polished_blackstone_bricks"},
        {pos: [25, 3, 7], state: "minecraft:polished_blackstone_bricks"},
        {pos: [25, 3, 8], state: "minecraft:polished_blackstone_bricks"},
        {pos: [25, 3, 9], state: "minecraft:polished_blackstone_bricks"},
        {pos: [25, 3, 10], state: "minecraft:polished_blackstone_bricks"},
        {pos: [25, 3, 11], state: "minecraft:polished_blackstone_bricks"},
        {pos: [25, 3, 12], state: "minecraft:polished_blackstone_bricks"},
        {pos: [25, 3, 14], state: "minecraft:polished_blackstone_bricks"},
        {pos: [25, 3, 15], state: "minecraft:polished_blackstone_bricks"},
        {pos: [26, 3, 1], state: "minecraft:polished_blackstone_bricks"},
        {pos: [26, 3, 2], state: "minecraft:polished_blackstone_bricks"},
        {pos: [26, 3, 3], state: "minecraft:polished_blackstone_bricks"},
        {pos: [26, 3, 5], state: "minecraft:polished_blackstone_bricks"},
        {pos: [26, 3, 7], state: "minecraft:polished_blackstone_bricks"},
        {pos: [26, 3, 8], state: "minecraft:polished_blackstone_bricks"},
        {pos: [26, 3, 9], state: "minecraft:polished_blackstone_bricks"},
        {pos: [26, 3, 10], state: "minecraft:polished_blackstone_bricks"},
        {pos: [26, 3, 11], state: "minecraft:polished_blackstone_bricks"},
        {pos: [26, 3, 12], state: "minecraft:polished_blackstone_bricks"},
        {pos: [26, 3, 14], state: "minecraft:polished_blackstone_bricks"},
        {pos: [26, 3, 15], state: "minecraft:polished_blackstone_bricks"},
        {pos: [27, 3, 5], state: "minecraft:polished_blackstone_bricks"},
        {pos: [27, 3, 6], state: "minecraft:polished_blackstone_bricks"},
        {pos: [27, 3, 7], state: "minecraft:polished_blackstone_bricks"},
        {pos: [27, 3, 8], state: "minecraft:polished_blackstone_bricks"},
        {pos: [27, 3, 9], state: "minecraft:polished_blackstone_bricks"},
        {pos: [27, 3, 10], state: "minecraft:polished_blackstone_bricks"},
        {pos: [27, 3, 11], state: "minecraft:polished_blackstone_bricks"},
        {pos: [27, 3, 12], state: "minecraft:polished_blackstone_bricks"},
        {pos: [28, 3, 5], state: "minecraft:polished_blackstone_bricks"},
        {pos: [28, 3, 6], state: "minecraft:polished_blackstone_bricks"},
        {pos: [28, 3, 7], state: "minecraft:polished_blackstone_bricks"},
        {pos: [28, 3, 9], state: "minecraft:polished_blackstone_bricks"},
        {pos: [28, 3, 10], state: "minecraft:polished_blackstone_bricks"},
        {pos: [28, 3, 11], state: "minecraft:polished_blackstone_bricks"},
        {pos: [28, 3, 12], state: "minecraft:polished_blackstone_bricks"},
        {pos: [29, 3, 5], state: "minecraft:polished_blackstone_bricks"},
        {pos: [29, 3, 6], state: "minecraft:polished_blackstone_bricks"},
        {pos: [29, 3, 7], state: "minecraft:polished_blackstone_bricks"},
        {pos: [29, 3, 9], state: "minecraft:polished_blackstone_bricks"},
        {pos: [29, 3, 10], state: "minecraft:polished_blackstone_bricks"},
        {pos: [29, 3, 11], state: "minecraft:polished_blackstone_bricks"},
        {pos: [29, 3, 12], state: "minecraft:polished_blackstone_bricks"},
        {pos: [30, 3, 6], state: "minecraft:polished_blackstone_bricks"},
        {pos: [30, 3, 7], state: "minecraft:polished_blackstone_bricks"},
        {pos: [30, 3, 8], state: "minecraft:polished_blackstone_bricks"},
        {pos: [30, 3, 9], state: "minecraft:polished_blackstone_bricks"},
        {pos: [30, 3, 10], state: "minecraft:polished_blackstone_bricks"},
        {pos: [30, 3, 11], state: "minecraft:polished_blackstone_bricks"},
        {pos: [0, 4, 7], state: "minecraft:polished_blackstone_bricks"},
        {pos: [0, 4, 8], state: "minecraft:polished_blackstone_bricks"},
        {pos: [0, 4, 10], state: "minecraft:polished_blackstone_bricks"},
        {pos: [0, 4, 11], state: "minecraft:polished_blackstone_bricks"},
        {pos: [0, 4, 12], state: "minecraft:polished_blackstone_bricks"},
        {pos: [1, 4, 6], state: "minecraft:polished_blackstone_bricks"},
        {pos: [1, 4, 7], state: "minecraft:polished_blackstone_bricks"},
        {pos: [1, 4, 8], state: "minecraft:polished_blackstone_bricks"},
        {pos: [1, 4, 9], state: "minecraft:polished_blackstone_bricks"},
        {pos: [1, 4, 10], state: "minecraft:polished_blackstone_bricks"},
        {pos: [1, 4, 11], state: "minecraft:polished_blackstone_bricks"},
        {pos: [1, 4, 12], state: "minecraft:polished_blackstone_bricks"},
        {pos: [2, 4, 5], state: "minecraft:blackstone"},
        {pos: [2, 4, 6], state: "minecraft:blackstone"},
        {pos: [2, 4, 7], state: "minecraft:blackstone"},
        {pos: [2, 4, 8], state: "minecraft:polished_blackstone_bricks"},
        {pos: [2, 4, 9], state: "minecraft:polished_blackstone_bricks"},
        {pos: [2, 4, 10], state: "minecraft:polished_blackstone_bricks"},
        {pos: [2, 4, 11], state: "minecraft:polished_blackstone_bricks"},
        {pos: [3, 4, 5], state: "minecraft:blackstone"},
        {pos: [3, 4, 6], state: "minecraft:blackstone"},
        {pos: [3, 4, 7], state: "minecraft:blackstone"},
        {pos: [3, 4, 8], state: "minecraft:blackstone"},
        {pos: [3, 4, 9], state: "minecraft:polished_blackstone_bricks"},
        {pos: [3, 4, 10], state: "minecraft:blackstone"},
        {pos: [3, 4, 11], state: "minecraft:polished_blackstone_bricks"},
        {pos: [3, 4, 12], state: "minecraft:polished_blackstone_bricks"},
        {pos: [4, 4, 5], state: "minecraft:polished_blackstone_bricks"},
        {pos: [4, 4, 6], state: "minecraft:blackstone"},
        {pos: [4, 4, 7], state: "minecraft:blackstone"},
        {pos: [5, 4, 5], state: "minecraft:polished_blackstone_bricks"},
        {pos: [5, 4, 6], state: "minecraft:blackstone"},
        {pos: [5, 4, 7], state: "minecraft:blackstone"},
        {pos: [5, 4, 11], state: "minecraft:blackstone"},
        {pos: [6, 4, 1], state: "minecraft:polished_blackstone_bricks"},
        {pos: [6, 4, 2], state: "minecraft:basalt{axis:y}"},
        {pos: [6, 4, 3], state: "minecraft:polished_blackstone_bricks"},
        {pos: [6, 4, 5], state: "minecraft:blackstone"},
        {pos: [6, 4, 6], state: "minecraft:polished_blackstone_bricks"},
        {pos: [6, 4, 7], state: "minecraft:blackstone"},
        {pos: [6, 4, 8], state: "minecraft:blackstone"},
        {pos: [6, 4, 9], state: "minecraft:blackstone"},
        {pos: [6, 4, 10], state: "minecraft:blackstone"},
        {pos: [7, 4, 1], state: "minecraft:polished_blackstone_bricks"},
        {pos: [7, 4, 2], state: "minecraft:polished_blackstone_bricks"},
        {pos: [7, 4, 3], state: "minecraft:polished_blackstone_bricks"},
        {pos: [7, 4, 6], state: "minecraft:blackstone"},
        {pos: [7, 4, 7], state: "minecraft:polished_blackstone_bricks"},
        {pos: [7, 4, 8], state: "minecraft:blackstone"},
        {pos: [7, 4, 9], state: "minecraft:blackstone"},
        {pos: [7, 4, 10], state: "minecraft:blackstone"},
        {pos: [8, 4, 1], state: "minecraft:polished_blackstone_bricks"},
        {pos: [8, 4, 2], state: "minecraft:polished_blackstone_bricks"},
        {pos: [8, 4, 3], state: "minecraft:polished_blackstone_bricks"},
        {pos: [8, 4, 7], state: "minecraft:polished_blackstone_bricks"},
        {pos: [8, 4, 8], state: "minecraft:blackstone"},
        {pos: [8, 4, 9], state: "minecraft:blackstone"},
        {pos: [8, 4, 10], state: "minecraft:blackstone"},
        {pos: [8, 4, 11], state: "minecraft:blackstone"},
        {pos: [9, 4, 7], state: "minecraft:polished_blackstone_bricks"},
        {pos: [9, 4, 8], state: "minecraft:blackstone"},
        {pos: [9, 4, 11], state: "minecraft:blackstone"},
        {pos: [9, 4, 12], state: "minecraft:polished_blackstone_bricks"},
        {pos: [10, 4, 7], state: "minecraft:blackstone"},
        {pos: [10, 4, 8], state: "minecraft:blackstone"},
        {pos: [10, 4, 12], state: "minecraft:polished_blackstone_bricks"},
        {pos: [11, 4, 7], state: "minecraft:blackstone"},
        {pos: [11, 4, 8], state: "minecraft:blackstone"},
        {pos: [11, 4, 11], state: "minecraft:blackstone"},
        {pos: [11, 4, 12], state: "minecraft:polished_blackstone_bricks"},
        {pos: [12, 4, 7], state: "minecraft:blackstone"},
        {pos: [12, 4, 8], state: "minecraft:polished_blackstone_bricks"},
        {pos: [12, 4, 9], state: "minecraft:polished_blackstone_bricks"},
        {pos: [12, 4, 10], state: "minecraft:blackstone"},
        {pos: [12, 4, 11], state: "minecraft:polished_blackstone_bricks"},
        {pos: [13, 4, 7], state: "minecraft:blackstone"},
        {pos: [13, 4, 8], state: "minecraft:blackstone"},
        {pos: [13, 4, 9], state: "minecraft:polished_blackstone_bricks"},
        {pos: [13, 4, 10], state: "minecraft:blackstone"},
        {pos: [13, 4, 11], state: "minecraft:polished_blackstone_bricks"},
        {pos: [14, 4, 7], state: "minecraft:blackstone"},
        {pos: [14, 4, 8], state: "minecraft:polished_blackstone_bricks"},
        {pos: [14, 4, 9], state: "minecraft:blackstone"},
        {pos: [14, 4, 10], state: "minecraft:blackstone"},
        {pos: [15, 4, 6], state: "minecraft:polished_blackstone_bricks"},
        {pos: [15, 4, 8], state: "minecraft:polished_blackstone_bricks"},
        {pos: [15, 4, 9], state: "minecraft:polished_blackstone_bricks"},
        {pos: [15, 4, 10], state: "minecraft:polished_blackstone_bricks"},
        {pos: [16, 4, 5], state: "minecraft:blackstone"},
        {pos: [16, 4, 6], state: "minecraft:blackstone"},
        {pos: [16, 4, 7], state: "minecraft:blackstone"},
        {pos: [16, 4, 8], state: "minecraft:polished_blackstone_bricks"},
        {pos: [16, 4, 9], state: "minecraft:polished_blackstone_bricks"},
        {pos: [17, 4, 5], state: "minecraft:blackstone"},
        {pos: [17, 4, 6], state: "minecraft:polished_blackstone_bricks"},
        {pos: [17, 4, 7], state: "minecraft:blackstone"},
        {pos: [17, 4, 8], state: "minecraft:blackstone"},
        {pos: [17, 4, 9], state: "minecraft:blackstone"},
        {pos: [18, 4, 6], state: "minecraft:blackstone"},
        {pos: [18, 4, 7], state: "minecraft:blackstone"},
        {pos: [18, 4, 8], state: "minecraft:blackstone"},
        {pos: [18, 4, 9], state: "minecraft:polished_blackstone_bricks"},
        {pos: [19, 4, 8], state: "minecraft:blackstone"},
        {pos: [19, 4, 9], state: "minecraft:polished_blackstone_bricks"},
        {pos: [19, 4, 10], state: "minecraft:polished_blackstone_bricks"},
        {pos: [20, 4, 8], state: "minecraft:blackstone"},
        {pos: [20, 4, 9], state: "minecraft:polished_blackstone_bricks"},
        {pos: [20, 4, 10], state: "minecraft:polished_blackstone_bricks"},
        {pos: [21, 4, 8], state: "minecraft:polished_blackstone_bricks"},
        {pos: [21, 4, 9], state: "minecraft:blackstone"},
        {pos: [21, 4, 10], state: "minecraft:polished_blackstone_bricks"},
        {pos: [22, 4, 8], state: "minecraft:blackstone"},
        {pos: [22, 4, 9], state: "minecraft:polished_blackstone_bricks"},
        {pos: [22, 4, 10], state: "minecraft:polished_blackstone_bricks"},
        {pos: [23, 4, 5], state: "minecraft:blackstone"},
        {pos: [23, 4, 6], state: "minecraft:polished_blackstone_bricks"},
        {pos: [23, 4, 7], state: "minecraft:blackstone"},
        {pos: [23, 4, 8], state: "minecraft:polished_blackstone_bricks"},
        {pos: [23, 4, 9], state: "minecraft:polished_blackstone_bricks"},
        {pos: [23, 4, 10], state: "minecraft:blackstone"},
        {pos: [23, 4, 11], state: "minecraft:polished_blackstone_bricks"},
        {pos: [24, 4, 2], state: "minecraft:polished_blackstone_bricks"},
        {pos: [24, 4, 3], state: "minecraft:polished_blackstone_bricks"},
        {pos: [24, 4, 5], state: "minecraft:blackstone"},
        {pos: [24, 4, 6], state: "minecraft:blackstone"},
        {pos: [24, 4, 7], state: "minecraft:blackstone"},
        {pos: [24, 4, 8], state: "minecraft:blackstone"},
        {pos: [24, 4, 9], state: "minecraft:blackstone"},
        {pos: [24, 4, 10], state: "minecraft:polished_blackstone_bricks"},
        {pos: [24, 4, 11], state: "minecraft:polished_blackstone_bricks"},
        {pos: [24, 4, 14], state: "minecraft:polished_blackstone_bricks"},
        {pos: [24, 4, 15], state: "minecraft:polished_blackstone_bricks"},
        {pos: [25, 4, 2], state: "minecraft:polished_blackstone_bricks"},
        {pos: [25, 4, 3], state: "minecraft:polished_blackstone_bricks"},
        {pos: [25, 4, 5], state: "minecraft:polished_blackstone_bricks"},
        {pos: [25, 4, 6], state: "minecraft:blackstone"},
        {pos: [25, 4, 7], state: "minecraft:polished_blackstone_bricks"},
        {pos: [25, 4, 8], state: "minecraft:blackstone"},
        {pos: [25, 4, 9], state: "minecraft:blackstone"},
        {pos: [25, 4, 10], state: "minecraft:blackstone"},
        {pos: [25, 4, 11], state: "minecraft:blackstone"},
        {pos: [25, 4, 12], state: "minecraft:polished_blackstone_bricks"},
        {pos: [25, 4, 14], state: "minecraft:polished_blackstone_bricks"},
        {pos: [25, 4, 15], state: "minecraft:polished_blackstone_bricks"},
        {pos: [26, 4, 1], state: "minecraft:polished_blackstone_bricks"},
        {pos: [26, 4, 2], state: "minecraft:polished_blackstone_bricks"},
        {pos: [26, 4, 3], state: "minecraft:polished_blackstone_bricks"},
        {pos: [26, 4, 5], state: "minecraft:polished_blackstone_bricks"},
        {pos: [26, 4, 7], state: "minecraft:blackstone"},
        {pos: [26, 4, 8], state: "minecraft:blackstone"},
        {pos: [26, 4, 9], state: "minecraft:blackstone"},
        {pos: [26, 4, 10], state: "minecraft:polished_blackstone_bricks"},
        {pos: [26, 4, 11], state: "minecraft:blackstone"},
        {pos: [26, 4, 12], state: "minecraft:polished_blackstone_bricks"},
        {pos: [26, 4, 14], state: "minecraft:polished_blackstone_bricks"},
        {pos: [26, 4, 15], state: "minecraft:polished_blackstone_bricks"},
        {pos: [27, 4, 6], state: "minecraft:polished_blackstone_bricks"},
        {pos: [27, 4, 7], state: "minecraft:blackstone"},
        {pos: [27, 4, 8], state: "minecraft:blackstone"},
        {pos: [27, 4, 9], state: "minecraft:polished_blackstone_bricks"},
        {pos: [27, 4, 10], state: "minecraft:blackstone"},
        {pos: [27, 4, 11], state: "minecraft:polished_blackstone_bricks"},
        {pos: [27, 4, 12], state: "minecraft:polished_blackstone_bricks"},
        {pos: [28, 4, 9], state: "minecraft:polished_blackstone_bricks"},
        {pos: [28, 4, 10], state: "minecraft:polished_blackstone_bricks"},
        {pos: [28, 4, 11], state: "minecraft:polished_blackstone_bricks"},
        {pos: [28, 4, 12], state: "minecraft:blackstone"},
        {pos: [29, 4, 8], state: "minecraft:polished_blackstone_bricks"},
        {pos: [29, 4, 9], state: "minecraft:polished_blackstone_bricks"},
        {pos: [29, 4, 10], state: "minecraft:blackstone"},
        {pos: [29, 4, 11], state: "minecraft:polished_blackstone_bricks"},
        {pos: [30, 4, 7], state: "minecraft:polished_blackstone_bricks"},
        {pos: [30, 4, 8], state: "minecraft:polished_blackstone_bricks"},
        {pos: [30, 4, 9], state: "minecraft:polished_blackstone_bricks"},
        {pos: [30, 4, 10], state: "minecraft:blackstone"},
        {pos: [30, 4, 11], state: "minecraft:blackstone"},
        {pos: [6, 5, 1], state: "minecraft:basalt{axis:y}"},
        {pos: [6, 5, 2], state: "minecraft:blackstone"},
        {pos: [6, 5, 3], state: "minecraft:polished_blackstone_bricks"},
        {pos: [6, 5, 9], state: "minecraft:polished_blackstone_bricks"},
        {pos: [7, 5, 1], state: "minecraft:polished_blackstone_bricks"},
        {pos: [7, 5, 2], state: "minecraft:polished_blackstone_bricks"},
        {pos: [7, 5, 3], state: "minecraft:polished_blackstone_bricks"},
        {pos: [7, 5, 8], state: "minecraft:polished_blackstone_bricks"},
        {pos: [7, 5, 9], state: "minecraft:polished_blackstone_bricks"},
        {pos: [8, 5, 1], state: "minecraft:polished_blackstone_bricks"},
        {pos: [8, 5, 2], state: "minecraft:polished_blackstone_bricks"},
        {pos: [8, 5, 3], state: "minecraft:polished_blackstone_bricks"},
        {pos: [8, 5, 8], state: "minecraft:blackstone"},
        {pos: [8, 5, 9], state: "minecraft:polished_blackstone_bricks"},
        {pos: [24, 5, 1], state: "minecraft:polished_blackstone_bricks"},
        {pos: [24, 5, 2], state: "minecraft:polished_blackstone_bricks"},
        {pos: [24, 5, 3], state: "minecraft:polished_blackstone_bricks"},
        {pos: [24, 5, 14], state: "minecraft:polished_blackstone_bricks"},
        {pos: [25, 5, 1], state: "minecraft:polished_blackstone_bricks"},
        {pos: [25, 5, 2], state: "minecraft:polished_blackstone_bricks"},
        {pos: [25, 5, 3], state: "minecraft:polished_blackstone_bricks"},
        {pos: [25, 5, 8], state: "minecraft:polished_blackstone_bricks"},
        {pos: [25, 5, 9], state: "minecraft:polished_blackstone_bricks"},
        {pos: [25, 5, 14], state: "minecraft:polished_blackstone_bricks"},
        {pos: [25, 5, 15], state: "minecraft:polished_blackstone_bricks"},
        {pos: [26, 5, 1], state: "minecraft:polished_blackstone_bricks"},
        {pos: [26, 5, 2], state: "minecraft:polished_blackstone_bricks"},
        {pos: [26, 5, 3], state: "minecraft:polished_blackstone_bricks"},
        {pos: [26, 5, 8], state: "minecraft:polished_blackstone_bricks"},
        {pos: [26, 5, 9], state: "minecraft:polished_blackstone_bricks"},
        {pos: [26, 5, 14], state: "minecraft:polished_blackstone_bricks"},
        {pos: [26, 5, 15], state: "minecraft:polished_blackstone_bricks"},
        {pos: [6, 6, 1], state: "minecraft:blackstone"},
        {pos: [6, 6, 2], state: "minecraft:polished_blackstone_bricks"},
        {pos: [7, 6, 1], state: "minecraft:polished_blackstone_bricks"},
        {pos: [7, 6, 2], state: "minecraft:polished_blackstone_bricks"},
        {pos: [7, 6, 3], state: "minecraft:polished_blackstone_bricks"},
        {pos: [7, 6, 8], state: "minecraft:polished_blackstone_bricks"},
        {pos: [7, 6, 9], state: "minecraft:blackstone"},
        {pos: [8, 6, 1], state: "minecraft:polished_blackstone_bricks"},
        {pos: [8, 6, 2], state: "minecraft:polished_blackstone_bricks"},
        {pos: [8, 6, 3], state: "minecraft:polished_blackstone_bricks"},
        {pos: [8, 6, 8], state: "minecraft:polished_blackstone_bricks"},
        {pos: [24, 6, 1], state: "minecraft:polished_blackstone_bricks"},
        {pos: [24, 6, 2], state: "minecraft:polished_blackstone_bricks"},
        {pos: [24, 6, 14], state: "minecraft:polished_blackstone_bricks"},
        {pos: [24, 6, 15], state: "minecraft:polished_blackstone_bricks"},
        {pos: [25, 6, 1], state: "minecraft:polished_blackstone_bricks"},
        {pos: [25, 6, 2], state: "minecraft:polished_blackstone_bricks"},
        {pos: [25, 6, 8], state: "minecraft:polished_blackstone_bricks"},
        {pos: [25, 6, 14], state: "minecraft:polished_blackstone_bricks"},
        {pos: [25, 6, 15], state: "minecraft:polished_blackstone_bricks"},
        {pos: [26, 6, 1], state: "minecraft:polished_blackstone_bricks"},
        {pos: [26, 6, 2], state: "minecraft:polished_blackstone_bricks"},
        {pos: [26, 6, 3], state: "minecraft:polished_blackstone_bricks"},
        {pos: [26, 6, 8], state: "minecraft:polished_blackstone_bricks"},
        {pos: [26, 6, 14], state: "minecraft:polished_blackstone_bricks"},
        {pos: [26, 6, 15], state: "minecraft:polished_blackstone_bricks"},
        {pos: [6, 7, 1], state: "minecraft:polished_blackstone_bricks"},
        {pos: [6, 7, 2], state: "minecraft:blackstone"},
        {pos: [6, 7, 3], state: "minecraft:polished_blackstone_bricks"},
        {pos: [7, 7, 1], state: "minecraft:polished_blackstone_bricks"},
        {pos: [7, 7, 3], state: "minecraft:polished_blackstone_bricks"},
        {pos: [7, 7, 8], state: "minecraft:polished_blackstone_bricks"},
        {pos: [8, 7, 1], state: "minecraft:polished_blackstone_bricks"},
        {pos: [8, 7, 2], state: "minecraft:polished_blackstone_bricks"},
        {pos: [8, 7, 3], state: "minecraft:polished_blackstone_bricks"},
        {pos: [8, 7, 8], state: "minecraft:polished_blackstone_bricks"},
        {pos: [8, 7, 9], state: "minecraft:polished_blackstone_bricks"},
        {pos: [24, 7, 1], state: "minecraft:polished_blackstone_bricks"},
        {pos: [24, 7, 8], state: "minecraft:polished_blackstone_bricks"},
        {pos: [24, 7, 14], state: "minecraft:polished_blackstone_bricks"},
        {pos: [24, 7, 15], state: "minecraft:polished_blackstone_bricks"},
        {pos: [25, 7, 1], state: "minecraft:polished_blackstone_bricks"},
        {pos: [25, 7, 2], state: "minecraft:polished_blackstone_bricks"},
        {pos: [25, 7, 8], state: "minecraft:polished_blackstone_bricks"},
        {pos: [25, 7, 14], state: "minecraft:polished_blackstone_bricks"},
        {pos: [25, 7, 15], state: "minecraft:polished_blackstone_bricks"},
        {pos: [26, 7, 1], state: "minecraft:polished_blackstone_bricks"},
        {pos: [26, 7, 2], state: "minecraft:polished_blackstone_bricks"},
        {pos: [26, 7, 3], state: "minecraft:polished_blackstone_bricks"},
        {pos: [26, 7, 8], state: "minecraft:polished_blackstone_bricks"},
        {pos: [26, 7, 14], state: "minecraft:polished_blackstone_bricks"},
        {pos: [26, 7, 15], state: "minecraft:polished_blackstone_bricks"},
        {pos: [6, 8, 1], state: "minecraft:basalt{axis:y}"},
        {pos: [6, 8, 3], state: "minecraft:blackstone"},
        {pos: [6, 8, 8], state: "minecraft:polished_blackstone_bricks"},
        {pos: [6, 8, 9], state: "minecraft:polished_blackstone_bricks"},
        {pos: [7, 8, 1], state: "minecraft:polished_blackstone_bricks"},
        {pos: [7, 8, 2], state: "minecraft:polished_blackstone_bricks"},
        {pos: [7, 8, 3], state: "minecraft:polished_blackstone_bricks"},
        {pos: [7, 8, 8], state: "minecraft:polished_blackstone_bricks"},
        {pos: [7, 8, 9], state: "minecraft:polished_blackstone_bricks"},
        {pos: [8, 8, 1], state: "minecraft:polished_blackstone_bricks"},
        {pos: [8, 8, 2], state: "minecraft:polished_blackstone_bricks"},
        {pos: [8, 8, 3], state: "minecraft:polished_blackstone_bricks"},
        {pos: [8, 8, 8], state: "minecraft:polished_blackstone_bricks"},
        {pos: [8, 8, 9], state: "minecraft:polished_blackstone_bricks"},
        {pos: [24, 8, 8], state: "minecraft:polished_blackstone_bricks"},
        {pos: [24, 8, 9], state: "minecraft:polished_blackstone_bricks"},
        {pos: [24, 8, 14], state: "minecraft:polished_blackstone_bricks"},
        {pos: [24, 8, 15], state: "minecraft:polished_blackstone_bricks"},
        {pos: [25, 8, 1], state: "minecraft:polished_blackstone_bricks"},
        {pos: [25, 8, 2], state: "minecraft:polished_blackstone_bricks"},
        {pos: [25, 8, 8], state: "minecraft:polished_blackstone_bricks"},
        {pos: [25, 8, 9], state: "minecraft:polished_blackstone_bricks"},
        {pos: [25, 8, 14], state: "minecraft:polished_blackstone_bricks"},
        {pos: [25, 8, 15], state: "minecraft:polished_blackstone_bricks"},
        {pos: [26, 8, 1], state: "minecraft:polished_blackstone_bricks"},
        {pos: [26, 8, 2], state: "minecraft:polished_blackstone_bricks"},
        {pos: [26, 8, 3], state: "minecraft:polished_blackstone_bricks"},
        {pos: [26, 8, 8], state: "minecraft:polished_blackstone_bricks"},
        {pos: [26, 8, 14], state: "minecraft:polished_blackstone_bricks"},
        {pos: [26, 8, 15], state: "minecraft:polished_blackstone_bricks"},
        {pos: [3, 9, 4], state: "minecraft:polished_blackstone_bricks"},
        {pos: [3, 9, 5], state: "minecraft:polished_blackstone_bricks"},
        {pos: [3, 9, 6], state: "minecraft:polished_blackstone_bricks"},
        {pos: [3, 9, 7], state: "minecraft:polished_blackstone_bricks"},
        {pos: [3, 9, 8], state: "minecraft:polished_blackstone_bricks"},
        {pos: [3, 9, 9], state: "minecraft:polished_blackstone_bricks"},
        {pos: [3, 9, 10], state: "minecraft:polished_blackstone_bricks"},
        {pos: [3, 9, 11], state: "minecraft:polished_blackstone_bricks"},
        {pos: [3, 9, 13], state: "minecraft:polished_blackstone_bricks"},
        {pos: [4, 9, 4], state: "minecraft:polished_blackstone_bricks"},
        {pos: [4, 9, 5], state: "minecraft:polished_blackstone_bricks"},
        {pos: [4, 9, 6], state: "minecraft:polished_blackstone_bricks"},
        {pos: [4, 9, 7], state: "minecraft:polished_blackstone_bricks"},
        {pos: [4, 9, 8], state: "minecraft:polished_blackstone_bricks"},
        {pos: [4, 9, 9], state: "minecraft:polished_blackstone_bricks"},
        {pos: [4, 9, 10], state: "minecraft:polished_blackstone_bricks"},
        {pos: [4, 9, 11], state: "minecraft:polished_blackstone_bricks"},
        {pos: [4, 9, 12], state: "minecraft:polished_blackstone_bricks"},
        {pos: [4, 9, 13], state: "minecraft:polished_blackstone_bricks"},
        {pos: [5, 9, 4], state: "minecraft:polished_blackstone_bricks"},
        {pos: [5, 9, 6], state: "minecraft:polished_blackstone_bricks"},
        {pos: [5, 9, 7], state: "minecraft:polished_blackstone_bricks"},
        {pos: [5, 9, 8], state: "minecraft:polished_blackstone_bricks"},
        {pos: [5, 9, 9], state: "minecraft:polished_blackstone_bricks"},
        {pos: [5, 9, 10], state: "minecraft:polished_blackstone_bricks"},
        {pos: [5, 9, 11], state: "minecraft:polished_blackstone_bricks"},
        {pos: [5, 9, 12], state: "minecraft:polished_blackstone_bricks"},
        {pos: [5, 9, 13], state: "minecraft:polished_blackstone_bricks"},
        {pos: [6, 9, 1], state: "minecraft:polished_blackstone_bricks"},
        {pos: [6, 9, 3], state: "minecraft:polished_blackstone_bricks"},
        {pos: [6, 9, 4], state: "minecraft:polished_blackstone_bricks"},
        {pos: [6, 9, 8], state: "minecraft:polished_blackstone_bricks"},
        {pos: [6, 9, 9], state: "minecraft:polished_blackstone_bricks"},
        {pos: [6, 9, 10], state: "minecraft:polished_blackstone_bricks"},
        {pos: [6, 9, 11], state: "minecraft:polished_blackstone_bricks"},
        {pos: [6, 9, 12], state: "minecraft:polished_blackstone_bricks"},
        {pos: [6, 9, 13], state: "minecraft:polished_blackstone_bricks"},
        {pos: [7, 9, 1], state: "minecraft:polished_blackstone_bricks"},
        {pos: [7, 9, 2], state: "minecraft:polished_blackstone_bricks"},
        {pos: [7, 9, 3], state: "minecraft:polished_blackstone_bricks"},
        {pos: [7, 9, 4], state: "minecraft:polished_blackstone_bricks"},
        {pos: [7, 9, 8], state: "minecraft:polished_blackstone_bricks"},
        {pos: [7, 9, 9], state: "minecraft:polished_blackstone_bricks"},
        {pos: [7, 9, 10], state: "minecraft:polished_blackstone_bricks"},
        {pos: [7, 9, 11], state: "minecraft:polished_blackstone_bricks"},
        {pos: [7, 9, 12], state: "minecraft:polished_blackstone_bricks"},
        {pos: [7, 9, 13], state: "minecraft:polished_blackstone_bricks"},
        {pos: [8, 9, 1], state: "minecraft:polished_blackstone_bricks"},
        {pos: [8, 9, 2], state: "minecraft:polished_blackstone_bricks"},
        {pos: [8, 9, 3], state: "minecraft:polished_blackstone_bricks"},
        {pos: [8, 9, 4], state: "minecraft:polished_blackstone_bricks"},
        {pos: [8, 9, 5], state: "minecraft:polished_blackstone_bricks"},
        {pos: [8, 9, 8], state: "minecraft:polished_blackstone_bricks"},
        {pos: [8, 9, 9], state: "minecraft:polished_blackstone_bricks"},
        {pos: [8, 9, 10], state: "minecraft:polished_blackstone_bricks"},
        {pos: [8, 9, 11], state: "minecraft:polished_blackstone_bricks"},
        {pos: [8, 9, 12], state: "minecraft:polished_blackstone_bricks"},
        {pos: [8, 9, 13], state: "minecraft:polished_blackstone_bricks"},
        {pos: [9, 9, 4], state: "minecraft:polished_blackstone_bricks"},
        {pos: [9, 9, 5], state: "minecraft:polished_blackstone_bricks"},
        {pos: [9, 9, 6], state: "minecraft:polished_blackstone_bricks"},
        {pos: [9, 9, 7], state: "minecraft:polished_blackstone_bricks"},
        {pos: [9, 9, 8], state: "minecraft:polished_blackstone_bricks"},
        {pos: [9, 9, 9], state: "minecraft:polished_blackstone_bricks"},
        {pos: [9, 9, 10], state: "minecraft:polished_blackstone_bricks"},
        {pos: [9, 9, 11], state: "minecraft:polished_blackstone_bricks"},
        {pos: [9, 9, 12], state: "minecraft:polished_blackstone_bricks"},
        {pos: [9, 9, 13], state: "minecraft:polished_blackstone_bricks"},
        {pos: [10, 9, 4], state: "minecraft:polished_blackstone_bricks"},
        {pos: [10, 9, 5], state: "minecraft:polished_blackstone_bricks"},
        {pos: [10, 9, 6], state: "minecraft:polished_blackstone_bricks"},
        {pos: [10, 9, 7], state: "minecraft:polished_blackstone_bricks"},
        {pos: [10, 9, 9], state: "minecraft:polished_blackstone_bricks"},
        {pos: [10, 9, 10], state: "minecraft:polished_blackstone_bricks"},
        {pos: [10, 9, 11], state: "minecraft:polished_blackstone_bricks"},
        {pos: [10, 9, 12], state: "minecraft:polished_blackstone_bricks"},
        {pos: [10, 9, 13], state: "minecraft:polished_blackstone_bricks"},
        {pos: [11, 9, 4], state: "minecraft:polished_blackstone_bricks"},
        {pos: [11, 9, 5], state: "minecraft:polished_blackstone_bricks"},
        {pos: [11, 9, 6], state: "minecraft:polished_blackstone_bricks"},
        {pos: [11, 9, 9], state: "minecraft:polished_blackstone_bricks"},
        {pos: [11, 9, 10], state: "minecraft:polished_blackstone_bricks"},
        {pos: [11, 9, 11], state: "minecraft:polished_blackstone_bricks"},
        {pos: [11, 9, 12], state: "minecraft:polished_blackstone_bricks"},
        {pos: [11, 9, 13], state: "minecraft:polished_blackstone_bricks"},
        {pos: [12, 9, 4], state: "minecraft:polished_blackstone_bricks"},
        {pos: [12, 9, 5], state: "minecraft:polished_blackstone_bricks"},
        {pos: [12, 9, 11], state: "minecraft:polished_blackstone_bricks"},
        {pos: [12, 9, 12], state: "minecraft:polished_blackstone_bricks"},
        {pos: [12, 9, 13], state: "minecraft:polished_blackstone_bricks"},
        {pos: [13, 9, 4], state: "minecraft:polished_blackstone_bricks"},
        {pos: [13, 9, 5], state: "minecraft:polished_blackstone_bricks"},
        {pos: [13, 9, 11], state: "minecraft:polished_blackstone_bricks"},
        {pos: [13, 9, 12], state: "minecraft:polished_blackstone_bricks"},
        {pos: [13, 9, 13], state: "minecraft:polished_blackstone_bricks"},
        {pos: [14, 9, 4], state: "minecraft:polished_blackstone_bricks"},
        {pos: [14, 9, 5], state: "minecraft:polished_blackstone_bricks"},
        {pos: [14, 9, 11], state: "minecraft:polished_blackstone_bricks"},
        {pos: [14, 9, 12], state: "minecraft:polished_blackstone_bricks"},
        {pos: [14, 9, 13], state: "minecraft:polished_blackstone_bricks"},
        {pos: [15, 9, 4], state: "minecraft:polished_blackstone_bricks"},
        {pos: [15, 9, 5], state: "minecraft:polished_blackstone_bricks"},
        {pos: [15, 9, 10], state: "minecraft:polished_blackstone_bricks"},
        {pos: [15, 9, 11], state: "minecraft:polished_blackstone_bricks"},
        {pos: [15, 9, 12], state: "minecraft:polished_blackstone_bricks"},
        {pos: [15, 9, 13], state: "minecraft:polished_blackstone_bricks"},
        {pos: [16, 9, 4], state: "minecraft:polished_blackstone_bricks"},
        {pos: [16, 9, 5], state: "minecraft:polished_blackstone_bricks"},
        {pos: [16, 9, 6], state: "minecraft:polished_blackstone_bricks"},
        {pos: [16, 9, 10], state: "minecraft:polished_blackstone_bricks"},
        {pos: [16, 9, 11], state: "minecraft:polished_blackstone_bricks"},
        {pos: [16, 9, 12], state: "minecraft:polished_blackstone_bricks"},
        {pos: [16, 9, 13], state: "minecraft:polished_blackstone_bricks"},
        {pos: [17, 9, 4], state: "minecraft:polished_blackstone_bricks"},
        {pos: [17, 9, 5], state: "minecraft:polished_blackstone_bricks"},
        {pos: [17, 9, 6], state: "minecraft:polished_blackstone_bricks"},
        {pos: [17, 9, 10], state: "minecraft:polished_blackstone_bricks"},
        {pos: [17, 9, 11], state: "minecraft:polished_blackstone_bricks"},
        {pos: [17, 9, 12], state: "minecraft:polished_blackstone_bricks"},
        {pos: [17, 9, 13], state: "minecraft:polished_blackstone_bricks"},
        {pos: [18, 9, 4], state: "minecraft:polished_blackstone_bricks"},
        {pos: [18, 9, 5], state: "minecraft:polished_blackstone_bricks"},
        {pos: [18, 9, 6], state: "minecraft:polished_blackstone_bricks"},
        {pos: [18, 9, 7], state: "minecraft:polished_blackstone_bricks"},
        {pos: [18, 9, 8], state: "minecraft:polished_blackstone_bricks"},
        {pos: [18, 9, 9], state: "minecraft:polished_blackstone_bricks"},
        {pos: [18, 9, 10], state: "minecraft:polished_blackstone_bricks"},
        {pos: [18, 9, 11], state: "minecraft:polished_blackstone_bricks"},
        {pos: [18, 9, 12], state: "minecraft:polished_blackstone_bricks"},
        {pos: [19, 9, 4], state: "minecraft:polished_blackstone_bricks"},
        {pos: [19, 9, 5], state: "minecraft:polished_blackstone_bricks"},
        {pos: [19, 9, 6], state: "minecraft:polished_blackstone_bricks"},
        {pos: [19, 9, 7], state: "minecraft:polished_blackstone_bricks"},
        {pos: [19, 9, 8], state: "minecraft:polished_blackstone_bricks"},
        {pos: [19, 9, 9], state: "minecraft:polished_blackstone_bricks"},
        {pos: [19, 9, 10], state: "minecraft:polished_blackstone_bricks"},
        {pos: [19, 9, 11], state: "minecraft:polished_blackstone_bricks"},
        {pos: [20, 9, 4], state: "minecraft:polished_blackstone_bricks"},
        {pos: [20, 9, 5], state: "minecraft:polished_blackstone_bricks"},
        {pos: [20, 9, 6], state: "minecraft:polished_blackstone_bricks"},
        {pos: [20, 9, 7], state: "minecraft:polished_blackstone_bricks"},
        {pos: [20, 9, 8], state: "minecraft:polished_blackstone_bricks"},
        {pos: [20, 9, 9], state: "minecraft:polished_blackstone_bricks"},
        {pos: [20, 9, 10], state: "minecraft:polished_blackstone_bricks"},
        {pos: [20, 9, 11], state: "minecraft:polished_blackstone_bricks"},
        {pos: [21, 9, 6], state: "minecraft:polished_blackstone_bricks"},
        {pos: [21, 9, 7], state: "minecraft:polished_blackstone_bricks"},
        {pos: [21, 9, 8], state: "minecraft:polished_blackstone_bricks"},
        {pos: [21, 9, 9], state: "minecraft:polished_blackstone_bricks"},
        {pos: [21, 9, 10], state: "minecraft:polished_blackstone_bricks"},
        {pos: [21, 9, 11], state: "minecraft:polished_blackstone_bricks"},
        {pos: [22, 9, 7], state: "minecraft:polished_blackstone_bricks"},
        {pos: [22, 9, 8], state: "minecraft:polished_blackstone_bricks"},
        {pos: [22, 9, 9], state: "minecraft:polished_blackstone_bricks"},
        {pos: [22, 9, 10], state: "minecraft:polished_blackstone_bricks"},
        {pos: [22, 9, 11], state: "minecraft:polished_blackstone_bricks"},
        {pos: [23, 9, 7], state: "minecraft:polished_blackstone_bricks"},
        {pos: [23, 9, 8], state: "minecraft:polished_blackstone_bricks"},
        {pos: [23, 9, 9], state: "minecraft:polished_blackstone_bricks"},
        {pos: [23, 9, 10], state: "minecraft:polished_blackstone_bricks"},
        {pos: [23, 9, 11], state: "minecraft:polished_blackstone_bricks"},
        {pos: [24, 9, 4], state: "minecraft:polished_blackstone_bricks"},
        {pos: [24, 9, 6], state: "minecraft:polished_blackstone_bricks"},
        {pos: [24, 9, 7], state: "minecraft:polished_blackstone_bricks"},
        {pos: [24, 9, 8], state: "minecraft:polished_blackstone_bricks"},
        {pos: [24, 9, 9], state: "minecraft:polished_blackstone_bricks"},
        {pos: [24, 9, 10], state: "minecraft:polished_blackstone_bricks"},
        {pos: [24, 9, 11], state: "minecraft:polished_blackstone_bricks"},
        {pos: [24, 9, 13], state: "minecraft:polished_blackstone_bricks"},
        {pos: [24, 9, 14], state: "minecraft:polished_blackstone_bricks"},
        {pos: [24, 9, 15], state: "minecraft:polished_blackstone_bricks"},
        {pos: [25, 9, 1], state: "minecraft:polished_blackstone_bricks"},
        {pos: [25, 9, 2], state: "minecraft:polished_blackstone_bricks"},
        {pos: [25, 9, 4], state: "minecraft:polished_blackstone_bricks"},
        {pos: [25, 9, 5], state: "minecraft:polished_blackstone_bricks"},
        {pos: [25, 9, 6], state: "minecraft:polished_blackstone_bricks"},
        {pos: [25, 9, 7], state: "minecraft:polished_blackstone_bricks"},
        {pos: [25, 9, 8], state: "minecraft:polished_blackstone_bricks"},
        {pos: [25, 9, 9], state: "minecraft:polished_blackstone_bricks"},
        {pos: [25, 9, 10], state: "minecraft:polished_blackstone_bricks"},
        {pos: [25, 9, 11], state: "minecraft:polished_blackstone_bricks"},
        {pos: [25, 9, 13], state: "minecraft:polished_blackstone_bricks"},
        {pos: [25, 9, 14], state: "minecraft:polished_blackstone_bricks"},
        {pos: [25, 9, 15], state: "minecraft:polished_blackstone_bricks"},
        {pos: [26, 9, 1], state: "minecraft:polished_blackstone_bricks"},
        {pos: [26, 9, 2], state: "minecraft:polished_blackstone_bricks"},
        {pos: [26, 9, 3], state: "minecraft:polished_blackstone_bricks"},
        {pos: [26, 9, 4], state: "minecraft:polished_blackstone_bricks"},
        {pos: [26, 9, 5], state: "minecraft:polished_blackstone_bricks"},
        {pos: [26, 9, 6], state: "minecraft:polished_blackstone_bricks"},
        {pos: [26, 9, 7], state: "minecraft:polished_blackstone_bricks"},
        {pos: [26, 9, 8], state: "minecraft:polished_blackstone_bricks"},
        {pos: [26, 9, 9], state: "minecraft:polished_blackstone_bricks"},
        {pos: [26, 9, 10], state: "minecraft:polished_blackstone_bricks"},
        {pos: [26, 9, 11], state: "minecraft:polished_blackstone_bricks"},
        {pos: [26, 9, 13], state: "minecraft:polished_blackstone_bricks"},
        {pos: [26, 9, 14], state: "minecraft:polished_blackstone_bricks"},
        {pos: [26, 9, 15], state: "minecraft:polished_blackstone_bricks"},
        {pos: [27, 9, 5], state: "minecraft:polished_blackstone_bricks"},
        {pos: [27, 9, 6], state: "minecraft:polished_blackstone_bricks"},
        {pos: [27, 9, 7], state: "minecraft:polished_blackstone_bricks"},
        {pos: [27, 9, 8], state: "minecraft:polished_blackstone_bricks"},
        {pos: [27, 9, 9], state: "minecraft:polished_blackstone_bricks"},
        {pos: [27, 9, 10], state: "minecraft:polished_blackstone_bricks"},
        {pos: [27, 9, 11], state: "minecraft:polished_blackstone_bricks"},
        {pos: [27, 9, 12], state: "minecraft:polished_blackstone_bricks"},
        {pos: [27, 9, 13], state: "minecraft:polished_blackstone_bricks"},
        {pos: [28, 9, 5], state: "minecraft:polished_blackstone_bricks"},
        {pos: [28, 9, 6], state: "minecraft:polished_blackstone_bricks"},
        {pos: [28, 9, 7], state: "minecraft:polished_blackstone_bricks"},
        {pos: [28, 9, 8], state: "minecraft:polished_blackstone_bricks"},
        {pos: [28, 9, 9], state: "minecraft:polished_blackstone_bricks"},
        {pos: [28, 9, 10], state: "minecraft:polished_blackstone_bricks"},
        {pos: [28, 9, 11], state: "minecraft:polished_blackstone_bricks"},
        {pos: [28, 9, 12], state: "minecraft:polished_blackstone_bricks"},
        {pos: [28, 9, 13], state: "minecraft:polished_blackstone_bricks"},
        {pos: [29, 9, 4], state: "minecraft:polished_blackstone_bricks"},
        {pos: [29, 9, 5], state: "minecraft:polished_blackstone_bricks"},
        {pos: [29, 9, 6], state: "minecraft:polished_blackstone_bricks"},
        {pos: [29, 9, 7], state: "minecraft:polished_blackstone_bricks"},
        {pos: [29, 9, 8], state: "minecraft:polished_blackstone_bricks"},
        {pos: [29, 9, 9], state: "minecraft:polished_blackstone_bricks"},
        {pos: [29, 9, 10], state: "minecraft:polished_blackstone_bricks"},
        {pos: [29, 9, 11], state: "minecraft:polished_blackstone_bricks"},
        {pos: [29, 9, 12], state: "minecraft:polished_blackstone_bricks"},
        {pos: [29, 9, 13], state: "minecraft:polished_blackstone_bricks"},
        {pos: [30, 9, 6], state: "minecraft:polished_blackstone_bricks"},
        {pos: [30, 9, 7], state: "minecraft:polished_blackstone_bricks"},
        {pos: [30, 9, 8], state: "minecraft:polished_blackstone_bricks"},
        {pos: [30, 9, 9], state: "minecraft:polished_blackstone_bricks"},
        {pos: [30, 9, 10], state: "minecraft:polished_blackstone_bricks"},
        {pos: [30, 9, 11], state: "minecraft:polished_blackstone_bricks"},
        {pos: [30, 9, 12], state: "minecraft:polished_blackstone_bricks"},
        {pos: [3, 10, 4], state: "minecraft:polished_blackstone_bricks"},
        {pos: [3, 10, 5], state: "minecraft:polished_blackstone_bricks"},
        {pos: [3, 10, 6], state: "minecraft:polished_blackstone_bricks"},
        {pos: [3, 10, 7], state: "minecraft:polished_blackstone_bricks"},
        {pos: [3, 10, 8], state: "minecraft:polished_blackstone_bricks"},
        {pos: [3, 10, 9], state: "minecraft:polished_blackstone_bricks"},
        {pos: [3, 10, 10], state: "minecraft:polished_blackstone_bricks"},
        {pos: [3, 10, 11], state: "minecraft:polished_blackstone_bricks"},
        {pos: [4, 10, 4], state: "minecraft:polished_blackstone_bricks"},
        {pos: [4, 10, 5], state: "minecraft:polished_blackstone_bricks"},
        {pos: [4, 10, 6], state: "minecraft:blackstone"},
        {pos: [4, 10, 7], state: "minecraft:polished_blackstone_bricks"},
        {pos: [4, 10, 8], state: "minecraft:polished_blackstone_bricks"},
        {pos: [4, 10, 9], state: "minecraft:polished_blackstone_bricks"},
        {pos: [4, 10, 10], state: "minecraft:polished_blackstone_bricks"},
        {pos: [4, 10, 11], state: "minecraft:polished_blackstone_bricks"},
        {pos: [4, 10, 12], state: "minecraft:polished_blackstone_bricks"},
        {pos: [4, 10, 13], state: "minecraft:polished_blackstone_bricks"},
        {pos: [5, 10, 4], state: "minecraft:blackstone"},
        {pos: [5, 10, 7], state: "minecraft:polished_blackstone_bricks"},
        {pos: [5, 10, 8], state: "minecraft:polished_blackstone_bricks"},
        {pos: [5, 10, 9], state: "minecraft:polished_blackstone_bricks"},
        {pos: [5, 10, 10], state: "minecraft:polished_blackstone_bricks"},
        {pos: [5, 10, 11], state: "minecraft:polished_blackstone_bricks"},
        {pos: [5, 10, 12], state: "minecraft:polished_blackstone_bricks"},
        {pos: [5, 10, 13], state: "minecraft:polished_blackstone_bricks"},
        {pos: [6, 10, 1], state: "minecraft:polished_blackstone_bricks"},
        {pos: [6, 10, 2], state: "minecraft:polished_blackstone_bricks"},
        {pos: [6, 10, 3], state: "minecraft:polished_blackstone_bricks"},
        {pos: [6, 10, 4], state: "minecraft:blackstone"},
        {pos: [6, 10, 8], state: "minecraft:polished_blackstone_bricks"},
        {pos: [6, 10, 9], state: "minecraft:polished_blackstone_bricks"},
        {pos: [6, 10, 10], state: "minecraft:polished_blackstone_bricks"},
        {pos: [6, 10, 11], state: "minecraft:polished_blackstone_bricks"},
        {pos: [6, 10, 12], state: "minecraft:polished_blackstone_bricks"},
        {pos: [6, 10, 13], state: "minecraft:polished_blackstone_bricks"},
        {pos: [7, 10, 1], state: "minecraft:polished_blackstone_bricks"},
        {pos: [7, 10, 2], state: "minecraft:polished_blackstone_bricks"},
        {pos: [7, 10, 3], state: "minecraft:polished_blackstone_bricks"},
        {pos: [7, 10, 4], state: "minecraft:polished_blackstone_bricks"},
        {pos: [7, 10, 8], state: "minecraft:polished_blackstone_bricks"},
        {pos: [7, 10, 9], state: "minecraft:polished_blackstone_bricks"},
        {pos: [7, 10, 10], state: "minecraft:polished_blackstone_bricks"},
        {pos: [7, 10, 11], state: "minecraft:polished_blackstone_bricks"},
        {pos: [7, 10, 12], state: "minecraft:polished_blackstone_bricks"},
        {pos: [8, 10, 1], state: "minecraft:polished_blackstone_bricks"},
        {pos: [8, 10, 2], state: "minecraft:polished_blackstone_bricks"},
        {pos: [8, 10, 3], state: "minecraft:polished_blackstone_bricks"},
        {pos: [8, 10, 4], state: "minecraft:polished_blackstone_bricks"},
        {pos: [8, 10, 5], state: "minecraft:blackstone"},
        {pos: [8, 10, 7], state: "minecraft:polished_blackstone_bricks"},
        {pos: [8, 10, 8], state: "minecraft:polished_blackstone_bricks"},
        {pos: [8, 10, 9], state: "minecraft:polished_blackstone_bricks"},
        {pos: [8, 10, 10], state: "minecraft:polished_blackstone_bricks"},
        {pos: [8, 10, 11], state: "minecraft:polished_blackstone_bricks"},
        {pos: [8, 10, 12], state: "minecraft:polished_blackstone_bricks"},
        {pos: [8, 10, 13], state: "minecraft:polished_blackstone_bricks"},
        {pos: [9, 10, 4], state: "minecraft:polished_blackstone_bricks"},
        {pos: [9, 10, 5], state: "minecraft:polished_blackstone_bricks"},
        {pos: [9, 10, 6], state: "minecraft:polished_blackstone_bricks"},
        {pos: [9, 10, 7], state: "minecraft:polished_blackstone_bricks"},
        {pos: [9, 10, 8], state: "minecraft:polished_blackstone_bricks"},
        {pos: [9, 10, 9], state: "minecraft:polished_blackstone_bricks"},
        {pos: [9, 10, 10], state: "minecraft:polished_blackstone_bricks"},
        {pos: [9, 10, 11], state: "minecraft:polished_blackstone_bricks"},
        {pos: [9, 10, 12], state: "minecraft:polished_blackstone_bricks"},
        {pos: [9, 10, 13], state: "minecraft:polished_blackstone_bricks"},
        {pos: [10, 10, 4], state: "minecraft:polished_blackstone_bricks"},
        {pos: [10, 10, 5], state: "minecraft:polished_blackstone_bricks"},
        {pos: [10, 10, 6], state: "minecraft:polished_blackstone_bricks"},
        {pos: [10, 10, 7], state: "minecraft:polished_blackstone_bricks"},
        {pos: [10, 10, 8], state: "minecraft:polished_blackstone_bricks"},
        {pos: [10, 10, 9], state: "minecraft:polished_blackstone_bricks"},
        {pos: [10, 10, 10], state: "minecraft:basalt{axis:y}"},
        {pos: [10, 10, 11], state: "minecraft:basalt{axis:y}"},
        {pos: [10, 10, 12], state: "minecraft:basalt{axis:y}"},
        {pos: [10, 10, 13], state: "minecraft:basalt{axis:y}"},
        {pos: [11, 10, 4], state: "minecraft:basalt{axis:y}"},
        {pos: [11, 10, 5], state: "minecraft:polished_blackstone_bricks"},
        {pos: [11, 10, 6], state: "minecraft:polished_blackstone_bricks"},
        {pos: [11, 10, 7], state: "minecraft:polished_blackstone_bricks"},
        {pos: [11, 10, 8], state: "minecraft:polished_blackstone_bricks"},
        {pos: [11, 10, 9], state: "minecraft:polished_blackstone_bricks"},
        {pos: [11, 10, 10], state: "minecraft:basalt{axis:y}"},
        {pos: [11, 10, 11], state: "minecraft:basalt{axis:y}"},
        {pos: [11, 10, 12], state: "minecraft:basalt{axis:y}"},
        {pos: [11, 10, 13], state: "minecraft:basalt{axis:y}"},
        {pos: [12, 10, 4], state: "minecraft:polished_blackstone_bricks"},
        {pos: [12, 10, 5], state: "minecraft:polished_blackstone_bricks"},
        {pos: [12, 10, 6], state: "minecraft:polished_blackstone_bricks"},
        {pos: [12, 10, 7], state: "minecraft:polished_blackstone_bricks"},
        {pos: [12, 10, 8], state: "minecraft:polished_blackstone_bricks"},
        {pos: [12, 10, 9], state: "minecraft:polished_blackstone_bricks"},
        {pos: [12, 10, 10], state: "minecraft:basalt{axis:y}"},
        {pos: [12, 10, 11], state: "minecraft:basalt{axis:y}"},
        {pos: [12, 10, 12], state: "minecraft:basalt{axis:y}"},
        {pos: [12, 10, 13], state: "minecraft:basalt{axis:y}"},
        {pos: [13, 10, 4], state: "minecraft:polished_blackstone_bricks"},
        {pos: [13, 10, 5], state: "minecraft:polished_blackstone_bricks"},
        {pos: [13, 10, 6], state: "minecraft:polished_blackstone_bricks"},
        {pos: [13, 10, 7], state: "minecraft:polished_blackstone_bricks"},
        {pos: [13, 10, 9], state: "minecraft:polished_blackstone_bricks"},
        {pos: [13, 10, 10], state: "minecraft:basalt{axis:y}"},
        {pos: [13, 10, 11], state: "minecraft:basalt{axis:y}"},
        {pos: [13, 10, 12], state: "minecraft:basalt{axis:y}"},
        {pos: [13, 10, 13], state: "minecraft:blackstone"},
        {pos: [13, 10, 14], state: "minecraft:polished_blackstone_bricks"},
        {pos: [14, 10, 4], state: "minecraft:polished_blackstone_bricks"},
        {pos: [14, 10, 5], state: "minecraft:polished_blackstone_bricks"},
        {pos: [14, 10, 6], state: "minecraft:polished_blackstone_bricks"},
        {pos: [14, 10, 7], state: "minecraft:polished_blackstone_bricks"},
        {pos: [14, 10, 11], state: "minecraft:basalt{axis:y}"},
        {pos: [14, 10, 12], state: "minecraft:basalt{axis:y}"},
        {pos: [14, 10, 13], state: "minecraft:blackstone"},
        {pos: [15, 10, 4], state: "minecraft:basalt{axis:y}"},
        {pos: [15, 10, 5], state: "minecraft:polished_blackstone_bricks"},
        {pos: [15, 10, 6], state: "minecraft:blackstone"},
        {pos: [15, 10, 10], state: "minecraft:basalt{axis:y}"},
        {pos: [15, 10, 11], state: "minecraft:basalt{axis:y}"},
        {pos: [15, 10, 12], state: "minecraft:basalt{axis:y}"},
        {pos: [15, 10, 13], state: "minecraft:blackstone"},
        {pos: [16, 10, 4], state: "minecraft:polished_blackstone_bricks"},
        {pos: [16, 10, 5], state: "minecraft:polished_blackstone_bricks"},
        {pos: [16, 10, 6], state: "minecraft:blackstone"},
        {pos: [16, 10, 11], state: "minecraft:basalt{axis:y}"},
        {pos: [16, 10, 12], state: "minecraft:basalt{axis:y}"},
        {pos: [16, 10, 13], state: "minecraft:blackstone"},
        {pos: [17, 10, 4], state: "minecraft:polished_blackstone_bricks"},
        {pos: [17, 10, 5], state: "minecraft:polished_blackstone_bricks"},
        {pos: [17, 10, 6], state: "minecraft:polished_blackstone_bricks"},
        {pos: [17, 10, 10], state: "minecraft:basalt{axis:y}"},
        {pos: [17, 10, 11], state: "minecraft:basalt{axis:y}"},
        {pos: [17, 10, 12], state: "minecraft:basalt{axis:y}"},
        {pos: [17, 10, 13], state: "minecraft:blackstone"},
        {pos: [18, 10, 4], state: "minecraft:basalt{axis:y}"},
        {pos: [18, 10, 5], state: "minecraft:polished_blackstone_bricks"},
        {pos: [18, 10, 6], state: "minecraft:polished_blackstone_bricks"},
        {pos: [18, 10, 7], state: "minecraft:blackstone"},
        {pos: [18, 10, 8], state: "minecraft:blackstone"},
        {pos: [18, 10, 10], state: "minecraft:basalt{axis:y}"},
        {pos: [18, 10, 11], state: "minecraft:basalt{axis:y}"},
        {pos: [18, 10, 12], state: "minecraft:basalt{axis:y}"},
        {pos: [18, 10, 13], state: "minecraft:blackstone"},
        {pos: [19, 10, 4], state: "minecraft:basalt{axis:y}"},
        {pos: [19, 10, 5], state: "minecraft:polished_blackstone_bricks"},
        {pos: [19, 10, 6], state: "minecraft:polished_blackstone_bricks"},
        {pos: [19, 10, 7], state: "minecraft:polished_blackstone_bricks"},
        {pos: [19, 10, 8], state: "minecraft:polished_blackstone_bricks"},
        {pos: [19, 10, 9], state: "minecraft:polished_blackstone_bricks"},
        {pos: [19, 10, 10], state: "minecraft:basalt{axis:y}"},
        {pos: [19, 10, 11], state: "minecraft:basalt{axis:y}"},
        {pos: [19, 10, 12], state: "minecraft:basalt{axis:y}"},
        {pos: [19, 10, 13], state: "minecraft:basalt{axis:y}"},
        {pos: [20, 10, 4], state: "minecraft:polished_blackstone_bricks"},
        {pos: [20, 10, 5], state: "minecraft:polished_blackstone_bricks"},
        {pos: [20, 10, 6], state: "minecraft:polished_blackstone_bricks"},
        {pos: [20, 10, 7], state: "minecraft:polished_blackstone_bricks"},
        {pos: [20, 10, 8], state: "minecraft:polished_blackstone_bricks"},
        {pos: [20, 10, 9], state: "minecraft:polished_blackstone_bricks"},
        {pos: [20, 10, 10], state: "minecraft:basalt{axis:y}"},
        {pos: [20, 10, 11], state: "minecraft:basalt{axis:y}"},
        {pos: [20, 10, 12], state: "minecraft:basalt{axis:y}"},
        {pos: [21, 10, 4], state: "minecraft:polished_blackstone_bricks"},
        {pos: [21, 10, 5], state: "minecraft:polished_blackstone_bricks"},
        {pos: [21, 10, 6], state: "minecraft:polished_blackstone_bricks"},
        {pos: [21, 10, 7], state: "minecraft:polished_blackstone_bricks"},
        {pos: [21, 10, 8], state: "minecraft:polished_blackstone_bricks"},
        {pos: [21, 10, 9], state: "minecraft:polished_blackstone_bricks"},
        {pos: [21, 10, 10], state: "minecraft:basalt{axis:y}"},
        {pos: [21, 10, 11], state: "minecraft:basalt{axis:y}"},
        {pos: [21, 10, 12], state: "minecraft:basalt{axis:y}"},
        {pos: [21, 10, 13], state: "minecraft:basalt{axis:y}"},
        {pos: [22, 10, 4], state: "minecraft:polished_blackstone_bricks"},
        {pos: [22, 10, 6], state: "minecraft:polished_blackstone_bricks"},
        {pos: [22, 10, 7], state: "minecraft:polished_blackstone_bricks"},
        {pos: [22, 10, 8], state: "minecraft:polished_blackstone_bricks"},
        {pos: [22, 10, 9], state: "minecraft:polished_blackstone_bricks"},
        {pos: [22, 10, 10], state: "minecraft:basalt{axis:y}"},
        {pos: [22, 10, 11], state: "minecraft:basalt{axis:y}"},
        {pos: [23, 10, 4], state: "minecraft:polished_blackstone_bricks"},
        {pos: [23, 10, 6], state: "minecraft:polished_blackstone_bricks"},
        {pos: [23, 10, 7], state: "minecraft:polished_blackstone_bricks"},
        {pos: [23, 10, 8], state: "minecraft:polished_blackstone_bricks"},
        {pos: [23, 10, 9], state: "minecraft:polished_blackstone_bricks"},
        {pos: [23, 10, 10], state: "minecraft:polished_blackstone_bricks"},
        {pos: [23, 10, 11], state: "minecraft:polished_blackstone_bricks"},
        {pos: [23, 10, 12], state: "minecraft:polished_blackstone_bricks"},
        {pos: [23, 10, 13], state: "minecraft:polished_blackstone_bricks"},
        {pos: [24, 10, 4], state: "minecraft:polished_blackstone_bricks"},
        {pos: [24, 10, 5], state: "minecraft:polished_blackstone_bricks"},
        {pos: [24, 10, 6], state: "minecraft:polished_blackstone_bricks"},
        {pos: [24, 10, 7], state: "minecraft:polished_blackstone_bricks"},
        {pos: [24, 10, 8], state: "minecraft:polished_blackstone_bricks"},
        {pos: [24, 10, 9], state: "minecraft:polished_blackstone_bricks"},
        {pos: [24, 10, 10], state: "minecraft:polished_blackstone_bricks"},
        {pos: [24, 10, 11], state: "minecraft:polished_blackstone_bricks"},
        {pos: [24, 10, 12], state: "minecraft:polished_blackstone_bricks"},
        {pos: [24, 10, 13], state: "minecraft:polished_blackstone_bricks"},
        {pos: [24, 10, 14], state: "minecraft:polished_blackstone_bricks"},
        {pos: [24, 10, 15], state: "minecraft:blackstone"},
        {pos: [25, 10, 1], state: "minecraft:polished_blackstone_bricks"},
        {pos: [25, 10, 2], state: "minecraft:polished_blackstone_bricks"},
        {pos: [25, 10, 3], state: "minecraft:polished_blackstone_bricks"},
        {pos: [25, 10, 4], state: "minecraft:polished_blackstone_bricks"},
        {pos: [25, 10, 5], state: "minecraft:polished_blackstone_bricks"},
        {pos: [25, 10, 6], state: "minecraft:polished_blackstone_bricks"},
        {pos: [25, 10, 7], state: "minecraft:polished_blackstone_bricks"},
        {pos: [25, 10, 8], state: "minecraft:polished_blackstone_bricks"},
        {pos: [25, 10, 9], state: "minecraft:polished_blackstone_bricks"},
        {pos: [25, 10, 10], state: "minecraft:polished_blackstone_bricks"},
        {pos: [25, 10, 11], state: "minecraft:polished_blackstone_bricks"},
        {pos: [25, 10, 13], state: "minecraft:polished_blackstone_bricks"},
        {pos: [25, 10, 14], state: "minecraft:polished_blackstone_bricks"},
        {pos: [25, 10, 15], state: "minecraft:polished_blackstone_bricks"},
        {pos: [26, 10, 1], state: "minecraft:polished_blackstone_bricks"},
        {pos: [26, 10, 2], state: "minecraft:polished_blackstone_bricks"},
        {pos: [26, 10, 3], state: "minecraft:polished_blackstone_bricks"},
        {pos: [26, 10, 4], state: "minecraft:polished_blackstone_bricks"},
        {pos: [26, 10, 5], state: "minecraft:polished_blackstone_bricks"},
        {pos: [26, 10, 6], state: "minecraft:polished_blackstone_bricks"},
        {pos: [26, 10, 7], state: "minecraft:polished_blackstone_bricks"},
        {pos: [26, 10, 8], state: "minecraft:polished_blackstone_bricks"},
        {pos: [26, 10, 9], state: "minecraft:polished_blackstone_bricks"},
        {pos: [26, 10, 10], state: "minecraft:polished_blackstone_bricks"},
        {pos: [26, 10, 11], state: "minecraft:polished_blackstone_bricks"},
        {pos: [26, 10, 12], state: "minecraft:polished_blackstone_bricks"},
        {pos: [26, 10, 13], state: "minecraft:polished_blackstone_bricks"},
        {pos: [26, 10, 14], state: "minecraft:polished_blackstone_bricks"},
        {pos: [26, 10, 15], state: "minecraft:polished_blackstone_bricks"},
        {pos: [27, 10, 4], state: "minecraft:polished_blackstone_bricks"},
        {pos: [27, 10, 5], state: "minecraft:polished_blackstone_bricks"},
        {pos: [27, 10, 6], state: "minecraft:polished_blackstone_bricks"},
        {pos: [27, 10, 7], state: "minecraft:polished_blackstone_bricks"},
        {pos: [27, 10, 8], state: "minecraft:polished_blackstone_bricks"},
        {pos: [27, 10, 9], state: "minecraft:polished_blackstone_bricks"},
        {pos: [27, 10, 10], state: "minecraft:polished_blackstone_bricks"},
        {pos: [27, 10, 11], state: "minecraft:polished_blackstone_bricks"},
        {pos: [27, 10, 12], state: "minecraft:polished_blackstone_bricks"},
        {pos: [27, 10, 13], state: "minecraft:polished_blackstone_bricks"},
        {pos: [28, 10, 4], state: "minecraft:polished_blackstone_bricks"},
        {pos: [28, 10, 5], state: "minecraft:polished_blackstone_bricks"},
        {pos: [28, 10, 6], state: "minecraft:polished_blackstone_bricks"},
        {pos: [28, 10, 7], state: "minecraft:polished_blackstone_bricks"},
        {pos: [28, 10, 8], state: "minecraft:polished_blackstone_bricks"},
        {pos: [28, 10, 9], state: "minecraft:polished_blackstone_bricks"},
        {pos: [28, 10, 10], state: "minecraft:polished_blackstone_bricks"},
        {pos: [28, 10, 11], state: "minecraft:polished_blackstone_bricks"},
        {pos: [28, 10, 12], state: "minecraft:polished_blackstone_bricks"},
        {pos: [28, 10, 13], state: "minecraft:polished_blackstone_bricks"},
        {pos: [29, 10, 4], state: "minecraft:polished_blackstone_bricks"},
        {pos: [29, 10, 5], state: "minecraft:polished_blackstone_bricks"},
        {pos: [29, 10, 6], state: "minecraft:polished_blackstone_bricks"},
        {pos: [29, 10, 7], state: "minecraft:polished_blackstone_bricks"},
        {pos: [29, 10, 8], state: "minecraft:polished_blackstone_bricks"},
        {pos: [29, 10, 9], state: "minecraft:polished_blackstone_bricks"},
        {pos: [29, 10, 10], state: "minecraft:blackstone"},
        {pos: [29, 10, 11], state: "minecraft:blackstone"},
        {pos: [29, 10, 13], state: "minecraft:polished_blackstone_bricks"},
        {pos: [30, 10, 5], state: "minecraft:polished_blackstone_bricks"},
        {pos: [30, 10, 6], state: "minecraft:polished_blackstone_bricks"},
        {pos: [30, 10, 7], state: "minecraft:polished_blackstone_bricks"},
        {pos: [30, 10, 8], state: "minecraft:polished_blackstone_bricks"},
        {pos: [30, 10, 9], state: "minecraft:polished_blackstone_bricks"},
        {pos: [30, 10, 10], state: "minecraft:blackstone"},
        {pos: [30, 10, 11], state: "minecraft:blackstone"},
        {pos: [30, 10, 12], state: "minecraft:blackstone"},
        {pos: [3, 11, 4], state: "minecraft:polished_blackstone_bricks"},
        {pos: [3, 11, 5], state: "minecraft:polished_blackstone_bricks"},
        {pos: [3, 11, 6], state: "minecraft:blackstone"},
        {pos: [3, 11, 7], state: "minecraft:blackstone"},
        {pos: [3, 11, 8], state: "minecraft:blackstone"},
        {pos: [3, 11, 9], state: "minecraft:blackstone"},
        {pos: [3, 11, 10], state: "minecraft:blackstone"},
        {pos: [3, 11, 11], state: "minecraft:blackstone"},
        {pos: [3, 11, 12], state: "minecraft:polished_blackstone_bricks"},
        {pos: [4, 11, 4], state: "minecraft:polished_blackstone_bricks"},
        {pos: [4, 11, 5], state: "minecraft:blackstone"},
        {pos: [4, 11, 7], state: "minecraft:polished_blackstone_bricks"},
        {pos: [4, 11, 8], state: "minecraft:polished_blackstone_bricks"},
        {pos: [4, 11, 9], state: "minecraft:polished_blackstone_bricks"},
        {pos: [4, 11, 10], state: "minecraft:polished_blackstone_bricks"},
        {pos: [4, 11, 11], state: "minecraft:polished_blackstone_bricks"},
        {pos: [4, 11, 12], state: "minecraft:polished_blackstone_bricks"},
        {pos: [4, 11, 13], state: "minecraft:polished_blackstone_bricks"},
        {pos: [5, 11, 4], state: "minecraft:blackstone"},
        {pos: [5, 11, 7], state: "minecraft:polished_blackstone_bricks"},
        {pos: [5, 11, 8], state: "minecraft:polished_blackstone_bricks"},
        {pos: [5, 11, 9], state: "minecraft:polished_blackstone_bricks"},
        {pos: [5, 11, 10], state: "minecraft:polished_blackstone_bricks"},
        {pos: [5, 11, 11], state: "minecraft:polished_blackstone_bricks"},
        {pos: [5, 11, 12], state: "minecraft:polished_blackstone_bricks"},
        {pos: [5, 11, 13], state: "minecraft:polished_blackstone_bricks"},
        {pos: [6, 11, 1], state: "minecraft:polished_blackstone_bricks"},
        {pos: [6, 11, 2], state: "minecraft:polished_blackstone_bricks"},
        {pos: [6, 11, 3], state: "minecraft:polished_blackstone_bricks"},
        {pos: [6, 11, 7], state: "minecraft:blackstone"},
        {pos: [6, 11, 8], state: "minecraft:polished_blackstone_bricks"},
        {pos: [6, 11, 9], state: "minecraft:polished_blackstone_bricks"},
        {pos: [6, 11, 10], state: "minecraft:polished_blackstone_bricks"},
        {pos: [6, 11, 11], state: "minecraft:polished_blackstone_bricks"},
        {pos: [6, 11, 12], state: "minecraft:polished_blackstone_bricks"},
        {pos: [6, 11, 13], state: "minecraft:polished_blackstone_bricks"},
        {pos: [7, 11, 1], state: "minecraft:polished_blackstone_bricks"},
        {pos: [7, 11, 2], state: "minecraft:polished_blackstone_bricks"},
        {pos: [7, 11, 3], state: "minecraft:polished_blackstone_bricks"},
        {pos: [7, 11, 4], state: "minecraft:blackstone"},
        {pos: [7, 11, 7], state: "minecraft:blackstone"},
        {pos: [7, 11, 8], state: "minecraft:polished_blackstone_bricks"},
        {pos: [7, 11, 9], state: "minecraft:polished_blackstone_bricks"},
        {pos: [7, 11, 10], state: "minecraft:polished_blackstone_bricks"},
        {pos: [7, 11, 11], state: "minecraft:polished_blackstone_bricks"},
        {pos: [7, 11, 12], state: "minecraft:polished_blackstone_bricks"},
        {pos: [7, 11, 13], state: "minecraft:polished_blackstone_bricks"},
        {pos: [8, 11, 1], state: "minecraft:polished_blackstone_bricks"},
        {pos: [8, 11, 2], state: "minecraft:polished_blackstone_bricks"},
        {pos: [8, 11, 3], state: "minecraft:polished_blackstone_bricks"},
        {pos: [8, 11, 4], state: "minecraft:polished_blackstone_bricks"},
        {pos: [8, 11, 5], state: "minecraft:blackstone"},
        {pos: [8, 11, 7], state: "minecraft:polished_blackstone_bricks"},
        {pos: [8, 11, 8], state: "minecraft:polished_blackstone_bricks"},
        {pos: [8, 11, 9], state: "minecraft:polished_blackstone_bricks"},
        {pos: [8, 11, 10], state: "minecraft:polished_blackstone_bricks"},
        {pos: [8, 11, 11], state: "minecraft:polished_blackstone_bricks"},
        {pos: [8, 11, 12], state: "minecraft:polished_blackstone_bricks"},
        {pos: [8, 11, 13], state: "minecraft:polished_blackstone_bricks"},
        {pos: [9, 11, 4], state: "minecraft:polished_blackstone_bricks"},
        {pos: [9, 11, 5], state: "minecraft:polished_blackstone_bricks"},
        {pos: [9, 11, 6], state: "minecraft:polished_blackstone_bricks"},
        {pos: [9, 11, 7], state: "minecraft:polished_blackstone_bricks"},
        {pos: [9, 11, 8], state: "minecraft:polished_blackstone_bricks"},
        {pos: [9, 11, 9], state: "minecraft:polished_blackstone_bricks"},
        {pos: [9, 11, 10], state: "minecraft:polished_blackstone_bricks"},
        {pos: [9, 11, 11], state: "minecraft:polished_blackstone_bricks"},
        {pos: [9, 11, 12], state: "minecraft:polished_blackstone_bricks"},
        {pos: [10, 11, 4], state: "minecraft:polished_blackstone_bricks"},
        {pos: [10, 11, 5], state: "minecraft:polished_blackstone_bricks"},
        {pos: [10, 11, 6], state: "minecraft:polished_blackstone_bricks"},
        {pos: [10, 11, 7], state: "minecraft:polished_blackstone_bricks"},
        {pos: [10, 11, 8], state: "minecraft:polished_blackstone_bricks"},
        {pos: [10, 11, 9], state: "minecraft:polished_blackstone_bricks"},
        {pos: [10, 11, 10], state: "minecraft:basalt{axis:y}"},
        {pos: [10, 11, 11], state: "minecraft:basalt{axis:y}"},
        {pos: [10, 11, 12], state: "minecraft:basalt{axis:y}"},
        {pos: [10, 11, 13], state: "minecraft:basalt{axis:y}"},
        {pos: [11, 11, 4], state: "minecraft:basalt{axis:y}"},
        {pos: [11, 11, 5], state: "minecraft:polished_blackstone_bricks"},
        {pos: [11, 11, 6], state: "minecraft:polished_blackstone_bricks"},
        {pos: [11, 11, 7], state: "minecraft:polished_blackstone_bricks"},
        {pos: [11, 11, 8], state: "minecraft:polished_blackstone_bricks"},
        {pos: [11, 11, 9], state: "minecraft:polished_blackstone_bricks"},
        {pos: [11, 11, 10], state: "minecraft:basalt{axis:y}"},
        {pos: [11, 11, 11], state: "minecraft:basalt{axis:y}"},
        {pos: [11, 11, 12], state: "minecraft:basalt{axis:y}"},
        {pos: [11, 11, 13], state: "minecraft:basalt{axis:y}"},
        {pos: [12, 11, 4], state: "minecraft:basalt{axis:y}"},
        {pos: [12, 11, 5], state: "minecraft:polished_blackstone_bricks"},
        {pos: [12, 11, 6], state: "minecraft:polished_blackstone_bricks"},
        {pos: [12, 11, 7], state: "minecraft:polished_blackstone_bricks"},
        {pos: [12, 11, 8], state: "minecraft:polished_blackstone_bricks"},
        {pos: [12, 11, 9], state: "minecraft:polished_blackstone_bricks"},
        {pos: [12, 11, 10], state: "minecraft:basalt{axis:y}"},
        {pos: [12, 11, 11], state: "minecraft:basalt{axis:y}"},
        {pos: [12, 11, 12], state: "minecraft:basalt{axis:y}"},
        {pos: [12, 11, 13], state: "minecraft:basalt{axis:y}"},
        {pos: [13, 11, 4], state: "minecraft:polished_blackstone_bricks"},
        {pos: [13, 11, 5], state: "minecraft:polished_blackstone_bricks"},
        {pos: [13, 11, 6], state: "minecraft:polished_blackstone_bricks"},
        {pos: [13, 11, 7], state: "minecraft:polished_blackstone_bricks"},
        {pos: [13, 11, 11], state: "minecraft:basalt{axis:y}"},
        {pos: [13, 11, 12], state: "minecraft:basalt{axis:y}"},
        {pos: [13, 11, 13], state: "minecraft:blackstone"},
        {pos: [14, 11, 4], state: "minecraft:basalt{axis:y}"},
        {pos: [14, 11, 5], state: "minecraft:polished_blackstone_bricks"},
        {pos: [14, 11, 6], state: "minecraft:polished_blackstone_bricks"},
        {pos: [14, 11, 7], state: "minecraft:polished_blackstone_bricks"},
        {pos: [14, 11, 11], state: "minecraft:basalt{axis:y}"},
        {pos: [14, 11, 12], state: "minecraft:basalt{axis:y}"},
        {pos: [14, 11, 13], state: "minecraft:blackstone"},
        {pos: [15, 11, 4], state: "minecraft:basalt{axis:y}"},
        {pos: [15, 11, 5], state: "minecraft:blackstone"},
        {pos: [15, 11, 11], state: "minecraft:basalt{axis:y}"},
        {pos: [15, 11, 12], state: "minecraft:blackstone"},
        {pos: [16, 11, 4], state: "minecraft:polished_blackstone_bricks"},
        {pos: [16, 11, 5], state: "minecraft:blackstone"},
        {pos: [16, 11, 6], state: "minecraft:blackstone"},
        {pos: [16, 11, 11], state: "minecraft:basalt{axis:y}"},
        {pos: [16, 11, 12], state: "minecraft:basalt{axis:y}"},
        {pos: [17, 11, 4], state: "minecraft:basalt{axis:y}"},
        {pos: [17, 11, 5], state: "minecraft:blackstone"},
        {pos: [17, 11, 6], state: "minecraft:blackstone"},
        {pos: [17, 11, 7], state: "minecraft:blackstone"},
        {pos: [17, 11, 11], state: "minecraft:basalt{axis:y}"},
        {pos: [17, 11, 12], state: "minecraft:basalt{axis:y}"},
        {pos: [18, 11, 5], state: "minecraft:polished_blackstone_bricks"},
        {pos: [18, 11, 6], state: "minecraft:blackstone"},
        {pos: [18, 11, 7], state: "minecraft:blackstone"},
        {pos: [18, 11, 8], state: "minecraft:blackstone"},
        {pos: [18, 11, 9], state: "minecraft:blackstone"},
        {pos: [18, 11, 10], state: "minecraft:basalt{axis:y}"},
        {pos: [18, 11, 11], state: "minecraft:basalt{axis:y}"},
        {pos: [18, 11, 12], state: "minecraft:basalt{axis:y}"},
        {pos: [19, 11, 4], state: "minecraft:basalt{axis:y}"},
        {pos: [19, 11, 5], state: "minecraft:polished_blackstone_bricks"},
        {pos: [19, 11, 6], state: "minecraft:blackstone"},
        {pos: [19, 11, 7], state: "minecraft:polished_blackstone_bricks"},
        {pos: [19, 11, 8], state: "minecraft:polished_blackstone_bricks"},
        {pos: [19, 11, 9], state: "minecraft:polished_blackstone_bricks"},
        {pos: [19, 11, 10], state: "minecraft:basalt{axis:y}"},
        {pos: [19, 11, 11], state: "minecraft:basalt{axis:y}"},
        {pos: [19, 11, 12], state: "minecraft:basalt{axis:y}"},
        {pos: [19, 11, 13], state: "minecraft:basalt{axis:y}"},
        {pos: [20, 11, 4], state: "minecraft:basalt{axis:y}"},
        {pos: [20, 11, 5], state: "minecraft:polished_blackstone_bricks"},
        {pos: [20, 11, 6], state: "minecraft:polished_blackstone_bricks"},
        {pos: [20, 11, 7], state: "minecraft:polished_blackstone_bricks"},
        {pos: [20, 11, 8], state: "minecraft:polished_blackstone_bricks"},
        {pos: [20, 11, 9], state: "minecraft:polished_blackstone_bricks"},
        {pos: [20, 11, 10], state: "minecraft:basalt{axis:y}"},
        {pos: [20, 11, 11], state: "minecraft:basalt{axis:y}"},
        {pos: [20, 11, 12], state: "minecraft:basalt{axis:y}"},
        {pos: [21, 11, 4], state: "minecraft:polished_blackstone_bricks"},
        {pos: [21, 11, 5], state: "minecraft:polished_blackstone_bricks"},
        {pos: [21, 11, 6], state: "minecraft:polished_blackstone_bricks"},
        {pos: [21, 11, 7], state: "minecraft:polished_blackstone_bricks"},
        {pos: [21, 11, 8], state: "minecraft:polished_blackstone_bricks"},
        {pos: [21, 11, 9], state: "minecraft:polished_blackstone_bricks"},
        {pos: [21, 11, 10], state: "minecraft:basalt{axis:y}"},
        {pos: [21, 11, 11], state: "minecraft:basalt{axis:y}"},
        {pos: [21, 11, 12], state: "minecraft:basalt{axis:y}"},
        {pos: [21, 11, 13], state: "minecraft:basalt{axis:y}"},
        {pos: [22, 11, 4], state: "minecraft:polished_blackstone_bricks"},
        {pos: [22, 11, 5], state: "minecraft:polished_blackstone_bricks"},
        {pos: [22, 11, 6], state: "minecraft:polished_blackstone_bricks"},
        {pos: [22, 11, 7], state: "minecraft:polished_blackstone_bricks"},
        {pos: [22, 11, 8], state: "minecraft:polished_blackstone_bricks"},
        {pos: [22, 11, 9], state: "minecraft:polished_blackstone_bricks"},
        {pos: [22, 11, 10], state: "minecraft:basalt{axis:y}"},
        {pos: [22, 11, 11], state: "minecraft:basalt{axis:y}"},
        {pos: [22, 11, 12], state: "minecraft:basalt{axis:y}"},
        {pos: [22, 11, 13], state: "minecraft:blackstone"},
        {pos: [23, 11, 4], state: "minecraft:polished_blackstone_bricks"},
        {pos: [23, 11, 5], state: "minecraft:polished_blackstone_bricks"},
        {pos: [23, 11, 6], state: "minecraft:polished_blackstone_bricks"},
        {pos: [23, 11, 7], state: "minecraft:polished_blackstone_bricks"},
        {pos: [23, 11, 8], state: "minecraft:polished_blackstone_bricks"},
        {pos: [23, 11, 9], state: "minecraft:polished_blackstone_bricks"},
        {pos: [23, 11, 10], state: "minecraft:polished_blackstone_bricks"},
        {pos: [23, 11, 11], state: "minecraft:polished_blackstone_bricks"},
        {pos: [23, 11, 12], state: "minecraft:polished_blackstone_bricks"},
        {pos: [23, 11, 13], state: "minecraft:polished_blackstone_bricks"},
        {pos: [24, 11, 4], state: "minecraft:polished_blackstone_bricks"},
        {pos: [24, 11, 5], state: "minecraft:blackstone"},
        {pos: [24, 11, 6], state: "minecraft:polished_blackstone_bricks"},
        {pos: [24, 11, 7], state: "minecraft:polished_blackstone_bricks"},
        {pos: [24, 11, 8], state: "minecraft:polished_blackstone_bricks"},
        {pos: [24, 11, 9], state: "minecraft:polished_blackstone_bricks"},
        {pos: [24, 11, 10], state: "minecraft:polished_blackstone_bricks"},
        {pos: [24, 11, 11], state: "minecraft:polished_blackstone_bricks"},
        {pos: [24, 11, 12], state: "minecraft:polished_blackstone_bricks"},
        {pos: [24, 11, 13], state: "minecraft:polished_blackstone_bricks"},
        {pos: [24, 11, 14], state: "minecraft:polished_blackstone_bricks"},
        {pos: [24, 11, 15], state: "minecraft:blackstone"},
        {pos: [25, 11, 1], state: "minecraft:polished_blackstone_bricks"},
        {pos: [25, 11, 2], state: "minecraft:polished_blackstone_bricks"},
        {pos: [25, 11, 3], state: "minecraft:polished_blackstone_bricks"},
        {pos: [25, 11, 4], state: "minecraft:blackstone"},
        {pos: [25, 11, 5], state: "minecraft:blackstone"},
        {pos: [25, 11, 6], state: "minecraft:blackstone"},
        {pos: [25, 11, 7], state: "minecraft:polished_blackstone_bricks"},
        {pos: [25, 11, 8], state: "minecraft:polished_blackstone_bricks"},
        {pos: [25, 11, 9], state: "minecraft:polished_blackstone_bricks"},
        {pos: [25, 11, 10], state: "minecraft:polished_blackstone_bricks"},
        {pos: [25, 11, 11], state: "minecraft:polished_blackstone_bricks"},
        {pos: [25, 11, 12], state: "minecraft:polished_blackstone_bricks"},
        {pos: [25, 11, 13], state: "minecraft:polished_blackstone_bricks"},
        {pos: [25, 11, 14], state: "minecraft:polished_blackstone_bricks"},
        {pos: [25, 11, 15], state: "minecraft:polished_blackstone_bricks"},
        {pos: [26, 11, 1], state: "minecraft:polished_blackstone_bricks"},
        {pos: [26, 11, 2], state: "minecraft:polished_blackstone_bricks"},
        {pos: [26, 11, 3], state: "minecraft:polished_blackstone_bricks"},
        {pos: [26, 11, 4], state: "minecraft:blackstone"},
        {pos: [26, 11, 5], state: "minecraft:blackstone"},
        {pos: [26, 11, 6], state: "minecraft:blackstone"},
        {pos: [26, 11, 7], state: "minecraft:polished_blackstone_bricks"},
        {pos: [26, 11, 8], state: "minecraft:polished_blackstone_bricks"},
        {pos: [26, 11, 9], state: "minecraft:polished_blackstone_bricks"},
        {pos: [26, 11, 10], state: "minecraft:polished_blackstone_bricks"},
        {pos: [26, 11, 11], state: "minecraft:polished_blackstone_bricks"},
        {pos: [26, 11, 12], state: "minecraft:polished_blackstone_bricks"},
        {pos: [26, 11, 13], state: "minecraft:polished_blackstone_bricks"},
        {pos: [26, 11, 14], state: "minecraft:polished_blackstone_bricks"},
        {pos: [26, 11, 15], state: "minecraft:polished_blackstone_bricks"},
