{
    size: [7, 6, 8],
    data: [
        {pos: [1, 0, 1], state: "minecraft:dirt"},
        {pos: [1, 0, 2], state: "minecraft:dirt"},
        {pos: [1, 0, 3], state: "minecraft:dirt"},
        {pos: [1, 0, 4], state: "minecraft:dirt"},
        {pos: [2, 0, 1], state: "minecraft:dirt"},
        {pos: [2, 0, 2], state: "minecraft:cobblestone"},
        {pos: [2, 0, 4], state: "minecraft:dirt"},
        {pos: [2, 0, 5], state: "minecraft:dirt"},
        {pos: [2, 0, 6], state: "minecraft:dirt"},
        {pos: [3, 0, 1], state: "minecraft:dirt"},
        {pos: [3, 0, 2], state: "minecraft:cobblestone"},
        {pos: [3, 0, 3], state: "minecraft:cobblestone"},
        {pos: [3, 0, 4], state: "minecraft:cobblestone"},
        {pos: [3, 0, 5], state: "minecraft:spruce_planks"},
        {pos: [3, 0, 6], state: "minecraft:spruce_planks"},
        {pos: [4, 0, 1], state: "minecraft:dirt"},
        {pos: [4, 0, 2], state: "minecraft:cobblestone"},
        {pos: [4, 0, 3], state: "minecraft:cobblestone"},
        {pos: [4, 0, 4], state: "minecraft:dirt"},
        {pos: [4, 0, 5], state: "minecraft:dirt"},
        {pos: [4, 0, 6], state: "minecraft:dirt"},
        {pos: [5, 0, 1], state: "minecraft:dirt"},
        {pos: [5, 0, 2], state: "minecraft:dirt"},
        {pos: [5, 0, 3], state: "minecraft:dirt"},
        {pos: [5, 0, 4], state: "minecraft:dirt"},
        {pos: [1, 1, 1], state: "minecraft:cobblestone"},
        {pos: [1, 1, 2], state: "minecraft:cobblestone"},
        {pos: [1, 1, 3], state: "minecraft:cobblestone"},
        {pos: [1, 1, 4], state: "minecraft:cobblestone"},
        {pos: [2, 1, 1], state: "minecraft:cobblestone"},
        {pos: [2, 1, 2], state: "minecraft:crafting_table"},
        {pos: [2, 1, 4], state: "minecraft:cobblestone"},
        {pos: [2, 1, 5], state: "minecraft:spruce_planks"},
        {pos: [2, 1, 6], state: "minecraft:spruce_planks"},
        {pos: [3, 1, 1], state: "minecraft:cobblestone"},
        {pos: [4, 1, 1], state: "minecraft:cobblestone"},
        {pos: [4, 1, 4], state: "minecraft:cobblestone"},
        {pos: [4, 1, 5], state: "minecraft:spruce_planks"},
        {pos: [4, 1, 6], state: "minecraft:spruce_planks"},
        {pos: [5, 1, 1], state: "minecraft:cobblestone"},
        {pos: [5, 1, 2], state: "minecraft:cobblestone"},
        {pos: [5, 1, 3], state: "minecraft:cobblestone"},
        {pos: [5, 1, 4], state: "minecraft:cobblestone"},
        {pos: [1, 2, 1], state: "minecraft:cobblestone"},
        {pos: [1, 2, 2], state: "minecraft:cobblestone"},
        {pos: [1, 2, 3], state: "minecraft:cobblestone"},
        {pos: [1, 2, 4], state: "minecraft:cobblestone"},
        {pos: [2, 2, 4], state: "minecraft:cobblestone"},
        {pos: [2, 2, 5], state: "minecraft:spruce_planks"},
        {pos: [2, 2, 6], state: "minecraft:spruce_planks"},
        {pos: [3, 2, 1], state: "minecraft:cobblestone"},
        {pos: [4, 2, 4], state: "minecraft:cobblestone"},
        {pos: [4, 2, 5], state: "minecraft:spruce_planks"},
        {pos: [4, 2, 6], state: "minecraft:spruce_planks"},
        {pos: [5, 2, 1], state: "minecraft:cobblestone"},
        {pos: [5, 2, 2], state: "minecraft:cobblestone"},
        {pos: [5, 2, 3], state: "minecraft:cobblestone"},
        {pos: [5, 2, 4], state: "minecraft:cobblestone"},
        {pos: [0, 3, 0], state: "minecraft:spruce_log{axis:x}"},
        {pos: [0, 3, 5], state: "minecraft:spruce_log{axis:x}"},
        {pos: [1, 3, 0], state: "minecraft:spruce_log{axis:x}"},
        {pos: [1, 3, 1], state: "minecraft:cobblestone"},
        {pos: [1, 3, 2], state: "minecraft:cobblestone"},
        {pos: [1, 3, 3], state: "minecraft:cobblestone"},
        {pos: [1, 3, 4], state: "minecraft:cobblestone"},
        {pos: [1, 3, 5], state: "minecraft:spruce_log{axis:z}"},
        {pos: [1, 3, 6], state: "minecraft:spruce_log{axis:z}"},
        {pos: [1, 3, 7], state: "minecraft:spruce_log{axis:z}"},
        {pos: [2, 3, 0], state: "minecraft:spruce_log{axis:x}"},
        {pos: [2, 3, 1], state: "minecraft:cobblestone"},
        {pos: [2, 3, 4], state: "minecraft:cobblestone"},
        {pos: [2, 3, 5], state: "minecraft:spruce_planks"},
        {pos: [2, 3, 6], state: "minecraft:spruce_planks"},
        {pos: [3, 3, 0], state: "minecraft:spruce_log{axis:x}"},
        {pos: [3, 3, 1], state: "minecraft:cobblestone"},
        {pos: [3, 3, 4], state: "minecraft:cobblestone"},
        {pos: [3, 3, 5], state: "minecraft:spruce_planks"},
        {pos: [3, 3, 6], state: "minecraft:spruce_planks"},
        {pos: [4, 3, 0], state: "minecraft:spruce_log{axis:x}"},
        {pos: [4, 3, 1], state: "minecraft:cobblestone"},
        {pos: [4, 3, 4], state: "minecraft:cobblestone"},
        {pos: [4, 3, 5], state: "minecraft:spruce_planks"},
        {pos: [4, 3, 6], state: "minecraft:spruce_planks"},
        {pos: [5, 3, 0], state: "minecraft:spruce_log{axis:x}"},
        {pos: [5, 3, 1], state: "minecraft:cobblestone"},
        {pos: [5, 3, 2], state: "minecraft:cobblestone"},
        {pos: [5, 3, 3], state: "minecraft:cobblestone"},
        {pos: [5, 3, 4], state: "minecraft:cobblestone"},
        {pos: [5, 3, 5], state: "minecraft:spruce_log{axis:z}"},
        {pos: [5, 3, 6], state: "minecraft:spruce_log{axis:z}"},
        {pos: [5, 3, 7], state: "minecraft:spruce_log{axis:z}"},
        {pos: [6, 3, 0], state: "minecraft:spruce_log{axis:x}"},
        {pos: [6, 3, 5], state: "minecraft:spruce_log{axis:x}"},
        {pos: [0, 4, 1], state: "minecraft:spruce_log{axis:x}"},
        {pos: [0, 4, 4], state: "minecraft:spruce_log{axis:x}"},
        {pos: [1, 4, 1], state: "minecraft:spruce_log{axis:x}"},
        {pos: [1, 4, 2], state: "minecraft:cobblestone"},
        {pos: [1, 4, 3], state: "minecraft:cobblestone"},
        {pos: [1, 4, 4], state: "minecraft:spruce_log{axis:x}"},
        {pos: [2, 4, 1], state: "minecraft:spruce_log{axis:x}"},
        {pos: [2, 4, 4], state: "minecraft:spruce_log{axis:x}"},
        {pos: [2, 4, 5], state: "minecraft:spruce_log{axis:z}"},
        {pos: [2, 4, 6], state: "minecraft:spruce_log{axis:z}"},
        {pos: [2, 4, 7], state: "minecraft:spruce_log{axis:z}"},
        {pos: [3, 4, 1], state: "minecraft:spruce_log{axis:x}"},
        {pos: [3, 4, 4], state: "minecraft:spruce_log{axis:z}"},
        {pos: [3, 4, 5], state: "minecraft:spruce_planks"},
        {pos: [3, 4, 6], state: "minecraft:spruce_planks"},
        {pos: [4, 4, 1], state: "minecraft:spruce_log{axis:x}"},
        {pos: [4, 4, 4], state: "minecraft:spruce_log{axis:x}"},
        {pos: [4, 4, 5], state: "minecraft:spruce_log{axis:z}"},
        {pos: [4, 4, 6], state: "minecraft:spruce_log{axis:z}"},
        {pos: [4, 4, 7], state: "minecraft:spruce_log{axis:z}"},
        {pos: [5, 4, 1], state: "minecraft:spruce_log{axis:x}"},
        {pos: [5, 4, 2], state: "minecraft:cobblestone"},
        {pos: [5, 4, 3], state: "minecraft:cobblestone"},
        {pos: [5, 4, 4], state: "minecraft:spruce_log{axis:x}"},
        {pos: [6, 4, 1], state: "minecraft:spruce_log{axis:x}"},
        {pos: [6, 4, 4], state: "minecraft:spruce_log{axis:x}"},
        {pos: [0, 5, 2], state: "minecraft:spruce_log{axis:x}"},
        {pos: [0, 5, 3], state: "minecraft:spruce_log{axis:x}"},
        {pos: [1, 5, 2], state: "minecraft:spruce_log{axis:x}"},
        {pos: [1, 5, 3], state: "minecraft:spruce_log{axis:x}"},
        {pos: [2, 5, 2], state: "minecraft:spruce_log{axis:x}"},
        {pos: [2, 5, 3], state: "minecraft:spruce_log{axis:x}"},
        {pos: [3, 5, 2], state: "minecraft:spruce_log{axis:x}"},
        {pos: [3, 5, 3], state: "minecraft:spruce_log{axis:x}"},
        {pos: [3, 5, 4], state: "minecraft:spruce_log{axis:z}"},
        {pos: [3, 5, 5], state: "minecraft:spruce_log{axis:z}"},
        {pos: [3, 5, 6], state: "minecraft:spruce_log{axis:z}"},
        {pos: [3, 5, 7], state: "minecraft:spruce_log{axis:z}"},
        {pos: [4, 5, 2], state: "minecraft:spruce_log{axis:x}"},
        {pos: [4, 5, 3], state: "minecraft:spruce_log{axis:x}"},
        {pos: [5, 5, 2], state: "minecraft:spruce_log{axis:x}"},
        {pos: [5, 5, 3], state: "minecraft:spruce_log{axis:x}"},
        {pos: [6, 5, 2], state: "minecraft:spruce_log{axis:x}"},
        {pos: [6, 5, 3], state: "minecraft:spruce_log{axis:x}"},
        {pos: [0, 0, 0], state: "minecraft:air"},
        {pos: [3, 0, 7], state: "minecraft:dirt_path"},
        {pos: [0, 1, 0], state: "minecraft:air"},
        {pos: [0, 1, 1], state: "minecraft:air"},
        {pos: [0, 1, 2], state: "minecraft:air"},
        {pos: [0, 1, 3], state: "minecraft:air"},
        {pos: [0, 1, 4], state: "minecraft:air"},
        {pos: [0, 1, 5], state: "minecraft:air"},
        {pos: [0, 1, 6], state: "minecraft:air"},
        {pos: [0, 1, 7], state: "minecraft:air"},
        {pos: [1, 1, 0], state: "minecraft:air"},
        {pos: [1, 1, 5], state: "minecraft:air"},
        {pos: [1, 1, 6], state: "minecraft:air"},
        {pos: [1, 1, 7], state: "minecraft:air"},
        {pos: [2, 1, 3], state: "minecraft:air"},
        {pos: [2, 1, 7], state: "minecraft:air"},
        {pos: [3, 1, 0], state: "minecraft:air"},
        {pos: [3, 1, 2], state: "minecraft:air"},
        {pos: [3, 1, 3], state: "minecraft:air"},
        {pos: [3, 1, 4], state: "minecraft:spruce_door{hinge:right,half:lower,powered:false,facing:north,open:false}"},
        {pos: [3, 1, 5], state: "minecraft:air"},
        {pos: [3, 1, 6], state: "minecraft:spruce_door{hinge:right,half:lower,powered:false,facing:north,open:false}"},
        {pos: [4, 1, 0], state: "minecraft:air"},
        {pos: [4, 1, 7], state: "minecraft:air"},
        {pos: [5, 1, 0], state: "minecraft:air"},
        {pos: [5, 1, 5], state: "minecraft:air"},
        {pos: [5, 1, 6], state: "minecraft:air"},
        {pos: [5, 1, 7], state: "minecraft:air"},
        {pos: [6, 1, 0], state: "minecraft:air"},
        {pos: [6, 1, 1], state: "minecraft:air"},
        {pos: [6, 1, 2], state: "minecraft:air"},
        {pos: [6, 1, 3], state: "minecraft:air"},
        {pos: [6, 1, 4], state: "minecraft:air"},
        {pos: [6, 1, 5], state: "minecraft:air"},
        {pos: [6, 1, 6], state: "minecraft:air"},
        {pos: [6, 1, 7], state: "minecraft:air"},
        {pos: [0, 2, 0], state: "minecraft:air"},
        {pos: [0, 2, 1], state: "minecraft:air"},
        {pos: [0, 2, 2], state: "minecraft:air"},
        {pos: [0, 2, 3], state: "minecraft:air"},
        {pos: [0, 2, 4], state: "minecraft:air"},
        {pos: [0, 2, 5], state: "minecraft:air"},
        {pos: [0, 2, 6], state: "minecraft:air"},
        {pos: [0, 2, 7], state: "minecraft:air"},
        {pos: [1, 2, 0], state: "minecraft:spruce_trapdoor{half:top,waterlogged:false,powered:false,facing:north,open:true}"},
        {pos: [1, 2, 5], state: "minecraft:air"},
        {pos: [1, 2, 6], state: "minecraft:air"},
        {pos: [1, 2, 7], state: "minecraft:air"},
        {pos: [2, 2, 0], state: "minecraft:air"},
        {pos: [2, 2, 1], state: "minecraft:glass_pane{east:true,waterlogged:false,south:false,north:false,west:true}"},
        {pos: [2, 2, 2], state: "minecraft:air"},
        {pos: [2, 2, 3], state: "minecraft:air"},
        {pos: [2, 2, 7], state: "minecraft:air"},
        {pos: [3, 2, 0], state: "minecraft:spruce_trapdoor{half:top,waterlogged:false,powered:false,facing:north,open:true}"},
        {pos: [3, 2, 2], state: "minecraft:air"},
        {pos: [3, 2, 3], state: "minecraft:air"},
        {pos: [3, 2, 4], state: "minecraft:spruce_door{hinge:right,half:upper,powered:false,facing:north,open:false}"},
        {pos: [3, 2, 5], state: "minecraft:air"},
        {pos: [3, 2, 6], state: "minecraft:spruce_door{hinge:right,half:upper,powered:false,facing:north,open:false}"},
        {pos: [3, 2, 7], state: "minecraft:air"},
        {pos: [4, 2, 0], state: "minecraft:air"},
        {pos: [4, 2, 1], state: "minecraft:glass_pane{east:true,waterlogged:false,south:false,north:false,west:true}"},
        {pos: [4, 2, 2], state: "minecraft:air"},
        {pos: [4, 2, 3], state: "minecraft:air"},
        {pos: [4, 2, 7], state: "minecraft:air"},
        {pos: [5, 2, 0], state: "minecraft:spruce_trapdoor{half:top,waterlogged:false,powered:false,facing:north,open:true}"},
        {pos: [5, 2, 5], state: "minecraft:air"},
        {pos: [5, 2, 6], state: "minecraft:air"},
        {pos: [5, 2, 7], state: "minecraft:air"},
        {pos: [6, 2, 0], state: "minecraft:air"},
        {pos: [6, 2, 1], state: "minecraft:air"},
        {pos: [6, 2, 2], state: "minecraft:air"},
        {pos: [6, 2, 3], state: "minecraft:air"},
        {pos: [6, 2, 4], state: "minecraft:air"},
        {pos: [6, 2, 5], state: "minecraft:air"},
        {pos: [6, 2, 6], state: "minecraft:air"},
        {pos: [6, 2, 7], state: "minecraft:air"},
        {pos: [0, 3, 1], state: "minecraft:air"},
        {pos: [0, 3, 2], state: "minecraft:air"},
        {pos: [0, 3, 3], state: "minecraft:air"},
        {pos: [0, 3, 4], state: "minecraft:air"},
        {pos: [0, 3, 6], state: "minecraft:air"},
        {pos: [0, 3, 7], state: "minecraft:air"},
        {pos: [2, 3, 2], state: "minecraft:air"},
        {pos: [2, 3, 3], state: "minecraft:air"},
        {pos: [2, 3, 7], state: "minecraft:air"},
        {pos: [3, 3, 2], state: "minecraft:air"},
        {pos: [3, 3, 3], state: "minecraft:air"},
        {pos: [3, 3, 7], state: "minecraft:wall_torch{facing:south}"},
        {pos: [4, 3, 2], state: "minecraft:air"},
        {pos: [4, 3, 3], state: "minecraft:air"},
        {pos: [4, 3, 7], state: "minecraft:air"},
        {pos: [6, 3, 1], state: "minecraft:air"},
        {pos: [6, 3, 2], state: "minecraft:air"},
        {pos: [6, 3, 3], state: "minecraft:air"},
        {pos: [6, 3, 4], state: "minecraft:air"},
        {pos: [6, 3, 6], state: "minecraft:air"},
        {pos: [6, 3, 7], state: "minecraft:air"},
        {pos: [0, 4, 0], state: "minecraft:air"},
        {pos: [0, 4, 2], state: "minecraft:air"},
        {pos: [0, 4, 3], state: "minecraft:air"},
        {pos: [0, 4, 5], state: "minecraft:air"},
        {pos: [0, 4, 6], state: "minecraft:air"},
        {pos: [0, 4, 7], state: "minecraft:air"},
        {pos: [1, 4, 0], state: "minecraft:air"},
        {pos: [1, 4, 5], state: "minecraft:air"},
        {pos: [1, 4, 6], state: "minecraft:air"},
        {pos: [1, 4, 7], state: "minecraft:air"},
        {pos: [2, 4, 0], state: "minecraft:air"},
        {pos: [2, 4, 2], state: "minecraft:air"},
        {pos: [2, 4, 3], state: "minecraft:air"},
        {pos: [3, 4, 0], state: "minecraft:air"},
        {pos: [3, 4, 2], state: "minecraft:wall_torch{facing:south}"},
        {pos: [3, 4, 3], state: "minecraft:wall_torch{facing:north}"},
        {pos: [3, 4, 7], state: "minecraft:air"},
        {pos: [4, 4, 0], state: "minecraft:air"},
        {pos: [4, 4, 2], state: "minecraft:air"},
        {pos: [4, 4, 3], state: "minecraft:air"},
        {pos: [5, 4, 0], state: "minecraft:air"},
        {pos: [5, 4, 5], state: "minecraft:air"},
        {pos: [5, 4, 6], state: "minecraft:air"},
        {pos: [5, 4, 7], state: "minecraft:air"},
        {pos: [6, 4, 0], state: "minecraft:air"},
        {pos: [6, 4, 2], state: "minecraft:air"},
        {pos: [6, 4, 3], state: "minecraft:air"},
        {pos: [6, 4, 5], state: "minecraft:air"},
        {pos: [6, 4, 6], state: "minecraft:air"},
        {pos: [6, 4, 7], state: "minecraft:air"},
        {pos: [0, 5, 0], state: "minecraft:air"},
        {pos: [0, 5, 1], state: "minecraft:air"},
        {pos: [0, 5, 4], state: "minecraft:air"},
        {pos: [0, 5, 5], state: "minecraft:air"},
        {pos: [0, 5, 6], state: "minecraft:air"},
        {pos: [0, 5, 7], state: "minecraft:air"},
        {pos: [1, 5, 0], state: "minecraft:air"},
        {pos: [1, 5, 1], state: "minecraft:air"},
        {pos: [1, 5, 4], state: "minecraft:air"},
        {pos: [1, 5, 5], state: "minecraft:air"},
        {pos: [1, 5, 6], state: "minecraft:air"},
        {pos: [1, 5, 7], state: "minecraft:air"},
        {pos: [2, 5, 0], state: "minecraft:air"},
        {pos: [2, 5, 1], state: "minecraft:air"},
        {pos: [2, 5, 4], state: "minecraft:air"},
        {pos: [2, 5, 5], state: "minecraft:air"},
        {pos: [2, 5, 6], state: "minecraft:air"},
        {pos: [2, 5, 7], state: "minecraft:air"},
        {pos: [3, 5, 0], state: "minecraft:air"},
        {pos: [3, 5, 1], state: "minecraft:air"},
        {pos: [4, 5, 0], state: "minecraft:air"},
        {pos: [4, 5, 1], state: "minecraft:air"},
        {pos: [4, 5, 4], state: "minecraft:air"},
        {pos: [4, 5, 5], state: "minecraft:air"},
        {pos: [4, 5, 6], state: "minecraft:air"},
        {pos: [4, 5, 7], state: "minecraft:air"},
        {pos: [5, 5, 0], state: "minecraft:air"},
        {pos: [5, 5, 1], state: "minecraft:air"},
        {pos: [5, 5, 4], state: "minecraft:air"},
        {pos: [5, 5, 5], state: "minecraft:air"},
        {pos: [5, 5, 6], state: "minecraft:air"},
        {pos: [5, 5, 7], state: "minecraft:air"},
        {pos: [6, 5, 0], state: "minecraft:air"},
        {pos: [6, 5, 1], state: "minecraft:air"},
        {pos: [6, 5, 4], state: "minecraft:air"},
        {pos: [6, 5, 5], state: "minecraft:air"},
        {pos: [6, 5, 6], state: "minecraft:air"},
        {pos: [6, 5, 7], state: "minecraft:air"},
        {pos: [0, 0, 6], state: "minecraft:jigsaw{orientation:up_north}", nbt: {final_state: "minecraft:grass_block", id: "minecraft:jigsaw", joint: "rollable", name: "minecraft:bottom", pool: "minecraft:village/taiga/zombie/decor", target: "minecraft:bottom"}},
        {pos: [2, 0, 3], state: "minecraft:jigsaw{orientation:up_north}", nbt: {final_state: "minecraft:cobblestone", id: "minecraft:jigsaw", joint: "rollable", name: "minecraft:bottom", pool: "minecraft:village/taiga/zombie/villagers", target: "minecraft:bottom"}},
        {pos: [3, 1, 7], state: "minecraft:jigsaw{orientation:south_up}", nbt: {final_state: "minecraft:structure_void", id: "minecraft:jigsaw", joint: "aligned", name: "minecraft:building_entrance", pool: "minecraft:empty", target: "minecraft:building_entrance"}},
        {pos: [4, 1, 2], state: "minecraft:blue_bed{part:head,facing:north,occupied:false}", nbt: {id: "minecraft:bed"}},
        {pos: [4, 1, 3], state: "minecraft:blue_bed{part:foot,facing:north,occupied:false}", nbt: {id: "minecraft:bed"}}
    ],
    entities: [],
    palette: [
        "minecraft:dirt",
        "minecraft:cobblestone",
        "minecraft:spruce_planks",
        "minecraft:crafting_table",
        "minecraft:spruce_log{axis:x}",
        "minecraft:spruce_log{axis:z}",
        "minecraft:air",
        "minecraft:dirt_path",
        "minecraft:spruce_door{hinge:right,half:lower,powered:false,facing:north,open:false}",
        "minecraft:spruce_trapdoor{half:top,waterlogged:false,powered:false,facing:north,open:true}",
        "minecraft:glass_pane{east:true,waterlogged:false,south:false,north:false,west:true}",
        "minecraft:spruce_door{hinge:right,half:upper,powered:false,facing:north,open:false}",
        "minecraft:wall_torch{facing:south}",
        "minecraft:wall_torch{facing:north}",
        "minecraft:jigsaw{orientation:up_north}",
        "minecraft:jigsaw{orientation:south_up}",
        "minecraft:blue_bed{part:head,facing:north,occupied:false}",
        "minecraft:blue_bed{part:foot,facing:north,occupied:false}"
    ]
}