{
    size: [10, 8, 11],
    data: [
        {pos: [0, 0, 5], state: "minecraft:dirt"},
        {pos: [1, 0, 2], state: "minecraft:dirt"},
        {pos: [1, 0, 3], state: "minecraft:acacia_wood{axis:y}"},
        {pos: [1, 0, 4], state: "minecraft:dirt"},
        {pos: [2, 0, 1], state: "minecraft:dirt"},
        {pos: [2, 0, 2], state: "minecraft:acacia_planks"},
        {pos: [2, 0, 3], state: "minecraft:acacia_planks"},
        {pos: [2, 0, 4], state: "minecraft:acacia_planks"},
        {pos: [2, 0, 5], state: "minecraft:dirt"},
        {pos: [3, 0, 1], state: "minecraft:dirt"},
        {pos: [3, 0, 2], state: "minecraft:acacia_planks"},
        {pos: [3, 0, 4], state: "minecraft:acacia_planks"},
        {pos: [3, 0, 5], state: "minecraft:dirt"},
        {pos: [4, 0, 1], state: "minecraft:dirt"},
        {pos: [4, 0, 2], state: "minecraft:acacia_planks"},
        {pos: [4, 0, 3], state: "minecraft:acacia_planks"},
        {pos: [4, 0, 4], state: "minecraft:acacia_planks"},
        {pos: [4, 0, 5], state: "minecraft:dirt"},
        {pos: [4, 0, 6], state: "minecraft:dirt"},
        {pos: [4, 0, 7], state: "minecraft:dirt"},
        {pos: [4, 0, 8], state: "minecraft:dirt"},
        {pos: [5, 0, 2], state: "minecraft:dirt"},
        {pos: [5, 0, 3], state: "minecraft:dirt"},
        {pos: [5, 0, 4], state: "minecraft:dirt"},
        {pos: [5, 0, 5], state: "minecraft:dirt"},
        {pos: [5, 0, 6], state: "minecraft:acacia_planks"},
        {pos: [5, 0, 7], state: "minecraft:acacia_planks"},
        {pos: [5, 0, 8], state: "minecraft:acacia_planks"},
        {pos: [5, 0, 9], state: "minecraft:dirt"},
        {pos: [6, 0, 5], state: "minecraft:dirt"},
        {pos: [6, 0, 6], state: "minecraft:acacia_planks"},
        {pos: [6, 0, 7], state: "minecraft:acacia_planks"},
        {pos: [6, 0, 8], state: "minecraft:acacia_planks"},
        {pos: [6, 0, 9], state: "minecraft:acacia_wood{axis:y}"},
        {pos: [7, 0, 5], state: "minecraft:dirt"},
        {pos: [7, 0, 6], state: "minecraft:acacia_planks"},
        {pos: [7, 0, 7], state: "minecraft:acacia_planks"},
        {pos: [7, 0, 9], state: "minecraft:dirt"},
        {pos: [8, 0, 6], state: "minecraft:dirt"},
        {pos: [8, 0, 7], state: "minecraft:dirt"},
        {pos: [8, 0, 8], state: "minecraft:dirt"},
        {pos: [1, 1, 2], state: "minecraft:acacia_wood{axis:y}"},
        {pos: [1, 1, 4], state: "minecraft:acacia_wood{axis:y}"},
        {pos: [2, 1, 1], state: "minecraft:acacia_wood{axis:y}"},
        {pos: [2, 1, 2], state: "minecraft:crafting_table"},
        {pos: [2, 1, 5], state: "minecraft:acacia_wood{axis:y}"},
        {pos: [3, 1, 1], state: "minecraft:acacia_wood{axis:x}"},
        {pos: [3, 1, 5], state: "minecraft:acacia_wood{axis:x}"},
        {pos: [4, 1, 1], state: "minecraft:acacia_wood{axis:y}"},
        {pos: [4, 1, 4], state: "minecraft:acacia_planks"},
        {pos: [4, 1, 5], state: "minecraft:acacia_wood{axis:y}"},
        {pos: [4, 1, 6], state: "minecraft:acacia_wood{axis:y}"},
        {pos: [4, 1, 7], state: "minecraft:acacia_wood{axis:z}"},
        {pos: [4, 1, 8], state: "minecraft:acacia_wood{axis:y}"},
        {pos: [5, 1, 2], state: "minecraft:acacia_wood{axis:y}"},
        {pos: [5, 1, 3], state: "minecraft:acacia_wood{axis:z}"},
        {pos: [5, 1, 4], state: "minecraft:acacia_wood{axis:y}"},
        {pos: [5, 1, 5], state: "minecraft:acacia_wood{axis:y}"},
        {pos: [5, 1, 9], state: "minecraft:acacia_wood{axis:y}"},
        {pos: [6, 1, 5], state: "minecraft:acacia_wood{axis:x}"},
        {pos: [7, 1, 5], state: "minecraft:acacia_wood{axis:y}"},
        {pos: [7, 1, 9], state: "minecraft:acacia_wood{axis:y}"},
        {pos: [8, 1, 6], state: "minecraft:acacia_wood{axis:y}"},
        {pos: [8, 1, 7], state: "minecraft:acacia_wood{axis:z}"},
        {pos: [8, 1, 8], state: "minecraft:acacia_wood{axis:y}"},
        {pos: [1, 2, 2], state: "minecraft:acacia_wood{axis:y}"},
        {pos: [1, 2, 4], state: "minecraft:acacia_wood{axis:y}"},
        {pos: [2, 2, 1], state: "minecraft:acacia_wood{axis:y}"},
        {pos: [2, 2, 5], state: "minecraft:acacia_wood{axis:y}"},
        {pos: [4, 2, 1], state: "minecraft:acacia_wood{axis:y}"},
        {pos: [4, 2, 5], state: "minecraft:acacia_wood{axis:y}"},
        {pos: [4, 2, 6], state: "minecraft:acacia_wood{axis:y}"},
        {pos: [4, 2, 8], state: "minecraft:acacia_wood{axis:y}"},
        {pos: [5, 2, 2], state: "minecraft:acacia_wood{axis:y}"},
        {pos: [5, 2, 4], state: "minecraft:acacia_wood{axis:y}"},
        {pos: [5, 2, 5], state: "minecraft:acacia_wood{axis:y}"},
        {pos: [5, 2, 9], state: "minecraft:acacia_wood{axis:y}"},
        {pos: [7, 2, 5], state: "minecraft:acacia_wood{axis:y}"},
        {pos: [7, 2, 9], state: "minecraft:acacia_wood{axis:y}"},
        {pos: [8, 2, 6], state: "minecraft:acacia_wood{axis:y}"},
        {pos: [8, 2, 8], state: "minecraft:acacia_wood{axis:y}"},
        {pos: [1, 3, 2], state: "minecraft:acacia_wood{axis:y}"},
        {pos: [1, 3, 3], state: "minecraft:acacia_wood{axis:z}"},
        {pos: [1, 3, 4], state: "minecraft:acacia_wood{axis:y}"},
        {pos: [2, 3, 1], state: "minecraft:acacia_wood{axis:y}"},
        {pos: [2, 3, 5], state: "minecraft:acacia_wood{axis:y}"},
        {pos: [3, 3, 1], state: "minecraft:acacia_wood{axis:x}"},
        {pos: [3, 3, 5], state: "minecraft:acacia_wood{axis:x}"},
        {pos: [4, 3, 1], state: "minecraft:acacia_wood{axis:y}"},
        {pos: [4, 3, 5], state: "minecraft:acacia_wood{axis:y}"},
        {pos: [4, 3, 6], state: "minecraft:acacia_wood{axis:y}"},
        {pos: [4, 3, 7], state: "minecraft:acacia_wood{axis:z}"},
        {pos: [4, 3, 8], state: "minecraft:acacia_wood{axis:y}"},
        {pos: [5, 3, 2], state: "minecraft:acacia_wood{axis:y}"},
        {pos: [5, 3, 3], state: "minecraft:acacia_wood{axis:z}"},
        {pos: [5, 3, 4], state: "minecraft:acacia_wood{axis:y}"},
        {pos: [5, 3, 5], state: "minecraft:acacia_wood{axis:y}"},
        {pos: [5, 3, 9], state: "minecraft:acacia_wood{axis:y}"},
        {pos: [6, 3, 5], state: "minecraft:acacia_wood{axis:x}"},
        {pos: [6, 3, 9], state: "minecraft:acacia_wood{axis:x}"},
        {pos: [7, 3, 5], state: "minecraft:acacia_wood{axis:y}"},
        {pos: [7, 3, 9], state: "minecraft:acacia_wood{axis:y}"},
        {pos: [8, 3, 6], state: "minecraft:acacia_wood{axis:y}"},
        {pos: [8, 3, 7], state: "minecraft:acacia_wood{axis:z}"},
        {pos: [8, 3, 8], state: "minecraft:acacia_wood{axis:y}"},
        {pos: [1, 4, 1], state: "minecraft:acacia_planks"},
        {pos: [1, 4, 2], state: "minecraft:acacia_planks"},
        {pos: [1, 4, 3], state: "minecraft:acacia_planks"},
        {pos: [1, 4, 4], state: "minecraft:acacia_planks"},
        {pos: [1, 4, 5], state: "minecraft:acacia_planks"},
        {pos: [2, 4, 1], state: "minecraft:acacia_planks"},
        {pos: [2, 4, 5], state: "minecraft:acacia_planks"},
        {pos: [3, 4, 1], state: "minecraft:acacia_planks"},
        {pos: [3, 4, 5], state: "minecraft:acacia_planks"},
        {pos: [4, 4, 1], state: "minecraft:acacia_planks"},
        {pos: [4, 4, 5], state: "minecraft:acacia_planks"},
        {pos: [4, 4, 6], state: "minecraft:acacia_planks"},
        {pos: [4, 4, 7], state: "minecraft:acacia_planks"},
        {pos: [4, 4, 8], state: "minecraft:acacia_planks"},
        {pos: [4, 4, 9], state: "minecraft:acacia_planks"},
        {pos: [5, 4, 1], state: "minecraft:acacia_planks"},
        {pos: [5, 4, 2], state: "minecraft:acacia_planks"},
        {pos: [5, 4, 3], state: "minecraft:acacia_planks"},
        {pos: [5, 4, 4], state: "minecraft:acacia_planks"},
        {pos: [5, 4, 5], state: "minecraft:acacia_planks"},
        {pos: [5, 4, 9], state: "minecraft:acacia_planks"},
        {pos: [6, 4, 5], state: "minecraft:acacia_planks"},
        {pos: [6, 4, 9], state: "minecraft:acacia_planks"},
        {pos: [7, 4, 5], state: "minecraft:acacia_planks"},
        {pos: [7, 4, 9], state: "minecraft:acacia_planks"},
        {pos: [8, 4, 5], state: "minecraft:acacia_planks"},
        {pos: [8, 4, 6], state: "minecraft:acacia_planks"},
        {pos: [8, 4, 7], state: "minecraft:acacia_planks"},
        {pos: [8, 4, 8], state: "minecraft:acacia_planks"},
        {pos: [8, 4, 9], state: "minecraft:acacia_planks"},
        {pos: [0, 0, 3], state: "minecraft:dirt_path"},
        {pos: [0, 0, 4], state: "minecraft:dirt_path"},
        {pos: [0, 0, 6], state: "minecraft:dirt_path"},
        {pos: [1, 0, 6], state: "minecraft:dirt_path"},
        {pos: [1, 0, 7], state: "minecraft:dirt_path"},
        {pos: [2, 0, 6], state: "minecraft:farmland{moisture:7}"},
        {pos: [2, 0, 7], state: "minecraft:farmland{moisture:7}"},
        {pos: [2, 0, 8], state: "minecraft:dirt_path"},
        {pos: [2, 0, 9], state: "minecraft:dirt_path"},
        {pos: [3, 0, 6], state: "minecraft:water{level:0}"},
        {pos: [3, 0, 7], state: "minecraft:farmland{moisture:7}"},
        {pos: [3, 0, 8], state: "minecraft:farmland{moisture:7}"},
        {pos: [3, 0, 9], state: "minecraft:dirt_path"},
        {pos: [4, 0, 10], state: "minecraft:dirt_path"},
        {pos: [5, 0, 10], state: "minecraft:dirt_path"},
        {pos: [6, 0, 10], state: "minecraft:dirt_path"},
        {pos: [1, 1, 3], state: "minecraft:acacia_door{hinge:left,half:lower,powered:false,facing:south,open:true}"},
        {pos: [2, 1, 4], state: "minecraft:acacia_stairs{half:bottom,waterlogged:false,shape:straight,facing:south}"},
        {pos: [2, 1, 6], state: "minecraft:wheat{age:0}"},
        {pos: [2, 1, 7], state: "minecraft:wheat{age:0}"},
        {pos: [3, 1, 3], state: "minecraft:air"},
        {pos: [3, 1, 4], state: "minecraft:acacia_stairs{half:bottom,waterlogged:false,shape:straight,facing:south}"},
        {pos: [3, 1, 7], state: "minecraft:wheat{age:1}"},
        {pos: [3, 1, 8], state: "minecraft:wheat{age:0}"},
        {pos: [5, 1, 8], state: "minecraft:acacia_stairs{half:bottom,waterlogged:false,shape:straight,facing:west}"},
        {pos: [6, 1, 9], state: "minecraft:acacia_door{hinge:right,half:lower,powered:false,facing:south,open:false}"},
        {pos: [7, 1, 8], state: "minecraft:air"},
        {pos: [9, 1, 0], state: "minecraft:air"},
        {pos: [9, 1, 9], state: "minecraft:air"},
        {pos: [9, 1, 10], state: "minecraft:air"},
        {pos: [1, 2, 3], state: "minecraft:acacia_door{hinge:left,half:upper,powered:false,facing:south,open:true}"},
        {pos: [3, 2, 1], state: "minecraft:glass_pane{east:true,waterlogged:false,south:false,north:false,west:true}"},
        {pos: [3, 2, 5], state: "minecraft:glass_pane{east:true,waterlogged:false,south:false,north:false,west:true}"},
        {pos: [4, 2, 4], state: "minecraft:potted_dandelion"},
        {pos: [4, 2, 7], state: "minecraft:glass_pane{east:false,waterlogged:false,south:true,north:true,west:false}"},
        {pos: [5, 2, 3], state: "minecraft:glass_pane{east:false,waterlogged:false,south:true,north:true,west:false}"},
        {pos: [6, 2, 5], state: "minecraft:glass_pane{east:true,waterlogged:false,south:false,north:false,west:true}"},
        {pos: [6, 2, 9], state: "minecraft:acacia_door{hinge:right,half:upper,powered:false,facing:south,open:false}"},
        {pos: [8, 2, 7], state: "minecraft:glass_pane{east:false,waterlogged:false,south:true,north:true,west:false}"},
        {pos: [4, 3, 3], state: "minecraft:wall_torch{facing:west}"},
        {pos: [6, 3, 6], state: "minecraft:wall_torch{facing:south}"},
        {pos: [0, 4, 1], state: "minecraft:acacia_stairs{half:bottom,waterlogged:false,shape:straight,facing:east}"},
        {pos: [0, 4, 2], state: "minecraft:acacia_stairs{half:bottom,waterlogged:false,shape:straight,facing:east}"},
        {pos: [0, 4, 3], state: "minecraft:acacia_stairs{half:bottom,waterlogged:false,shape:straight,facing:east}"},
        {pos: [0, 4, 4], state: "minecraft:acacia_stairs{half:bottom,waterlogged:false,shape:straight,facing:east}"},
        {pos: [0, 4, 5], state: "minecraft:acacia_stairs{half:bottom,waterlogged:false,shape:straight,facing:east}"},
        {pos: [1, 4, 0], state: "minecraft:acacia_stairs{half:bottom,waterlogged:false,shape:straight,facing:south}"},
        {pos: [1, 4, 6], state: "minecraft:acacia_stairs{half:bottom,waterlogged:false,shape:straight,facing:north}"},
        {pos: [2, 4, 0], state: "minecraft:acacia_stairs{half:bottom,waterlogged:false,shape:straight,facing:south}"},
        {pos: [2, 4, 6], state: "minecraft:acacia_stairs{half:bottom,waterlogged:false,shape:straight,facing:north}"},
        {pos: [3, 4, 0], state: "minecraft:acacia_stairs{half:bottom,waterlogged:false,shape:straight,facing:south}"},
        {pos: [3, 4, 6], state: "minecraft:acacia_stairs{half:bottom,waterlogged:false,shape:inner_right,facing:north}"},
        {pos: [3, 4, 7], state: "minecraft:acacia_stairs{half:bottom,waterlogged:false,shape:straight,facing:east}"},
        {pos: [3, 4, 8], state: "minecraft:acacia_stairs{half:bottom,waterlogged:false,shape:straight,facing:east}"},
        {pos: [3, 4, 9], state: "minecraft:acacia_stairs{half:bottom,waterlogged:false,shape:straight,facing:east}"},
        {pos: [4, 4, 0], state: "minecraft:acacia_stairs{half:bottom,waterlogged:false,shape:straight,facing:south}"},
        {pos: [4, 4, 10], state: "minecraft:acacia_stairs{half:bottom,waterlogged:false,shape:straight,facing:north}"},
        {pos: [5, 4, 0], state: "minecraft:acacia_stairs{half:bottom,waterlogged:false,shape:straight,facing:south}"},
        {pos: [5, 4, 10], state: "minecraft:acacia_stairs{half:bottom,waterlogged:false,shape:straight,facing:north}"},
        {pos: [6, 4, 1], state: "minecraft:acacia_stairs{half:bottom,waterlogged:false,shape:straight,facing:west}"},
        {pos: [6, 4, 2], state: "minecraft:acacia_stairs{half:bottom,waterlogged:false,shape:straight,facing:west}"},
        {pos: [6, 4, 3], state: "minecraft:acacia_stairs{half:bottom,waterlogged:false,shape:straight,facing:west}"},
        {pos: [6, 4, 4], state: "minecraft:acacia_stairs{half:bottom,waterlogged:false,shape:inner_right,facing:south}"},
        {pos: [6, 4, 10], state: "minecraft:acacia_stairs{half:bottom,waterlogged:false,shape:straight,facing:north}"},
        {pos: [7, 4, 4], state: "minecraft:acacia_stairs{half:bottom,waterlogged:false,shape:straight,facing:south}"},
        {pos: [7, 4, 10], state: "minecraft:acacia_stairs{half:bottom,waterlogged:false,shape:straight,facing:north}"},
        {pos: [8, 4, 4], state: "minecraft:acacia_stairs{half:bottom,waterlogged:false,shape:straight,facing:south}"},
        {pos: [8, 4, 10], state: "minecraft:acacia_stairs{half:bottom,waterlogged:false,shape:straight,facing:north}"},
        {pos: [9, 4, 5], state: "minecraft:acacia_stairs{half:bottom,waterlogged:false,shape:straight,facing:west}"},
        {pos: [9, 4, 6], state: "minecraft:acacia_stairs{half:bottom,waterlogged:false,shape:straight,facing:west}"},
        {pos: [9, 4, 7], state: "minecraft:acacia_stairs{half:bottom,waterlogged:false,shape:straight,facing:west}"},
        {pos: [9, 4, 8], state: "minecraft:acacia_stairs{half:bottom,waterlogged:false,shape:straight,facing:west}"},
        {pos: [9, 4, 9], state: "minecraft:acacia_stairs{half:bottom,waterlogged:false,shape:straight,facing:west}"},
        {pos: [1, 5, 1], state: "minecraft:acacia_stairs{half:bottom,waterlogged:false,shape:outer_right,facing:east}"},
        {pos: [1, 5, 2], state: "minecraft:acacia_stairs{half:bottom,waterlogged:false,shape:straight,facing:east}"},
        {pos: [1, 5, 3], state: "minecraft:acacia_stairs{half:bottom,waterlogged:false,shape:straight,facing:east}"},
        {pos: [1, 5, 4], state: "minecraft:acacia_stairs{half:bottom,waterlogged:false,shape:straight,facing:east}"},
        {pos: [1, 5, 5], state: "minecraft:acacia_stairs{half:bottom,waterlogged:false,shape:outer_right,facing:north}"},
        {pos: [2, 5, 1], state: "minecraft:acacia_stairs{half:bottom,waterlogged:false,shape:straight,facing:south}"},
        {pos: [2, 5, 2], state: "minecraft:acacia_slab{waterlogged:false,type:top}"},
        {pos: [2, 5, 3], state: "minecraft:acacia_slab{waterlogged:false,type:top}"},
        {pos: [2, 5, 4], state: "minecraft:acacia_slab{waterlogged:false,type:top}"},
        {pos: [2, 5, 5], state: "minecraft:acacia_stairs{half:bottom,waterlogged:false,shape:straight,facing:north}"},
        {pos: [3, 5, 1], state: "minecraft:acacia_stairs{half:bottom,waterlogged:false,shape:straight,facing:south}"},
        {pos: [3, 5, 2], state: "minecraft:acacia_slab{waterlogged:false,type:top}"},
        {pos: [3, 5, 3], state: "minecraft:acacia_slab{waterlogged:false,type:top}"},
        {pos: [3, 5, 4], state: "minecraft:acacia_slab{waterlogged:false,type:top}"},
        {pos: [3, 5, 5], state: "minecraft:acacia_stairs{half:bottom,waterlogged:false,shape:straight,facing:north}"},
        {pos: [4, 5, 1], state: "minecraft:acacia_stairs{half:bottom,waterlogged:false,shape:straight,facing:south}"},
        {pos: [4, 5, 2], state: "minecraft:acacia_slab{waterlogged:false,type:top}"},
        {pos: [4, 5, 3], state: "minecraft:acacia_slab{waterlogged:false,type:top}"},
        {pos: [4, 5, 4], state: "minecraft:acacia_slab{waterlogged:false,type:top}"},
        {pos: [4, 5, 5], state: "minecraft:acacia_stairs{half:bottom,waterlogged:false,shape:inner_right,facing:north}"},
        {pos: [4, 5, 6], state: "minecraft:acacia_stairs{half:bottom,waterlogged:false,shape:straight,facing:east}"},
        {pos: [4, 5, 7], state: "minecraft:acacia_stairs{half:bottom,waterlogged:false,shape:straight,facing:east}"},
        {pos: [4, 5, 8], state: "minecraft:acacia_stairs{half:bottom,waterlogged:false,shape:straight,facing:east}"},
        {pos: [4, 5, 9], state: "minecraft:acacia_stairs{half:bottom,waterlogged:false,shape:outer_left,facing:east}"},
        {pos: [5, 5, 1], state: "minecraft:acacia_stairs{half:bottom,waterlogged:false,shape:outer_left,facing:west}"},
        {pos: [5, 5, 2], state: "minecraft:acacia_stairs{half:bottom,waterlogged:false,shape:straight,facing:west}"},
        {pos: [5, 5, 3], state: "minecraft:acacia_stairs{half:bottom,waterlogged:false,shape:straight,facing:west}"},
        {pos: [5, 5, 4], state: "minecraft:acacia_stairs{half:bottom,waterlogged:false,shape:straight,facing:west}"},
        {pos: [5, 5, 5], state: "minecraft:acacia_stairs{half:bottom,waterlogged:false,shape:inner_right,facing:south}"},
        {pos: [5, 5, 6], state: "minecraft:acacia_slab{waterlogged:false,type:top}"},
        {pos: [5, 5, 7], state: "minecraft:acacia_slab{waterlogged:false,type:top}"},
        {pos: [5, 5, 8], state: "minecraft:acacia_slab{waterlogged:false,type:top}"},
        {pos: [5, 5, 9], state: "minecraft:acacia_stairs{half:bottom,waterlogged:false,shape:straight,facing:north}"},
        {pos: [6, 5, 5], state: "minecraft:acacia_stairs{half:bottom,waterlogged:false,shape:straight,facing:south}"},
        {pos: [6, 5, 6], state: "minecraft:acacia_slab{waterlogged:false,type:top}"},
        {pos: [6, 5, 7], state: "minecraft:acacia_slab{waterlogged:false,type:top}"},
        {pos: [6, 5, 8], state: "minecraft:acacia_slab{waterlogged:false,type:top}"},
        {pos: [6, 5, 9], state: "minecraft:acacia_stairs{half:bottom,waterlogged:false,shape:straight,facing:north}"},
        {pos: [7, 5, 5], state: "minecraft:acacia_stairs{half:bottom,waterlogged:false,shape:straight,facing:south}"},
        {pos: [7, 5, 6], state: "minecraft:acacia_slab{waterlogged:false,type:top}"},
        {pos: [7, 5, 7], state: "minecraft:acacia_slab{waterlogged:false,type:top}"},
        {pos: [7, 5, 8], state: "minecraft:acacia_slab{waterlogged:false,type:top}"},
        {pos: [7, 5, 9], state: "minecraft:acacia_stairs{half:bottom,waterlogged:false,shape:straight,facing:north}"},
        {pos: [8, 5, 5], state: "minecraft:acacia_stairs{half:bottom,waterlogged:false,shape:outer_left,facing:west}"},
        {pos: [8, 5, 6], state: "minecraft:acacia_stairs{half:bottom,waterlogged:false,shape:straight,facing:west}"},
        {pos: [8, 5, 7], state: "minecraft:acacia_stairs{half:bottom,waterlogged:false,shape:straight,facing:west}"},
        {pos: [8, 5, 8], state: "minecraft:acacia_stairs{half:bottom,waterlogged:false,shape:straight,facing:west}"},
        {pos: [8, 5, 9], state: "minecraft:acacia_stairs{half:bottom,waterlogged:false,shape:outer_left,facing:north}"},
        {pos: [3, 0, 3], state: "minecraft:jigsaw{orientation:up_north}", nbt: {final_state: "minecraft:acacia_planks", id: "minecraft:jigsaw", joint: "rollable", name: "minecraft:bottom", pool: "minecraft:village/savanna/villagers", target: "minecraft:bottom"}},
        {pos: [7, 0, 2], state: "minecraft:jigsaw{orientation:up_north}", nbt: {final_state: "minecraft:grass_block", id: "minecraft:jigsaw", joint: "rollable", name: "minecraft:bottom", pool: "minecraft:village/savanna/decor", target: "minecraft:bottom"}},
        {pos: [7, 0, 8], state: "minecraft:jigsaw{orientation:up_north}", nbt: {final_state: "minecraft:acacia_planks", id: "minecraft:jigsaw", joint: "rollable", name: "minecraft:bottom", pool: "minecraft:village/savanna/villagers", target: "minecraft:bottom"}},
        {pos: [0, 1, 5], state: "minecraft:jigsaw{orientation:west_up}", nbt: {final_state: "minecraft:structure_void", id: "minecraft:jigsaw", joint: "aligned", name: "minecraft:building_entrance", pool: "minecraft:empty", target: "minecraft:building_entrance"}},
        {pos: [3, 1, 2], state: "minecraft:orange_bed{part:foot,facing:east,occupied:false}", nbt: {id: "minecraft:bed"}},
        {pos: [4, 1, 2], state: "minecraft:orange_bed{part:head,facing:east,occupied:false}", nbt: {id: "minecraft:bed"}},
        {pos: [5, 1, 6], state: "minecraft:orange_bed{part:head,facing:north,occupied:false}", nbt: {id: "minecraft:bed"}},
        {pos: [5, 1, 7], state: "minecraft:orange_bed{part:foot,facing:north,occupied:false}", nbt: {id: "minecraft:bed"}},
        {pos: [7, 1, 6], state: "minecraft:chest{waterlogged:false,facing:west,type:single}", nbt: {LootTable: "minecraft:chests/village/village_savanna_house", id: "minecraft:chest"}}
    ],
    entities: [],
    palette: [
        "minecraft:dirt",
        "minecraft:acacia_wood{axis:y}",
        "minecraft:acacia_planks",
        "minecraft:crafting_table",
        "minecraft:acacia_wood{axis:x}",
        "minecraft:acacia_wood{axis:z}",
        "minecraft:dirt_path",
        "minecraft:farmland{moisture:7}",
        "minecraft:water{level:0}",
        "minecraft:acacia_door{hinge:left,half:lower,powered:false,facing:south,open:true}",
        "minecraft:acacia_stairs{half:bottom,waterlogged:false,shape:straight,facing:south}",
        "minecraft:wheat{age:0}",
        "minecraft:air",
        "minecraft:wheat{age:1}",
        "minecraft:acacia_stairs{half:bottom,waterlogged:false,shape:straight,facing:west}",
        "minecraft:acacia_door{hinge:right,half:lower,powered:false,facing:south,open:false}",
        "minecraft:acacia_door{hinge:left,half:upper,powered:false,facing:south,open:true}",
        "minecraft:glass_pane{east:true,waterlogged:false,south:false,north:false,west:true}",
        "minecraft:potted_dandelion",
        "minecraft:glass_pane{east:false,waterlogged:false,south:true,north:true,west:false}",
        "minecraft:acacia_door{hinge:right,half:upper,powered:false,facing:south,open:false}",
        "minecraft:wall_torch{facing:west}",
        "minecraft:wall_torch{facing:south}",
        "minecraft:acacia_stairs{half:bottom,waterlogged:false,shape:straight,facing:east}",
        "minecraft:acacia_stairs{half:bottom,waterlogged:false,shape:straight,facing:north}",
        "minecraft:acacia_stairs{half:bottom,waterlogged:false,shape:inner_right,facing:north}",
        "minecraft:acacia_stairs{half:bottom,waterlogged:false,shape:inner_right,facing:south}",
        "minecraft:acacia_stairs{half:bottom,waterlogged:false,shape:outer_right,facing:east}",
        "minecraft:acacia_stairs{half:bottom,waterlogged:false,shape:outer_right,facing:north}",
        "minecraft:acacia_slab{waterlogged:false,type:top}",
        "minecraft:acacia_stairs{half:bottom,waterlogged:false,shape:outer_left,facing:east}",
        "minecraft:acacia_stairs{half:bottom,waterlogged:false,shape:outer_left,facing:west}",
        "minecraft:acacia_stairs{half:bottom,waterlogged:false,shape:outer_left,facing:north}",
        "minecraft:jigsaw{orientation:up_north}",
        "minecraft:jigsaw{orientation:west_up}",
        "minecraft:orange_bed{part:foot,facing:east,occupied:false}",
        "minecraft:orange_bed{part:head,facing:east,occupied:false}",
        "minecraft:orange_bed{part:head,facing:north,occupied:false}",
        "minecraft:orange_bed{part:foot,facing:north,occupied:false}",
        "minecraft:chest{waterlogged:false,facing:west,type:single}"
    ]
}