{
    size: [5, 5, 5],
    data: [
        {pos: [0, 0, 0], state: "minecraft:sand"},
        {pos: [0, 0, 1], state: "minecraft:sand"},
        {pos: [0, 0, 2], state: "minecraft:sand"},
        {pos: [0, 0, 3], state: "minecraft:sand"},
        {pos: [0, 0, 4], state: "minecraft:sand"},
        {pos: [1, 0, 0], state: "minecraft:sand"},
        {pos: [1, 0, 1], state: "minecraft:smooth_sandstone"},
        {pos: [1, 0, 2], state: "minecraft:smooth_sandstone"},
        {pos: [1, 0, 3], state: "minecraft:smooth_sandstone"},
        {pos: [1, 0, 4], state: "minecraft:sand"},
        {pos: [2, 0, 0], state: "minecraft:sand"},
        {pos: [2, 0, 1], state: "minecraft:smooth_sandstone"},
        {pos: [2, 0, 2], state: "minecraft:terracotta"},
        {pos: [2, 0, 3], state: "minecraft:smooth_sandstone"},
        {pos: [2, 0, 4], state: "minecraft:smooth_sandstone"},
        {pos: [3, 0, 0], state: "minecraft:sand"},
        {pos: [3, 0, 1], state: "minecraft:smooth_sandstone"},
        {pos: [3, 0, 3], state: "minecraft:smooth_sandstone"},
        {pos: [3, 0, 4], state: "minecraft:sand"},
        {pos: [4, 0, 0], state: "minecraft:sand"},
        {pos: [4, 0, 1], state: "minecraft:sand"},
        {pos: [4, 0, 2], state: "minecraft:sand"},
        {pos: [4, 0, 3], state: "minecraft:sand"},
        {pos: [4, 0, 4], state: "minecraft:sand"},
        {pos: [0, 1, 0], state: "minecraft:cut_sandstone"},
        {pos: [0, 1, 1], state: "minecraft:smooth_sandstone"},
        {pos: [0, 1, 2], state: "minecraft:smooth_sandstone"},
        {pos: [0, 1, 3], state: "minecraft:smooth_sandstone"},
        {pos: [0, 1, 4], state: "minecraft:cut_sandstone"},
        {pos: [1, 1, 0], state: "minecraft:smooth_sandstone"},
        {pos: [1, 1, 4], state: "minecraft:smooth_sandstone"},
        {pos: [2, 1, 0], state: "minecraft:smooth_sandstone"},
        {pos: [3, 1, 0], state: "minecraft:smooth_sandstone"},
        {pos: [4, 1, 0], state: "minecraft:cut_sandstone"},
        {pos: [4, 1, 1], state: "minecraft:smooth_sandstone"},
        {pos: [4, 1, 2], state: "minecraft:smooth_sandstone"},
        {pos: [4, 1, 3], state: "minecraft:smooth_sandstone"},
        {pos: [4, 1, 4], state: "minecraft:cut_sandstone"},
        {pos: [0, 2, 0], state: "minecraft:cut_sandstone"},
        {pos: [0, 2, 1], state: "minecraft:smooth_sandstone"},
        {pos: [0, 2, 2], state: "minecraft:smooth_sandstone"},
        {pos: [0, 2, 3], state: "minecraft:smooth_sandstone"},
        {pos: [0, 2, 4], state: "minecraft:cut_sandstone"},
        {pos: [1, 2, 0], state: "minecraft:smooth_sandstone"},
        {pos: [1, 2, 4], state: "minecraft:smooth_sandstone"},
        {pos: [3, 2, 0], state: "minecraft:smooth_sandstone"},
        {pos: [3, 2, 4], state: "minecraft:smooth_sandstone"},
        {pos: [4, 2, 0], state: "minecraft:cut_sandstone"},
        {pos: [4, 2, 1], state: "minecraft:smooth_sandstone"},
        {pos: [4, 2, 2], state: "minecraft:smooth_sandstone"},
        {pos: [4, 2, 3], state: "minecraft:smooth_sandstone"},
        {pos: [4, 2, 4], state: "minecraft:cut_sandstone"},
        {pos: [0, 3, 0], state: "minecraft:cut_sandstone"},
        {pos: [0, 3, 1], state: "minecraft:smooth_sandstone"},
        {pos: [0, 3, 2], state: "minecraft:smooth_sandstone"},
        {pos: [0, 3, 3], state: "minecraft:smooth_sandstone"},
        {pos: [0, 3, 4], state: "minecraft:cut_sandstone"},
        {pos: [1, 3, 0], state: "minecraft:smooth_sandstone"},
        {pos: [1, 3, 4], state: "minecraft:smooth_sandstone"},
        {pos: [2, 3, 4], state: "minecraft:smooth_sandstone"},
        {pos: [3, 3, 0], state: "minecraft:smooth_sandstone"},
        {pos: [3, 3, 4], state: "minecraft:smooth_sandstone"},
        {pos: [4, 3, 0], state: "minecraft:cut_sandstone"},
        {pos: [4, 3, 1], state: "minecraft:smooth_sandstone"},
        {pos: [4, 3, 2], state: "minecraft:smooth_sandstone"},
        {pos: [4, 3, 3], state: "minecraft:smooth_sandstone"},
        {pos: [4, 3, 4], state: "minecraft:cut_sandstone"},
        {pos: [0, 4, 0], state: "minecraft:terracotta"},
        {pos: [0, 4, 2], state: "minecraft:terracotta"},
        {pos: [0, 4, 4], state: "minecraft:terracotta"},
        {pos: [2, 4, 0], state: "minecraft:terracotta"},
        {pos: [2, 4, 4], state: "minecraft:terracotta"},
        {pos: [4, 4, 0], state: "minecraft:terracotta"},
        {pos: [4, 4, 2], state: "minecraft:terracotta"},
        {pos: [4, 4, 4], state: "minecraft:terracotta"},
        {pos: [1, 1, 2], state: "minecraft:air"},
        {pos: [1, 1, 3], state: "minecraft:air"},
        {pos: [2, 1, 2], state: "minecraft:air"},
        {pos: [2, 1, 3], state: "minecraft:air"},
        {pos: [2, 1, 4], state: "minecraft:jungle_door{hinge:left,half:lower,powered:false,facing:south,open:false}"},
        {pos: [3, 1, 2], state: "minecraft:air"},
        {pos: [3, 1, 3], state: "minecraft:air"},
        {pos: [1, 2, 1], state: "minecraft:air"},
        {pos: [1, 2, 2], state: "minecraft:air"},
        {pos: [1, 2, 3], state: "minecraft:air"},
        {pos: [2, 2, 0], state: "minecraft:air"},
        {pos: [2, 2, 1], state: "minecraft:air"},
        {pos: [2, 2, 2], state: "minecraft:air"},
        {pos: [2, 2, 3], state: "minecraft:air"},
        {pos: [2, 2, 4], state: "minecraft:jungle_door{hinge:left,half:upper,powered:false,facing:south,open:false}"},
        {pos: [3, 2, 1], state: "minecraft:air"},
        {pos: [3, 2, 2], state: "minecraft:air"},
        {pos: [3, 2, 3], state: "minecraft:air"},
        {pos: [1, 3, 1], state: "minecraft:air"},
        {pos: [1, 3, 2], state: "minecraft:air"},
        {pos: [1, 3, 3], state: "minecraft:air"},
        {pos: [2, 3, 0], state: "minecraft:smooth_sandstone_slab{waterlogged:false,type:top}"},
        {pos: [2, 3, 1], state: "minecraft:air"},
        {pos: [2, 3, 2], state: "minecraft:air"},
        {pos: [2, 3, 3], state: "minecraft:wall_torch{facing:north}"},
        {pos: [3, 3, 1], state: "minecraft:air"},
        {pos: [3, 3, 2], state: "minecraft:air"},
        {pos: [3, 3, 3], state: "minecraft:air"},
        {pos: [0, 4, 1], state: "minecraft:smooth_sandstone_stairs{half:bottom,waterlogged:false,shape:straight,facing:east}"},
        {pos: [0, 4, 3], state: "minecraft:smooth_sandstone_stairs{half:bottom,waterlogged:false,shape:straight,facing:east}"},
        {pos: [1, 4, 0], state: "minecraft:smooth_sandstone_stairs{half:bottom,waterlogged:false,shape:straight,facing:south}"},
        {pos: [1, 4, 1], state: "minecraft:smooth_sandstone_slab{waterlogged:false,type:top}"},
        {pos: [1, 4, 2], state: "minecraft:smooth_sandstone_slab{waterlogged:false,type:top}"},
        {pos: [1, 4, 3], state: "minecraft:smooth_sandstone_slab{waterlogged:false,type:top}"},
        {pos: [1, 4, 4], state: "minecraft:smooth_sandstone_stairs{half:bottom,waterlogged:false,shape:straight,facing:north}"},
        {pos: [2, 4, 1], state: "minecraft:smooth_sandstone_slab{waterlogged:false,type:top}"},
        {pos: [2, 4, 2], state: "minecraft:smooth_sandstone_slab{waterlogged:false,type:top}"},
        {pos: [2, 4, 3], state: "minecraft:smooth_sandstone_slab{waterlogged:false,type:top}"},
        {pos: [3, 4, 0], state: "minecraft:smooth_sandstone_stairs{half:bottom,waterlogged:false,shape:straight,facing:south}"},
        {pos: [3, 4, 1], state: "minecraft:smooth_sandstone_slab{waterlogged:false,type:top}"},
        {pos: [3, 4, 2], state: "minecraft:smooth_sandstone_slab{waterlogged:false,type:top}"},
        {pos: [3, 4, 3], state: "minecraft:smooth_sandstone_slab{waterlogged:false,type:top}"},
        {pos: [3, 4, 4], state: "minecraft:smooth_sandstone_stairs{half:bottom,waterlogged:false,shape:straight,facing:north}"},
        {pos: [4, 4, 1], state: "minecraft:smooth_sandstone_stairs{half:bottom,waterlogged:false,shape:straight,facing:west}"},
        {pos: [4, 4, 3], state: "minecraft:smooth_sandstone_stairs{half:bottom,waterlogged:false,shape:straight,facing:west}"},
        {pos: [3, 0, 2], state: "minecraft:jigsaw{orientation:up_north}", nbt: {final_state: "minecraft:smooth_sandstone", id: "minecraft:jigsaw", joint: "rollable", name: "minecraft:bottom", pool: "minecraft:village/desert/villagers", target: "minecraft:bottom"}},
        {pos: [1, 1, 1], state: "minecraft:cyan_bed{part:head,facing:west,occupied:false}", nbt: {id: "minecraft:bed"}},
        {pos: [2, 1, 1], state: "minecraft:cyan_bed{part:foot,facing:west,occupied:false}", nbt: {id: "minecraft:bed"}},
        {pos: [3, 1, 1], state: "minecraft:chest{waterlogged:false,facing:south,type:single}", nbt: {LootTable: "minecraft:chests/village/village_desert_house", id: "minecraft:chest"}},
        {pos: [3, 1, 4], state: "minecraft:jigsaw{orientation:south_up}", nbt: {final_state: "minecraft:smooth_sandstone", id: "minecraft:jigsaw", joint: "aligned", name: "minecraft:building_entrance", pool: "minecraft:empty", target: "minecraft:building_entrance"}}
    ],
    entities: [],
    palette: [
        "minecraft:sand",
        "minecraft:smooth_sandstone",
        "minecraft:terracotta",
        "minecraft:cut_sandstone",
        "minecraft:air",
        "minecraft:jungle_door{hinge:left,half:lower,powered:false,facing:south,open:false}",
        "minecraft:jungle_door{hinge:left,half:upper,powered:false,facing:south,open:false}",
        "minecraft:smooth_sandstone_slab{waterlogged:false,type:top}",
        "minecraft:wall_torch{facing:north}",
        "minecraft:smooth_sandstone_stairs{half:bottom,waterlogged:false,shape:straight,facing:east}",
        "minecraft:smooth_sandstone_stairs{half:bottom,waterlogged:false,shape:straight,facing:south}",
        "minecraft:smooth_sandstone_stairs{half:bottom,waterlogged:false,shape:straight,facing:north}",
        "minecraft:smooth_sandstone_stairs{half:bottom,waterlogged:false,shape:straight,facing:west}",
        "minecraft:jigsaw{orientation:up_north}",
        "minecraft:cyan_bed{part:head,facing:west,occupied:false}",
        "minecraft:cyan_bed{part:foot,facing:west,occupied:false}",
        "minecraft:chest{waterlogged:false,facing:south,type:single}",
        "minecraft:jigsaw{orientation:south_up}"
    ]
}