{
    size: [8, 5, 7],
    data: [
        {pos: [0, 0, 0], state: "minecraft:sand"},
        {pos: [0, 0, 1], state: "minecraft:smooth_sandstone"},
        {pos: [0, 0, 2], state: "minecraft:sand"},
        {pos: [0, 0, 3], state: "minecraft:sand"},
        {pos: [0, 0, 4], state: "minecraft:sand"},
        {pos: [0, 0, 5], state: "minecraft:sand"},
        {pos: [0, 0, 6], state: "minecraft:sand"},
        {pos: [1, 0, 0], state: "minecraft:sand"},
        {pos: [1, 0, 1], state: "minecraft:smooth_sandstone"},
        {pos: [1, 0, 2], state: "minecraft:sand"},
        {pos: [1, 0, 6], state: "minecraft:sand"},
        {pos: [2, 0, 0], state: "minecraft:sand"},
        {pos: [2, 0, 1], state: "minecraft:smooth_sandstone"},
        {pos: [2, 0, 2], state: "minecraft:sand"},
        {pos: [2, 0, 4], state: "minecraft:sand"},
        {pos: [2, 0, 6], state: "minecraft:sand"},
        {pos: [3, 0, 0], state: "minecraft:sand"},
        {pos: [3, 0, 1], state: "minecraft:smooth_sandstone"},
        {pos: [3, 0, 2], state: "minecraft:sand"},
        {pos: [3, 0, 6], state: "minecraft:sand"},
        {pos: [4, 0, 0], state: "minecraft:sand"},
        {pos: [4, 0, 1], state: "minecraft:smooth_sandstone"},
        {pos: [4, 0, 2], state: "minecraft:sand"},
        {pos: [4, 0, 3], state: "minecraft:sand"},
        {pos: [4, 0, 4], state: "minecraft:smooth_sandstone"},
        {pos: [4, 0, 5], state: "minecraft:sand"},
        {pos: [4, 0, 6], state: "minecraft:sand"},
        {pos: [5, 0, 0], state: "minecraft:sand"},
        {pos: [5, 0, 1], state: "minecraft:smooth_sandstone"},
        {pos: [5, 0, 2], state: "minecraft:smooth_sandstone"},
        {pos: [5, 0, 4], state: "minecraft:smooth_sandstone"},
        {pos: [5, 0, 5], state: "minecraft:smooth_sandstone"},
        {pos: [5, 0, 6], state: "minecraft:sand"},
        {pos: [6, 0, 0], state: "minecraft:sand"},
        {pos: [6, 0, 1], state: "minecraft:smooth_sandstone"},
        {pos: [6, 0, 2], state: "minecraft:smooth_sandstone"},
        {pos: [6, 0, 3], state: "minecraft:smooth_sandstone"},
        {pos: [6, 0, 4], state: "minecraft:smooth_sandstone"},
        {pos: [6, 0, 5], state: "minecraft:smooth_sandstone"},
        {pos: [6, 0, 6], state: "minecraft:sand"},
        {pos: [7, 0, 0], state: "minecraft:sand"},
        {pos: [7, 0, 1], state: "minecraft:sand"},
        {pos: [7, 0, 2], state: "minecraft:sand"},
        {pos: [7, 0, 3], state: "minecraft:sand"},
        {pos: [7, 0, 4], state: "minecraft:sand"},
        {pos: [7, 0, 5], state: "minecraft:sand"},
        {pos: [7, 0, 6], state: "minecraft:sand"},
        {pos: [4, 1, 0], state: "minecraft:smooth_sandstone"},
        {pos: [4, 1, 2], state: "minecraft:smooth_sandstone"},
        {pos: [4, 1, 3], state: "minecraft:smooth_sandstone"},
        {pos: [4, 1, 5], state: "minecraft:smooth_sandstone"},
        {pos: [4, 1, 6], state: "minecraft:smooth_sandstone"},
        {pos: [5, 1, 0], state: "minecraft:smooth_sandstone"},
        {pos: [5, 1, 6], state: "minecraft:smooth_sandstone"},
        {pos: [6, 1, 0], state: "minecraft:smooth_sandstone"},
        {pos: [6, 1, 2], state: "minecraft:cut_sandstone"},
        {pos: [6, 1, 6], state: "minecraft:smooth_sandstone"},
        {pos: [7, 1, 0], state: "minecraft:smooth_sandstone"},
        {pos: [7, 1, 1], state: "minecraft:smooth_sandstone"},
        {pos: [7, 1, 2], state: "minecraft:smooth_sandstone"},
        {pos: [7, 1, 3], state: "minecraft:smooth_sandstone"},
        {pos: [7, 1, 4], state: "minecraft:smooth_sandstone"},
        {pos: [7, 1, 5], state: "minecraft:smooth_sandstone"},
        {pos: [7, 1, 6], state: "minecraft:smooth_sandstone"},
        {pos: [4, 2, 0], state: "minecraft:smooth_sandstone"},
        {pos: [4, 2, 2], state: "minecraft:smooth_sandstone"},
        {pos: [4, 2, 3], state: "minecraft:smooth_sandstone"},
        {pos: [4, 2, 5], state: "minecraft:smooth_sandstone"},
        {pos: [4, 2, 6], state: "minecraft:smooth_sandstone"},
        {pos: [7, 2, 0], state: "minecraft:smooth_sandstone"},
        {pos: [7, 2, 1], state: "minecraft:smooth_sandstone"},
        {pos: [7, 2, 3], state: "minecraft:smooth_sandstone"},
        {pos: [7, 2, 5], state: "minecraft:smooth_sandstone"},
        {pos: [7, 2, 6], state: "minecraft:smooth_sandstone"},
        {pos: [4, 3, 0], state: "minecraft:smooth_sandstone"},
        {pos: [4, 3, 1], state: "minecraft:smooth_sandstone"},
        {pos: [4, 3, 2], state: "minecraft:smooth_sandstone"},
        {pos: [4, 3, 3], state: "minecraft:smooth_sandstone"},
        {pos: [4, 3, 4], state: "minecraft:smooth_sandstone"},
        {pos: [4, 3, 5], state: "minecraft:smooth_sandstone"},
        {pos: [4, 3, 6], state: "minecraft:smooth_sandstone"},
        {pos: [5, 3, 0], state: "minecraft:smooth_sandstone"},
        {pos: [5, 3, 6], state: "minecraft:smooth_sandstone"},
        {pos: [6, 3, 0], state: "minecraft:smooth_sandstone"},
        {pos: [6, 3, 6], state: "minecraft:smooth_sandstone"},
        {pos: [7, 3, 0], state: "minecraft:smooth_sandstone"},
        {pos: [7, 3, 1], state: "minecraft:smooth_sandstone"},
        {pos: [7, 3, 2], state: "minecraft:smooth_sandstone"},
        {pos: [7, 3, 3], state: "minecraft:smooth_sandstone"},
        {pos: [7, 3, 4], state: "minecraft:smooth_sandstone"},
        {pos: [7, 3, 5], state: "minecraft:smooth_sandstone"},
        {pos: [7, 3, 6], state: "minecraft:smooth_sandstone"},
        {pos: [1, 0, 3], state: "minecraft:air"},
        {pos: [3, 0, 5], state: "minecraft:air"},
        {pos: [0, 1, 0], state: "minecraft:sandstone_wall{east:low,waterlogged:false,south:none,north:none,west:none,up:true}"},
        {pos: [0, 1, 2], state: "minecraft:sandstone_wall{east:low,waterlogged:false,south:low,north:none,west:none,up:true}"},
        {pos: [0, 1, 3], state: "minecraft:sandstone_wall{east:none,waterlogged:false,south:low,north:low,west:none,up:false}"},
        {pos: [0, 1, 4], state: "minecraft:sandstone_wall{east:none,waterlogged:false,south:low,north:low,west:none,up:true}"},
        {pos: [0, 1, 5], state: "minecraft:sandstone_wall{east:none,waterlogged:false,south:low,north:low,west:none,up:false}"},
        {pos: [0, 1, 6], state: "minecraft:sandstone_wall{east:low,waterlogged:false,south:none,north:low,west:none,up:true}"},
        {pos: [1, 1, 0], state: "minecraft:sandstone_wall{east:low,waterlogged:false,south:none,north:none,west:low,up:false}"},
        {pos: [1, 1, 1], state: "minecraft:air"},
        {pos: [1, 1, 2], state: "minecraft:sandstone_wall{east:low,waterlogged:false,south:none,north:none,west:low,up:false}"},
        {pos: [1, 1, 3], state: "minecraft:air"},
        {pos: [1, 1, 4], state: "minecraft:air"},
        {pos: [1, 1, 5], state: "minecraft:air"},
        {pos: [1, 1, 6], state: "minecraft:sandstone_wall{east:low,waterlogged:false,south:none,north:none,west:low,up:false}"},
        {pos: [2, 1, 0], state: "minecraft:sandstone_wall{east:low,waterlogged:false,south:none,north:none,west:low,up:true}"},
        {pos: [2, 1, 1], state: "minecraft:air"},
        {pos: [2, 1, 2], state: "minecraft:sandstone_wall{east:low,waterlogged:false,south:none,north:none,west:low,up:true}"},
        {pos: [2, 1, 3], state: "minecraft:air"},
        {pos: [2, 1, 4], state: "minecraft:cactus{age:0}"},
        {pos: [2, 1, 5], state: "minecraft:air"},
        {pos: [2, 1, 6], state: "minecraft:sandstone_wall{east:low,waterlogged:false,south:none,north:none,west:low,up:true}"},
        {pos: [3, 1, 0], state: "minecraft:sandstone_wall{east:low,waterlogged:false,south:none,north:none,west:low,up:false}"},
        {pos: [3, 1, 1], state: "minecraft:air"},
        {pos: [3, 1, 2], state: "minecraft:sandstone_wall{east:low,waterlogged:false,south:none,north:none,west:low,up:false}"},
        {pos: [3, 1, 3], state: "minecraft:air"},
        {pos: [3, 1, 4], state: "minecraft:air"},
        {pos: [3, 1, 5], state: "minecraft:air"},
        {pos: [3, 1, 6], state: "minecraft:sandstone_wall{east:low,waterlogged:false,south:none,north:none,west:low,up:false}"},
        {pos: [4, 1, 1], state: "minecraft:jungle_door{hinge:left,half:lower,powered:false,facing:west,open:false}"},
        {pos: [4, 1, 4], state: "minecraft:jungle_door{hinge:right,half:lower,powered:false,facing:west,open:false}"},
        {pos: [5, 1, 1], state: "minecraft:air"},
        {pos: [5, 1, 2], state: "minecraft:air"},
        {pos: [5, 1, 3], state: "minecraft:air"},
        {pos: [5, 1, 4], state: "minecraft:air"},
        {pos: [5, 1, 5], state: "minecraft:air"},
        {pos: [6, 1, 1], state: "minecraft:smooth_sandstone_stairs{half:bottom,waterlogged:false,shape:straight,facing:north}"},
        {pos: [6, 1, 3], state: "minecraft:smooth_sandstone_stairs{half:bottom,waterlogged:false,shape:straight,facing:south}"},
        {pos: [0, 2, 0], state: "minecraft:air"},
        {pos: [0, 2, 1], state: "minecraft:air"},
        {pos: [0, 2, 2], state: "minecraft:air"},
        {pos: [0, 2, 3], state: "minecraft:air"},
        {pos: [0, 2, 4], state: "minecraft:potted_dead_bush"},
        {pos: [0, 2, 5], state: "minecraft:air"},
        {pos: [0, 2, 6], state: "minecraft:air"},
        {pos: [1, 2, 0], state: "minecraft:air"},
        {pos: [1, 2, 1], state: "minecraft:air"},
        {pos: [1, 2, 2], state: "minecraft:air"},
        {pos: [1, 2, 3], state: "minecraft:air"},
        {pos: [1, 2, 4], state: "minecraft:air"},
        {pos: [1, 2, 5], state: "minecraft:air"},
        {pos: [1, 2, 6], state: "minecraft:air"},
        {pos: [2, 2, 0], state: "minecraft:torch"},
        {pos: [2, 2, 1], state: "minecraft:air"},
        {pos: [2, 2, 2], state: "minecraft:torch"},
        {pos: [2, 2, 3], state: "minecraft:air"},
        {pos: [2, 2, 4], state: "minecraft:cactus{age:0}"},
        {pos: [2, 2, 5], state: "minecraft:air"},
        {pos: [2, 2, 6], state: "minecraft:potted_dead_bush"},
        {pos: [3, 2, 0], state: "minecraft:air"},
        {pos: [3, 2, 1], state: "minecraft:air"},
        {pos: [3, 2, 2], state: "minecraft:air"},
        {pos: [3, 2, 3], state: "minecraft:air"},
        {pos: [3, 2, 4], state: "minecraft:air"},
        {pos: [3, 2, 5], state: "minecraft:air"},
        {pos: [3, 2, 6], state: "minecraft:air"},
        {pos: [4, 2, 1], state: "minecraft:jungle_door{hinge:left,half:upper,powered:false,facing:west,open:false}"},
        {pos: [4, 2, 4], state: "minecraft:jungle_door{hinge:right,half:upper,powered:false,facing:west,open:false}"},
        {pos: [5, 2, 0], state: "minecraft:smooth_sandstone_slab{waterlogged:false,type:bottom}"},
        {pos: [5, 2, 1], state: "minecraft:air"},
        {pos: [5, 2, 2], state: "minecraft:air"},
        {pos: [5, 2, 3], state: "minecraft:air"},
        {pos: [5, 2, 4], state: "minecraft:air"},
        {pos: [5, 2, 5], state: "minecraft:air"},
        {pos: [5, 2, 6], state: "minecraft:smooth_sandstone_slab{waterlogged:false,type:bottom}"},
        {pos: [6, 2, 0], state: "minecraft:smooth_sandstone_slab{waterlogged:false,type:bottom}"},
        {pos: [6, 2, 1], state: "minecraft:air"},
        {pos: [6, 2, 2], state: "minecraft:torch"},
        {pos: [6, 2, 3], state: "minecraft:air"},
        {pos: [6, 2, 4], state: "minecraft:air"},
        {pos: [6, 2, 5], state: "minecraft:air"},
        {pos: [6, 2, 6], state: "minecraft:smooth_sandstone_slab{waterlogged:false,type:bottom}"},
        {pos: [7, 2, 2], state: "minecraft:smooth_sandstone_slab{waterlogged:false,type:bottom}"},
        {pos: [7, 2, 4], state: "minecraft:smooth_sandstone_slab{waterlogged:false,type:bottom}"},
        {pos: [0, 3, 0], state: "minecraft:air"},
        {pos: [0, 3, 1], state: "minecraft:air"},
        {pos: [0, 3, 2], state: "minecraft:air"},
        {pos: [0, 3, 3], state: "minecraft:air"},
        {pos: [0, 3, 4], state: "minecraft:air"},
        {pos: [0, 3, 5], state: "minecraft:air"},
        {pos: [0, 3, 6], state: "minecraft:air"},
        {pos: [1, 3, 0], state: "minecraft:air"},
        {pos: [1, 3, 1], state: "minecraft:air"},
        {pos: [1, 3, 2], state: "minecraft:air"},
        {pos: [1, 3, 3], state: "minecraft:air"},
        {pos: [1, 3, 4], state: "minecraft:air"},
        {pos: [1, 3, 5], state: "minecraft:air"},
        {pos: [1, 3, 6], state: "minecraft:air"},
        {pos: [2, 3, 0], state: "minecraft:air"},
        {pos: [2, 3, 1], state: "minecraft:air"},
        {pos: [2, 3, 2], state: "minecraft:air"},
        {pos: [2, 3, 3], state: "minecraft:air"},
        {pos: [2, 3, 4], state: "minecraft:cactus{age:0}"},
        {pos: [2, 3, 5], state: "minecraft:air"},
        {pos: [2, 3, 6], state: "minecraft:air"},
        {pos: [3, 3, 0], state: "minecraft:air"},
        {pos: [3, 3, 1], state: "minecraft:air"},
        {pos: [3, 3, 2], state: "minecraft:air"},
        {pos: [3, 3, 3], state: "minecraft:air"},
        {pos: [3, 3, 4], state: "minecraft:air"},
        {pos: [3, 3, 5], state: "minecraft:air"},
        {pos: [3, 3, 6], state: "minecraft:air"},
        {pos: [5, 3, 1], state: "minecraft:smooth_sandstone_slab{waterlogged:false,type:top}"},
        {pos: [5, 3, 2], state: "minecraft:smooth_sandstone_slab{waterlogged:false,type:top}"},
        {pos: [5, 3, 3], state: "minecraft:smooth_sandstone_slab{waterlogged:false,type:top}"},
        {pos: [5, 3, 4], state: "minecraft:smooth_sandstone_slab{waterlogged:false,type:top}"},
        {pos: [5, 3, 5], state: "minecraft:smooth_sandstone_slab{waterlogged:false,type:top}"},
        {pos: [6, 3, 1], state: "minecraft:smooth_sandstone_slab{waterlogged:false,type:top}"},
        {pos: [6, 3, 2], state: "minecraft:smooth_sandstone_slab{waterlogged:false,type:top}"},
        {pos: [6, 3, 3], state: "minecraft:smooth_sandstone_slab{waterlogged:false,type:top}"},
        {pos: [6, 3, 4], state: "minecraft:smooth_sandstone_slab{waterlogged:false,type:top}"},
        {pos: [6, 3, 5], state: "minecraft:smooth_sandstone_slab{waterlogged:false,type:top}"},
        {pos: [0, 4, 0], state: "minecraft:air"},
        {pos: [0, 4, 1], state: "minecraft:air"},
        {pos: [0, 4, 2], state: "minecraft:air"},
        {pos: [0, 4, 3], state: "minecraft:air"},
        {pos: [0, 4, 4], state: "minecraft:air"},
        {pos: [0, 4, 5], state: "minecraft:air"},
        {pos: [0, 4, 6], state: "minecraft:air"},
        {pos: [1, 4, 0], state: "minecraft:air"},
        {pos: [1, 4, 1], state: "minecraft:air"},
        {pos: [1, 4, 2], state: "minecraft:air"},
        {pos: [1, 4, 3], state: "minecraft:air"},
        {pos: [1, 4, 4], state: "minecraft:air"},
        {pos: [1, 4, 5], state: "minecraft:air"},
        {pos: [1, 4, 6], state: "minecraft:air"},
        {pos: [2, 4, 0], state: "minecraft:air"},
        {pos: [2, 4, 1], state: "minecraft:air"},
        {pos: [2, 4, 2], state: "minecraft:air"},
        {pos: [2, 4, 3], state: "minecraft:air"},
        {pos: [2, 4, 4], state: "minecraft:air"},
        {pos: [2, 4, 5], state: "minecraft:air"},
        {pos: [2, 4, 6], state: "minecraft:air"},
        {pos: [3, 4, 0], state: "minecraft:air"},
        {pos: [3, 4, 1], state: "minecraft:air"},
        {pos: [3, 4, 2], state: "minecraft:air"},
        {pos: [3, 4, 3], state: "minecraft:air"},
        {pos: [3, 4, 4], state: "minecraft:air"},
        {pos: [3, 4, 5], state: "minecraft:air"},
        {pos: [3, 4, 6], state: "minecraft:air"},
        {pos: [4, 4, 0], state: "minecraft:smooth_sandstone_slab{waterlogged:false,type:bottom}"},
        {pos: [4, 4, 1], state: "minecraft:air"},
        {pos: [4, 4, 2], state: "minecraft:smooth_sandstone_slab{waterlogged:false,type:bottom}"},
        {pos: [4, 4, 3], state: "minecraft:air"},
        {pos: [4, 4, 4], state: "minecraft:smooth_sandstone_slab{waterlogged:false,type:bottom}"},
        {pos: [4, 4, 5], state: "minecraft:air"},
        {pos: [4, 4, 6], state: "minecraft:smooth_sandstone_slab{waterlogged:false,type:bottom}"},
        {pos: [5, 4, 0], state: "minecraft:air"},
        {pos: [5, 4, 1], state: "minecraft:air"},
        {pos: [5, 4, 2], state: "minecraft:air"},
        {pos: [5, 4, 3], state: "minecraft:air"},
        {pos: [5, 4, 4], state: "minecraft:air"},
        {pos: [5, 4, 5], state: "minecraft:air"},
        {pos: [5, 4, 6], state: "minecraft:air"},
        {pos: [6, 4, 0], state: "minecraft:air"},
        {pos: [6, 4, 1], state: "minecraft:air"},
        {pos: [6, 4, 2], state: "minecraft:air"},
        {pos: [6, 4, 3], state: "minecraft:air"},
        {pos: [6, 4, 4], state: "minecraft:air"},
        {pos: [6, 4, 5], state: "minecraft:air"},
        {pos: [6, 4, 6], state: "minecraft:air"},
        {pos: [7, 4, 0], state: "minecraft:smooth_sandstone_slab{waterlogged:false,type:bottom}"},
        {pos: [7, 4, 1], state: "minecraft:air"},
        {pos: [7, 4, 2], state: "minecraft:smooth_sandstone_slab{waterlogged:false,type:bottom}"},
        {pos: [7, 4, 3], state: "minecraft:air"},
        {pos: [7, 4, 4], state: "minecraft:smooth_sandstone_slab{waterlogged:false,type:bottom}"},
        {pos: [7, 4, 5], state: "minecraft:air"},
        {pos: [7, 4, 6], state: "minecraft:smooth_sandstone_slab{waterlogged:false,type:bottom}"},
        {pos: [5, 0, 3], state: "minecraft:jigsaw{orientation:up_north}", nbt: {final_state: "minecraft:smooth_sandstone", id: "minecraft:jigsaw", joint: "rollable", name: "minecraft:bottom", pool: "minecraft:village/desert/villagers", target: "minecraft:bottom"}},
        {pos: [0, 1, 1], state: "minecraft:jigsaw{orientation:west_up}", nbt: {final_state: "minecraft:structure_void", id: "minecraft:jigsaw", joint: "aligned", name: "minecraft:building_entrance", pool: "minecraft:empty", target: "minecraft:building_entrance"}},
        {pos: [6, 1, 4], state: "minecraft:lime_bed{part:foot,facing:south,occupied:false}", nbt: {id: "minecraft:bed"}},
        {pos: [6, 1, 5], state: "minecraft:lime_bed{part:head,facing:south,occupied:false}", nbt: {id: "minecraft:bed"}}
    ],
    entities: [],
    palette: [
        "minecraft:sand",
        "minecraft:smooth_sandstone",
        "minecraft:cut_sandstone",
        "minecraft:air",
        "minecraft:sandstone_wall{east:low,waterlogged:false,south:none,north:none,west:none,up:true}",
        "minecraft:sandstone_wall{east:low,waterlogged:false,south:low,north:none,west:none,up:true}",
        "minecraft:sandstone_wall{east:none,waterlogged:false,south:low,north:low,west:none,up:false}",
        "minecraft:sandstone_wall{east:none,waterlogged:false,south:low,north:low,west:none,up:true}",
        "minecraft:sandstone_wall{east:low,waterlogged:false,south:none,north:low,west:none,up:true}",
        "minecraft:sandstone_wall{east:low,waterlogged:false,south:none,north:none,west:low,up:false}",
        "minecraft:sandstone_wall{east:low,waterlogged:false,south:none,north:none,west:low,up:true}",
        "minecraft:cactus{age:0}",
        "minecraft:jungle_door{hinge:left,half:lower,powered:false,facing:west,open:false}",
        "minecraft:jungle_door{hinge:right,half:lower,powered:false,facing:west,open:false}",
        "minecraft:smooth_sandstone_stairs{half:bottom,waterlogged:false,shape:straight,facing:north}",
        "minecraft:smooth_sandstone_stairs{half:bottom,waterlogged:false,shape:straight,facing:south}",
        "minecraft:potted_dead_bush",
        "minecraft:torch",
        "minecraft:jungle_door{hinge:left,half:upper,powered:false,facing:west,open:false}",
        "minecraft:jungle_door{hinge:right,half:upper,powered:false,facing:west,open:false}",
        "minecraft:smooth_sandstone_slab{waterlogged:false,type:bottom}",
        "minecraft:smooth_sandstone_slab{waterlogged:false,type:top}",
        "minecraft:jigsaw{orientation:up_north}",
        "minecraft:jigsaw{orientation:west_up}",
        "minecraft:lime_bed{part:foot,facing:south,occupied:false}",
        "minecraft:lime_bed{part:head,facing:south,occupied:false}"
    ]
}