{
    size: [7, 7, 7],
    data: [
        {pos: [0, 0, 1], state: "minecraft:smooth_sandstone"},
        {pos: [0, 0, 2], state: "minecraft:smooth_sandstone"},
        {pos: [0, 0, 3], state: "minecraft:smooth_sandstone"},
        {pos: [1, 0, 0], state: "minecraft:cut_sandstone"},
        {pos: [1, 0, 2], state: "minecraft:smooth_sandstone"},
        {pos: [1, 0, 3], state: "minecraft:smooth_sandstone"},
        {pos: [1, 0, 4], state: "minecraft:smooth_sandstone"},
        {pos: [1, 0, 5], state: "minecraft:smooth_sandstone"},
        {pos: [1, 0, 6], state: "minecraft:cut_sandstone"},
        {pos: [2, 0, 0], state: "minecraft:smooth_sandstone"},
        {pos: [2, 0, 2], state: "minecraft:smooth_sandstone"},
        {pos: [2, 0, 3], state: "minecraft:smooth_sandstone"},
        {pos: [2, 0, 5], state: "minecraft:smooth_sandstone"},
        {pos: [2, 0, 6], state: "minecraft:smooth_sandstone"},
        {pos: [3, 0, 0], state: "minecraft:smooth_sandstone"},
        {pos: [3, 0, 2], state: "minecraft:smooth_sandstone"},
        {pos: [3, 0, 6], state: "minecraft:cut_sandstone"},
        {pos: [4, 0, 0], state: "minecraft:cut_sandstone"},
        {pos: [4, 0, 1], state: "minecraft:smooth_sandstone"},
        {pos: [4, 0, 2], state: "minecraft:smooth_sandstone"},
        {pos: [4, 0, 3], state: "minecraft:smooth_sandstone"},
        {pos: [4, 0, 6], state: "minecraft:smooth_sandstone"},
        {pos: [5, 0, 1], state: "minecraft:smooth_sandstone"},
        {pos: [5, 0, 2], state: "minecraft:smooth_sandstone"},
        {pos: [5, 0, 3], state: "minecraft:smooth_sandstone"},
        {pos: [5, 0, 6], state: "minecraft:smooth_sandstone"},
        {pos: [6, 0, 3], state: "minecraft:cut_sandstone"},
        {pos: [6, 0, 4], state: "minecraft:smooth_sandstone"},
        {pos: [6, 0, 5], state: "minecraft:smooth_sandstone"},
        {pos: [6, 0, 6], state: "minecraft:cut_sandstone"},
        {pos: [0, 1, 1], state: "minecraft:smooth_sandstone"},
        {pos: [0, 1, 2], state: "minecraft:smooth_sandstone"},
        {pos: [1, 1, 0], state: "minecraft:cut_sandstone"},
        {pos: [1, 1, 1], state: "minecraft:smooth_sandstone"},
        {pos: [1, 1, 2], state: "minecraft:smooth_sandstone"},
        {pos: [1, 1, 3], state: "minecraft:smooth_sandstone"},
        {pos: [1, 1, 4], state: "minecraft:smooth_sandstone"},
        {pos: [1, 1, 5], state: "minecraft:smooth_sandstone"},
        {pos: [1, 1, 6], state: "minecraft:cut_sandstone"},
        {pos: [2, 1, 0], state: "minecraft:smooth_sandstone"},
        {pos: [2, 1, 1], state: "minecraft:smooth_sandstone"},
        {pos: [2, 1, 2], state: "minecraft:smooth_sandstone"},
        {pos: [2, 1, 3], state: "minecraft:smooth_sandstone"},
        {pos: [2, 1, 5], state: "minecraft:smooth_sandstone"},
        {pos: [2, 1, 6], state: "minecraft:smooth_sandstone"},
        {pos: [3, 1, 0], state: "minecraft:smooth_sandstone"},
        {pos: [3, 1, 1], state: "minecraft:smooth_sandstone"},
        {pos: [3, 1, 2], state: "minecraft:smooth_sandstone"},
        {pos: [3, 1, 6], state: "minecraft:cut_sandstone"},
        {pos: [4, 1, 0], state: "minecraft:cut_sandstone"},
        {pos: [4, 1, 1], state: "minecraft:smooth_sandstone"},
        {pos: [4, 1, 2], state: "minecraft:smooth_sandstone"},
        {pos: [4, 1, 3], state: "minecraft:smooth_sandstone"},
        {pos: [4, 1, 6], state: "minecraft:smooth_sandstone"},
        {pos: [5, 1, 2], state: "minecraft:smooth_sandstone"},
        {pos: [5, 1, 3], state: "minecraft:smooth_sandstone"},
        {pos: [5, 1, 6], state: "minecraft:smooth_sandstone"},
        {pos: [6, 1, 3], state: "minecraft:cut_sandstone"},
        {pos: [6, 1, 4], state: "minecraft:smooth_sandstone"},
        {pos: [6, 1, 5], state: "minecraft:smooth_sandstone"},
        {pos: [6, 1, 6], state: "minecraft:cut_sandstone"},
        {pos: [1, 2, 0], state: "minecraft:cut_sandstone"},
        {pos: [1, 2, 2], state: "minecraft:cut_sandstone"},
        {pos: [1, 2, 3], state: "minecraft:smooth_sandstone"},
        {pos: [1, 2, 4], state: "minecraft:smooth_sandstone"},
        {pos: [1, 2, 5], state: "minecraft:smooth_sandstone"},
        {pos: [1, 2, 6], state: "minecraft:cut_sandstone"},
        {pos: [2, 2, 0], state: "minecraft:smooth_sandstone"},
        {pos: [2, 2, 4], state: "minecraft:smooth_sandstone"},
        {pos: [2, 2, 5], state: "minecraft:smooth_sandstone"},
        {pos: [2, 2, 6], state: "minecraft:smooth_sandstone"},
        {pos: [3, 2, 0], state: "minecraft:smooth_sandstone"},
        {pos: [3, 2, 2], state: "minecraft:cartography_table"},
        {pos: [3, 2, 3], state: "minecraft:smooth_sandstone"},
        {pos: [3, 2, 4], state: "minecraft:smooth_sandstone"},
        {pos: [3, 2, 5], state: "minecraft:smooth_sandstone"},
        {pos: [3, 2, 6], state: "minecraft:cut_sandstone"},
        {pos: [4, 2, 0], state: "minecraft:cut_sandstone"},
        {pos: [4, 2, 1], state: "minecraft:smooth_sandstone"},
        {pos: [4, 2, 2], state: "minecraft:smooth_sandstone"},
        {pos: [4, 2, 3], state: "minecraft:smooth_sandstone"},
        {pos: [4, 2, 4], state: "minecraft:smooth_sandstone"},
        {pos: [4, 2, 5], state: "minecraft:smooth_sandstone"},
        {pos: [4, 2, 6], state: "minecraft:smooth_sandstone"},
        {pos: [5, 2, 3], state: "minecraft:smooth_sandstone"},
        {pos: [5, 2, 4], state: "minecraft:smooth_sandstone"},
        {pos: [5, 2, 5], state: "minecraft:smooth_sandstone"},
        {pos: [5, 2, 6], state: "minecraft:smooth_sandstone"},
        {pos: [6, 2, 3], state: "minecraft:cut_sandstone"},
        {pos: [6, 2, 4], state: "minecraft:smooth_sandstone"},
        {pos: [6, 2, 5], state: "minecraft:smooth_sandstone"},
        {pos: [6, 2, 6], state: "minecraft:cut_sandstone"},
        {pos: [1, 3, 0], state: "minecraft:cut_sandstone"},
        {pos: [1, 3, 2], state: "minecraft:cut_sandstone"},
        {pos: [1, 3, 6], state: "minecraft:cut_sandstone"},
        {pos: [2, 3, 0], state: "minecraft:smooth_sandstone"},
        {pos: [3, 3, 0], state: "minecraft:smooth_sandstone"},
        {pos: [3, 3, 3], state: "minecraft:cut_sandstone"},
        {pos: [3, 3, 5], state: "minecraft:smooth_sandstone"},
        {pos: [3, 3, 6], state: "minecraft:cut_sandstone"},
        {pos: [4, 3, 0], state: "minecraft:cut_sandstone"},
        {pos: [4, 3, 1], state: "minecraft:smooth_sandstone"},
        {pos: [4, 3, 2], state: "minecraft:cut_sandstone"},
        {pos: [4, 3, 6], state: "minecraft:smooth_sandstone"},
        {pos: [5, 3, 6], state: "minecraft:smooth_sandstone"},
        {pos: [6, 3, 3], state: "minecraft:cut_sandstone"},
        {pos: [6, 3, 4], state: "minecraft:smooth_sandstone"},
        {pos: [6, 3, 5], state: "minecraft:smooth_sandstone"},
        {pos: [6, 3, 6], state: "minecraft:cut_sandstone"},
        {pos: [1, 4, 0], state: "minecraft:cut_sandstone"},
        {pos: [1, 4, 1], state: "minecraft:smooth_sandstone"},
        {pos: [1, 4, 2], state: "minecraft:cut_sandstone"},
        {pos: [2, 4, 0], state: "minecraft:smooth_sandstone"},
        {pos: [3, 4, 0], state: "minecraft:smooth_sandstone"},
        {pos: [3, 4, 3], state: "minecraft:cut_sandstone"},
        {pos: [3, 4, 5], state: "minecraft:smooth_sandstone"},
        {pos: [3, 4, 6], state: "minecraft:cut_sandstone"},
        {pos: [4, 4, 0], state: "minecraft:cut_sandstone"},
        {pos: [4, 4, 1], state: "minecraft:smooth_sandstone"},
        {pos: [4, 4, 2], state: "minecraft:cut_sandstone"},
        {pos: [4, 4, 6], state: "minecraft:smooth_sandstone"},
        {pos: [5, 4, 6], state: "minecraft:smooth_sandstone"},
        {pos: [6, 4, 3], state: "minecraft:cut_sandstone"},
        {pos: [6, 4, 4], state: "minecraft:smooth_sandstone"},
        {pos: [6, 4, 5], state: "minecraft:smooth_sandstone"},
        {pos: [6, 4, 6], state: "minecraft:cut_sandstone"},
        {pos: [1, 5, 0], state: "minecraft:cut_sandstone"},
        {pos: [1, 5, 2], state: "minecraft:cut_sandstone"},
        {pos: [3, 5, 3], state: "minecraft:cut_sandstone"},
        {pos: [3, 5, 4], state: "minecraft:smooth_sandstone"},
        {pos: [3, 5, 5], state: "minecraft:smooth_sandstone"},
        {pos: [3, 5, 6], state: "minecraft:cut_sandstone"},
        {pos: [4, 5, 0], state: "minecraft:cut_sandstone"},
        {pos: [4, 5, 2], state: "minecraft:cut_sandstone"},
        {pos: [4, 5, 3], state: "minecraft:smooth_sandstone"},
        {pos: [4, 5, 6], state: "minecraft:smooth_sandstone"},
        {pos: [5, 5, 3], state: "minecraft:smooth_sandstone"},
        {pos: [5, 5, 6], state: "minecraft:smooth_sandstone"},
        {pos: [6, 5, 3], state: "minecraft:cut_sandstone"},
        {pos: [6, 5, 4], state: "minecraft:smooth_sandstone"},
        {pos: [6, 5, 5], state: "minecraft:smooth_sandstone"},
        {pos: [6, 5, 6], state: "minecraft:cut_sandstone"},
        {pos: [3, 6, 3], state: "minecraft:cut_sandstone"},
        {pos: [3, 6, 6], state: "minecraft:cut_sandstone"},
        {pos: [6, 6, 3], state: "minecraft:cut_sandstone"},
        {pos: [6, 6, 6], state: "minecraft:cut_sandstone"},
        {pos: [0, 0, 0], state: "minecraft:potted_cactus"},
        {pos: [0, 0, 4], state: "minecraft:smooth_sandstone_stairs{half:bottom,waterlogged:false,shape:straight,facing:north}"},
        {pos: [0, 0, 6], state: "minecraft:air"},
        {pos: [1, 0, 1], state: "minecraft:air"},
        {pos: [2, 0, 1], state: "minecraft:air"},
        {pos: [2, 0, 4], state: "minecraft:air"},
        {pos: [3, 0, 1], state: "minecraft:air"},
        {pos: [3, 0, 3], state: "minecraft:air"},
        {pos: [3, 0, 4], state: "minecraft:air"},
        {pos: [3, 0, 5], state: "minecraft:air"},
        {pos: [4, 0, 4], state: "minecraft:air"},
        {pos: [4, 0, 5], state: "minecraft:air"},
        {pos: [5, 0, 4], state: "minecraft:air"},
        {pos: [5, 0, 5], state: "minecraft:air"},
        {pos: [6, 0, 0], state: "minecraft:smooth_sandstone_stairs{half:bottom,waterlogged:false,shape:straight,facing:west}"},
        {pos: [6, 0, 1], state: "minecraft:smooth_sandstone_slab{waterlogged:false,type:bottom}"},
        {pos: [6, 0, 2], state: "minecraft:smooth_sandstone_slab{waterlogged:false,type:bottom}"},
        {pos: [0, 1, 0], state: "minecraft:air"},
        {pos: [0, 1, 3], state: "minecraft:smooth_sandstone_stairs{half:bottom,waterlogged:false,shape:straight,facing:north}"},
        {pos: [0, 1, 4], state: "minecraft:air"},
        {pos: [0, 1, 5], state: "minecraft:air"},
        {pos: [0, 1, 6], state: "minecraft:air"},
        {pos: [2, 1, 4], state: "minecraft:wall_torch{facing:south}"},
        {pos: [3, 1, 3], state: "minecraft:air"},
        {pos: [3, 1, 4], state: "minecraft:air"},
        {pos: [3, 1, 5], state: "minecraft:air"},
        {pos: [4, 1, 4], state: "minecraft:air"},
        {pos: [4, 1, 5], state: "minecraft:air"},
        {pos: [5, 1, 0], state: "minecraft:air"},
        {pos: [5, 1, 1], state: "minecraft:smooth_sandstone_stairs{half:bottom,waterlogged:false,shape:straight,facing:south}"},
        {pos: [5, 1, 4], state: "minecraft:air"},
        {pos: [5, 1, 5], state: "minecraft:air"},
        {pos: [6, 1, 0], state: "minecraft:air"},
        {pos: [6, 1, 1], state: "minecraft:air"},
        {pos: [6, 1, 2], state: "minecraft:air"},
        {pos: [0, 2, 0], state: "minecraft:air"},
        {pos: [0, 2, 1], state: "minecraft:air"},
        {pos: [0, 2, 2], state: "minecraft:air"},
        {pos: [0, 2, 3], state: "minecraft:air"},
        {pos: [0, 2, 4], state: "minecraft:air"},
        {pos: [0, 2, 5], state: "minecraft:air"},
        {pos: [0, 2, 6], state: "minecraft:air"},
        {pos: [1, 2, 1], state: "minecraft:jungle_door{hinge:right,half:lower,powered:false,facing:west,open:false}"},
        {pos: [2, 2, 1], state: "minecraft:air"},
        {pos: [2, 2, 2], state: "minecraft:air"},
        {pos: [2, 2, 3], state: "minecraft:smooth_sandstone_stairs{half:bottom,waterlogged:false,shape:straight,facing:south}"},
        {pos: [3, 2, 1], state: "minecraft:air"},
        {pos: [5, 2, 0], state: "minecraft:air"},
        {pos: [5, 2, 1], state: "minecraft:air"},
        {pos: [5, 2, 2], state: "minecraft:smooth_sandstone_stairs{half:bottom,waterlogged:false,shape:straight,facing:south}"},
        {pos: [6, 2, 0], state: "minecraft:air"},
        {pos: [6, 2, 1], state: "minecraft:air"},
        {pos: [6, 2, 2], state: "minecraft:air"},
        {pos: [0, 3, 0], state: "minecraft:air"},
        {pos: [0, 3, 1], state: "minecraft:air"},
        {pos: [0, 3, 2], state: "minecraft:air"},
        {pos: [0, 3, 3], state: "minecraft:air"},
        {pos: [0, 3, 4], state: "minecraft:air"},
        {pos: [0, 3, 5], state: "minecraft:air"},
        {pos: [0, 3, 6], state: "minecraft:air"},
        {pos: [1, 3, 1], state: "minecraft:jungle_door{hinge:right,half:upper,powered:false,facing:west,open:false}"},
        {pos: [1, 3, 3], state: "minecraft:smooth_sandstone_slab{waterlogged:false,type:bottom}"},
        {pos: [1, 3, 4], state: "minecraft:smooth_sandstone_slab{waterlogged:false,type:bottom}"},
        {pos: [1, 3, 5], state: "minecraft:smooth_sandstone_slab{waterlogged:false,type:bottom}"},
        {pos: [2, 3, 1], state: "minecraft:air"},
        {pos: [2, 3, 2], state: "minecraft:air"},
        {pos: [2, 3, 3], state: "minecraft:air"},
        {pos: [2, 3, 4], state: "minecraft:air"},
        {pos: [2, 3, 5], state: "minecraft:potted_cactus"},
        {pos: [2, 3, 6], state: "minecraft:smooth_sandstone_slab{waterlogged:false,type:bottom}"},
        {pos: [3, 3, 1], state: "minecraft:air"},
        {pos: [3, 3, 2], state: "minecraft:wall_torch{facing:north}"},
        {pos: [3, 3, 4], state: "minecraft:jungle_door{hinge:left,half:lower,powered:false,facing:west,open:false}"},
        {pos: [4, 3, 3], state: "minecraft:air"},
        {pos: [4, 3, 4], state: "minecraft:air"},
        {pos: [4, 3, 5], state: "minecraft:air"},
        {pos: [5, 3, 0], state: "minecraft:air"},
        {pos: [5, 3, 1], state: "minecraft:air"},
        {pos: [5, 3, 2], state: "minecraft:air"},
        {pos: [5, 3, 3], state: "minecraft:air"},
        {pos: [5, 3, 4], state: "minecraft:air"},
        {pos: [5, 3, 5], state: "minecraft:air"},
        {pos: [6, 3, 0], state: "minecraft:air"},
        {pos: [6, 3, 1], state: "minecraft:air"},
        {pos: [6, 3, 2], state: "minecraft:air"},
        {pos: [0, 4, 0], state: "minecraft:air"},
        {pos: [0, 4, 1], state: "minecraft:air"},
        {pos: [0, 4, 2], state: "minecraft:air"},
        {pos: [0, 4, 3], state: "minecraft:air"},
        {pos: [0, 4, 4], state: "minecraft:air"},
        {pos: [0, 4, 5], state: "minecraft:air"},
        {pos: [0, 4, 6], state: "minecraft:air"},
        {pos: [1, 4, 3], state: "minecraft:air"},
        {pos: [1, 4, 4], state: "minecraft:air"},
        {pos: [1, 4, 5], state: "minecraft:air"},
        {pos: [1, 4, 6], state: "minecraft:air"},
        {pos: [2, 4, 1], state: "minecraft:air"},
        {pos: [2, 4, 2], state: "minecraft:air"},
        {pos: [2, 4, 3], state: "minecraft:air"},
        {pos: [2, 4, 4], state: "minecraft:air"},
        {pos: [2, 4, 5], state: "minecraft:air"},
        {pos: [2, 4, 6], state: "minecraft:air"},
        {pos: [3, 4, 1], state: "minecraft:air"},
        {pos: [3, 4, 2], state: "minecraft:air"},
        {pos: [3, 4, 4], state: "minecraft:jungle_door{hinge:left,half:upper,powered:false,facing:west,open:false}"},
        {pos: [4, 4, 3], state: "minecraft:air"},
        {pos: [4, 4, 4], state: "minecraft:air"},
        {pos: [4, 4, 5], state: "minecraft:air"},
        {pos: [5, 4, 0], state: "minecraft:air"},
        {pos: [5, 4, 1], state: "minecraft:air"},
        {pos: [5, 4, 2], state: "minecraft:air"},
        {pos: [5, 4, 3], state: "minecraft:air"},
        {pos: [5, 4, 4], state: "minecraft:air"},
        {pos: [5, 4, 5], state: "minecraft:air"},
        {pos: [6, 4, 0], state: "minecraft:air"},
        {pos: [6, 4, 1], state: "minecraft:air"},
        {pos: [6, 4, 2], state: "minecraft:air"},
        {pos: [0, 5, 0], state: "minecraft:air"},
        {pos: [0, 5, 1], state: "minecraft:air"},
        {pos: [0, 5, 2], state: "minecraft:air"},
        {pos: [0, 5, 3], state: "minecraft:air"},
        {pos: [0, 5, 4], state: "minecraft:air"},
        {pos: [0, 5, 5], state: "minecraft:air"},
        {pos: [0, 5, 6], state: "minecraft:air"},
        {pos: [1, 5, 1], state: "minecraft:smooth_sandstone_slab{waterlogged:false,type:bottom}"},
        {pos: [1, 5, 3], state: "minecraft:air"},
        {pos: [1, 5, 4], state: "minecraft:air"},
        {pos: [1, 5, 5], state: "minecraft:air"},
        {pos: [1, 5, 6], state: "minecraft:air"},
        {pos: [2, 5, 0], state: "minecraft:smooth_sandstone_slab{waterlogged:false,type:bottom}"},
        {pos: [2, 5, 1], state: "minecraft:smooth_sandstone_slab{waterlogged:false,type:bottom}"},
        {pos: [2, 5, 2], state: "minecraft:smooth_sandstone_slab{waterlogged:false,type:bottom}"},
        {pos: [2, 5, 3], state: "minecraft:air"},
        {pos: [2, 5, 4], state: "minecraft:air"},
        {pos: [2, 5, 5], state: "minecraft:air"},
        {pos: [2, 5, 6], state: "minecraft:air"},
        {pos: [3, 5, 0], state: "minecraft:smooth_sandstone_slab{waterlogged:false,type:bottom}"},
        {pos: [3, 5, 1], state: "minecraft:smooth_sandstone_slab{waterlogged:false,type:bottom}"},
        {pos: [3, 5, 2], state: "minecraft:smooth_sandstone_slab{waterlogged:false,type:bottom}"},
        {pos: [4, 5, 1], state: "minecraft:smooth_sandstone_slab{waterlogged:false,type:bottom}"},
        {pos: [4, 5, 4], state: "minecraft:air"},
        {pos: [4, 5, 5], state: "minecraft:air"},
        {pos: [5, 5, 0], state: "minecraft:air"},
        {pos: [5, 5, 1], state: "minecraft:air"},
        {pos: [5, 5, 2], state: "minecraft:air"},
        {pos: [5, 5, 4], state: "minecraft:wall_torch{facing:south}"},
        {pos: [5, 5, 5], state: "minecraft:air"},
        {pos: [6, 5, 0], state: "minecraft:air"},
        {pos: [6, 5, 1], state: "minecraft:air"},
        {pos: [6, 5, 2], state: "minecraft:air"},
        {pos: [0, 6, 0], state: "minecraft:air"},
        {pos: [0, 6, 1], state: "minecraft:air"},
        {pos: [0, 6, 2], state: "minecraft:air"},
        {pos: [0, 6, 3], state: "minecraft:air"},
        {pos: [0, 6, 4], state: "minecraft:air"},
        {pos: [0, 6, 5], state: "minecraft:air"},
        {pos: [0, 6, 6], state: "minecraft:air"},
        {pos: [1, 6, 0], state: "minecraft:air"},
        {pos: [1, 6, 1], state: "minecraft:air"},
        {pos: [1, 6, 2], state: "minecraft:air"},
        {pos: [1, 6, 3], state: "minecraft:air"},
        {pos: [1, 6, 4], state: "minecraft:air"},
        {pos: [1, 6, 5], state: "minecraft:air"},
        {pos: [1, 6, 6], state: "minecraft:air"},
        {pos: [2, 6, 0], state: "minecraft:air"},
        {pos: [2, 6, 1], state: "minecraft:air"},
        {pos: [2, 6, 2], state: "minecraft:air"},
        {pos: [2, 6, 3], state: "minecraft:air"},
        {pos: [2, 6, 4], state: "minecraft:air"},
        {pos: [2, 6, 5], state: "minecraft:air"},
        {pos: [2, 6, 6], state: "minecraft:air"},
        {pos: [3, 6, 0], state: "minecraft:air"},
        {pos: [3, 6, 1], state: "minecraft:air"},
        {pos: [3, 6, 2], state: "minecraft:air"},
        {pos: [3, 6, 4], state: "minecraft:smooth_sandstone_slab{waterlogged:false,type:bottom}"},
        {pos: [3, 6, 5], state: "minecraft:smooth_sandstone_slab{waterlogged:false,type:bottom}"},
        {pos: [4, 6, 0], state: "minecraft:air"},
        {pos: [4, 6, 1], state: "minecraft:air"},
        {pos: [4, 6, 2], state: "minecraft:air"},
        {pos: [4, 6, 3], state: "minecraft:smooth_sandstone_slab{waterlogged:false,type:bottom}"},
        {pos: [4, 6, 4], state: "minecraft:smooth_sandstone_slab{waterlogged:false,type:bottom}"},
        {pos: [4, 6, 5], state: "minecraft:smooth_sandstone_slab{waterlogged:false,type:bottom}"},
        {pos: [4, 6, 6], state: "minecraft:smooth_sandstone_slab{waterlogged:false,type:bottom}"},
        {pos: [5, 6, 0], state: "minecraft:air"},
        {pos: [5, 6, 1], state: "minecraft:air"},
        {pos: [5, 6, 2], state: "minecraft:air"},
        {pos: [5, 6, 3], state: "minecraft:smooth_sandstone_slab{waterlogged:false,type:bottom}"},
        {pos: [5, 6, 4], state: "minecraft:smooth_sandstone_slab{waterlogged:false,type:bottom}"},
        {pos: [5, 6, 5], state: "minecraft:smooth_sandstone_slab{waterlogged:false,type:bottom}"},
        {pos: [5, 6, 6], state: "minecraft:smooth_sandstone_slab{waterlogged:false,type:bottom}"},
        {pos: [6, 6, 0], state: "minecraft:air"},
        {pos: [6, 6, 1], state: "minecraft:air"},
        {pos: [6, 6, 2], state: "minecraft:air"},
        {pos: [6, 6, 4], state: "minecraft:smooth_sandstone_slab{waterlogged:false,type:bottom}"},
        {pos: [6, 6, 5], state: "minecraft:smooth_sandstone_slab{waterlogged:false,type:bottom}"},
        {pos: [0, 0, 5], state: "minecraft:jigsaw{orientation:west_up}", nbt: {final_state: "minecraft:structure_void", id: "minecraft:jigsaw", joint: "aligned", name: "minecraft:building_entrance", pool: "minecraft:empty", target: "minecraft:building_entrance"}},
        {pos: [5, 0, 0], state: "minecraft:jigsaw{orientation:up_north}", nbt: {final_state: "minecraft:smooth_sandstone", id: "minecraft:jigsaw", joint: "rollable", name: "minecraft:bottom", pool: "minecraft:village/common/cats", target: "minecraft:bottom"}}
    ],
    entities: [],
    palette: [
        "minecraft:smooth_sandstone",
        "minecraft:cut_sandstone",
        "minecraft:cartography_table",
        "minecraft:potted_cactus",
        "minecraft:smooth_sandstone_stairs{half:bottom,waterlogged:false,shape:straight,facing:north}",
        "minecraft:air",
        "minecraft:smooth_sandstone_stairs{half:bottom,waterlogged:false,shape:straight,facing:west}",
        "minecraft:smooth_sandstone_slab{waterlogged:false,type:bottom}",
        "minecraft:wall_torch{facing:south}",
        "minecraft:smooth_sandstone_stairs{half:bottom,waterlogged:false,shape:straight,facing:south}",
        "minecraft:jungle_door{hinge:right,half:lower,powered:false,facing:west,open:false}",
        "minecraft:jungle_door{hinge:right,half:upper,powered:false,facing:west,open:false}",
        "minecraft:wall_torch{facing:north}",
        "minecraft:jungle_door{hinge:left,half:lower,powered:false,facing:west,open:false}",
        "minecraft:jungle_door{hinge:left,half:upper,powered:false,facing:west,open:false}",
        "minecraft:jigsaw{orientation:west_up}",
        "minecraft:jigsaw{orientation:up_north}"
    ]
}