{
    size: [6, 18, 5],
    data: [
        {pos: [0, 0, 0], state: "minecraft:sand"},
        {pos: [0, 0, 1], state: "minecraft:sand"},
        {pos: [0, 0, 2], state: "minecraft:smooth_sandstone"},
        {pos: [0, 0, 3], state: "minecraft:sand"},
        {pos: [0, 0, 4], state: "minecraft:sand"},
        {pos: [1, 0, 0], state: "minecraft:sand"},
        {pos: [1, 0, 1], state: "minecraft:sand"},
        {pos: [1, 0, 2], state: "minecraft:smooth_sandstone"},
        {pos: [1, 0, 3], state: "minecraft:sand"},
        {pos: [1, 0, 4], state: "minecraft:sand"},
        {pos: [2, 0, 0], state: "minecraft:sand"},
        {pos: [2, 0, 1], state: "minecraft:smooth_sandstone"},
        {pos: [2, 0, 2], state: "minecraft:smooth_sandstone"},
        {pos: [2, 0, 4], state: "minecraft:sand"},
        {pos: [3, 0, 0], state: "minecraft:sand"},
        {pos: [3, 0, 1], state: "minecraft:smooth_sandstone"},
        {pos: [3, 0, 2], state: "minecraft:smooth_sandstone"},
        {pos: [3, 0, 3], state: "minecraft:smooth_sandstone"},
        {pos: [3, 0, 4], state: "minecraft:sand"},
        {pos: [4, 0, 0], state: "minecraft:sand"},
        {pos: [4, 0, 1], state: "minecraft:sand"},
        {pos: [4, 0, 2], state: "minecraft:sand"},
        {pos: [4, 0, 3], state: "minecraft:sand"},
        {pos: [4, 0, 4], state: "minecraft:sand"},
        {pos: [5, 0, 0], state: "minecraft:sand"},
        {pos: [5, 0, 1], state: "minecraft:sand"},
        {pos: [5, 0, 2], state: "minecraft:sand"},
        {pos: [5, 0, 3], state: "minecraft:sand"},
        {pos: [5, 0, 4], state: "minecraft:sand"},
        {pos: [1, 1, 0], state: "minecraft:cut_sandstone"},
        {pos: [1, 1, 1], state: "minecraft:smooth_sandstone"},
        {pos: [1, 1, 3], state: "minecraft:smooth_sandstone"},
        {pos: [1, 1, 4], state: "minecraft:cut_sandstone"},
        {pos: [2, 1, 0], state: "minecraft:smooth_sandstone"},
        {pos: [2, 1, 4], state: "minecraft:smooth_sandstone"},
        {pos: [3, 1, 0], state: "minecraft:smooth_sandstone"},
        {pos: [3, 1, 4], state: "minecraft:smooth_sandstone"},
        {pos: [4, 1, 0], state: "minecraft:smooth_sandstone"},
        {pos: [4, 1, 1], state: "minecraft:smooth_sandstone"},
        {pos: [4, 1, 2], state: "minecraft:smooth_sandstone"},
        {pos: [4, 1, 3], state: "minecraft:smooth_sandstone"},
        {pos: [4, 1, 4], state: "minecraft:smooth_sandstone"},
        {pos: [5, 1, 0], state: "minecraft:cut_sandstone"},
        {pos: [5, 1, 1], state: "minecraft:smooth_sandstone"},
        {pos: [5, 1, 2], state: "minecraft:smooth_sandstone"},
        {pos: [5, 1, 3], state: "minecraft:smooth_sandstone"},
        {pos: [5, 1, 4], state: "minecraft:cut_sandstone"},
        {pos: [1, 2, 0], state: "minecraft:cut_sandstone"},
        {pos: [1, 2, 1], state: "minecraft:smooth_sandstone"},
        {pos: [1, 2, 3], state: "minecraft:smooth_sandstone"},
        {pos: [1, 2, 4], state: "minecraft:cut_sandstone"},
        {pos: [2, 2, 0], state: "minecraft:smooth_sandstone"},
        {pos: [2, 2, 4], state: "minecraft:smooth_sandstone"},
        {pos: [3, 2, 0], state: "minecraft:smooth_sandstone"},
        {pos: [3, 2, 4], state: "minecraft:smooth_sandstone"},
        {pos: [4, 2, 0], state: "minecraft:smooth_sandstone"},
        {pos: [4, 2, 3], state: "minecraft:smooth_sandstone"},
        {pos: [4, 2, 4], state: "minecraft:smooth_sandstone"},
        {pos: [5, 2, 0], state: "minecraft:cut_sandstone"},
        {pos: [5, 2, 1], state: "minecraft:smooth_sandstone"},
        {pos: [5, 2, 2], state: "minecraft:smooth_sandstone"},
        {pos: [5, 2, 3], state: "minecraft:smooth_sandstone"},
        {pos: [5, 2, 4], state: "minecraft:cut_sandstone"},
        {pos: [1, 3, 0], state: "minecraft:cut_sandstone"},
        {pos: [1, 3, 1], state: "minecraft:smooth_sandstone"},
        {pos: [1, 3, 2], state: "minecraft:cut_sandstone"},
        {pos: [1, 3, 3], state: "minecraft:smooth_sandstone"},
        {pos: [1, 3, 4], state: "minecraft:cut_sandstone"},
        {pos: [2, 3, 0], state: "minecraft:smooth_sandstone"},
        {pos: [2, 3, 3], state: "minecraft:smooth_sandstone"},
        {pos: [2, 3, 4], state: "minecraft:smooth_sandstone"},
        {pos: [3, 3, 0], state: "minecraft:smooth_sandstone"},
        {pos: [3, 3, 4], state: "minecraft:smooth_sandstone"},
        {pos: [4, 3, 0], state: "minecraft:smooth_sandstone"},
        {pos: [4, 3, 4], state: "minecraft:smooth_sandstone"},
        {pos: [5, 3, 0], state: "minecraft:cut_sandstone"},
        {pos: [5, 3, 1], state: "minecraft:smooth_sandstone"},
        {pos: [5, 3, 2], state: "minecraft:smooth_sandstone"},
        {pos: [5, 3, 3], state: "minecraft:smooth_sandstone"},
        {pos: [5, 3, 4], state: "minecraft:cut_sandstone"},
        {pos: [1, 4, 0], state: "minecraft:cut_sandstone"},
        {pos: [1, 4, 1], state: "minecraft:smooth_sandstone"},
        {pos: [1, 4, 2], state: "minecraft:smooth_sandstone"},
        {pos: [1, 4, 3], state: "minecraft:smooth_sandstone"},
        {pos: [1, 4, 4], state: "minecraft:cut_sandstone"},
        {pos: [2, 4, 0], state: "minecraft:smooth_sandstone"},
        {pos: [2, 4, 1], state: "minecraft:smooth_sandstone"},
        {pos: [2, 4, 4], state: "minecraft:smooth_sandstone"},
        {pos: [3, 4, 0], state: "minecraft:smooth_sandstone"},
        {pos: [3, 4, 4], state: "minecraft:smooth_sandstone"},
        {pos: [4, 4, 0], state: "minecraft:smooth_sandstone"},
        {pos: [4, 4, 4], state: "minecraft:smooth_sandstone"},
        {pos: [5, 4, 0], state: "minecraft:cut_sandstone"},
        {pos: [5, 4, 1], state: "minecraft:smooth_sandstone"},
        {pos: [5, 4, 2], state: "minecraft:smooth_sandstone"},
        {pos: [5, 4, 3], state: "minecraft:smooth_sandstone"},
        {pos: [5, 4, 4], state: "minecraft:cut_sandstone"},
        {pos: [1, 5, 0], state: "minecraft:cut_sandstone"},
        {pos: [1, 5, 1], state: "minecraft:smooth_sandstone"},
        {pos: [1, 5, 3], state: "minecraft:smooth_sandstone"},
        {pos: [1, 5, 4], state: "minecraft:cut_sandstone"},
        {pos: [2, 5, 0], state: "minecraft:smooth_sandstone"},
        {pos: [2, 5, 4], state: "minecraft:smooth_sandstone"},
        {pos: [3, 5, 0], state: "minecraft:smooth_sandstone"},
        {pos: [3, 5, 2], state: "minecraft:smooth_sandstone"},
        {pos: [3, 5, 4], state: "minecraft:smooth_sandstone"},
        {pos: [4, 5, 0], state: "minecraft:smooth_sandstone"},
        {pos: [4, 5, 1], state: "minecraft:smooth_sandstone"},
        {pos: [4, 5, 4], state: "minecraft:smooth_sandstone"},
        {pos: [5, 5, 0], state: "minecraft:cut_sandstone"},
        {pos: [5, 5, 1], state: "minecraft:smooth_sandstone"},
        {pos: [5, 5, 2], state: "minecraft:smooth_sandstone"},
        {pos: [5, 5, 3], state: "minecraft:smooth_sandstone"},
        {pos: [5, 5, 4], state: "minecraft:cut_sandstone"},
        {pos: [1, 6, 0], state: "minecraft:cut_sandstone"},
        {pos: [1, 6, 1], state: "minecraft:smooth_sandstone"},
        {pos: [1, 6, 2], state: "minecraft:smooth_sandstone"},
        {pos: [1, 6, 3], state: "minecraft:smooth_sandstone"},
        {pos: [1, 6, 4], state: "minecraft:cut_sandstone"},
        {pos: [2, 6, 0], state: "minecraft:smooth_sandstone"},
        {pos: [2, 6, 4], state: "minecraft:smooth_sandstone"},
        {pos: [3, 6, 0], state: "minecraft:smooth_sandstone"},
        {pos: [3, 6, 4], state: "minecraft:smooth_sandstone"},
        {pos: [4, 6, 0], state: "minecraft:smooth_sandstone"},
        {pos: [4, 6, 3], state: "minecraft:smooth_sandstone"},
        {pos: [4, 6, 4], state: "minecraft:smooth_sandstone"},
        {pos: [5, 6, 0], state: "minecraft:cut_sandstone"},
        {pos: [5, 6, 1], state: "minecraft:smooth_sandstone"},
        {pos: [5, 6, 2], state: "minecraft:smooth_sandstone"},
        {pos: [5, 6, 3], state: "minecraft:smooth_sandstone"},
        {pos: [5, 6, 4], state: "minecraft:cut_sandstone"},
        {pos: [1, 7, 0], state: "minecraft:cut_sandstone"},
        {pos: [1, 7, 1], state: "minecraft:smooth_sandstone"},
        {pos: [1, 7, 2], state: "minecraft:cut_sandstone"},
        {pos: [1, 7, 3], state: "minecraft:smooth_sandstone"},
        {pos: [1, 7, 4], state: "minecraft:cut_sandstone"},
        {pos: [2, 7, 0], state: "minecraft:smooth_sandstone"},
        {pos: [2, 7, 3], state: "minecraft:smooth_sandstone"},
        {pos: [2, 7, 4], state: "minecraft:smooth_sandstone"},
        {pos: [3, 7, 0], state: "minecraft:smooth_sandstone"},
        {pos: [3, 7, 4], state: "minecraft:smooth_sandstone"},
        {pos: [4, 7, 0], state: "minecraft:smooth_sandstone"},
        {pos: [4, 7, 4], state: "minecraft:smooth_sandstone"},
        {pos: [5, 7, 0], state: "minecraft:cut_sandstone"},
        {pos: [5, 7, 1], state: "minecraft:smooth_sandstone"},
        {pos: [5, 7, 2], state: "minecraft:smooth_sandstone"},
        {pos: [5, 7, 3], state: "minecraft:smooth_sandstone"},
        {pos: [5, 7, 4], state: "minecraft:cut_sandstone"},
        {pos: [1, 8, 0], state: "minecraft:cut_sandstone"},
        {pos: [1, 8, 1], state: "minecraft:smooth_sandstone"},
        {pos: [1, 8, 2], state: "minecraft:smooth_sandstone"},
        {pos: [1, 8, 3], state: "minecraft:smooth_sandstone"},
        {pos: [1, 8, 4], state: "minecraft:cut_sandstone"},
        {pos: [2, 8, 0], state: "minecraft:smooth_sandstone"},
        {pos: [2, 8, 1], state: "minecraft:smooth_sandstone"},
        {pos: [2, 8, 4], state: "minecraft:smooth_sandstone"},
        {pos: [3, 8, 0], state: "minecraft:smooth_sandstone"},
        {pos: [3, 8, 4], state: "minecraft:smooth_sandstone"},
        {pos: [4, 8, 0], state: "minecraft:smooth_sandstone"},
        {pos: [4, 8, 4], state: "minecraft:smooth_sandstone"},
        {pos: [5, 8, 0], state: "minecraft:cut_sandstone"},
        {pos: [5, 8, 1], state: "minecraft:smooth_sandstone"},
        {pos: [5, 8, 2], state: "minecraft:smooth_sandstone"},
        {pos: [5, 8, 3], state: "minecraft:smooth_sandstone"},
        {pos: [5, 8, 4], state: "minecraft:cut_sandstone"},
        {pos: [1, 9, 0], state: "minecraft:cut_sandstone"},
        {pos: [1, 9, 1], state: "minecraft:smooth_sandstone"},
        {pos: [1, 9, 3], state: "minecraft:smooth_sandstone"},
        {pos: [1, 9, 4], state: "minecraft:cut_sandstone"},
        {pos: [2, 9, 0], state: "minecraft:smooth_sandstone"},
        {pos: [2, 9, 4], state: "minecraft:smooth_sandstone"},
        {pos: [3, 9, 0], state: "minecraft:smooth_sandstone"},
        {pos: [3, 9, 4], state: "minecraft:smooth_sandstone"},
        {pos: [4, 9, 0], state: "minecraft:smooth_sandstone"},
        {pos: [4, 9, 1], state: "minecraft:smooth_sandstone"},
        {pos: [4, 9, 4], state: "minecraft:smooth_sandstone"},
        {pos: [5, 9, 0], state: "minecraft:cut_sandstone"},
        {pos: [5, 9, 1], state: "minecraft:smooth_sandstone"},
        {pos: [5, 9, 2], state: "minecraft:smooth_sandstone"},
        {pos: [5, 9, 3], state: "minecraft:smooth_sandstone"},
        {pos: [5, 9, 4], state: "minecraft:cut_sandstone"},
        {pos: [1, 10, 0], state: "minecraft:cut_sandstone"},
        {pos: [1, 10, 1], state: "minecraft:smooth_sandstone"},
        {pos: [1, 10, 2], state: "minecraft:smooth_sandstone"},
        {pos: [1, 10, 3], state: "minecraft:smooth_sandstone"},
        {pos: [1, 10, 4], state: "minecraft:cut_sandstone"},
        {pos: [2, 10, 0], state: "minecraft:smooth_sandstone"},
        {pos: [2, 10, 4], state: "minecraft:smooth_sandstone"},
        {pos: [3, 10, 0], state: "minecraft:smooth_sandstone"},
        {pos: [3, 10, 4], state: "minecraft:smooth_sandstone"},
        {pos: [4, 10, 0], state: "minecraft:smooth_sandstone"},
        {pos: [4, 10, 3], state: "minecraft:smooth_sandstone"},
        {pos: [4, 10, 4], state: "minecraft:smooth_sandstone"},
        {pos: [5, 10, 0], state: "minecraft:cut_sandstone"},
        {pos: [5, 10, 1], state: "minecraft:smooth_sandstone"},
        {pos: [5, 10, 2], state: "minecraft:smooth_sandstone"},
        {pos: [5, 10, 3], state: "minecraft:smooth_sandstone"},
        {pos: [5, 10, 4], state: "minecraft:cut_sandstone"},
        {pos: [1, 11, 0], state: "minecraft:cut_sandstone"},
        {pos: [1, 11, 1], state: "minecraft:smooth_sandstone"},
        {pos: [1, 11, 2], state: "minecraft:cut_sandstone"},
        {pos: [1, 11, 3], state: "minecraft:smooth_sandstone"},
        {pos: [1, 11, 4], state: "minecraft:cut_sandstone"},
        {pos: [2, 11, 0], state: "minecraft:smooth_sandstone"},
        {pos: [2, 11, 3], state: "minecraft:smooth_sandstone"},
        {pos: [2, 11, 4], state: "minecraft:smooth_sandstone"},
        {pos: [3, 11, 0], state: "minecraft:smooth_sandstone"},
        {pos: [3, 11, 4], state: "minecraft:smooth_sandstone"},
        {pos: [4, 11, 0], state: "minecraft:smooth_sandstone"},
        {pos: [4, 11, 4], state: "minecraft:smooth_sandstone"},
        {pos: [5, 11, 0], state: "minecraft:cut_sandstone"},
        {pos: [5, 11, 1], state: "minecraft:smooth_sandstone"},
        {pos: [5, 11, 2], state: "minecraft:smooth_sandstone"},
        {pos: [5, 11, 3], state: "minecraft:smooth_sandstone"},
        {pos: [5, 11, 4], state: "minecraft:cut_sandstone"},
        {pos: [1, 12, 0], state: "minecraft:cut_sandstone"},
        {pos: [1, 12, 1], state: "minecraft:smooth_sandstone"},
        {pos: [1, 12, 2], state: "minecraft:smooth_sandstone"},
        {pos: [1, 12, 3], state: "minecraft:smooth_sandstone"},
        {pos: [1, 12, 4], state: "minecraft:cut_sandstone"},
        {pos: [2, 12, 0], state: "minecraft:smooth_sandstone"},
        {pos: [2, 12, 1], state: "minecraft:smooth_sandstone"},
        {pos: [2, 12, 4], state: "minecraft:smooth_sandstone"},
        {pos: [3, 12, 0], state: "minecraft:smooth_sandstone"},
        {pos: [3, 12, 2], state: "minecraft:smooth_sandstone"},
        {pos: [3, 12, 4], state: "minecraft:smooth_sandstone"},
        {pos: [4, 12, 0], state: "minecraft:smooth_sandstone"},
        {pos: [4, 12, 4], state: "minecraft:smooth_sandstone"},
        {pos: [5, 12, 0], state: "minecraft:cut_sandstone"},
        {pos: [5, 12, 1], state: "minecraft:smooth_sandstone"},
        {pos: [5, 12, 2], state: "minecraft:smooth_sandstone"},
        {pos: [5, 12, 3], state: "minecraft:smooth_sandstone"},
        {pos: [5, 12, 4], state: "minecraft:cut_sandstone"},
        {pos: [1, 13, 0], state: "minecraft:cut_sandstone"},
        {pos: [1, 13, 1], state: "minecraft:smooth_sandstone"},
        {pos: [1, 13, 3], state: "minecraft:smooth_sandstone"},
        {pos: [1, 13, 4], state: "minecraft:cut_sandstone"},
        {pos: [2, 13, 0], state: "minecraft:smooth_sandstone"},
        {pos: [2, 13, 4], state: "minecraft:smooth_sandstone"},
        {pos: [3, 13, 0], state: "minecraft:smooth_sandstone"},
        {pos: [3, 13, 4], state: "minecraft:smooth_sandstone"},
        {pos: [4, 13, 0], state: "minecraft:smooth_sandstone"},
        {pos: [4, 13, 1], state: "minecraft:smooth_sandstone"},
        {pos: [4, 13, 4], state: "minecraft:smooth_sandstone"},
        {pos: [5, 13, 0], state: "minecraft:cut_sandstone"},
        {pos: [5, 13, 1], state: "minecraft:smooth_sandstone"},
        {pos: [5, 13, 2], state: "minecraft:smooth_sandstone"},
        {pos: [5, 13, 3], state: "minecraft:smooth_sandstone"},
        {pos: [5, 13, 4], state: "minecraft:cut_sandstone"},
        {pos: [1, 14, 0], state: "minecraft:cut_sandstone"},
        {pos: [1, 14, 1], state: "minecraft:smooth_sandstone"},
        {pos: [1, 14, 2], state: "minecraft:smooth_sandstone"},
        {pos: [1, 14, 3], state: "minecraft:smooth_sandstone"},
        {pos: [1, 14, 4], state: "minecraft:cut_sandstone"},
        {pos: [2, 14, 0], state: "minecraft:smooth_sandstone"},
        {pos: [2, 14, 4], state: "minecraft:smooth_sandstone"},
        {pos: [3, 14, 0], state: "minecraft:smooth_sandstone"},
        {pos: [3, 14, 4], state: "minecraft:smooth_sandstone"},
        {pos: [4, 14, 0], state: "minecraft:smooth_sandstone"},
        {pos: [4, 14, 4], state: "minecraft:smooth_sandstone"},
        {pos: [5, 14, 0], state: "minecraft:cut_sandstone"},
        {pos: [5, 14, 1], state: "minecraft:smooth_sandstone"},
        {pos: [5, 14, 2], state: "minecraft:smooth_sandstone"},
        {pos: [5, 14, 3], state: "minecraft:smooth_sandstone"},
        {pos: [5, 14, 4], state: "minecraft:cut_sandstone"},
        {pos: [1, 15, 0], state: "minecraft:cut_sandstone"},
        {pos: [1, 15, 1], state: "minecraft:cut_sandstone"},
        {pos: [1, 15, 2], state: "minecraft:cut_sandstone"},
        {pos: [1, 15, 3], state: "minecraft:cut_sandstone"},
        {pos: [1, 15, 4], state: "minecraft:cut_sandstone"},
        {pos: [2, 15, 0], state: "minecraft:cut_sandstone"},
        {pos: [2, 15, 2], state: "minecraft:cut_sandstone"},
        {pos: [2, 15, 3], state: "minecraft:cut_sandstone"},
        {pos: [2, 15, 4], state: "minecraft:cut_sandstone"},
        {pos: [3, 15, 0], state: "minecraft:cut_sandstone"},
        {pos: [3, 15, 2], state: "minecraft:cut_sandstone"},
        {pos: [3, 15, 3], state: "minecraft:cut_sandstone"},
        {pos: [3, 15, 4], state: "minecraft:cut_sandstone"},
        {pos: [4, 15, 0], state: "minecraft:cut_sandstone"},
        {pos: [4, 15, 4], state: "minecraft:cut_sandstone"},
        {pos: [5, 15, 0], state: "minecraft:cut_sandstone"},
        {pos: [5, 15, 1], state: "minecraft:cut_sandstone"},
        {pos: [5, 15, 2], state: "minecraft:cut_sandstone"},
        {pos: [5, 15, 3], state: "minecraft:cut_sandstone"},
        {pos: [5, 15, 4], state: "minecraft:cut_sandstone"},
        {pos: [1, 16, 0], state: "minecraft:cut_sandstone"},
        {pos: [1, 16, 2], state: "minecraft:cut_sandstone"},
        {pos: [1, 16, 4], state: "minecraft:cut_sandstone"},
        {pos: [3, 16, 0], state: "minecraft:cut_sandstone"},
        {pos: [3, 16, 4], state: "minecraft:cut_sandstone"},
        {pos: [5, 16, 0], state: "minecraft:cut_sandstone"},
        {pos: [5, 16, 2], state: "minecraft:cut_sandstone"},
        {pos: [5, 16, 4], state: "minecraft:cut_sandstone"},
        {pos: [0, 1, 0], state: "minecraft:air"},
        {pos: [0, 1, 1], state: "minecraft:air"},
        {pos: [0, 1, 3], state: "minecraft:air"},
        {pos: [0, 1, 4], state: "minecraft:air"},
        {pos: [1, 1, 2], state: "minecraft:jungle_door{hinge:right,half:lower,powered:false,facing:west,open:false}"},
        {pos: [2, 1, 1], state: "minecraft:air"},
        {pos: [2, 1, 2], state: "minecraft:air"},
        {pos: [2, 1, 3], state: "minecraft:air"},
        {pos: [3, 1, 1], state: "minecraft:smooth_sandstone_stairs{half:bottom,waterlogged:false,shape:straight,facing:east}"},
        {pos: [0, 2, 0], state: "minecraft:air"},
        {pos: [0, 2, 1], state: "minecraft:air"},
        {pos: [0, 2, 2], state: "minecraft:air"},
        {pos: [0, 2, 3], state: "minecraft:air"},
        {pos: [0, 2, 4], state: "minecraft:air"},
        {pos: [1, 2, 2], state: "minecraft:jungle_door{hinge:right,half:upper,powered:false,facing:west,open:false}"},
        {pos: [2, 2, 1], state: "minecraft:wall_torch{facing:east}"},
        {pos: [2, 2, 2], state: "minecraft:air"},
        {pos: [2, 2, 3], state: "minecraft:air"},
        {pos: [3, 2, 1], state: "minecraft:air"},
        {pos: [3, 2, 2], state: "minecraft:air"},
        {pos: [3, 2, 3], state: "minecraft:air"},
        {pos: [4, 2, 1], state: "minecraft:air"},
        {pos: [4, 2, 2], state: "minecraft:smooth_sandstone_stairs{half:bottom,waterlogged:false,shape:straight,facing:south}"},
        {pos: [0, 3, 0], state: "minecraft:air"},
        {pos: [0, 3, 1], state: "minecraft:air"},
        {pos: [0, 3, 2], state: "minecraft:wall_torch{facing:west}"},
        {pos: [0, 3, 3], state: "minecraft:air"},
        {pos: [0, 3, 4], state: "minecraft:air"},
        {pos: [2, 3, 1], state: "minecraft:air"},
        {pos: [2, 3, 2], state: "minecraft:air"},
        {pos: [3, 3, 1], state: "minecraft:air"},
        {pos: [3, 3, 2], state: "minecraft:air"},
        {pos: [3, 3, 3], state: "minecraft:smooth_sandstone_stairs{half:bottom,waterlogged:false,shape:straight,facing:west}"},
        {pos: [4, 3, 1], state: "minecraft:air"},
        {pos: [4, 3, 2], state: "minecraft:air"},
        {pos: [4, 3, 3], state: "minecraft:air"},
        {pos: [0, 4, 0], state: "minecraft:air"},
        {pos: [0, 4, 1], state: "minecraft:air"},
        {pos: [0, 4, 2], state: "minecraft:air"},
        {pos: [0, 4, 3], state: "minecraft:air"},
        {pos: [0, 4, 4], state: "minecraft:air"},
        {pos: [2, 4, 2], state: "minecraft:smooth_sandstone_stairs{half:bottom,waterlogged:false,shape:straight,facing:north}"},
        {pos: [2, 4, 3], state: "minecraft:air"},
        {pos: [3, 4, 1], state: "minecraft:air"},
        {pos: [3, 4, 2], state: "minecraft:air"},
        {pos: [3, 4, 3], state: "minecraft:air"},
        {pos: [4, 4, 1], state: "minecraft:air"},
        {pos: [4, 4, 2], state: "minecraft:air"},
        {pos: [4, 4, 3], state: "minecraft:wall_torch{facing:west}"},
        {pos: [0, 5, 0], state: "minecraft:air"},
        {pos: [0, 5, 1], state: "minecraft:air"},
        {pos: [0, 5, 2], state: "minecraft:air"},
        {pos: [0, 5, 3], state: "minecraft:air"},
        {pos: [0, 5, 4], state: "minecraft:air"},
        {pos: [1, 5, 2], state: "minecraft:air"},
        {pos: [2, 5, 1], state: "minecraft:air"},
        {pos: [2, 5, 2], state: "minecraft:air"},
        {pos: [2, 5, 3], state: "minecraft:air"},
        {pos: [3, 5, 1], state: "minecraft:smooth_sandstone_stairs{half:bottom,waterlogged:false,shape:straight,facing:east}"},
        {pos: [3, 5, 3], state: "minecraft:air"},
        {pos: [4, 5, 2], state: "minecraft:air"},
        {pos: [4, 5, 3], state: "minecraft:air"},
        {pos: [0, 6, 0], state: "minecraft:air"},
        {pos: [0, 6, 1], state: "minecraft:air"},
        {pos: [0, 6, 2], state: "minecraft:air"},
        {pos: [0, 6, 3], state: "minecraft:air"},
        {pos: [0, 6, 4], state: "minecraft:air"},
        {pos: [2, 6, 1], state: "minecraft:air"},
        {pos: [2, 6, 2], state: "minecraft:air"},
        {pos: [2, 6, 3], state: "minecraft:air"},
        {pos: [3, 6, 1], state: "minecraft:air"},
        {pos: [3, 6, 2], state: "minecraft:air"},
        {pos: [3, 6, 3], state: "minecraft:air"},
        {pos: [4, 6, 1], state: "minecraft:air"},
        {pos: [4, 6, 2], state: "minecraft:smooth_sandstone_stairs{half:bottom,waterlogged:false,shape:straight,facing:south}"},
        {pos: [0, 7, 0], state: "minecraft:air"},
        {pos: [0, 7, 1], state: "minecraft:air"},
        {pos: [0, 7, 2], state: "minecraft:air"},
        {pos: [0, 7, 3], state: "minecraft:air"},
        {pos: [0, 7, 4], state: "minecraft:air"},
        {pos: [2, 7, 1], state: "minecraft:air"},
        {pos: [2, 7, 2], state: "minecraft:air"},
        {pos: [3, 7, 1], state: "minecraft:air"},
        {pos: [3, 7, 2], state: "minecraft:air"},
        {pos: [3, 7, 3], state: "minecraft:smooth_sandstone_stairs{half:bottom,waterlogged:false,shape:straight,facing:west}"},
        {pos: [4, 7, 1], state: "minecraft:wall_torch{facing:south}"},
        {pos: [4, 7, 2], state: "minecraft:air"},
        {pos: [4, 7, 3], state: "minecraft:air"},
        {pos: [0, 8, 0], state: "minecraft:air"},
        {pos: [0, 8, 1], state: "minecraft:air"},
        {pos: [0, 8, 2], state: "minecraft:air"},
        {pos: [0, 8, 3], state: "minecraft:air"},
        {pos: [0, 8, 4], state: "minecraft:air"},
        {pos: [2, 8, 2], state: "minecraft:smooth_sandstone_stairs{half:bottom,waterlogged:false,shape:straight,facing:north}"},
        {pos: [2, 8, 3], state: "minecraft:air"},
        {pos: [3, 8, 1], state: "minecraft:air"},
        {pos: [3, 8, 2], state: "minecraft:air"},
        {pos: [3, 8, 3], state: "minecraft:air"},
        {pos: [4, 8, 1], state: "minecraft:air"},
        {pos: [4, 8, 2], state: "minecraft:air"},
        {pos: [4, 8, 3], state: "minecraft:air"},
        {pos: [0, 9, 0], state: "minecraft:air"},
        {pos: [0, 9, 1], state: "minecraft:air"},
        {pos: [0, 9, 2], state: "minecraft:air"},
        {pos: [0, 9, 3], state: "minecraft:air"},
        {pos: [0, 9, 4], state: "minecraft:air"},
        {pos: [1, 9, 2], state: "minecraft:air"},
        {pos: [2, 9, 1], state: "minecraft:air"},
        {pos: [2, 9, 2], state: "minecraft:air"},
        {pos: [2, 9, 3], state: "minecraft:wall_torch{facing:north}"},
        {pos: [3, 9, 1], state: "minecraft:smooth_sandstone_stairs{half:bottom,waterlogged:false,shape:straight,facing:east}"},
        {pos: [3, 9, 2], state: "minecraft:air"},
        {pos: [3, 9, 3], state: "minecraft:air"},
        {pos: [4, 9, 2], state: "minecraft:air"},
        {pos: [4, 9, 3], state: "minecraft:air"},
        {pos: [0, 10, 0], state: "minecraft:air"},
        {pos: [0, 10, 1], state: "minecraft:air"},
        {pos: [0, 10, 2], state: "minecraft:air"},
        {pos: [0, 10, 3], state: "minecraft:air"},
        {pos: [0, 10, 4], state: "minecraft:air"},
        {pos: [2, 10, 1], state: "minecraft:air"},
        {pos: [2, 10, 2], state: "minecraft:air"},
        {pos: [2, 10, 3], state: "minecraft:air"},
        {pos: [3, 10, 1], state: "minecraft:air"},
        {pos: [3, 10, 2], state: "minecraft:air"},
        {pos: [3, 10, 3], state: "minecraft:air"},
        {pos: [4, 10, 1], state: "minecraft:air"},
        {pos: [4, 10, 2], state: "minecraft:smooth_sandstone_stairs{half:bottom,waterlogged:false,shape:straight,facing:south}"},
        {pos: [0, 11, 0], state: "minecraft:air"},
        {pos: [0, 11, 1], state: "minecraft:air"},
        {pos: [0, 11, 2], state: "minecraft:air"},
        {pos: [0, 11, 3], state: "minecraft:air"},
        {pos: [0, 11, 4], state: "minecraft:air"},
        {pos: [2, 11, 1], state: "minecraft:air"},
        {pos: [2, 11, 2], state: "minecraft:air"},
        {pos: [3, 11, 1], state: "minecraft:air"},
        {pos: [3, 11, 2], state: "minecraft:air"},
        {pos: [3, 11, 3], state: "minecraft:smooth_sandstone_stairs{half:bottom,waterlogged:false,shape:straight,facing:west}"},
        {pos: [4, 11, 1], state: "minecraft:air"},
        {pos: [4, 11, 2], state: "minecraft:air"},
        {pos: [4, 11, 3], state: "minecraft:air"},
        {pos: [0, 12, 0], state: "minecraft:air"},
        {pos: [0, 12, 1], state: "minecraft:air"},
        {pos: [0, 12, 2], state: "minecraft:air"},
        {pos: [0, 12, 3], state: "minecraft:air"},
        {pos: [0, 12, 4], state: "minecraft:air"},
        {pos: [2, 12, 2], state: "minecraft:smooth_sandstone_stairs{half:bottom,waterlogged:false,shape:straight,facing:north}"},
        {pos: [2, 12, 3], state: "minecraft:air"},
        {pos: [3, 12, 1], state: "minecraft:air"},
        {pos: [3, 12, 3], state: "minecraft:air"},
        {pos: [4, 12, 1], state: "minecraft:air"},
        {pos: [4, 12, 2], state: "minecraft:air"},
        {pos: [4, 12, 3], state: "minecraft:wall_torch{facing:north}"},
        {pos: [0, 13, 0], state: "minecraft:air"},
        {pos: [0, 13, 1], state: "minecraft:air"},
        {pos: [0, 13, 2], state: "minecraft:air"},
        {pos: [0, 13, 3], state: "minecraft:air"},
        {pos: [0, 13, 4], state: "minecraft:air"},
        {pos: [1, 13, 2], state: "minecraft:air"},
        {pos: [2, 13, 1], state: "minecraft:air"},
        {pos: [2, 13, 2], state: "minecraft:air"},
        {pos: [2, 13, 3], state: "minecraft:air"},
        {pos: [3, 13, 1], state: "minecraft:smooth_sandstone_stairs{half:bottom,waterlogged:false,shape:straight,facing:east}"},
        {pos: [3, 13, 3], state: "minecraft:air"},
        {pos: [4, 13, 2], state: "minecraft:air"},
        {pos: [4, 13, 3], state: "minecraft:air"},
        {pos: [0, 14, 0], state: "minecraft:air"},
        {pos: [0, 14, 1], state: "minecraft:air"},
        {pos: [0, 14, 2], state: "minecraft:air"},
        {pos: [0, 14, 3], state: "minecraft:air"},
        {pos: [0, 14, 4], state: "minecraft:air"},
        {pos: [2, 14, 1], state: "minecraft:air"},
        {pos: [2, 14, 2], state: "minecraft:air"},
        {pos: [2, 14, 3], state: "minecraft:air"},
        {pos: [3, 14, 1], state: "minecraft:air"},
        {pos: [3, 14, 2], state: "minecraft:air"},
        {pos: [3, 14, 3], state: "minecraft:air"},
        {pos: [4, 14, 1], state: "minecraft:air"},
        {pos: [4, 14, 2], state: "minecraft:smooth_sandstone_stairs{half:bottom,waterlogged:false,shape:straight,facing:south}"},
        {pos: [4, 14, 3], state: "minecraft:air"},
        {pos: [0, 15, 0], state: "minecraft:air"},
        {pos: [0, 15, 1], state: "minecraft:air"},
        {pos: [0, 15, 2], state: "minecraft:air"},
        {pos: [0, 15, 3], state: "minecraft:air"},
        {pos: [0, 15, 4], state: "minecraft:air"},
        {pos: [2, 15, 1], state: "minecraft:air"},
        {pos: [3, 15, 1], state: "minecraft:air"},
        {pos: [4, 15, 1], state: "minecraft:air"},
        {pos: [4, 15, 2], state: "minecraft:air"},
        {pos: [4, 15, 3], state: "minecraft:smooth_sandstone_stairs{half:bottom,waterlogged:false,shape:straight,facing:south}"},
        {pos: [0, 16, 0], state: "minecraft:air"},
        {pos: [0, 16, 1], state: "minecraft:air"},
        {pos: [0, 16, 2], state: "minecraft:air"},
        {pos: [0, 16, 3], state: "minecraft:air"},
        {pos: [0, 16, 4], state: "minecraft:air"},
        {pos: [1, 16, 1], state: "minecraft:air"},
        {pos: [1, 16, 3], state: "minecraft:air"},
        {pos: [2, 16, 0], state: "minecraft:air"},
        {pos: [2, 16, 1], state: "minecraft:air"},
        {pos: [2, 16, 2], state: "minecraft:air"},
        {pos: [2, 16, 3], state: "minecraft:air"},
        {pos: [2, 16, 4], state: "minecraft:air"},
        {pos: [3, 16, 1], state: "minecraft:air"},
        {pos: [3, 16, 2], state: "minecraft:air"},
        {pos: [3, 16, 3], state: "minecraft:air"},
        {pos: [4, 16, 0], state: "minecraft:air"},
        {pos: [4, 16, 1], state: "minecraft:air"},
        {pos: [4, 16, 2], state: "minecraft:air"},
        {pos: [4, 16, 3], state: "minecraft:air"},
        {pos: [4, 16, 4], state: "minecraft:air"},
        {pos: [5, 16, 1], state: "minecraft:air"},
        {pos: [5, 16, 3], state: "minecraft:air"},
        {pos: [0, 17, 0], state: "minecraft:air"},
        {pos: [0, 17, 1], state: "minecraft:air"},
        {pos: [0, 17, 2], state: "minecraft:air"},
        {pos: [0, 17, 3], state: "minecraft:air"},
        {pos: [0, 17, 4], state: "minecraft:air"},
        {pos: [1, 17, 0], state: "minecraft:torch"},
        {pos: [1, 17, 1], state: "minecraft:air"},
        {pos: [1, 17, 2], state: "minecraft:air"},
        {pos: [1, 17, 3], state: "minecraft:air"},
        {pos: [1, 17, 4], state: "minecraft:torch"},
        {pos: [2, 17, 0], state: "minecraft:air"},
        {pos: [2, 17, 1], state: "minecraft:air"},
        {pos: [2, 17, 2], state: "minecraft:air"},
        {pos: [2, 17, 3], state: "minecraft:air"},
        {pos: [2, 17, 4], state: "minecraft:air"},
        {pos: [3, 17, 0], state: "minecraft:air"},
        {pos: [3, 17, 1], state: "minecraft:air"},
        {pos: [3, 17, 2], state: "minecraft:air"},
        {pos: [3, 17, 3], state: "minecraft:air"},
        {pos: [3, 17, 4], state: "minecraft:air"},
        {pos: [4, 17, 0], state: "minecraft:air"},
        {pos: [4, 17, 1], state: "minecraft:air"},
        {pos: [4, 17, 2], state: "minecraft:air"},
        {pos: [4, 17, 3], state: "minecraft:air"},
        {pos: [4, 17, 4], state: "minecraft:air"},
        {pos: [5, 17, 0], state: "minecraft:torch"},
        {pos: [5, 17, 1], state: "minecraft:air"},
        {pos: [5, 17, 2], state: "minecraft:air"},
        {pos: [5, 17, 3], state: "minecraft:air"},
        {pos: [5, 17, 4], state: "minecraft:torch"},
        {pos: [2, 0, 3], state: "minecraft:jigsaw{orientation:up_north}", nbt: {final_state: "minecraft:smooth_sandstone", id: "minecraft:jigsaw", joint: "rollable", name: "minecraft:bottom", pool: "minecraft:village/desert/villagers", target: "minecraft:bottom"}},
        {pos: [0, 1, 2], state: "minecraft:jigsaw{orientation:west_up}", nbt: {final_state: "minecraft:air", id: "minecraft:jigsaw", joint: "aligned", name: "minecraft:building_entrance", pool: "minecraft:empty", target: "minecraft:building_entrance"}},
        {pos: [3, 1, 2], state: "minecraft:green_bed{part:foot,facing:south,occupied:false}", nbt: {id: "minecraft:bed"}},
        {pos: [3, 1, 3], state: "minecraft:green_bed{part:head,facing:south,occupied:false}", nbt: {id: "minecraft:bed"}},
        {pos: [3, 13, 2], state: "minecraft:chest{waterlogged:false,facing:west,type:single}", nbt: {LootTable: "minecraft:chests/village/village_desert_house", id: "minecraft:chest"}}
    ],
    entities: [],
    palette: [
        "minecraft:sand",
        "minecraft:smooth_sandstone",
        "minecraft:cut_sandstone",
        "minecraft:air",
        "minecraft:jungle_door{hinge:right,half:lower,powered:false,facing:west,open:false}",
        "minecraft:smooth_sandstone_stairs{half:bottom,waterlogged:false,shape:straight,facing:east}",
        "minecraft:jungle_door{hinge:right,half:upper,powered:false,facing:west,open:false}",
        "minecraft:wall_torch{facing:east}",
        "minecraft:smooth_sandstone_stairs{half:bottom,waterlogged:false,shape:straight,facing:south}",
        "minecraft:wall_torch{facing:west}",
        "minecraft:smooth_sandstone_stairs{half:bottom,waterlogged:false,shape:straight,facing:west}",
        "minecraft:smooth_sandstone_stairs{half:bottom,waterlogged:false,shape:straight,facing:north}",
        "minecraft:wall_torch{facing:south}",
        "minecraft:wall_torch{facing:north}",
        "minecraft:torch",
        "minecraft:jigsaw{orientation:up_north}",
        "minecraft:jigsaw{orientation:west_up}",
        "minecraft:green_bed{part:foot,facing:south,occupied:false}",
        "minecraft:green_bed{part:head,facing:south,occupied:false}",
        "minecraft:chest{waterlogged:false,facing:west,type:single}"
    ]
}