{
    size: [6, 6, 7],
    data: [
        {pos: [0, 0, 0], state: "minecraft:sand"},
        {pos: [0, 0, 1], state: "minecraft:sand"},
        {pos: [0, 0, 2], state: "minecraft:sand"},
        {pos: [0, 0, 3], state: "minecraft:sand"},
        {pos: [0, 0, 4], state: "minecraft:sand"},
        {pos: [0, 0, 5], state: "minecraft:sand"},
        {pos: [0, 0, 6], state: "minecraft:sand"},
        {pos: [1, 0, 0], state: "minecraft:sand"},
        {pos: [1, 0, 1], state: "minecraft:sand"},
        {pos: [1, 0, 2], state: "minecraft:sand"},
        {pos: [1, 0, 3], state: "minecraft:smooth_sandstone"},
        {pos: [1, 0, 4], state: "minecraft:sand"},
        {pos: [1, 0, 5], state: "minecraft:sand"},
        {pos: [1, 0, 6], state: "minecraft:sand"},
        {pos: [2, 0, 0], state: "minecraft:sand"},
        {pos: [2, 0, 1], state: "minecraft:smooth_sandstone"},
        {pos: [2, 0, 2], state: "minecraft:smooth_sandstone"},
        {pos: [2, 0, 3], state: "minecraft:smooth_sandstone"},
        {pos: [2, 0, 4], state: "minecraft:smooth_sandstone"},
        {pos: [2, 0, 5], state: "minecraft:smooth_sandstone"},
        {pos: [2, 0, 6], state: "minecraft:sand"},
        {pos: [3, 0, 0], state: "minecraft:sand"},
        {pos: [3, 0, 1], state: "minecraft:smooth_sandstone"},
        {pos: [3, 0, 3], state: "minecraft:smooth_sandstone"},
        {pos: [3, 0, 5], state: "minecraft:smooth_sandstone"},
        {pos: [3, 0, 6], state: "minecraft:sand"},
        {pos: [4, 0, 0], state: "minecraft:sand"},
        {pos: [4, 0, 1], state: "minecraft:smooth_sandstone"},
        {pos: [4, 0, 2], state: "minecraft:smooth_sandstone"},
        {pos: [4, 0, 3], state: "minecraft:smooth_sandstone"},
        {pos: [4, 0, 4], state: "minecraft:smooth_sandstone"},
        {pos: [4, 0, 5], state: "minecraft:smooth_sandstone"},
        {pos: [4, 0, 6], state: "minecraft:sand"},
        {pos: [5, 0, 0], state: "minecraft:sand"},
        {pos: [5, 0, 1], state: "minecraft:sand"},
        {pos: [5, 0, 2], state: "minecraft:sand"},
        {pos: [5, 0, 3], state: "minecraft:sand"},
        {pos: [5, 0, 4], state: "minecraft:sand"},
        {pos: [5, 0, 5], state: "minecraft:sand"},
        {pos: [5, 0, 6], state: "minecraft:sand"},
        {pos: [1, 1, 0], state: "minecraft:smooth_sandstone"},
        {pos: [1, 1, 1], state: "minecraft:smooth_sandstone"},
        {pos: [1, 1, 2], state: "minecraft:smooth_sandstone"},
        {pos: [1, 1, 4], state: "minecraft:smooth_sandstone"},
        {pos: [1, 1, 5], state: "minecraft:smooth_sandstone"},
        {pos: [1, 1, 6], state: "minecraft:smooth_sandstone"},
        {pos: [2, 1, 0], state: "minecraft:smooth_sandstone"},
        {pos: [2, 1, 6], state: "minecraft:smooth_sandstone"},
        {pos: [3, 1, 0], state: "minecraft:smooth_sandstone"},
        {pos: [3, 1, 6], state: "minecraft:smooth_sandstone"},
        {pos: [4, 1, 0], state: "minecraft:smooth_sandstone"},
        {pos: [4, 1, 3], state: "minecraft:terracotta"},
        {pos: [4, 1, 6], state: "minecraft:smooth_sandstone"},
        {pos: [5, 1, 0], state: "minecraft:smooth_sandstone"},
        {pos: [5, 1, 1], state: "minecraft:smooth_sandstone"},
        {pos: [5, 1, 2], state: "minecraft:smooth_sandstone"},
        {pos: [5, 1, 3], state: "minecraft:smooth_sandstone"},
        {pos: [5, 1, 4], state: "minecraft:smooth_sandstone"},
        {pos: [5, 1, 5], state: "minecraft:smooth_sandstone"},
        {pos: [5, 1, 6], state: "minecraft:smooth_sandstone"},
        {pos: [1, 2, 0], state: "minecraft:smooth_sandstone"},
        {pos: [1, 2, 2], state: "minecraft:smooth_sandstone"},
        {pos: [1, 2, 4], state: "minecraft:smooth_sandstone"},
        {pos: [1, 2, 6], state: "minecraft:smooth_sandstone"},
        {pos: [2, 2, 0], state: "minecraft:smooth_sandstone"},
        {pos: [2, 2, 6], state: "minecraft:smooth_sandstone"},
        {pos: [4, 2, 0], state: "minecraft:smooth_sandstone"},
        {pos: [4, 2, 6], state: "minecraft:smooth_sandstone"},
        {pos: [5, 2, 0], state: "minecraft:smooth_sandstone"},
        {pos: [5, 2, 1], state: "minecraft:smooth_sandstone"},
        {pos: [5, 2, 3], state: "minecraft:smooth_sandstone"},
        {pos: [5, 2, 5], state: "minecraft:smooth_sandstone"},
        {pos: [5, 2, 6], state: "minecraft:smooth_sandstone"},
        {pos: [1, 3, 0], state: "minecraft:smooth_sandstone"},
        {pos: [1, 3, 2], state: "minecraft:smooth_sandstone"},
        {pos: [1, 3, 3], state: "minecraft:smooth_sandstone"},
        {pos: [1, 3, 4], state: "minecraft:smooth_sandstone"},
        {pos: [1, 3, 6], state: "minecraft:smooth_sandstone"},
        {pos: [2, 3, 0], state: "minecraft:smooth_sandstone"},
        {pos: [2, 3, 6], state: "minecraft:smooth_sandstone"},
        {pos: [4, 3, 0], state: "minecraft:smooth_sandstone"},
        {pos: [4, 3, 6], state: "minecraft:smooth_sandstone"},
        {pos: [5, 3, 0], state: "minecraft:smooth_sandstone"},
        {pos: [5, 3, 1], state: "minecraft:smooth_sandstone"},
        {pos: [5, 3, 3], state: "minecraft:smooth_sandstone"},
        {pos: [5, 3, 5], state: "minecraft:smooth_sandstone"},
        {pos: [5, 3, 6], state: "minecraft:smooth_sandstone"},
        {pos: [1, 4, 0], state: "minecraft:cut_sandstone"},
        {pos: [1, 4, 1], state: "minecraft:cut_sandstone"},
        {pos: [1, 4, 2], state: "minecraft:cut_sandstone"},
        {pos: [1, 4, 3], state: "minecraft:cut_sandstone"},
        {pos: [1, 4, 4], state: "minecraft:cut_sandstone"},
        {pos: [1, 4, 5], state: "minecraft:cut_sandstone"},
        {pos: [1, 4, 6], state: "minecraft:cut_sandstone"},
        {pos: [2, 4, 0], state: "minecraft:cut_sandstone"},
        {pos: [2, 4, 1], state: "minecraft:cut_sandstone"},
        {pos: [2, 4, 2], state: "minecraft:cut_sandstone"},
        {pos: [2, 4, 3], state: "minecraft:cut_sandstone"},
        {pos: [2, 4, 4], state: "minecraft:cut_sandstone"},
        {pos: [2, 4, 5], state: "minecraft:cut_sandstone"},
        {pos: [2, 4, 6], state: "minecraft:cut_sandstone"},
        {pos: [3, 4, 0], state: "minecraft:cut_sandstone"},
        {pos: [3, 4, 1], state: "minecraft:cut_sandstone"},
        {pos: [3, 4, 2], state: "minecraft:cut_sandstone"},
        {pos: [3, 4, 3], state: "minecraft:cut_sandstone"},
        {pos: [3, 4, 4], state: "minecraft:cut_sandstone"},
        {pos: [3, 4, 5], state: "minecraft:cut_sandstone"},
        {pos: [3, 4, 6], state: "minecraft:cut_sandstone"},
        {pos: [4, 4, 0], state: "minecraft:cut_sandstone"},
        {pos: [4, 4, 1], state: "minecraft:cut_sandstone"},
        {pos: [4, 4, 2], state: "minecraft:cut_sandstone"},
        {pos: [4, 4, 3], state: "minecraft:cut_sandstone"},
        {pos: [4, 4, 4], state: "minecraft:cut_sandstone"},
        {pos: [4, 4, 5], state: "minecraft:cut_sandstone"},
        {pos: [4, 4, 6], state: "minecraft:cut_sandstone"},
        {pos: [5, 4, 0], state: "minecraft:cut_sandstone"},
        {pos: [5, 4, 1], state: "minecraft:cut_sandstone"},
        {pos: [5, 4, 2], state: "minecraft:cut_sandstone"},
        {pos: [5, 4, 3], state: "minecraft:cut_sandstone"},
        {pos: [5, 4, 4], state: "minecraft:cut_sandstone"},
        {pos: [5, 4, 5], state: "minecraft:cut_sandstone"},
        {pos: [5, 4, 6], state: "minecraft:cut_sandstone"},
        {pos: [0, 1, 0], state: "minecraft:air"},
        {pos: [0, 1, 1], state: "minecraft:potted_cactus"},
        {pos: [0, 1, 2], state: "minecraft:air"},
        {pos: [0, 1, 4], state: "minecraft:air"},
        {pos: [0, 1, 5], state: "minecraft:air"},
        {pos: [0, 1, 6], state: "minecraft:air"},
        {pos: [1, 1, 3], state: "minecraft:jungle_door{hinge:right,half:lower,powered:false,facing:west,open:false}"},
        {pos: [2, 1, 2], state: "minecraft:air"},
        {pos: [2, 1, 3], state: "minecraft:air"},
        {pos: [2, 1, 4], state: "minecraft:air"},
        {pos: [2, 1, 5], state: "minecraft:air"},
        {pos: [3, 1, 2], state: "minecraft:air"},
        {pos: [3, 1, 3], state: "minecraft:air"},
        {pos: [3, 1, 4], state: "minecraft:air"},
        {pos: [4, 1, 2], state: "minecraft:air"},
        {pos: [4, 1, 4], state: "minecraft:air"},
        {pos: [0, 2, 0], state: "minecraft:air"},
        {pos: [0, 2, 1], state: "minecraft:air"},
        {pos: [0, 2, 2], state: "minecraft:wall_torch{facing:west}"},
        {pos: [0, 2, 3], state: "minecraft:air"},
        {pos: [0, 2, 4], state: "minecraft:wall_torch{facing:west}"},
        {pos: [0, 2, 5], state: "minecraft:air"},
        {pos: [0, 2, 6], state: "minecraft:air"},
        {pos: [1, 2, 1], state: "minecraft:sandstone_slab{waterlogged:false,type:bottom}"},
        {pos: [1, 2, 3], state: "minecraft:jungle_door{hinge:right,half:upper,powered:false,facing:west,open:false}"},
        {pos: [1, 2, 5], state: "minecraft:sandstone_slab{waterlogged:false,type:bottom}"},
        {pos: [2, 2, 1], state: "minecraft:air"},
        {pos: [2, 2, 2], state: "minecraft:air"},
        {pos: [2, 2, 3], state: "minecraft:air"},
        {pos: [2, 2, 4], state: "minecraft:air"},
        {pos: [2, 2, 5], state: "minecraft:air"},
        {pos: [3, 2, 0], state: "minecraft:sandstone_slab{waterlogged:false,type:bottom}"},
        {pos: [3, 2, 1], state: "minecraft:air"},
        {pos: [3, 2, 2], state: "minecraft:air"},
        {pos: [3, 2, 3], state: "minecraft:air"},
        {pos: [3, 2, 4], state: "minecraft:air"},
        {pos: [3, 2, 5], state: "minecraft:air"},
        {pos: [3, 2, 6], state: "minecraft:sandstone_slab{waterlogged:false,type:bottom}"},
        {pos: [4, 2, 1], state: "minecraft:air"},
        {pos: [4, 2, 2], state: "minecraft:air"},
        {pos: [4, 2, 3], state: "minecraft:potted_cactus"},
        {pos: [4, 2, 4], state: "minecraft:air"},
        {pos: [4, 2, 5], state: "minecraft:air"},
        {pos: [5, 2, 2], state: "minecraft:sandstone_slab{waterlogged:false,type:bottom}"},
        {pos: [5, 2, 4], state: "minecraft:sandstone_slab{waterlogged:false,type:bottom}"},
        {pos: [0, 3, 0], state: "minecraft:air"},
        {pos: [0, 3, 1], state: "minecraft:air"},
        {pos: [0, 3, 2], state: "minecraft:air"},
        {pos: [0, 3, 3], state: "minecraft:air"},
        {pos: [0, 3, 4], state: "minecraft:air"},
        {pos: [0, 3, 5], state: "minecraft:air"},
        {pos: [0, 3, 6], state: "minecraft:air"},
        {pos: [1, 3, 1], state: "minecraft:sandstone_slab{waterlogged:false,type:top}"},
        {pos: [1, 3, 5], state: "minecraft:sandstone_slab{waterlogged:false,type:top}"},
        {pos: [2, 3, 1], state: "minecraft:air"},
        {pos: [2, 3, 2], state: "minecraft:air"},
        {pos: [2, 3, 3], state: "minecraft:wall_torch{facing:east}"},
        {pos: [2, 3, 4], state: "minecraft:air"},
        {pos: [2, 3, 5], state: "minecraft:air"},
        {pos: [3, 3, 0], state: "minecraft:sandstone_slab{waterlogged:false,type:top}"},
        {pos: [3, 3, 1], state: "minecraft:air"},
        {pos: [3, 3, 2], state: "minecraft:air"},
        {pos: [3, 3, 3], state: "minecraft:air"},
        {pos: [3, 3, 4], state: "minecraft:air"},
        {pos: [3, 3, 5], state: "minecraft:air"},
        {pos: [3, 3, 6], state: "minecraft:sandstone_slab{waterlogged:false,type:top}"},
        {pos: [4, 3, 1], state: "minecraft:wall_torch{facing:west}"},
        {pos: [4, 3, 2], state: "minecraft:air"},
        {pos: [4, 3, 3], state: "minecraft:air"},
        {pos: [4, 3, 4], state: "minecraft:air"},
        {pos: [4, 3, 5], state: "minecraft:wall_torch{facing:west}"},
        {pos: [5, 3, 2], state: "minecraft:sandstone_slab{waterlogged:false,type:top}"},
        {pos: [5, 3, 4], state: "minecraft:sandstone_slab{waterlogged:false,type:top}"},
        {pos: [0, 4, 0], state: "minecraft:air"},
        {pos: [0, 4, 1], state: "minecraft:air"},
        {pos: [0, 4, 2], state: "minecraft:air"},
        {pos: [0, 4, 3], state: "minecraft:air"},
        {pos: [0, 4, 4], state: "minecraft:air"},
        {pos: [0, 4, 5], state: "minecraft:air"},
        {pos: [0, 4, 6], state: "minecraft:air"},
        {pos: [0, 5, 0], state: "minecraft:air"},
        {pos: [0, 5, 1], state: "minecraft:air"},
        {pos: [0, 5, 2], state: "minecraft:air"},
        {pos: [0, 5, 3], state: "minecraft:air"},
        {pos: [0, 5, 4], state: "minecraft:air"},
        {pos: [0, 5, 5], state: "minecraft:air"},
        {pos: [0, 5, 6], state: "minecraft:air"},
        {pos: [1, 5, 0], state: "minecraft:sandstone_slab{waterlogged:false,type:bottom}"},
        {pos: [1, 5, 1], state: "minecraft:air"},
        {pos: [1, 5, 2], state: "minecraft:air"},
        {pos: [1, 5, 3], state: "minecraft:sandstone_slab{waterlogged:false,type:bottom}"},
        {pos: [1, 5, 4], state: "minecraft:air"},
        {pos: [1, 5, 5], state: "minecraft:air"},
        {pos: [1, 5, 6], state: "minecraft:sandstone_slab{waterlogged:false,type:bottom}"},
        {pos: [2, 5, 0], state: "minecraft:air"},
        {pos: [2, 5, 1], state: "minecraft:air"},
        {pos: [2, 5, 2], state: "minecraft:air"},
        {pos: [2, 5, 3], state: "minecraft:air"},
        {pos: [2, 5, 4], state: "minecraft:air"},
        {pos: [2, 5, 5], state: "minecraft:air"},
        {pos: [2, 5, 6], state: "minecraft:air"},
        {pos: [3, 5, 0], state: "minecraft:sandstone_slab{waterlogged:false,type:bottom}"},
        {pos: [3, 5, 1], state: "minecraft:air"},
        {pos: [3, 5, 2], state: "minecraft:air"},
        {pos: [3, 5, 3], state: "minecraft:air"},
        {pos: [3, 5, 4], state: "minecraft:air"},
        {pos: [3, 5, 5], state: "minecraft:air"},
        {pos: [3, 5, 6], state: "minecraft:sandstone_slab{waterlogged:false,type:bottom}"},
        {pos: [4, 5, 0], state: "minecraft:air"},
        {pos: [4, 5, 1], state: "minecraft:air"},
        {pos: [4, 5, 2], state: "minecraft:air"},
        {pos: [4, 5, 3], state: "minecraft:air"},
        {pos: [4, 5, 4], state: "minecraft:air"},
        {pos: [4, 5, 5], state: "minecraft:air"},
        {pos: [4, 5, 6], state: "minecraft:air"},
        {pos: [5, 5, 0], state: "minecraft:sandstone_slab{waterlogged:false,type:bottom}"},
        {pos: [5, 5, 1], state: "minecraft:air"},
        {pos: [5, 5, 2], state: "minecraft:air"},
        {pos: [5, 5, 3], state: "minecraft:sandstone_slab{waterlogged:false,type:bottom}"},
        {pos: [5, 5, 4], state: "minecraft:air"},
        {pos: [5, 5, 5], state: "minecraft:air"},
        {pos: [5, 5, 6], state: "minecraft:sandstone_slab{waterlogged:false,type:bottom}"},
        {pos: [3, 0, 2], state: "minecraft:jigsaw{orientation:up_north}", nbt: {final_state: "minecraft:smooth_sandstone", id: "minecraft:jigsaw", joint: "rollable", name: "minecraft:bottom", pool: "minecraft:village/desert/villagers", target: "minecraft:bottom"}},
        {pos: [3, 0, 4], state: "minecraft:jigsaw{orientation:up_north}", nbt: {final_state: "minecraft:smooth_sandstone", id: "minecraft:jigsaw", joint: "rollable", name: "minecraft:bottom", pool: "minecraft:village/desert/villagers", target: "minecraft:bottom"}},
        {pos: [0, 1, 3], state: "minecraft:jigsaw{orientation:west_up}", nbt: {final_state: "minecraft:air", id: "minecraft:jigsaw", joint: "aligned", name: "minecraft:building_entrance", pool: "minecraft:empty", target: "minecraft:building_entrance"}},
        {pos: [2, 1, 1], state: "minecraft:chest{waterlogged:false,facing:south,type:single}", nbt: {LootTable: "minecraft:chests/village/village_desert_house", id: "minecraft:chest"}},
        {pos: [3, 1, 1], state: "minecraft:lime_bed{part:foot,facing:east,occupied:false}", nbt: {id: "minecraft:bed"}},
        {pos: [3, 1, 5], state: "minecraft:lime_bed{part:foot,facing:east,occupied:false}", nbt: {id: "minecraft:bed"}},
        {pos: [4, 1, 1], state: "minecraft:lime_bed{part:head,facing:east,occupied:false}", nbt: {id: "minecraft:bed"}},
        {pos: [4, 1, 5], state: "minecraft:lime_bed{part:head,facing:east,occupied:false}", nbt: {id: "minecraft:bed"}}
    ],
    entities: [],
    palette: [
        "minecraft:sand",
        "minecraft:smooth_sandstone",
        "minecraft:terracotta",
        "minecraft:cut_sandstone",
        "minecraft:air",
        "minecraft:potted_cactus",
        "minecraft:jungle_door{hinge:right,half:lower,powered:false,facing:west,open:false}",
        "minecraft:wall_torch{facing:west}",
        "minecraft:sandstone_slab{waterlogged:false,type:bottom}",
        "minecraft:jungle_door{hinge:right,half:upper,powered:false,facing:west,open:false}",
        "minecraft:sandstone_slab{waterlogged:false,type:top}",
        "minecraft:wall_torch{facing:east}",
        "minecraft:jigsaw{orientation:up_north}",
        "minecraft:jigsaw{orientation:west_up}",
        "minecraft:chest{waterlogged:false,facing:south,type:single}",
        "minecraft:lime_bed{part:foot,facing:east,occupied:false}",
        "minecraft:lime_bed{part:head,facing:east,occupied:false}"
    ]
}