{
    size: [9, 7, 5],
    data: [
        {pos: [0, 0, 0], state: "minecraft:sand"},
        {pos: [0, 0, 1], state: "minecraft:sand"},
        {pos: [0, 0, 2], state: "minecraft:sand"},
        {pos: [0, 0, 3], state: "minecraft:sand"},
        {pos: [0, 0, 4], state: "minecraft:sand"},
        {pos: [1, 0, 0], state: "minecraft:sand"},
        {pos: [1, 0, 1], state: "minecraft:sand"},
        {pos: [1, 0, 2], state: "minecraft:sand"},
        {pos: [1, 0, 3], state: "minecraft:sand"},
        {pos: [1, 0, 4], state: "minecraft:sand"},
        {pos: [2, 0, 0], state: "minecraft:sand"},
        {pos: [2, 0, 1], state: "minecraft:smooth_sandstone"},
        {pos: [2, 0, 2], state: "minecraft:smooth_sandstone"},
        {pos: [2, 0, 4], state: "minecraft:sand"},
        {pos: [3, 0, 0], state: "minecraft:sand"},
        {pos: [3, 0, 1], state: "minecraft:smooth_sandstone"},
        {pos: [3, 0, 2], state: "minecraft:smooth_sandstone"},
        {pos: [3, 0, 3], state: "minecraft:smooth_sandstone"},
        {pos: [3, 0, 4], state: "minecraft:sand"},
        {pos: [4, 0, 0], state: "minecraft:smooth_sandstone"},
        {pos: [4, 0, 1], state: "minecraft:smooth_sandstone"},
        {pos: [4, 0, 2], state: "minecraft:smooth_sandstone"},
        {pos: [4, 0, 3], state: "minecraft:smooth_sandstone"},
        {pos: [4, 0, 4], state: "minecraft:sand"},
        {pos: [5, 0, 0], state: "minecraft:sand"},
        {pos: [5, 0, 1], state: "minecraft:smooth_sandstone"},
        {pos: [5, 0, 2], state: "minecraft:smooth_sandstone"},
        {pos: [5, 0, 3], state: "minecraft:smooth_sandstone"},
        {pos: [5, 0, 4], state: "minecraft:sand"},
        {pos: [6, 0, 0], state: "minecraft:sand"},
        {pos: [6, 0, 1], state: "minecraft:smooth_sandstone"},
        {pos: [6, 0, 2], state: "minecraft:smooth_sandstone"},
        {pos: [6, 0, 3], state: "minecraft:smooth_sandstone"},
        {pos: [6, 0, 4], state: "minecraft:sand"},
        {pos: [7, 0, 0], state: "minecraft:sand"},
        {pos: [7, 0, 1], state: "minecraft:sand"},
        {pos: [7, 0, 2], state: "minecraft:sand"},
        {pos: [7, 0, 3], state: "minecraft:sand"},
        {pos: [7, 0, 4], state: "minecraft:sand"},
        {pos: [8, 0, 0], state: "minecraft:sand"},
        {pos: [8, 0, 1], state: "minecraft:sand"},
        {pos: [8, 0, 2], state: "minecraft:sand"},
        {pos: [8, 0, 3], state: "minecraft:sand"},
        {pos: [8, 0, 4], state: "minecraft:sand"},
        {pos: [0, 1, 0], state: "minecraft:cut_sandstone"},
        {pos: [0, 1, 1], state: "minecraft:smooth_sandstone"},
        {pos: [0, 1, 2], state: "minecraft:smooth_sandstone"},
        {pos: [0, 1, 3], state: "minecraft:smooth_sandstone"},
        {pos: [0, 1, 4], state: "minecraft:cut_sandstone"},
        {pos: [1, 1, 0], state: "minecraft:smooth_sandstone"},
        {pos: [1, 1, 4], state: "minecraft:smooth_sandstone"},
        {pos: [2, 1, 0], state: "minecraft:smooth_sandstone"},
        {pos: [2, 1, 4], state: "minecraft:smooth_sandstone"},
        {pos: [3, 1, 4], state: "minecraft:smooth_sandstone"},
        {pos: [4, 1, 4], state: "minecraft:smooth_sandstone"},
        {pos: [5, 1, 0], state: "minecraft:smooth_sandstone"},
        {pos: [5, 1, 4], state: "minecraft:smooth_sandstone"},
        {pos: [6, 1, 0], state: "minecraft:smooth_sandstone"},
        {pos: [6, 1, 4], state: "minecraft:smooth_sandstone"},
        {pos: [7, 1, 0], state: "minecraft:smooth_sandstone"},
        {pos: [7, 1, 1], state: "minecraft:bookshelf"},
        {pos: [7, 1, 2], state: "minecraft:bookshelf"},
        {pos: [7, 1, 3], state: "minecraft:bookshelf"},
        {pos: [7, 1, 4], state: "minecraft:smooth_sandstone"},
        {pos: [8, 1, 0], state: "minecraft:cut_sandstone"},
        {pos: [8, 1, 1], state: "minecraft:smooth_sandstone"},
        {pos: [8, 1, 2], state: "minecraft:smooth_sandstone"},
        {pos: [8, 1, 3], state: "minecraft:smooth_sandstone"},
        {pos: [8, 1, 4], state: "minecraft:cut_sandstone"},
        {pos: [0, 2, 0], state: "minecraft:cut_sandstone"},
        {pos: [0, 2, 1], state: "minecraft:smooth_sandstone"},
        {pos: [0, 2, 2], state: "minecraft:smooth_sandstone"},
        {pos: [0, 2, 3], state: "minecraft:smooth_sandstone"},
        {pos: [0, 2, 4], state: "minecraft:cut_sandstone"},
        {pos: [1, 2, 0], state: "minecraft:smooth_sandstone"},
        {pos: [1, 2, 4], state: "minecraft:smooth_sandstone"},
        {pos: [3, 2, 0], state: "minecraft:smooth_sandstone"},
        {pos: [3, 2, 4], state: "minecraft:smooth_sandstone"},
        {pos: [4, 2, 4], state: "minecraft:smooth_sandstone"},
        {pos: [5, 2, 0], state: "minecraft:smooth_sandstone"},
        {pos: [5, 2, 4], state: "minecraft:smooth_sandstone"},
        {pos: [7, 2, 0], state: "minecraft:smooth_sandstone"},
        {pos: [7, 2, 1], state: "minecraft:bookshelf"},
        {pos: [7, 2, 2], state: "minecraft:bookshelf"},
        {pos: [7, 2, 3], state: "minecraft:bookshelf"},
        {pos: [7, 2, 4], state: "minecraft:smooth_sandstone"},
        {pos: [8, 2, 0], state: "minecraft:cut_sandstone"},
        {pos: [8, 2, 1], state: "minecraft:smooth_sandstone"},
        {pos: [8, 2, 2], state: "minecraft:smooth_sandstone"},
        {pos: [8, 2, 3], state: "minecraft:smooth_sandstone"},
        {pos: [8, 2, 4], state: "minecraft:cut_sandstone"},
        {pos: [0, 3, 0], state: "minecraft:cut_sandstone"},
        {pos: [0, 3, 1], state: "minecraft:smooth_sandstone"},
        {pos: [0, 3, 2], state: "minecraft:smooth_sandstone"},
        {pos: [0, 3, 3], state: "minecraft:smooth_sandstone"},
        {pos: [0, 3, 4], state: "minecraft:cut_sandstone"},
        {pos: [1, 3, 0], state: "minecraft:smooth_sandstone"},
        {pos: [1, 3, 4], state: "minecraft:smooth_sandstone"},
        {pos: [3, 3, 0], state: "minecraft:smooth_sandstone"},
        {pos: [3, 3, 4], state: "minecraft:smooth_sandstone"},
        {pos: [4, 3, 0], state: "minecraft:sandstone_slab{waterlogged:false,type:double}"},
        {pos: [4, 3, 4], state: "minecraft:smooth_sandstone"},
        {pos: [5, 3, 0], state: "minecraft:smooth_sandstone"},
        {pos: [5, 3, 4], state: "minecraft:smooth_sandstone"},
        {pos: [7, 3, 0], state: "minecraft:smooth_sandstone"},
        {pos: [7, 3, 1], state: "minecraft:bookshelf"},
        {pos: [7, 3, 2], state: "minecraft:bookshelf"},
        {pos: [7, 3, 3], state: "minecraft:bookshelf"},
        {pos: [7, 3, 4], state: "minecraft:smooth_sandstone"},
        {pos: [8, 3, 0], state: "minecraft:cut_sandstone"},
        {pos: [8, 3, 1], state: "minecraft:smooth_sandstone"},
        {pos: [8, 3, 2], state: "minecraft:smooth_sandstone"},
        {pos: [8, 3, 3], state: "minecraft:smooth_sandstone"},
        {pos: [8, 3, 4], state: "minecraft:cut_sandstone"},
        {pos: [0, 4, 0], state: "minecraft:cut_sandstone"},
        {pos: [0, 4, 1], state: "minecraft:smooth_sandstone"},
        {pos: [0, 4, 2], state: "minecraft:smooth_sandstone"},
        {pos: [0, 4, 3], state: "minecraft:smooth_sandstone"},
        {pos: [0, 4, 4], state: "minecraft:cut_sandstone"},
        {pos: [1, 4, 0], state: "minecraft:smooth_sandstone"},
        {pos: [1, 4, 1], state: "minecraft:smooth_sandstone"},
        {pos: [1, 4, 2], state: "minecraft:smooth_sandstone"},
        {pos: [1, 4, 3], state: "minecraft:smooth_sandstone"},
        {pos: [1, 4, 4], state: "minecraft:smooth_sandstone"},
        {pos: [2, 4, 0], state: "minecraft:smooth_sandstone"},
        {pos: [2, 4, 1], state: "minecraft:smooth_sandstone"},
        {pos: [2, 4, 2], state: "minecraft:smooth_sandstone"},
        {pos: [2, 4, 3], state: "minecraft:smooth_sandstone"},
        {pos: [2, 4, 4], state: "minecraft:smooth_sandstone"},
        {pos: [3, 4, 0], state: "minecraft:smooth_sandstone"},
        {pos: [3, 4, 1], state: "minecraft:smooth_sandstone"},
        {pos: [3, 4, 2], state: "minecraft:smooth_sandstone"},
        {pos: [3, 4, 3], state: "minecraft:smooth_sandstone"},
        {pos: [3, 4, 4], state: "minecraft:smooth_sandstone"},
        {pos: [4, 4, 0], state: "minecraft:smooth_sandstone"},
        {pos: [4, 4, 1], state: "minecraft:smooth_sandstone"},
        {pos: [4, 4, 2], state: "minecraft:smooth_sandstone"},
        {pos: [4, 4, 3], state: "minecraft:smooth_sandstone"},
        {pos: [4, 4, 4], state: "minecraft:smooth_sandstone"},
        {pos: [5, 4, 0], state: "minecraft:smooth_sandstone"},
        {pos: [5, 4, 1], state: "minecraft:smooth_sandstone"},
        {pos: [5, 4, 2], state: "minecraft:smooth_sandstone"},
        {pos: [5, 4, 3], state: "minecraft:smooth_sandstone"},
        {pos: [5, 4, 4], state: "minecraft:smooth_sandstone"},
        {pos: [6, 4, 0], state: "minecraft:smooth_sandstone"},
        {pos: [6, 4, 1], state: "minecraft:smooth_sandstone"},
        {pos: [6, 4, 2], state: "minecraft:smooth_sandstone"},
        {pos: [6, 4, 3], state: "minecraft:smooth_sandstone"},
        {pos: [6, 4, 4], state: "minecraft:smooth_sandstone"},
        {pos: [7, 4, 0], state: "minecraft:smooth_sandstone"},
        {pos: [7, 4, 1], state: "minecraft:smooth_sandstone"},
        {pos: [7, 4, 2], state: "minecraft:smooth_sandstone"},
        {pos: [7, 4, 3], state: "minecraft:smooth_sandstone"},
        {pos: [7, 4, 4], state: "minecraft:smooth_sandstone"},
        {pos: [8, 4, 0], state: "minecraft:cut_sandstone"},
        {pos: [8, 4, 1], state: "minecraft:smooth_sandstone"},
        {pos: [8, 4, 2], state: "minecraft:smooth_sandstone"},
        {pos: [8, 4, 3], state: "minecraft:smooth_sandstone"},
        {pos: [8, 4, 4], state: "minecraft:cut_sandstone"},
        {pos: [0, 5, 0], state: "minecraft:cut_sandstone"},
        {pos: [0, 5, 1], state: "minecraft:cut_sandstone"},
        {pos: [0, 5, 2], state: "minecraft:cut_sandstone"},
        {pos: [0, 5, 3], state: "minecraft:cut_sandstone"},
        {pos: [0, 5, 4], state: "minecraft:cut_sandstone"},
        {pos: [1, 5, 0], state: "minecraft:cut_sandstone"},
        {pos: [1, 5, 4], state: "minecraft:cut_sandstone"},
        {pos: [2, 5, 0], state: "minecraft:cut_sandstone"},
        {pos: [2, 5, 4], state: "minecraft:cut_sandstone"},
        {pos: [3, 5, 0], state: "minecraft:cut_sandstone"},
        {pos: [3, 5, 4], state: "minecraft:cut_sandstone"},
        {pos: [4, 5, 0], state: "minecraft:cut_sandstone"},
        {pos: [4, 5, 4], state: "minecraft:cut_sandstone"},
        {pos: [5, 5, 0], state: "minecraft:cut_sandstone"},
        {pos: [5, 5, 4], state: "minecraft:cut_sandstone"},
        {pos: [6, 5, 0], state: "minecraft:cut_sandstone"},
        {pos: [6, 5, 4], state: "minecraft:cut_sandstone"},
        {pos: [7, 5, 0], state: "minecraft:cut_sandstone"},
        {pos: [7, 5, 4], state: "minecraft:cut_sandstone"},
        {pos: [8, 5, 0], state: "minecraft:cut_sandstone"},
        {pos: [8, 5, 1], state: "minecraft:cut_sandstone"},
        {pos: [8, 5, 2], state: "minecraft:cut_sandstone"},
        {pos: [8, 5, 3], state: "minecraft:cut_sandstone"},
        {pos: [8, 5, 4], state: "minecraft:cut_sandstone"},
        {pos: [0, 6, 0], state: "minecraft:cut_sandstone"},
        {pos: [0, 6, 4], state: "minecraft:cut_sandstone"},
        {pos: [8, 6, 0], state: "minecraft:cut_sandstone"},
        {pos: [8, 6, 4], state: "minecraft:cut_sandstone"},
        {pos: [1, 1, 1], state: "minecraft:smooth_sandstone_stairs{half:bottom,waterlogged:false,shape:straight,facing:west}"},
        {pos: [1, 1, 3], state: "minecraft:smooth_sandstone_stairs{half:bottom,waterlogged:false,shape:straight,facing:west}"},
        {pos: [2, 1, 1], state: "minecraft:air"},
        {pos: [2, 1, 2], state: "minecraft:air"},
        {pos: [2, 1, 3], state: "minecraft:air"},
        {pos: [3, 1, 1], state: "minecraft:air"},
        {pos: [3, 1, 2], state: "minecraft:white_carpet"},
        {pos: [3, 1, 3], state: "minecraft:air"},
        {pos: [4, 1, 0], state: "minecraft:jungle_door{hinge:left,half:lower,powered:false,facing:north,open:false}"},
        {pos: [4, 1, 1], state: "minecraft:air"},
        {pos: [4, 1, 2], state: "minecraft:lime_carpet"},
        {pos: [4, 1, 3], state: "minecraft:air"},
        {pos: [5, 1, 1], state: "minecraft:air"},
        {pos: [5, 1, 2], state: "minecraft:white_carpet"},
        {pos: [5, 1, 3], state: "minecraft:air"},
        {pos: [6, 1, 1], state: "minecraft:air"},
        {pos: [6, 1, 2], state: "minecraft:air"},
        {pos: [6, 1, 3], state: "minecraft:air"},
        {pos: [1, 2, 1], state: "minecraft:air"},
        {pos: [1, 2, 2], state: "minecraft:wall_torch{facing:east}"},
        {pos: [1, 2, 3], state: "minecraft:air"},
        {pos: [2, 2, 0], state: "minecraft:potted_cactus"},
        {pos: [2, 2, 1], state: "minecraft:air"},
        {pos: [2, 2, 2], state: "minecraft:air"},
        {pos: [2, 2, 3], state: "minecraft:air"},
        {pos: [2, 2, 4], state: "minecraft:potted_cactus"},
        {pos: [3, 2, 1], state: "minecraft:air"},
        {pos: [3, 2, 2], state: "minecraft:air"},
        {pos: [3, 2, 3], state: "minecraft:air"},
        {pos: [4, 2, 0], state: "minecraft:jungle_door{hinge:left,half:upper,powered:false,facing:north,open:false}"},
        {pos: [4, 2, 1], state: "minecraft:air"},
        {pos: [4, 2, 2], state: "minecraft:air"},
        {pos: [4, 2, 3], state: "minecraft:wall_torch{facing:north}"},
        {pos: [5, 2, 1], state: "minecraft:air"},
        {pos: [5, 2, 2], state: "minecraft:air"},
        {pos: [5, 2, 3], state: "minecraft:air"},
        {pos: [6, 2, 0], state: "minecraft:potted_cactus"},
        {pos: [6, 2, 1], state: "minecraft:air"},
        {pos: [6, 2, 2], state: "minecraft:air"},
        {pos: [6, 2, 3], state: "minecraft:air"},
        {pos: [6, 2, 4], state: "minecraft:potted_cactus"},
        {pos: [1, 3, 1], state: "minecraft:air"},
        {pos: [1, 3, 2], state: "minecraft:air"},
        {pos: [1, 3, 3], state: "minecraft:air"},
        {pos: [2, 3, 0], state: "minecraft:sandstone_slab{waterlogged:false,type:top}"},
        {pos: [2, 3, 1], state: "minecraft:air"},
        {pos: [2, 3, 2], state: "minecraft:air"},
        {pos: [2, 3, 3], state: "minecraft:air"},
        {pos: [2, 3, 4], state: "minecraft:sandstone_slab{waterlogged:false,type:top}"},
        {pos: [3, 3, 1], state: "minecraft:air"},
        {pos: [3, 3, 2], state: "minecraft:air"},
        {pos: [3, 3, 3], state: "minecraft:air"},
        {pos: [4, 3, 1], state: "minecraft:air"},
        {pos: [4, 3, 2], state: "minecraft:air"},
        {pos: [4, 3, 3], state: "minecraft:air"},
        {pos: [5, 3, 1], state: "minecraft:air"},
        {pos: [5, 3, 2], state: "minecraft:air"},
        {pos: [5, 3, 3], state: "minecraft:air"},
        {pos: [6, 3, 0], state: "minecraft:sandstone_slab{waterlogged:false,type:top}"},
        {pos: [6, 3, 1], state: "minecraft:air"},
        {pos: [6, 3, 2], state: "minecraft:air"},
        {pos: [6, 3, 3], state: "minecraft:air"},
        {pos: [6, 3, 4], state: "minecraft:sandstone_slab{waterlogged:false,type:top}"},
        {pos: [1, 5, 1], state: "minecraft:air"},
        {pos: [1, 5, 2], state: "minecraft:air"},
        {pos: [1, 5, 3], state: "minecraft:air"},
        {pos: [2, 5, 1], state: "minecraft:air"},
        {pos: [2, 5, 2], state: "minecraft:air"},
        {pos: [2, 5, 3], state: "minecraft:air"},
        {pos: [3, 5, 1], state: "minecraft:air"},
        {pos: [3, 5, 2], state: "minecraft:air"},
        {pos: [3, 5, 3], state: "minecraft:air"},
        {pos: [4, 5, 1], state: "minecraft:air"},
        {pos: [4, 5, 2], state: "minecraft:air"},
        {pos: [4, 5, 3], state: "minecraft:air"},
        {pos: [5, 5, 1], state: "minecraft:air"},
        {pos: [5, 5, 2], state: "minecraft:air"},
        {pos: [5, 5, 3], state: "minecraft:air"},
        {pos: [6, 5, 1], state: "minecraft:air"},
        {pos: [6, 5, 2], state: "minecraft:air"},
        {pos: [6, 5, 3], state: "minecraft:air"},
        {pos: [7, 5, 1], state: "minecraft:air"},
        {pos: [7, 5, 2], state: "minecraft:air"},
        {pos: [7, 5, 3], state: "minecraft:air"},
        {pos: [0, 6, 1], state: "minecraft:air"},
        {pos: [0, 6, 2], state: "minecraft:air"},
        {pos: [0, 6, 3], state: "minecraft:air"},
        {pos: [1, 6, 0], state: "minecraft:air"},
        {pos: [1, 6, 1], state: "minecraft:air"},
        {pos: [1, 6, 2], state: "minecraft:air"},
        {pos: [1, 6, 3], state: "minecraft:air"},
        {pos: [1, 6, 4], state: "minecraft:air"},
        {pos: [2, 6, 0], state: "minecraft:air"},
        {pos: [2, 6, 1], state: "minecraft:air"},
        {pos: [2, 6, 2], state: "minecraft:air"},
        {pos: [2, 6, 3], state: "minecraft:air"},
        {pos: [2, 6, 4], state: "minecraft:air"},
        {pos: [3, 6, 0], state: "minecraft:air"},
        {pos: [3, 6, 1], state: "minecraft:air"},
        {pos: [3, 6, 2], state: "minecraft:air"},
        {pos: [3, 6, 3], state: "minecraft:air"},
        {pos: [3, 6, 4], state: "minecraft:air"},
        {pos: [4, 6, 0], state: "minecraft:air"},
        {pos: [4, 6, 1], state: "minecraft:air"},
        {pos: [4, 6, 2], state: "minecraft:air"},
        {pos: [4, 6, 3], state: "minecraft:air"},
        {pos: [4, 6, 4], state: "minecraft:air"},
        {pos: [5, 6, 0], state: "minecraft:air"},
        {pos: [5, 6, 1], state: "minecraft:air"},
        {pos: [5, 6, 2], state: "minecraft:air"},
        {pos: [5, 6, 3], state: "minecraft:air"},
        {pos: [5, 6, 4], state: "minecraft:air"},
        {pos: [6, 6, 0], state: "minecraft:air"},
        {pos: [6, 6, 1], state: "minecraft:air"},
        {pos: [6, 6, 2], state: "minecraft:air"},
        {pos: [6, 6, 3], state: "minecraft:air"},
        {pos: [6, 6, 4], state: "minecraft:air"},
        {pos: [7, 6, 0], state: "minecraft:air"},
        {pos: [7, 6, 1], state: "minecraft:air"},
        {pos: [7, 6, 2], state: "minecraft:air"},
        {pos: [7, 6, 3], state: "minecraft:air"},
        {pos: [7, 6, 4], state: "minecraft:air"},
        {pos: [8, 6, 1], state: "minecraft:air"},
        {pos: [8, 6, 2], state: "minecraft:air"},
        {pos: [8, 6, 3], state: "minecraft:air"},
        {pos: [2, 0, 3], state: "minecraft:jigsaw{orientation:up_north}", nbt: {final_state: "minecraft:smooth_sandstone", id: "minecraft:jigsaw", joint: "rollable", name: "minecraft:bottom", pool: "minecraft:village/common/cats", target: "minecraft:bottom"}},
        {pos: [1, 1, 2], state: "minecraft:lectern{has_book:false,powered:false,facing:east}", nbt: {id: "minecraft:lectern"}},
        {pos: [3, 1, 0], state: "minecraft:jigsaw{orientation:north_up}", nbt: {final_state: "minecraft:smooth_sandstone", id: "minecraft:jigsaw", joint: "aligned", name: "minecraft:building_entrance", pool: "minecraft:empty", target: "minecraft:building_entrance"}}
    ],
    entities: [],
    palette: [
        "minecraft:sand",
        "minecraft:smooth_sandstone",
        "minecraft:cut_sandstone",
        "minecraft:bookshelf",
        "minecraft:sandstone_slab{waterlogged:false,type:double}",
        "minecraft:smooth_sandstone_stairs{half:bottom,waterlogged:false,shape:straight,facing:west}",
        "minecraft:air",
        "minecraft:white_carpet",
        "minecraft:jungle_door{hinge:left,half:lower,powered:false,facing:north,open:false}",
        "minecraft:lime_carpet",
        "minecraft:wall_torch{facing:east}",
        "minecraft:potted_cactus",
        "minecraft:jungle_door{hinge:left,half:upper,powered:false,facing:north,open:false}",
        "minecraft:wall_torch{facing:north}",
        "minecraft:sandstone_slab{waterlogged:false,type:top}",
        "minecraft:jigsaw{orientation:up_north}",
        "minecraft:lectern{has_book:false,powered:false,facing:east}",
        "minecraft:jigsaw{orientation:north_up}"
    ]
}