{
    size: [7, 6, 5],
    data: [
        {pos: [0, 0, 0], state: "minecraft:sand"},
        {pos: [0, 0, 2], state: "minecraft:smooth_sandstone"},
        {pos: [0, 0, 4], state: "minecraft:sand"},
        {pos: [1, 0, 2], state: "minecraft:smooth_sandstone"},
        {pos: [2, 0, 0], state: "minecraft:sand"},
        {pos: [2, 0, 1], state: "minecraft:sand"},
        {pos: [2, 0, 2], state: "minecraft:smooth_sandstone"},
        {pos: [2, 0, 3], state: "minecraft:sand"},
        {pos: [2, 0, 4], state: "minecraft:sand"},
        {pos: [3, 0, 0], state: "minecraft:sand"},
        {pos: [3, 0, 1], state: "minecraft:smooth_sandstone"},
        {pos: [3, 0, 2], state: "minecraft:smooth_sandstone"},
        {pos: [3, 0, 3], state: "minecraft:smooth_sandstone"},
        {pos: [3, 0, 4], state: "minecraft:sand"},
        {pos: [4, 0, 0], state: "minecraft:sand"},
        {pos: [4, 0, 1], state: "minecraft:smooth_sandstone"},
        {pos: [4, 0, 2], state: "minecraft:smooth_sandstone"},
        {pos: [4, 0, 3], state: "minecraft:smooth_sandstone"},
        {pos: [4, 0, 4], state: "minecraft:sand"},
        {pos: [5, 0, 0], state: "minecraft:sand"},
        {pos: [5, 0, 1], state: "minecraft:smooth_sandstone"},
        {pos: [5, 0, 2], state: "minecraft:smooth_sandstone"},
        {pos: [5, 0, 3], state: "minecraft:smooth_sandstone"},
        {pos: [5, 0, 4], state: "minecraft:sand"},
        {pos: [6, 0, 0], state: "minecraft:sand"},
        {pos: [6, 0, 1], state: "minecraft:sand"},
        {pos: [6, 0, 2], state: "minecraft:sand"},
        {pos: [6, 0, 3], state: "minecraft:sand"},
        {pos: [6, 0, 4], state: "minecraft:sand"},
        {pos: [2, 1, 0], state: "minecraft:cut_sandstone"},
        {pos: [2, 1, 1], state: "minecraft:smooth_sandstone"},
        {pos: [2, 1, 3], state: "minecraft:smooth_sandstone"},
        {pos: [2, 1, 4], state: "minecraft:cut_sandstone"},
        {pos: [3, 1, 0], state: "minecraft:smooth_sandstone"},
        {pos: [3, 1, 4], state: "minecraft:smooth_sandstone"},
        {pos: [4, 1, 0], state: "minecraft:smooth_sandstone"},
        {pos: [4, 1, 4], state: "minecraft:smooth_sandstone"},
        {pos: [5, 1, 0], state: "minecraft:smooth_sandstone"},
        {pos: [5, 1, 1], state: "minecraft:chiseled_sandstone"},
        {pos: [5, 1, 4], state: "minecraft:smooth_sandstone"},
        {pos: [6, 1, 0], state: "minecraft:cut_sandstone"},
        {pos: [6, 1, 1], state: "minecraft:smooth_sandstone"},
        {pos: [6, 1, 2], state: "minecraft:smooth_sandstone"},
        {pos: [6, 1, 3], state: "minecraft:smooth_sandstone"},
        {pos: [6, 1, 4], state: "minecraft:cut_sandstone"},
        {pos: [2, 2, 0], state: "minecraft:cut_sandstone"},
        {pos: [2, 2, 1], state: "minecraft:smooth_sandstone"},
        {pos: [2, 2, 3], state: "minecraft:smooth_sandstone"},
        {pos: [2, 2, 4], state: "minecraft:cut_sandstone"},
        {pos: [3, 2, 0], state: "minecraft:smooth_sandstone"},
        {pos: [3, 2, 4], state: "minecraft:smooth_sandstone"},
        {pos: [4, 2, 0], state: "minecraft:smooth_sandstone"},
        {pos: [4, 2, 4], state: "minecraft:smooth_sandstone"},
        {pos: [5, 2, 0], state: "minecraft:smooth_sandstone"},
        {pos: [5, 2, 4], state: "minecraft:smooth_sandstone"},
        {pos: [6, 2, 0], state: "minecraft:cut_sandstone"},
        {pos: [6, 2, 1], state: "minecraft:smooth_sandstone"},
        {pos: [6, 2, 3], state: "minecraft:smooth_sandstone"},
        {pos: [6, 2, 4], state: "minecraft:cut_sandstone"},
        {pos: [2, 3, 0], state: "minecraft:cut_sandstone"},
        {pos: [2, 3, 1], state: "minecraft:smooth_sandstone"},
        {pos: [2, 3, 2], state: "minecraft:smooth_sandstone"},
        {pos: [2, 3, 3], state: "minecraft:smooth_sandstone"},
        {pos: [2, 3, 4], state: "minecraft:cut_sandstone"},
        {pos: [3, 3, 0], state: "minecraft:smooth_sandstone"},
        {pos: [3, 3, 4], state: "minecraft:smooth_sandstone"},
        {pos: [4, 3, 0], state: "minecraft:smooth_sandstone"},
        {pos: [4, 3, 4], state: "minecraft:smooth_sandstone"},
        {pos: [5, 3, 0], state: "minecraft:smooth_sandstone"},
        {pos: [5, 3, 4], state: "minecraft:smooth_sandstone"},
        {pos: [6, 3, 0], state: "minecraft:cut_sandstone"},
        {pos: [6, 3, 1], state: "minecraft:smooth_sandstone"},
        {pos: [6, 3, 3], state: "minecraft:smooth_sandstone"},
        {pos: [6, 3, 4], state: "minecraft:cut_sandstone"},
        {pos: [1, 4, 0], state: "minecraft:smooth_sandstone_slab{waterlogged:false,type:double}"},
        {pos: [1, 4, 4], state: "minecraft:smooth_sandstone_slab{waterlogged:false,type:double}"},
        {pos: [2, 4, 0], state: "minecraft:cut_sandstone"},
        {pos: [2, 4, 1], state: "minecraft:smooth_sandstone"},
        {pos: [2, 4, 2], state: "minecraft:smooth_sandstone"},
        {pos: [2, 4, 3], state: "minecraft:smooth_sandstone"},
        {pos: [2, 4, 4], state: "minecraft:cut_sandstone"},
        {pos: [3, 4, 0], state: "minecraft:cut_sandstone"},
        {pos: [3, 4, 4], state: "minecraft:cut_sandstone"},
        {pos: [4, 4, 0], state: "minecraft:cut_sandstone"},
        {pos: [4, 4, 4], state: "minecraft:cut_sandstone"},
        {pos: [5, 4, 0], state: "minecraft:cut_sandstone"},
        {pos: [5, 4, 4], state: "minecraft:cut_sandstone"},
        {pos: [6, 4, 0], state: "minecraft:cut_sandstone"},
        {pos: [6, 4, 1], state: "minecraft:cut_sandstone"},
        {pos: [6, 4, 2], state: "minecraft:cut_sandstone"},
        {pos: [6, 4, 3], state: "minecraft:cut_sandstone"},
        {pos: [6, 4, 4], state: "minecraft:cut_sandstone"},
        {pos: [2, 5, 2], state: "minecraft:smooth_sandstone_slab{waterlogged:false,type:double}"},
        {pos: [6, 5, 2], state: "minecraft:smooth_sandstone_slab{waterlogged:false,type:double}"},
        {pos: [0, 1, 0], state: "minecraft:sandstone_wall{east:none,waterlogged:false,south:none,north:none,west:none,up:true}"},
        {pos: [0, 1, 1], state: "minecraft:air"},
        {pos: [0, 1, 3], state: "minecraft:air"},
        {pos: [0, 1, 4], state: "minecraft:sandstone_wall{east:none,waterlogged:false,south:none,north:none,west:none,up:true}"},
        {pos: [1, 1, 0], state: "minecraft:air"},
        {pos: [1, 1, 1], state: "minecraft:air"},
        {pos: [1, 1, 2], state: "minecraft:air"},
        {pos: [1, 1, 3], state: "minecraft:air"},
        {pos: [1, 1, 4], state: "minecraft:air"},
        {pos: [2, 1, 2], state: "minecraft:jungle_door{hinge:right,half:lower,powered:false,facing:west,open:false}"},
        {pos: [3, 1, 1], state: "minecraft:green_carpet"},
        {pos: [3, 1, 2], state: "minecraft:air"},
        {pos: [3, 1, 3], state: "minecraft:green_carpet"},
        {pos: [4, 1, 1], state: "minecraft:air"},
        {pos: [4, 1, 2], state: "minecraft:air"},
        {pos: [4, 1, 3], state: "minecraft:air"},
        {pos: [0, 2, 0], state: "minecraft:sandstone_wall{east:none,waterlogged:false,south:none,north:none,west:none,up:true}"},
        {pos: [0, 2, 1], state: "minecraft:air"},
        {pos: [0, 2, 2], state: "minecraft:air"},
        {pos: [0, 2, 3], state: "minecraft:air"},
        {pos: [0, 2, 4], state: "minecraft:sandstone_wall{east:none,waterlogged:false,south:none,north:none,west:none,up:true}"},
        {pos: [1, 2, 0], state: "minecraft:air"},
        {pos: [1, 2, 1], state: "minecraft:air"},
        {pos: [1, 2, 2], state: "minecraft:air"},
        {pos: [1, 2, 3], state: "minecraft:air"},
        {pos: [1, 2, 4], state: "minecraft:air"},
        {pos: [2, 2, 2], state: "minecraft:jungle_door{hinge:right,half:upper,powered:false,facing:west,open:false}"},
        {pos: [3, 2, 1], state: "minecraft:air"},
        {pos: [3, 2, 2], state: "minecraft:air"},
        {pos: [3, 2, 3], state: "minecraft:air"},
        {pos: [4, 2, 1], state: "minecraft:air"},
        {pos: [4, 2, 2], state: "minecraft:air"},
        {pos: [4, 2, 3], state: "minecraft:air"},
        {pos: [5, 2, 1], state: "minecraft:torch"},
        {pos: [5, 2, 2], state: "minecraft:air"},
        {pos: [5, 2, 3], state: "minecraft:air"},
        {pos: [6, 2, 2], state: "minecraft:potted_cactus"},
        {pos: [0, 3, 0], state: "minecraft:sandstone_wall{east:none,waterlogged:false,south:none,north:none,west:none,up:true}"},
        {pos: [0, 3, 1], state: "minecraft:air"},
        {pos: [0, 3, 2], state: "minecraft:air"},
        {pos: [0, 3, 3], state: "minecraft:air"},
        {pos: [0, 3, 4], state: "minecraft:sandstone_wall{east:none,waterlogged:false,south:none,north:none,west:none,up:true}"},
        {pos: [1, 3, 0], state: "minecraft:air"},
        {pos: [1, 3, 1], state: "minecraft:air"},
        {pos: [1, 3, 2], state: "minecraft:wall_torch{facing:west}"},
        {pos: [1, 3, 3], state: "minecraft:air"},
        {pos: [1, 3, 4], state: "minecraft:air"},
        {pos: [3, 3, 1], state: "minecraft:air"},
        {pos: [3, 3, 2], state: "minecraft:air"},
        {pos: [3, 3, 3], state: "minecraft:air"},
        {pos: [4, 3, 1], state: "minecraft:air"},
        {pos: [4, 3, 2], state: "minecraft:air"},
        {pos: [4, 3, 3], state: "minecraft:air"},
        {pos: [5, 3, 1], state: "minecraft:air"},
        {pos: [5, 3, 2], state: "minecraft:air"},
        {pos: [5, 3, 3], state: "minecraft:air"},
        {pos: [6, 3, 2], state: "minecraft:smooth_sandstone_slab{waterlogged:false,type:top}"},
        {pos: [0, 4, 0], state: "minecraft:smooth_sandstone_slab{waterlogged:false,type:bottom}"},
        {pos: [0, 4, 1], state: "minecraft:smooth_sandstone_slab{waterlogged:false,type:bottom}"},
        {pos: [0, 4, 2], state: "minecraft:smooth_sandstone_slab{waterlogged:false,type:bottom}"},
        {pos: [0, 4, 3], state: "minecraft:smooth_sandstone_slab{waterlogged:false,type:bottom}"},
        {pos: [0, 4, 4], state: "minecraft:smooth_sandstone_slab{waterlogged:false,type:bottom}"},
        {pos: [1, 4, 1], state: "minecraft:smooth_sandstone_slab{waterlogged:false,type:top}"},
        {pos: [1, 4, 2], state: "minecraft:smooth_sandstone_slab{waterlogged:false,type:top}"},
        {pos: [1, 4, 3], state: "minecraft:smooth_sandstone_slab{waterlogged:false,type:top}"},
        {pos: [3, 4, 1], state: "minecraft:air"},
        {pos: [3, 4, 2], state: "minecraft:air"},
        {pos: [3, 4, 3], state: "minecraft:air"},
        {pos: [4, 4, 1], state: "minecraft:air"},
        {pos: [4, 4, 2], state: "minecraft:air"},
        {pos: [4, 4, 3], state: "minecraft:air"},
        {pos: [5, 4, 1], state: "minecraft:air"},
        {pos: [5, 4, 2], state: "minecraft:air"},
        {pos: [5, 4, 3], state: "minecraft:air"},
        {pos: [0, 5, 0], state: "minecraft:air"},
        {pos: [0, 5, 1], state: "minecraft:air"},
        {pos: [0, 5, 2], state: "minecraft:air"},
        {pos: [0, 5, 3], state: "minecraft:air"},
        {pos: [0, 5, 4], state: "minecraft:air"},
        {pos: [1, 5, 0], state: "minecraft:air"},
        {pos: [1, 5, 1], state: "minecraft:air"},
        {pos: [1, 5, 2], state: "minecraft:air"},
        {pos: [1, 5, 3], state: "minecraft:air"},
        {pos: [1, 5, 4], state: "minecraft:air"},
        {pos: [2, 5, 0], state: "minecraft:air"},
        {pos: [2, 5, 1], state: "minecraft:smooth_sandstone_slab{waterlogged:false,type:bottom}"},
        {pos: [2, 5, 3], state: "minecraft:smooth_sandstone_slab{waterlogged:false,type:bottom}"},
        {pos: [2, 5, 4], state: "minecraft:air"},
        {pos: [3, 5, 0], state: "minecraft:air"},
        {pos: [3, 5, 1], state: "minecraft:smooth_sandstone_slab{waterlogged:false,type:bottom}"},
        {pos: [3, 5, 2], state: "minecraft:smooth_sandstone_slab{waterlogged:false,type:bottom}"},
        {pos: [3, 5, 3], state: "minecraft:smooth_sandstone_slab{waterlogged:false,type:bottom}"},
        {pos: [3, 5, 4], state: "minecraft:air"},
        {pos: [4, 5, 0], state: "minecraft:air"},
        {pos: [4, 5, 1], state: "minecraft:smooth_sandstone_slab{waterlogged:false,type:bottom}"},
        {pos: [4, 5, 2], state: "minecraft:smooth_sandstone_slab{waterlogged:false,type:bottom}"},
        {pos: [4, 5, 3], state: "minecraft:smooth_sandstone_slab{waterlogged:false,type:bottom}"},
        {pos: [4, 5, 4], state: "minecraft:air"},
        {pos: [5, 5, 0], state: "minecraft:air"},
        {pos: [5, 5, 1], state: "minecraft:smooth_sandstone_slab{waterlogged:false,type:bottom}"},
        {pos: [5, 5, 2], state: "minecraft:smooth_sandstone_slab{waterlogged:false,type:bottom}"},
        {pos: [5, 5, 3], state: "minecraft:smooth_sandstone_slab{waterlogged:false,type:bottom}"},
        {pos: [5, 5, 4], state: "minecraft:air"},
        {pos: [6, 5, 0], state: "minecraft:air"},
        {pos: [6, 5, 1], state: "minecraft:smooth_sandstone_slab{waterlogged:false,type:bottom}"},
        {pos: [6, 5, 3], state: "minecraft:smooth_sandstone_slab{waterlogged:false,type:bottom}"},
        {pos: [6, 5, 4], state: "minecraft:air"},
        {pos: [0, 0, 3], state: "minecraft:jigsaw{orientation:up_north}", nbt: {final_state: "minecraft:sand", id: "minecraft:jigsaw", joint: "rollable", name: "minecraft:bottom", pool: "minecraft:village/common/cats", target: "minecraft:bottom"}},
        {pos: [1, 0, 1], state: "minecraft:jigsaw{orientation:up_north}", nbt: {final_state: "minecraft:sand", id: "minecraft:jigsaw", joint: "rollable", name: "minecraft:bottom", pool: "minecraft:village/desert/villagers", target: "minecraft:bottom"}},
        {pos: [0, 1, 2], state: "minecraft:jigsaw{orientation:west_up}", nbt: {final_state: "minecraft:structure_void", id: "minecraft:jigsaw", joint: "aligned", name: "minecraft:building_entrance", pool: "minecraft:empty", target: "minecraft:building_entrance"}},
        {pos: [5, 1, 2], state: "minecraft:green_bed{part:foot,facing:south,occupied:false}", nbt: {id: "minecraft:bed"}},
        {pos: [5, 1, 3], state: "minecraft:green_bed{part:head,facing:south,occupied:false}", nbt: {id: "minecraft:bed"}}
    ],
    entities: [],
    palette: [
        "minecraft:sand",
        "minecraft:smooth_sandstone",
        "minecraft:cut_sandstone",
        "minecraft:chiseled_sandstone",
        "minecraft:smooth_sandstone_slab{waterlogged:false,type:double}",
        "minecraft:sandstone_wall{east:none,waterlogged:false,south:none,north:none,west:none,up:true}",
        "minecraft:air",
        "minecraft:jungle_door{hinge:right,half:lower,powered:false,facing:west,open:false}",
        "minecraft:green_carpet",
        "minecraft:jungle_door{hinge:right,half:upper,powered:false,facing:west,open:false}",
        "minecraft:torch",
        "minecraft:potted_cactus",
        "minecraft:wall_torch{facing:west}",
        "minecraft:smooth_sandstone_slab{waterlogged:false,type:top}",
        "minecraft:smooth_sandstone_slab{waterlogged:false,type:bottom}",
        "minecraft:jigsaw{orientation:up_north}",
        "minecraft:jigsaw{orientation:west_up}",
        "minecraft:green_bed{part:foot,facing:south,occupied:false}",
        "minecraft:green_bed{part:head,facing:south,occupied:false}"
    ]
}