{
    size: [14, 24, 14],
    data: [
        {pos: [0, 0, 0], state: "minecraft:deepslate{axis:y}"},
        {pos: [0, 0, 1], state: "minecraft:deepslate{axis:y}"},
        {pos: [0, 0, 2], state: "minecraft:deepslate_bricks"},
        {pos: [0, 0, 3], state: "minecraft:deepslate_bricks"},
        {pos: [0, 0, 4], state: "minecraft:deepslate_bricks"},
        {pos: [0, 0, 5], state: "minecraft:deepslate_bricks"},
        {pos: [0, 0, 6], state: "minecraft:deepslate_bricks"},
        {pos: [0, 0, 7], state: "minecraft:deepslate_bricks"},
        {pos: [0, 0, 8], state: "minecraft:deepslate_bricks"},
        {pos: [0, 0, 9], state: "minecraft:deepslate_bricks"},
        {pos: [0, 0, 10], state: "minecraft:deepslate_bricks"},
        {pos: [0, 0, 11], state: "minecraft:deepslate_bricks"},
        {pos: [0, 0, 12], state: "minecraft:deepslate{axis:y}"},
        {pos: [1, 0, 0], state: "minecraft:deepslate{axis:y}"},
        {pos: [1, 0, 1], state: "minecraft:deepslate_bricks"},
        {pos: [1, 0, 2], state: "minecraft:deepslate_bricks"},
        {pos: [1, 0, 3], state: "minecraft:deepslate_bricks"},
        {pos: [1, 0, 4], state: "minecraft:deepslate_bricks"},
        {pos: [1, 0, 5], state: "minecraft:deepslate{axis:y}"},
        {pos: [1, 0, 6], state: "minecraft:deepslate{axis:y}"},
        {pos: [1, 0, 7], state: "minecraft:deepslate_bricks"},
        {pos: [1, 0, 8], state: "minecraft:deepslate_bricks"},
        {pos: [1, 0, 9], state: "minecraft:deepslate_bricks"},
        {pos: [1, 0, 10], state: "minecraft:deepslate_bricks"},
        {pos: [1, 0, 11], state: "minecraft:deepslate_bricks"},
        {pos: [1, 0, 12], state: "minecraft:deepslate{axis:y}"},
        {pos: [2, 0, 0], state: "minecraft:deepslate{axis:y}"},
        {pos: [2, 0, 1], state: "minecraft:deepslate_bricks"},
        {pos: [2, 0, 2], state: "minecraft:deepslate_bricks"},
        {pos: [2, 0, 3], state: "minecraft:deepslate_bricks"},
        {pos: [2, 0, 4], state: "minecraft:deepslate_bricks"},
        {pos: [2, 0, 5], state: "minecraft:deepslate{axis:y}"},
        {pos: [2, 0, 6], state: "minecraft:deepslate{axis:y}"},
        {pos: [2, 0, 7], state: "minecraft:deepslate{axis:y}"},
        {pos: [2, 0, 8], state: "minecraft:deepslate_bricks"},
        {pos: [2, 0, 9], state: "minecraft:deepslate_bricks"},
        {pos: [2, 0, 10], state: "minecraft:deepslate_bricks"},
        {pos: [2, 0, 11], state: "minecraft:deepslate_bricks"},
        {pos: [2, 0, 12], state: "minecraft:deepslate{axis:y}"},
        {pos: [3, 0, 0], state: "minecraft:deepslate_bricks"},
        {pos: [3, 0, 1], state: "minecraft:deepslate_bricks"},
        {pos: [3, 0, 2], state: "minecraft:deepslate_bricks"},
        {pos: [3, 0, 3], state: "minecraft:deepslate_bricks"},
        {pos: [3, 0, 4], state: "minecraft:deepslate_bricks"},
        {pos: [3, 0, 5], state: "minecraft:deepslate{axis:y}"},
        {pos: [3, 0, 6], state: "minecraft:deepslate_bricks"},
        {pos: [3, 0, 7], state: "minecraft:deepslate_bricks"},
        {pos: [3, 0, 8], state: "minecraft:deepslate_bricks"},
        {pos: [3, 0, 9], state: "minecraft:deepslate_bricks"},
        {pos: [3, 0, 10], state: "minecraft:deepslate_bricks"},
        {pos: [3, 0, 11], state: "minecraft:deepslate_bricks"},
        {pos: [3, 0, 12], state: "minecraft:deepslate{axis:y}"},
        {pos: [4, 0, 0], state: "minecraft:deepslate_bricks"},
        {pos: [4, 0, 1], state: "minecraft:deepslate{axis:y}"},
        {pos: [4, 0, 2], state: "minecraft:deepslate_bricks"},
        {pos: [4, 0, 3], state: "minecraft:deepslate_bricks"},
        {pos: [4, 0, 4], state: "minecraft:deepslate_bricks"},
        {pos: [4, 0, 5], state: "minecraft:deepslate_bricks"},
        {pos: [4, 0, 6], state: "minecraft:deepslate_bricks"},
        {pos: [4, 0, 7], state: "minecraft:deepslate_bricks"},
        {pos: [4, 0, 8], state: "minecraft:deepslate_bricks"},
        {pos: [4, 0, 9], state: "minecraft:deepslate_bricks"},
        {pos: [4, 0, 10], state: "minecraft:deepslate_bricks"},
        {pos: [4, 0, 11], state: "minecraft:deepslate_bricks"},
        {pos: [4, 0, 12], state: "minecraft:deepslate{axis:y}"},
        {pos: [5, 0, 0], state: "minecraft:deepslate_bricks"},
        {pos: [5, 0, 1], state: "minecraft:deepslate{axis:y}"},
        {pos: [5, 0, 2], state: "minecraft:deepslate_bricks"},
        {pos: [5, 0, 3], state: "minecraft:deepslate_bricks"},
        {pos: [5, 0, 4], state: "minecraft:deepslate_bricks"},
        {pos: [5, 0, 5], state: "minecraft:deepslate{axis:y}"},
        {pos: [5, 0, 6], state: "minecraft:deepslate{axis:y}"},
        {pos: [5, 0, 7], state: "minecraft:deepslate{axis:y}"},
        {pos: [5, 0, 8], state: "minecraft:deepslate_bricks"},
        {pos: [5, 0, 9], state: "minecraft:deepslate_bricks"},
        {pos: [5, 0, 10], state: "minecraft:deepslate_bricks"},
        {pos: [5, 0, 11], state: "minecraft:deepslate_bricks"},
        {pos: [5, 0, 12], state: "minecraft:deepslate{axis:y}"},
        {pos: [6, 0, 1], state: "minecraft:deepslate_bricks"},
        {pos: [6, 0, 2], state: "minecraft:deepslate_bricks"},
        {pos: [6, 0, 3], state: "minecraft:deepslate{axis:y}"},
        {pos: [6, 0, 4], state: "minecraft:deepslate{axis:y}"},
        {pos: [6, 0, 5], state: "minecraft:deepslate{axis:y}"},
        {pos: [6, 0, 6], state: "minecraft:deepslate_bricks"},
        {pos: [6, 0, 7], state: "minecraft:deepslate_bricks"},
        {pos: [6, 0, 8], state: "minecraft:deepslate_bricks"},
        {pos: [6, 0, 9], state: "minecraft:deepslate_bricks"},
        {pos: [6, 0, 10], state: "minecraft:deepslate_bricks"},
        {pos: [6, 0, 11], state: "minecraft:deepslate_bricks"},
        {pos: [6, 0, 12], state: "minecraft:deepslate{axis:y}"},
        {pos: [7, 0, 0], state: "minecraft:deepslate_bricks"},
        {pos: [7, 0, 1], state: "minecraft:deepslate_bricks"},
        {pos: [7, 0, 2], state: "minecraft:deepslate{axis:y}"},
        {pos: [7, 0, 3], state: "minecraft:deepslate{axis:y}"},
        {pos: [7, 0, 4], state: "minecraft:deepslate{axis:y}"},
        {pos: [7, 0, 5], state: "minecraft:deepslate_bricks"},
        {pos: [7, 0, 6], state: "minecraft:deepslate_bricks"},
        {pos: [7, 0, 7], state: "minecraft:deepslate{axis:y}"},
        {pos: [7, 0, 8], state: "minecraft:deepslate{axis:y}"},
        {pos: [7, 0, 9], state: "minecraft:deepslate_bricks"},
        {pos: [7, 0, 10], state: "minecraft:deepslate_bricks"},
        {pos: [7, 0, 11], state: "minecraft:deepslate_bricks"},
        {pos: [7, 0, 12], state: "minecraft:deepslate{axis:y}"},
        {pos: [8, 0, 0], state: "minecraft:deepslate_bricks"},
        {pos: [8, 0, 1], state: "minecraft:deepslate{axis:y}"},
        {pos: [8, 0, 2], state: "minecraft:deepslate{axis:y}"},
        {pos: [8, 0, 3], state: "minecraft:deepslate_bricks"},
        {pos: [8, 0, 4], state: "minecraft:deepslate_bricks"},
        {pos: [8, 0, 5], state: "minecraft:deepslate_bricks"},
        {pos: [8, 0, 6], state: "minecraft:deepslate_bricks"},
        {pos: [8, 0, 7], state: "minecraft:deepslate{axis:y}"},
        {pos: [8, 0, 8], state: "minecraft:deepslate_bricks"},
        {pos: [8, 0, 9], state: "minecraft:deepslate_bricks"},
        {pos: [8, 0, 10], state: "minecraft:deepslate_bricks"},
        {pos: [8, 0, 11], state: "minecraft:deepslate_bricks"},
        {pos: [8, 0, 12], state: "minecraft:deepslate{axis:y}"},
        {pos: [9, 0, 0], state: "minecraft:deepslate_bricks"},
        {pos: [9, 0, 1], state: "minecraft:deepslate_bricks"},
        {pos: [9, 0, 2], state: "minecraft:deepslate_bricks"},
        {pos: [9, 0, 3], state: "minecraft:deepslate_bricks"},
        {pos: [9, 0, 4], state: "minecraft:deepslate_bricks"},
        {pos: [9, 0, 5], state: "minecraft:deepslate_bricks"},
        {pos: [9, 0, 6], state: "minecraft:deepslate_bricks"},
        {pos: [9, 0, 7], state: "minecraft:deepslate_bricks"},
        {pos: [9, 0, 8], state: "minecraft:deepslate_bricks"},
        {pos: [9, 0, 9], state: "minecraft:deepslate_bricks"},
        {pos: [9, 0, 10], state: "minecraft:deepslate_bricks"},
        {pos: [9, 0, 11], state: "minecraft:deepslate_bricks"},
        {pos: [9, 0, 12], state: "minecraft:deepslate{axis:y}"},
        {pos: [10, 0, 0], state: "minecraft:deepslate_bricks"},
        {pos: [10, 0, 1], state: "minecraft:deepslate_bricks"},
        {pos: [10, 0, 2], state: "minecraft:deepslate_bricks"},
        {pos: [10, 0, 3], state: "minecraft:deepslate_bricks"},
        {pos: [10, 0, 4], state: "minecraft:deepslate_bricks"},
        {pos: [10, 0, 5], state: "minecraft:deepslate_bricks"},
        {pos: [10, 0, 6], state: "minecraft:deepslate_bricks"},
        {pos: [10, 0, 7], state: "minecraft:deepslate_bricks"},
        {pos: [10, 0, 8], state: "minecraft:deepslate_bricks"},
        {pos: [10, 0, 9], state: "minecraft:deepslate_bricks"},
        {pos: [10, 0, 10], state: "minecraft:deepslate_bricks"},
        {pos: [10, 0, 11], state: "minecraft:deepslate_bricks"},
        {pos: [10, 0, 12], state: "minecraft:deepslate{axis:y}"},
        {pos: [11, 0, 0], state: "minecraft:deepslate_bricks"},
        {pos: [11, 0, 1], state: "minecraft:deepslate_bricks"},
        {pos: [11, 0, 2], state: "minecraft:deepslate_bricks"},
        {pos: [11, 0, 3], state: "minecraft:deepslate_bricks"},
        {pos: [11, 0, 4], state: "minecraft:deepslate_bricks"},
        {pos: [11, 0, 5], state: "minecraft:deepslate_bricks"},
        {pos: [11, 0, 6], state: "minecraft:deepslate_bricks"},
        {pos: [11, 0, 7], state: "minecraft:deepslate_bricks"},
        {pos: [11, 0, 8], state: "minecraft:deepslate_bricks"},
        {pos: [11, 0, 9], state: "minecraft:deepslate_bricks"},
        {pos: [11, 0, 10], state: "minecraft:deepslate_bricks"},
        {pos: [11, 0, 11], state: "minecraft:deepslate_bricks"},
        {pos: [11, 0, 12], state: "minecraft:deepslate{axis:y}"},
        {pos: [12, 0, 0], state: "minecraft:deepslate{axis:y}"},
        {pos: [12, 0, 1], state: "minecraft:deepslate{axis:y}"},
        {pos: [12, 0, 2], state: "minecraft:deepslate{axis:y}"},
        {pos: [12, 0, 3], state: "minecraft:deepslate{axis:y}"},
        {pos: [12, 0, 4], state: "minecraft:deepslate{axis:y}"},
        {pos: [12, 0, 5], state: "minecraft:deepslate{axis:y}"},
        {pos: [12, 0, 6], state: "minecraft:deepslate{axis:y}"},
        {pos: [12, 0, 7], state: "minecraft:deepslate{axis:y}"},
        {pos: [12, 0, 8], state: "minecraft:deepslate{axis:y}"},
        {pos: [12, 0, 9], state: "minecraft:deepslate{axis:y}"},
        {pos: [12, 0, 10], state: "minecraft:deepslate{axis:y}"},
        {pos: [12, 0, 11], state: "minecraft:deepslate{axis:y}"},
        {pos: [12, 0, 12], state: "minecraft:deepslate{axis:y}"},
        {pos: [0, 1, 0], state: "minecraft:deepslate{axis:y}"},
        {pos: [0, 1, 1], state: "minecraft:gray_wool"},
        {pos: [0, 1, 2], state: "minecraft:deepslate{axis:y}"},
        {pos: [0, 1, 10], state: "minecraft:gray_wool"},
        {pos: [0, 1, 11], state: "minecraft:gray_wool"},
        {pos: [0, 1, 12], state: "minecraft:deepslate{axis:y}"},
        {pos: [1, 1, 0], state: "minecraft:gray_wool"},
        {pos: [1, 1, 1], state: "minecraft:gray_wool"},
        {pos: [1, 1, 2], state: "minecraft:deepslate{axis:y}"},
        {pos: [1, 1, 10], state: "minecraft:deepslate_bricks"},
        {pos: [1, 1, 11], state: "minecraft:gray_wool"},
        {pos: [1, 1, 12], state: "minecraft:deepslate{axis:y}"},
        {pos: [2, 1, 0], state: "minecraft:deepslate{axis:y}"},
        {pos: [2, 1, 1], state: "minecraft:deepslate{axis:y}"},
        {pos: [2, 1, 2], state: "minecraft:deepslate{axis:y}"},
        {pos: [2, 1, 3], state: "minecraft:gray_wool"},
        {pos: [2, 1, 10], state: "minecraft:deepslate_bricks"},
        {pos: [2, 1, 11], state: "minecraft:gray_wool"},
        {pos: [2, 1, 12], state: "minecraft:deepslate_bricks"},
        {pos: [3, 1, 2], state: "minecraft:gray_wool"},
        {pos: [3, 1, 3], state: "minecraft:gray_wool"},
        {pos: [3, 1, 10], state: "minecraft:gray_wool"},
        {pos: [3, 1, 11], state: "minecraft:gray_wool"},
        {pos: [3, 1, 12], state: "minecraft:deepslate_bricks"},
        {pos: [4, 1, 10], state: "minecraft:deepslate_bricks"},
        {pos: [4, 1, 11], state: "minecraft:gray_wool"},
        {pos: [4, 1, 12], state: "minecraft:deepslate_bricks"},
        {pos: [5, 1, 10], state: "minecraft:deepslate_bricks"},
        {pos: [5, 1, 11], state: "minecraft:gray_wool"},
        {pos: [5, 1, 12], state: "minecraft:deepslate_bricks"},
        {pos: [6, 1, 10], state: "minecraft:gray_wool"},
        {pos: [6, 1, 11], state: "minecraft:gray_wool"},
        {pos: [6, 1, 12], state: "minecraft:deepslate{axis:y}"},
        {pos: [7, 1, 10], state: "minecraft:deepslate_bricks"},
        {pos: [7, 1, 11], state: "minecraft:gray_wool"},
        {pos: [7, 1, 12], state: "minecraft:deepslate{axis:y}"},
        {pos: [8, 1, 10], state: "minecraft:deepslate_bricks"},
        {pos: [8, 1, 11], state: "minecraft:gray_wool"},
        {pos: [8, 1, 12], state: "minecraft:deepslate{axis:y}"},
        {pos: [9, 1, 10], state: "minecraft:gray_wool"},
        {pos: [9, 1, 11], state: "minecraft:gray_wool"},
        {pos: [9, 1, 12], state: "minecraft:deepslate{axis:y}"},
        {pos: [10, 1, 0], state: "minecraft:gray_wool"},
        {pos: [10, 1, 1], state: "minecraft:deepslate_bricks"},
        {pos: [10, 1, 2], state: "minecraft:deepslate_bricks"},
        {pos: [10, 1, 3], state: "minecraft:gray_wool"},
        {pos: [10, 1, 4], state: "minecraft:deepslate_bricks"},
        {pos: [10, 1, 5], state: "minecraft:deepslate_bricks"},
        {pos: [10, 1, 6], state: "minecraft:gray_wool"},
        {pos: [10, 1, 7], state: "minecraft:deepslate_bricks"},
        {pos: [10, 1, 8], state: "minecraft:deepslate_bricks"},
        {pos: [10, 1, 9], state: "minecraft:gray_wool"},
        {pos: [10, 1, 10], state: "minecraft:gray_wool"},
        {pos: [10, 1, 11], state: "minecraft:gray_wool"},
        {pos: [10, 1, 12], state: "minecraft:deepslate{axis:y}"},
        {pos: [11, 1, 0], state: "minecraft:gray_wool"},
        {pos: [11, 1, 1], state: "minecraft:gray_wool"},
        {pos: [11, 1, 2], state: "minecraft:gray_wool"},
        {pos: [11, 1, 3], state: "minecraft:gray_wool"},
        {pos: [11, 1, 4], state: "minecraft:gray_wool"},
        {pos: [11, 1, 5], state: "minecraft:gray_wool"},
        {pos: [11, 1, 6], state: "minecraft:gray_wool"},
        {pos: [11, 1, 7], state: "minecraft:gray_wool"},
        {pos: [11, 1, 8], state: "minecraft:gray_wool"},
        {pos: [11, 1, 9], state: "minecraft:gray_wool"},
        {pos: [11, 1, 10], state: "minecraft:gray_wool"},
        {pos: [11, 1, 11], state: "minecraft:gray_wool"},
        {pos: [11, 1, 12], state: "minecraft:deepslate_bricks"},
        {pos: [12, 1, 0], state: "minecraft:deepslate{axis:y}"},
        {pos: [12, 1, 1], state: "minecraft:deepslate{axis:y}"},
        {pos: [12, 1, 2], state: "minecraft:deepslate_bricks"},
        {pos: [12, 1, 3], state: "minecraft:deepslate_bricks"},
        {pos: [12, 1, 4], state: "minecraft:deepslate_bricks"},
        {pos: [12, 1, 5], state: "minecraft:deepslate_bricks"},
        {pos: [12, 1, 6], state: "minecraft:deepslate{axis:y}"},
        {pos: [12, 1, 7], state: "minecraft:deepslate{axis:y}"},
        {pos: [12, 1, 8], state: "minecraft:deepslate{axis:y}"},
        {pos: [12, 1, 9], state: "minecraft:deepslate{axis:y}"},
        {pos: [12, 1, 10], state: "minecraft:deepslate{axis:y}"},
        {pos: [12, 1, 11], state: "minecraft:deepslate_bricks"},
        {pos: [12, 1, 12], state: "minecraft:deepslate_bricks"},
        {pos: [0, 2, 0], state: "minecraft:deepslate{axis:y}"},
        {pos: [0, 2, 1], state: "minecraft:gray_wool"},
        {pos: [0, 2, 2], state: "minecraft:deepslate_bricks"},
        {pos: [0, 2, 10], state: "minecraft:gray_wool"},
        {pos: [0, 2, 11], state: "minecraft:gray_wool"},
        {pos: [0, 2, 12], state: "minecraft:deepslate_tiles"},
        {pos: [1, 2, 0], state: "minecraft:gray_wool"},
        {pos: [1, 2, 1], state: "minecraft:gray_wool"},
        {pos: [1, 2, 2], state: "minecraft:deepslate_bricks"},
        {pos: [1, 2, 10], state: "minecraft:chiseled_deepslate"},
        {pos: [1, 2, 11], state: "minecraft:gray_wool"},
        {pos: [1, 2, 12], state: "minecraft:deepslate_tiles"},
        {pos: [2, 2, 0], state: "minecraft:deepslate_bricks"},
        {pos: [2, 2, 1], state: "minecraft:deepslate_bricks"},
        {pos: [2, 2, 2], state: "minecraft:deepslate_bricks"},
        {pos: [2, 2, 3], state: "minecraft:gray_wool"},
        {pos: [2, 2, 10], state: "minecraft:chiseled_deepslate"},
        {pos: [2, 2, 11], state: "minecraft:gray_wool"},
        {pos: [2, 2, 12], state: "minecraft:deepslate_bricks"},
        {pos: [3, 2, 2], state: "minecraft:gray_wool"},
        {pos: [3, 2, 3], state: "minecraft:gray_wool"},
        {pos: [3, 2, 10], state: "minecraft:gray_wool"},
        {pos: [3, 2, 11], state: "minecraft:gray_wool"},
        {pos: [3, 2, 12], state: "minecraft:chiseled_deepslate"},
        {pos: [4, 2, 10], state: "minecraft:chiseled_deepslate"},
        {pos: [4, 2, 11], state: "minecraft:gray_wool"},
        {pos: [4, 2, 12], state: "minecraft:chiseled_deepslate"},
        {pos: [5, 2, 10], state: "minecraft:chiseled_deepslate"},
        {pos: [5, 2, 11], state: "minecraft:gray_wool"},
        {pos: [5, 2, 12], state: "minecraft:deepslate_bricks"},
        {pos: [6, 2, 10], state: "minecraft:gray_wool"},
        {pos: [6, 2, 11], state: "minecraft:gray_wool"},
        {pos: [6, 2, 12], state: "minecraft:deepslate_tiles"},
        {pos: [7, 2, 10], state: "minecraft:chiseled_deepslate"},
        {pos: [7, 2, 11], state: "minecraft:gray_wool"},
        {pos: [7, 2, 12], state: "minecraft:deepslate_tiles"},
        {pos: [8, 2, 10], state: "minecraft:chiseled_deepslate"},
        {pos: [8, 2, 11], state: "minecraft:gray_wool"},
        {pos: [8, 2, 12], state: "minecraft:deepslate_tiles"},
        {pos: [9, 2, 10], state: "minecraft:gray_wool"},
        {pos: [9, 2, 11], state: "minecraft:gray_wool"},
        {pos: [9, 2, 12], state: "minecraft:deepslate_tiles"},
        {pos: [10, 2, 0], state: "minecraft:gray_wool"},
        {pos: [10, 2, 1], state: "minecraft:chiseled_deepslate"},
        {pos: [10, 2, 2], state: "minecraft:chiseled_deepslate"},
        {pos: [10, 2, 3], state: "minecraft:gray_wool"},
        {pos: [10, 2, 4], state: "minecraft:chiseled_deepslate"},
        {pos: [10, 2, 5], state: "minecraft:chiseled_deepslate"},
        {pos: [10, 2, 6], state: "minecraft:gray_wool"},
        {pos: [10, 2, 7], state: "minecraft:chiseled_deepslate"},
        {pos: [10, 2, 8], state: "minecraft:chiseled_deepslate"},
        {pos: [10, 2, 9], state: "minecraft:gray_wool"},
        {pos: [10, 2, 10], state: "minecraft:gray_wool"},
        {pos: [10, 2, 11], state: "minecraft:gray_wool"},
        {pos: [10, 2, 12], state: "minecraft:deepslate_tiles"},
        {pos: [11, 2, 0], state: "minecraft:gray_wool"},
        {pos: [11, 2, 1], state: "minecraft:gray_wool"},
        {pos: [11, 2, 2], state: "minecraft:gray_wool"},
        {pos: [11, 2, 3], state: "minecraft:gray_wool"},
        {pos: [11, 2, 4], state: "minecraft:gray_wool"},
        {pos: [11, 2, 5], state: "minecraft:gray_wool"},
        {pos: [11, 2, 6], state: "minecraft:gray_wool"},
        {pos: [11, 2, 7], state: "minecraft:gray_wool"},
        {pos: [11, 2, 8], state: "minecraft:gray_wool"},
        {pos: [11, 2, 9], state: "minecraft:gray_wool"},
        {pos: [11, 2, 10], state: "minecraft:gray_wool"},
        {pos: [11, 2, 11], state: "minecraft:gray_wool"},
        {pos: [11, 2, 12], state: "minecraft:deepslate_bricks"},
        {pos: [12, 2, 0], state: "minecraft:deepslate_tiles"},
        {pos: [12, 2, 1], state: "minecraft:deepslate_tiles"},
        {pos: [12, 2, 2], state: "minecraft:deepslate_bricks"},
        {pos: [12, 2, 3], state: "minecraft:chiseled_deepslate"},
        {pos: [12, 2, 4], state: "minecraft:chiseled_deepslate"},
        {pos: [12, 2, 5], state: "minecraft:deepslate_bricks"},
        {pos: [12, 2, 6], state: "minecraft:deepslate_tiles"},
        {pos: [12, 2, 7], state: "minecraft:deepslate_tiles"},
        {pos: [12, 2, 8], state: "minecraft:deepslate_tiles"},
        {pos: [12, 2, 9], state: "minecraft:deepslate_tiles"},
        {pos: [12, 2, 10], state: "minecraft:deepslate_tiles"},
        {pos: [12, 2, 11], state: "minecraft:deepslate_bricks"},
        {pos: [12, 2, 12], state: "minecraft:chiseled_deepslate"},
        {pos: [0, 3, 0], state: "minecraft:deepslate_bricks"},
        {pos: [0, 3, 1], state: "minecraft:gray_wool"},
        {pos: [0, 3, 2], state: "minecraft:deepslate_bricks"},
        {pos: [0, 3, 3], state: "minecraft:chiseled_deepslate"},
        {pos: [0, 3, 10], state: "minecraft:gray_wool"},
        {pos: [0, 3, 11], state: "minecraft:gray_wool"},
        {pos: [1, 3, 0], state: "minecraft:gray_wool"},
        {pos: [1, 3, 1], state: "minecraft:gray_wool"},
        {pos: [1, 3, 2], state: "minecraft:deepslate_bricks"},
        {pos: [1, 3, 11], state: "minecraft:gray_wool"},
        {pos: [2, 3, 0], state: "minecraft:deepslate_bricks"},
        {pos: [2, 3, 1], state: "minecraft:deepslate_bricks"},
        {pos: [2, 3, 2], state: "minecraft:deepslate_bricks"},
        {pos: [2, 3, 3], state: "minecraft:gray_wool"},
        {pos: [2, 3, 11], state: "minecraft:gray_wool"},
        {pos: [2, 3, 12], state: "minecraft:deepslate_bricks"},
        {pos: [3, 3, 0], state: "minecraft:chiseled_deepslate"},
        {pos: [3, 3, 2], state: "minecraft:gray_wool"},
        {pos: [3, 3, 3], state: "minecraft:gray_wool"},
        {pos: [3, 3, 10], state: "minecraft:gray_wool"},
        {pos: [3, 3, 11], state: "minecraft:gray_wool"},
        {pos: [3, 3, 12], state: "minecraft:chiseled_deepslate"},
        {pos: [4, 3, 11], state: "minecraft:gray_wool"},
        {pos: [4, 3, 12], state: "minecraft:chiseled_deepslate"},
        {pos: [5, 3, 11], state: "minecraft:gray_wool"},
        {pos: [5, 3, 12], state: "minecraft:deepslate_bricks"},
        {pos: [6, 3, 10], state: "minecraft:gray_wool"},
        {pos: [6, 3, 11], state: "minecraft:gray_wool"},
        {pos: [7, 3, 11], state: "minecraft:gray_wool"},
        {pos: [8, 3, 11], state: "minecraft:gray_wool"},
        {pos: [9, 3, 10], state: "minecraft:gray_wool"},
        {pos: [9, 3, 11], state: "minecraft:gray_wool"},
        {pos: [10, 3, 0], state: "minecraft:gray_wool"},
        {pos: [10, 3, 3], state: "minecraft:gray_wool"},
        {pos: [10, 3, 6], state: "minecraft:gray_wool"},
        {pos: [10, 3, 9], state: "minecraft:gray_wool"},
        {pos: [10, 3, 10], state: "minecraft:gray_wool"},
        {pos: [10, 3, 11], state: "minecraft:gray_wool"},
        {pos: [11, 3, 0], state: "minecraft:gray_wool"},
        {pos: [11, 3, 1], state: "minecraft:gray_wool"},
        {pos: [11, 3, 2], state: "minecraft:gray_wool"},
        {pos: [11, 3, 3], state: "minecraft:gray_wool"},
        {pos: [11, 3, 4], state: "minecraft:gray_wool"},
        {pos: [11, 3, 5], state: "minecraft:gray_wool"},
        {pos: [11, 3, 6], state: "minecraft:gray_wool"},
        {pos: [11, 3, 7], state: "minecraft:gray_wool"},
        {pos: [11, 3, 8], state: "minecraft:gray_wool"},
        {pos: [11, 3, 9], state: "minecraft:gray_wool"},
        {pos: [11, 3, 10], state: "minecraft:gray_wool"},
        {pos: [11, 3, 11], state: "minecraft:gray_wool"},
        {pos: [11, 3, 12], state: "minecraft:deepslate_bricks"},
        {pos: [12, 3, 2], state: "minecraft:deepslate_bricks"},
        {pos: [12, 3, 3], state: "minecraft:chiseled_deepslate"},
        {pos: [12, 3, 4], state: "minecraft:chiseled_deepslate"},
        {pos: [12, 3, 5], state: "minecraft:deepslate_bricks"},
        {pos: [12, 3, 11], state: "minecraft:deepslate_bricks"},
        {pos: [12, 3, 12], state: "minecraft:chiseled_deepslate"},
        {pos: [0, 4, 0], state: "minecraft:deepslate_bricks"},
        {pos: [0, 4, 1], state: "minecraft:deepslate_bricks"},
        {pos: [0, 4, 2], state: "minecraft:deepslate_bricks"},
        {pos: [0, 4, 10], state: "minecraft:gray_wool"},
        {pos: [0, 4, 11], state: "minecraft:gray_wool"},
        {pos: [0, 4, 12], state: "minecraft:gray_wool"},
        {pos: [1, 4, 0], state: "minecraft:deepslate_bricks"},
        {pos: [1, 4, 1], state: "minecraft:deepslate_bricks"},
        {pos: [1, 4, 2], state: "minecraft:deepslate_bricks"},
        {pos: [1, 4, 11], state: "minecraft:gray_wool"},
        {pos: [1, 4, 12], state: "minecraft:gray_wool"},
        {pos: [2, 4, 0], state: "minecraft:deepslate_bricks"},
        {pos: [2, 4, 1], state: "minecraft:deepslate_bricks"},
        {pos: [2, 4, 2], state: "minecraft:deepslate_bricks"},
        {pos: [2, 4, 3], state: "minecraft:gray_wool"},
        {pos: [2, 4, 11], state: "minecraft:gray_wool"},
        {pos: [2, 4, 12], state: "minecraft:gray_wool"},
        {pos: [2, 4, 13], state: "minecraft:deepslate_bricks"},
        {pos: [3, 4, 2], state: "minecraft:gray_wool"},
        {pos: [3, 4, 3], state: "minecraft:gray_wool"},
        {pos: [3, 4, 10], state: "minecraft:gray_wool"},
        {pos: [3, 4, 11], state: "minecraft:gray_wool"},
        {pos: [3, 4, 12], state: "minecraft:gray_wool"},
        {pos: [3, 4, 13], state: "minecraft:deepslate_bricks"},
        {pos: [4, 4, 11], state: "minecraft:gray_wool"},
        {pos: [4, 4, 12], state: "minecraft:gray_wool"},
        {pos: [4, 4, 13], state: "minecraft:deepslate_bricks"},
        {pos: [5, 4, 11], state: "minecraft:gray_wool"},
        {pos: [5, 4, 12], state: "minecraft:gray_wool"},
        {pos: [5, 4, 13], state: "minecraft:deepslate_bricks"},
        {pos: [6, 4, 10], state: "minecraft:gray_wool"},
        {pos: [6, 4, 11], state: "minecraft:gray_wool"},
        {pos: [6, 4, 12], state: "minecraft:gray_wool"},
        {pos: [7, 4, 11], state: "minecraft:gray_wool"},
        {pos: [7, 4, 12], state: "minecraft:gray_wool"},
        {pos: [8, 4, 11], state: "minecraft:gray_wool"},
        {pos: [8, 4, 12], state: "minecraft:gray_wool"},
        {pos: [9, 4, 10], state: "minecraft:gray_wool"},
        {pos: [9, 4, 11], state: "minecraft:gray_wool"},
        {pos: [9, 4, 12], state: "minecraft:gray_wool"},
        {pos: [10, 4, 0], state: "minecraft:gray_wool"},
        {pos: [10, 4, 3], state: "minecraft:gray_wool"},
        {pos: [10, 4, 6], state: "minecraft:gray_wool"},
        {pos: [10, 4, 9], state: "minecraft:gray_wool"},
        {pos: [10, 4, 10], state: "minecraft:gray_wool"},
        {pos: [10, 4, 11], state: "minecraft:gray_wool"},
        {pos: [10, 4, 12], state: "minecraft:gray_wool"},
        {pos: [11, 4, 0], state: "minecraft:gray_wool"},
        {pos: [11, 4, 1], state: "minecraft:gray_wool"},
        {pos: [11, 4, 2], state: "minecraft:gray_wool"},
        {pos: [11, 4, 3], state: "minecraft:gray_wool"},
        {pos: [11, 4, 4], state: "minecraft:gray_wool"},
        {pos: [11, 4, 5], state: "minecraft:gray_wool"},
        {pos: [11, 4, 6], state: "minecraft:gray_wool"},
        {pos: [11, 4, 7], state: "minecraft:gray_wool"},
        {pos: [11, 4, 8], state: "minecraft:gray_wool"},
        {pos: [11, 4, 9], state: "minecraft:gray_wool"},
        {pos: [11, 4, 10], state: "minecraft:gray_wool"},
        {pos: [11, 4, 11], state: "minecraft:gray_wool"},
        {pos: [11, 4, 12], state: "minecraft:gray_wool"},
        {pos: [11, 4, 13], state: "minecraft:deepslate_bricks"},
        {pos: [12, 4, 0], state: "minecraft:gray_wool"},
        {pos: [12, 4, 1], state: "minecraft:gray_wool"},
        {pos: [12, 4, 2], state: "minecraft:gray_wool"},
        {pos: [12, 4, 3], state: "minecraft:gray_wool"},
        {pos: [12, 4, 4], state: "minecraft:gray_wool"},
        {pos: [12, 4, 5], state: "minecraft:gray_wool"},
        {pos: [12, 4, 6], state: "minecraft:gray_wool"},
        {pos: [12, 4, 7], state: "minecraft:gray_wool"},
        {pos: [12, 4, 8], state: "minecraft:gray_wool"},
        {pos: [12, 4, 9], state: "minecraft:gray_wool"},
        {pos: [12, 4, 10], state: "minecraft:gray_wool"},
        {pos: [12, 4, 11], state: "minecraft:gray_wool"},
        {pos: [12, 4, 12], state: "minecraft:gray_wool"},
        {pos: [12, 4, 13], state: "minecraft:deepslate_bricks"},
        {pos: [13, 4, 2], state: "minecraft:deepslate_bricks"},
        {pos: [13, 4, 3], state: "minecraft:deepslate_bricks"},
        {pos: [13, 4, 4], state: "minecraft:deepslate_bricks"},
        {pos: [13, 4, 5], state: "minecraft:deepslate_bricks"},
        {pos: [13, 4, 11], state: "minecraft:deepslate_bricks"},
        {pos: [13, 4, 12], state: "minecraft:deepslate_bricks"},
        {pos: [13, 4, 13], state: "minecraft:deepslate_bricks"},
        {pos: [0, 5, 1], state: "minecraft:gray_wool"},
        {pos: [0, 5, 13], state: "minecraft:chiseled_deepslate"},
        {pos: [1, 5, 0], state: "minecraft:gray_wool"},
        {pos: [1, 5, 1], state: "minecraft:gray_wool"},
        {pos: [1, 5, 10], state: "minecraft:chiseled_deepslate"},
        {pos: [1, 5, 13], state: "minecraft:chiseled_deepslate"},
        {pos: [2, 5, 3], state: "minecraft:gray_wool"},
        {pos: [2, 5, 10], state: "minecraft:chiseled_deepslate"},
        {pos: [3, 5, 2], state: "minecraft:gray_wool"},
        {pos: [3, 5, 3], state: "minecraft:gray_wool"},
        {pos: [3, 5, 13], state: "minecraft:chiseled_deepslate"},
        {pos: [4, 5, 10], state: "minecraft:chiseled_deepslate"},
        {pos: [4, 5, 13], state: "minecraft:chiseled_deepslate"},
        {pos: [5, 5, 10], state: "minecraft:chiseled_deepslate"},
        {pos: [6, 5, 13], state: "minecraft:chiseled_deepslate"},
        {pos: [7, 5, 10], state: "minecraft:chiseled_deepslate"},
        {pos: [7, 5, 13], state: "minecraft:chiseled_deepslate"},
        {pos: [8, 5, 10], state: "minecraft:chiseled_deepslate"},
        {pos: [9, 5, 13], state: "minecraft:chiseled_deepslate"},
        {pos: [10, 5, 1], state: "minecraft:chiseled_deepslate"},
        {pos: [10, 5, 2], state: "minecraft:chiseled_deepslate"},
        {pos: [10, 5, 4], state: "minecraft:chiseled_deepslate"},
        {pos: [10, 5, 5], state: "minecraft:chiseled_deepslate"},
        {pos: [10, 5, 7], state: "minecraft:chiseled_deepslate"},
        {pos: [10, 5, 8], state: "minecraft:chiseled_deepslate"},
        {pos: [10, 5, 13], state: "minecraft:chiseled_deepslate"},
        {pos: [12, 5, 13], state: "minecraft:chiseled_deepslate"},
        {pos: [13, 5, 0], state: "minecraft:chiseled_deepslate"},
        {pos: [13, 5, 1], state: "minecraft:chiseled_deepslate"},
        {pos: [13, 5, 3], state: "minecraft:chiseled_deepslate"},
        {pos: [13, 5, 4], state: "minecraft:chiseled_deepslate"},
        {pos: [13, 5, 6], state: "minecraft:chiseled_deepslate"},
        {pos: [13, 5, 7], state: "minecraft:chiseled_deepslate"},
        {pos: [13, 5, 9], state: "minecraft:chiseled_deepslate"},
        {pos: [13, 5, 10], state: "minecraft:chiseled_deepslate"},
        {pos: [13, 5, 12], state: "minecraft:chiseled_deepslate"},
        {pos: [13, 5, 13], state: "minecraft:chiseled_deepslate"},
        {pos: [1, 6, 1], state: "minecraft:gray_wool"},
        {pos: [3, 6, 3], state: "minecraft:gray_wool"},
        {pos: [1, 1, 3], state: "minecraft:deepslate_brick_stairs{half:bottom,waterlogged:false,shape:straight,facing:east}"},
        {pos: [1, 1, 9], state: "minecraft:deepslate_brick_stairs{half:bottom,waterlogged:false,shape:straight,facing:south}"},
        {pos: [2, 1, 9], state: "minecraft:deepslate_brick_stairs{half:bottom,waterlogged:false,shape:straight,facing:south}"},
        {pos: [3, 1, 1], state: "minecraft:deepslate_brick_stairs{half:bottom,waterlogged:false,shape:straight,facing:south}"},
        {pos: [4, 1, 9], state: "minecraft:deepslate_brick_stairs{half:bottom,waterlogged:false,shape:straight,facing:south}"},
        {pos: [5, 1, 9], state: "minecraft:deepslate_brick_stairs{half:bottom,waterlogged:false,shape:straight,facing:south}"},
        {pos: [7, 1, 9], state: "minecraft:deepslate_brick_stairs{half:bottom,waterlogged:false,shape:straight,facing:south}"},
        {pos: [8, 1, 9], state: "minecraft:deepslate_brick_stairs{half:bottom,waterlogged:false,shape:straight,facing:south}"},
        {pos: [9, 1, 1], state: "minecraft:deepslate_brick_stairs{half:bottom,waterlogged:false,shape:straight,facing:east}"},
        {pos: [9, 1, 2], state: "minecraft:deepslate_brick_stairs{half:bottom,waterlogged:false,shape:straight,facing:east}"},
        {pos: [9, 1, 4], state: "minecraft:deepslate_brick_stairs{half:bottom,waterlogged:false,shape:straight,facing:east}"},
        {pos: [9, 1, 5], state: "minecraft:deepslate_brick_stairs{half:bottom,waterlogged:false,shape:straight,facing:east}"},
        {pos: [9, 1, 7], state: "minecraft:deepslate_brick_stairs{half:bottom,waterlogged:false,shape:straight,facing:east}"},
        {pos: [9, 1, 8], state: "minecraft:deepslate_brick_stairs{half:bottom,waterlogged:false,shape:straight,facing:east}"},
        {pos: [0, 3, 12], state: "minecraft:deepslate_tile_stairs{half:bottom,waterlogged:false,shape:straight,facing:north}"},
        {pos: [1, 3, 3], state: "minecraft:deepslate_tile_stairs{half:top,waterlogged:false,shape:straight,facing:north}"},
        {pos: [1, 3, 10], state: "minecraft:deepslate_tile_stairs{half:bottom,waterlogged:false,shape:straight,facing:south}"},
        {pos: [1, 3, 12], state: "minecraft:deepslate_tile_stairs{half:bottom,waterlogged:false,shape:straight,facing:north}"},
        {pos: [2, 3, 10], state: "minecraft:deepslate_tile_stairs{half:bottom,waterlogged:false,shape:straight,facing:south}"},
        {pos: [3, 3, 1], state: "minecraft:deepslate_tile_stairs{half:top,waterlogged:false,shape:straight,facing:west}"},
        {pos: [4, 3, 10], state: "minecraft:deepslate_tile_stairs{half:bottom,waterlogged:false,shape:straight,facing:south}"},
        {pos: [5, 3, 10], state: "minecraft:deepslate_tile_stairs{half:bottom,waterlogged:false,shape:straight,facing:south}"},
        {pos: [6, 3, 12], state: "minecraft:deepslate_tile_stairs{half:bottom,waterlogged:false,shape:straight,facing:north}"},
        {pos: [7, 3, 10], state: "minecraft:deepslate_tile_stairs{half:bottom,waterlogged:false,shape:straight,facing:south}"},
        {pos: [7, 3, 12], state: "minecraft:deepslate_tile_stairs{half:bottom,waterlogged:false,shape:straight,facing:north}"},
        {pos: [8, 3, 10], state: "minecraft:deepslate_tile_stairs{half:bottom,waterlogged:false,shape:straight,facing:south}"},
        {pos: [8, 3, 12], state: "minecraft:deepslate_tile_stairs{half:bottom,waterlogged:false,shape:straight,facing:north}"},
        {pos: [9, 3, 12], state: "minecraft:deepslate_tile_stairs{half:bottom,waterlogged:false,shape:straight,facing:north}"},
        {pos: [10, 3, 1], state: "minecraft:deepslate_tile_stairs{half:bottom,waterlogged:false,shape:straight,facing:east}"},
        {pos: [10, 3, 2], state: "minecraft:deepslate_tile_stairs{half:bottom,waterlogged:false,shape:straight,facing:east}"},
        {pos: [10, 3, 4], state: "minecraft:deepslate_tile_stairs{half:bottom,waterlogged:false,shape:straight,facing:east}"},
        {pos: [10, 3, 5], state: "minecraft:deepslate_tile_stairs{half:bottom,waterlogged:false,shape:straight,facing:east}"},
        {pos: [10, 3, 7], state: "minecraft:deepslate_tile_stairs{half:bottom,waterlogged:false,shape:straight,facing:east}"},
        {pos: [10, 3, 8], state: "minecraft:deepslate_tile_stairs{half:bottom,waterlogged:false,shape:straight,facing:east}"},
        {pos: [10, 3, 12], state: "minecraft:deepslate_tile_stairs{half:bottom,waterlogged:false,shape:straight,facing:north}"},
        {pos: [12, 3, 0], state: "minecraft:deepslate_tile_stairs{half:bottom,waterlogged:false,shape:straight,facing:west}"},
        {pos: [12, 3, 1], state: "minecraft:deepslate_tile_stairs{half:bottom,waterlogged:false,shape:straight,facing:west}"},
        {pos: [12, 3, 6], state: "minecraft:deepslate_tile_stairs{half:bottom,waterlogged:false,shape:straight,facing:west}"},
        {pos: [12, 3, 7], state: "minecraft:deepslate_tile_stairs{half:bottom,waterlogged:false,shape:straight,facing:west}"},
        {pos: [12, 3, 8], state: "minecraft:deepslate_tile_stairs{half:bottom,waterlogged:false,shape:straight,facing:west}"},
        {pos: [12, 3, 9], state: "minecraft:deepslate_tile_stairs{half:bottom,waterlogged:false,shape:straight,facing:west}"},
        {pos: [12, 3, 10], state: "minecraft:deepslate_tile_stairs{half:bottom,waterlogged:false,shape:straight,facing:west}"},
        {pos: [0, 4, 3], state: "minecraft:deepslate_tile_stairs{half:bottom,waterlogged:false,shape:straight,facing:north}"},
        {pos: [0, 4, 13], state: "minecraft:deepslate_tile_stairs{half:top,waterlogged:false,shape:straight,facing:north}"},
        {pos: [1, 4, 3], state: "minecraft:deepslate_tile_stairs{half:bottom,waterlogged:false,shape:straight,facing:north}"},
        {pos: [1, 4, 10], state: "minecraft:deepslate_tile_stairs{half:top,waterlogged:false,shape:straight,facing:south}"},
        {pos: [1, 4, 13], state: "minecraft:deepslate_tile_stairs{half:top,waterlogged:false,shape:straight,facing:north}"},
        {pos: [2, 4, 10], state: "minecraft:deepslate_tile_stairs{half:top,waterlogged:false,shape:straight,facing:south}"},
        {pos: [3, 4, 0], state: "minecraft:deepslate_tile_stairs{half:bottom,waterlogged:false,shape:straight,facing:west}"},
        {pos: [3, 4, 1], state: "minecraft:deepslate_tile_stairs{half:bottom,waterlogged:false,shape:straight,facing:west}"},
        {pos: [4, 4, 10], state: "minecraft:deepslate_tile_stairs{half:top,waterlogged:false,shape:straight,facing:south}"},
        {pos: [5, 4, 10], state: "minecraft:deepslate_tile_stairs{half:top,waterlogged:false,shape:straight,facing:south}"},
        {pos: [6, 4, 13], state: "minecraft:deepslate_tile_stairs{half:top,waterlogged:false,shape:straight,facing:north}"},
        {pos: [7, 4, 10], state: "minecraft:deepslate_tile_stairs{half:top,waterlogged:false,shape:straight,facing:south}"},
        {pos: [7, 4, 13], state: "minecraft:deepslate_tile_stairs{half:top,waterlogged:false,shape:straight,facing:north}"},
        {pos: [8, 4, 10], state: "minecraft:deepslate_tile_stairs{half:top,waterlogged:false,shape:straight,facing:south}"},
        {pos: [8, 4, 13], state: "minecraft:deepslate_tile_stairs{half:top,waterlogged:false,shape:straight,facing:north}"},
        {pos: [9, 4, 13], state: "minecraft:deepslate_tile_stairs{half:top,waterlogged:false,shape:straight,facing:north}"},
        {pos: [10, 4, 1], state: "minecraft:deepslate_tile_stairs{half:top,waterlogged:false,shape:straight,facing:east}"},
        {pos: [10, 4, 2], state: "minecraft:deepslate_tile_stairs{half:top,waterlogged:false,shape:straight,facing:east}"},
        {pos: [10, 4, 4], state: "minecraft:deepslate_tile_stairs{half:top,waterlogged:false,shape:straight,facing:east}"},
        {pos: [10, 4, 5], state: "minecraft:deepslate_tile_stairs{half:top,waterlogged:false,shape:straight,facing:east}"},
        {pos: [10, 4, 7], state: "minecraft:deepslate_tile_stairs{half:top,waterlogged:false,shape:straight,facing:east}"},
        {pos: [10, 4, 8], state: "minecraft:deepslate_tile_stairs{half:top,waterlogged:false,shape:straight,facing:east}"},
        {pos: [10, 4, 13], state: "minecraft:deepslate_tile_stairs{half:top,waterlogged:false,shape:straight,facing:north}"},
        {pos: [13, 4, 0], state: "minecraft:deepslate_tile_stairs{half:top,waterlogged:false,shape:straight,facing:west}"},
        {pos: [13, 4, 1], state: "minecraft:deepslate_tile_stairs{half:top,waterlogged:false,shape:straight,facing:west}"},
        {pos: [13, 4, 6], state: "minecraft:deepslate_tile_stairs{half:top,waterlogged:false,shape:straight,facing:west}"},
        {pos: [13, 4, 7], state: "minecraft:deepslate_tile_stairs{half:top,waterlogged:false,shape:straight,facing:west}"},
        {pos: [13, 4, 8], state: "minecraft:deepslate_tile_stairs{half:top,waterlogged:false,shape:straight,facing:west}"},
        {pos: [13, 4, 9], state: "minecraft:deepslate_tile_stairs{half:top,waterlogged:false,shape:straight,facing:west}"},
        {pos: [13, 4, 10], state: "minecraft:deepslate_tile_stairs{half:top,waterlogged:false,shape:straight,facing:west}"},
        {pos: [0, 5, 3], state: "minecraft:deepslate_tile_stairs{half:top,waterlogged:false,shape:straight,facing:north}"},
        {pos: [0, 5, 10], state: "minecraft:deepslate_tile_stairs{half:bottom,waterlogged:false,shape:straight,facing:north}"},
        {pos: [1, 5, 3], state: "minecraft:deepslate_tile_stairs{half:top,waterlogged:false,shape:straight,facing:north}"},
        {pos: [2, 5, 13], state: "minecraft:deepslate_tile_wall{east:low,waterlogged:false,south:none,north:none,west:low,up:false}"},
        {pos: [3, 5, 0], state: "minecraft:deepslate_tile_stairs{half:top,waterlogged:false,shape:straight,facing:west}"},
        {pos: [3, 5, 1], state: "minecraft:deepslate_tile_stairs{half:top,waterlogged:false,shape:straight,facing:west}"},
        {pos: [3, 5, 10], state: "minecraft:deepslate_tile_stairs{half:bottom,waterlogged:false,shape:straight,facing:north}"},
        {pos: [5, 5, 13], state: "minecraft:deepslate_tile_wall{east:low,waterlogged:false,south:none,north:none,west:low,up:false}"},
        {pos: [6, 5, 10], state: "minecraft:deepslate_tile_stairs{half:bottom,waterlogged:false,shape:straight,facing:north}"},
        {pos: [8, 5, 13], state: "minecraft:deepslate_tile_wall{east:low,waterlogged:false,south:none,north:none,west:low,up:false}"},
        {pos: [9, 5, 10], state: "minecraft:deepslate_tile_stairs{half:bottom,waterlogged:false,shape:straight,facing:north}"},
        {pos: [10, 5, 0], state: "minecraft:deepslate_tile_stairs{half:bottom,waterlogged:false,shape:straight,facing:west}"},
        {pos: [10, 5, 3], state: "minecraft:deepslate_tile_stairs{half:bottom,waterlogged:false,shape:straight,facing:west}"},
        {pos: [10, 5, 6], state: "minecraft:deepslate_tile_stairs{half:bottom,waterlogged:false,shape:straight,facing:west}"},
        {pos: [10, 5, 9], state: "minecraft:deepslate_tile_stairs{half:bottom,waterlogged:false,shape:straight,facing:west}"},
        {pos: [10, 5, 10], state: "minecraft:deepslate_tile_stairs{half:bottom,waterlogged:false,shape:outer_left,facing:north}"},
        {pos: [11, 5, 13], state: "minecraft:deepslate_tile_wall{east:low,waterlogged:false,south:none,north:none,west:low,up:false}"},
        {pos: [13, 5, 2], state: "minecraft:deepslate_tile_wall{east:none,waterlogged:false,south:low,north:low,west:none,up:false}"},
        {pos: [13, 5, 5], state: "minecraft:deepslate_tile_wall{east:none,waterlogged:false,south:low,north:low,west:none,up:false}"},
        {pos: [13, 5, 8], state: "minecraft:deepslate_tile_wall{east:none,waterlogged:false,south:low,north:low,west:none,up:false}"},
        {pos: [13, 5, 11], state: "minecraft:deepslate_tile_wall{east:none,waterlogged:false,south:low,north:low,west:none,up:false}"},
        {pos: [0, 6, 3], state: "minecraft:deepslate_tile_stairs{half:bottom,waterlogged:false,shape:straight,facing:north}"},
        {pos: [0, 6, 13], state: "minecraft:deepslate_tile_stairs{half:bottom,waterlogged:false,shape:straight,facing:north}"},
        {pos: [1, 6, 10], state: "minecraft:deepslate_tile_stairs{half:bottom,waterlogged:false,shape:straight,facing:north}"},
        {pos: [1, 6, 13], state: "minecraft:deepslate_tile_stairs{half:bottom,waterlogged:false,shape:straight,facing:north}"},
        {pos: [2, 6, 10], state: "minecraft:deepslate_tile_stairs{half:bottom,waterlogged:false,shape:straight,facing:north}"},
        {pos: [3, 6, 0], state: "minecraft:deepslate_tile_stairs{half:bottom,waterlogged:false,shape:straight,facing:west}"},
        {pos: [3, 6, 13], state: "minecraft:deepslate_tile_stairs{half:bottom,waterlogged:false,shape:straight,facing:north}"},
        {pos: [4, 6, 10], state: "minecraft:deepslate_tile_stairs{half:bottom,waterlogged:false,shape:straight,facing:north}"},
        {pos: [4, 6, 13], state: "minecraft:deepslate_tile_stairs{half:bottom,waterlogged:false,shape:straight,facing:north}"},
        {pos: [5, 6, 10], state: "minecraft:deepslate_tile_stairs{half:bottom,waterlogged:false,shape:straight,facing:north}"},
        {pos: [6, 6, 13], state: "minecraft:deepslate_tile_stairs{half:bottom,waterlogged:false,shape:straight,facing:north}"},
        {pos: [7, 6, 10], state: "minecraft:deepslate_tile_stairs{half:bottom,waterlogged:false,shape:straight,facing:north}"},
        {pos: [7, 6, 13], state: "minecraft:deepslate_tile_stairs{half:bottom,waterlogged:false,shape:straight,facing:north}"},
        {pos: [10, 6, 1], state: "minecraft:deepslate_tile_stairs{half:bottom,waterlogged:false,shape:straight,facing:west}"},
        {pos: [10, 6, 2], state: "minecraft:deepslate_tile_stairs{half:bottom,waterlogged:false,shape:straight,facing:west}"},
        {pos: [10, 6, 4], state: "minecraft:deepslate_tile_stairs{half:bottom,waterlogged:false,shape:straight,facing:west}"},
        {pos: [10, 6, 5], state: "minecraft:deepslate_tile_stairs{half:bottom,waterlogged:false,shape:straight,facing:west}"},
        {pos: [10, 6, 7], state: "minecraft:deepslate_tile_stairs{half:bottom,waterlogged:false,shape:straight,facing:west}"},
        {pos: [10, 6, 8], state: "minecraft:deepslate_tile_stairs{half:bottom,waterlogged:false,shape:straight,facing:west}"},
        {pos: [12, 6, 13], state: "minecraft:deepslate_tile_stairs{half:bottom,waterlogged:false,shape:straight,facing:north}"},
        {pos: [13, 6, 0], state: "minecraft:deepslate_tile_stairs{half:bottom,waterlogged:false,shape:straight,facing:west}"},
        {pos: [13, 6, 1], state: "minecraft:deepslate_tile_stairs{half:bottom,waterlogged:false,shape:straight,facing:west}"},
        {pos: [13, 6, 3], state: "minecraft:deepslate_tile_stairs{half:bottom,waterlogged:false,shape:straight,facing:west}"},
        {pos: [13, 6, 4], state: "minecraft:deepslate_tile_stairs{half:bottom,waterlogged:false,shape:straight,facing:west}"},
        {pos: [13, 6, 6], state: "minecraft:deepslate_tile_stairs{half:bottom,waterlogged:false,shape:straight,facing:west}"},
        {pos: [13, 6, 7], state: "minecraft:deepslate_tile_stairs{half:bottom,waterlogged:false,shape:straight,facing:west}"},
        {pos: [13, 6, 9], state: "minecraft:deepslate_tile_stairs{half:bottom,waterlogged:false,shape:straight,facing:west}"},
        {pos: [13, 6, 10], state: "minecraft:deepslate_tile_stairs{half:bottom,waterlogged:false,shape:straight,facing:west}"},
        {pos: [13, 6, 12], state: "minecraft:deepslate_tile_stairs{half:bottom,waterlogged:false,shape:straight,facing:west}"},
        {pos: [13, 6, 13], state: "minecraft:deepslate_tile_stairs{half:bottom,waterlogged:false,shape:outer_left,facing:north}"},
        {pos: [0, 7, 13], state: "minecraft:deepslate_tile_stairs{half:bottom,waterlogged:false,shape:straight,facing:west}"},
        {pos: [1, 7, 13], state: "minecraft:deepslate_tile_stairs{half:bottom,waterlogged:false,shape:straight,facing:east}"},
        {pos: [4, 7, 10], state: "minecraft:deepslate_tile_stairs{half:bottom,waterlogged:false,shape:straight,facing:west}"},
        {pos: [5, 7, 10], state: "minecraft:deepslate_tile_stairs{half:bottom,waterlogged:false,shape:straight,facing:east}"},
        {pos: [6, 7, 13], state: "minecraft:deepslate_tile_stairs{half:bottom,waterlogged:false,shape:straight,facing:west}"},
        {pos: [7, 7, 13], state: "minecraft:deepslate_tile_stairs{half:bottom,waterlogged:false,shape:straight,facing:east}"},
        {pos: [10, 7, 4], state: "minecraft:deepslate_tile_stairs{half:bottom,waterlogged:false,shape:straight,facing:north}"},
        {pos: [10, 7, 5], state: "minecraft:deepslate_tile_stairs{half:bottom,waterlogged:false,shape:straight,facing:south}"},
        {pos: [12, 7, 13], state: "minecraft:deepslate_tile_stairs{half:bottom,waterlogged:false,shape:straight,facing:west}"},
        {pos: [13, 7, 0], state: "minecraft:deepslate_tile_stairs{half:bottom,waterlogged:false,shape:straight,facing:north}"},
        {pos: [13, 7, 1], state: "minecraft:deepslate_tile_stairs{half:bottom,waterlogged:false,shape:straight,facing:south}"},
        {pos: [13, 7, 6], state: "minecraft:deepslate_tile_stairs{half:bottom,waterlogged:false,shape:straight,facing:north}"},
        {pos: [13, 7, 7], state: "minecraft:deepslate_tile_stairs{half:bottom,waterlogged:false,shape:straight,facing:south}"},
        {pos: [13, 7, 12], state: "minecraft:deepslate_tile_stairs{half:bottom,waterlogged:false,shape:straight,facing:north}"},
        {pos: [13, 7, 13], state: "minecraft:deepslate_tile_slab{waterlogged:false,type:bottom}"},
        {pos: [6, 0, 0], state: "minecraft:jigsaw{orientation:north_up}", nbt: {final_state: "minecraft:deepslate_bricks", id: "minecraft:jigsaw", joint: "rollable", name: "minecraft:connect_top_right_corner", pool: "minecraft:empty", target: "minecraft:empty"}}
    ],
    entities: [],
    palette: [
        "minecraft:deepslate{axis:y}",
        "minecraft:deepslate_bricks",
        "minecraft:gray_wool",
        "minecraft:deepslate_tiles",
        "minecraft:chiseled_deepslate",
        "minecraft:deepslate_brick_stairs{half:bottom,waterlogged:false,shape:straight,facing:east}",
        "minecraft:deepslate_brick_stairs{half:bottom,waterlogged:false,shape:straight,facing:south}",
        "minecraft:deepslate_tile_stairs{half:bottom,waterlogged:false,shape:straight,facing:north}",
        "minecraft:deepslate_tile_stairs{half:top,waterlogged:false,shape:straight,facing:north}",
        "minecraft:deepslate_tile_stairs{half:bottom,waterlogged:false,shape:straight,facing:south}",
        "minecraft:deepslate_tile_stairs{half:top,waterlogged:false,shape:straight,facing:west}",
        "minecraft:deepslate_tile_stairs{half:bottom,waterlogged:false,shape:straight,facing:east}",
        "minecraft:deepslate_tile_stairs{half:bottom,waterlogged:false,shape:straight,facing:west}",
        "minecraft:deepslate_tile_stairs{half:top,waterlogged:false,shape:straight,facing:south}",
        "minecraft:deepslate_tile_stairs{half:top,waterlogged:false,shape:straight,facing:east}",
        "minecraft:deepslate_tile_wall{east:low,waterlogged:false,south:none,north:none,west:low,up:false}",
        "minecraft:deepslate_tile_stairs{half:bottom,waterlogged:false,shape:outer_left,facing:north}",
        "minecraft:deepslate_tile_wall{east:none,waterlogged:false,south:low,north:low,west:none,up:false}",
        "minecraft:deepslate_tile_slab{waterlogged:false,type:bottom}",
        "minecraft:jigsaw{orientation:north_up}"
    ]
}