{
    size: [14, 6, 8],
    data: [
        {pos: [0, 0, 6], state: "minecraft:polished_blackstone_bricks"},
        {pos: [1, 0, 6], state: "minecraft:polished_blackstone_bricks"},
        {pos: [1, 0, 7], state: "minecraft:polished_blackstone_bricks"},
        {pos: [2, 0, 6], state: "minecraft:polished_blackstone_bricks"},
        {pos: [2, 0, 7], state: "minecraft:polished_blackstone_bricks"},
        {pos: [3, 0, 6], state: "minecraft:polished_blackstone_bricks"},
        {pos: [3, 0, 7], state: "minecraft:polished_blackstone_bricks"},
        {pos: [4, 0, 1], state: "minecraft:polished_blackstone_bricks"},
        {pos: [4, 0, 2], state: "minecraft:basalt{axis:y}"},
        {pos: [4, 0, 3], state: "minecraft:basalt{axis:y}"},
        {pos: [4, 0, 5], state: "minecraft:polished_blackstone_bricks"},
        {pos: [4, 0, 6], state: "minecraft:polished_blackstone_bricks"},
        {pos: [4, 0, 7], state: "minecraft:polished_blackstone_bricks"},
        {pos: [5, 0, 1], state: "minecraft:basalt{axis:y}"},
        {pos: [5, 0, 2], state: "minecraft:polished_blackstone_bricks"},
        {pos: [5, 0, 3], state: "minecraft:basalt{axis:y}"},
        {pos: [5, 0, 4], state: "minecraft:basalt{axis:y}"},
        {pos: [5, 0, 5], state: "minecraft:basalt{axis:y}"},
        {pos: [5, 0, 6], state: "minecraft:polished_blackstone_bricks"},
        {pos: [5, 0, 7], state: "minecraft:polished_blackstone_bricks"},
        {pos: [6, 0, 0], state: "minecraft:basalt{axis:y}"},
        {pos: [6, 0, 1], state: "minecraft:basalt{axis:y}"},
        {pos: [6, 0, 2], state: "minecraft:polished_blackstone_bricks"},
        {pos: [6, 0, 3], state: "minecraft:polished_blackstone_bricks"},
        {pos: [6, 0, 4], state: "minecraft:polished_blackstone_bricks"},
        {pos: [6, 0, 5], state: "minecraft:basalt{axis:y}"},
        {pos: [6, 0, 6], state: "minecraft:polished_blackstone_bricks"},
        {pos: [7, 0, 0], state: "minecraft:basalt{axis:y}"},
        {pos: [7, 0, 1], state: "minecraft:polished_blackstone_bricks"},
        {pos: [7, 0, 3], state: "minecraft:polished_blackstone_bricks"},
        {pos: [7, 0, 4], state: "minecraft:polished_blackstone_bricks"},
        {pos: [8, 0, 0], state: "minecraft:basalt{axis:y}"},
        {pos: [8, 0, 1], state: "minecraft:polished_blackstone_bricks"},
        {pos: [8, 0, 2], state: "minecraft:polished_blackstone_bricks"},
        {pos: [8, 0, 3], state: "minecraft:polished_blackstone_bricks"},
        {pos: [8, 0, 4], state: "minecraft:polished_blackstone_bricks"},
        {pos: [8, 0, 5], state: "minecraft:polished_blackstone_bricks"},
        {pos: [9, 0, 0], state: "minecraft:basalt{axis:y}"},
        {pos: [9, 0, 1], state: "minecraft:polished_blackstone_bricks"},
        {pos: [9, 0, 2], state: "minecraft:polished_blackstone_bricks"},
        {pos: [9, 0, 3], state: "minecraft:polished_blackstone_bricks"},
        {pos: [9, 0, 4], state: "minecraft:polished_blackstone_bricks"},
        {pos: [9, 0, 5], state: "minecraft:polished_blackstone_bricks"},
        {pos: [9, 0, 6], state: "minecraft:polished_blackstone_bricks"},
        {pos: [9, 0, 7], state: "minecraft:polished_blackstone_bricks"},
        {pos: [10, 0, 0], state: "minecraft:basalt{axis:y}"},
        {pos: [10, 0, 1], state: "minecraft:polished_blackstone_bricks"},
        {pos: [10, 0, 2], state: "minecraft:polished_blackstone_bricks"},
        {pos: [10, 0, 3], state: "minecraft:polished_blackstone_bricks"},
        {pos: [10, 0, 4], state: "minecraft:polished_blackstone_bricks"},
        {pos: [10, 0, 5], state: "minecraft:polished_blackstone_bricks"},
        {pos: [10, 0, 6], state: "minecraft:polished_blackstone_bricks"},
        {pos: [10, 0, 7], state: "minecraft:basalt{axis:y}"},
        {pos: [11, 0, 0], state: "minecraft:basalt{axis:y}"},
        {pos: [11, 0, 1], state: "minecraft:polished_blackstone_bricks"},
        {pos: [11, 0, 2], state: "minecraft:polished_blackstone_bricks"},
        {pos: [11, 0, 3], state: "minecraft:polished_blackstone_bricks"},
        {pos: [11, 0, 4], state: "minecraft:basalt{axis:y}"},
        {pos: [11, 0, 5], state: "minecraft:polished_blackstone_bricks"},
        {pos: [11, 0, 6], state: "minecraft:polished_blackstone_bricks"},
        {pos: [11, 0, 7], state: "minecraft:basalt{axis:y}"},
        {pos: [12, 0, 1], state: "minecraft:basalt{axis:y}"},
        {pos: [12, 0, 2], state: "minecraft:polished_blackstone_bricks"},
        {pos: [12, 0, 3], state: "minecraft:polished_blackstone_bricks"},
        {pos: [12, 0, 4], state: "minecraft:polished_blackstone_bricks"},
        {pos: [12, 0, 5], state: "minecraft:basalt{axis:y}"},
        {pos: [12, 0, 6], state: "minecraft:polished_blackstone_bricks"},
        {pos: [12, 0, 7], state: "minecraft:polished_blackstone_bricks"},
        {pos: [13, 0, 3], state: "minecraft:polished_blackstone_bricks"},
        {pos: [13, 0, 4], state: "minecraft:polished_blackstone_bricks"},
        {pos: [13, 0, 5], state: "minecraft:polished_blackstone_bricks"},
        {pos: [13, 0, 6], state: "minecraft:basalt{axis:y}"},
        {pos: [0, 1, 3], state: "minecraft:basalt{axis:y}"},
        {pos: [0, 1, 4], state: "minecraft:polished_blackstone_bricks"},
        {pos: [0, 1, 5], state: "minecraft:polished_blackstone_bricks"},
        {pos: [0, 1, 6], state: "minecraft:polished_blackstone_bricks"},
        {pos: [0, 1, 7], state: "minecraft:polished_blackstone_bricks"},
        {pos: [1, 1, 6], state: "minecraft:polished_blackstone_bricks"},
        {pos: [1, 1, 7], state: "minecraft:polished_blackstone_bricks"},
        {pos: [6, 1, 7], state: "minecraft:polished_blackstone_bricks"},
        {pos: [7, 1, 0], state: "minecraft:basalt{axis:y}"},
        {pos: [7, 1, 7], state: "minecraft:polished_blackstone_bricks"},
        {pos: [8, 1, 7], state: "minecraft:polished_blackstone_bricks"},
        {pos: [9, 1, 0], state: "minecraft:basalt{axis:y}"},
        {pos: [9, 1, 1], state: "minecraft:basalt{axis:y}"},
        {pos: [9, 1, 2], state: "minecraft:polished_blackstone_bricks"},
        {pos: [9, 1, 5], state: "minecraft:polished_blackstone_bricks"},
        {pos: [9, 1, 6], state: "minecraft:polished_blackstone_bricks"},
        {pos: [9, 1, 7], state: "minecraft:polished_blackstone_bricks"},
        {pos: [11, 1, 0], state: "minecraft:basalt{axis:y}"},
        {pos: [0, 2, 3], state: "minecraft:basalt{axis:y}"},
        {pos: [0, 2, 4], state: "minecraft:polished_blackstone_bricks"},
        {pos: [0, 2, 5], state: "minecraft:polished_blackstone_bricks"},
        {pos: [0, 2, 6], state: "minecraft:polished_blackstone_bricks"},
        {pos: [0, 2, 7], state: "minecraft:polished_blackstone_bricks"},
        {pos: [1, 2, 6], state: "minecraft:polished_blackstone_bricks"},
        {pos: [1, 2, 7], state: "minecraft:polished_blackstone_bricks"},
        {pos: [7, 2, 0], state: "minecraft:basalt{axis:y}"},
        {pos: [8, 2, 0], state: "minecraft:polished_blackstone_bricks"},
        {pos: [9, 2, 0], state: "minecraft:polished_blackstone_bricks"},
        {pos: [9, 2, 7], state: "minecraft:polished_blackstone_bricks"},
        {pos: [0, 3, 1], state: "minecraft:polished_blackstone_bricks"},
        {pos: [0, 3, 2], state: "minecraft:polished_blackstone_bricks"},
        {pos: [0, 3, 3], state: "minecraft:basalt{axis:y}"},
        {pos: [0, 3, 4], state: "minecraft:basalt{axis:y}"},
        {pos: [0, 3, 5], state: "minecraft:basalt{axis:y}"},
        {pos: [0, 3, 6], state: "minecraft:polished_blackstone_bricks"},
        {pos: [0, 3, 7], state: "minecraft:polished_blackstone_bricks"},
        {pos: [1, 3, 1], state: "minecraft:polished_blackstone_bricks"},
        {pos: [1, 3, 7], state: "minecraft:polished_blackstone_bricks"},
        {pos: [4, 3, 0], state: "minecraft:polished_blackstone_bricks"},
        {pos: [4, 3, 7], state: "minecraft:polished_blackstone_bricks"},
        {pos: [5, 3, 0], state: "minecraft:polished_blackstone_bricks"},
        {pos: [5, 3, 7], state: "minecraft:polished_blackstone_bricks"},
        {pos: [6, 3, 0], state: "minecraft:polished_blackstone_bricks"},
        {pos: [6, 3, 7], state: "minecraft:polished_blackstone_bricks"},
        {pos: [7, 3, 7], state: "minecraft:polished_blackstone_bricks"},
        {pos: [8, 3, 0], state: "minecraft:basalt{axis:y}"},
        {pos: [8, 3, 7], state: "minecraft:polished_blackstone_bricks"},
        {pos: [9, 3, 0], state: "minecraft:polished_blackstone_bricks"},
        {pos: [9, 3, 7], state: "minecraft:polished_blackstone_bricks"},
        {pos: [0, 4, 1], state: "minecraft:basalt{axis:y}"},
        {pos: [0, 4, 6], state: "minecraft:basalt{axis:y}"},
        {pos: [0, 4, 7], state: "minecraft:polished_blackstone_bricks"},
        {pos: [1, 4, 1], state: "minecraft:polished_blackstone_bricks"},
        {pos: [3, 4, 0], state: "minecraft:polished_blackstone_bricks"},
        {pos: [4, 4, 0], state: "minecraft:basalt{axis:y}"},
        {pos: [5, 4, 0], state: "minecraft:polished_blackstone_bricks"},
        {pos: [5, 4, 7], state: "minecraft:polished_blackstone_bricks"},
        {pos: [6, 4, 0], state: "minecraft:polished_blackstone_bricks"},
        {pos: [6, 4, 7], state: "minecraft:basalt{axis:y}"},
        {pos: [7, 4, 0], state: "minecraft:basalt{axis:y}"},
        {pos: [7, 4, 1], state: "minecraft:polished_blackstone_bricks"},
        {pos: [7, 4, 2], state: "minecraft:polished_blackstone_bricks"},
        {pos: [7, 4, 3], state: "minecraft:polished_blackstone_bricks"},
        {pos: [8, 4, 0], state: "minecraft:basalt{axis:y}"},
        {pos: [8, 4, 1], state: "minecraft:basalt{axis:y}"},
        {pos: [8, 4, 2], state: "minecraft:polished_blackstone_bricks"},
        {pos: [8, 4, 3], state: "minecraft:polished_blackstone_bricks"},
        {pos: [8, 4, 4], state: "minecraft:polished_blackstone_bricks"},
        {pos: [8, 4, 5], state: "minecraft:polished_blackstone_bricks"},
        {pos: [9, 4, 0], state: "minecraft:basalt{axis:y}"},
        {pos: [9, 4, 1], state: "minecraft:polished_blackstone_bricks"},
        {pos: [9, 4, 2], state: "minecraft:polished_blackstone_bricks"},
        {pos: [9, 4, 3], state: "minecraft:polished_blackstone_bricks"},
        {pos: [9, 4, 4], state: "minecraft:polished_blackstone_bricks"},
        {pos: [9, 4, 5], state: "minecraft:polished_blackstone_bricks"},
        {pos: [9, 4, 6], state: "minecraft:polished_blackstone_bricks"},
        {pos: [9, 4, 7], state: "minecraft:polished_blackstone_bricks"},
        {pos: [10, 4, 0], state: "minecraft:polished_blackstone_bricks"},
        {pos: [10, 4, 1], state: "minecraft:polished_blackstone_bricks"},
        {pos: [10, 4, 2], state: "minecraft:polished_blackstone_bricks"},
        {pos: [10, 4, 3], state: "minecraft:polished_blackstone_bricks"},
        {pos: [10, 4, 4], state: "minecraft:polished_blackstone_bricks"},
        {pos: [10, 4, 5], state: "minecraft:polished_blackstone_bricks"},
        {pos: [10, 4, 6], state: "minecraft:polished_blackstone_bricks"},
        {pos: [10, 4, 7], state: "minecraft:polished_blackstone_bricks"},
        {pos: [11, 4, 1], state: "minecraft:polished_blackstone_bricks"},
        {pos: [11, 4, 3], state: "minecraft:basalt{axis:y}"},
        {pos: [11, 4, 4], state: "minecraft:polished_blackstone_bricks"},
        {pos: [11, 4, 6], state: "minecraft:polished_blackstone_bricks"},
        {pos: [11, 4, 7], state: "minecraft:basalt{axis:y}"},
        {pos: [0, 5, 2], state: "minecraft:polished_blackstone_bricks"},
        {pos: [0, 5, 3], state: "minecraft:polished_blackstone_bricks"},
        {pos: [0, 5, 4], state: "minecraft:polished_blackstone_bricks"},
        {pos: [0, 5, 5], state: "minecraft:polished_blackstone_bricks"},
        {pos: [0, 5, 6], state: "minecraft:basalt{axis:y}"},
        {pos: [0, 5, 7], state: "minecraft:polished_blackstone_bricks"},
        {pos: [1, 5, 1], state: "minecraft:basalt{axis:y}"},
        {pos: [1, 5, 2], state: "minecraft:polished_blackstone_bricks"},
        {pos: [1, 5, 3], state: "minecraft:polished_blackstone_bricks"},
        {pos: [1, 5, 4], state: "minecraft:polished_blackstone_bricks"},
        {pos: [1, 5, 5], state: "minecraft:polished_blackstone_bricks"},
        {pos: [1, 5, 6], state: "minecraft:basalt{axis:y}"},
        {pos: [1, 5, 7], state: "minecraft:polished_blackstone_bricks"},
        {pos: [2, 5, 1], state: "minecraft:basalt{axis:y}"},
        {pos: [2, 5, 2], state: "minecraft:polished_blackstone_bricks"},
        {pos: [2, 5, 3], state: "minecraft:polished_blackstone_bricks"},
        {pos: [2, 5, 4], state: "minecraft:polished_blackstone_bricks"},
        {pos: [2, 5, 5], state: "minecraft:polished_blackstone_bricks"},
        {pos: [2, 5, 6], state: "minecraft:basalt{axis:y}"},
        {pos: [2, 5, 7], state: "minecraft:basalt{axis:y}"},
        {pos: [3, 5, 2], state: "minecraft:polished_blackstone_bricks"},
        {pos: [3, 5, 3], state: "minecraft:polished_blackstone_bricks"},
        {pos: [3, 5, 4], state: "minecraft:polished_blackstone_bricks"},
        {pos: [3, 5, 5], state: "minecraft:polished_blackstone_bricks"},
        {pos: [3, 5, 6], state: "minecraft:polished_blackstone_bricks"},
        {pos: [3, 5, 7], state: "minecraft:basalt{axis:y}"},
        {pos: [4, 5, 0], state: "minecraft:basalt{axis:y}"},
        {pos: [4, 5, 1], state: "minecraft:polished_blackstone_bricks"},
        {pos: [4, 5, 2], state: "minecraft:polished_blackstone_bricks"},
        {pos: [4, 5, 5], state: "minecraft:polished_blackstone_bricks"},
        {pos: [4, 5, 6], state: "minecraft:polished_blackstone_bricks"},
        {pos: [4, 5, 7], state: "minecraft:basalt{axis:y}"},
        {pos: [5, 5, 0], state: "minecraft:polished_blackstone_bricks"},
        {pos: [5, 5, 1], state: "minecraft:polished_blackstone_bricks"},
        {pos: [5, 5, 4], state: "minecraft:polished_blackstone_bricks"},
        {pos: [5, 5, 6], state: "minecraft:basalt{axis:y}"},
        {pos: [5, 5, 7], state: "minecraft:basalt{axis:y}"},
        {pos: [6, 5, 0], state: "minecraft:polished_blackstone_bricks"},
        {pos: [6, 5, 1], state: "minecraft:polished_blackstone_bricks"},
        {pos: [6, 5, 3], state: "minecraft:polished_blackstone_bricks"},
        {pos: [6, 5, 4], state: "minecraft:polished_blackstone_bricks"},
        {pos: [6, 5, 5], state: "minecraft:polished_blackstone_bricks"},
        {pos: [6, 5, 6], state: "minecraft:basalt{axis:y}"},
        {pos: [6, 5, 7], state: "minecraft:basalt{axis:y}"},
        {pos: [7, 5, 0], state: "minecraft:basalt{axis:y}"},
        {pos: [7, 5, 2], state: "minecraft:polished_blackstone_bricks"},
        {pos: [7, 5, 3], state: "minecraft:polished_blackstone_bricks"},
        {pos: [7, 5, 4], state: "minecraft:polished_blackstone_bricks"},
        {pos: [7, 5, 5], state: "minecraft:polished_blackstone_bricks"},
        {pos: [8, 5, 0], state: "minecraft:basalt{axis:y}"},
        {pos: [8, 5, 2], state: "minecraft:polished_blackstone_bricks"},
        {pos: [8, 5, 3], state: "minecraft:basalt{axis:y}"},
        {pos: [8, 5, 4], state: "minecraft:basalt{axis:y}"},
        {pos: [8, 5, 5], state: "minecraft:polished_blackstone_bricks"},
        {pos: [9, 5, 0], state: "minecraft:basalt{axis:y}"},
        {pos: [9, 5, 1], state: "minecraft:basalt{axis:y}"},
        {pos: [9, 5, 2], state: "minecraft:polished_blackstone_bricks"},
        {pos: [9, 5, 3], state: "minecraft:basalt{axis:y}"},
        {pos: [9, 5, 4], state: "minecraft:basalt{axis:y}"},
        {pos: [9, 5, 5], state: "minecraft:polished_blackstone_bricks"},
        {pos: [9, 5, 6], state: "minecraft:polished_blackstone_bricks"},
        {pos: [10, 5, 0], state: "minecraft:basalt{axis:y}"},
        {pos: [10, 5, 1], state: "minecraft:polished_blackstone_bricks"},
        {pos: [10, 5, 2], state: "minecraft:basalt{axis:y}"},
        {pos: [10, 5, 3], state: "minecraft:basalt{axis:y}"},
        {pos: [10, 5, 4], state: "minecraft:basalt{axis:y}"},
        {pos: [10, 5, 5], state: "minecraft:basalt{axis:y}"},
        {pos: [10, 5, 6], state: "minecraft:polished_blackstone_bricks"},
        {pos: [11, 5, 0], state: "minecraft:basalt{axis:y}"},
        {pos: [11, 5, 1], state: "minecraft:basalt{axis:y}"},
        {pos: [11, 5, 2], state: "minecraft:basalt{axis:y}"},
        {pos: [11, 5, 3], state: "minecraft:basalt{axis:y}"},
        {pos: [11, 5, 4], state: "minecraft:polished_blackstone_bricks"},
        {pos: [11, 5, 5], state: "minecraft:basalt{axis:y}"},
        {pos: [11, 5, 6], state: "minecraft:basalt{axis:y}"},
        {pos: [11, 5, 7], state: "minecraft:basalt{axis:y}"},
        {pos: [0, 0, 3], state: "minecraft:blackstone_slab{waterlogged:false,type:bottom}"},
        {pos: [0, 0, 4], state: "minecraft:blackstone_slab{waterlogged:false,type:bottom}"},
        {pos: [0, 0, 5], state: "minecraft:blackstone_slab{waterlogged:false,type:bottom}"},
        {pos: [1, 0, 3], state: "minecraft:air"},
        {pos: [1, 0, 4], state: "minecraft:blackstone_slab{waterlogged:false,type:bottom}"},
        {pos: [1, 0, 5], state: "minecraft:blackstone_slab{waterlogged:false,type:bottom}"},
        {pos: [2, 0, 3], state: "minecraft:air"},
        {pos: [2, 0, 4], state: "minecraft:air"},
        {pos: [2, 0, 5], state: "minecraft:air"},
        {pos: [3, 0, 2], state: "minecraft:polished_blackstone_brick_stairs{half:bottom,waterlogged:false,shape:straight,facing:east}"},
        {pos: [3, 0, 3], state: "minecraft:polished_blackstone_brick_stairs{half:bottom,waterlogged:false,shape:straight,facing:east}"},
        {pos: [3, 0, 4], state: "minecraft:polished_blackstone_brick_stairs{half:bottom,waterlogged:false,shape:straight,facing:east}"},
        {pos: [3, 0, 5], state: "minecraft:polished_blackstone_brick_stairs{half:bottom,waterlogged:false,shape:straight,facing:east}"},
        {pos: [7, 0, 5], state: "minecraft:air"},
        {pos: [7, 0, 6], state: "minecraft:air"},
        {pos: [8, 0, 6], state: "minecraft:air"},
        {pos: [0, 1, 0], state: "minecraft:air"},
        {pos: [0, 1, 1], state: "minecraft:air"},
        {pos: [1, 1, 3], state: "minecraft:polished_blackstone_brick_stairs{half:top,waterlogged:false,shape:straight,facing:west}"},
        {pos: [1, 1, 4], state: "minecraft:polished_blackstone_brick_stairs{half:top,waterlogged:false,shape:straight,facing:west}"},
        {pos: [1, 1, 5], state: "minecraft:polished_blackstone_brick_stairs{half:top,waterlogged:false,shape:straight,facing:west}"},
        {pos: [2, 1, 0], state: "minecraft:air"},
        {pos: [2, 1, 3], state: "minecraft:air"},
        {pos: [2, 1, 4], state: "minecraft:air"},
        {pos: [2, 1, 5], state: "minecraft:air"},
        {pos: [2, 1, 6], state: "minecraft:air"},
        {pos: [3, 1, 0], state: "minecraft:air"},
        {pos: [3, 1, 3], state: "minecraft:air"},
        {pos: [3, 1, 4], state: "minecraft:air"},
        {pos: [3, 1, 5], state: "minecraft:air"},
        {pos: [3, 1, 6], state: "minecraft:air"},
        {pos: [4, 1, 3], state: "minecraft:air"},
        {pos: [4, 1, 4], state: "minecraft:air"},
        {pos: [4, 1, 5], state: "minecraft:air"},
        {pos: [4, 1, 6], state: "minecraft:air"},
        {pos: [4, 1, 7], state: "minecraft:air"},
        {pos: [5, 1, 0], state: "minecraft:air"},
        {pos: [5, 1, 2], state: "minecraft:air"},
        {pos: [5, 1, 3], state: "minecraft:air"},
        {pos: [5, 1, 4], state: "minecraft:air"},
        {pos: [5, 1, 5], state: "minecraft:air"},
        {pos: [5, 1, 6], state: "minecraft:air"},
        {pos: [5, 1, 7], state: "minecraft:air"},
        {pos: [6, 1, 0], state: "minecraft:air"},
        {pos: [6, 1, 2], state: "minecraft:air"},
        {pos: [6, 1, 3], state: "minecraft:air"},
        {pos: [6, 1, 4], state: "minecraft:air"},
        {pos: [6, 1, 5], state: "minecraft:air"},
        {pos: [6, 1, 6], state: "minecraft:air"},
        {pos: [7, 1, 3], state: "minecraft:air"},
        {pos: [7, 1, 4], state: "minecraft:air"},
        {pos: [7, 1, 5], state: "minecraft:air"},
        {pos: [7, 1, 6], state: "minecraft:air"},
        {pos: [8, 1, 3], state: "minecraft:air"},
        {pos: [8, 1, 4], state: "minecraft:air"},
        {pos: [8, 1, 5], state: "minecraft:air"},
        {pos: [8, 1, 6], state: "minecraft:air"},
        {pos: [9, 1, 4], state: "minecraft:air"},
        {pos: [10, 1, 4], state: "minecraft:air"},
        {pos: [10, 1, 5], state: "minecraft:air"},
        {pos: [10, 1, 6], state: "minecraft:air"},
        {pos: [11, 1, 4], state: "minecraft:air"},
        {pos: [11, 1, 5], state: "minecraft:air"},
        {pos: [11, 1, 7], state: "minecraft:air"},
        {pos: [12, 1, 7], state: "minecraft:air"},
        {pos: [13, 1, 0], state: "minecraft:air"},
        {pos: [13, 1, 7], state: "minecraft:air"},
        {pos: [0, 2, 0], state: "minecraft:air"},
        {pos: [0, 2, 2], state: "minecraft:air"},
        {pos: [1, 2, 0], state: "minecraft:air"},
        {pos: [1, 2, 3], state: "minecraft:air"},
        {pos: [1, 2, 4], state: "minecraft:lantern{waterlogged:false,hanging:false}"},
        {pos: [1, 2, 5], state: "minecraft:air"},
        {pos: [2, 2, 0], state: "minecraft:air"},
        {pos: [2, 2, 3], state: "minecraft:air"},
        {pos: [2, 2, 4], state: "minecraft:air"},
        {pos: [2, 2, 5], state: "minecraft:air"},
        {pos: [2, 2, 6], state: "minecraft:air"},
        {pos: [3, 2, 0], state: "minecraft:air"},
        {pos: [3, 2, 3], state: "minecraft:air"},
        {pos: [3, 2, 4], state: "minecraft:air"},
        {pos: [3, 2, 5], state: "minecraft:air"},
        {pos: [3, 2, 6], state: "minecraft:air"},
        {pos: [4, 2, 0], state: "minecraft:air"},
        {pos: [4, 2, 3], state: "minecraft:air"},
        {pos: [4, 2, 4], state: "minecraft:air"},
        {pos: [4, 2, 5], state: "minecraft:air"},
        {pos: [4, 2, 6], state: "minecraft:air"},
        {pos: [4, 2, 7], state: "minecraft:air"},
        {pos: [5, 2, 0], state: "minecraft:air"},
        {pos: [5, 2, 3], state: "minecraft:air"},
        {pos: [5, 2, 4], state: "minecraft:air"},
        {pos: [5, 2, 5], state: "minecraft:air"},
        {pos: [5, 2, 6], state: "minecraft:air"},
        {pos: [5, 2, 7], state: "minecraft:air"},
        {pos: [6, 2, 0], state: "minecraft:air"},
        {pos: [6, 2, 3], state: "minecraft:air"},
        {pos: [6, 2, 4], state: "minecraft:air"},
        {pos: [6, 2, 5], state: "minecraft:air"},
        {pos: [6, 2, 6], state: "minecraft:air"},
        {pos: [6, 2, 7], state: "minecraft:air"},
        {pos: [7, 2, 2], state: "minecraft:air"},
        {pos: [7, 2, 3], state: "minecraft:air"},
        {pos: [7, 2, 4], state: "minecraft:air"},
        {pos: [7, 2, 5], state: "minecraft:air"},
        {pos: [7, 2, 6], state: "minecraft:air"},
        {pos: [7, 2, 7], state: "minecraft:air"},
        {pos: [8, 2, 3], state: "minecraft:air"},
        {pos: [8, 2, 4], state: "minecraft:air"},
        {pos: [8, 2, 5], state: "minecraft:air"},
        {pos: [8, 2, 6], state: "minecraft:air"},
        {pos: [9, 2, 1], state: "minecraft:blackstone_wall{east:none,waterlogged:false,south:none,north:low,west:none,up:true}"},
        {pos: [9, 2, 6], state: "minecraft:blackstone_wall{east:none,waterlogged:false,south:low,north:none,west:none,up:true}"},
        {pos: [10, 2, 0], state: "minecraft:air"},
        {pos: [10, 2, 3], state: "minecraft:air"},
        {pos: [10, 2, 4], state: "minecraft:air"},
        {pos: [10, 2, 5], state: "minecraft:air"},
        {pos: [10, 2, 6], state: "minecraft:air"},
        {pos: [11, 2, 0], state: "minecraft:air"},
        {pos: [11, 2, 3], state: "minecraft:air"},
        {pos: [11, 2, 4], state: "minecraft:air"},
        {pos: [11, 2, 5], state: "minecraft:air"},
        {pos: [11, 2, 7], state: "minecraft:air"},
        {pos: [12, 2, 0], state: "minecraft:air"},
        {pos: [12, 2, 4], state: "minecraft:air"},
        {pos: [12, 2, 7], state: "minecraft:air"},
        {pos: [13, 2, 0], state: "minecraft:air"},
        {pos: [13, 2, 7], state: "minecraft:air"},
        {pos: [0, 3, 0], state: "minecraft:air"},
        {pos: [1, 3, 0], state: "minecraft:air"},
        {pos: [2, 3, 0], state: "minecraft:air"},
        {pos: [2, 3, 1], state: "minecraft:air"},
        {pos: [2, 3, 2], state: "minecraft:air"},
        {pos: [2, 3, 5], state: "minecraft:air"},
        {pos: [2, 3, 6], state: "minecraft:air"},
        {pos: [3, 3, 0], state: "minecraft:air"},
        {pos: [3, 3, 4], state: "minecraft:air"},
        {pos: [3, 3, 5], state: "minecraft:air"},
        {pos: [3, 3, 6], state: "minecraft:air"},
        {pos: [3, 3, 7], state: "minecraft:air"},
        {pos: [4, 3, 4], state: "minecraft:air"},
        {pos: [4, 3, 5], state: "minecraft:air"},
        {pos: [4, 3, 6], state: "minecraft:air"},
        {pos: [5, 3, 4], state: "minecraft:air"},
        {pos: [5, 3, 5], state: "minecraft:air"},
        {pos: [5, 3, 6], state: "minecraft:lantern{waterlogged:false,hanging:true}"},
        {pos: [6, 3, 3], state: "minecraft:air"},
        {pos: [6, 3, 4], state: "minecraft:air"},
        {pos: [6, 3, 5], state: "minecraft:air"},
        {pos: [6, 3, 6], state: "minecraft:air"},
        {pos: [7, 3, 3], state: "minecraft:air"},
        {pos: [7, 3, 4], state: "minecraft:air"},
        {pos: [7, 3, 5], state: "minecraft:air"},
        {pos: [7, 3, 6], state: "minecraft:air"},
        {pos: [8, 3, 4], state: "minecraft:air"},
        {pos: [8, 3, 5], state: "minecraft:air"},
        {pos: [9, 3, 1], state: "minecraft:blackstone_wall{east:none,waterlogged:false,south:none,north:low,west:none,up:true}"},
        {pos: [9, 3, 3], state: "minecraft:air"},
        {pos: [10, 3, 0], state: "minecraft:air"},
        {pos: [10, 3, 3], state: "minecraft:air"},
        {pos: [10, 3, 4], state: "minecraft:air"},
        {pos: [10, 3, 5], state: "minecraft:air"},
        {pos: [11, 3, 0], state: "minecraft:air"},
        {pos: [11, 3, 1], state: "minecraft:air"},
        {pos: [11, 3, 2], state: "minecraft:air"},
        {pos: [11, 3, 3], state: "minecraft:air"},
        {pos: [11, 3, 4], state: "minecraft:air"},
        {pos: [11, 3, 5], state: "minecraft:air"},
        {pos: [11, 3, 7], state: "minecraft:air"},
        {pos: [12, 3, 0], state: "minecraft:air"},
        {pos: [12, 3, 4], state: "minecraft:air"},
        {pos: [12, 3, 7], state: "minecraft:air"},
        {pos: [13, 3, 0], state: "minecraft:air"},
        {pos: [13, 3, 6], state: "minecraft:air"},
        {pos: [13, 3, 7], state: "minecraft:air"},
        {pos: [0, 4, 0], state: "minecraft:air"},
        {pos: [1, 4, 0], state: "minecraft:air"},
        {pos: [1, 4, 3], state: "minecraft:air"},
        {pos: [2, 4, 0], state: "minecraft:air"},
        {pos: [2, 4, 1], state: "minecraft:air"},
        {pos: [4, 4, 5], state: "minecraft:air"},
        {pos: [4, 4, 6], state: "minecraft:air"},
        {pos: [5, 4, 1], state: "minecraft:lantern{waterlogged:false,hanging:true}"},
        {pos: [5, 4, 6], state: "minecraft:chain{waterlogged:false,axis:y}"},
        {pos: [11, 4, 0], state: "minecraft:air"},
        {pos: [12, 4, 0], state: "minecraft:air"},
        {pos: [12, 4, 7], state: "minecraft:air"},
        {pos: [13, 4, 0], state: "minecraft:air"},
        {pos: [13, 4, 7], state: "minecraft:air"},
        {pos: [0, 5, 0], state: "minecraft:air"},
        {pos: [1, 5, 0], state: "minecraft:air"},
        {pos: [2, 5, 0], state: "minecraft:air"},
        {pos: [12, 5, 0], state: "minecraft:air"},
        {pos: [13, 5, 0], state: "minecraft:air"},
        {pos: [13, 5, 6], state: "minecraft:air"},
        {pos: [13, 5, 7], state: "minecraft:air"},
        {pos: [0, 0, 0], state: "minecraft:jigsaw{orientation:north_up}", nbt: {final_state: "minecraft:polished_blackstone_bricks", id: "minecraft:jigsaw", joint: "rollable", name: "minecraft:outer_connector_left", pool: "minecraft:empty", target: "minecraft:empty"}},
        {pos: [0, 0, 7], state: "minecraft:jigsaw{orientation:south_up}", nbt: {final_state: "minecraft:polished_blackstone_bricks", id: "minecraft:jigsaw", joint: "rollable", name: "minecraft:outer_connector_right", pool: "minecraft:empty", target: "minecraft:empty"}},
        {pos: [4, 0, 4], state: "minecraft:jigsaw{orientation:up_north}", nbt: {final_state: "minecraft:basalt", id: "minecraft:jigsaw", joint: "aligned", name: "minecraft:empty", pool: "minecraft:bastion/mobs/piglin", target: "minecraft:mob_connector"}},
        {pos: [7, 0, 2], state: "minecraft:jigsaw{orientation:up_east}", nbt: {final_state: "minecraft:basalt", id: "minecraft:jigsaw", joint: "aligned", name: "minecraft:empty", pool: "minecraft:bastion/mobs/piglin", target: "minecraft:mob_connector"}}
    ],
    entities: [],
    palette: [
        "minecraft:polished_blackstone_bricks",
        "minecraft:basalt{axis:y}",
        "minecraft:blackstone_slab{waterlogged:false,type:bottom}",
        "minecraft:air",
        "minecraft:polished_blackstone_brick_stairs{half:bottom,waterlogged:false,shape:straight,facing:east}",
        "minecraft:polished_blackstone_brick_stairs{half:top,waterlogged:false,shape:straight,facing:west}",
        "minecraft:lantern{waterlogged:false,hanging:false}",
        "minecraft:blackstone_wall{east:none,waterlogged:false,south:none,north:low,west:none,up:true}",
        "minecraft:blackstone_wall{east:none,waterlogged:false,south:low,north:none,west:none,up:true}",
        "minecraft:lantern{waterlogged:false,hanging:true}",
        "minecraft:chain{waterlogged:false,axis:y}",
        "minecraft:jigsaw{orientation:north_up}",
        "minecraft:jigsaw{orientation:south_up}",
        "minecraft:jigsaw{orientation:up_north}",
        "minecraft:jigsaw{orientation:up_east}"
    ]
}