{
    size: [9, 6, 9],
    data: [
        {pos: [1, 0, 7], state: "minecraft:acacia_wood{axis:y}"},
        {pos: [3, 0, 4], state: "minecraft:acacia_wood{axis:y}"},
        {pos: [4, 0, 3], state: "minecraft:acacia_wood{axis:y}"},
        {pos: [4, 0, 4], state: "minecraft:acacia_wood{axis:y}"},
        {pos: [4, 0, 5], state: "minecraft:acacia_wood{axis:y}"},
        {pos: [5, 0, 4], state: "minecraft:acacia_wood{axis:y}"},
        {pos: [2, 1, 3], state: "minecraft:acacia_wood{axis:y}"},
        {pos: [2, 1, 4], state: "minecraft:acacia_wood{axis:y}"},
        {pos: [2, 1, 5], state: "minecraft:acacia_wood{axis:z}"},
        {pos: [3, 1, 2], state: "minecraft:acacia_wood{axis:y}"},
        {pos: [3, 1, 3], state: "minecraft:acacia_wood{axis:y}"},
        {pos: [3, 1, 5], state: "minecraft:acacia_wood{axis:y}"},
        {pos: [3, 1, 6], state: "minecraft:acacia_wood{axis:y}"},
        {pos: [4, 1, 2], state: "minecraft:acacia_wood{axis:y}"},
        {pos: [4, 1, 6], state: "minecraft:acacia_wood{axis:y}"},
        {pos: [5, 1, 2], state: "minecraft:acacia_wood{axis:y}"},
        {pos: [5, 1, 3], state: "minecraft:acacia_wood{axis:y}"},
        {pos: [5, 1, 5], state: "minecraft:acacia_wood{axis:y}"},
        {pos: [5, 1, 6], state: "minecraft:acacia_wood{axis:y}"},
        {pos: [6, 1, 3], state: "minecraft:acacia_wood{axis:y}"},
        {pos: [6, 1, 4], state: "minecraft:acacia_wood{axis:y}"},
        {pos: [6, 1, 5], state: "minecraft:acacia_wood{axis:y}"},
        {pos: [4, 4, 4], state: "minecraft:acacia_slab{waterlogged:false,type:double}"},
        {pos: [0, 0, 0], state: "minecraft:air"},
        {pos: [0, 0, 3], state: "minecraft:dirt_path"},
        {pos: [0, 0, 4], state: "minecraft:dirt_path"},
        {pos: [0, 0, 5], state: "minecraft:dirt_path"},
        {pos: [1, 0, 0], state: "minecraft:air"},
        {pos: [1, 0, 1], state: "minecraft:dirt_path"},
        {pos: [1, 0, 2], state: "minecraft:dirt_path"},
        {pos: [1, 0, 3], state: "minecraft:dirt_path"},
        {pos: [1, 0, 4], state: "minecraft:dirt_path"},
        {pos: [1, 0, 5], state: "minecraft:dirt_path"},
        {pos: [1, 0, 6], state: "minecraft:dirt_path"},
        {pos: [2, 0, 0], state: "minecraft:air"},
        {pos: [2, 0, 1], state: "minecraft:dirt_path"},
        {pos: [2, 0, 2], state: "minecraft:dirt_path"},
        {pos: [2, 0, 3], state: "minecraft:dirt_path"},
        {pos: [2, 0, 4], state: "minecraft:dirt_path"},
        {pos: [2, 0, 5], state: "minecraft:dirt_path"},
        {pos: [2, 0, 6], state: "minecraft:dirt_path"},
        {pos: [2, 0, 7], state: "minecraft:dirt_path"},
        {pos: [3, 0, 0], state: "minecraft:dirt_path"},
        {pos: [3, 0, 1], state: "minecraft:dirt_path"},
        {pos: [3, 0, 2], state: "minecraft:dirt_path"},
        {pos: [3, 0, 3], state: "minecraft:dirt_path"},
        {pos: [3, 0, 5], state: "minecraft:dirt_path"},
        {pos: [3, 0, 6], state: "minecraft:dirt_path"},
        {pos: [3, 0, 7], state: "minecraft:dirt_path"},
        {pos: [3, 0, 8], state: "minecraft:dirt_path"},
        {pos: [4, 0, 0], state: "minecraft:dirt_path"},
        {pos: [4, 0, 1], state: "minecraft:dirt_path"},
        {pos: [4, 0, 2], state: "minecraft:dirt_path"},
        {pos: [4, 0, 6], state: "minecraft:dirt_path"},
        {pos: [4, 0, 7], state: "minecraft:dirt_path"},
        {pos: [4, 0, 8], state: "minecraft:dirt_path"},
        {pos: [5, 0, 0], state: "minecraft:dirt_path"},
        {pos: [5, 0, 1], state: "minecraft:dirt_path"},
        {pos: [5, 0, 2], state: "minecraft:dirt_path"},
        {pos: [5, 0, 3], state: "minecraft:dirt_path"},
        {pos: [5, 0, 5], state: "minecraft:dirt_path"},
        {pos: [5, 0, 6], state: "minecraft:dirt_path"},
        {pos: [5, 0, 7], state: "minecraft:dirt_path"},
        {pos: [5, 0, 8], state: "minecraft:dirt_path"},
        {pos: [6, 0, 0], state: "minecraft:air"},
        {pos: [6, 0, 1], state: "minecraft:dirt_path"},
        {pos: [6, 0, 2], state: "minecraft:dirt_path"},
        {pos: [6, 0, 3], state: "minecraft:dirt_path"},
        {pos: [6, 0, 4], state: "minecraft:dirt_path"},
        {pos: [6, 0, 5], state: "minecraft:dirt_path"},
        {pos: [6, 0, 6], state: "minecraft:dirt_path"},
        {pos: [6, 0, 7], state: "minecraft:dirt_path"},
        {pos: [7, 0, 0], state: "minecraft:air"},
        {pos: [7, 0, 1], state: "minecraft:dirt_path"},
        {pos: [7, 0, 2], state: "minecraft:dirt_path"},
        {pos: [7, 0, 3], state: "minecraft:dirt_path"},
        {pos: [7, 0, 4], state: "minecraft:dirt_path"},
        {pos: [7, 0, 5], state: "minecraft:dirt_path"},
        {pos: [7, 0, 6], state: "minecraft:dirt_path"},
        {pos: [7, 0, 7], state: "minecraft:dirt_path"},
        {pos: [8, 0, 3], state: "minecraft:dirt_path"},
        {pos: [8, 0, 4], state: "minecraft:dirt_path"},
        {pos: [8, 0, 5], state: "minecraft:dirt_path"},
        {pos: [0, 1, 0], state: "minecraft:air"},
        {pos: [1, 1, 0], state: "minecraft:air"},
        {pos: [2, 1, 0], state: "minecraft:air"},
        {pos: [3, 1, 0], state: "minecraft:air"},
        {pos: [3, 1, 4], state: "minecraft:water{level:0}"},
        {pos: [4, 1, 3], state: "minecraft:water{level:0}"},
        {pos: [4, 1, 4], state: "minecraft:water{level:0}"},
        {pos: [4, 1, 5], state: "minecraft:water{level:0}"},
        {pos: [5, 1, 0], state: "minecraft:air"},
        {pos: [5, 1, 4], state: "minecraft:water{level:0}"},
        {pos: [6, 1, 0], state: "minecraft:air"},
        {pos: [7, 1, 0], state: "minecraft:air"},
        {pos: [8, 1, 0], state: "minecraft:air"},
        {pos: [0, 2, 0], state: "minecraft:air"},
        {pos: [1, 2, 0], state: "minecraft:air"},
        {pos: [2, 2, 0], state: "minecraft:air"},
        {pos: [2, 2, 4], state: "minecraft:torch"},
        {pos: [3, 2, 0], state: "minecraft:air"},
        {pos: [3, 2, 3], state: "minecraft:acacia_fence{east:false,waterlogged:false,south:false,north:false,west:false}"},
        {pos: [3, 2, 5], state: "minecraft:acacia_fence{east:false,waterlogged:false,south:false,north:false,west:false}"},
        {pos: [4, 2, 0], state: "minecraft:air"},
        {pos: [4, 2, 2], state: "minecraft:torch"},
        {pos: [4, 2, 6], state: "minecraft:torch"},
        {pos: [5, 2, 0], state: "minecraft:air"},
        {pos: [5, 2, 3], state: "minecraft:acacia_fence{east:false,waterlogged:false,south:false,north:false,west:false}"},
        {pos: [5, 2, 5], state: "minecraft:acacia_fence{east:false,waterlogged:false,south:false,north:false,west:false}"},
        {pos: [6, 2, 0], state: "minecraft:air"},
        {pos: [6, 2, 4], state: "minecraft:torch"},
        {pos: [7, 2, 0], state: "minecraft:air"},
        {pos: [8, 2, 0], state: "minecraft:air"},
        {pos: [0, 3, 0], state: "minecraft:air"},
        {pos: [1, 3, 0], state: "minecraft:air"},
        {pos: [2, 3, 0], state: "minecraft:air"},
        {pos: [3, 3, 0], state: "minecraft:air"},
        {pos: [3, 3, 3], state: "minecraft:acacia_fence{east:false,waterlogged:false,south:false,north:false,west:false}"},
        {pos: [3, 3, 5], state: "minecraft:acacia_fence{east:false,waterlogged:false,south:false,north:false,west:false}"},
        {pos: [4, 3, 0], state: "minecraft:air"},
        {pos: [5, 3, 0], state: "minecraft:air"},
        {pos: [5, 3, 3], state: "minecraft:acacia_fence{east:false,waterlogged:false,south:false,north:false,west:false}"},
        {pos: [5, 3, 5], state: "minecraft:acacia_fence{east:false,waterlogged:false,south:false,north:false,west:false}"},
        {pos: [6, 3, 0], state: "minecraft:air"},
        {pos: [7, 3, 0], state: "minecraft:air"},
        {pos: [8, 3, 0], state: "minecraft:air"},
        {pos: [0, 4, 0], state: "minecraft:air"},
        {pos: [1, 4, 0], state: "minecraft:air"},
        {pos: [2, 4, 0], state: "minecraft:air"},
        {pos: [3, 4, 0], state: "minecraft:air"},
        {pos: [3, 4, 3], state: "minecraft:acacia_stairs{half:bottom,waterlogged:false,shape:outer_right,facing:east}"},
        {pos: [3, 4, 4], state: "minecraft:acacia_stairs{half:bottom,waterlogged:false,shape:straight,facing:east}"},
        {pos: [3, 4, 5], state: "minecraft:acacia_stairs{half:bottom,waterlogged:false,shape:outer_left,facing:east}"},
        {pos: [4, 4, 0], state: "minecraft:air"},
        {pos: [4, 4, 3], state: "minecraft:acacia_stairs{half:bottom,waterlogged:false,shape:straight,facing:south}"},
        {pos: [4, 4, 5], state: "minecraft:acacia_stairs{half:bottom,waterlogged:false,shape:straight,facing:north}"},
        {pos: [5, 4, 0], state: "minecraft:air"},
        {pos: [5, 4, 3], state: "minecraft:acacia_stairs{half:bottom,waterlogged:false,shape:outer_right,facing:south}"},
        {pos: [5, 4, 4], state: "minecraft:acacia_stairs{half:bottom,waterlogged:false,shape:straight,facing:west}"},
        {pos: [5, 4, 5], state: "minecraft:acacia_stairs{half:bottom,waterlogged:false,shape:outer_right,facing:west}"},
        {pos: [6, 4, 0], state: "minecraft:air"},
        {pos: [7, 4, 0], state: "minecraft:air"},
        {pos: [8, 4, 0], state: "minecraft:air"},
        {pos: [0, 5, 0], state: "minecraft:air"},
        {pos: [1, 5, 0], state: "minecraft:air"},
        {pos: [2, 5, 0], state: "minecraft:air"},
        {pos: [3, 5, 0], state: "minecraft:air"},
        {pos: [4, 5, 0], state: "minecraft:air"},
        {pos: [5, 5, 0], state: "minecraft:air"},
        {pos: [6, 5, 0], state: "minecraft:air"},
        {pos: [7, 5, 0], state: "minecraft:air"},
        {pos: [8, 5, 0], state: "minecraft:air"},
        {pos: [7, 0, 8], state: "minecraft:jigsaw{orientation:up_north}", nbt: {final_state: "minecraft:grass_block", id: "minecraft:jigsaw", joint: "rollable", name: "minecraft:bottom", pool: "minecraft:village/common/cats", target: "minecraft:bottom"}},
        {pos: [8, 0, 0], state: "minecraft:jigsaw{orientation:up_north}", nbt: {final_state: "minecraft:grass_block", id: "minecraft:jigsaw", joint: "rollable", name: "minecraft:bottom", pool: "minecraft:village/common/cats", target: "minecraft:bottom"}},
        {pos: [0, 1, 4], state: "minecraft:jigsaw{orientation:west_up}", nbt: {final_state: "minecraft:structure_void", id: "minecraft:jigsaw", joint: "aligned", name: "minecraft:street", pool: "minecraft:village/savanna/zombie/streets", target: "minecraft:street"}},
        {pos: [1, 1, 7], state: "minecraft:bell{attachment:floor,powered:false,facing:east}", nbt: {id: "minecraft:bell"}},
        {pos: [4, 1, 0], state: "minecraft:jigsaw{orientation:north_up}", nbt: {final_state: "minecraft:structure_void", id: "minecraft:jigsaw", joint: "aligned", name: "minecraft:street", pool: "minecraft:village/savanna/zombie/streets", target: "minecraft:street"}},
        {pos: [4, 1, 8], state: "minecraft:jigsaw{orientation:south_up}", nbt: {final_state: "minecraft:structure_void", id: "minecraft:jigsaw", joint: "aligned", name: "minecraft:street", pool: "minecraft:village/savanna/zombie/streets", target: "minecraft:street"}},
        {pos: [8, 1, 4], state: "minecraft:jigsaw{orientation:east_up}", nbt: {final_state: "minecraft:structure_void", id: "minecraft:jigsaw", joint: "aligned", name: "minecraft:street", pool: "minecraft:village/savanna/zombie/streets", target: "minecraft:street"}}
    ],
    entities: [],
    palette: [
        "minecraft:acacia_wood{axis:y}",
        "minecraft:acacia_wood{axis:z}",
        "minecraft:acacia_slab{waterlogged:false,type:double}",
        "minecraft:air",
        "minecraft:dirt_path",
        "minecraft:water{level:0}",
        "minecraft:torch",
        "minecraft:acacia_fence{east:false,waterlogged:false,south:false,north:false,west:false}",
        "minecraft:acacia_stairs{half:bottom,waterlogged:false,shape:outer_right,facing:east}",
        "minecraft:acacia_stairs{half:bottom,waterlogged:false,shape:straight,facing:east}",
        "minecraft:acacia_stairs{half:bottom,waterlogged:false,shape:outer_left,facing:east}",
        "minecraft:acacia_stairs{half:bottom,waterlogged:false,shape:straight,facing:south}",
        "minecraft:acacia_stairs{half:bottom,waterlogged:false,shape:straight,facing:north}",
        "minecraft:acacia_stairs{half:bottom,waterlogged:false,shape:outer_right,facing:south}",
        "minecraft:acacia_stairs{half:bottom,waterlogged:false,shape:straight,facing:west}",
        "minecraft:acacia_stairs{half:bottom,waterlogged:false,shape:outer_right,facing:west}",
        "minecraft:jigsaw{orientation:up_north}",
        "minecraft:jigsaw{orientation:west_up}",
        "minecraft:bell{attachment:floor,powered:false,facing:east}",
        "minecraft:jigsaw{orientation:north_up}",
        "minecraft:jigsaw{orientation:south_up}",
        "minecraft:jigsaw{orientation:east_up}"
    ]
}