{
    size: [6, 12, 11],
    data: [
        {pos: [0, 0, 2], state: "minecraft:waxed_oxidized_copper"},
        {pos: [0, 0, 3], state: "minecraft:waxed_oxidized_copper"},
        {pos: [0, 0, 4], state: "minecraft:waxed_oxidized_copper"},
        {pos: [0, 0, 5], state: "minecraft:tuff_bricks"},
        {pos: [0, 0, 6], state: "minecraft:tuff_bricks"},
        {pos: [0, 0, 7], state: "minecraft:tuff_bricks"},
        {pos: [0, 0, 8], state: "minecraft:tuff_bricks"},
        {pos: [0, 0, 9], state: "minecraft:tuff_bricks"},
        {pos: [0, 0, 10], state: "minecraft:tuff_bricks"},
        {pos: [1, 0, 0], state: "minecraft:tuff_bricks"},
        {pos: [1, 0, 1], state: "minecraft:waxed_oxidized_cut_copper"},
        {pos: [1, 0, 2], state: "minecraft:waxed_oxidized_copper"},
        {pos: [1, 0, 3], state: "minecraft:waxed_oxidized_copper"},
        {pos: [1, 0, 4], state: "minecraft:waxed_oxidized_copper"},
        {pos: [1, 0, 5], state: "minecraft:waxed_oxidized_cut_copper"},
        {pos: [1, 0, 6], state: "minecraft:tuff_bricks"},
        {pos: [1, 0, 7], state: "minecraft:tuff_bricks"},
        {pos: [1, 0, 8], state: "minecraft:tuff_bricks"},
        {pos: [1, 0, 9], state: "minecraft:tuff_bricks"},
        {pos: [1, 0, 10], state: "minecraft:tuff_bricks"},
        {pos: [2, 0, 0], state: "minecraft:tuff_bricks"},
        {pos: [2, 0, 1], state: "minecraft:waxed_oxidized_cut_copper"},
        {pos: [2, 0, 2], state: "minecraft:waxed_oxidized_copper"},
        {pos: [2, 0, 3], state: "minecraft:waxed_oxidized_copper"},
        {pos: [2, 0, 4], state: "minecraft:waxed_oxidized_copper"},
        {pos: [2, 0, 5], state: "minecraft:waxed_oxidized_cut_copper"},
        {pos: [2, 0, 6], state: "minecraft:tuff_bricks"},
        {pos: [2, 0, 7], state: "minecraft:tuff_bricks"},
        {pos: [2, 0, 8], state: "minecraft:tuff_bricks"},
        {pos: [2, 0, 9], state: "minecraft:tuff_bricks"},
        {pos: [2, 0, 10], state: "minecraft:tuff_bricks"},
        {pos: [3, 0, 0], state: "minecraft:tuff_bricks"},
        {pos: [3, 0, 1], state: "minecraft:waxed_oxidized_cut_copper"},
        {pos: [3, 0, 2], state: "minecraft:waxed_oxidized_copper"},
        {pos: [3, 0, 3], state: "minecraft:waxed_oxidized_copper"},
        {pos: [3, 0, 4], state: "minecraft:waxed_oxidized_copper"},
        {pos: [3, 0, 5], state: "minecraft:waxed_oxidized_cut_copper"},
        {pos: [3, 0, 6], state: "minecraft:tuff_bricks"},
        {pos: [3, 0, 7], state: "minecraft:tuff_bricks"},
        {pos: [3, 0, 8], state: "minecraft:tuff_bricks"},
        {pos: [3, 0, 9], state: "minecraft:tuff_bricks"},
        {pos: [3, 0, 10], state: "minecraft:tuff_bricks"},
        {pos: [4, 0, 2], state: "minecraft:tuff_bricks"},
        {pos: [4, 0, 3], state: "minecraft:tuff_bricks"},
        {pos: [4, 0, 4], state: "minecraft:tuff_bricks"},
        {pos: [4, 0, 7], state: "minecraft:tuff_bricks"},
        {pos: [4, 0, 8], state: "minecraft:tuff_bricks"},
        {pos: [4, 0, 9], state: "minecraft:tuff_bricks"},
        {pos: [5, 0, 2], state: "minecraft:tuff_bricks"},
        {pos: [5, 0, 3], state: "minecraft:tuff_bricks"},
        {pos: [5, 0, 4], state: "minecraft:tuff_bricks"},
        {pos: [5, 0, 7], state: "minecraft:tuff_bricks"},
        {pos: [5, 0, 8], state: "minecraft:tuff_bricks"},
        {pos: [5, 0, 9], state: "minecraft:tuff_bricks"},
        {pos: [0, 1, 5], state: "minecraft:waxed_copper_block"},
        {pos: [0, 1, 6], state: "minecraft:waxed_copper_block"},
        {pos: [0, 1, 7], state: "minecraft:waxed_copper_block"},
        {pos: [0, 1, 8], state: "minecraft:waxed_copper_block"},
        {pos: [0, 1, 9], state: "minecraft:waxed_copper_block"},
        {pos: [0, 1, 10], state: "minecraft:waxed_copper_block"},
        {pos: [1, 1, 0], state: "minecraft:waxed_copper_block"},
        {pos: [1, 1, 6], state: "minecraft:waxed_copper_block"},
        {pos: [1, 1, 7], state: "minecraft:tuff_bricks"},
        {pos: [1, 1, 8], state: "minecraft:tuff_bricks"},
        {pos: [1, 1, 9], state: "minecraft:tuff_bricks"},
        {pos: [1, 1, 10], state: "minecraft:tuff_bricks"},
        {pos: [2, 1, 0], state: "minecraft:waxed_copper_block"},
        {pos: [2, 1, 6], state: "minecraft:waxed_copper_block"},
        {pos: [2, 1, 7], state: "minecraft:tuff_bricks"},
        {pos: [2, 1, 8], state: "minecraft:tuff_bricks"},
        {pos: [2, 1, 9], state: "minecraft:tuff_bricks"},
        {pos: [2, 1, 10], state: "minecraft:tuff_bricks"},
        {pos: [3, 1, 0], state: "minecraft:waxed_copper_block"},
        {pos: [3, 1, 6], state: "minecraft:waxed_copper_block"},
        {pos: [3, 1, 7], state: "minecraft:tuff_bricks"},
        {pos: [3, 1, 8], state: "minecraft:tuff_bricks"},
        {pos: [3, 1, 9], state: "minecraft:tuff_bricks"},
        {pos: [3, 1, 10], state: "minecraft:tuff_bricks"},
        {pos: [4, 1, 2], state: "minecraft:waxed_copper_block"},
        {pos: [4, 1, 3], state: "minecraft:waxed_copper_block"},
        {pos: [4, 1, 4], state: "minecraft:waxed_copper_block"},
        {pos: [4, 1, 7], state: "minecraft:tuff_bricks"},
        {pos: [4, 1, 8], state: "minecraft:tuff_bricks"},
        {pos: [4, 1, 9], state: "minecraft:tuff_bricks"},
        {pos: [5, 1, 2], state: "minecraft:waxed_copper_block"},
        {pos: [5, 1, 3], state: "minecraft:waxed_copper_block"},
        {pos: [5, 1, 4], state: "minecraft:waxed_copper_block"},
        {pos: [5, 1, 7], state: "minecraft:waxed_copper_block"},
        {pos: [5, 1, 8], state: "minecraft:waxed_copper_block"},
        {pos: [5, 1, 9], state: "minecraft:waxed_copper_block"},
        {pos: [0, 2, 5], state: "minecraft:tuff_bricks"},
        {pos: [0, 2, 6], state: "minecraft:tuff_bricks"},
        {pos: [0, 2, 7], state: "minecraft:tuff_bricks"},
        {pos: [0, 2, 8], state: "minecraft:waxed_copper_bulb{powered:false,lit:true}"},
        {pos: [0, 2, 9], state: "minecraft:tuff_bricks"},
        {pos: [0, 2, 10], state: "minecraft:tuff_bricks"},
        {pos: [1, 2, 0], state: "minecraft:tuff_bricks"},
        {pos: [1, 2, 6], state: "minecraft:tuff_bricks"},
        {pos: [1, 2, 7], state: "minecraft:tuff_bricks"},
        {pos: [1, 2, 8], state: "minecraft:tuff_bricks"},
        {pos: [1, 2, 9], state: "minecraft:tuff_bricks"},
        {pos: [1, 2, 10], state: "minecraft:tuff_bricks"},
        {pos: [2, 2, 0], state: "minecraft:waxed_copper_bulb{powered:false,lit:true}"},
        {pos: [2, 2, 6], state: "minecraft:waxed_copper_bulb{powered:false,lit:true}"},
        {pos: [2, 2, 7], state: "minecraft:tuff_bricks"},
        {pos: [2, 2, 8], state: "minecraft:tuff_bricks"},
        {pos: [2, 2, 9], state: "minecraft:tuff_bricks"},
        {pos: [2, 2, 10], state: "minecraft:tuff_bricks"},
        {pos: [3, 2, 0], state: "minecraft:tuff_bricks"},
        {pos: [3, 2, 6], state: "minecraft:tuff_bricks"},
        {pos: [3, 2, 7], state: "minecraft:tuff_bricks"},
        {pos: [3, 2, 8], state: "minecraft:tuff_bricks"},
        {pos: [3, 2, 9], state: "minecraft:tuff_bricks"},
        {pos: [3, 2, 10], state: "minecraft:tuff_bricks"},
        {pos: [4, 2, 2], state: "minecraft:tuff_bricks"},
        {pos: [4, 2, 3], state: "minecraft:tuff_bricks"},
        {pos: [4, 2, 4], state: "minecraft:tuff_bricks"},
        {pos: [4, 2, 7], state: "minecraft:tuff_bricks"},
        {pos: [4, 2, 8], state: "minecraft:tuff_bricks"},
        {pos: [4, 2, 9], state: "minecraft:tuff_bricks"},
        {pos: [5, 2, 2], state: "minecraft:tuff_bricks"},
        {pos: [5, 2, 3], state: "minecraft:waxed_copper_bulb{powered:false,lit:true}"},
        {pos: [5, 2, 4], state: "minecraft:tuff_bricks"},
        {pos: [5, 2, 7], state: "minecraft:tuff_bricks"},
        {pos: [5, 2, 8], state: "minecraft:waxed_copper_bulb{powered:false,lit:true}"},
        {pos: [5, 2, 9], state: "minecraft:tuff_bricks"},
        {pos: [0, 3, 5], state: "minecraft:chiseled_tuff_bricks"},
        {pos: [0, 3, 6], state: "minecraft:chiseled_tuff_bricks"},
        {pos: [0, 3, 7], state: "minecraft:chiseled_tuff_bricks"},
        {pos: [0, 3, 8], state: "minecraft:chiseled_tuff_bricks"},
        {pos: [0, 3, 9], state: "minecraft:chiseled_tuff_bricks"},
        {pos: [0, 3, 10], state: "minecraft:chiseled_tuff_bricks"},
        {pos: [1, 3, 0], state: "minecraft:chiseled_tuff_bricks"},
        {pos: [1, 3, 6], state: "minecraft:chiseled_tuff_bricks"},
        {pos: [1, 3, 7], state: "minecraft:tuff_bricks"},
        {pos: [1, 3, 8], state: "minecraft:tuff_bricks"},
        {pos: [1, 3, 9], state: "minecraft:tuff_bricks"},
        {pos: [1, 3, 10], state: "minecraft:chiseled_tuff_bricks"},
        {pos: [2, 3, 0], state: "minecraft:chiseled_tuff_bricks"},
        {pos: [2, 3, 6], state: "minecraft:chiseled_tuff_bricks"},
        {pos: [2, 3, 7], state: "minecraft:tuff_bricks"},
        {pos: [2, 3, 8], state: "minecraft:tuff_bricks"},
        {pos: [2, 3, 9], state: "minecraft:tuff_bricks"},
        {pos: [2, 3, 10], state: "minecraft:chiseled_tuff_bricks"},
        {pos: [3, 3, 0], state: "minecraft:chiseled_tuff_bricks"},
        {pos: [3, 3, 6], state: "minecraft:chiseled_tuff_bricks"},
        {pos: [3, 3, 7], state: "minecraft:chiseled_tuff_bricks"},
        {pos: [3, 3, 8], state: "minecraft:tuff_bricks"},
        {pos: [3, 3, 9], state: "minecraft:tuff_bricks"},
        {pos: [3, 3, 10], state: "minecraft:chiseled_tuff_bricks"},
        {pos: [4, 3, 2], state: "minecraft:chiseled_tuff_bricks"},
        {pos: [4, 3, 3], state: "minecraft:chiseled_tuff_bricks"},
        {pos: [4, 3, 4], state: "minecraft:chiseled_tuff_bricks"},
        {pos: [4, 3, 7], state: "minecraft:chiseled_tuff_bricks"},
        {pos: [4, 3, 8], state: "minecraft:tuff_bricks"},
        {pos: [4, 3, 9], state: "minecraft:tuff_bricks"},
        {pos: [5, 3, 2], state: "minecraft:chiseled_tuff_bricks"},
        {pos: [5, 3, 3], state: "minecraft:chiseled_tuff_bricks"},
        {pos: [5, 3, 4], state: "minecraft:chiseled_tuff_bricks"},
        {pos: [5, 3, 7], state: "minecraft:chiseled_tuff_bricks"},
        {pos: [5, 3, 8], state: "minecraft:chiseled_tuff_bricks"},
        {pos: [5, 3, 9], state: "minecraft:chiseled_tuff_bricks"},
        {pos: [0, 4, 2], state: "minecraft:polished_tuff"},
        {pos: [0, 4, 3], state: "minecraft:polished_tuff"},
        {pos: [0, 4, 4], state: "minecraft:polished_tuff"},
        {pos: [0, 4, 5], state: "minecraft:tuff_bricks"},
        {pos: [0, 4, 6], state: "minecraft:tuff_bricks"},
        {pos: [0, 4, 7], state: "minecraft:tuff_bricks"},
        {pos: [0, 4, 8], state: "minecraft:tuff_bricks"},
        {pos: [0, 4, 9], state: "minecraft:tuff_bricks"},
        {pos: [0, 4, 10], state: "minecraft:tuff_bricks"},
        {pos: [1, 4, 0], state: "minecraft:tuff_bricks"},
        {pos: [1, 4, 1], state: "minecraft:polished_tuff"},
        {pos: [1, 4, 2], state: "minecraft:polished_tuff"},
        {pos: [1, 4, 3], state: "minecraft:polished_tuff"},
        {pos: [1, 4, 4], state: "minecraft:polished_tuff"},
        {pos: [1, 4, 5], state: "minecraft:polished_tuff"},
        {pos: [1, 4, 6], state: "minecraft:tuff_bricks"},
        {pos: [1, 4, 7], state: "minecraft:tuff_bricks"},
        {pos: [1, 4, 8], state: "minecraft:tuff_bricks"},
        {pos: [1, 4, 9], state: "minecraft:tuff_bricks"},
        {pos: [1, 4, 10], state: "minecraft:tuff_bricks"},
        {pos: [2, 4, 0], state: "minecraft:tuff_bricks"},
        {pos: [2, 4, 1], state: "minecraft:polished_tuff"},
        {pos: [2, 4, 2], state: "minecraft:polished_tuff"},
        {pos: [2, 4, 3], state: "minecraft:polished_tuff"},
        {pos: [2, 4, 4], state: "minecraft:polished_tuff"},
        {pos: [2, 4, 5], state: "minecraft:polished_tuff"},
        {pos: [2, 4, 6], state: "minecraft:tuff_bricks"},
        {pos: [2, 4, 7], state: "minecraft:tuff_bricks"},
        {pos: [2, 4, 8], state: "minecraft:tuff_bricks"},
        {pos: [2, 4, 9], state: "minecraft:tuff_bricks"},
        {pos: [2, 4, 10], state: "minecraft:tuff_bricks"},
        {pos: [3, 4, 0], state: "minecraft:tuff_bricks"},
        {pos: [3, 4, 1], state: "minecraft:polished_tuff"},
        {pos: [3, 4, 2], state: "minecraft:polished_tuff"},
        {pos: [3, 4, 4], state: "minecraft:polished_tuff"},
        {pos: [3, 4, 5], state: "minecraft:polished_tuff"},
        {pos: [3, 4, 6], state: "minecraft:tuff_bricks"},
        {pos: [3, 4, 7], state: "minecraft:tuff_bricks"},
        {pos: [3, 4, 8], state: "minecraft:tuff_bricks"},
        {pos: [3, 4, 9], state: "minecraft:tuff_bricks"},
        {pos: [3, 4, 10], state: "minecraft:tuff_bricks"},
        {pos: [4, 4, 2], state: "minecraft:tuff_bricks"},
        {pos: [4, 4, 3], state: "minecraft:tuff_bricks"},
        {pos: [4, 4, 4], state: "minecraft:tuff_bricks"},
        {pos: [4, 4, 7], state: "minecraft:tuff_bricks"},
        {pos: [4, 4, 8], state: "minecraft:tuff_bricks"},
        {pos: [4, 4, 9], state: "minecraft:tuff_bricks"},
        {pos: [5, 4, 2], state: "minecraft:tuff_bricks"},
        {pos: [5, 4, 3], state: "minecraft:tuff_bricks"},
        {pos: [5, 4, 4], state: "minecraft:tuff_bricks"},
        {pos: [5, 4, 7], state: "minecraft:tuff_bricks"},
        {pos: [5, 4, 8], state: "minecraft:tuff_bricks"},
        {pos: [5, 4, 9], state: "minecraft:tuff_bricks"},
        {pos: [0, 5, 2], state: "minecraft:waxed_oxidized_copper"},
        {pos: [0, 5, 3], state: "minecraft:waxed_oxidized_copper"},
        {pos: [0, 5, 4], state: "minecraft:waxed_oxidized_copper"},
        {pos: [0, 5, 5], state: "minecraft:waxed_oxidized_copper"},
        {pos: [0, 5, 6], state: "minecraft:waxed_copper_block"},
        {pos: [0, 5, 7], state: "minecraft:waxed_copper_block"},
        {pos: [0, 5, 8], state: "minecraft:waxed_copper_block"},
        {pos: [0, 5, 9], state: "minecraft:waxed_copper_block"},
        {pos: [0, 5, 10], state: "minecraft:waxed_copper_block"},
        {pos: [1, 5, 0], state: "minecraft:tuff_bricks"},
        {pos: [1, 5, 1], state: "minecraft:waxed_oxidized_copper"},
        {pos: [1, 5, 2], state: "minecraft:waxed_oxidized_copper"},
        {pos: [1, 5, 3], state: "minecraft:waxed_oxidized_copper"},
        {pos: [1, 5, 4], state: "minecraft:waxed_oxidized_copper"},
        {pos: [1, 5, 5], state: "minecraft:waxed_oxidized_copper"},
        {pos: [1, 5, 6], state: "minecraft:waxed_oxidized_copper"},
        {pos: [1, 5, 7], state: "minecraft:waxed_oxidized_copper"},
        {pos: [1, 5, 8], state: "minecraft:waxed_oxidized_copper"},
        {pos: [1, 5, 9], state: "minecraft:waxed_oxidized_copper"},
        {pos: [1, 5, 10], state: "minecraft:waxed_oxidized_copper"},
        {pos: [2, 5, 0], state: "minecraft:tuff_bricks"},
        {pos: [2, 5, 1], state: "minecraft:waxed_oxidized_copper"},
        {pos: [2, 5, 2], state: "minecraft:waxed_oxidized_copper"},
        {pos: [2, 5, 3], state: "minecraft:waxed_copper_block"},
        {pos: [2, 5, 4], state: "minecraft:waxed_oxidized_copper"},
        {pos: [2, 5, 5], state: "minecraft:waxed_oxidized_copper"},
        {pos: [2, 5, 6], state: "minecraft:waxed_oxidized_copper"},
        {pos: [2, 5, 7], state: "minecraft:waxed_oxidized_copper"},
        {pos: [2, 5, 8], state: "minecraft:waxed_oxidized_copper"},
        {pos: [2, 5, 9], state: "minecraft:waxed_oxidized_copper"},
        {pos: [2, 5, 10], state: "minecraft:waxed_oxidized_copper"},
        {pos: [3, 5, 0], state: "minecraft:tuff_bricks"},
        {pos: [3, 5, 1], state: "minecraft:waxed_oxidized_copper"},
        {pos: [3, 5, 2], state: "minecraft:waxed_copper_block"},
        {pos: [3, 5, 4], state: "minecraft:waxed_copper_block"},
        {pos: [3, 5, 5], state: "minecraft:waxed_oxidized_copper"},
        {pos: [3, 5, 6], state: "minecraft:waxed_oxidized_copper"},
        {pos: [3, 5, 7], state: "minecraft:waxed_oxidized_copper"},
        {pos: [3, 5, 8], state: "minecraft:waxed_oxidized_copper"},
        {pos: [3, 5, 9], state: "minecraft:waxed_oxidized_copper"},
        {pos: [3, 5, 10], state: "minecraft:waxed_oxidized_copper"},
        {pos: [4, 5, 2], state: "minecraft:waxed_oxidized_copper"},
        {pos: [4, 5, 3], state: "minecraft:tuff_bricks"},
        {pos: [4, 5, 4], state: "minecraft:waxed_oxidized_copper"},
        {pos: [4, 5, 7], state: "minecraft:waxed_oxidized_copper"},
        {pos: [4, 5, 8], state: "minecraft:waxed_oxidized_copper"},
        {pos: [4, 5, 9], state: "minecraft:waxed_oxidized_copper"},
        {pos: [5, 5, 2], state: "minecraft:tuff_bricks"},
        {pos: [5, 5, 3], state: "minecraft:tuff_bricks"},
        {pos: [5, 5, 4], state: "minecraft:tuff_bricks"},
        {pos: [5, 5, 7], state: "minecraft:tuff_bricks"},
        {pos: [5, 5, 8], state: "minecraft:tuff_bricks"},
        {pos: [5, 5, 9], state: "minecraft:tuff_bricks"},
        {pos: [0, 6, 6], state: "minecraft:waxed_copper_block"},
        {pos: [0, 6, 7], state: "minecraft:waxed_copper_grate{waterlogged:false}"},
        {pos: [0, 6, 8], state: "minecraft:waxed_copper_grate{waterlogged:false}"},
        {pos: [0, 6, 9], state: "minecraft:waxed_copper_grate{waterlogged:false}"},
        {pos: [0, 6, 10], state: "minecraft:waxed_copper_block"},
        {pos: [1, 6, 0], state: "minecraft:waxed_copper_block"},
        {pos: [2, 6, 0], state: "minecraft:waxed_copper_block"},
        {pos: [3, 6, 0], state: "minecraft:waxed_copper_block"},
        {pos: [4, 6, 3], state: "minecraft:waxed_chiseled_copper"},
        {pos: [5, 6, 2], state: "minecraft:waxed_copper_block"},
        {pos: [5, 6, 3], state: "minecraft:waxed_copper_block"},
        {pos: [5, 6, 4], state: "minecraft:waxed_copper_block"},
        {pos: [5, 6, 7], state: "minecraft:waxed_copper_block"},
        {pos: [5, 6, 8], state: "minecraft:waxed_copper_block"},
        {pos: [5, 6, 9], state: "minecraft:waxed_copper_block"},
        {pos: [0, 7, 6], state: "minecraft:waxed_copper_block"},
        {pos: [0, 7, 7], state: "minecraft:waxed_copper_grate{waterlogged:false}"},
        {pos: [0, 7, 8], state: "minecraft:waxed_copper_grate{waterlogged:false}"},
        {pos: [0, 7, 9], state: "minecraft:waxed_copper_grate{waterlogged:false}"},
        {pos: [0, 7, 10], state: "minecraft:waxed_chiseled_copper"},
        {pos: [1, 7, 0], state: "minecraft:tuff_bricks"},
        {pos: [2, 7, 0], state: "minecraft:waxed_copper_bulb{powered:false,lit:true}"},
        {pos: [3, 7, 0], state: "minecraft:tuff_bricks"},
        {pos: [5, 7, 2], state: "minecraft:tuff_bricks"},
        {pos: [5, 7, 3], state: "minecraft:waxed_copper_bulb{powered:false,lit:true}"},
        {pos: [5, 7, 4], state: "minecraft:tuff_bricks"},
        {pos: [5, 7, 7], state: "minecraft:tuff_bricks"},
        {pos: [5, 7, 8], state: "minecraft:waxed_copper_bulb{powered:false,lit:true}"},
        {pos: [5, 7, 9], state: "minecraft:tuff_bricks"},
        {pos: [0, 8, 6], state: "minecraft:waxed_copper_block"},
        {pos: [0, 8, 7], state: "minecraft:waxed_copper_grate{waterlogged:false}"},
        {pos: [0, 8, 8], state: "minecraft:waxed_copper_grate{waterlogged:false}"},
        {pos: [0, 8, 9], state: "minecraft:waxed_copper_grate{waterlogged:false}"},
        {pos: [0, 8, 10], state: "minecraft:waxed_copper_block"},
        {pos: [1, 8, 0], state: "minecraft:chiseled_tuff_bricks"},
        {pos: [2, 8, 0], state: "minecraft:chiseled_tuff_bricks"},
        {pos: [3, 8, 0], state: "minecraft:chiseled_tuff_bricks"},
        {pos: [5, 8, 2], state: "minecraft:chiseled_tuff_bricks"},
        {pos: [5, 8, 3], state: "minecraft:chiseled_tuff_bricks"},
        {pos: [5, 8, 4], state: "minecraft:chiseled_tuff_bricks"},
        {pos: [5, 8, 7], state: "minecraft:chiseled_tuff_bricks"},
        {pos: [5, 8, 8], state: "minecraft:chiseled_tuff_bricks"},
        {pos: [5, 8, 9], state: "minecraft:chiseled_tuff_bricks"},
        {pos: [0, 9, 2], state: "minecraft:polished_tuff"},
        {pos: [0, 9, 3], state: "minecraft:polished_tuff"},
        {pos: [0, 9, 4], state: "minecraft:polished_tuff"},
        {pos: [0, 9, 5], state: "minecraft:polished_tuff"},
        {pos: [0, 9, 6], state: "minecraft:waxed_copper_block"},
        {pos: [0, 9, 7], state: "minecraft:waxed_copper_block"},
        {pos: [0, 9, 8], state: "minecraft:waxed_copper_block"},
        {pos: [0, 9, 9], state: "minecraft:waxed_copper_block"},
        {pos: [0, 9, 10], state: "minecraft:waxed_copper_block"},
        {pos: [1, 9, 0], state: "minecraft:tuff_bricks"},
        {pos: [1, 9, 1], state: "minecraft:polished_tuff"},
        {pos: [1, 9, 2], state: "minecraft:polished_tuff"},
        {pos: [1, 9, 3], state: "minecraft:polished_tuff"},
        {pos: [1, 9, 4], state: "minecraft:polished_tuff"},
        {pos: [1, 9, 5], state: "minecraft:polished_tuff"},
        {pos: [1, 9, 6], state: "minecraft:polished_tuff"},
        {pos: [1, 9, 7], state: "minecraft:polished_tuff"},
        {pos: [1, 9, 8], state: "minecraft:polished_tuff"},
        {pos: [1, 9, 9], state: "minecraft:polished_tuff"},
        {pos: [1, 9, 10], state: "minecraft:polished_tuff"},
        {pos: [2, 9, 0], state: "minecraft:tuff_bricks"},
        {pos: [2, 9, 1], state: "minecraft:polished_tuff"},
        {pos: [2, 9, 2], state: "minecraft:polished_tuff"},
        {pos: [2, 9, 3], state: "minecraft:polished_tuff"},
        {pos: [2, 9, 4], state: "minecraft:polished_tuff"},
        {pos: [2, 9, 5], state: "minecraft:polished_tuff"},
        {pos: [2, 9, 6], state: "minecraft:polished_tuff"},
        {pos: [2, 9, 7], state: "minecraft:polished_tuff"},
        {pos: [2, 9, 8], state: "minecraft:polished_tuff"},
        {pos: [2, 9, 9], state: "minecraft:polished_tuff"},
        {pos: [2, 9, 10], state: "minecraft:polished_tuff"},
        {pos: [3, 9, 0], state: "minecraft:tuff_bricks"},
        {pos: [3, 9, 1], state: "minecraft:polished_tuff"},
        {pos: [3, 9, 2], state: "minecraft:polished_tuff"},
        {pos: [3, 9, 3], state: "minecraft:polished_tuff"},
        {pos: [3, 9, 4], state: "minecraft:polished_tuff"},
        {pos: [3, 9, 5], state: "minecraft:polished_tuff"},
        {pos: [3, 9, 6], state: "minecraft:polished_tuff"},
        {pos: [3, 9, 7], state: "minecraft:polished_tuff"},
        {pos: [3, 9, 8], state: "minecraft:polished_tuff"},
        {pos: [3, 9, 9], state: "minecraft:polished_tuff"},
        {pos: [3, 9, 10], state: "minecraft:polished_tuff"},
        {pos: [4, 9, 2], state: "minecraft:polished_tuff"},
        {pos: [4, 9, 3], state: "minecraft:polished_tuff"},
        {pos: [4, 9, 4], state: "minecraft:polished_tuff"},
        {pos: [4, 9, 7], state: "minecraft:polished_tuff"},
        {pos: [4, 9, 8], state: "minecraft:polished_tuff"},
        {pos: [4, 9, 9], state: "minecraft:polished_tuff"},
        {pos: [5, 9, 2], state: "minecraft:tuff_bricks"},
        {pos: [5, 9, 3], state: "minecraft:tuff_bricks"},
        {pos: [5, 9, 4], state: "minecraft:tuff_bricks"},
        {pos: [5, 9, 7], state: "minecraft:tuff_bricks"},
        {pos: [5, 9, 8], state: "minecraft:tuff_bricks"},
        {pos: [5, 9, 9], state: "minecraft:tuff_bricks"},
        {pos: [0, 10, 2], state: "minecraft:waxed_copper_block"},
        {pos: [0, 10, 3], state: "minecraft:waxed_copper_block"},
        {pos: [0, 10, 4], state: "minecraft:waxed_copper_block"},
        {pos: [0, 10, 5], state: "minecraft:waxed_copper_block"},
        {pos: [0, 10, 6], state: "minecraft:waxed_copper_block"},
        {pos: [0, 10, 7], state: "minecraft:waxed_copper_block"},
        {pos: [0, 10, 8], state: "minecraft:waxed_copper_block"},
        {pos: [0, 10, 9], state: "minecraft:waxed_copper_block"},
        {pos: [0, 10, 10], state: "minecraft:waxed_copper_block"},
        {pos: [1, 10, 0], state: "minecraft:tuff_bricks"},
        {pos: [1, 10, 1], state: "minecraft:tuff_bricks"},
        {pos: [1, 10, 2], state: "minecraft:tuff_bricks"},
        {pos: [1, 10, 3], state: "minecraft:tuff_bricks"},
        {pos: [1, 10, 4], state: "minecraft:tuff_bricks"},
        {pos: [1, 10, 5], state: "minecraft:tuff_bricks"},
        {pos: [1, 10, 6], state: "minecraft:tuff_bricks"},
        {pos: [1, 10, 7], state: "minecraft:tuff_bricks"},
        {pos: [1, 10, 8], state: "minecraft:tuff_bricks"},
        {pos: [1, 10, 9], state: "minecraft:tuff_bricks"},
        {pos: [1, 10, 10], state: "minecraft:tuff_bricks"},
        {pos: [2, 10, 0], state: "minecraft:tuff_bricks"},
        {pos: [2, 10, 1], state: "minecraft:tuff_bricks"},
        {pos: [2, 10, 2], state: "minecraft:tuff_bricks"},
        {pos: [2, 10, 3], state: "minecraft:tuff_bricks"},
        {pos: [2, 10, 4], state: "minecraft:tuff_bricks"},
        {pos: [2, 10, 5], state: "minecraft:tuff_bricks"},
        {pos: [2, 10, 6], state: "minecraft:tuff_bricks"},
        {pos: [2, 10, 7], state: "minecraft:tuff_bricks"},
        {pos: [2, 10, 8], state: "minecraft:tuff_bricks"},
        {pos: [2, 10, 9], state: "minecraft:tuff_bricks"},
        {pos: [2, 10, 10], state: "minecraft:tuff_bricks"},
        {pos: [3, 10, 0], state: "minecraft:tuff_bricks"},
        {pos: [3, 10, 1], state: "minecraft:tuff_bricks"},
        {pos: [3, 10, 2], state: "minecraft:tuff_bricks"},
        {pos: [3, 10, 3], state: "minecraft:tuff_bricks"},
        {pos: [3, 10, 4], state: "minecraft:tuff_bricks"},
        {pos: [3, 10, 5], state: "minecraft:tuff_bricks"},
        {pos: [3, 10, 6], state: "minecraft:tuff_bricks"},
        {pos: [3, 10, 7], state: "minecraft:tuff_bricks"},
        {pos: [3, 10, 8], state: "minecraft:tuff_bricks"},
        {pos: [3, 10, 9], state: "minecraft:tuff_bricks"},
        {pos: [3, 10, 10], state: "minecraft:tuff_bricks"},
        {pos: [4, 10, 2], state: "minecraft:tuff_bricks"},
        {pos: [4, 10, 3], state: "minecraft:tuff_bricks"},
        {pos: [4, 10, 4], state: "minecraft:tuff_bricks"},
        {pos: [4, 10, 7], state: "minecraft:tuff_bricks"},
        {pos: [4, 10, 8], state: "minecraft:tuff_bricks"},
        {pos: [4, 10, 9], state: "minecraft:tuff_bricks"},
        {pos: [5, 10, 2], state: "minecraft:tuff_bricks"},
        {pos: [5, 10, 3], state: "minecraft:tuff_bricks"},
        {pos: [5, 10, 4], state: "minecraft:tuff_bricks"},
        {pos: [5, 10, 7], state: "minecraft:tuff_bricks"},
        {pos: [5, 10, 8], state: "minecraft:tuff_bricks"},
        {pos: [5, 10, 9], state: "minecraft:tuff_bricks"},
        {pos: [0, 11, 2], state: "minecraft:tuff_bricks"},
        {pos: [0, 11, 3], state: "minecraft:tuff_bricks"},
        {pos: [0, 11, 4], state: "minecraft:tuff_bricks"},
        {pos: [0, 11, 5], state: "minecraft:tuff_bricks"},
        {pos: [0, 11, 6], state: "minecraft:tuff_bricks"},
        {pos: [0, 11, 7], state: "minecraft:tuff_bricks"},
        {pos: [0, 11, 8], state: "minecraft:tuff_bricks"},
        {pos: [0, 11, 9], state: "minecraft:tuff_bricks"},
        {pos: [0, 11, 10], state: "minecraft:tuff_bricks"},
        {pos: [1, 11, 0], state: "minecraft:tuff_bricks"},
        {pos: [1, 11, 1], state: "minecraft:tuff_bricks"},
        {pos: [1, 11, 2], state: "minecraft:tuff_bricks"},
        {pos: [1, 11, 3], state: "minecraft:tuff_bricks"},
        {pos: [1, 11, 4], state: "minecraft:tuff_bricks"},
        {pos: [1, 11, 5], state: "minecraft:tuff_bricks"},
        {pos: [1, 11, 6], state: "minecraft:tuff_bricks"},
        {pos: [1, 11, 7], state: "minecraft:tuff_bricks"},
        {pos: [1, 11, 8], state: "minecraft:tuff_bricks"},
        {pos: [1, 11, 9], state: "minecraft:tuff_bricks"},
        {pos: [1, 11, 10], state: "minecraft:tuff_bricks"},
        {pos: [2, 11, 0], state: "minecraft:tuff_bricks"},
        {pos: [2, 11, 1], state: "minecraft:tuff_bricks"},
        {pos: [2, 11, 2], state: "minecraft:tuff_bricks"},
        {pos: [2, 11, 3], state: "minecraft:tuff_bricks"},
        {pos: [2, 11, 4], state: "minecraft:tuff_bricks"},
        {pos: [2, 11, 5], state: "minecraft:tuff_bricks"},
        {pos: [2, 11, 6], state: "minecraft:tuff_bricks"},
        {pos: [2, 11, 7], state: "minecraft:tuff_bricks"},
        {pos: [2, 11, 8], state: "minecraft:tuff_bricks"},
        {pos: [2, 11, 9], state: "minecraft:tuff_bricks"},
        {pos: [2, 11, 10], state: "minecraft:tuff_bricks"},
        {pos: [3, 11, 0], state: "minecraft:tuff_bricks"},
        {pos: [3, 11, 1], state: "minecraft:tuff_bricks"},
        {pos: [3, 11, 2], state: "minecraft:tuff_bricks"},
        {pos: [3, 11, 3], state: "minecraft:tuff_bricks"},
        {pos: [3, 11, 4], state: "minecraft:tuff_bricks"},
        {pos: [3, 11, 5], state: "minecraft:tuff_bricks"},
        {pos: [3, 11, 6], state: "minecraft:tuff_bricks"},
        {pos: [3, 11, 7], state: "minecraft:tuff_bricks"},
        {pos: [3, 11, 8], state: "minecraft:tuff_bricks"},
        {pos: [3, 11, 9], state: "minecraft:tuff_bricks"},
        {pos: [3, 11, 10], state: "minecraft:tuff_bricks"},
        {pos: [4, 11, 2], state: "minecraft:tuff_bricks"},
        {pos: [4, 11, 3], state: "minecraft:tuff_bricks"},
        {pos: [4, 11, 4], state: "minecraft:tuff_bricks"},
        {pos: [4, 11, 7], state: "minecraft:tuff_bricks"},
        {pos: [4, 11, 8], state: "minecraft:tuff_bricks"},
        {pos: [4, 11, 9], state: "minecraft:tuff_bricks"},
        {pos: [5, 11, 2], state: "minecraft:tuff_bricks"},
        {pos: [5, 11, 3], state: "minecraft:tuff_bricks"},
        {pos: [5, 11, 4], state: "minecraft:tuff_bricks"},
        {pos: [5, 11, 7], state: "minecraft:tuff_bricks"},
        {pos: [5, 11, 8], state: "minecraft:tuff_bricks"},
        {pos: [5, 11, 9], state: "minecraft:tuff_bricks"},
        {pos: [0, 1, 2], state: "minecraft:air"},
        {pos: [0, 1, 3], state: "minecraft:air"},
        {pos: [0, 1, 4], state: "minecraft:air"},
        {pos: [1, 1, 1], state: "minecraft:air"},
        {pos: [1, 1, 2], state: "minecraft:air"},
        {pos: [1, 1, 3], state: "minecraft:air"},
        {pos: [1, 1, 4], state: "minecraft:air"},
        {pos: [1, 1, 5], state: "minecraft:air"},
        {pos: [2, 1, 1], state: "minecraft:air"},
        {pos: [2, 1, 2], state: "minecraft:air"},
        {pos: [2, 1, 3], state: "minecraft:air"},
        {pos: [2, 1, 4], state: "minecraft:air"},
        {pos: [2, 1, 5], state: "minecraft:air"},
        {pos: [3, 1, 1], state: "minecraft:air"},
        {pos: [3, 1, 2], state: "minecraft:air"},
        {pos: [3, 1, 3], state: "minecraft:air"},
        {pos: [3, 1, 4], state: "minecraft:air"},
        {pos: [3, 1, 5], state: "minecraft:air"},
        {pos: [0, 2, 2], state: "minecraft:air"},
        {pos: [0, 2, 3], state: "minecraft:air"},
        {pos: [0, 2, 4], state: "minecraft:air"},
        {pos: [1, 2, 1], state: "minecraft:air"},
        {pos: [1, 2, 2], state: "minecraft:air"},
        {pos: [1, 2, 3], state: "minecraft:air"},
        {pos: [1, 2, 4], state: "minecraft:air"},
        {pos: [1, 2, 5], state: "minecraft:air"},
        {pos: [2, 2, 1], state: "minecraft:air"},
        {pos: [2, 2, 2], state: "minecraft:air"},
        {pos: [2, 2, 3], state: "minecraft:air"},
        {pos: [2, 2, 4], state: "minecraft:air"},
        {pos: [2, 2, 5], state: "minecraft:air"},
        {pos: [3, 2, 1], state: "minecraft:air"},
        {pos: [3, 2, 2], state: "minecraft:air"},
        {pos: [3, 2, 3], state: "minecraft:air"},
        {pos: [3, 2, 4], state: "minecraft:air"},
        {pos: [3, 2, 5], state: "minecraft:air"},
        {pos: [0, 3, 2], state: "minecraft:air"},
        {pos: [0, 3, 3], state: "minecraft:air"},
        {pos: [0, 3, 4], state: "minecraft:air"},
        {pos: [1, 3, 1], state: "minecraft:air"},
        {pos: [1, 3, 2], state: "minecraft:air"},
        {pos: [1, 3, 3], state: "minecraft:air"},
        {pos: [1, 3, 4], state: "minecraft:air"},
        {pos: [1, 3, 5], state: "minecraft:air"},
        {pos: [2, 3, 1], state: "minecraft:air"},
        {pos: [2, 3, 2], state: "minecraft:air"},
        {pos: [2, 3, 3], state: "minecraft:air"},
        {pos: [2, 3, 4], state: "minecraft:air"},
        {pos: [2, 3, 5], state: "minecraft:air"},
        {pos: [3, 3, 1], state: "minecraft:air"},
        {pos: [3, 3, 2], state: "minecraft:air"},
        {pos: [3, 3, 3], state: "minecraft:ladder{waterlogged:false,facing:west}"},
        {pos: [3, 3, 4], state: "minecraft:air"},
        {pos: [3, 3, 5], state: "minecraft:air"},
        {pos: [3, 4, 3], state: "minecraft:ladder{waterlogged:false,facing:west}"},
        {pos: [3, 5, 3], state: "minecraft:ladder{waterlogged:false,facing:west}"},
        {pos: [0, 6, 2], state: "minecraft:air"},
        {pos: [0, 6, 3], state: "minecraft:air"},
        {pos: [0, 6, 4], state: "minecraft:air"},
        {pos: [0, 6, 5], state: "minecraft:air"},
        {pos: [1, 6, 1], state: "minecraft:air"},
        {pos: [1, 6, 2], state: "minecraft:air"},
        {pos: [1, 6, 3], state: "minecraft:air"},
        {pos: [1, 6, 4], state: "minecraft:air"},
        {pos: [1, 6, 5], state: "minecraft:air"},
        {pos: [1, 6, 6], state: "minecraft:air"},
        {pos: [1, 6, 7], state: "minecraft:air"},
        {pos: [1, 6, 8], state: "minecraft:air"},
        {pos: [1, 6, 9], state: "minecraft:air"},
        {pos: [1, 6, 10], state: "minecraft:air"},
        {pos: [2, 6, 1], state: "minecraft:air"},
        {pos: [2, 6, 2], state: "minecraft:air"},
        {pos: [2, 6, 3], state: "minecraft:air"},
        {pos: [2, 6, 4], state: "minecraft:air"},
        {pos: [2, 6, 5], state: "minecraft:air"},
        {pos: [2, 6, 6], state: "minecraft:air"},
        {pos: [2, 6, 7], state: "minecraft:air"},
        {pos: [2, 6, 8], state: "minecraft:air"},
        {pos: [2, 6, 9], state: "minecraft:air"},
        {pos: [2, 6, 10], state: "minecraft:air"},
        {pos: [3, 6, 1], state: "minecraft:air"},
        {pos: [3, 6, 2], state: "minecraft:air"},
        {pos: [3, 6, 3], state: "minecraft:ladder{waterlogged:false,facing:west}"},
        {pos: [3, 6, 4], state: "minecraft:air"},
        {pos: [3, 6, 5], state: "minecraft:air"},
        {pos: [3, 6, 6], state: "minecraft:air"},
        {pos: [3, 6, 7], state: "minecraft:air"},
        {pos: [3, 6, 8], state: "minecraft:air"},
        {pos: [3, 6, 9], state: "minecraft:air"},
        {pos: [3, 6, 10], state: "minecraft:air"},
        {pos: [4, 6, 2], state: "minecraft:air"},
        {pos: [4, 6, 4], state: "minecraft:air"},
        {pos: [4, 6, 7], state: "minecraft:air"},
        {pos: [4, 6, 8], state: "minecraft:air"},
        {pos: [4, 6, 9], state: "minecraft:air"},
        {pos: [0, 7, 2], state: "minecraft:air"},
        {pos: [0, 7, 3], state: "minecraft:air"},
        {pos: [0, 7, 4], state: "minecraft:air"},
        {pos: [0, 7, 5], state: "minecraft:air"},
        {pos: [1, 7, 1], state: "minecraft:air"},
        {pos: [1, 7, 2], state: "minecraft:air"},
        {pos: [1, 7, 3], state: "minecraft:air"},
        {pos: [1, 7, 4], state: "minecraft:air"},
        {pos: [1, 7, 5], state: "minecraft:air"},
        {pos: [1, 7, 6], state: "minecraft:air"},
        {pos: [1, 7, 7], state: "minecraft:air"},
        {pos: [1, 7, 8], state: "minecraft:air"},
        {pos: [1, 7, 9], state: "minecraft:air"},
        {pos: [1, 7, 10], state: "minecraft:air"},
        {pos: [2, 7, 1], state: "minecraft:air"},
        {pos: [2, 7, 2], state: "minecraft:air"},
        {pos: [2, 7, 3], state: "minecraft:air"},
        {pos: [2, 7, 4], state: "minecraft:air"},
        {pos: [2, 7, 5], state: "minecraft:air"},
        {pos: [2, 7, 6], state: "minecraft:air"},
        {pos: [2, 7, 7], state: "minecraft:air"},
        {pos: [2, 7, 8], state: "minecraft:air"},
        {pos: [2, 7, 9], state: "minecraft:air"},
        {pos: [3, 7, 1], state: "minecraft:air"},
        {pos: [3, 7, 2], state: "minecraft:air"},
        {pos: [3, 7, 3], state: "minecraft:air"},
        {pos: [3, 7, 4], state: "minecraft:air"},
        {pos: [3, 7, 5], state: "minecraft:air"},
        {pos: [3, 7, 6], state: "minecraft:air"},
        {pos: [3, 7, 7], state: "minecraft:air"},
        {pos: [3, 7, 8], state: "minecraft:air"},
        {pos: [3, 7, 9], state: "minecraft:air"},
        {pos: [3, 7, 10], state: "minecraft:air"},
        {pos: [4, 7, 2], state: "minecraft:air"},
        {pos: [4, 7, 3], state: "minecraft:air"},
        {pos: [4, 7, 4], state: "minecraft:air"},
        {pos: [4, 7, 7], state: "minecraft:air"},
        {pos: [4, 7, 8], state: "minecraft:air"},
        {pos: [4, 7, 9], state: "minecraft:air"},
        {pos: [0, 8, 2], state: "minecraft:air"},
        {pos: [0, 8, 3], state: "minecraft:air"},
        {pos: [0, 8, 4], state: "minecraft:air"},
        {pos: [0, 8, 5], state: "minecraft:air"},
        {pos: [1, 8, 1], state: "minecraft:air"},
        {pos: [1, 8, 2], state: "minecraft:air"},
        {pos: [1, 8, 3], state: "minecraft:air"},
        {pos: [1, 8, 4], state: "minecraft:air"},
        {pos: [1, 8, 5], state: "minecraft:air"},
        {pos: [1, 8, 6], state: "minecraft:air"},
        {pos: [1, 8, 7], state: "minecraft:air"},
        {pos: [1, 8, 8], state: "minecraft:air"},
        {pos: [1, 8, 9], state: "minecraft:air"},
        {pos: [1, 8, 10], state: "minecraft:air"},
        {pos: [2, 8, 1], state: "minecraft:air"},
        {pos: [2, 8, 2], state: "minecraft:air"},
        {pos: [2, 8, 3], state: "minecraft:air"},
        {pos: [2, 8, 4], state: "minecraft:air"},
        {pos: [2, 8, 5], state: "minecraft:air"},
        {pos: [2, 8, 6], state: "minecraft:air"},
        {pos: [2, 8, 7], state: "minecraft:air"},
        {pos: [2, 8, 8], state: "minecraft:air"},
        {pos: [2, 8, 9], state: "minecraft:air"},
        {pos: [2, 8, 10], state: "minecraft:air"},
        {pos: [3, 8, 1], state: "minecraft:air"},
        {pos: [3, 8, 2], state: "minecraft:air"},
        {pos: [3, 8, 3], state: "minecraft:air"},
        {pos: [3, 8, 4], state: "minecraft:air"},
        {pos: [3, 8, 5], state: "minecraft:air"},
        {pos: [3, 8, 6], state: "minecraft:air"},
        {pos: [3, 8, 7], state: "minecraft:air"},
        {pos: [3, 8, 8], state: "minecraft:air"},
        {pos: [3, 8, 9], state: "minecraft:air"},
        {pos: [3, 8, 10], state: "minecraft:air"},
        {pos: [4, 8, 2], state: "minecraft:air"},
        {pos: [4, 8, 3], state: "minecraft:air"},
        {pos: [4, 8, 4], state: "minecraft:air"},
        {pos: [4, 8, 7], state: "minecraft:air"},
        {pos: [4, 8, 8], state: "minecraft:air"},
        {pos: [4, 8, 9], state: "minecraft:air"},
        {pos: [2, 7, 10], state: "minecraft:jigsaw{orientation:south_up}", nbt: {final_state: "minecraft:air", id: "minecraft:jigsaw", joint: "rollable", name: "minecraft:right_staircase", placement_priority: 0, pool: "minecraft:empty", selection_priority: 0, target: "minecraft:empty"}}
    ],
    entities: [],
    palette: [
        "minecraft:waxed_oxidized_copper",
        "minecraft:tuff_bricks",
        "minecraft:waxed_oxidized_cut_copper",
        "minecraft:waxed_copper_block",
        "minecraft:waxed_copper_bulb{powered:false,lit:true}",
        "minecraft:chiseled_tuff_bricks",
        "minecraft:polished_tuff",
        "minecraft:waxed_copper_grate{waterlogged:false}",
        "minecraft:waxed_chiseled_copper",
        "minecraft:air",
        "minecraft:ladder{waterlogged:false,facing:west}",
        "minecraft:jigsaw{orientation:south_up}"
    ]
}