{
    size: [15, 23, 15],
    data: [
        {pos: [1, 0, 4], state: "minecraft:dark_oak_log{axis:y}"},
        {pos: [1, 0, 10], state: "minecraft:dark_oak_log{axis:y}"},
        {pos: [2, 0, 3], state: "minecraft:mossy_cobblestone"},
        {pos: [2, 0, 4], state: "minecraft:mossy_cobblestone"},
        {pos: [2, 0, 5], state: "minecraft:mossy_cobblestone"},
        {pos: [2, 0, 6], state: "minecraft:mossy_cobblestone"},
        {pos: [2, 0, 7], state: "minecraft:mossy_cobblestone"},
        {pos: [2, 0, 8], state: "minecraft:mossy_cobblestone"},
        {pos: [2, 0, 9], state: "minecraft:mossy_cobblestone"},
        {pos: [2, 0, 10], state: "minecraft:mossy_cobblestone"},
        {pos: [2, 0, 11], state: "minecraft:mossy_cobblestone"},
        {pos: [3, 0, 2], state: "minecraft:mossy_cobblestone"},
        {pos: [3, 0, 3], state: "minecraft:mossy_cobblestone"},
        {pos: [3, 0, 4], state: "minecraft:birch_planks"},
        {pos: [3, 0, 5], state: "minecraft:birch_planks"},
        {pos: [3, 0, 6], state: "minecraft:birch_planks"},
        {pos: [3, 0, 7], state: "minecraft:birch_planks"},
        {pos: [3, 0, 8], state: "minecraft:birch_planks"},
        {pos: [3, 0, 9], state: "minecraft:birch_planks"},
        {pos: [3, 0, 10], state: "minecraft:birch_planks"},
        {pos: [3, 0, 11], state: "minecraft:mossy_cobblestone"},
        {pos: [3, 0, 12], state: "minecraft:mossy_cobblestone"},
        {pos: [4, 0, 1], state: "minecraft:dark_oak_log{axis:y}"},
        {pos: [4, 0, 2], state: "minecraft:mossy_cobblestone"},
        {pos: [4, 0, 3], state: "minecraft:birch_planks"},
        {pos: [4, 0, 4], state: "minecraft:birch_planks"},
        {pos: [4, 0, 5], state: "minecraft:birch_planks"},
        {pos: [4, 0, 6], state: "minecraft:birch_planks"},
        {pos: [4, 0, 7], state: "minecraft:birch_planks"},
        {pos: [4, 0, 8], state: "minecraft:birch_planks"},
        {pos: [4, 0, 9], state: "minecraft:birch_planks"},
        {pos: [4, 0, 10], state: "minecraft:birch_planks"},
        {pos: [4, 0, 11], state: "minecraft:birch_planks"},
        {pos: [4, 0, 12], state: "minecraft:mossy_cobblestone"},
        {pos: [4, 0, 13], state: "minecraft:dark_oak_log{axis:y}"},
        {pos: [5, 0, 2], state: "minecraft:mossy_cobblestone"},
        {pos: [5, 0, 3], state: "minecraft:birch_planks"},
        {pos: [5, 0, 4], state: "minecraft:birch_planks"},
        {pos: [5, 0, 5], state: "minecraft:birch_planks"},
        {pos: [5, 0, 6], state: "minecraft:birch_planks"},
        {pos: [5, 0, 7], state: "minecraft:birch_planks"},
        {pos: [5, 0, 8], state: "minecraft:birch_planks"},
        {pos: [5, 0, 9], state: "minecraft:birch_planks"},
        {pos: [5, 0, 10], state: "minecraft:birch_planks"},
        {pos: [5, 0, 11], state: "minecraft:birch_planks"},
        {pos: [5, 0, 12], state: "minecraft:mossy_cobblestone"},
        {pos: [6, 0, 2], state: "minecraft:mossy_cobblestone"},
        {pos: [6, 0, 3], state: "minecraft:birch_planks"},
        {pos: [6, 0, 4], state: "minecraft:birch_planks"},
        {pos: [6, 0, 5], state: "minecraft:birch_planks"},
        {pos: [6, 0, 6], state: "minecraft:birch_planks"},
        {pos: [6, 0, 7], state: "minecraft:birch_planks"},
        {pos: [6, 0, 8], state: "minecraft:birch_planks"},
        {pos: [6, 0, 9], state: "minecraft:birch_planks"},
        {pos: [6, 0, 10], state: "minecraft:birch_planks"},
        {pos: [6, 0, 11], state: "minecraft:birch_planks"},
        {pos: [6, 0, 12], state: "minecraft:mossy_cobblestone"},
        {pos: [7, 0, 2], state: "minecraft:mossy_cobblestone"},
        {pos: [7, 0, 3], state: "minecraft:birch_planks"},
        {pos: [7, 0, 4], state: "minecraft:birch_planks"},
        {pos: [7, 0, 5], state: "minecraft:birch_planks"},
        {pos: [7, 0, 6], state: "minecraft:birch_planks"},
        {pos: [7, 0, 7], state: "minecraft:birch_planks"},
        {pos: [7, 0, 8], state: "minecraft:birch_planks"},
        {pos: [7, 0, 9], state: "minecraft:birch_planks"},
        {pos: [7, 0, 10], state: "minecraft:birch_planks"},
        {pos: [7, 0, 11], state: "minecraft:birch_planks"},
        {pos: [7, 0, 12], state: "minecraft:birch_planks"},
        {pos: [8, 0, 2], state: "minecraft:mossy_cobblestone"},
        {pos: [8, 0, 3], state: "minecraft:birch_planks"},
        {pos: [8, 0, 4], state: "minecraft:birch_planks"},
        {pos: [8, 0, 5], state: "minecraft:birch_planks"},
        {pos: [8, 0, 6], state: "minecraft:birch_planks"},
        {pos: [8, 0, 7], state: "minecraft:birch_planks"},
        {pos: [8, 0, 8], state: "minecraft:birch_planks"},
        {pos: [8, 0, 9], state: "minecraft:birch_planks"},
        {pos: [8, 0, 10], state: "minecraft:birch_planks"},
        {pos: [8, 0, 11], state: "minecraft:birch_planks"},
        {pos: [8, 0, 12], state: "minecraft:mossy_cobblestone"},
        {pos: [9, 0, 2], state: "minecraft:mossy_cobblestone"},
        {pos: [9, 0, 3], state: "minecraft:birch_planks"},
        {pos: [9, 0, 4], state: "minecraft:birch_planks"},
        {pos: [9, 0, 5], state: "minecraft:birch_planks"},
        {pos: [9, 0, 6], state: "minecraft:birch_planks"},
        {pos: [9, 0, 7], state: "minecraft:birch_planks"},
        {pos: [9, 0, 8], state: "minecraft:birch_planks"},
        {pos: [9, 0, 9], state: "minecraft:birch_planks"},
        {pos: [9, 0, 10], state: "minecraft:birch_planks"},
        {pos: [9, 0, 11], state: "minecraft:birch_planks"},
        {pos: [9, 0, 12], state: "minecraft:mossy_cobblestone"},
        {pos: [10, 0, 1], state: "minecraft:dark_oak_log{axis:y}"},
        {pos: [10, 0, 2], state: "minecraft:mossy_cobblestone"},
        {pos: [10, 0, 3], state: "minecraft:birch_planks"},
        {pos: [10, 0, 4], state: "minecraft:birch_planks"},
        {pos: [10, 0, 5], state: "minecraft:birch_planks"},
        {pos: [10, 0, 6], state: "minecraft:birch_planks"},
        {pos: [10, 0, 7], state: "minecraft:birch_planks"},
        {pos: [10, 0, 8], state: "minecraft:birch_planks"},
        {pos: [10, 0, 9], state: "minecraft:birch_planks"},
        {pos: [10, 0, 10], state: "minecraft:birch_planks"},
        {pos: [10, 0, 11], state: "minecraft:birch_planks"},
        {pos: [10, 0, 12], state: "minecraft:mossy_cobblestone"},
        {pos: [10, 0, 13], state: "minecraft:dark_oak_log{axis:y}"},
        {pos: [11, 0, 2], state: "minecraft:mossy_cobblestone"},
        {pos: [11, 0, 3], state: "minecraft:birch_planks"},
        {pos: [11, 0, 4], state: "minecraft:birch_planks"},
        {pos: [11, 0, 5], state: "minecraft:birch_planks"},
        {pos: [11, 0, 6], state: "minecraft:birch_planks"},
        {pos: [11, 0, 7], state: "minecraft:birch_planks"},
        {pos: [11, 0, 8], state: "minecraft:birch_planks"},
        {pos: [11, 0, 9], state: "minecraft:birch_planks"},
        {pos: [11, 0, 10], state: "minecraft:birch_planks"},
        {pos: [11, 0, 11], state: "minecraft:mossy_cobblestone"},
        {pos: [11, 0, 12], state: "minecraft:mossy_cobblestone"},
        {pos: [12, 0, 3], state: "minecraft:mossy_cobblestone"},
        {pos: [12, 0, 4], state: "minecraft:mossy_cobblestone"},
        {pos: [12, 0, 5], state: "minecraft:mossy_cobblestone"},
        {pos: [12, 0, 6], state: "minecraft:mossy_cobblestone"},
        {pos: [12, 0, 7], state: "minecraft:mossy_cobblestone"},
        {pos: [12, 0, 8], state: "minecraft:mossy_cobblestone"},
        {pos: [12, 0, 9], state: "minecraft:mossy_cobblestone"},
        {pos: [12, 0, 10], state: "minecraft:mossy_cobblestone"},
        {pos: [12, 0, 11], state: "minecraft:mossy_cobblestone"},
        {pos: [13, 0, 4], state: "minecraft:dark_oak_log{axis:y}"},
        {pos: [13, 0, 10], state: "minecraft:dark_oak_log{axis:y}"},
        {pos: [1, 1, 4], state: "minecraft:dark_oak_log{axis:y}"},
        {pos: [1, 1, 10], state: "minecraft:dark_oak_log{axis:y}"},
        {pos: [2, 1, 3], state: "minecraft:mossy_cobblestone"},
        {pos: [2, 1, 4], state: "minecraft:mossy_cobblestone"},
        {pos: [2, 1, 5], state: "minecraft:mossy_cobblestone"},
        {pos: [2, 1, 6], state: "minecraft:mossy_cobblestone"},
        {pos: [2, 1, 7], state: "minecraft:mossy_cobblestone"},
        {pos: [2, 1, 8], state: "minecraft:mossy_cobblestone"},
        {pos: [2, 1, 9], state: "minecraft:mossy_cobblestone"},
        {pos: [2, 1, 10], state: "minecraft:mossy_cobblestone"},
        {pos: [2, 1, 11], state: "minecraft:mossy_cobblestone"},
        {pos: [3, 1, 2], state: "minecraft:mossy_cobblestone"},
        {pos: [3, 1, 3], state: "minecraft:mossy_cobblestone"},
        {pos: [3, 1, 11], state: "minecraft:mossy_cobblestone"},
        {pos: [3, 1, 12], state: "minecraft:mossy_cobblestone"},
        {pos: [4, 1, 1], state: "minecraft:dark_oak_log{axis:y}"},
        {pos: [4, 1, 2], state: "minecraft:mossy_cobblestone"},
        {pos: [4, 1, 12], state: "minecraft:mossy_cobblestone"},
        {pos: [4, 1, 13], state: "minecraft:dark_oak_log{axis:y}"},
        {pos: [5, 1, 2], state: "minecraft:mossy_cobblestone"},
        {pos: [5, 1, 12], state: "minecraft:mossy_cobblestone"},
        {pos: [6, 1, 2], state: "minecraft:mossy_cobblestone"},
        {pos: [6, 1, 12], state: "minecraft:mossy_cobblestone"},
        {pos: [7, 1, 2], state: "minecraft:mossy_cobblestone"},
        {pos: [8, 1, 2], state: "minecraft:mossy_cobblestone"},
        {pos: [8, 1, 12], state: "minecraft:mossy_cobblestone"},
        {pos: [9, 1, 2], state: "minecraft:mossy_cobblestone"},
        {pos: [9, 1, 12], state: "minecraft:mossy_cobblestone"},
        {pos: [10, 1, 1], state: "minecraft:dark_oak_log{axis:y}"},
        {pos: [10, 1, 2], state: "minecraft:mossy_cobblestone"},
        {pos: [10, 1, 4], state: "minecraft:birch_planks"},
        {pos: [10, 1, 5], state: "minecraft:mossy_cobblestone"},
        {pos: [10, 1, 12], state: "minecraft:mossy_cobblestone"},
        {pos: [10, 1, 13], state: "minecraft:dark_oak_log{axis:y}"},
        {pos: [11, 1, 2], state: "minecraft:mossy_cobblestone"},
        {pos: [11, 1, 3], state: "minecraft:mossy_cobblestone"},
        {pos: [11, 1, 11], state: "minecraft:mossy_cobblestone"},
        {pos: [11, 1, 12], state: "minecraft:mossy_cobblestone"},
        {pos: [12, 1, 3], state: "minecraft:mossy_cobblestone"},
        {pos: [12, 1, 4], state: "minecraft:mossy_cobblestone"},
        {pos: [12, 1, 5], state: "minecraft:mossy_cobblestone"},
        {pos: [12, 1, 6], state: "minecraft:mossy_cobblestone"},
        {pos: [12, 1, 7], state: "minecraft:mossy_cobblestone"},
        {pos: [12, 1, 8], state: "minecraft:mossy_cobblestone"},
        {pos: [12, 1, 9], state: "minecraft:mossy_cobblestone"},
        {pos: [12, 1, 10], state: "minecraft:mossy_cobblestone"},
        {pos: [12, 1, 11], state: "minecraft:mossy_cobblestone"},
        {pos: [13, 1, 4], state: "minecraft:dark_oak_log{axis:y}"},
        {pos: [13, 1, 10], state: "minecraft:dark_oak_log{axis:y}"},
        {pos: [1, 2, 4], state: "minecraft:dark_oak_log{axis:y}"},
        {pos: [1, 2, 10], state: "minecraft:dark_oak_log{axis:y}"},
        {pos: [2, 2, 3], state: "minecraft:mossy_cobblestone"},
        {pos: [2, 2, 4], state: "minecraft:mossy_cobblestone"},
        {pos: [2, 2, 5], state: "minecraft:mossy_cobblestone"},
        {pos: [2, 2, 7], state: "minecraft:mossy_cobblestone"},
        {pos: [2, 2, 9], state: "minecraft:mossy_cobblestone"},
        {pos: [2, 2, 10], state: "minecraft:mossy_cobblestone"},
        {pos: [2, 2, 11], state: "minecraft:mossy_cobblestone"},
        {pos: [3, 2, 2], state: "minecraft:mossy_cobblestone"},
        {pos: [3, 2, 3], state: "minecraft:mossy_cobblestone"},
        {pos: [3, 2, 11], state: "minecraft:mossy_cobblestone"},
        {pos: [3, 2, 12], state: "minecraft:mossy_cobblestone"},
        {pos: [4, 2, 1], state: "minecraft:dark_oak_log{axis:y}"},
        {pos: [4, 2, 2], state: "minecraft:mossy_cobblestone"},
        {pos: [4, 2, 12], state: "minecraft:mossy_cobblestone"},
        {pos: [4, 2, 13], state: "minecraft:dark_oak_log{axis:y}"},
        {pos: [5, 2, 2], state: "minecraft:mossy_cobblestone"},
        {pos: [5, 2, 12], state: "minecraft:mossy_cobblestone"},
        {pos: [6, 2, 12], state: "minecraft:mossy_cobblestone"},
        {pos: [7, 2, 2], state: "minecraft:mossy_cobblestone"},
        {pos: [8, 2, 12], state: "minecraft:mossy_cobblestone"},
        {pos: [9, 2, 2], state: "minecraft:mossy_cobblestone"},
        {pos: [9, 2, 12], state: "minecraft:mossy_cobblestone"},
        {pos: [10, 2, 1], state: "minecraft:dark_oak_log{axis:y}"},
        {pos: [10, 2, 2], state: "minecraft:mossy_cobblestone"},
        {pos: [10, 2, 6], state: "minecraft:mossy_cobblestone"},
        {pos: [10, 2, 12], state: "minecraft:mossy_cobblestone"},
        {pos: [10, 2, 13], state: "minecraft:dark_oak_log{axis:y}"},
        {pos: [11, 2, 2], state: "minecraft:mossy_cobblestone"},
        {pos: [11, 2, 3], state: "minecraft:mossy_cobblestone"},
        {pos: [11, 2, 11], state: "minecraft:mossy_cobblestone"},
        {pos: [11, 2, 12], state: "minecraft:mossy_cobblestone"},
        {pos: [12, 2, 3], state: "minecraft:mossy_cobblestone"},
        {pos: [12, 2, 4], state: "minecraft:mossy_cobblestone"},
        {pos: [12, 2, 5], state: "minecraft:mossy_cobblestone"},
        {pos: [12, 2, 7], state: "minecraft:mossy_cobblestone"},
        {pos: [12, 2, 9], state: "minecraft:mossy_cobblestone"},
        {pos: [12, 2, 10], state: "minecraft:mossy_cobblestone"},
        {pos: [12, 2, 11], state: "minecraft:mossy_cobblestone"},
        {pos: [13, 2, 4], state: "minecraft:dark_oak_log{axis:y}"},
        {pos: [13, 2, 10], state: "minecraft:dark_oak_log{axis:y}"},
        {pos: [2, 3, 4], state: "minecraft:mossy_cobblestone"},
        {pos: [2, 3, 5], state: "minecraft:mossy_cobblestone"},
        {pos: [2, 3, 6], state: "minecraft:mossy_cobblestone"},
        {pos: [2, 3, 7], state: "minecraft:mossy_cobblestone"},
        {pos: [2, 3, 8], state: "minecraft:mossy_cobblestone"},
        {pos: [2, 3, 9], state: "minecraft:mossy_cobblestone"},
        {pos: [2, 3, 10], state: "minecraft:mossy_cobblestone"},
        {pos: [3, 3, 3], state: "minecraft:mossy_cobblestone"},
        {pos: [3, 3, 11], state: "minecraft:mossy_cobblestone"},
        {pos: [4, 3, 2], state: "minecraft:mossy_cobblestone"},
        {pos: [4, 3, 12], state: "minecraft:mossy_cobblestone"},
        {pos: [5, 3, 2], state: "minecraft:mossy_cobblestone"},
        {pos: [5, 3, 12], state: "minecraft:mossy_cobblestone"},
        {pos: [6, 3, 2], state: "minecraft:mossy_cobblestone"},
        {pos: [6, 3, 12], state: "minecraft:mossy_cobblestone"},
        {pos: [7, 3, 2], state: "minecraft:mossy_cobblestone"},
        {pos: [7, 3, 12], state: "minecraft:mossy_cobblestone"},
        {pos: [8, 3, 2], state: "minecraft:mossy_cobblestone"},
        {pos: [8, 3, 12], state: "minecraft:mossy_cobblestone"},
        {pos: [9, 3, 2], state: "minecraft:mossy_cobblestone"},
        {pos: [9, 3, 12], state: "minecraft:mossy_cobblestone"},
        {pos: [10, 3, 2], state: "minecraft:mossy_cobblestone"},
        {pos: [10, 3, 7], state: "minecraft:mossy_cobblestone"},
        {pos: [10, 3, 12], state: "minecraft:mossy_cobblestone"},
        {pos: [11, 3, 3], state: "minecraft:mossy_cobblestone"},
        {pos: [11, 3, 11], state: "minecraft:mossy_cobblestone"},
        {pos: [12, 3, 4], state: "minecraft:mossy_cobblestone"},
        {pos: [12, 3, 5], state: "minecraft:mossy_cobblestone"},
        {pos: [12, 3, 6], state: "minecraft:mossy_cobblestone"},
        {pos: [12, 3, 7], state: "minecraft:mossy_cobblestone"},
        {pos: [12, 3, 8], state: "minecraft:mossy_cobblestone"},
        {pos: [12, 3, 9], state: "minecraft:mossy_cobblestone"},
        {pos: [12, 3, 10], state: "minecraft:mossy_cobblestone"},
        {pos: [3, 4, 4], state: "minecraft:mossy_cobblestone"},
        {pos: [3, 4, 5], state: "minecraft:dark_oak_planks"},
        {pos: [3, 4, 6], state: "minecraft:dark_oak_planks"},
        {pos: [3, 4, 7], state: "minecraft:dark_oak_planks"},
        {pos: [3, 4, 8], state: "minecraft:dark_oak_planks"},
        {pos: [3, 4, 9], state: "minecraft:dark_oak_planks"},
        {pos: [3, 4, 10], state: "minecraft:mossy_cobblestone"},
        {pos: [4, 4, 3], state: "minecraft:mossy_cobblestone"},
        {pos: [4, 4, 11], state: "minecraft:mossy_cobblestone"},
        {pos: [5, 4, 3], state: "minecraft:dark_oak_planks"},
        {pos: [5, 4, 11], state: "minecraft:dark_oak_planks"},
        {pos: [6, 4, 3], state: "minecraft:dark_oak_planks"},
        {pos: [6, 4, 11], state: "minecraft:dark_oak_planks"},
        {pos: [7, 4, 3], state: "minecraft:dark_oak_planks"},
        {pos: [7, 4, 11], state: "minecraft:dark_oak_planks"},
        {pos: [8, 4, 3], state: "minecraft:dark_oak_planks"},
        {pos: [8, 4, 11], state: "minecraft:dark_oak_planks"},
        {pos: [9, 4, 3], state: "minecraft:dark_oak_planks"},
        {pos: [9, 4, 11], state: "minecraft:dark_oak_planks"},
        {pos: [10, 4, 3], state: "minecraft:mossy_cobblestone"},
        {pos: [10, 4, 8], state: "minecraft:mossy_cobblestone"},
        {pos: [10, 4, 11], state: "minecraft:mossy_cobblestone"},
        {pos: [11, 4, 4], state: "minecraft:mossy_cobblestone"},
        {pos: [11, 4, 5], state: "minecraft:dark_oak_planks"},
        {pos: [11, 4, 6], state: "minecraft:dark_oak_planks"},
        {pos: [11, 4, 7], state: "minecraft:dark_oak_planks"},
        {pos: [11, 4, 8], state: "minecraft:dark_oak_planks"},
        {pos: [11, 4, 9], state: "minecraft:dark_oak_planks"},
        {pos: [11, 4, 10], state: "minecraft:mossy_cobblestone"},
        {pos: [3, 5, 4], state: "minecraft:dark_oak_log{axis:y}"},
        {pos: [3, 5, 5], state: "minecraft:dark_oak_planks"},
        {pos: [3, 5, 6], state: "minecraft:birch_planks"},
        {pos: [3, 5, 7], state: "minecraft:dark_oak_log{axis:x}"},
        {pos: [3, 5, 8], state: "minecraft:birch_planks"},
        {pos: [3, 5, 9], state: "minecraft:dark_oak_planks"},
        {pos: [3, 5, 10], state: "minecraft:dark_oak_log{axis:y}"},
        {pos: [4, 5, 3], state: "minecraft:dark_oak_log{axis:y}"},
        {pos: [4, 5, 4], state: "minecraft:birch_planks"},
        {pos: [4, 5, 5], state: "minecraft:birch_planks"},
        {pos: [4, 5, 6], state: "minecraft:birch_planks"},
        {pos: [4, 5, 7], state: "minecraft:birch_planks"},
        {pos: [4, 5, 8], state: "minecraft:birch_planks"},
        {pos: [4, 5, 9], state: "minecraft:birch_planks"},
        {pos: [4, 5, 10], state: "minecraft:birch_planks"},
        {pos: [4, 5, 11], state: "minecraft:dark_oak_log{axis:y}"},
        {pos: [5, 5, 3], state: "minecraft:dark_oak_planks"},
        {pos: [5, 5, 4], state: "minecraft:birch_planks"},
        {pos: [5, 5, 5], state: "minecraft:birch_planks"},
        {pos: [5, 5, 6], state: "minecraft:birch_planks"},
        {pos: [5, 5, 7], state: "minecraft:birch_planks"},
        {pos: [5, 5, 8], state: "minecraft:birch_planks"},
        {pos: [5, 5, 9], state: "minecraft:birch_planks"},
        {pos: [5, 5, 10], state: "minecraft:birch_planks"},
        {pos: [5, 5, 11], state: "minecraft:dark_oak_planks"},
        {pos: [6, 5, 3], state: "minecraft:birch_planks"},
        {pos: [6, 5, 4], state: "minecraft:birch_planks"},
        {pos: [6, 5, 5], state: "minecraft:birch_planks"},
        {pos: [6, 5, 6], state: "minecraft:birch_planks"},
        {pos: [6, 5, 7], state: "minecraft:birch_planks"},
        {pos: [6, 5, 8], state: "minecraft:birch_planks"},
        {pos: [6, 5, 9], state: "minecraft:birch_planks"},
        {pos: [6, 5, 10], state: "minecraft:birch_planks"},
        {pos: [6, 5, 11], state: "minecraft:birch_planks"},
        {pos: [7, 5, 3], state: "minecraft:dark_oak_log{axis:z}"},
        {pos: [7, 5, 4], state: "minecraft:birch_planks"},
        {pos: [7, 5, 5], state: "minecraft:birch_planks"},
        {pos: [7, 5, 6], state: "minecraft:birch_planks"},
        {pos: [7, 5, 7], state: "minecraft:birch_planks"},
        {pos: [7, 5, 8], state: "minecraft:birch_planks"},
        {pos: [7, 5, 9], state: "minecraft:birch_planks"},
        {pos: [7, 5, 10], state: "minecraft:birch_planks"},
        {pos: [7, 5, 11], state: "minecraft:dark_oak_log{axis:z}"},
        {pos: [8, 5, 3], state: "minecraft:birch_planks"},
        {pos: [8, 5, 4], state: "minecraft:birch_planks"},
        {pos: [8, 5, 5], state: "minecraft:birch_planks"},
        {pos: [8, 5, 6], state: "minecraft:birch_planks"},
        {pos: [8, 5, 7], state: "minecraft:birch_planks"},
        {pos: [8, 5, 8], state: "minecraft:birch_planks"},
        {pos: [8, 5, 9], state: "minecraft:birch_planks"},
        {pos: [8, 5, 10], state: "minecraft:birch_planks"},
        {pos: [8, 5, 11], state: "minecraft:birch_planks"},
        {pos: [9, 5, 3], state: "minecraft:dark_oak_planks"},
        {pos: [9, 5, 4], state: "minecraft:birch_planks"},
        {pos: [9, 5, 6], state: "minecraft:birch_planks"},
        {pos: [9, 5, 7], state: "minecraft:birch_planks"},
        {pos: [9, 5, 8], state: "minecraft:birch_planks"},
        {pos: [9, 5, 9], state: "minecraft:birch_planks"},
        {pos: [9, 5, 10], state: "minecraft:birch_planks"},
        {pos: [9, 5, 11], state: "minecraft:dark_oak_planks"},
        {pos: [10, 5, 3], state: "minecraft:dark_oak_log{axis:y}"},
        {pos: [10, 5, 4], state: "minecraft:birch_planks"},
        {pos: [10, 5, 9], state: "minecraft:birch_planks"},
        {pos: [10, 5, 10], state: "minecraft:birch_planks"},
        {pos: [10, 5, 11], state: "minecraft:dark_oak_log{axis:y}"},
        {pos: [11, 5, 4], state: "minecraft:dark_oak_log{axis:y}"},
        {pos: [11, 5, 5], state: "minecraft:dark_oak_planks"},
        {pos: [11, 5, 6], state: "minecraft:birch_planks"},
        {pos: [11, 5, 7], state: "minecraft:dark_oak_log{axis:x}"},
        {pos: [11, 5, 8], state: "minecraft:birch_planks"},
        {pos: [11, 5, 9], state: "minecraft:dark_oak_planks"},
        {pos: [11, 5, 10], state: "minecraft:dark_oak_log{axis:y}"},
        {pos: [3, 6, 4], state: "minecraft:dark_oak_log{axis:y}"},
        {pos: [3, 6, 5], state: "minecraft:dark_oak_planks"},
        {pos: [3, 6, 9], state: "minecraft:dark_oak_planks"},
        {pos: [3, 6, 10], state: "minecraft:dark_oak_log{axis:y}"},
        {pos: [4, 6, 3], state: "minecraft:dark_oak_log{axis:y}"},
        {pos: [4, 6, 9], state: "minecraft:mossy_cobblestone"},
        {pos: [4, 6, 10], state: "minecraft:birch_planks"},
        {pos: [4, 6, 11], state: "minecraft:dark_oak_log{axis:y}"},
        {pos: [5, 6, 3], state: "minecraft:dark_oak_planks"},
        {pos: [5, 6, 11], state: "minecraft:dark_oak_planks"},
        {pos: [9, 6, 3], state: "minecraft:dark_oak_planks"},
        {pos: [9, 6, 11], state: "minecraft:dark_oak_planks"},
        {pos: [10, 6, 3], state: "minecraft:dark_oak_log{axis:y}"},
        {pos: [10, 6, 11], state: "minecraft:dark_oak_log{axis:y}"},
        {pos: [11, 6, 4], state: "minecraft:dark_oak_log{axis:y}"},
        {pos: [11, 6, 5], state: "minecraft:dark_oak_planks"},
        {pos: [11, 6, 9], state: "minecraft:dark_oak_planks"},
        {pos: [11, 6, 10], state: "minecraft:dark_oak_log{axis:y}"},
        {pos: [3, 7, 4], state: "minecraft:dark_oak_log{axis:y}"},
        {pos: [3, 7, 5], state: "minecraft:dark_oak_planks"},
        {pos: [3, 7, 9], state: "minecraft:dark_oak_planks"},
        {pos: [3, 7, 10], state: "minecraft:dark_oak_log{axis:y}"},
        {pos: [4, 7, 3], state: "minecraft:dark_oak_log{axis:y}"},
        {pos: [4, 7, 11], state: "minecraft:dark_oak_log{axis:y}"},
        {pos: [5, 7, 3], state: "minecraft:dark_oak_planks"},
        {pos: [5, 7, 11], state: "minecraft:dark_oak_planks"},
        {pos: [9, 7, 3], state: "minecraft:dark_oak_planks"},
        {pos: [9, 7, 11], state: "minecraft:dark_oak_planks"},
        {pos: [10, 7, 3], state: "minecraft:dark_oak_log{axis:y}"},
        {pos: [10, 7, 11], state: "minecraft:dark_oak_log{axis:y}"},
        {pos: [11, 7, 4], state: "minecraft:dark_oak_log{axis:y}"},
        {pos: [11, 7, 5], state: "minecraft:dark_oak_planks"},
        {pos: [11, 7, 9], state: "minecraft:dark_oak_planks"},
        {pos: [11, 7, 10], state: "minecraft:dark_oak_log{axis:y}"},
        {pos: [3, 8, 4], state: "minecraft:dark_oak_log{axis:y}"},
        {pos: [3, 8, 5], state: "minecraft:dark_oak_planks"},
        {pos: [3, 8, 6], state: "minecraft:dark_oak_planks"},
        {pos: [3, 8, 8], state: "minecraft:dark_oak_planks"},
        {pos: [3, 8, 9], state: "minecraft:dark_oak_planks"},
        {pos: [3, 8, 10], state: "minecraft:dark_oak_log{axis:y}"},
        {pos: [4, 8, 3], state: "minecraft:dark_oak_log{axis:y}"},
        {pos: [4, 8, 11], state: "minecraft:dark_oak_log{axis:y}"},
        {pos: [5, 8, 3], state: "minecraft:dark_oak_planks"},
        {pos: [5, 8, 11], state: "minecraft:dark_oak_planks"},
        {pos: [6, 8, 3], state: "minecraft:dark_oak_planks"},
        {pos: [6, 8, 11], state: "minecraft:dark_oak_planks"},
        {pos: [8, 8, 3], state: "minecraft:dark_oak_planks"},
        {pos: [8, 8, 11], state: "minecraft:dark_oak_planks"},
        {pos: [9, 8, 3], state: "minecraft:dark_oak_planks"},
        {pos: [9, 8, 11], state: "minecraft:dark_oak_planks"},
        {pos: [10, 8, 3], state: "minecraft:dark_oak_log{axis:y}"},
        {pos: [10, 8, 11], state: "minecraft:dark_oak_log{axis:y}"},
        {pos: [11, 8, 4], state: "minecraft:dark_oak_log{axis:y}"},
        {pos: [11, 8, 5], state: "minecraft:dark_oak_planks"},
        {pos: [11, 8, 6], state: "minecraft:dark_oak_planks"},
        {pos: [11, 8, 8], state: "minecraft:dark_oak_planks"},
        {pos: [11, 8, 9], state: "minecraft:dark_oak_planks"},
        {pos: [11, 8, 10], state: "minecraft:dark_oak_log{axis:y}"},
        {pos: [3, 9, 4], state: "minecraft:dark_oak_log{axis:y}"},
        {pos: [3, 9, 5], state: "minecraft:dark_oak_planks"},
        {pos: [3, 9, 6], state: "minecraft:dark_oak_planks"},
        {pos: [3, 9, 7], state: "minecraft:dark_oak_log{axis:x}"},
        {pos: [3, 9, 8], state: "minecraft:dark_oak_planks"},
        {pos: [3, 9, 9], state: "minecraft:dark_oak_planks"},
        {pos: [3, 9, 10], state: "minecraft:dark_oak_log{axis:y}"},
        {pos: [4, 9, 3], state: "minecraft:dark_oak_log{axis:y}"},
        {pos: [4, 9, 4], state: "minecraft:birch_planks"},
        {pos: [4, 9, 5], state: "minecraft:birch_planks"},
        {pos: [4, 9, 6], state: "minecraft:birch_planks"},
        {pos: [4, 9, 11], state: "minecraft:dark_oak_log{axis:y}"},
        {pos: [5, 9, 3], state: "minecraft:dark_oak_planks"},
        {pos: [5, 9, 4], state: "minecraft:birch_planks"},
        {pos: [5, 9, 5], state: "minecraft:birch_planks"},
        {pos: [5, 9, 6], state: "minecraft:birch_planks"},
        {pos: [5, 9, 7], state: "minecraft:birch_planks"},
        {pos: [5, 9, 8], state: "minecraft:birch_planks"},
        {pos: [5, 9, 9], state: "minecraft:birch_planks"},
        {pos: [5, 9, 11], state: "minecraft:dark_oak_planks"},
        {pos: [6, 9, 3], state: "minecraft:dark_oak_planks"},
        {pos: [6, 9, 4], state: "minecraft:birch_planks"},
        {pos: [6, 9, 5], state: "minecraft:birch_planks"},
        {pos: [6, 9, 6], state: "minecraft:birch_planks"},
        {pos: [6, 9, 7], state: "minecraft:birch_planks"},
        {pos: [6, 9, 8], state: "minecraft:birch_planks"},
        {pos: [6, 9, 9], state: "minecraft:birch_planks"},
        {pos: [6, 9, 10], state: "minecraft:birch_planks"},
        {pos: [6, 9, 11], state: "minecraft:dark_oak_planks"},
        {pos: [7, 9, 3], state: "minecraft:dark_oak_log{axis:z}"},
        {pos: [7, 9, 4], state: "minecraft:birch_planks"},
        {pos: [7, 9, 5], state: "minecraft:birch_planks"},
        {pos: [7, 9, 6], state: "minecraft:birch_planks"},
        {pos: [7, 9, 7], state: "minecraft:birch_planks"},
        {pos: [7, 9, 8], state: "minecraft:birch_planks"},
        {pos: [7, 9, 9], state: "minecraft:birch_planks"},
        {pos: [7, 9, 10], state: "minecraft:birch_planks"},
        {pos: [7, 9, 11], state: "minecraft:dark_oak_log{axis:z}"},
        {pos: [8, 9, 3], state: "minecraft:dark_oak_planks"},
        {pos: [8, 9, 4], state: "minecraft:birch_planks"},
        {pos: [8, 9, 5], state: "minecraft:birch_planks"},
        {pos: [8, 9, 6], state: "minecraft:birch_planks"},
        {pos: [8, 9, 7], state: "minecraft:birch_planks"},
        {pos: [8, 9, 8], state: "minecraft:birch_planks"},
        {pos: [8, 9, 9], state: "minecraft:birch_planks"},
        {pos: [8, 9, 10], state: "minecraft:birch_planks"},
        {pos: [8, 9, 11], state: "minecraft:dark_oak_planks"},
        {pos: [9, 9, 3], state: "minecraft:dark_oak_planks"},
        {pos: [9, 9, 4], state: "minecraft:birch_planks"},
        {pos: [9, 9, 5], state: "minecraft:birch_planks"},
        {pos: [9, 9, 6], state: "minecraft:birch_planks"},
        {pos: [9, 9, 7], state: "minecraft:birch_planks"},
        {pos: [9, 9, 8], state: "minecraft:birch_planks"},
        {pos: [9, 9, 9], state: "minecraft:birch_planks"},
        {pos: [9, 9, 10], state: "minecraft:birch_planks"},
        {pos: [9, 9, 11], state: "minecraft:dark_oak_planks"},
        {pos: [10, 9, 3], state: "minecraft:dark_oak_log{axis:y}"},
        {pos: [10, 9, 4], state: "minecraft:birch_planks"},
        {pos: [10, 9, 5], state: "minecraft:birch_planks"},
        {pos: [10, 9, 6], state: "minecraft:birch_planks"},
        {pos: [10, 9, 7], state: "minecraft:birch_planks"},
        {pos: [10, 9, 8], state: "minecraft:birch_planks"},
        {pos: [10, 9, 9], state: "minecraft:birch_planks"},
        {pos: [10, 9, 10], state: "minecraft:birch_planks"},
        {pos: [10, 9, 11], state: "minecraft:dark_oak_log{axis:y}"},
        {pos: [11, 9, 4], state: "minecraft:dark_oak_log{axis:y}"},
        {pos: [11, 9, 5], state: "minecraft:dark_oak_planks"},
        {pos: [11, 9, 6], state: "minecraft:dark_oak_planks"},
        {pos: [11, 9, 7], state: "minecraft:dark_oak_log{axis:x}"},
        {pos: [11, 9, 8], state: "minecraft:dark_oak_planks"},
        {pos: [11, 9, 9], state: "minecraft:dark_oak_planks"},
        {pos: [11, 9, 10], state: "minecraft:dark_oak_log{axis:y}"},
        {pos: [3, 10, 4], state: "minecraft:dark_oak_log{axis:y}"},
        {pos: [3, 10, 5], state: "minecraft:dark_oak_planks"},
        {pos: [3, 10, 6], state: "minecraft:dark_oak_log{axis:x}"},
        {pos: [3, 10, 7], state: "minecraft:dark_oak_planks"},
        {pos: [3, 10, 8], state: "minecraft:dark_oak_log{axis:x}"},
        {pos: [3, 10, 9], state: "minecraft:dark_oak_planks"},
        {pos: [3, 10, 10], state: "minecraft:dark_oak_log{axis:y}"},
        {pos: [4, 10, 3], state: "minecraft:dark_oak_log{axis:y}"},
        {pos: [4, 10, 11], state: "minecraft:dark_oak_log{axis:y}"},
        {pos: [5, 10, 3], state: "minecraft:dark_oak_planks"},
        {pos: [5, 10, 11], state: "minecraft:dark_oak_planks"},
        {pos: [6, 10, 3], state: "minecraft:dark_oak_log{axis:z}"},
        {pos: [6, 10, 11], state: "minecraft:dark_oak_log{axis:z}"},
        {pos: [7, 10, 3], state: "minecraft:dark_oak_planks"},
        {pos: [7, 10, 11], state: "minecraft:dark_oak_planks"},
        {pos: [8, 10, 3], state: "minecraft:dark_oak_log{axis:z}"},
        {pos: [8, 10, 11], state: "minecraft:dark_oak_log{axis:z}"},
        {pos: [9, 10, 3], state: "minecraft:dark_oak_planks"},
        {pos: [9, 10, 11], state: "minecraft:dark_oak_planks"},
        {pos: [10, 10, 3], state: "minecraft:dark_oak_log{axis:y}"},
        {pos: [10, 10, 5], state: "minecraft:birch_planks"},
        {pos: [10, 10, 11], state: "minecraft:dark_oak_log{axis:y}"},
        {pos: [11, 10, 4], state: "minecraft:dark_oak_log{axis:y}"},
        {pos: [11, 10, 5], state: "minecraft:dark_oak_planks"},
        {pos: [11, 10, 6], state: "minecraft:dark_oak_log{axis:x}"},
        {pos: [11, 10, 7], state: "minecraft:dark_oak_planks"},
        {pos: [11, 10, 8], state: "minecraft:dark_oak_log{axis:x}"},
        {pos: [11, 10, 9], state: "minecraft:dark_oak_planks"},
        {pos: [11, 10, 10], state: "minecraft:dark_oak_log{axis:y}"},
        {pos: [3, 11, 4], state: "minecraft:mossy_cobblestone"},
        {pos: [3, 11, 5], state: "minecraft:dark_oak_planks"},
        {pos: [3, 11, 6], state: "minecraft:dark_oak_planks"},
        {pos: [3, 11, 7], state: "minecraft:dark_oak_log{axis:x}"},
        {pos: [3, 11, 8], state: "minecraft:dark_oak_planks"},
        {pos: [3, 11, 9], state: "minecraft:dark_oak_planks"},
        {pos: [3, 11, 10], state: "minecraft:mossy_cobblestone"},
        {pos: [4, 11, 3], state: "minecraft:mossy_cobblestone"},
        {pos: [4, 11, 11], state: "minecraft:mossy_cobblestone"},
        {pos: [5, 11, 3], state: "minecraft:dark_oak_planks"},
        {pos: [5, 11, 11], state: "minecraft:dark_oak_planks"},
        {pos: [6, 11, 3], state: "minecraft:dark_oak_planks"},
        {pos: [6, 11, 11], state: "minecraft:dark_oak_planks"},
        {pos: [7, 11, 3], state: "minecraft:dark_oak_log{axis:z}"},
        {pos: [7, 11, 11], state: "minecraft:dark_oak_log{axis:z}"},
        {pos: [8, 11, 3], state: "minecraft:dark_oak_planks"},
        {pos: [8, 11, 11], state: "minecraft:dark_oak_planks"},
        {pos: [9, 11, 3], state: "minecraft:dark_oak_planks"},
        {pos: [9, 11, 11], state: "minecraft:dark_oak_planks"},
        {pos: [10, 11, 3], state: "minecraft:mossy_cobblestone"},
        {pos: [10, 11, 11], state: "minecraft:mossy_cobblestone"},
        {pos: [11, 11, 4], state: "minecraft:mossy_cobblestone"},
        {pos: [11, 11, 5], state: "minecraft:dark_oak_planks"},
        {pos: [11, 11, 6], state: "minecraft:dark_oak_planks"},
        {pos: [11, 11, 7], state: "minecraft:dark_oak_log{axis:x}"},
        {pos: [11, 11, 8], state: "minecraft:dark_oak_planks"},
        {pos: [11, 11, 9], state: "minecraft:dark_oak_planks"},
        {pos: [11, 11, 10], state: "minecraft:mossy_cobblestone"},
        {pos: [2, 12, 4], state: "minecraft:mossy_cobblestone"},
        {pos: [2, 12, 10], state: "minecraft:mossy_cobblestone"},
        {pos: [3, 12, 3], state: "minecraft:mossy_cobblestone"},
        {pos: [3, 12, 4], state: "minecraft:mossy_cobblestone"},
        {pos: [3, 12, 5], state: "minecraft:mossy_cobblestone"},
        {pos: [3, 12, 6], state: "minecraft:mossy_cobblestone"},
        {pos: [3, 12, 7], state: "minecraft:mossy_cobblestone"},
        {pos: [3, 12, 8], state: "minecraft:mossy_cobblestone"},
        {pos: [3, 12, 9], state: "minecraft:mossy_cobblestone"},
        {pos: [3, 12, 10], state: "minecraft:mossy_cobblestone"},
        {pos: [3, 12, 11], state: "minecraft:mossy_cobblestone"},
        {pos: [4, 12, 2], state: "minecraft:mossy_cobblestone"},
        {pos: [4, 12, 3], state: "minecraft:mossy_cobblestone"},
        {pos: [4, 12, 11], state: "minecraft:mossy_cobblestone"},
        {pos: [4, 12, 12], state: "minecraft:mossy_cobblestone"},
        {pos: [5, 12, 3], state: "minecraft:mossy_cobblestone"},
        {pos: [5, 12, 11], state: "minecraft:mossy_cobblestone"},
        {pos: [6, 12, 3], state: "minecraft:mossy_cobblestone"},
        {pos: [6, 12, 11], state: "minecraft:mossy_cobblestone"},
        {pos: [7, 12, 3], state: "minecraft:mossy_cobblestone"},
        {pos: [7, 12, 11], state: "minecraft:mossy_cobblestone"},
        {pos: [8, 12, 3], state: "minecraft:mossy_cobblestone"},
        {pos: [8, 12, 11], state: "minecraft:mossy_cobblestone"},
        {pos: [9, 12, 3], state: "minecraft:mossy_cobblestone"},
        {pos: [9, 12, 11], state: "minecraft:mossy_cobblestone"},
        {pos: [10, 12, 2], state: "minecraft:mossy_cobblestone"},
        {pos: [10, 12, 3], state: "minecraft:mossy_cobblestone"},
        {pos: [10, 12, 11], state: "minecraft:mossy_cobblestone"},
        {pos: [10, 12, 12], state: "minecraft:mossy_cobblestone"},
        {pos: [11, 12, 3], state: "minecraft:mossy_cobblestone"},
        {pos: [11, 12, 4], state: "minecraft:mossy_cobblestone"},
        {pos: [11, 12, 5], state: "minecraft:mossy_cobblestone"},
        {pos: [11, 12, 6], state: "minecraft:mossy_cobblestone"},
        {pos: [11, 12, 7], state: "minecraft:mossy_cobblestone"},
        {pos: [11, 12, 8], state: "minecraft:mossy_cobblestone"},
        {pos: [11, 12, 9], state: "minecraft:mossy_cobblestone"},
        {pos: [11, 12, 10], state: "minecraft:mossy_cobblestone"},
        {pos: [11, 12, 11], state: "minecraft:mossy_cobblestone"},
        {pos: [12, 12, 4], state: "minecraft:mossy_cobblestone"},
        {pos: [12, 12, 10], state: "minecraft:mossy_cobblestone"},
        {pos: [1, 13, 3], state: "minecraft:dark_oak_log{axis:x}"},
        {pos: [1, 13, 4], state: "minecraft:dark_oak_log{axis:z}"},
        {pos: [1, 13, 5], state: "minecraft:dark_oak_log{axis:z}"},
        {pos: [1, 13, 6], state: "minecraft:dark_oak_log{axis:z}"},
        {pos: [1, 13, 7], state: "minecraft:dark_oak_log{axis:z}"},
        {pos: [1, 13, 8], state: "minecraft:dark_oak_log{axis:z}"},
        {pos: [1, 13, 9], state: "minecraft:dark_oak_log{axis:z}"},
        {pos: [1, 13, 10], state: "minecraft:dark_oak_log{axis:z}"},
        {pos: [1, 13, 11], state: "minecraft:dark_oak_log{axis:x}"},
        {pos: [2, 13, 2], state: "minecraft:mossy_cobblestone"},
        {pos: [2, 13, 3], state: "minecraft:birch_planks"},
        {pos: [2, 13, 4], state: "minecraft:birch_planks"},
        {pos: [2, 13, 5], state: "minecraft:birch_planks"},
        {pos: [2, 13, 6], state: "minecraft:birch_planks"},
        {pos: [2, 13, 7], state: "minecraft:birch_planks"},
        {pos: [2, 13, 8], state: "minecraft:birch_planks"},
        {pos: [2, 13, 9], state: "minecraft:birch_planks"},
        {pos: [2, 13, 10], state: "minecraft:birch_planks"},
        {pos: [2, 13, 11], state: "minecraft:birch_planks"},
        {pos: [2, 13, 12], state: "minecraft:mossy_cobblestone"},
        {pos: [3, 13, 1], state: "minecraft:dark_oak_log{axis:z}"},
        {pos: [3, 13, 2], state: "minecraft:birch_planks"},
        {pos: [3, 13, 3], state: "minecraft:birch_planks"},
        {pos: [3, 13, 4], state: "minecraft:birch_planks"},
        {pos: [3, 13, 5], state: "minecraft:birch_planks"},
        {pos: [3, 13, 6], state: "minecraft:birch_planks"},
        {pos: [3, 13, 7], state: "minecraft:birch_planks"},
        {pos: [3, 13, 8], state: "minecraft:birch_planks"},
        {pos: [3, 13, 9], state: "minecraft:birch_planks"},
        {pos: [3, 13, 10], state: "minecraft:birch_planks"},
        {pos: [3, 13, 11], state: "minecraft:birch_planks"},
        {pos: [3, 13, 12], state: "minecraft:birch_planks"},
        {pos: [3, 13, 13], state: "minecraft:dark_oak_log{axis:z}"},
        {pos: [4, 13, 1], state: "minecraft:dark_oak_log{axis:x}"},
        {pos: [4, 13, 2], state: "minecraft:birch_planks"},
        {pos: [4, 13, 3], state: "minecraft:birch_planks"},
        {pos: [4, 13, 4], state: "minecraft:birch_planks"},
        {pos: [4, 13, 5], state: "minecraft:birch_planks"},
        {pos: [4, 13, 6], state: "minecraft:birch_planks"},
        {pos: [4, 13, 7], state: "minecraft:birch_planks"},
        {pos: [4, 13, 8], state: "minecraft:birch_planks"},
        {pos: [4, 13, 9], state: "minecraft:birch_planks"},
        {pos: [4, 13, 10], state: "minecraft:birch_planks"},
        {pos: [4, 13, 11], state: "minecraft:birch_planks"},
        {pos: [4, 13, 12], state: "minecraft:birch_planks"},
        {pos: [4, 13, 13], state: "minecraft:dark_oak_log{axis:x}"},
        {pos: [5, 13, 1], state: "minecraft:dark_oak_log{axis:x}"},
        {pos: [5, 13, 2], state: "minecraft:birch_planks"},
        {pos: [5, 13, 3], state: "minecraft:birch_planks"},
        {pos: [5, 13, 4], state: "minecraft:birch_planks"},
        {pos: [5, 13, 5], state: "minecraft:birch_planks"},
        {pos: [5, 13, 6], state: "minecraft:birch_planks"},
        {pos: [5, 13, 7], state: "minecraft:birch_planks"},
        {pos: [5, 13, 8], state: "minecraft:birch_planks"},
        {pos: [5, 13, 9], state: "minecraft:birch_planks"},
        {pos: [5, 13, 10], state: "minecraft:birch_planks"},
        {pos: [5, 13, 11], state: "minecraft:birch_planks"},
        {pos: [5, 13, 12], state: "minecraft:birch_planks"},
        {pos: [5, 13, 13], state: "minecraft:dark_oak_log{axis:x}"},
        {pos: [6, 13, 1], state: "minecraft:dark_oak_log{axis:x}"},
        {pos: [6, 13, 2], state: "minecraft:birch_planks"},
        {pos: [6, 13, 3], state: "minecraft:birch_planks"},
        {pos: [6, 13, 4], state: "minecraft:birch_planks"},
        {pos: [6, 13, 5], state: "minecraft:birch_planks"},
        {pos: [6, 13, 6], state: "minecraft:birch_planks"},
        {pos: [6, 13, 7], state: "minecraft:birch_planks"},
        {pos: [6, 13, 8], state: "minecraft:birch_planks"},
        {pos: [6, 13, 9], state: "minecraft:birch_planks"},
        {pos: [6, 13, 10], state: "minecraft:birch_planks"},
        {pos: [6, 13, 11], state: "minecraft:birch_planks"},
        {pos: [6, 13, 12], state: "minecraft:birch_planks"},
        {pos: [6, 13, 13], state: "minecraft:dark_oak_log{axis:x}"},
        {pos: [7, 13, 1], state: "minecraft:dark_oak_log{axis:x}"},
        {pos: [7, 13, 2], state: "minecraft:birch_planks"},
        {pos: [7, 13, 3], state: "minecraft:birch_planks"},
        {pos: [7, 13, 4], state: "minecraft:birch_planks"},
        {pos: [7, 13, 5], state: "minecraft:birch_planks"},
        {pos: [7, 13, 6], state: "minecraft:birch_planks"},
        {pos: [7, 13, 7], state: "minecraft:birch_planks"},
        {pos: [7, 13, 8], state: "minecraft:birch_planks"},
        {pos: [7, 13, 9], state: "minecraft:birch_planks"},
        {pos: [7, 13, 10], state: "minecraft:birch_planks"},
        {pos: [7, 13, 11], state: "minecraft:birch_planks"},
        {pos: [7, 13, 12], state: "minecraft:birch_planks"},
        {pos: [7, 13, 13], state: "minecraft:dark_oak_log{axis:x}"},
        {pos: [8, 13, 1], state: "minecraft:dark_oak_log{axis:x}"},
        {pos: [8, 13, 2], state: "minecraft:birch_planks"},
        {pos: [8, 13, 3], state: "minecraft:birch_planks"},
        {pos: [8, 13, 4], state: "minecraft:birch_planks"},
        {pos: [8, 13, 5], state: "minecraft:birch_planks"},
        {pos: [8, 13, 6], state: "minecraft:birch_planks"},
        {pos: [8, 13, 7], state: "minecraft:birch_planks"},
        {pos: [8, 13, 8], state: "minecraft:birch_planks"},
        {pos: [8, 13, 9], state: "minecraft:birch_planks"},
        {pos: [8, 13, 10], state: "minecraft:birch_planks"},
        {pos: [8, 13, 11], state: "minecraft:birch_planks"},
        {pos: [8, 13, 12], state: "minecraft:birch_planks"},
        {pos: [8, 13, 13], state: "minecraft:dark_oak_log{axis:x}"},
        {pos: [9, 13, 1], state: "minecraft:dark_oak_log{axis:x}"},
        {pos: [9, 13, 2], state: "minecraft:birch_planks"},
        {pos: [9, 13, 3], state: "minecraft:birch_planks"},
        {pos: [9, 13, 4], state: "minecraft:birch_planks"},
        {pos: [9, 13, 6], state: "minecraft:birch_planks"},
        {pos: [9, 13, 7], state: "minecraft:birch_planks"},
        {pos: [9, 13, 8], state: "minecraft:birch_planks"},
        {pos: [9, 13, 9], state: "minecraft:birch_planks"},
        {pos: [9, 13, 10], state: "minecraft:birch_planks"},
        {pos: [9, 13, 11], state: "minecraft:birch_planks"},
        {pos: [9, 13, 12], state: "minecraft:birch_planks"},
        {pos: [9, 13, 13], state: "minecraft:dark_oak_log{axis:x}"},
        {pos: [10, 13, 1], state: "minecraft:dark_oak_log{axis:x}"},
        {pos: [10, 13, 2], state: "minecraft:birch_planks"},
        {pos: [10, 13, 3], state: "minecraft:birch_planks"},
        {pos: [10, 13, 4], state: "minecraft:birch_planks"},
        {pos: [10, 13, 9], state: "minecraft:birch_planks"},
        {pos: [10, 13, 10], state: "minecraft:birch_planks"},
        {pos: [10, 13, 11], state: "minecraft:birch_planks"},
        {pos: [10, 13, 12], state: "minecraft:birch_planks"},
        {pos: [10, 13, 13], state: "minecraft:dark_oak_log{axis:x}"},
        {pos: [11, 13, 1], state: "minecraft:dark_oak_log{axis:z}"},
        {pos: [11, 13, 2], state: "minecraft:birch_planks"},
        {pos: [11, 13, 3], state: "minecraft:birch_planks"},
        {pos: [11, 13, 4], state: "minecraft:birch_planks"},
        {pos: [11, 13, 5], state: "minecraft:birch_planks"},
        {pos: [11, 13, 6], state: "minecraft:birch_planks"},
        {pos: [11, 13, 7], state: "minecraft:birch_planks"},
        {pos: [11, 13, 8], state: "minecraft:birch_planks"},
        {pos: [11, 13, 9], state: "minecraft:birch_planks"},
        {pos: [11, 13, 10], state: "minecraft:birch_planks"},
        {pos: [11, 13, 11], state: "minecraft:birch_planks"},
        {pos: [11, 13, 12], state: "minecraft:birch_planks"},
        {pos: [11, 13, 13], state: "minecraft:dark_oak_log{axis:z}"},
        {pos: [12, 13, 2], state: "minecraft:mossy_cobblestone"},
        {pos: [12, 13, 3], state: "minecraft:birch_planks"},
        {pos: [12, 13, 4], state: "minecraft:birch_planks"},
        {pos: [12, 13, 5], state: "minecraft:birch_planks"},
        {pos: [12, 13, 6], state: "minecraft:birch_planks"},
        {pos: [12, 13, 7], state: "minecraft:birch_planks"},
        {pos: [12, 13, 8], state: "minecraft:birch_planks"},
        {pos: [12, 13, 9], state: "minecraft:birch_planks"},
        {pos: [12, 13, 10], state: "minecraft:birch_planks"},
        {pos: [12, 13, 11], state: "minecraft:birch_planks"},
        {pos: [12, 13, 12], state: "minecraft:mossy_cobblestone"},
        {pos: [13, 13, 3], state: "minecraft:dark_oak_log{axis:x}"},
        {pos: [13, 13, 4], state: "minecraft:dark_oak_log{axis:z}"},
        {pos: [13, 13, 5], state: "minecraft:dark_oak_log{axis:z}"},
        {pos: [13, 13, 6], state: "minecraft:dark_oak_log{axis:z}"},
        {pos: [13, 13, 7], state: "minecraft:dark_oak_log{axis:z}"},
        {pos: [13, 13, 8], state: "minecraft:dark_oak_log{axis:z}"},
        {pos: [13, 13, 9], state: "minecraft:dark_oak_log{axis:z}"},
        {pos: [13, 13, 10], state: "minecraft:dark_oak_log{axis:z}"},
        {pos: [13, 13, 11], state: "minecraft:dark_oak_log{axis:x}"},
        {pos: [4, 14, 4], state: "minecraft:dark_oak_log{axis:y}"},
        {pos: [4, 14, 10], state: "minecraft:dark_oak_log{axis:y}"},
        {pos: [10, 14, 4], state: "minecraft:dark_oak_log{axis:y}"},
        {pos: [10, 14, 10], state: "minecraft:dark_oak_log{axis:y}"},
        {pos: [4, 15, 4], state: "minecraft:dark_oak_log{axis:y}"},
        {pos: [4, 15, 10], state: "minecraft:dark_oak_log{axis:y}"},
        {pos: [10, 15, 4], state: "minecraft:dark_oak_log{axis:y}"},
        {pos: [10, 15, 10], state: "minecraft:dark_oak_log{axis:y}"},
        {pos: [2, 16, 2], state: "minecraft:dark_oak_planks"},
        {pos: [2, 16, 12], state: "minecraft:dark_oak_planks"},
        {pos: [4, 16, 4], state: "minecraft:dark_oak_log{axis:y}"},
        {pos: [4, 16, 10], state: "minecraft:dark_oak_log{axis:y}"},
        {pos: [10, 16, 4], state: "minecraft:dark_oak_log{axis:y}"},
        {pos: [10, 16, 10], state: "minecraft:dark_oak_log{axis:y}"},
        {pos: [12, 16, 2], state: "minecraft:dark_oak_planks"},
        {pos: [12, 16, 12], state: "minecraft:dark_oak_planks"},
        {pos: [2, 17, 2], state: "minecraft:dark_oak_planks"},
        {pos: [2, 17, 3], state: "minecraft:dark_oak_planks"},
        {pos: [2, 17, 12], state: "minecraft:dark_oak_planks"},
        {pos: [3, 17, 2], state: "minecraft:dark_oak_planks"},
        {pos: [3, 17, 3], state: "minecraft:dark_oak_planks"},
        {pos: [3, 17, 11], state: "minecraft:dark_oak_planks"},
        {pos: [4, 17, 4], state: "minecraft:dark_oak_log{axis:y}"},
        {pos: [4, 17, 10], state: "minecraft:dark_oak_log{axis:y}"},
        {pos: [10, 17, 4], state: "minecraft:dark_oak_log{axis:y}"},
        {pos: [10, 17, 10], state: "minecraft:dark_oak_log{axis:y}"},
        {pos: [11, 17, 2], state: "minecraft:dark_oak_planks"},
        {pos: [11, 17, 3], state: "minecraft:dark_oak_planks"},
        {pos: [11, 17, 11], state: "minecraft:dark_oak_planks"},
        {pos: [11, 17, 12], state: "minecraft:dark_oak_planks"},
        {pos: [12, 17, 2], state: "minecraft:dark_oak_planks"},
        {pos: [12, 17, 3], state: "minecraft:dark_oak_planks"},
        {pos: [12, 17, 11], state: "minecraft:dark_oak_planks"},
        {pos: [12, 17, 12], state: "minecraft:dark_oak_planks"},
        {pos: [2, 18, 3], state: "minecraft:dark_oak_planks"},
        {pos: [2, 18, 4], state: "minecraft:dark_oak_planks"},
        {pos: [2, 18, 5], state: "minecraft:dark_oak_planks"},
        {pos: [2, 18, 9], state: "minecraft:dark_oak_planks"},
        {pos: [2, 18, 10], state: "minecraft:dark_oak_planks"},
        {pos: [2, 18, 11], state: "minecraft:dark_oak_planks"},
        {pos: [3, 18, 2], state: "minecraft:dark_oak_planks"},
        {pos: [3, 18, 3], state: "minecraft:dark_oak_planks"},
        {pos: [3, 18, 4], state: "minecraft:dark_oak_planks"},
        {pos: [3, 18, 5], state: "minecraft:dark_oak_planks"},
        {pos: [3, 18, 9], state: "minecraft:dark_oak_planks"},
        {pos: [3, 18, 10], state: "minecraft:dark_oak_planks"},
        {pos: [3, 18, 11], state: "minecraft:dark_oak_planks"},
        {pos: [3, 18, 12], state: "minecraft:dark_oak_planks"},
        {pos: [4, 18, 2], state: "minecraft:dark_oak_planks"},
        {pos: [4, 18, 3], state: "minecraft:dark_oak_planks"},
        {pos: [4, 18, 4], state: "minecraft:dark_oak_planks"},
        {pos: [4, 18, 5], state: "minecraft:dark_oak_planks"},
        {pos: [4, 18, 9], state: "minecraft:dark_oak_planks"},
        {pos: [4, 18, 10], state: "minecraft:dark_oak_planks"},
        {pos: [4, 18, 11], state: "minecraft:dark_oak_planks"},
        {pos: [4, 18, 12], state: "minecraft:dark_oak_planks"},
        {pos: [5, 18, 2], state: "minecraft:dark_oak_planks"},
        {pos: [5, 18, 3], state: "minecraft:dark_oak_planks"},
        {pos: [5, 18, 4], state: "minecraft:dark_oak_planks"},
        {pos: [5, 18, 5], state: "minecraft:dark_oak_planks"},
        {pos: [5, 18, 9], state: "minecraft:dark_oak_planks"},
        {pos: [5, 18, 10], state: "minecraft:dark_oak_planks"},
        {pos: [5, 18, 11], state: "minecraft:dark_oak_planks"},
        {pos: [5, 18, 12], state: "minecraft:dark_oak_planks"},
        {pos: [9, 18, 2], state: "minecraft:dark_oak_planks"},
        {pos: [9, 18, 3], state: "minecraft:dark_oak_planks"},
        {pos: [9, 18, 4], state: "minecraft:dark_oak_planks"},
        {pos: [9, 18, 5], state: "minecraft:dark_oak_planks"},
        {pos: [9, 18, 9], state: "minecraft:dark_oak_planks"},
        {pos: [9, 18, 10], state: "minecraft:dark_oak_planks"},
        {pos: [9, 18, 11], state: "minecraft:dark_oak_planks"},
        {pos: [9, 18, 12], state: "minecraft:dark_oak_planks"},
        {pos: [10, 18, 2], state: "minecraft:dark_oak_planks"},
        {pos: [10, 18, 3], state: "minecraft:dark_oak_planks"},
        {pos: [10, 18, 4], state: "minecraft:dark_oak_planks"},
        {pos: [10, 18, 5], state: "minecraft:dark_oak_planks"},
        {pos: [10, 18, 9], state: "minecraft:dark_oak_planks"},
        {pos: [10, 18, 10], state: "minecraft:dark_oak_planks"},
        {pos: [10, 18, 11], state: "minecraft:dark_oak_planks"},
        {pos: [10, 18, 12], state: "minecraft:dark_oak_planks"},
        {pos: [11, 18, 2], state: "minecraft:dark_oak_planks"},
        {pos: [11, 18, 3], state: "minecraft:dark_oak_planks"},
        {pos: [11, 18, 4], state: "minecraft:dark_oak_planks"},
        {pos: [11, 18, 5], state: "minecraft:dark_oak_planks"},
        {pos: [11, 18, 9], state: "minecraft:dark_oak_planks"},
        {pos: [11, 18, 10], state: "minecraft:dark_oak_planks"},
        {pos: [11, 18, 11], state: "minecraft:dark_oak_planks"},
        {pos: [11, 18, 12], state: "minecraft:dark_oak_planks"},
        {pos: [12, 18, 3], state: "minecraft:dark_oak_planks"},
        {pos: [12, 18, 4], state: "minecraft:dark_oak_planks"},
        {pos: [12, 18, 5], state: "minecraft:dark_oak_planks"},
        {pos: [12, 18, 9], state: "minecraft:dark_oak_planks"},
        {pos: [12, 18, 10], state: "minecraft:dark_oak_planks"},
        {pos: [12, 18, 11], state: "minecraft:dark_oak_planks"},
        {pos: [2, 19, 4], state: "minecraft:dark_oak_planks"},
        {pos: [2, 19, 5], state: "minecraft:dark_oak_planks"},
        {pos: [2, 19, 6], state: "minecraft:dark_oak_planks"},
        {pos: [2, 19, 7], state: "minecraft:dark_oak_planks"},
        {pos: [2, 19, 8], state: "minecraft:dark_oak_planks"},
        {pos: [2, 19, 9], state: "minecraft:dark_oak_planks"},
        {pos: [2, 19, 10], state: "minecraft:dark_oak_planks"},
        {pos: [3, 19, 3], state: "minecraft:dark_oak_planks"},
        {pos: [3, 19, 4], state: "minecraft:dark_oak_planks"},
        {pos: [3, 19, 5], state: "minecraft:dark_oak_planks"},
        {pos: [3, 19, 6], state: "minecraft:dark_oak_planks"},
        {pos: [3, 19, 7], state: "minecraft:dark_oak_planks"},
        {pos: [3, 19, 8], state: "minecraft:dark_oak_planks"},
        {pos: [3, 19, 9], state: "minecraft:dark_oak_planks"},
        {pos: [3, 19, 10], state: "minecraft:dark_oak_planks"},
        {pos: [3, 19, 11], state: "minecraft:dark_oak_planks"},
        {pos: [4, 19, 2], state: "minecraft:dark_oak_planks"},
        {pos: [4, 19, 3], state: "minecraft:dark_oak_planks"},
        {pos: [4, 19, 4], state: "minecraft:dark_oak_planks"},
        {pos: [4, 19, 5], state: "minecraft:dark_oak_planks"},
        {pos: [4, 19, 6], state: "minecraft:dark_oak_planks"},
        {pos: [4, 19, 7], state: "minecraft:dark_oak_planks"},
        {pos: [4, 19, 8], state: "minecraft:dark_oak_planks"},
        {pos: [4, 19, 9], state: "minecraft:dark_oak_planks"},
        {pos: [4, 19, 10], state: "minecraft:dark_oak_planks"},
        {pos: [4, 19, 11], state: "minecraft:dark_oak_planks"},
        {pos: [4, 19, 12], state: "minecraft:dark_oak_planks"},
        {pos: [5, 19, 2], state: "minecraft:dark_oak_planks"},
        {pos: [5, 19, 3], state: "minecraft:dark_oak_planks"},
        {pos: [5, 19, 4], state: "minecraft:dark_oak_planks"},
        {pos: [5, 19, 5], state: "minecraft:dark_oak_planks"},
        {pos: [5, 19, 6], state: "minecraft:dark_oak_planks"},
        {pos: [5, 19, 8], state: "minecraft:dark_oak_planks"},
        {pos: [5, 19, 9], state: "minecraft:dark_oak_planks"},
        {pos: [5, 19, 10], state: "minecraft:dark_oak_planks"},
        {pos: [5, 19, 11], state: "minecraft:dark_oak_planks"},
        {pos: [5, 19, 12], state: "minecraft:dark_oak_planks"},
        {pos: [6, 19, 2], state: "minecraft:dark_oak_planks"},
        {pos: [6, 19, 3], state: "minecraft:dark_oak_planks"},
        {pos: [6, 19, 4], state: "minecraft:dark_oak_planks"},
        {pos: [6, 19, 5], state: "minecraft:dark_oak_planks"},
        {pos: [6, 19, 9], state: "minecraft:dark_oak_planks"},
        {pos: [6, 19, 10], state: "minecraft:dark_oak_planks"},
        {pos: [6, 19, 11], state: "minecraft:dark_oak_planks"},
        {pos: [6, 19, 12], state: "minecraft:dark_oak_planks"},
        {pos: [7, 19, 2], state: "minecraft:dark_oak_planks"},
        {pos: [7, 19, 3], state: "minecraft:dark_oak_planks"},
        {pos: [7, 19, 4], state: "minecraft:dark_oak_planks"},
        {pos: [7, 19, 10], state: "minecraft:dark_oak_planks"},
        {pos: [7, 19, 11], state: "minecraft:dark_oak_planks"},
        {pos: [7, 19, 12], state: "minecraft:dark_oak_planks"},
        {pos: [8, 19, 2], state: "minecraft:dark_oak_planks"},
        {pos: [8, 19, 3], state: "minecraft:dark_oak_planks"},
        {pos: [8, 19, 4], state: "minecraft:dark_oak_planks"},
        {pos: [8, 19, 5], state: "minecraft:dark_oak_planks"},
        {pos: [8, 19, 9], state: "minecraft:dark_oak_planks"},
        {pos: [8, 19, 10], state: "minecraft:dark_oak_planks"},
        {pos: [8, 19, 11], state: "minecraft:dark_oak_planks"},
        {pos: [8, 19, 12], state: "minecraft:dark_oak_planks"},
        {pos: [9, 19, 2], state: "minecraft:dark_oak_planks"},
        {pos: [9, 19, 3], state: "minecraft:dark_oak_planks"},
        {pos: [9, 19, 4], state: "minecraft:dark_oak_planks"},
        {pos: [9, 19, 5], state: "minecraft:dark_oak_planks"},
        {pos: [9, 19, 6], state: "minecraft:dark_oak_planks"},
        {pos: [9, 19, 8], state: "minecraft:dark_oak_planks"},
        {pos: [9, 19, 9], state: "minecraft:dark_oak_planks"},
        {pos: [9, 19, 10], state: "minecraft:dark_oak_planks"},
        {pos: [9, 19, 11], state: "minecraft:dark_oak_planks"},
        {pos: [9, 19, 12], state: "minecraft:dark_oak_planks"},
        {pos: [10, 19, 2], state: "minecraft:dark_oak_planks"},
        {pos: [10, 19, 3], state: "minecraft:dark_oak_planks"},
        {pos: [10, 19, 4], state: "minecraft:dark_oak_planks"},
        {pos: [10, 19, 5], state: "minecraft:dark_oak_planks"},
        {pos: [10, 19, 6], state: "minecraft:dark_oak_planks"},
        {pos: [10, 19, 7], state: "minecraft:dark_oak_planks"},
        {pos: [10, 19, 8], state: "minecraft:dark_oak_planks"},
        {pos: [10, 19, 9], state: "minecraft:dark_oak_planks"},
        {pos: [10, 19, 10], state: "minecraft:dark_oak_planks"},
        {pos: [10, 19, 11], state: "minecraft:dark_oak_planks"},
        {pos: [10, 19, 12], state: "minecraft:dark_oak_planks"},
        {pos: [11, 19, 3], state: "minecraft:dark_oak_planks"},
        {pos: [11, 19, 4], state: "minecraft:dark_oak_planks"},
        {pos: [11, 19, 5], state: "minecraft:dark_oak_planks"},
        {pos: [11, 19, 6], state: "minecraft:dark_oak_planks"},
        {pos: [11, 19, 7], state: "minecraft:dark_oak_planks"},
        {pos: [11, 19, 8], state: "minecraft:dark_oak_planks"},
        {pos: [11, 19, 9], state: "minecraft:dark_oak_planks"},
        {pos: [11, 19, 10], state: "minecraft:dark_oak_planks"},
        {pos: [11, 19, 11], state: "minecraft:dark_oak_planks"},
        {pos: [12, 19, 4], state: "minecraft:dark_oak_planks"},
        {pos: [12, 19, 5], state: "minecraft:dark_oak_planks"},
        {pos: [12, 19, 6], state: "minecraft:dark_oak_planks"},
        {pos: [12, 19, 7], state: "minecraft:dark_oak_planks"},
        {pos: [12, 19, 8], state: "minecraft:dark_oak_planks"},
        {pos: [12, 19, 9], state: "minecraft:dark_oak_planks"},
        {pos: [12, 19, 10], state: "minecraft:dark_oak_planks"},
        {pos: [3, 20, 5], state: "minecraft:dark_oak_planks"},
        {pos: [3, 20, 6], state: "minecraft:dark_oak_planks"},
        {pos: [3, 20, 7], state: "minecraft:dark_oak_planks"},
        {pos: [3, 20, 8], state: "minecraft:dark_oak_planks"},
        {pos: [3, 20, 9], state: "minecraft:dark_oak_planks"},
        {pos: [4, 20, 4], state: "minecraft:dark_oak_planks"},
        {pos: [4, 20, 5], state: "minecraft:dark_oak_planks"},
        {pos: [4, 20, 6], state: "minecraft:dark_oak_planks"},
        {pos: [4, 20, 7], state: "minecraft:dark_oak_planks"},
        {pos: [4, 20, 8], state: "minecraft:dark_oak_planks"},
        {pos: [4, 20, 9], state: "minecraft:dark_oak_planks"},
        {pos: [4, 20, 10], state: "minecraft:dark_oak_planks"},
        {pos: [5, 20, 3], state: "minecraft:dark_oak_planks"},
        {pos: [5, 20, 4], state: "minecraft:dark_oak_planks"},
        {pos: [5, 20, 5], state: "minecraft:dark_oak_planks"},
        {pos: [5, 20, 6], state: "minecraft:dark_oak_planks"},
        {pos: [5, 20, 7], state: "minecraft:dark_oak_planks"},
        {pos: [5, 20, 8], state: "minecraft:dark_oak_planks"},
        {pos: [5, 20, 9], state: "minecraft:dark_oak_planks"},
        {pos: [5, 20, 10], state: "minecraft:dark_oak_planks"},
        {pos: [5, 20, 11], state: "minecraft:dark_oak_planks"},
        {pos: [6, 20, 3], state: "minecraft:dark_oak_planks"},
        {pos: [6, 20, 4], state: "minecraft:dark_oak_planks"},
        {pos: [6, 20, 5], state: "minecraft:dark_oak_planks"},
        {pos: [6, 20, 6], state: "minecraft:dark_oak_planks"},
        {pos: [6, 20, 7], state: "minecraft:dark_oak_planks"},
        {pos: [6, 20, 8], state: "minecraft:dark_oak_planks"},
        {pos: [6, 20, 9], state: "minecraft:dark_oak_planks"},
        {pos: [6, 20, 10], state: "minecraft:dark_oak_planks"},
        {pos: [6, 20, 11], state: "minecraft:dark_oak_planks"},
        {pos: [7, 20, 3], state: "minecraft:dark_oak_planks"},
        {pos: [7, 20, 4], state: "minecraft:dark_oak_planks"},
        {pos: [7, 20, 5], state: "minecraft:dark_oak_planks"},
        {pos: [7, 20, 6], state: "minecraft:dark_oak_planks"},
        {pos: [7, 20, 7], state: "minecraft:dark_oak_planks"},
        {pos: [7, 20, 8], state: "minecraft:dark_oak_planks"},
        {pos: [7, 20, 9], state: "minecraft:dark_oak_planks"},
        {pos: [7, 20, 10], state: "minecraft:dark_oak_planks"},
        {pos: [7, 20, 11], state: "minecraft:dark_oak_planks"},
        {pos: [8, 20, 3], state: "minecraft:dark_oak_planks"},
        {pos: [8, 20, 4], state: "minecraft:dark_oak_planks"},
        {pos: [8, 20, 5], state: "minecraft:dark_oak_planks"},
        {pos: [8, 20, 6], state: "minecraft:dark_oak_planks"},
        {pos: [8, 20, 7], state: "minecraft:dark_oak_planks"},
        {pos: [8, 20, 8], state: "minecraft:dark_oak_planks"},
        {pos: [8, 20, 9], state: "minecraft:dark_oak_planks"},
        {pos: [8, 20, 10], state: "minecraft:dark_oak_planks"},
        {pos: [8, 20, 11], state: "minecraft:dark_oak_planks"},
        {pos: [9, 20, 3], state: "minecraft:dark_oak_planks"},
        {pos: [9, 20, 4], state: "minecraft:dark_oak_planks"},
        {pos: [9, 20, 5], state: "minecraft:dark_oak_planks"},
        {pos: [9, 20, 6], state: "minecraft:dark_oak_planks"},
        {pos: [9, 20, 7], state: "minecraft:dark_oak_planks"},
        {pos: [9, 20, 8], state: "minecraft:dark_oak_planks"},
        {pos: [9, 20, 9], state: "minecraft:dark_oak_planks"},
        {pos: [9, 20, 10], state: "minecraft:dark_oak_planks"},
        {pos: [9, 20, 11], state: "minecraft:dark_oak_planks"},
        {pos: [10, 20, 4], state: "minecraft:dark_oak_planks"},
        {pos: [10, 20, 5], state: "minecraft:dark_oak_planks"},
        {pos: [10, 20, 6], state: "minecraft:dark_oak_planks"},
        {pos: [10, 20, 7], state: "minecraft:dark_oak_planks"},
        {pos: [10, 20, 8], state: "minecraft:dark_oak_planks"},
        {pos: [10, 20, 9], state: "minecraft:dark_oak_planks"},
        {pos: [10, 20, 10], state: "minecraft:dark_oak_planks"},
        {pos: [11, 20, 5], state: "minecraft:dark_oak_planks"},
        {pos: [11, 20, 6], state: "minecraft:dark_oak_planks"},
        {pos: [11, 20, 7], state: "minecraft:dark_oak_planks"},
        {pos: [11, 20, 8], state: "minecraft:dark_oak_planks"},
        {pos: [11, 20, 9], state: "minecraft:dark_oak_planks"},
        {pos: [0, 0, 0], state: "minecraft:air"},
        {pos: [0, 0, 1], state: "minecraft:air"},
        {pos: [0, 0, 2], state: "minecraft:air"},
        {pos: [0, 0, 3], state: "minecraft:air"},
        {pos: [0, 0, 4], state: "minecraft:air"},
        {pos: [0, 0, 5], state: "minecraft:air"},
        {pos: [0, 0, 6], state: "minecraft:air"},
        {pos: [0, 0, 7], state: "minecraft:air"},
        {pos: [0, 0, 8], state: "minecraft:air"},
        {pos: [0, 0, 9], state: "minecraft:air"},
        {pos: [0, 0, 10], state: "minecraft:air"},
        {pos: [0, 0, 11], state: "minecraft:air"},
        {pos: [0, 0, 12], state: "minecraft:air"},
        {pos: [0, 0, 13], state: "minecraft:air"},
        {pos: [0, 0, 14], state: "minecraft:air"},
        {pos: [1, 0, 0], state: "minecraft:air"},
        {pos: [1, 0, 1], state: "minecraft:air"},
        {pos: [1, 0, 2], state: "minecraft:air"},
        {pos: [1, 0, 3], state: "minecraft:vine{east:true,south:false,north:false,west:false,up:false}"},
        {pos: [1, 0, 5], state: "minecraft:vine{east:true,south:false,north:false,west:false,up:false}"},
        {pos: [1, 0, 6], state: "minecraft:vine{east:true,south:false,north:false,west:false,up:false}"},
        {pos: [1, 0, 7], state: "minecraft:vine{east:true,south:false,north:false,west:false,up:false}"},
        {pos: [1, 0, 8], state: "minecraft:vine{east:true,south:false,north:false,west:false,up:false}"},
        {pos: [1, 0, 9], state: "minecraft:vine{east:true,south:false,north:false,west:false,up:false}"},
        {pos: [1, 0, 11], state: "minecraft:vine{east:true,south:false,north:false,west:false,up:false}"},
        {pos: [1, 0, 12], state: "minecraft:air"},
        {pos: [1, 0, 13], state: "minecraft:air"},
        {pos: [1, 0, 14], state: "minecraft:air"},
        {pos: [2, 0, 0], state: "minecraft:air"},
        {pos: [2, 0, 1], state: "minecraft:air"},
        {pos: [2, 0, 2], state: "minecraft:vine{east:true,south:true,north:false,west:false,up:false}"},
        {pos: [2, 0, 12], state: "minecraft:vine{east:true,south:false,north:true,west:false,up:false}"},
        {pos: [2, 0, 13], state: "minecraft:air"},
        {pos: [2, 0, 14], state: "minecraft:air"},
        {pos: [3, 0, 0], state: "minecraft:air"},
        {pos: [3, 0, 1], state: "minecraft:vine{east:false,south:true,north:false,west:false,up:false}"},
        {pos: [3, 0, 13], state: "minecraft:vine{east:false,south:false,north:true,west:false,up:false}"},
        {pos: [3, 0, 14], state: "minecraft:air"},
        {pos: [4, 0, 0], state: "minecraft:air"},
        {pos: [4, 0, 14], state: "minecraft:air"},
        {pos: [5, 0, 0], state: "minecraft:air"},
        {pos: [5, 0, 1], state: "minecraft:vine{east:false,south:true,north:false,west:false,up:false}"},
        {pos: [5, 0, 13], state: "minecraft:vine{east:false,south:false,north:true,west:false,up:false}"},
        {pos: [5, 0, 14], state: "minecraft:air"},
        {pos: [6, 0, 0], state: "minecraft:air"},
        {pos: [6, 0, 1], state: "minecraft:vine{east:false,south:true,north:false,west:false,up:false}"},
        {pos: [6, 0, 13], state: "minecraft:vine{east:false,south:false,north:true,west:false,up:false}"},
        {pos: [6, 0, 14], state: "minecraft:air"},
        {pos: [7, 0, 0], state: "minecraft:air"},
        {pos: [7, 0, 1], state: "minecraft:vine{east:false,south:true,north:false,west:false,up:false}"},
        {pos: [7, 0, 13], state: "minecraft:air"},
        {pos: [7, 0, 14], state: "minecraft:air"},
        {pos: [8, 0, 0], state: "minecraft:air"},
        {pos: [8, 0, 1], state: "minecraft:vine{east:false,south:true,north:false,west:false,up:false}"},
        {pos: [8, 0, 13], state: "minecraft:vine{east:false,south:false,north:true,west:false,up:false}"},
        {pos: [8, 0, 14], state: "minecraft:air"},
        {pos: [9, 0, 0], state: "minecraft:air"},
        {pos: [9, 0, 1], state: "minecraft:vine{east:false,south:true,north:false,west:false,up:false}"},
        {pos: [9, 0, 13], state: "minecraft:vine{east:false,south:false,north:true,west:false,up:false}"},
        {pos: [9, 0, 14], state: "minecraft:air"},
        {pos: [10, 0, 0], state: "minecraft:air"},
        {pos: [10, 0, 14], state: "minecraft:air"},
        {pos: [11, 0, 0], state: "minecraft:air"},
        {pos: [11, 0, 1], state: "minecraft:vine{east:false,south:true,north:false,west:false,up:false}"},
        {pos: [11, 0, 13], state: "minecraft:vine{east:false,south:false,north:true,west:false,up:false}"},
        {pos: [11, 0, 14], state: "minecraft:air"},
        {pos: [12, 0, 0], state: "minecraft:air"},
        {pos: [12, 0, 1], state: "minecraft:air"},
        {pos: [12, 0, 2], state: "minecraft:vine{east:false,south:true,north:false,west:true,up:false}"},
        {pos: [12, 0, 12], state: "minecraft:vine{east:false,south:false,north:true,west:true,up:false}"},
        {pos: [12, 0, 13], state: "minecraft:air"},
        {pos: [12, 0, 14], state: "minecraft:air"},
        {pos: [13, 0, 0], state: "minecraft:air"},
        {pos: [13, 0, 1], state: "minecraft:air"},
        {pos: [13, 0, 2], state: "minecraft:air"},
        {pos: [13, 0, 3], state: "minecraft:vine{east:false,south:false,north:false,west:true,up:false}"},
        {pos: [13, 0, 5], state: "minecraft:vine{east:false,south:false,north:false,west:true,up:false}"},
        {pos: [13, 0, 6], state: "minecraft:vine{east:false,south:false,north:false,west:true,up:false}"},
        {pos: [13, 0, 7], state: "minecraft:vine{east:false,south:false,north:false,west:true,up:false}"},
        {pos: [13, 0, 8], state: "minecraft:vine{east:false,south:false,north:false,west:true,up:false}"},
        {pos: [13, 0, 9], state: "minecraft:vine{east:false,south:false,north:false,west:true,up:false}"},
        {pos: [13, 0, 11], state: "minecraft:vine{east:false,south:false,north:false,west:true,up:false}"},
        {pos: [13, 0, 12], state: "minecraft:air"},
        {pos: [13, 0, 13], state: "minecraft:air"},
        {pos: [13, 0, 14], state: "minecraft:air"},
        {pos: [14, 0, 0], state: "minecraft:air"},
        {pos: [14, 0, 1], state: "minecraft:air"},
        {pos: [14, 0, 2], state: "minecraft:air"},
        {pos: [14, 0, 3], state: "minecraft:air"},
        {pos: [14, 0, 4], state: "minecraft:air"},
        {pos: [14, 0, 5], state: "minecraft:air"},
        {pos: [14, 0, 6], state: "minecraft:air"},
        {pos: [14, 0, 7], state: "minecraft:air"},
        {pos: [14, 0, 8], state: "minecraft:air"},
        {pos: [14, 0, 9], state: "minecraft:air"},
        {pos: [14, 0, 10], state: "minecraft:air"},
        {pos: [14, 0, 11], state: "minecraft:air"},
        {pos: [14, 0, 12], state: "minecraft:air"},
        {pos: [14, 0, 13], state: "minecraft:air"},
        {pos: [14, 0, 14], state: "minecraft:air"},
        {pos: [0, 1, 0], state: "minecraft:air"},
        {pos: [0, 1, 1], state: "minecraft:air"},
        {pos: [0, 1, 2], state: "minecraft:air"},
        {pos: [0, 1, 3], state: "minecraft:air"},
        {pos: [0, 1, 4], state: "minecraft:air"},
        {pos: [0, 1, 5], state: "minecraft:air"},
        {pos: [0, 1, 6], state: "minecraft:air"},
        {pos: [0, 1, 7], state: "minecraft:air"},
        {pos: [0, 1, 8], state: "minecraft:air"},
        {pos: [0, 1, 9], state: "minecraft:air"},
        {pos: [0, 1, 10], state: "minecraft:air"},
        {pos: [0, 1, 11], state: "minecraft:air"},
        {pos: [0, 1, 12], state: "minecraft:air"},
        {pos: [0, 1, 13], state: "minecraft:air"},
        {pos: [0, 1, 14], state: "minecraft:air"},
        {pos: [1, 1, 0], state: "minecraft:air"},
        {pos: [1, 1, 1], state: "minecraft:air"},
        {pos: [1, 1, 2], state: "minecraft:air"},
        {pos: [1, 1, 3], state: "minecraft:vine{east:true,south:false,north:false,west:false,up:false}"},
        {pos: [1, 1, 5], state: "minecraft:vine{east:true,south:false,north:false,west:false,up:false}"},
        {pos: [1, 1, 6], state: "minecraft:vine{east:true,south:false,north:false,west:false,up:false}"},
        {pos: [1, 1, 7], state: "minecraft:vine{east:true,south:false,north:false,west:false,up:false}"},
        {pos: [1, 1, 8], state: "minecraft:vine{east:true,south:false,north:false,west:false,up:false}"},
        {pos: [1, 1, 9], state: "minecraft:vine{east:true,south:false,north:false,west:false,up:false}"},
        {pos: [1, 1, 11], state: "minecraft:vine{east:true,south:false,north:false,west:false,up:false}"},
        {pos: [1, 1, 12], state: "minecraft:air"},
        {pos: [1, 1, 13], state: "minecraft:air"},
        {pos: [1, 1, 14], state: "minecraft:air"},
        {pos: [2, 1, 0], state: "minecraft:air"},
        {pos: [2, 1, 1], state: "minecraft:air"},
        {pos: [2, 1, 2], state: "minecraft:vine{east:true,south:true,north:false,west:false,up:false}"},
        {pos: [2, 1, 12], state: "minecraft:vine{east:true,south:false,north:true,west:false,up:false}"},
        {pos: [2, 1, 13], state: "minecraft:air"},
        {pos: [2, 1, 14], state: "minecraft:air"},
        {pos: [3, 1, 0], state: "minecraft:air"},
        {pos: [3, 1, 1], state: "minecraft:vine{east:false,south:true,north:false,west:false,up:false}"},
        {pos: [3, 1, 4], state: "minecraft:air"},
        {pos: [3, 1, 5], state: "minecraft:dark_oak_slab{waterlogged:false,type:top}"},
        {pos: [3, 1, 6], state: "minecraft:dark_oak_slab{waterlogged:false,type:top}"},
        {pos: [3, 1, 7], state: "minecraft:dark_oak_slab{waterlogged:false,type:top}"},
        {pos: [3, 1, 8], state: "minecraft:dark_oak_slab{waterlogged:false,type:top}"},
        {pos: [3, 1, 9], state: "minecraft:dark_oak_slab{waterlogged:false,type:top}"},
        {pos: [3, 1, 10], state: "minecraft:air"},
        {pos: [3, 1, 13], state: "minecraft:vine{east:false,south:false,north:true,west:false,up:false}"},
        {pos: [3, 1, 14], state: "minecraft:air"},
        {pos: [4, 1, 0], state: "minecraft:air"},
        {pos: [4, 1, 3], state: "minecraft:air"},
        {pos: [4, 1, 4], state: "minecraft:air"},
        {pos: [4, 1, 5], state: "minecraft:air"},
        {pos: [4, 1, 6], state: "minecraft:air"},
        {pos: [4, 1, 7], state: "minecraft:air"},
        {pos: [4, 1, 8], state: "minecraft:air"},
        {pos: [4, 1, 9], state: "minecraft:air"},
        {pos: [4, 1, 10], state: "minecraft:air"},
        {pos: [4, 1, 11], state: "minecraft:air"},
        {pos: [4, 1, 14], state: "minecraft:air"},
        {pos: [5, 1, 0], state: "minecraft:air"},
        {pos: [5, 1, 1], state: "minecraft:vine{east:false,south:true,north:false,west:false,up:false}"},
        {pos: [5, 1, 3], state: "minecraft:air"},
        {pos: [5, 1, 4], state: "minecraft:air"},
        {pos: [5, 1, 5], state: "minecraft:air"},
        {pos: [5, 1, 6], state: "minecraft:air"},
        {pos: [5, 1, 7], state: "minecraft:air"},
        {pos: [5, 1, 8], state: "minecraft:air"},
        {pos: [5, 1, 9], state: "minecraft:air"},
        {pos: [5, 1, 10], state: "minecraft:air"},
        {pos: [5, 1, 11], state: "minecraft:air"},
        {pos: [5, 1, 13], state: "minecraft:vine{east:false,south:false,north:true,west:false,up:false}"},
        {pos: [5, 1, 14], state: "minecraft:air"},
        {pos: [6, 1, 0], state: "minecraft:air"},
        {pos: [6, 1, 1], state: "minecraft:vine{east:false,south:true,north:false,west:false,up:false}"},
        {pos: [6, 1, 3], state: "minecraft:air"},
        {pos: [6, 1, 4], state: "minecraft:air"},
        {pos: [6, 1, 5], state: "minecraft:air"},
        {pos: [6, 1, 6], state: "minecraft:air"},
        {pos: [6, 1, 7], state: "minecraft:air"},
        {pos: [6, 1, 8], state: "minecraft:air"},
        {pos: [6, 1, 9], state: "minecraft:air"},
        {pos: [6, 1, 10], state: "minecraft:air"},
        {pos: [6, 1, 11], state: "minecraft:air"},
        {pos: [6, 1, 13], state: "minecraft:vine{east:false,south:false,north:true,west:false,up:false}"},
        {pos: [6, 1, 14], state: "minecraft:air"},
        {pos: [7, 1, 0], state: "minecraft:air"},
        {pos: [7, 1, 1], state: "minecraft:vine{east:false,south:true,north:false,west:false,up:false}"},
        {pos: [7, 1, 3], state: "minecraft:air"},
        {pos: [7, 1, 4], state: "minecraft:air"},
        {pos: [7, 1, 5], state: "minecraft:air"},
        {pos: [7, 1, 6], state: "minecraft:air"},
        {pos: [7, 1, 7], state: "minecraft:air"},
        {pos: [7, 1, 8], state: "minecraft:air"},
        {pos: [7, 1, 9], state: "minecraft:air"},
        {pos: [7, 1, 10], state: "minecraft:air"},
        {pos: [7, 1, 11], state: "minecraft:air"},
        {pos: [7, 1, 12], state: "minecraft:air"},
        {pos: [7, 1, 14], state: "minecraft:air"},
        {pos: [8, 1, 0], state: "minecraft:air"},
        {pos: [8, 1, 1], state: "minecraft:vine{east:false,south:true,north:false,west:false,up:false}"},
        {pos: [8, 1, 3], state: "minecraft:air"},
        {pos: [8, 1, 4], state: "minecraft:air"},
        {pos: [8, 1, 5], state: "minecraft:air"},
        {pos: [8, 1, 6], state: "minecraft:air"},
        {pos: [8, 1, 7], state: "minecraft:air"},
        {pos: [8, 1, 8], state: "minecraft:air"},
        {pos: [8, 1, 9], state: "minecraft:air"},
        {pos: [8, 1, 10], state: "minecraft:air"},
        {pos: [8, 1, 11], state: "minecraft:air"},
        {pos: [8, 1, 13], state: "minecraft:vine{east:false,south:false,north:true,west:false,up:false}"},
        {pos: [8, 1, 14], state: "minecraft:air"},
        {pos: [9, 1, 0], state: "minecraft:air"},
        {pos: [9, 1, 1], state: "minecraft:vine{east:false,south:true,north:false,west:false,up:false}"},
        {pos: [9, 1, 3], state: "minecraft:air"},
        {pos: [9, 1, 4], state: "minecraft:mossy_cobblestone_stairs{half:bottom,waterlogged:false,shape:straight,facing:east}"},
        {pos: [9, 1, 5], state: "minecraft:air"},
        {pos: [9, 1, 6], state: "minecraft:air"},
        {pos: [9, 1, 7], state: "minecraft:air"},
        {pos: [9, 1, 8], state: "minecraft:air"},
        {pos: [9, 1, 9], state: "minecraft:air"},
        {pos: [9, 1, 10], state: "minecraft:air"},
        {pos: [9, 1, 11], state: "minecraft:air"},
        {pos: [9, 1, 13], state: "minecraft:vine{east:false,south:false,north:true,west:false,up:false}"},
        {pos: [9, 1, 14], state: "minecraft:air"},
        {pos: [10, 1, 0], state: "minecraft:air"},
        {pos: [10, 1, 3], state: "minecraft:air"},
        {pos: [10, 1, 6], state: "minecraft:air"},
        {pos: [10, 1, 7], state: "minecraft:air"},
        {pos: [10, 1, 8], state: "minecraft:air"},
        {pos: [10, 1, 9], state: "minecraft:air"},
        {pos: [10, 1, 10], state: "minecraft:air"},
        {pos: [10, 1, 11], state: "minecraft:air"},
        {pos: [10, 1, 14], state: "minecraft:air"},
        {pos: [11, 1, 0], state: "minecraft:air"},
        {pos: [11, 1, 1], state: "minecraft:vine{east:false,south:true,north:false,west:false,up:false}"},
        {pos: [11, 1, 4], state: "minecraft:air"},
        {pos: [11, 1, 5], state: "minecraft:air"},
        {pos: [11, 1, 6], state: "minecraft:air"},
        {pos: [11, 1, 7], state: "minecraft:air"},
        {pos: [11, 1, 8], state: "minecraft:air"},
        {pos: [11, 1, 9], state: "minecraft:air"},
        {pos: [11, 1, 10], state: "minecraft:air"},
        {pos: [11, 1, 13], state: "minecraft:vine{east:false,south:false,north:true,west:false,up:false}"},
        {pos: [11, 1, 14], state: "minecraft:air"},
        {pos: [12, 1, 0], state: "minecraft:air"},
        {pos: [12, 1, 1], state: "minecraft:air"},
        {pos: [12, 1, 2], state: "minecraft:vine{east:false,south:true,north:false,west:true,up:false}"},
        {pos: [12, 1, 12], state: "minecraft:vine{east:false,south:false,north:true,west:true,up:false}"},
        {pos: [12, 1, 13], state: "minecraft:air"},
        {pos: [12, 1, 14], state: "minecraft:air"},
        {pos: [13, 1, 0], state: "minecraft:air"},
        {pos: [13, 1, 1], state: "minecraft:air"},
        {pos: [13, 1, 2], state: "minecraft:air"},
        {pos: [13, 1, 3], state: "minecraft:vine{east:false,south:false,north:false,west:true,up:false}"},
        {pos: [13, 1, 5], state: "minecraft:vine{east:false,south:false,north:false,west:true,up:false}"},
        {pos: [13, 1, 6], state: "minecraft:vine{east:false,south:false,north:false,west:true,up:false}"},
        {pos: [13, 1, 7], state: "minecraft:vine{east:false,south:false,north:false,west:true,up:false}"},
        {pos: [13, 1, 8], state: "minecraft:vine{east:false,south:false,north:false,west:true,up:false}"},
        {pos: [13, 1, 9], state: "minecraft:vine{east:false,south:false,north:false,west:true,up:false}"},
        {pos: [13, 1, 11], state: "minecraft:vine{east:false,south:false,north:false,west:true,up:false}"},
        {pos: [13, 1, 12], state: "minecraft:air"},
        {pos: [13, 1, 13], state: "minecraft:air"},
        {pos: [13, 1, 14], state: "minecraft:air"},
        {pos: [14, 1, 0], state: "minecraft:air"},
        {pos: [14, 1, 1], state: "minecraft:air"},
        {pos: [14, 1, 2], state: "minecraft:air"},
        {pos: [14, 1, 3], state: "minecraft:air"},
        {pos: [14, 1, 4], state: "minecraft:air"},
        {pos: [14, 1, 5], state: "minecraft:air"},
        {pos: [14, 1, 6], state: "minecraft:air"},
        {pos: [14, 1, 7], state: "minecraft:air"},
        {pos: [14, 1, 8], state: "minecraft:air"},
        {pos: [14, 1, 9], state: "minecraft:air"},
        {pos: [14, 1, 10], state: "minecraft:air"},
        {pos: [14, 1, 11], state: "minecraft:air"},
        {pos: [14, 1, 12], state: "minecraft:air"},
        {pos: [14, 1, 13], state: "minecraft:air"},
        {pos: [14, 1, 14], state: "minecraft:air"},
        {pos: [0, 2, 0], state: "minecraft:air"},
        {pos: [0, 2, 1], state: "minecraft:air"},
        {pos: [0, 2, 2], state: "minecraft:air"},
        {pos: [0, 2, 3], state: "minecraft:air"},
        {pos: [0, 2, 4], state: "minecraft:air"},
        {pos: [0, 2, 5], state: "minecraft:air"},
        {pos: [0, 2, 6], state: "minecraft:air"},
        {pos: [0, 2, 7], state: "minecraft:air"},
        {pos: [0, 2, 8], state: "minecraft:air"},
        {pos: [0, 2, 9], state: "minecraft:air"},
        {pos: [0, 2, 10], state: "minecraft:air"},
        {pos: [0, 2, 11], state: "minecraft:air"},
        {pos: [0, 2, 12], state: "minecraft:air"},
        {pos: [0, 2, 13], state: "minecraft:air"},
        {pos: [0, 2, 14], state: "minecraft:air"},
        {pos: [1, 2, 0], state: "minecraft:air"},
        {pos: [1, 2, 1], state: "minecraft:air"},
        {pos: [1, 2, 2], state: "minecraft:air"},
        {pos: [1, 2, 3], state: "minecraft:vine{east:true,south:false,north:false,west:false,up:false}"},
        {pos: [1, 2, 5], state: "minecraft:vine{east:true,south:false,north:false,west:false,up:false}"},
        {pos: [1, 2, 6], state: "minecraft:air"},
        {pos: [1, 2, 7], state: "minecraft:vine{east:true,south:false,north:false,west:false,up:false}"},
        {pos: [1, 2, 8], state: "minecraft:air"},
        {pos: [1, 2, 9], state: "minecraft:vine{east:true,south:false,north:false,west:false,up:false}"},
        {pos: [1, 2, 11], state: "minecraft:vine{east:true,south:false,north:false,west:false,up:false}"},
        {pos: [1, 2, 12], state: "minecraft:air"},
        {pos: [1, 2, 13], state: "minecraft:air"},
        {pos: [1, 2, 14], state: "minecraft:air"},
        {pos: [2, 2, 0], state: "minecraft:air"},
        {pos: [2, 2, 1], state: "minecraft:air"},
        {pos: [2, 2, 2], state: "minecraft:vine{east:true,south:true,north:false,west:false,up:false}"},
        {pos: [2, 2, 6], state: "minecraft:air"},
        {pos: [2, 2, 8], state: "minecraft:air"},
        {pos: [2, 2, 12], state: "minecraft:vine{east:true,south:false,north:true,west:false,up:false}"},
        {pos: [2, 2, 13], state: "minecraft:air"},
        {pos: [2, 2, 14], state: "minecraft:air"},
        {pos: [3, 2, 0], state: "minecraft:air"},
        {pos: [3, 2, 1], state: "minecraft:vine{east:false,south:true,north:false,west:false,up:false}"},
        {pos: [3, 2, 4], state: "minecraft:air"},
        {pos: [3, 2, 5], state: "minecraft:air"},
        {pos: [3, 2, 6], state: "minecraft:air"},
        {pos: [3, 2, 7], state: "minecraft:air"},
        {pos: [3, 2, 8], state: "minecraft:air"},
        {pos: [3, 2, 9], state: "minecraft:air"},
        {pos: [3, 2, 10], state: "minecraft:air"},
        {pos: [3, 2, 13], state: "minecraft:vine{east:false,south:false,north:true,west:false,up:false}"},
        {pos: [3, 2, 14], state: "minecraft:air"},
        {pos: [4, 2, 0], state: "minecraft:air"},
        {pos: [4, 2, 3], state: "minecraft:air"},
        {pos: [4, 2, 4], state: "minecraft:air"},
        {pos: [4, 2, 5], state: "minecraft:air"},
        {pos: [4, 2, 6], state: "minecraft:air"},
        {pos: [4, 2, 7], state: "minecraft:air"},
        {pos: [4, 2, 8], state: "minecraft:air"},
        {pos: [4, 2, 9], state: "minecraft:air"},
        {pos: [4, 2, 10], state: "minecraft:air"},
        {pos: [4, 2, 11], state: "minecraft:air"},
        {pos: [4, 2, 14], state: "minecraft:air"},
        {pos: [5, 2, 0], state: "minecraft:air"},
        {pos: [5, 2, 1], state: "minecraft:vine{east:false,south:true,north:false,west:false,up:false}"},
        {pos: [5, 2, 3], state: "minecraft:air"},
        {pos: [5, 2, 4], state: "minecraft:air"},
        {pos: [5, 2, 5], state: "minecraft:air"},
        {pos: [5, 2, 6], state: "minecraft:air"},
        {pos: [5, 2, 7], state: "minecraft:air"},
        {pos: [5, 2, 8], state: "minecraft:air"},
        {pos: [5, 2, 9], state: "minecraft:air"},
        {pos: [5, 2, 10], state: "minecraft:air"},
        {pos: [5, 2, 11], state: "minecraft:air"},
        {pos: [5, 2, 13], state: "minecraft:vine{east:false,south:false,north:true,west:false,up:false}"},
        {pos: [5, 2, 14], state: "minecraft:air"},
        {pos: [6, 2, 0], state: "minecraft:air"},
        {pos: [6, 2, 1], state: "minecraft:air"},
        {pos: [6, 2, 2], state: "minecraft:air"},
        {pos: [6, 2, 3], state: "minecraft:air"},
        {pos: [6, 2, 4], state: "minecraft:air"},
        {pos: [6, 2, 5], state: "minecraft:air"},
        {pos: [6, 2, 6], state: "minecraft:air"},
        {pos: [6, 2, 7], state: "minecraft:air"},
        {pos: [6, 2, 8], state: "minecraft:air"},
        {pos: [6, 2, 9], state: "minecraft:air"},
        {pos: [6, 2, 10], state: "minecraft:air"},
        {pos: [6, 2, 11], state: "minecraft:air"},
        {pos: [6, 2, 13], state: "minecraft:vine{east:false,south:false,north:true,west:false,up:false}"},
        {pos: [6, 2, 14], state: "minecraft:air"},
        {pos: [7, 2, 0], state: "minecraft:air"},
        {pos: [7, 2, 1], state: "minecraft:vine{east:false,south:true,north:false,west:false,up:false}"},
        {pos: [7, 2, 3], state: "minecraft:air"},
        {pos: [7, 2, 4], state: "minecraft:air"},
        {pos: [7, 2, 5], state: "minecraft:air"},
        {pos: [7, 2, 6], state: "minecraft:air"},
        {pos: [7, 2, 7], state: "minecraft:air"},
        {pos: [7, 2, 8], state: "minecraft:air"},
        {pos: [7, 2, 9], state: "minecraft:air"},
        {pos: [7, 2, 10], state: "minecraft:air"},
        {pos: [7, 2, 11], state: "minecraft:air"},
        {pos: [7, 2, 12], state: "minecraft:air"},
        {pos: [7, 2, 13], state: "minecraft:air"},
        {pos: [7, 2, 14], state: "minecraft:air"},
        {pos: [8, 2, 0], state: "minecraft:air"},
        {pos: [8, 2, 1], state: "minecraft:air"},
        {pos: [8, 2, 2], state: "minecraft:air"},
        {pos: [8, 2, 3], state: "minecraft:air"},
        {pos: [8, 2, 4], state: "minecraft:air"},
        {pos: [8, 2, 5], state: "minecraft:air"},
        {pos: [8, 2, 6], state: "minecraft:air"},
        {pos: [8, 2, 7], state: "minecraft:air"},
        {pos: [8, 2, 8], state: "minecraft:air"},
        {pos: [8, 2, 9], state: "minecraft:air"},
        {pos: [8, 2, 10], state: "minecraft:air"},
        {pos: [8, 2, 11], state: "minecraft:air"},
        {pos: [8, 2, 13], state: "minecraft:vine{east:false,south:false,north:true,west:false,up:false}"},
        {pos: [8, 2, 14], state: "minecraft:air"},
        {pos: [9, 2, 0], state: "minecraft:air"},
        {pos: [9, 2, 1], state: "minecraft:vine{east:false,south:true,north:false,west:false,up:false}"},
        {pos: [9, 2, 3], state: "minecraft:air"},
        {pos: [9, 2, 4], state: "minecraft:air"},
        {pos: [9, 2, 5], state: "minecraft:air"},
        {pos: [9, 2, 6], state: "minecraft:air"},
        {pos: [9, 2, 7], state: "minecraft:air"},
        {pos: [9, 2, 8], state: "minecraft:air"},
        {pos: [9, 2, 9], state: "minecraft:air"},
        {pos: [9, 2, 10], state: "minecraft:air"},
        {pos: [9, 2, 11], state: "minecraft:air"},
        {pos: [9, 2, 13], state: "minecraft:vine{east:false,south:false,north:true,west:false,up:false}"},
        {pos: [9, 2, 14], state: "minecraft:air"},
        {pos: [10, 2, 0], state: "minecraft:air"},
        {pos: [10, 2, 3], state: "minecraft:air"},
        {pos: [10, 2, 4], state: "minecraft:air"},
        {pos: [10, 2, 5], state: "minecraft:mossy_cobblestone_stairs{half:bottom,waterlogged:false,shape:straight,facing:south}"},
        {pos: [10, 2, 7], state: "minecraft:air"},
        {pos: [10, 2, 8], state: "minecraft:air"},
        {pos: [10, 2, 9], state: "minecraft:air"},
        {pos: [10, 2, 10], state: "minecraft:air"},
        {pos: [10, 2, 11], state: "minecraft:air"},
        {pos: [10, 2, 14], state: "minecraft:air"},
        {pos: [11, 2, 0], state: "minecraft:air"},
        {pos: [11, 2, 1], state: "minecraft:vine{east:false,south:true,north:false,west:false,up:false}"},
        {pos: [11, 2, 4], state: "minecraft:air"},
        {pos: [11, 2, 5], state: "minecraft:air"},
        {pos: [11, 2, 6], state: "minecraft:air"},
        {pos: [11, 2, 7], state: "minecraft:air"},
        {pos: [11, 2, 8], state: "minecraft:air"},
        {pos: [11, 2, 9], state: "minecraft:air"},
        {pos: [11, 2, 10], state: "minecraft:air"},
        {pos: [11, 2, 13], state: "minecraft:vine{east:false,south:false,north:true,west:false,up:false}"},
        {pos: [11, 2, 14], state: "minecraft:air"},
        {pos: [12, 2, 0], state: "minecraft:air"},
        {pos: [12, 2, 1], state: "minecraft:air"},
        {pos: [12, 2, 2], state: "minecraft:vine{east:false,south:true,north:false,west:true,up:false}"},
        {pos: [12, 2, 6], state: "minecraft:air"},
        {pos: [12, 2, 8], state: "minecraft:air"},
        {pos: [12, 2, 12], state: "minecraft:vine{east:false,south:false,north:true,west:true,up:false}"},
        {pos: [12, 2, 13], state: "minecraft:air"},
        {pos: [12, 2, 14], state: "minecraft:air"},
        {pos: [13, 2, 0], state: "minecraft:air"},
        {pos: [13, 2, 1], state: "minecraft:air"},
        {pos: [13, 2, 2], state: "minecraft:air"},
        {pos: [13, 2, 3], state: "minecraft:vine{east:false,south:false,north:false,west:true,up:false}"},
        {pos: [13, 2, 5], state: "minecraft:vine{east:false,south:false,north:false,west:true,up:false}"},
        {pos: [13, 2, 6], state: "minecraft:air"},
        {pos: [13, 2, 7], state: "minecraft:vine{east:false,south:false,north:false,west:true,up:false}"},
        {pos: [13, 2, 8], state: "minecraft:air"},
        {pos: [13, 2, 9], state: "minecraft:vine{east:false,south:false,north:false,west:true,up:false}"},
        {pos: [13, 2, 11], state: "minecraft:vine{east:false,south:false,north:false,west:true,up:false}"},
        {pos: [13, 2, 12], state: "minecraft:air"},
        {pos: [13, 2, 13], state: "minecraft:air"},
        {pos: [13, 2, 14], state: "minecraft:air"},
        {pos: [14, 2, 0], state: "minecraft:air"},
        {pos: [14, 2, 1], state: "minecraft:air"},
        {pos: [14, 2, 2], state: "minecraft:air"},
        {pos: [14, 2, 3], state: "minecraft:air"},
        {pos: [14, 2, 4], state: "minecraft:air"},
        {pos: [14, 2, 5], state: "minecraft:air"},
        {pos: [14, 2, 6], state: "minecraft:air"},
        {pos: [14, 2, 7], state: "minecraft:air"},
        {pos: [14, 2, 8], state: "minecraft:air"},
        {pos: [14, 2, 9], state: "minecraft:air"},
        {pos: [14, 2, 10], state: "minecraft:air"},
        {pos: [14, 2, 11], state: "minecraft:air"},
        {pos: [14, 2, 12], state: "minecraft:air"},
        {pos: [14, 2, 13], state: "minecraft:air"},
        {pos: [14, 2, 14], state: "minecraft:air"},
        {pos: [0, 3, 0], state: "minecraft:air"},
        {pos: [0, 3, 1], state: "minecraft:air"},
        {pos: [0, 3, 2], state: "minecraft:air"},
        {pos: [0, 3, 3], state: "minecraft:air"},
        {pos: [0, 3, 4], state: "minecraft:air"},
        {pos: [0, 3, 5], state: "minecraft:air"},
        {pos: [0, 3, 6], state: "minecraft:air"},
        {pos: [0, 3, 7], state: "minecraft:air"},
        {pos: [0, 3, 8], state: "minecraft:air"},
        {pos: [0, 3, 9], state: "minecraft:air"},
        {pos: [0, 3, 10], state: "minecraft:air"},
        {pos: [0, 3, 11], state: "minecraft:air"},
        {pos: [0, 3, 12], state: "minecraft:air"},
        {pos: [0, 3, 13], state: "minecraft:air"},
        {pos: [0, 3, 14], state: "minecraft:air"},
        {pos: [1, 3, 0], state: "minecraft:air"},
        {pos: [1, 3, 1], state: "minecraft:air"},
        {pos: [1, 3, 2], state: "minecraft:air"},
        {pos: [1, 3, 3], state: "minecraft:air"},
        {pos: [1, 3, 4], state: "minecraft:dark_oak_slab{waterlogged:false,type:bottom}"},
        {pos: [1, 3, 5], state: "minecraft:vine{east:true,south:false,north:false,west:false,up:false}"},
        {pos: [1, 3, 6], state: "minecraft:vine{east:true,south:false,north:false,west:false,up:false}"},
        {pos: [1, 3, 7], state: "minecraft:vine{east:true,south:false,north:false,west:false,up:false}"},
        {pos: [1, 3, 8], state: "minecraft:vine{east:true,south:false,north:false,west:false,up:false}"},
        {pos: [1, 3, 9], state: "minecraft:vine{east:true,south:false,north:false,west:false,up:false}"},
        {pos: [1, 3, 10], state: "minecraft:dark_oak_slab{waterlogged:false,type:bottom}"},
        {pos: [1, 3, 11], state: "minecraft:air"},
        {pos: [1, 3, 12], state: "minecraft:air"},
        {pos: [1, 3, 13], state: "minecraft:air"},
        {pos: [1, 3, 14], state: "minecraft:air"},
        {pos: [2, 3, 0], state: "minecraft:air"},
        {pos: [2, 3, 1], state: "minecraft:air"},
        {pos: [2, 3, 2], state: "minecraft:air"},
        {pos: [2, 3, 3], state: "minecraft:dark_oak_fence{east:true,waterlogged:false,south:true,north:false,west:false}"},
        {pos: [2, 3, 11], state: "minecraft:dark_oak_fence{east:true,waterlogged:false,south:false,north:true,west:false}"},
        {pos: [2, 3, 12], state: "minecraft:air"},
        {pos: [2, 3, 13], state: "minecraft:air"},
        {pos: [2, 3, 14], state: "minecraft:air"},
        {pos: [3, 3, 0], state: "minecraft:air"},
        {pos: [3, 3, 1], state: "minecraft:air"},
        {pos: [3, 3, 2], state: "minecraft:dark_oak_fence{east:true,waterlogged:false,south:true,north:false,west:false}"},
        {pos: [3, 3, 4], state: "minecraft:dark_oak_stairs{half:top,waterlogged:false,shape:straight,facing:north}"},
        {pos: [3, 3, 5], state: "minecraft:air"},
        {pos: [3, 3, 6], state: "minecraft:air"},
        {pos: [3, 3, 7], state: "minecraft:air"},
        {pos: [3, 3, 8], state: "minecraft:air"},
        {pos: [3, 3, 9], state: "minecraft:air"},
        {pos: [3, 3, 10], state: "minecraft:dark_oak_stairs{half:top,waterlogged:false,shape:straight,facing:south}"},
        {pos: [3, 3, 12], state: "minecraft:dark_oak_fence{east:true,waterlogged:false,south:false,north:true,west:false}"},
        {pos: [3, 3, 13], state: "minecraft:air"},
        {pos: [3, 3, 14], state: "minecraft:air"},
        {pos: [4, 3, 0], state: "minecraft:air"},
        {pos: [4, 3, 1], state: "minecraft:dark_oak_slab{waterlogged:false,type:bottom}"},
        {pos: [4, 3, 3], state: "minecraft:dark_oak_stairs{half:top,waterlogged:false,shape:straight,facing:west}"},
        {pos: [4, 3, 4], state: "minecraft:air"},
        {pos: [4, 3, 5], state: "minecraft:air"},
        {pos: [4, 3, 6], state: "minecraft:air"},
        {pos: [4, 3, 7], state: "minecraft:air"},
        {pos: [4, 3, 8], state: "minecraft:air"},
        {pos: [4, 3, 9], state: "minecraft:air"},
        {pos: [4, 3, 10], state: "minecraft:air"},
        {pos: [4, 3, 11], state: "minecraft:dark_oak_stairs{half:top,waterlogged:false,shape:straight,facing:west}"},
        {pos: [4, 3, 13], state: "minecraft:dark_oak_slab{waterlogged:false,type:bottom}"},
        {pos: [4, 3, 14], state: "minecraft:air"},
        {pos: [5, 3, 0], state: "minecraft:air"},
        {pos: [5, 3, 1], state: "minecraft:vine{east:false,south:true,north:false,west:false,up:false}"},
        {pos: [5, 3, 3], state: "minecraft:air"},
        {pos: [5, 3, 4], state: "minecraft:air"},
        {pos: [5, 3, 5], state: "minecraft:air"},
        {pos: [5, 3, 6], state: "minecraft:air"},
        {pos: [5, 3, 7], state: "minecraft:air"},
        {pos: [5, 3, 8], state: "minecraft:air"},
        {pos: [5, 3, 9], state: "minecraft:air"},
        {pos: [5, 3, 10], state: "minecraft:air"},
        {pos: [5, 3, 11], state: "minecraft:air"},
        {pos: [5, 3, 13], state: "minecraft:vine{east:false,south:false,north:true,west:false,up:false}"},
        {pos: [5, 3, 14], state: "minecraft:air"},
        {pos: [6, 3, 0], state: "minecraft:air"},
        {pos: [6, 3, 1], state: "minecraft:vine{east:false,south:true,north:false,west:false,up:false}"},
        {pos: [6, 3, 3], state: "minecraft:air"},
        {pos: [6, 3, 4], state: "minecraft:air"},
        {pos: [6, 3, 5], state: "minecraft:air"},
        {pos: [6, 3, 6], state: "minecraft:air"},
        {pos: [6, 3, 7], state: "minecraft:air"},
        {pos: [6, 3, 8], state: "minecraft:air"},
        {pos: [6, 3, 9], state: "minecraft:air"},
        {pos: [6, 3, 10], state: "minecraft:air"},
        {pos: [6, 3, 11], state: "minecraft:air"},
        {pos: [6, 3, 13], state: "minecraft:vine{east:false,south:false,north:true,west:false,up:false}"},
        {pos: [6, 3, 14], state: "minecraft:air"},
        {pos: [7, 3, 0], state: "minecraft:air"},
        {pos: [7, 3, 1], state: "minecraft:vine{east:false,south:true,north:false,west:false,up:false}"},
        {pos: [7, 3, 3], state: "minecraft:air"},
        {pos: [7, 3, 4], state: "minecraft:air"},
        {pos: [7, 3, 5], state: "minecraft:air"},
        {pos: [7, 3, 6], state: "minecraft:air"},
        {pos: [7, 3, 7], state: "minecraft:air"},
        {pos: [7, 3, 8], state: "minecraft:air"},
        {pos: [7, 3, 9], state: "minecraft:air"},
        {pos: [7, 3, 10], state: "minecraft:air"},
        {pos: [7, 3, 11], state: "minecraft:air"},
        {pos: [7, 3, 13], state: "minecraft:vine{east:false,south:false,north:true,west:false,up:false}"},
        {pos: [7, 3, 14], state: "minecraft:air"},
        {pos: [8, 3, 0], state: "minecraft:air"},
        {pos: [8, 3, 1], state: "minecraft:vine{east:false,south:true,north:false,west:false,up:false}"},
        {pos: [8, 3, 3], state: "minecraft:air"},
        {pos: [8, 3, 4], state: "minecraft:air"},
        {pos: [8, 3, 5], state: "minecraft:air"},
        {pos: [8, 3, 6], state: "minecraft:air"},
        {pos: [8, 3, 7], state: "minecraft:air"},
        {pos: [8, 3, 8], state: "minecraft:air"},
        {pos: [8, 3, 9], state: "minecraft:air"},
        {pos: [8, 3, 10], state: "minecraft:air"},
        {pos: [8, 3, 11], state: "minecraft:air"},
        {pos: [8, 3, 13], state: "minecraft:vine{east:false,south:false,north:true,west:false,up:false}"},
        {pos: [8, 3, 14], state: "minecraft:air"},
        {pos: [9, 3, 0], state: "minecraft:air"},
        {pos: [9, 3, 1], state: "minecraft:vine{east:false,south:true,north:false,west:false,up:false}"},
        {pos: [9, 3, 3], state: "minecraft:air"},
        {pos: [9, 3, 4], state: "minecraft:air"},
        {pos: [9, 3, 5], state: "minecraft:air"},
        {pos: [9, 3, 6], state: "minecraft:air"},
        {pos: [9, 3, 7], state: "minecraft:air"},
        {pos: [9, 3, 8], state: "minecraft:air"},
        {pos: [9, 3, 9], state: "minecraft:air"},
        {pos: [9, 3, 10], state: "minecraft:air"},
        {pos: [9, 3, 11], state: "minecraft:air"},
        {pos: [9, 3, 13], state: "minecraft:vine{east:false,south:false,north:true,west:false,up:false}"},
        {pos: [9, 3, 14], state: "minecraft:air"},
        {pos: [10, 3, 0], state: "minecraft:air"},
        {pos: [10, 3, 1], state: "minecraft:dark_oak_slab{waterlogged:false,type:bottom}"},
        {pos: [10, 3, 3], state: "minecraft:dark_oak_stairs{half:top,waterlogged:false,shape:straight,facing:east}"},
        {pos: [10, 3, 4], state: "minecraft:air"},
        {pos: [10, 3, 5], state: "minecraft:air"},
        {pos: [10, 3, 6], state: "minecraft:mossy_cobblestone_stairs{half:bottom,waterlogged:false,shape:straight,facing:south}"},
        {pos: [10, 3, 8], state: "minecraft:air"},
        {pos: [10, 3, 9], state: "minecraft:air"},
        {pos: [10, 3, 10], state: "minecraft:air"},
        {pos: [10, 3, 11], state: "minecraft:dark_oak_stairs{half:top,waterlogged:false,shape:straight,facing:east}"},
        {pos: [10, 3, 13], state: "minecraft:dark_oak_slab{waterlogged:false,type:bottom}"},
