{
    size: [10, 7, 10],
    data: [
        {pos: [3, 0, 3], state: "minecraft:cobblestone"},
        {pos: [3, 0, 4], state: "minecraft:cobblestone"},
        {pos: [3, 0, 5], state: "minecraft:cobblestone"},
        {pos: [3, 0, 6], state: "minecraft:cobblestone"},
        {pos: [4, 0, 3], state: "minecraft:cobblestone"},
        {pos: [4, 0, 6], state: "minecraft:cobblestone"},
        {pos: [5, 0, 3], state: "minecraft:cobblestone"},
        {pos: [5, 0, 6], state: "minecraft:cobblestone"},
        {pos: [6, 0, 4], state: "minecraft:cobblestone"},
        {pos: [6, 0, 5], state: "minecraft:cobblestone"},
        {pos: [6, 0, 6], state: "minecraft:cobblestone"},
        {pos: [2, 1, 3], state: "minecraft:cobblestone"},
        {pos: [2, 1, 5], state: "minecraft:cobblestone"},
        {pos: [2, 1, 6], state: "minecraft:cobblestone"},
        {pos: [2, 1, 7], state: "minecraft:cobblestone"},
        {pos: [3, 1, 2], state: "minecraft:cobblestone"},
        {pos: [3, 1, 3], state: "minecraft:cobblestone"},
        {pos: [3, 1, 4], state: "minecraft:cobblestone"},
        {pos: [3, 1, 5], state: "minecraft:cobblestone"},
        {pos: [3, 1, 6], state: "minecraft:cobblestone"},
        {pos: [3, 1, 7], state: "minecraft:cobblestone"},
        {pos: [4, 1, 2], state: "minecraft:cobblestone"},
        {pos: [4, 1, 3], state: "minecraft:cobblestone"},
        {pos: [4, 1, 6], state: "minecraft:cobblestone"},
        {pos: [4, 1, 7], state: "minecraft:cobblestone"},
        {pos: [5, 1, 2], state: "minecraft:cobblestone"},
        {pos: [5, 1, 3], state: "minecraft:cobblestone"},
        {pos: [5, 1, 6], state: "minecraft:cobblestone"},
        {pos: [6, 1, 2], state: "minecraft:cobblestone"},
        {pos: [6, 1, 3], state: "minecraft:cobblestone"},
        {pos: [6, 1, 4], state: "minecraft:cobblestone"},
        {pos: [6, 1, 5], state: "minecraft:cobblestone"},
        {pos: [6, 1, 6], state: "minecraft:cobblestone"},
        {pos: [6, 1, 7], state: "minecraft:cobblestone"},
        {pos: [7, 1, 2], state: "minecraft:cobblestone"},
        {pos: [7, 1, 3], state: "minecraft:cobblestone"},
        {pos: [7, 1, 4], state: "minecraft:cobblestone"},
        {pos: [7, 1, 5], state: "minecraft:cobblestone"},
        {pos: [7, 1, 6], state: "minecraft:cobblestone"},
        {pos: [7, 1, 7], state: "minecraft:cobblestone"},
        {pos: [3, 2, 3], state: "minecraft:cobblestone"},
        {pos: [3, 2, 4], state: "minecraft:cobblestone"},
        {pos: [3, 2, 5], state: "minecraft:cobblestone"},
        {pos: [3, 2, 6], state: "minecraft:cobblestone"},
        {pos: [4, 2, 3], state: "minecraft:cobblestone"},
        {pos: [4, 2, 6], state: "minecraft:cobblestone"},
        {pos: [5, 2, 3], state: "minecraft:cobblestone"},
        {pos: [5, 2, 6], state: "minecraft:cobblestone"},
        {pos: [6, 2, 3], state: "minecraft:cobblestone"},
        {pos: [6, 2, 4], state: "minecraft:cobblestone"},
        {pos: [6, 2, 5], state: "minecraft:cobblestone"},
        {pos: [6, 2, 6], state: "minecraft:cobblestone"},
        {pos: [3, 5, 3], state: "minecraft:cobblestone"},
        {pos: [3, 5, 4], state: "minecraft:cobblestone"},
        {pos: [3, 5, 5], state: "minecraft:cobblestone"},
        {pos: [3, 5, 6], state: "minecraft:cobblestone"},
        {pos: [4, 5, 3], state: "minecraft:cobblestone"},
        {pos: [4, 5, 4], state: "minecraft:cobblestone"},
        {pos: [4, 5, 5], state: "minecraft:cobblestone"},
        {pos: [4, 5, 6], state: "minecraft:cobblestone"},
        {pos: [5, 5, 3], state: "minecraft:cobblestone"},
        {pos: [5, 5, 4], state: "minecraft:cobblestone"},
        {pos: [5, 5, 5], state: "minecraft:cobblestone"},
        {pos: [5, 5, 6], state: "minecraft:cobblestone"},
        {pos: [6, 5, 3], state: "minecraft:cobblestone"},
        {pos: [6, 5, 4], state: "minecraft:cobblestone"},
        {pos: [6, 5, 5], state: "minecraft:cobblestone"},
        {pos: [6, 5, 6], state: "minecraft:cobblestone"},
        {pos: [0, 0, 4], state: "minecraft:dirt_path"},
        {pos: [0, 0, 5], state: "minecraft:dirt_path"},
        {pos: [1, 0, 2], state: "minecraft:dirt_path"},
        {pos: [1, 0, 3], state: "minecraft:dirt_path"},
        {pos: [1, 0, 4], state: "minecraft:dirt_path"},
        {pos: [1, 0, 5], state: "minecraft:dirt_path"},
        {pos: [1, 0, 7], state: "minecraft:dirt_path"},
        {pos: [2, 0, 1], state: "minecraft:dirt_path"},
        {pos: [2, 0, 2], state: "minecraft:dirt_path"},
        {pos: [2, 0, 3], state: "minecraft:dirt_path"},
        {pos: [2, 0, 4], state: "minecraft:dirt_path"},
        {pos: [2, 0, 5], state: "minecraft:dirt_path"},
        {pos: [2, 0, 6], state: "minecraft:dirt_path"},
        {pos: [2, 0, 7], state: "minecraft:dirt_path"},
        {pos: [2, 0, 8], state: "minecraft:dirt_path"},
        {pos: [3, 0, 1], state: "minecraft:dirt_path"},
        {pos: [3, 0, 2], state: "minecraft:dirt_path"},
        {pos: [3, 0, 7], state: "minecraft:dirt_path"},
        {pos: [3, 0, 8], state: "minecraft:dirt_path"},
        {pos: [4, 0, 0], state: "minecraft:dirt_path"},
        {pos: [4, 0, 1], state: "minecraft:dirt_path"},
        {pos: [4, 0, 2], state: "minecraft:dirt_path"},
        {pos: [4, 0, 4], state: "minecraft:water{level:0}"},
        {pos: [4, 0, 5], state: "minecraft:water{level:0}"},
        {pos: [4, 0, 7], state: "minecraft:dirt_path"},
        {pos: [4, 0, 8], state: "minecraft:dirt_path"},
        {pos: [4, 0, 9], state: "minecraft:dirt_path"},
        {pos: [5, 0, 0], state: "minecraft:dirt_path"},
        {pos: [5, 0, 1], state: "minecraft:dirt_path"},
        {pos: [5, 0, 2], state: "minecraft:dirt_path"},
        {pos: [5, 0, 4], state: "minecraft:water{level:0}"},
        {pos: [5, 0, 5], state: "minecraft:water{level:0}"},
        {pos: [5, 0, 7], state: "minecraft:dirt_path"},
        {pos: [5, 0, 8], state: "minecraft:dirt_path"},
        {pos: [5, 0, 9], state: "minecraft:dirt_path"},
        {pos: [6, 0, 1], state: "minecraft:dirt_path"},
        {pos: [6, 0, 2], state: "minecraft:dirt_path"},
        {pos: [6, 0, 7], state: "minecraft:dirt_path"},
        {pos: [6, 0, 8], state: "minecraft:dirt_path"},
        {pos: [7, 0, 1], state: "minecraft:dirt_path"},
        {pos: [7, 0, 2], state: "minecraft:dirt_path"},
        {pos: [7, 0, 3], state: "minecraft:dirt_path"},
        {pos: [7, 0, 4], state: "minecraft:dirt_path"},
        {pos: [7, 0, 5], state: "minecraft:dirt_path"},
        {pos: [7, 0, 6], state: "minecraft:dirt_path"},
        {pos: [7, 0, 7], state: "minecraft:dirt_path"},
        {pos: [7, 0, 8], state: "minecraft:dirt_path"},
        {pos: [8, 0, 1], state: "minecraft:dirt_path"},
        {pos: [8, 0, 2], state: "minecraft:dirt_path"},
        {pos: [8, 0, 3], state: "minecraft:dirt_path"},
        {pos: [8, 0, 4], state: "minecraft:dirt_path"},
        {pos: [8, 0, 5], state: "minecraft:dirt_path"},
        {pos: [8, 0, 6], state: "minecraft:dirt_path"},
        {pos: [8, 0, 7], state: "minecraft:dirt_path"},
        {pos: [8, 0, 8], state: "minecraft:dirt_path"},
        {pos: [9, 0, 4], state: "minecraft:dirt_path"},
        {pos: [9, 0, 5], state: "minecraft:dirt_path"},
        {pos: [4, 1, 4], state: "minecraft:water{level:0}"},
        {pos: [4, 1, 5], state: "minecraft:water{level:0}"},
        {pos: [5, 1, 4], state: "minecraft:water{level:0}"},
        {pos: [5, 1, 5], state: "minecraft:water{level:0}"},
        {pos: [3, 3, 3], state: "minecraft:oak_fence{east:false,waterlogged:false,south:false,north:false,west:false}"},
        {pos: [3, 3, 6], state: "minecraft:oak_fence{east:false,waterlogged:false,south:false,north:false,west:false}"},
        {pos: [6, 3, 3], state: "minecraft:oak_fence{east:false,waterlogged:false,south:false,north:false,west:false}"},
        {pos: [6, 3, 6], state: "minecraft:oak_fence{east:false,waterlogged:false,south:false,north:false,west:false}"},
        {pos: [3, 4, 3], state: "minecraft:oak_fence{east:false,waterlogged:false,south:false,north:false,west:false}"},
        {pos: [3, 4, 6], state: "minecraft:oak_fence{east:false,waterlogged:false,south:false,north:false,west:false}"},
        {pos: [6, 4, 3], state: "minecraft:oak_fence{east:false,waterlogged:false,south:false,north:false,west:false}"},
        {pos: [6, 4, 6], state: "minecraft:oak_fence{east:false,waterlogged:false,south:false,north:false,west:false}"},
        {pos: [3, 6, 3], state: "minecraft:torch"},
        {pos: [3, 6, 6], state: "minecraft:torch"},
        {pos: [6, 6, 3], state: "minecraft:torch"},
        {pos: [6, 6, 6], state: "minecraft:torch"},
        {pos: [1, 0, 1], state: "minecraft:jigsaw{orientation:up_north}", nbt: {final_state: "minecraft:dirt_path", id: "minecraft:jigsaw", joint: "rollable", name: "minecraft:bottom", pool: "minecraft:village/plains/villagers", target: "minecraft:bottom"}},
        {pos: [1, 0, 6], state: "minecraft:jigsaw{orientation:up_north}", nbt: {final_state: "minecraft:dirt_path", id: "minecraft:jigsaw", joint: "rollable", name: "minecraft:bottom", pool: "minecraft:village/common/iron_golem", target: "minecraft:bottom"}},
        {pos: [1, 0, 8], state: "minecraft:jigsaw{orientation:up_north}", nbt: {final_state: "minecraft:dirt_path", id: "minecraft:jigsaw", joint: "rollable", name: "minecraft:bottom", pool: "minecraft:village/plains/villagers", target: "minecraft:bottom"}},
        {pos: [6, 0, 3], state: "minecraft:jigsaw{orientation:down_south}", nbt: {final_state: "minecraft:cobblestone", id: "minecraft:jigsaw", joint: "rollable", name: "minecraft:bottom", pool: "minecraft:village/common/well_bottoms", target: "minecraft:bottom"}},
        {pos: [0, 1, 4], state: "minecraft:jigsaw{orientation:west_up}", nbt: {final_state: "minecraft:structure_void", id: "minecraft:jigsaw", joint: "aligned", name: "minecraft:street", pool: "minecraft:village/plains/streets", target: "minecraft:street"}},
        {pos: [2, 1, 2], state: "minecraft:jigsaw{orientation:up_north}", nbt: {final_state: "minecraft:cobblestone", id: "minecraft:jigsaw", joint: "rollable", name: "minecraft:bottom", pool: "minecraft:village/common/cats", target: "minecraft:bottom"}},
        {pos: [2, 1, 4], state: "minecraft:jigsaw{orientation:up_north}", nbt: {final_state: "minecraft:cobblestone", id: "minecraft:jigsaw", joint: "rollable", name: "minecraft:bottom", pool: "minecraft:village/common/cats", target: "minecraft:bottom"}},
        {pos: [4, 1, 9], state: "minecraft:jigsaw{orientation:south_up}", nbt: {final_state: "minecraft:structure_void", id: "minecraft:jigsaw", joint: "aligned", name: "minecraft:street", pool: "minecraft:village/plains/streets", target: "minecraft:street"}},
        {pos: [5, 1, 0], state: "minecraft:jigsaw{orientation:north_up}", nbt: {final_state: "minecraft:structure_void", id: "minecraft:jigsaw", joint: "aligned", name: "minecraft:street", pool: "minecraft:village/plains/streets", target: "minecraft:street"}},
        {pos: [5, 1, 7], state: "minecraft:jigsaw{orientation:up_north}", nbt: {final_state: "minecraft:cobblestone", id: "minecraft:jigsaw", joint: "rollable", name: "minecraft:bottom", pool: "minecraft:village/common/cats", target: "minecraft:bottom"}},
        {pos: [9, 1, 5], state: "minecraft:jigsaw{orientation:east_up}", nbt: {final_state: "minecraft:structure_void", id: "minecraft:jigsaw", joint: "aligned", name: "minecraft:street", pool: "minecraft:village/plains/streets", target: "minecraft:street"}},
        {pos: [3, 2, 7], state: "minecraft:bell{attachment:floor,powered:false,facing:north}", nbt: {id: "minecraft:bell"}}
    ],
    entities: [],
    palette: [
        "minecraft:cobblestone",
        "minecraft:dirt_path",
        "minecraft:water{level:0}",
        "minecraft:oak_fence{east:false,waterlogged:false,south:false,north:false,west:false}",
        "minecraft:torch",
        "minecraft:jigsaw{orientation:up_north}",
        "minecraft:jigsaw{orientation:down_south}",
        "minecraft:jigsaw{orientation:west_up}",
        "minecraft:jigsaw{orientation:south_up}",
        "minecraft:jigsaw{orientation:north_up}",
        "minecraft:jigsaw{orientation:east_up}",
        "minecraft:bell{attachment:floor,powered:false,facing:north}"
    ]
}