{
    size: [10, 8, 8],
    data: [
        {pos: [0, 0, 0], state: "minecraft:polished_deepslate"},
        {pos: [0, 0, 1], state: "minecraft:polished_deepslate"},
        {pos: [0, 0, 6], state: "minecraft:polished_deepslate"},
        {pos: [0, 0, 7], state: "minecraft:polished_deepslate"},
        {pos: [1, 0, 0], state: "minecraft:polished_deepslate"},
        {pos: [1, 0, 1], state: "minecraft:deepslate{axis:y}"},
        {pos: [1, 0, 2], state: "minecraft:deepslate{axis:y}"},
        {pos: [1, 0, 3], state: "minecraft:polished_deepslate"},
        {pos: [1, 0, 4], state: "minecraft:polished_deepslate"},
        {pos: [1, 0, 5], state: "minecraft:deepslate{axis:y}"},
        {pos: [1, 0, 6], state: "minecraft:deepslate{axis:y}"},
        {pos: [1, 0, 7], state: "minecraft:polished_deepslate"},
        {pos: [2, 0, 0], state: "minecraft:polished_deepslate"},
        {pos: [2, 0, 1], state: "minecraft:deepslate{axis:y}"},
        {pos: [2, 0, 2], state: "minecraft:cobbled_deepslate"},
        {pos: [2, 0, 3], state: "minecraft:cobbled_deepslate"},
        {pos: [2, 0, 4], state: "minecraft:cobbled_deepslate"},
        {pos: [2, 0, 5], state: "minecraft:cobbled_deepslate"},
        {pos: [2, 0, 6], state: "minecraft:deepslate{axis:y}"},
        {pos: [2, 0, 7], state: "minecraft:polished_deepslate"},
        {pos: [3, 0, 1], state: "minecraft:deepslate{axis:y}"},
        {pos: [3, 0, 2], state: "minecraft:cobbled_deepslate"},
        {pos: [3, 0, 3], state: "minecraft:cobbled_deepslate"},
        {pos: [3, 0, 4], state: "minecraft:cobbled_deepslate"},
        {pos: [3, 0, 5], state: "minecraft:cobbled_deepslate"},
        {pos: [3, 0, 6], state: "minecraft:deepslate{axis:y}"},
        {pos: [4, 0, 1], state: "minecraft:deepslate{axis:y}"},
        {pos: [4, 0, 2], state: "minecraft:cobbled_deepslate"},
        {pos: [4, 0, 3], state: "minecraft:cobbled_deepslate"},
        {pos: [4, 0, 4], state: "minecraft:cobbled_deepslate"},
        {pos: [4, 0, 5], state: "minecraft:cobbled_deepslate"},
        {pos: [4, 0, 6], state: "minecraft:deepslate{axis:y}"},
        {pos: [5, 0, 1], state: "minecraft:deepslate{axis:y}"},
        {pos: [5, 0, 2], state: "minecraft:cobbled_deepslate"},
        {pos: [5, 0, 3], state: "minecraft:cobbled_deepslate"},
        {pos: [5, 0, 4], state: "minecraft:cobbled_deepslate"},
        {pos: [5, 0, 5], state: "minecraft:cobbled_deepslate"},
        {pos: [5, 0, 6], state: "minecraft:deepslate{axis:y}"},
        {pos: [6, 0, 1], state: "minecraft:deepslate{axis:y}"},
        {pos: [6, 0, 2], state: "minecraft:cobbled_deepslate"},
        {pos: [6, 0, 3], state: "minecraft:cobbled_deepslate"},
        {pos: [6, 0, 4], state: "minecraft:cobbled_deepslate"},
        {pos: [6, 0, 5], state: "minecraft:cobbled_deepslate"},
        {pos: [6, 0, 6], state: "minecraft:deepslate{axis:y}"},
        {pos: [7, 0, 0], state: "minecraft:polished_deepslate"},
        {pos: [7, 0, 1], state: "minecraft:deepslate{axis:y}"},
        {pos: [7, 0, 2], state: "minecraft:deepslate{axis:y}"},
        {pos: [7, 0, 3], state: "minecraft:deepslate{axis:y}"},
        {pos: [7, 0, 4], state: "minecraft:deepslate{axis:y}"},
        {pos: [7, 0, 5], state: "minecraft:deepslate{axis:y}"},
        {pos: [7, 0, 6], state: "minecraft:deepslate{axis:y}"},
        {pos: [7, 0, 7], state: "minecraft:polished_deepslate"},
        {pos: [8, 0, 0], state: "minecraft:polished_deepslate"},
        {pos: [8, 0, 1], state: "minecraft:deepslate{axis:y}"},
        {pos: [8, 0, 2], state: "minecraft:deepslate{axis:y}"},
        {pos: [8, 0, 3], state: "minecraft:polished_deepslate"},
        {pos: [8, 0, 4], state: "minecraft:polished_deepslate"},
        {pos: [8, 0, 5], state: "minecraft:deepslate{axis:y}"},
        {pos: [8, 0, 6], state: "minecraft:deepslate{axis:y}"},
        {pos: [8, 0, 7], state: "minecraft:polished_deepslate"},
        {pos: [9, 0, 0], state: "minecraft:polished_deepslate"},
        {pos: [9, 0, 1], state: "minecraft:polished_deepslate"},
        {pos: [9, 0, 6], state: "minecraft:polished_deepslate"},
        {pos: [9, 0, 7], state: "minecraft:polished_deepslate"},
        {pos: [0, 1, 0], state: "minecraft:polished_deepslate"},
        {pos: [0, 1, 7], state: "minecraft:polished_deepslate"},
        {pos: [1, 1, 0], state: "minecraft:polished_deepslate"},
        {pos: [1, 1, 7], state: "minecraft:polished_deepslate"},
        {pos: [2, 1, 2], state: "minecraft:polished_deepslate"},
        {pos: [2, 1, 3], state: "minecraft:deepslate{axis:y}"},
        {pos: [2, 1, 4], state: "minecraft:deepslate{axis:y}"},
        {pos: [2, 1, 5], state: "minecraft:polished_deepslate"},
        {pos: [3, 1, 2], state: "minecraft:polished_deepslate"},
        {pos: [3, 1, 3], state: "minecraft:cobbled_deepslate"},
        {pos: [3, 1, 4], state: "minecraft:cobbled_deepslate"},
        {pos: [3, 1, 5], state: "minecraft:polished_deepslate"},
        {pos: [4, 1, 2], state: "minecraft:polished_deepslate"},
        {pos: [4, 1, 3], state: "minecraft:deepslate{axis:y}"},
        {pos: [4, 1, 4], state: "minecraft:deepslate{axis:y}"},
        {pos: [4, 1, 5], state: "minecraft:polished_deepslate"},
        {pos: [5, 1, 2], state: "minecraft:polished_deepslate"},
        {pos: [5, 1, 3], state: "minecraft:deepslate{axis:y}"},
        {pos: [5, 1, 4], state: "minecraft:deepslate{axis:y}"},
        {pos: [5, 1, 5], state: "minecraft:polished_deepslate"},
        {pos: [6, 1, 2], state: "minecraft:polished_deepslate"},
        {pos: [6, 1, 3], state: "minecraft:deepslate{axis:y}"},
        {pos: [6, 1, 4], state: "minecraft:deepslate{axis:y}"},
        {pos: [6, 1, 5], state: "minecraft:polished_deepslate"},
        {pos: [8, 1, 0], state: "minecraft:polished_deepslate"},
        {pos: [8, 1, 7], state: "minecraft:polished_deepslate"},
        {pos: [9, 1, 0], state: "minecraft:polished_deepslate"},
        {pos: [9, 1, 1], state: "minecraft:polished_deepslate"},
        {pos: [9, 1, 6], state: "minecraft:polished_deepslate"},
        {pos: [9, 1, 7], state: "minecraft:polished_deepslate"},
        {pos: [0, 2, 0], state: "minecraft:polished_deepslate"},
        {pos: [0, 2, 7], state: "minecraft:polished_deepslate"},
        {pos: [3, 2, 2], state: "minecraft:deepslate_tiles"},
        {pos: [3, 2, 5], state: "minecraft:deepslate_tiles"},
        {pos: [9, 2, 0], state: "minecraft:polished_deepslate"},
        {pos: [9, 2, 7], state: "minecraft:polished_deepslate"},
        {pos: [3, 2, 3], state: "minecraft:deepslate_tile_slab{waterlogged:false,type:bottom}"},
        {pos: [3, 2, 4], state: "minecraft:deepslate_tile_slab{waterlogged:false,type:bottom}"},
        {pos: [4, 2, 2], state: "minecraft:white_candle{waterlogged:false,lit:false,candles:1}"},
        {pos: [4, 2, 3], state: "minecraft:white_candle{waterlogged:false,lit:false,candles:1}"},
        {pos: [4, 2, 4], state: "minecraft:white_candle{waterlogged:false,lit:false,candles:4}"},
        {pos: [4, 2, 5], state: "minecraft:white_candle{waterlogged:false,lit:false,candles:1}"},
        {pos: [3, 3, 1], state: "minecraft:polished_deepslate_wall{east:none,waterlogged:false,south:low,north:none,west:none,up:true}"},
        {pos: [3, 3, 2], state: "minecraft:deepslate_brick_stairs{half:top,waterlogged:false,shape:straight,facing:north}"},
        {pos: [3, 3, 5], state: "minecraft:deepslate_brick_stairs{half:top,waterlogged:false,shape:straight,facing:south}"},
        {pos: [3, 3, 6], state: "minecraft:polished_deepslate_wall{east:none,waterlogged:false,south:none,north:low,west:none,up:true}"},
        {pos: [3, 4, 2], state: "minecraft:deepslate_brick_slab{waterlogged:false,type:bottom}"},
        {pos: [3, 4, 3], state: "minecraft:deepslate_brick_slab{waterlogged:false,type:bottom}"},
        {pos: [3, 4, 4], state: "minecraft:deepslate_brick_slab{waterlogged:false,type:bottom}"},
        {pos: [3, 4, 5], state: "minecraft:deepslate_brick_slab{waterlogged:false,type:bottom}"},
        {pos: [0, 0, 3], state: "minecraft:jigsaw{orientation:west_up}", nbt: {final_state: "minecraft:structure_void", id: "minecraft:jigsaw", joint: "rollable", name: "minecraft:connect_structure", pool: "minecraft:empty", target: "minecraft:empty"}},
        {pos: [0, 0, 5], state: "minecraft:jigsaw{orientation:west_up}", nbt: {final_state: "minecraft:structure_void", id: "minecraft:jigsaw", joint: "rollable", name: "minecraft:connect_structure", pool: "minecraft:empty", target: "minecraft:empty"}}
    ],
    entities: [],
    palette: [
        "minecraft:polished_deepslate",
        "minecraft:deepslate{axis:y}",
        "minecraft:cobbled_deepslate",
        "minecraft:deepslate_tiles",
        "minecraft:deepslate_tile_slab{waterlogged:false,type:bottom}",
        "minecraft:white_candle{waterlogged:false,lit:false,candles:1}",
        "minecraft:white_candle{waterlogged:false,lit:false,candles:4}",
        "minecraft:polished_deepslate_wall{east:none,waterlogged:false,south:low,north:none,west:none,up:true}",
        "minecraft:deepslate_brick_stairs{half:top,waterlogged:false,shape:straight,facing:north}",
        "minecraft:deepslate_brick_stairs{half:top,waterlogged:false,shape:straight,facing:south}",
        "minecraft:polished_deepslate_wall{east:none,waterlogged:false,south:none,north:low,west:none,up:true}",
        "minecraft:deepslate_brick_slab{waterlogged:false,type:bottom}",
        "minecraft:jigsaw{orientation:west_up}"
    ]
}