{
    size: [17, 23, 17],
    data: [
        {pos: [4, 0, 6], state: "minecraft:deepslate_tiles"},
        {pos: [4, 0, 7], state: "minecraft:deepslate_bricks"},
        {pos: [4, 0, 8], state: "minecraft:deepslate_bricks"},
        {pos: [4, 0, 10], state: "minecraft:deepslate_tiles"},
        {pos: [5, 0, 5], state: "minecraft:deepslate_bricks"},
        {pos: [5, 0, 6], state: "minecraft:deepslate_bricks"},
        {pos: [5, 0, 7], state: "minecraft:deepslate_bricks"},
        {pos: [5, 0, 11], state: "minecraft:deepslate_bricks"},
        {pos: [6, 0, 4], state: "minecraft:deepslate_tiles"},
        {pos: [6, 0, 5], state: "minecraft:deepslate_bricks"},
        {pos: [6, 0, 6], state: "minecraft:deepslate_bricks"},
        {pos: [6, 0, 12], state: "minecraft:deepslate_tiles"},
        {pos: [7, 0, 4], state: "minecraft:deepslate_bricks"},
        {pos: [7, 0, 5], state: "minecraft:deepslate_bricks"},
        {pos: [7, 0, 6], state: "minecraft:deepslate_tiles"},
        {pos: [7, 0, 7], state: "minecraft:deepslate_tiles"},
        {pos: [7, 0, 12], state: "minecraft:deepslate_bricks"},
        {pos: [8, 0, 4], state: "minecraft:deepslate_bricks"},
        {pos: [8, 0, 5], state: "minecraft:deepslate_bricks"},
        {pos: [8, 0, 6], state: "minecraft:deepslate_tiles"},
        {pos: [8, 0, 11], state: "minecraft:deepslate_bricks"},
        {pos: [8, 0, 12], state: "minecraft:deepslate_bricks"},
        {pos: [9, 0, 4], state: "minecraft:deepslate_bricks"},
        {pos: [9, 0, 5], state: "minecraft:deepslate_bricks"},
        {pos: [9, 0, 6], state: "minecraft:deepslate_tiles"},
        {pos: [9, 0, 12], state: "minecraft:deepslate_bricks"},
        {pos: [10, 0, 4], state: "minecraft:deepslate_bricks"},
        {pos: [10, 0, 5], state: "minecraft:deepslate_bricks"},
        {pos: [10, 0, 6], state: "minecraft:deepslate_bricks"},
        {pos: [10, 0, 7], state: "minecraft:deepslate_tiles"},
        {pos: [10, 0, 10], state: "minecraft:deepslate_bricks"},
        {pos: [10, 0, 12], state: "minecraft:deepslate_tiles"},
        {pos: [11, 0, 5], state: "minecraft:deepslate_bricks"},
        {pos: [11, 0, 6], state: "minecraft:deepslate_bricks"},
        {pos: [11, 0, 7], state: "minecraft:deepslate_bricks"},
        {pos: [11, 0, 8], state: "minecraft:deepslate_bricks"},
        {pos: [11, 0, 9], state: "minecraft:deepslate_bricks"},
        {pos: [11, 0, 10], state: "minecraft:deepslate_bricks"},
        {pos: [11, 0, 11], state: "minecraft:deepslate_bricks"},
        {pos: [12, 0, 6], state: "minecraft:deepslate_tiles"},
        {pos: [12, 0, 7], state: "minecraft:deepslate_bricks"},
        {pos: [12, 0, 8], state: "minecraft:deepslate_bricks"},
        {pos: [12, 0, 9], state: "minecraft:deepslate_bricks"},
        {pos: [12, 0, 10], state: "minecraft:deepslate_tiles"},
        {pos: [5, 1, 5], state: "minecraft:deepslate_bricks"},
        {pos: [10, 1, 6], state: "minecraft:deepslate_tiles"},
        {pos: [11, 1, 5], state: "minecraft:deepslate_bricks"},
        {pos: [5, 2, 5], state: "minecraft:deepslate_bricks"},
        {pos: [10, 2, 6], state: "minecraft:deepslate_tiles"},
        {pos: [11, 2, 5], state: "minecraft:deepslate_bricks"},
        {pos: [11, 3, 5], state: "minecraft:deepslate_bricks"},
        {pos: [5, 4, 5], state: "minecraft:deepslate_bricks"},
        {pos: [10, 4, 6], state: "minecraft:deepslate_tiles"},
        {pos: [11, 4, 5], state: "minecraft:deepslate_bricks"},
        {pos: [5, 5, 5], state: "minecraft:deepslate_bricks"},
        {pos: [10, 5, 6], state: "minecraft:deepslate_tiles"},
        {pos: [11, 5, 5], state: "minecraft:deepslate_bricks"},
        {pos: [5, 6, 5], state: "minecraft:deepslate_bricks"},
        {pos: [10, 6, 6], state: "minecraft:deepslate_tiles"},
        {pos: [10, 6, 10], state: "minecraft:deepslate_tiles"},
        {pos: [11, 6, 5], state: "minecraft:deepslate_bricks"},
        {pos: [11, 6, 11], state: "minecraft:deepslate_bricks"},
        {pos: [4, 7, 5], state: "minecraft:deepslate_bricks"},
        {pos: [5, 7, 4], state: "minecraft:deepslate_bricks"},
        {pos: [5, 7, 5], state: "minecraft:deepslate_bricks"},
        {pos: [6, 7, 3], state: "minecraft:deepslate_bricks"},
        {pos: [6, 7, 4], state: "minecraft:deepslate_bricks"},
        {pos: [6, 7, 6], state: "minecraft:deepslate_bricks"},
        {pos: [7, 7, 3], state: "minecraft:deepslate_bricks"},
        {pos: [7, 7, 4], state: "minecraft:deepslate_bricks"},
        {pos: [7, 7, 5], state: "minecraft:deepslate_bricks"},
        {pos: [8, 7, 3], state: "minecraft:deepslate_bricks"},
        {pos: [8, 7, 4], state: "minecraft:deepslate_bricks"},
        {pos: [8, 7, 5], state: "minecraft:deepslate_bricks"},
        {pos: [9, 7, 3], state: "minecraft:deepslate_bricks"},
        {pos: [9, 7, 4], state: "minecraft:deepslate_bricks"},
        {pos: [9, 7, 5], state: "minecraft:deepslate_bricks"},
        {pos: [9, 7, 6], state: "minecraft:deepslate_bricks"},
        {pos: [9, 7, 7], state: "minecraft:deepslate_bricks"},
        {pos: [9, 7, 8], state: "minecraft:deepslate_bricks"},
        {pos: [10, 7, 3], state: "minecraft:deepslate_bricks"},
        {pos: [10, 7, 4], state: "minecraft:deepslate_bricks"},
        {pos: [10, 7, 6], state: "minecraft:deepslate_bricks"},
        {pos: [10, 7, 7], state: "minecraft:deepslate_bricks"},
        {pos: [10, 7, 8], state: "minecraft:deepslate_bricks"},
        {pos: [10, 7, 10], state: "minecraft:deepslate_bricks"},
        {pos: [11, 7, 4], state: "minecraft:deepslate_bricks"},
        {pos: [11, 7, 5], state: "minecraft:deepslate_bricks"},
        {pos: [11, 7, 7], state: "minecraft:deepslate_bricks"},
        {pos: [11, 7, 8], state: "minecraft:deepslate_bricks"},
        {pos: [11, 7, 9], state: "minecraft:deepslate_bricks"},
        {pos: [11, 7, 11], state: "minecraft:deepslate_bricks"},
        {pos: [11, 7, 12], state: "minecraft:deepslate_bricks"},
        {pos: [12, 7, 5], state: "minecraft:deepslate_bricks"},
        {pos: [12, 7, 6], state: "minecraft:deepslate_bricks"},
        {pos: [12, 7, 7], state: "minecraft:deepslate_bricks"},
        {pos: [12, 7, 8], state: "minecraft:deepslate_bricks"},
        {pos: [12, 7, 9], state: "minecraft:deepslate_bricks"},
        {pos: [12, 7, 10], state: "minecraft:deepslate_bricks"},
        {pos: [12, 7, 11], state: "minecraft:deepslate_bricks"},
        {pos: [13, 7, 6], state: "minecraft:deepslate_bricks"},
        {pos: [13, 7, 7], state: "minecraft:deepslate_bricks"},
        {pos: [13, 7, 8], state: "minecraft:deepslate_bricks"},
        {pos: [13, 7, 9], state: "minecraft:deepslate_bricks"},
        {pos: [13, 7, 10], state: "minecraft:deepslate_bricks"},
        {pos: [6, 13, 3], state: "minecraft:deepslate_tiles"},
        {pos: [9, 13, 6], state: "minecraft:deepslate_tiles"},
        {pos: [9, 13, 10], state: "minecraft:deepslate_tiles"},
        {pos: [10, 13, 3], state: "minecraft:deepslate_tiles"},
        {pos: [10, 13, 4], state: "minecraft:deepslate_tiles"},
        {pos: [10, 13, 5], state: "minecraft:deepslate_tiles"},
        {pos: [10, 13, 6], state: "minecraft:deepslate_tiles"},
        {pos: [10, 13, 7], state: "minecraft:deepslate_tiles"},
        {pos: [10, 13, 8], state: "minecraft:deepslate_tiles"},
        {pos: [10, 13, 10], state: "minecraft:deepslate_tiles"},
        {pos: [10, 13, 11], state: "minecraft:deepslate_tiles"},
        {pos: [10, 13, 12], state: "minecraft:deepslate_tiles"},
        {pos: [10, 13, 13], state: "minecraft:deepslate_tiles"},
        {pos: [11, 13, 5], state: "minecraft:deepslate_tiles"},
        {pos: [11, 13, 6], state: "minecraft:deepslate_tiles"},
        {pos: [12, 13, 6], state: "minecraft:deepslate_tiles"},
        {pos: [13, 13, 6], state: "minecraft:deepslate_tiles"},
        {pos: [2, 14, 6], state: "minecraft:deepslate_tiles"},
        {pos: [6, 14, 2], state: "minecraft:deepslate_tiles"},
        {pos: [10, 14, 2], state: "minecraft:deepslate_tiles"},
        {pos: [10, 14, 3], state: "minecraft:deepslate_tiles"},
        {pos: [10, 14, 14], state: "minecraft:deepslate_tiles"},
        {pos: [14, 14, 6], state: "minecraft:deepslate_tiles"},
        {pos: [14, 14, 10], state: "minecraft:deepslate_tiles"},
        {pos: [1, 15, 6], state: "minecraft:deepslate_tiles"},
        {pos: [2, 15, 6], state: "minecraft:deepslate_tiles"},
        {pos: [6, 15, 1], state: "minecraft:deepslate_tiles"},
        {pos: [6, 15, 2], state: "minecraft:deepslate_tiles"},
        {pos: [10, 15, 1], state: "minecraft:deepslate_tiles"},
        {pos: [10, 15, 2], state: "minecraft:deepslate_tiles"},
        {pos: [10, 15, 14], state: "minecraft:deepslate_tiles"},
        {pos: [14, 15, 6], state: "minecraft:deepslate_tiles"},
        {pos: [14, 15, 10], state: "minecraft:deepslate_tiles"},
        {pos: [15, 15, 6], state: "minecraft:deepslate_tiles"},
        {pos: [15, 15, 10], state: "minecraft:deepslate_tiles"},
        {pos: [1, 16, 6], state: "minecraft:deepslate_tiles"},
        {pos: [2, 16, 6], state: "minecraft:deepslate_tiles"},
        {pos: [6, 16, 1], state: "minecraft:deepslate_tiles"},
        {pos: [6, 16, 2], state: "minecraft:deepslate_tiles"},
        {pos: [10, 16, 1], state: "minecraft:deepslate_tiles"},
        {pos: [10, 16, 2], state: "minecraft:deepslate_tiles"},
        {pos: [10, 16, 14], state: "minecraft:deepslate_tiles"},
        {pos: [10, 16, 15], state: "minecraft:deepslate_tiles"},
        {pos: [14, 16, 6], state: "minecraft:deepslate_tiles"},
        {pos: [15, 16, 6], state: "minecraft:deepslate_tiles"},
        {pos: [15, 16, 10], state: "minecraft:deepslate_tiles"},
        {pos: [2, 17, 6], state: "minecraft:deepslate_tiles"},
        {pos: [3, 17, 6], state: "minecraft:deepslate_tiles"},
        {pos: [6, 17, 2], state: "minecraft:deepslate_tiles"},
        {pos: [6, 17, 3], state: "minecraft:deepslate_tiles"},
        {pos: [10, 17, 2], state: "minecraft:deepslate_tiles"},
        {pos: [10, 17, 3], state: "minecraft:deepslate_tiles"},
        {pos: [10, 17, 13], state: "minecraft:deepslate_tiles"},
        {pos: [10, 17, 14], state: "minecraft:deepslate_tiles"},
        {pos: [13, 17, 6], state: "minecraft:deepslate_tiles"},
        {pos: [14, 17, 6], state: "minecraft:deepslate_tiles"},
        {pos: [14, 17, 10], state: "minecraft:deepslate_tiles"},
        {pos: [3, 18, 6], state: "minecraft:deepslate_tiles"},
        {pos: [4, 18, 6], state: "minecraft:deepslate_tiles"},
        {pos: [5, 18, 6], state: "minecraft:deepslate_tiles"},
        {pos: [6, 18, 3], state: "minecraft:deepslate_tiles"},
        {pos: [6, 18, 4], state: "minecraft:deepslate_tiles"},
        {pos: [6, 18, 5], state: "minecraft:deepslate_tiles"},
        {pos: [6, 18, 6], state: "minecraft:deepslate_tiles"},
        {pos: [6, 18, 7], state: "minecraft:deepslate_tiles"},
        {pos: [6, 18, 8], state: "minecraft:deepslate_tiles"},
        {pos: [6, 18, 9], state: "minecraft:deepslate_tiles"},
        {pos: [6, 18, 10], state: "minecraft:deepslate_tiles"},
        {pos: [6, 18, 11], state: "minecraft:deepslate_tiles"},
        {pos: [6, 18, 12], state: "minecraft:deepslate_tiles"},
        {pos: [6, 18, 13], state: "minecraft:deepslate_tiles"},
        {pos: [7, 18, 6], state: "minecraft:deepslate_tiles"},
        {pos: [7, 18, 10], state: "minecraft:deepslate_tiles"},
        {pos: [8, 18, 6], state: "minecraft:deepslate_tiles"},
        {pos: [8, 18, 10], state: "minecraft:deepslate_tiles"},
        {pos: [9, 18, 6], state: "minecraft:deepslate_tiles"},
        {pos: [9, 18, 10], state: "minecraft:deepslate_tiles"},
        {pos: [10, 18, 3], state: "minecraft:deepslate_tiles"},
        {pos: [10, 18, 4], state: "minecraft:deepslate_tiles"},
        {pos: [10, 18, 5], state: "minecraft:deepslate_tiles"},
        {pos: [10, 18, 6], state: "minecraft:deepslate_tiles"},
        {pos: [10, 18, 7], state: "minecraft:deepslate_tiles"},
        {pos: [10, 18, 8], state: "minecraft:deepslate_tiles"},
        {pos: [10, 18, 9], state: "minecraft:deepslate_tiles"},
        {pos: [10, 18, 10], state: "minecraft:deepslate_tiles"},
        {pos: [10, 18, 11], state: "minecraft:deepslate_tiles"},
        {pos: [10, 18, 12], state: "minecraft:deepslate_tiles"},
        {pos: [10, 18, 13], state: "minecraft:deepslate_tiles"},
        {pos: [11, 18, 6], state: "minecraft:deepslate_tiles"},
        {pos: [11, 18, 10], state: "minecraft:deepslate_tiles"},
        {pos: [12, 18, 6], state: "minecraft:deepslate_tiles"},
        {pos: [12, 18, 10], state: "minecraft:deepslate_tiles"},
        {pos: [13, 18, 6], state: "minecraft:deepslate_tiles"},
        {pos: [13, 18, 10], state: "minecraft:deepslate_tiles"},
        {pos: [3, 0, 5], state: "minecraft:deepslate_tile_stairs{half:bottom,waterlogged:false,shape:outer_right,facing:east}"},
        {pos: [3, 0, 6], state: "minecraft:deepslate_tile_stairs{half:bottom,waterlogged:false,shape:straight,facing:east}"},
        {pos: [3, 0, 7], state: "minecraft:deepslate_tile_stairs{half:bottom,waterlogged:false,shape:straight,facing:east}"},
        {pos: [3, 0, 8], state: "minecraft:deepslate_tile_stairs{half:bottom,waterlogged:false,shape:straight,facing:east}"},
        {pos: [3, 0, 9], state: "minecraft:deepslate_tile_stairs{half:bottom,waterlogged:false,shape:straight,facing:east}"},
        {pos: [3, 0, 10], state: "minecraft:deepslate_tile_stairs{half:bottom,waterlogged:false,shape:straight,facing:east}"},
        {pos: [3, 0, 11], state: "minecraft:deepslate_tile_stairs{half:bottom,waterlogged:false,shape:outer_right,facing:north}"},
        {pos: [4, 0, 4], state: "minecraft:deepslate_tile_stairs{half:bottom,waterlogged:false,shape:outer_right,facing:east}"},
        {pos: [4, 0, 5], state: "minecraft:deepslate_tile_stairs{half:bottom,waterlogged:false,shape:inner_left,facing:south}"},
        {pos: [4, 0, 11], state: "minecraft:deepslate_tile_stairs{half:bottom,waterlogged:false,shape:inner_left,facing:east}"},
        {pos: [4, 0, 12], state: "minecraft:deepslate_tile_stairs{half:bottom,waterlogged:false,shape:outer_right,facing:north}"},
        {pos: [5, 0, 3], state: "minecraft:deepslate_tile_stairs{half:bottom,waterlogged:false,shape:outer_right,facing:east}"},
        {pos: [5, 0, 4], state: "minecraft:deepslate_tile_stairs{half:bottom,waterlogged:false,shape:inner_left,facing:south}"},
        {pos: [5, 0, 12], state: "minecraft:deepslate_tile_stairs{half:bottom,waterlogged:false,shape:inner_left,facing:east}"},
        {pos: [5, 0, 13], state: "minecraft:deepslate_tile_stairs{half:bottom,waterlogged:false,shape:outer_right,facing:north}"},
        {pos: [6, 0, 3], state: "minecraft:deepslate_tile_stairs{half:bottom,waterlogged:false,shape:straight,facing:south}"},
        {pos: [6, 0, 13], state: "minecraft:deepslate_tile_stairs{half:bottom,waterlogged:false,shape:straight,facing:north}"},
        {pos: [7, 0, 3], state: "minecraft:deepslate_tile_stairs{half:bottom,waterlogged:false,shape:straight,facing:south}"},
        {pos: [7, 0, 13], state: "minecraft:deepslate_tile_stairs{half:bottom,waterlogged:false,shape:straight,facing:north}"},
        {pos: [8, 0, 3], state: "minecraft:deepslate_tile_stairs{half:bottom,waterlogged:false,shape:straight,facing:south}"},
        {pos: [8, 0, 13], state: "minecraft:deepslate_tile_stairs{half:bottom,waterlogged:false,shape:straight,facing:north}"},
        {pos: [9, 0, 3], state: "minecraft:deepslate_tile_stairs{half:bottom,waterlogged:false,shape:straight,facing:south}"},
        {pos: [10, 0, 3], state: "minecraft:deepslate_tile_stairs{half:bottom,waterlogged:false,shape:straight,facing:south}"},
        {pos: [10, 0, 13], state: "minecraft:deepslate_tile_stairs{half:bottom,waterlogged:false,shape:straight,facing:north}"},
        {pos: [11, 0, 3], state: "minecraft:deepslate_tile_stairs{half:bottom,waterlogged:false,shape:outer_right,facing:south}"},
        {pos: [11, 0, 4], state: "minecraft:deepslate_tile_stairs{half:bottom,waterlogged:false,shape:inner_left,facing:west}"},
        {pos: [11, 0, 12], state: "minecraft:deepslate_tile_stairs{half:bottom,waterlogged:false,shape:straight,facing:north}"},
        {pos: [12, 0, 4], state: "minecraft:deepslate_tile_stairs{half:bottom,waterlogged:false,shape:outer_right,facing:south}"},
        {pos: [12, 0, 5], state: "minecraft:deepslate_tile_stairs{half:bottom,waterlogged:false,shape:inner_left,facing:west}"},
        {pos: [12, 0, 11], state: "minecraft:deepslate_tile_stairs{half:bottom,waterlogged:false,shape:inner_left,facing:north}"},
        {pos: [12, 0, 12], state: "minecraft:deepslate_tile_stairs{half:bottom,waterlogged:false,shape:outer_right,facing:west}"},
        {pos: [13, 0, 5], state: "minecraft:deepslate_tile_stairs{half:bottom,waterlogged:false,shape:outer_right,facing:south}"},
        {pos: [13, 0, 6], state: "minecraft:deepslate_tile_stairs{half:bottom,waterlogged:false,shape:straight,facing:west}"},
        {pos: [11, 7, 6], state: "minecraft:ladder{waterlogged:false,facing:south}"},
        {pos: [6, 8, 3], state: "minecraft:polished_deepslate_wall{east:none,waterlogged:false,south:none,north:none,west:none,up:true}"},
        {pos: [10, 8, 3], state: "minecraft:polished_deepslate_wall{east:none,waterlogged:false,south:none,north:none,west:none,up:true}"},
        {pos: [13, 8, 6], state: "minecraft:polished_deepslate_wall{east:none,waterlogged:false,south:none,north:none,west:none,up:true}"},
        {pos: [13, 8, 10], state: "minecraft:polished_deepslate_wall{east:none,waterlogged:false,south:none,north:none,west:none,up:true}"},
        {pos: [6, 9, 3], state: "minecraft:polished_deepslate_wall{east:none,waterlogged:false,south:none,north:none,west:none,up:true}"},
        {pos: [10, 9, 3], state: "minecraft:polished_deepslate_wall{east:none,waterlogged:false,south:none,north:none,west:none,up:true}"},
        {pos: [13, 9, 6], state: "minecraft:polished_deepslate_wall{east:none,waterlogged:false,south:none,north:none,west:none,up:true}"},
        {pos: [13, 9, 10], state: "minecraft:polished_deepslate_wall{east:none,waterlogged:false,south:none,north:none,west:none,up:true}"},
        {pos: [6, 10, 3], state: "minecraft:polished_deepslate_wall{east:none,waterlogged:false,south:none,north:none,west:none,up:true}"},
        {pos: [10, 10, 3], state: "minecraft:polished_deepslate_wall{east:none,waterlogged:false,south:none,north:none,west:none,up:true}"},
        {pos: [13, 10, 6], state: "minecraft:polished_deepslate_wall{east:none,waterlogged:false,south:none,north:none,west:none,up:true}"},
        {pos: [13, 10, 10], state: "minecraft:polished_deepslate_wall{east:none,waterlogged:false,south:none,north:none,west:none,up:true}"},
        {pos: [6, 11, 3], state: "minecraft:polished_deepslate_wall{east:none,waterlogged:false,south:none,north:none,west:none,up:true}"},
        {pos: [10, 11, 3], state: "minecraft:polished_deepslate_wall{east:none,waterlogged:false,south:none,north:none,west:none,up:true}"},
        {pos: [13, 11, 6], state: "minecraft:polished_deepslate_wall{east:none,waterlogged:false,south:none,north:none,west:none,up:true}"},
        {pos: [13, 11, 10], state: "minecraft:polished_deepslate_wall{east:none,waterlogged:false,south:none,north:none,west:none,up:true}"},
        {pos: [6, 12, 3], state: "minecraft:polished_deepslate_wall{east:none,waterlogged:false,south:none,north:none,west:none,up:true}"},
        {pos: [10, 12, 3], state: "minecraft:polished_deepslate_wall{east:none,waterlogged:false,south:none,north:none,west:none,up:true}"},
        {pos: [10, 12, 13], state: "minecraft:polished_deepslate_wall{east:none,waterlogged:false,south:none,north:none,west:none,up:true}"},
        {pos: [13, 12, 6], state: "minecraft:polished_deepslate_wall{east:none,waterlogged:false,south:none,north:none,west:none,up:true}"},
        {pos: [13, 12, 10], state: "minecraft:polished_deepslate_wall{east:none,waterlogged:false,south:none,north:none,west:none,up:true}"},
        {pos: [8, 13, 4], state: "minecraft:deepslate_tile_slab{waterlogged:false,type:top}"},
        {pos: [9, 13, 4], state: "minecraft:deepslate_tile_slab{waterlogged:false,type:top}"},
        {pos: [9, 13, 5], state: "minecraft:deepslate_tile_slab{waterlogged:false,type:top}"},
        {pos: [9, 13, 7], state: "minecraft:deepslate_tile_slab{waterlogged:false,type:top}"},
        {pos: [9, 13, 9], state: "minecraft:deepslate_tile_slab{waterlogged:false,type:top}"},
        {pos: [9, 13, 11], state: "minecraft:deepslate_tile_slab{waterlogged:false,type:top}"},
        {pos: [9, 13, 12], state: "minecraft:deepslate_tile_slab{waterlogged:false,type:top}"},
        {pos: [11, 13, 4], state: "minecraft:deepslate_tile_slab{waterlogged:false,type:top}"},
        {pos: [11, 13, 7], state: "minecraft:deepslate_tile_slab{waterlogged:false,type:top}"},
        {pos: [11, 13, 12], state: "minecraft:deepslate_tile_slab{waterlogged:false,type:top}"},
        {pos: [12, 13, 5], state: "minecraft:deepslate_tile_slab{waterlogged:false,type:top}"},
        {pos: [12, 13, 7], state: "minecraft:deepslate_tile_slab{waterlogged:false,type:top}"},
        {pos: [3, 14, 5], state: "minecraft:deepslate_tile_slab{waterlogged:false,type:top}"},
        {pos: [11, 14, 3], state: "minecraft:deepslate_tile_slab{waterlogged:false,type:top}"},
        {pos: [12, 14, 4], state: "minecraft:deepslate_tile_slab{waterlogged:false,type:top}"},
        {pos: [13, 14, 5], state: "minecraft:deepslate_tile_slab{waterlogged:false,type:top}"},
        {pos: [2, 15, 5], state: "minecraft:deepslate_tile_slab{waterlogged:false,type:top}"},
        {pos: [3, 15, 4], state: "minecraft:deepslate_tile_slab{waterlogged:false,type:top}"},
        {pos: [5, 15, 2], state: "minecraft:deepslate_tile_slab{waterlogged:false,type:top}"},
        {pos: [8, 15, 14], state: "minecraft:deepslate_tile_slab{waterlogged:false,type:top}"},
        {pos: [9, 15, 14], state: "minecraft:deepslate_tile_slab{waterlogged:false,type:top}"},
        {pos: [11, 15, 2], state: "minecraft:deepslate_tile_slab{waterlogged:false,type:top}"},
        {pos: [11, 15, 14], state: "minecraft:deepslate_tile_slab{waterlogged:false,type:top}"},
        {pos: [12, 15, 3], state: "minecraft:deepslate_tile_slab{waterlogged:false,type:top}"},
        {pos: [12, 15, 13], state: "minecraft:deepslate_tile_slab{waterlogged:false,type:top}"},
        {pos: [13, 15, 4], state: "minecraft:deepslate_tile_slab{waterlogged:false,type:top}"},
        {pos: [14, 15, 5], state: "minecraft:deepslate_tile_slab{waterlogged:false,type:top}"},
        {pos: [14, 15, 7], state: "minecraft:deepslate_tile_slab{waterlogged:false,type:top}"},
        {pos: [14, 15, 8], state: "minecraft:deepslate_tile_slab{waterlogged:false,type:top}"},
        {pos: [14, 15, 9], state: "minecraft:deepslate_tile_slab{waterlogged:false,type:top}"},
        {pos: [6, 17, 6], state: "minecraft:deepslate_tile_wall{east:none,waterlogged:false,south:none,north:none,west:none,up:true}"},
        {pos: [10, 17, 6], state: "minecraft:deepslate_tile_wall{east:none,waterlogged:false,south:none,north:none,west:none,up:true}"},
        {pos: [8, 0, 16], state: "minecraft:jigsaw{orientation:south_up}", nbt: {final_state: "minecraft:air", id: "minecraft:jigsaw", joint: "rollable", name: "minecraft:connect_structure", pool: "minecraft:empty", target: "minecraft:empty"}},
        {pos: [10, 14, 7], state: "minecraft:chest{waterlogged:false,facing:south,type:single}", nbt: {LootTable: "minecraft:chests/ancient_city", id: "minecraft:chest"}}
    ],
    entities: [],
    palette: [
        "minecraft:deepslate_tiles",
        "minecraft:deepslate_bricks",
        "minecraft:deepslate_tile_stairs{half:bottom,waterlogged:false,shape:outer_right,facing:east}",
        "minecraft:deepslate_tile_stairs{half:bottom,waterlogged:false,shape:straight,facing:east}",
        "minecraft:deepslate_tile_stairs{half:bottom,waterlogged:false,shape:outer_right,facing:north}",
        "minecraft:deepslate_tile_stairs{half:bottom,waterlogged:false,shape:inner_left,facing:south}",
        "minecraft:deepslate_tile_stairs{half:bottom,waterlogged:false,shape:inner_left,facing:east}",
        "minecraft:deepslate_tile_stairs{half:bottom,waterlogged:false,shape:straight,facing:south}",
        "minecraft:deepslate_tile_stairs{half:bottom,waterlogged:false,shape:straight,facing:north}",
        "minecraft:deepslate_tile_stairs{half:bottom,waterlogged:false,shape:outer_right,facing:south}",
        "minecraft:deepslate_tile_stairs{half:bottom,waterlogged:false,shape:inner_left,facing:west}",
        "minecraft:deepslate_tile_stairs{half:bottom,waterlogged:false,shape:inner_left,facing:north}",
        "minecraft:deepslate_tile_stairs{half:bottom,waterlogged:false,shape:outer_right,facing:west}",
        "minecraft:deepslate_tile_stairs{half:bottom,waterlogged:false,shape:straight,facing:west}",
        "minecraft:ladder{waterlogged:false,facing:south}",
        "minecraft:polished_deepslate_wall{east:none,waterlogged:false,south:none,north:none,west:none,up:true}",
        "minecraft:deepslate_tile_slab{waterlogged:false,type:top}",
        "minecraft:deepslate_tile_wall{east:none,waterlogged:false,south:none,north:none,west:none,up:true}",
        "minecraft:jigsaw{orientation:south_up}",
        "minecraft:chest{waterlogged:false,facing:south,type:single}"
    ]
}