{
    size: [17, 23, 17],
    data: [
        {pos: [4, 0, 6], state: "minecraft:deepslate_tiles"},
        {pos: [4, 0, 7], state: "minecraft:deepslate_bricks"},
        {pos: [4, 0, 8], state: "minecraft:deepslate_bricks"},
        {pos: [4, 0, 9], state: "minecraft:deepslate_bricks"},
        {pos: [4, 0, 10], state: "minecraft:deepslate_tiles"},
        {pos: [5, 0, 5], state: "minecraft:polished_basalt{axis:y}"},
        {pos: [5, 0, 6], state: "minecraft:deepslate_bricks"},
        {pos: [5, 0, 7], state: "minecraft:deepslate_bricks"},
        {pos: [5, 0, 8], state: "minecraft:deepslate_bricks"},
        {pos: [5, 0, 9], state: "minecraft:deepslate_bricks"},
        {pos: [5, 0, 10], state: "minecraft:deepslate_bricks"},
        {pos: [5, 0, 11], state: "minecraft:polished_basalt{axis:y}"},
        {pos: [6, 0, 4], state: "minecraft:deepslate_tiles"},
        {pos: [6, 0, 5], state: "minecraft:deepslate_bricks"},
        {pos: [6, 0, 6], state: "minecraft:deepslate_bricks"},
        {pos: [6, 0, 7], state: "minecraft:deepslate_tiles"},
        {pos: [6, 0, 8], state: "minecraft:deepslate_tiles"},
        {pos: [6, 0, 9], state: "minecraft:deepslate_tiles"},
        {pos: [6, 0, 10], state: "minecraft:deepslate_bricks"},
        {pos: [6, 0, 11], state: "minecraft:deepslate_bricks"},
        {pos: [6, 0, 12], state: "minecraft:deepslate_tiles"},
        {pos: [7, 0, 4], state: "minecraft:deepslate_bricks"},
        {pos: [7, 0, 5], state: "minecraft:deepslate_bricks"},
        {pos: [7, 0, 6], state: "minecraft:deepslate_tiles"},
        {pos: [7, 0, 7], state: "minecraft:deepslate_tiles"},
        {pos: [7, 0, 8], state: "minecraft:deepslate_tiles"},
        {pos: [7, 0, 9], state: "minecraft:deepslate_tiles"},
        {pos: [7, 0, 10], state: "minecraft:deepslate_tiles"},
        {pos: [7, 0, 11], state: "minecraft:deepslate_bricks"},
        {pos: [7, 0, 12], state: "minecraft:deepslate_bricks"},
        {pos: [8, 0, 4], state: "minecraft:deepslate_bricks"},
        {pos: [8, 0, 5], state: "minecraft:deepslate_bricks"},
        {pos: [8, 0, 6], state: "minecraft:deepslate_tiles"},
        {pos: [8, 0, 7], state: "minecraft:deepslate_tiles"},
        {pos: [8, 0, 8], state: "minecraft:deepslate_tiles"},
        {pos: [8, 0, 9], state: "minecraft:deepslate_tiles"},
        {pos: [8, 0, 10], state: "minecraft:deepslate_tiles"},
        {pos: [8, 0, 11], state: "minecraft:deepslate_bricks"},
        {pos: [8, 0, 12], state: "minecraft:deepslate_bricks"},
        {pos: [9, 0, 4], state: "minecraft:deepslate_bricks"},
        {pos: [9, 0, 5], state: "minecraft:deepslate_bricks"},
        {pos: [9, 0, 6], state: "minecraft:deepslate_tiles"},
        {pos: [9, 0, 7], state: "minecraft:deepslate_tiles"},
        {pos: [9, 0, 8], state: "minecraft:deepslate_tiles"},
        {pos: [9, 0, 9], state: "minecraft:deepslate_tiles"},
        {pos: [9, 0, 10], state: "minecraft:deepslate_tiles"},
        {pos: [9, 0, 11], state: "minecraft:deepslate_bricks"},
        {pos: [9, 0, 12], state: "minecraft:deepslate_bricks"},
        {pos: [10, 0, 4], state: "minecraft:deepslate_bricks"},
        {pos: [10, 0, 5], state: "minecraft:deepslate_bricks"},
        {pos: [10, 0, 6], state: "minecraft:deepslate_bricks"},
        {pos: [10, 0, 7], state: "minecraft:deepslate_tiles"},
        {pos: [10, 0, 8], state: "minecraft:deepslate_tiles"},
        {pos: [10, 0, 9], state: "minecraft:deepslate_tiles"},
        {pos: [10, 0, 10], state: "minecraft:deepslate_bricks"},
        {pos: [10, 0, 11], state: "minecraft:deepslate_bricks"},
        {pos: [10, 0, 12], state: "minecraft:deepslate_tiles"},
        {pos: [11, 0, 5], state: "minecraft:polished_basalt{axis:y}"},
        {pos: [11, 0, 6], state: "minecraft:deepslate_bricks"},
        {pos: [11, 0, 7], state: "minecraft:deepslate_bricks"},
        {pos: [11, 0, 8], state: "minecraft:deepslate_bricks"},
        {pos: [11, 0, 9], state: "minecraft:deepslate_bricks"},
        {pos: [11, 0, 10], state: "minecraft:deepslate_bricks"},
        {pos: [11, 0, 11], state: "minecraft:polished_basalt{axis:y}"},
        {pos: [12, 0, 6], state: "minecraft:deepslate_tiles"},
        {pos: [12, 0, 7], state: "minecraft:deepslate_bricks"},
        {pos: [12, 0, 8], state: "minecraft:deepslate_bricks"},
        {pos: [12, 0, 9], state: "minecraft:deepslate_bricks"},
        {pos: [12, 0, 10], state: "minecraft:deepslate_tiles"},
        {pos: [5, 1, 5], state: "minecraft:polished_basalt{axis:y}"},
        {pos: [5, 1, 11], state: "minecraft:polished_basalt{axis:y}"},
        {pos: [6, 1, 6], state: "minecraft:deepslate_tiles"},
        {pos: [6, 1, 10], state: "minecraft:deepslate_tiles"},
        {pos: [10, 1, 6], state: "minecraft:deepslate_tiles"},
        {pos: [10, 1, 10], state: "minecraft:deepslate_bricks"},
        {pos: [11, 1, 5], state: "minecraft:polished_basalt{axis:y}"},
        {pos: [11, 1, 11], state: "minecraft:polished_basalt{axis:y}"},
        {pos: [5, 2, 5], state: "minecraft:polished_basalt{axis:y}"},
        {pos: [5, 2, 11], state: "minecraft:polished_basalt{axis:y}"},
        {pos: [6, 2, 6], state: "minecraft:deepslate_tiles"},
        {pos: [6, 2, 10], state: "minecraft:deepslate_tiles"},
        {pos: [10, 2, 6], state: "minecraft:deepslate_tiles"},
        {pos: [10, 2, 10], state: "minecraft:deepslate_tiles"},
        {pos: [11, 2, 5], state: "minecraft:polished_basalt{axis:y}"},
        {pos: [11, 2, 11], state: "minecraft:polished_basalt{axis:y}"},
        {pos: [5, 3, 5], state: "minecraft:polished_basalt{axis:y}"},
        {pos: [5, 3, 11], state: "minecraft:polished_basalt{axis:y}"},
        {pos: [6, 3, 6], state: "minecraft:deepslate_tiles"},
        {pos: [6, 3, 10], state: "minecraft:deepslate_tiles"},
        {pos: [10, 3, 6], state: "minecraft:deepslate_tiles"},
        {pos: [10, 3, 10], state: "minecraft:deepslate_tiles"},
        {pos: [11, 3, 5], state: "minecraft:polished_basalt{axis:y}"},
        {pos: [11, 3, 11], state: "minecraft:polished_basalt{axis:y}"},
        {pos: [5, 4, 5], state: "minecraft:polished_basalt{axis:y}"},
        {pos: [5, 4, 11], state: "minecraft:polished_basalt{axis:y}"},
        {pos: [6, 4, 6], state: "minecraft:deepslate_tiles"},
        {pos: [6, 4, 10], state: "minecraft:deepslate_tiles"},
        {pos: [10, 4, 6], state: "minecraft:deepslate_tiles"},
        {pos: [10, 4, 10], state: "minecraft:deepslate_tiles"},
        {pos: [11, 4, 5], state: "minecraft:polished_basalt{axis:y}"},
        {pos: [11, 4, 11], state: "minecraft:polished_basalt{axis:y}"},
        {pos: [5, 5, 5], state: "minecraft:polished_basalt{axis:y}"},
        {pos: [5, 5, 11], state: "minecraft:polished_basalt{axis:y}"},
        {pos: [6, 5, 6], state: "minecraft:deepslate_tiles"},
        {pos: [6, 5, 10], state: "minecraft:deepslate_tiles"},
        {pos: [10, 5, 6], state: "minecraft:deepslate_tiles"},
        {pos: [10, 5, 10], state: "minecraft:deepslate_tiles"},
        {pos: [11, 5, 5], state: "minecraft:polished_basalt{axis:y}"},
        {pos: [11, 5, 11], state: "minecraft:polished_basalt{axis:y}"},
        {pos: [5, 6, 5], state: "minecraft:polished_basalt{axis:y}"},
        {pos: [5, 6, 11], state: "minecraft:polished_basalt{axis:y}"},
        {pos: [6, 6, 6], state: "minecraft:deepslate_tiles"},
        {pos: [6, 6, 10], state: "minecraft:deepslate_tiles"},
        {pos: [10, 6, 6], state: "minecraft:deepslate_tiles"},
        {pos: [10, 6, 10], state: "minecraft:deepslate_tiles"},
        {pos: [11, 6, 5], state: "minecraft:polished_basalt{axis:y}"},
        {pos: [11, 6, 11], state: "minecraft:polished_basalt{axis:y}"},
        {pos: [3, 7, 6], state: "minecraft:deepslate_bricks"},
        {pos: [3, 7, 7], state: "minecraft:deepslate_bricks"},
        {pos: [3, 7, 8], state: "minecraft:deepslate_bricks"},
        {pos: [3, 7, 9], state: "minecraft:deepslate_bricks"},
        {pos: [3, 7, 10], state: "minecraft:deepslate_bricks"},
        {pos: [4, 7, 5], state: "minecraft:deepslate_bricks"},
        {pos: [4, 7, 6], state: "minecraft:deepslate_bricks"},
        {pos: [4, 7, 7], state: "minecraft:deepslate_bricks"},
        {pos: [4, 7, 8], state: "minecraft:deepslate_bricks"},
        {pos: [4, 7, 9], state: "minecraft:deepslate_bricks"},
        {pos: [4, 7, 10], state: "minecraft:deepslate_bricks"},
        {pos: [4, 7, 11], state: "minecraft:deepslate_bricks"},
        {pos: [5, 7, 4], state: "minecraft:deepslate_bricks"},
        {pos: [5, 7, 5], state: "minecraft:polished_basalt{axis:y}"},
        {pos: [5, 7, 7], state: "minecraft:deepslate_bricks"},
        {pos: [5, 7, 8], state: "minecraft:deepslate_bricks"},
        {pos: [5, 7, 9], state: "minecraft:deepslate_bricks"},
        {pos: [5, 7, 11], state: "minecraft:polished_basalt{axis:y}"},
        {pos: [5, 7, 12], state: "minecraft:deepslate_bricks"},
        {pos: [6, 7, 3], state: "minecraft:deepslate_bricks"},
        {pos: [6, 7, 4], state: "minecraft:deepslate_bricks"},
        {pos: [6, 7, 6], state: "minecraft:deepslate_bricks"},
        {pos: [6, 7, 7], state: "minecraft:deepslate_bricks"},
        {pos: [6, 7, 8], state: "minecraft:deepslate_bricks"},
        {pos: [6, 7, 9], state: "minecraft:deepslate_bricks"},
        {pos: [6, 7, 10], state: "minecraft:deepslate_bricks"},
        {pos: [6, 7, 12], state: "minecraft:deepslate_bricks"},
        {pos: [6, 7, 13], state: "minecraft:deepslate_bricks"},
        {pos: [7, 7, 3], state: "minecraft:deepslate_bricks"},
        {pos: [7, 7, 4], state: "minecraft:deepslate_bricks"},
        {pos: [7, 7, 5], state: "minecraft:deepslate_bricks"},
        {pos: [7, 7, 6], state: "minecraft:deepslate_bricks"},
        {pos: [7, 7, 7], state: "minecraft:deepslate_bricks"},
        {pos: [7, 7, 8], state: "minecraft:deepslate_bricks"},
        {pos: [7, 7, 9], state: "minecraft:deepslate_bricks"},
        {pos: [7, 7, 10], state: "minecraft:deepslate_bricks"},
        {pos: [7, 7, 11], state: "minecraft:deepslate_bricks"},
        {pos: [7, 7, 12], state: "minecraft:deepslate_bricks"},
        {pos: [7, 7, 13], state: "minecraft:deepslate_bricks"},
        {pos: [8, 7, 3], state: "minecraft:deepslate_bricks"},
        {pos: [8, 7, 4], state: "minecraft:deepslate_bricks"},
        {pos: [8, 7, 5], state: "minecraft:deepslate_bricks"},
        {pos: [8, 7, 6], state: "minecraft:deepslate_bricks"},
        {pos: [8, 7, 7], state: "minecraft:deepslate_bricks"},
        {pos: [8, 7, 8], state: "minecraft:deepslate_bricks"},
        {pos: [8, 7, 9], state: "minecraft:deepslate_bricks"},
        {pos: [8, 7, 10], state: "minecraft:deepslate_bricks"},
        {pos: [8, 7, 11], state: "minecraft:deepslate_bricks"},
        {pos: [8, 7, 12], state: "minecraft:deepslate_bricks"},
        {pos: [8, 7, 13], state: "minecraft:deepslate_bricks"},
        {pos: [9, 7, 3], state: "minecraft:deepslate_bricks"},
        {pos: [9, 7, 4], state: "minecraft:deepslate_bricks"},
        {pos: [9, 7, 5], state: "minecraft:deepslate_bricks"},
        {pos: [9, 7, 6], state: "minecraft:deepslate_bricks"},
        {pos: [9, 7, 7], state: "minecraft:deepslate_bricks"},
        {pos: [9, 7, 8], state: "minecraft:deepslate_bricks"},
        {pos: [9, 7, 9], state: "minecraft:deepslate_bricks"},
        {pos: [9, 7, 10], state: "minecraft:deepslate_bricks"},
        {pos: [9, 7, 11], state: "minecraft:deepslate_bricks"},
        {pos: [9, 7, 12], state: "minecraft:deepslate_bricks"},
        {pos: [9, 7, 13], state: "minecraft:deepslate_bricks"},
        {pos: [10, 7, 3], state: "minecraft:deepslate_bricks"},
        {pos: [10, 7, 4], state: "minecraft:deepslate_bricks"},
        {pos: [10, 7, 6], state: "minecraft:deepslate_bricks"},
        {pos: [10, 7, 7], state: "minecraft:deepslate_bricks"},
        {pos: [10, 7, 8], state: "minecraft:deepslate_bricks"},
        {pos: [10, 7, 9], state: "minecraft:deepslate_bricks"},
        {pos: [10, 7, 10], state: "minecraft:deepslate_bricks"},
        {pos: [10, 7, 12], state: "minecraft:deepslate_bricks"},
        {pos: [10, 7, 13], state: "minecraft:deepslate_bricks"},
        {pos: [11, 7, 4], state: "minecraft:deepslate_bricks"},
        {pos: [11, 7, 5], state: "minecraft:polished_basalt{axis:y}"},
        {pos: [11, 7, 7], state: "minecraft:deepslate_bricks"},
        {pos: [11, 7, 8], state: "minecraft:deepslate_bricks"},
        {pos: [11, 7, 9], state: "minecraft:deepslate_bricks"},
        {pos: [11, 7, 11], state: "minecraft:polished_basalt{axis:y}"},
        {pos: [11, 7, 12], state: "minecraft:deepslate_bricks"},
        {pos: [12, 7, 5], state: "minecraft:deepslate_bricks"},
        {pos: [12, 7, 6], state: "minecraft:deepslate_bricks"},
        {pos: [12, 7, 7], state: "minecraft:deepslate_bricks"},
        {pos: [12, 7, 8], state: "minecraft:deepslate_bricks"},
        {pos: [12, 7, 9], state: "minecraft:deepslate_bricks"},
        {pos: [12, 7, 10], state: "minecraft:deepslate_bricks"},
        {pos: [12, 7, 11], state: "minecraft:deepslate_bricks"},
        {pos: [13, 7, 6], state: "minecraft:deepslate_bricks"},
        {pos: [13, 7, 7], state: "minecraft:deepslate_bricks"},
        {pos: [13, 7, 8], state: "minecraft:deepslate_bricks"},
        {pos: [13, 7, 9], state: "minecraft:deepslate_bricks"},
        {pos: [13, 7, 10], state: "minecraft:deepslate_bricks"},
        {pos: [5, 8, 5], state: "minecraft:polished_basalt{axis:y}"},
        {pos: [5, 8, 11], state: "minecraft:polished_basalt{axis:y}"},
        {pos: [8, 8, 8], state: "minecraft:polished_basalt{axis:y}"},
        {pos: [11, 8, 5], state: "minecraft:polished_basalt{axis:y}"},
        {pos: [11, 8, 11], state: "minecraft:polished_basalt{axis:y}"},
        {pos: [5, 9, 5], state: "minecraft:chiseled_deepslate"},
        {pos: [5, 9, 11], state: "minecraft:chiseled_deepslate"},
        {pos: [8, 9, 8], state: "minecraft:polished_basalt{axis:y}"},
        {pos: [11, 9, 5], state: "minecraft:chiseled_deepslate"},
        {pos: [11, 9, 11], state: "minecraft:chiseled_deepslate"},
        {pos: [8, 10, 8], state: "minecraft:polished_basalt{axis:y}"},
        {pos: [8, 11, 8], state: "minecraft:polished_basalt{axis:y}"},
        {pos: [8, 12, 8], state: "minecraft:polished_basalt{axis:y}"},
        {pos: [3, 13, 6], state: "minecraft:deepslate_tiles"},
        {pos: [3, 13, 10], state: "minecraft:deepslate_tiles"},
        {pos: [4, 13, 6], state: "minecraft:deepslate_tiles"},
        {pos: [4, 13, 10], state: "minecraft:deepslate_tiles"},
        {pos: [5, 13, 5], state: "minecraft:deepslate_tiles"},
        {pos: [5, 13, 6], state: "minecraft:deepslate_tiles"},
        {pos: [5, 13, 10], state: "minecraft:deepslate_tiles"},
        {pos: [5, 13, 11], state: "minecraft:deepslate_tiles"},
        {pos: [6, 13, 3], state: "minecraft:deepslate_tiles"},
        {pos: [6, 13, 4], state: "minecraft:deepslate_tiles"},
        {pos: [6, 13, 5], state: "minecraft:deepslate_tiles"},
        {pos: [6, 13, 6], state: "minecraft:deepslate_tiles"},
        {pos: [6, 13, 7], state: "minecraft:deepslate_tiles"},
        {pos: [6, 13, 8], state: "minecraft:deepslate_tiles"},
        {pos: [6, 13, 9], state: "minecraft:deepslate_tiles"},
        {pos: [6, 13, 10], state: "minecraft:deepslate_tiles"},
        {pos: [6, 13, 11], state: "minecraft:deepslate_tiles"},
        {pos: [6, 13, 12], state: "minecraft:deepslate_tiles"},
        {pos: [6, 13, 13], state: "minecraft:deepslate_tiles"},
        {pos: [7, 13, 6], state: "minecraft:deepslate_tiles"},
        {pos: [7, 13, 10], state: "minecraft:deepslate_tiles"},
        {pos: [8, 13, 6], state: "minecraft:deepslate_tiles"},
        {pos: [8, 13, 8], state: "minecraft:polished_basalt{axis:y}"},
        {pos: [8, 13, 10], state: "minecraft:deepslate_tiles"},
        {pos: [9, 13, 6], state: "minecraft:deepslate_tiles"},
        {pos: [9, 13, 10], state: "minecraft:deepslate_tiles"},
        {pos: [10, 13, 3], state: "minecraft:deepslate_tiles"},
        {pos: [10, 13, 4], state: "minecraft:deepslate_tiles"},
        {pos: [10, 13, 5], state: "minecraft:deepslate_tiles"},
        {pos: [10, 13, 6], state: "minecraft:deepslate_tiles"},
        {pos: [10, 13, 7], state: "minecraft:deepslate_tiles"},
        {pos: [10, 13, 8], state: "minecraft:deepslate_tiles"},
        {pos: [10, 13, 9], state: "minecraft:deepslate_tiles"},
        {pos: [10, 13, 10], state: "minecraft:deepslate_tiles"},
        {pos: [10, 13, 11], state: "minecraft:deepslate_tiles"},
        {pos: [10, 13, 12], state: "minecraft:deepslate_tiles"},
        {pos: [10, 13, 13], state: "minecraft:deepslate_tiles"},
        {pos: [11, 13, 5], state: "minecraft:deepslate_tiles"},
        {pos: [11, 13, 6], state: "minecraft:deepslate_tiles"},
        {pos: [11, 13, 10], state: "minecraft:deepslate_tiles"},
        {pos: [11, 13, 11], state: "minecraft:deepslate_tiles"},
        {pos: [12, 13, 6], state: "minecraft:deepslate_tiles"},
        {pos: [12, 13, 10], state: "minecraft:deepslate_tiles"},
        {pos: [13, 13, 6], state: "minecraft:deepslate_tiles"},
        {pos: [13, 13, 10], state: "minecraft:deepslate_tiles"},
        {pos: [2, 14, 6], state: "minecraft:deepslate_tiles"},
        {pos: [2, 14, 10], state: "minecraft:deepslate_tiles"},
        {pos: [3, 14, 6], state: "minecraft:deepslate_tiles"},
        {pos: [3, 14, 10], state: "minecraft:deepslate_tiles"},
        {pos: [6, 14, 2], state: "minecraft:deepslate_tiles"},
        {pos: [6, 14, 3], state: "minecraft:deepslate_tiles"},
        {pos: [6, 14, 13], state: "minecraft:deepslate_tiles"},
        {pos: [6, 14, 14], state: "minecraft:deepslate_tiles"},
        {pos: [8, 14, 8], state: "minecraft:polished_basalt{axis:y}"},
        {pos: [10, 14, 2], state: "minecraft:deepslate_tiles"},
        {pos: [10, 14, 3], state: "minecraft:deepslate_tiles"},
        {pos: [10, 14, 13], state: "minecraft:deepslate_tiles"},
        {pos: [10, 14, 14], state: "minecraft:deepslate_tiles"},
        {pos: [13, 14, 6], state: "minecraft:deepslate_tiles"},
        {pos: [13, 14, 10], state: "minecraft:deepslate_tiles"},
        {pos: [14, 14, 6], state: "minecraft:deepslate_tiles"},
        {pos: [14, 14, 10], state: "minecraft:deepslate_tiles"},
        {pos: [1, 15, 6], state: "minecraft:deepslate_tiles"},
        {pos: [1, 15, 10], state: "minecraft:deepslate_tiles"},
        {pos: [2, 15, 6], state: "minecraft:deepslate_tiles"},
        {pos: [2, 15, 10], state: "minecraft:deepslate_tiles"},
        {pos: [6, 15, 1], state: "minecraft:deepslate_tiles"},
        {pos: [6, 15, 2], state: "minecraft:deepslate_tiles"},
        {pos: [6, 15, 14], state: "minecraft:deepslate_tiles"},
        {pos: [6, 15, 15], state: "minecraft:deepslate_tiles"},
        {pos: [8, 15, 8], state: "minecraft:chiseled_deepslate"},
        {pos: [10, 15, 1], state: "minecraft:deepslate_tiles"},
        {pos: [10, 15, 2], state: "minecraft:deepslate_tiles"},
        {pos: [10, 15, 14], state: "minecraft:deepslate_tiles"},
        {pos: [10, 15, 15], state: "minecraft:deepslate_tiles"},
        {pos: [14, 15, 6], state: "minecraft:deepslate_tiles"},
        {pos: [14, 15, 10], state: "minecraft:deepslate_tiles"},
        {pos: [15, 15, 6], state: "minecraft:deepslate_tiles"},
        {pos: [15, 15, 10], state: "minecraft:deepslate_tiles"},
        {pos: [1, 16, 6], state: "minecraft:deepslate_tiles"},
        {pos: [1, 16, 10], state: "minecraft:deepslate_tiles"},
        {pos: [2, 16, 6], state: "minecraft:deepslate_tiles"},
        {pos: [2, 16, 10], state: "minecraft:deepslate_tiles"},
        {pos: [6, 16, 1], state: "minecraft:deepslate_tiles"},
        {pos: [6, 16, 2], state: "minecraft:deepslate_tiles"},
        {pos: [6, 16, 14], state: "minecraft:deepslate_tiles"},
        {pos: [6, 16, 15], state: "minecraft:deepslate_tiles"},
        {pos: [10, 16, 1], state: "minecraft:deepslate_tiles"},
        {pos: [10, 16, 2], state: "minecraft:deepslate_tiles"},
        {pos: [10, 16, 14], state: "minecraft:deepslate_tiles"},
        {pos: [10, 16, 15], state: "minecraft:deepslate_tiles"},
        {pos: [14, 16, 6], state: "minecraft:deepslate_tiles"},
        {pos: [14, 16, 10], state: "minecraft:deepslate_tiles"},
        {pos: [15, 16, 6], state: "minecraft:deepslate_tiles"},
        {pos: [15, 16, 10], state: "minecraft:deepslate_tiles"},
        {pos: [2, 17, 6], state: "minecraft:deepslate_tiles"},
        {pos: [2, 17, 10], state: "minecraft:deepslate_tiles"},
        {pos: [3, 17, 6], state: "minecraft:deepslate_tiles"},
        {pos: [3, 17, 10], state: "minecraft:deepslate_tiles"},
        {pos: [6, 17, 2], state: "minecraft:deepslate_tiles"},
        {pos: [6, 17, 3], state: "minecraft:deepslate_tiles"},
        {pos: [6, 17, 13], state: "minecraft:deepslate_tiles"},
        {pos: [6, 17, 14], state: "minecraft:deepslate_tiles"},
        {pos: [10, 17, 2], state: "minecraft:deepslate_tiles"},
        {pos: [10, 17, 3], state: "minecraft:deepslate_tiles"},
        {pos: [10, 17, 13], state: "minecraft:deepslate_tiles"},
        {pos: [10, 17, 14], state: "minecraft:deepslate_tiles"},
        {pos: [13, 17, 6], state: "minecraft:deepslate_tiles"},
        {pos: [13, 17, 10], state: "minecraft:deepslate_tiles"},
        {pos: [14, 17, 6], state: "minecraft:deepslate_tiles"},
        {pos: [14, 17, 10], state: "minecraft:deepslate_tiles"},
        {pos: [3, 18, 6], state: "minecraft:deepslate_tiles"},
        {pos: [3, 18, 10], state: "minecraft:deepslate_tiles"},
        {pos: [4, 18, 6], state: "minecraft:deepslate_tiles"},
        {pos: [4, 18, 10], state: "minecraft:deepslate_tiles"},
        {pos: [5, 18, 6], state: "minecraft:deepslate_tiles"},
        {pos: [5, 18, 10], state: "minecraft:deepslate_tiles"},
        {pos: [6, 18, 3], state: "minecraft:deepslate_tiles"},
        {pos: [6, 18, 4], state: "minecraft:deepslate_tiles"},
        {pos: [6, 18, 5], state: "minecraft:deepslate_tiles"},
        {pos: [6, 18, 6], state: "minecraft:deepslate_tiles"},
        {pos: [6, 18, 7], state: "minecraft:deepslate_tiles"},
        {pos: [6, 18, 8], state: "minecraft:deepslate_tiles"},
        {pos: [6, 18, 9], state: "minecraft:deepslate_tiles"},
        {pos: [6, 18, 10], state: "minecraft:deepslate_tiles"},
        {pos: [6, 18, 11], state: "minecraft:deepslate_tiles"},
        {pos: [6, 18, 12], state: "minecraft:deepslate_tiles"},
        {pos: [6, 18, 13], state: "minecraft:deepslate_tiles"},
        {pos: [7, 18, 6], state: "minecraft:deepslate_tiles"},
        {pos: [7, 18, 10], state: "minecraft:deepslate_tiles"},
        {pos: [8, 18, 6], state: "minecraft:deepslate_tiles"},
        {pos: [8, 18, 10], state: "minecraft:deepslate_tiles"},
        {pos: [9, 18, 6], state: "minecraft:deepslate_tiles"},
        {pos: [9, 18, 10], state: "minecraft:deepslate_tiles"},
        {pos: [10, 18, 3], state: "minecraft:deepslate_tiles"},
        {pos: [10, 18, 4], state: "minecraft:deepslate_tiles"},
        {pos: [10, 18, 5], state: "minecraft:deepslate_tiles"},
        {pos: [10, 18, 6], state: "minecraft:deepslate_tiles"},
        {pos: [10, 18, 7], state: "minecraft:deepslate_tiles"},
        {pos: [10, 18, 8], state: "minecraft:deepslate_tiles"},
        {pos: [10, 18, 9], state: "minecraft:deepslate_tiles"},
        {pos: [10, 18, 10], state: "minecraft:deepslate_tiles"},
        {pos: [10, 18, 11], state: "minecraft:deepslate_tiles"},
        {pos: [10, 18, 12], state: "minecraft:deepslate_tiles"},
        {pos: [10, 18, 13], state: "minecraft:deepslate_tiles"},
        {pos: [11, 18, 6], state: "minecraft:deepslate_tiles"},
        {pos: [11, 18, 10], state: "minecraft:deepslate_tiles"},
        {pos: [12, 18, 6], state: "minecraft:deepslate_tiles"},
        {pos: [12, 18, 10], state: "minecraft:deepslate_tiles"},
        {pos: [13, 18, 6], state: "minecraft:deepslate_tiles"},
        {pos: [13, 18, 10], state: "minecraft:deepslate_tiles"},
        {pos: [3, 0, 5], state: "minecraft:deepslate_tile_stairs{half:bottom,waterlogged:false,shape:outer_right,facing:east}"},
        {pos: [3, 0, 6], state: "minecraft:deepslate_tile_stairs{half:bottom,waterlogged:false,shape:straight,facing:east}"},
        {pos: [3, 0, 7], state: "minecraft:deepslate_tile_stairs{half:bottom,waterlogged:false,shape:straight,facing:east}"},
        {pos: [3, 0, 8], state: "minecraft:deepslate_tile_stairs{half:bottom,waterlogged:false,shape:straight,facing:east}"},
        {pos: [3, 0, 9], state: "minecraft:deepslate_tile_stairs{half:bottom,waterlogged:false,shape:straight,facing:east}"},
        {pos: [3, 0, 10], state: "minecraft:deepslate_tile_stairs{half:bottom,waterlogged:false,shape:straight,facing:east}"},
        {pos: [3, 0, 11], state: "minecraft:deepslate_tile_stairs{half:bottom,waterlogged:false,shape:outer_right,facing:north}"},
        {pos: [4, 0, 4], state: "minecraft:deepslate_tile_stairs{half:bottom,waterlogged:false,shape:outer_right,facing:east}"},
        {pos: [4, 0, 5], state: "minecraft:deepslate_tile_stairs{half:bottom,waterlogged:false,shape:inner_left,facing:south}"},
        {pos: [4, 0, 11], state: "minecraft:deepslate_tile_stairs{half:bottom,waterlogged:false,shape:inner_left,facing:east}"},
        {pos: [4, 0, 12], state: "minecraft:deepslate_tile_stairs{half:bottom,waterlogged:false,shape:outer_right,facing:north}"},
        {pos: [5, 0, 3], state: "minecraft:deepslate_tile_stairs{half:bottom,waterlogged:false,shape:outer_right,facing:east}"},
        {pos: [5, 0, 4], state: "minecraft:deepslate_tile_stairs{half:bottom,waterlogged:false,shape:inner_left,facing:south}"},
        {pos: [5, 0, 12], state: "minecraft:deepslate_tile_stairs{half:bottom,waterlogged:false,shape:inner_left,facing:east}"},
        {pos: [5, 0, 13], state: "minecraft:deepslate_tile_stairs{half:bottom,waterlogged:false,shape:outer_right,facing:north}"},
        {pos: [6, 0, 3], state: "minecraft:deepslate_tile_stairs{half:bottom,waterlogged:false,shape:straight,facing:south}"},
        {pos: [6, 0, 13], state: "minecraft:deepslate_tile_stairs{half:bottom,waterlogged:false,shape:straight,facing:north}"},
        {pos: [7, 0, 3], state: "minecraft:deepslate_tile_stairs{half:bottom,waterlogged:false,shape:straight,facing:south}"},
        {pos: [7, 0, 13], state: "minecraft:deepslate_tile_stairs{half:bottom,waterlogged:false,shape:straight,facing:north}"},
        {pos: [8, 0, 3], state: "minecraft:deepslate_tile_stairs{half:bottom,waterlogged:false,shape:straight,facing:south}"},
        {pos: [8, 0, 13], state: "minecraft:deepslate_tile_stairs{half:bottom,waterlogged:false,shape:straight,facing:north}"},
        {pos: [9, 0, 3], state: "minecraft:deepslate_tile_stairs{half:bottom,waterlogged:false,shape:straight,facing:south}"},
        {pos: [9, 0, 13], state: "minecraft:deepslate_tile_stairs{half:bottom,waterlogged:false,shape:straight,facing:north}"},
        {pos: [10, 0, 3], state: "minecraft:deepslate_tile_stairs{half:bottom,waterlogged:false,shape:straight,facing:south}"},
        {pos: [10, 0, 13], state: "minecraft:deepslate_tile_stairs{half:bottom,waterlogged:false,shape:straight,facing:north}"},
        {pos: [11, 0, 3], state: "minecraft:deepslate_tile_stairs{half:bottom,waterlogged:false,shape:outer_right,facing:south}"},
        {pos: [11, 0, 4], state: "minecraft:deepslate_tile_stairs{half:bottom,waterlogged:false,shape:inner_left,facing:west}"},
        {pos: [11, 0, 12], state: "minecraft:deepslate_tile_stairs{half:bottom,waterlogged:false,shape:inner_left,facing:north}"},
        {pos: [11, 0, 13], state: "minecraft:deepslate_tile_stairs{half:bottom,waterlogged:false,shape:outer_right,facing:west}"},
        {pos: [12, 0, 4], state: "minecraft:deepslate_tile_stairs{half:bottom,waterlogged:false,shape:outer_right,facing:south}"},
        {pos: [12, 0, 5], state: "minecraft:deepslate_tile_stairs{half:bottom,waterlogged:false,shape:inner_left,facing:west}"},
        {pos: [12, 0, 11], state: "minecraft:deepslate_tile_stairs{half:bottom,waterlogged:false,shape:inner_left,facing:north}"},
        {pos: [12, 0, 12], state: "minecraft:deepslate_tile_stairs{half:bottom,waterlogged:false,shape:outer_right,facing:west}"},
        {pos: [13, 0, 5], state: "minecraft:deepslate_tile_stairs{half:bottom,waterlogged:false,shape:outer_right,facing:south}"},
        {pos: [13, 0, 6], state: "minecraft:deepslate_tile_stairs{half:bottom,waterlogged:false,shape:straight,facing:west}"},
        {pos: [13, 0, 7], state: "minecraft:deepslate_tile_stairs{half:bottom,waterlogged:false,shape:straight,facing:west}"},
        {pos: [13, 0, 8], state: "minecraft:deepslate_tile_stairs{half:bottom,waterlogged:false,shape:straight,facing:west}"},
        {pos: [13, 0, 9], state: "minecraft:deepslate_tile_stairs{half:bottom,waterlogged:false,shape:straight,facing:west}"},
        {pos: [13, 0, 10], state: "minecraft:deepslate_tile_stairs{half:bottom,waterlogged:false,shape:straight,facing:west}"},
        {pos: [13, 0, 11], state: "minecraft:deepslate_tile_stairs{half:bottom,waterlogged:false,shape:outer_left,facing:north}"},
        {pos: [5, 1, 6], state: "minecraft:ladder{waterlogged:false,facing:south}"},
        {pos: [5, 1, 10], state: "minecraft:ladder{waterlogged:false,facing:north}"},
        {pos: [6, 1, 5], state: "minecraft:ladder{waterlogged:false,facing:east}"},
        {pos: [6, 1, 11], state: "minecraft:ladder{waterlogged:false,facing:east}"},
        {pos: [10, 1, 5], state: "minecraft:ladder{waterlogged:false,facing:west}"},
        {pos: [10, 1, 11], state: "minecraft:ladder{waterlogged:false,facing:west}"},
        {pos: [11, 1, 6], state: "minecraft:ladder{waterlogged:false,facing:south}"},
        {pos: [11, 1, 10], state: "minecraft:ladder{waterlogged:false,facing:north}"},
        {pos: [5, 2, 6], state: "minecraft:ladder{waterlogged:false,facing:south}"},
        {pos: [5, 2, 10], state: "minecraft:ladder{waterlogged:false,facing:north}"},
        {pos: [6, 2, 5], state: "minecraft:ladder{waterlogged:false,facing:east}"},
        {pos: [6, 2, 11], state: "minecraft:ladder{waterlogged:false,facing:east}"},
        {pos: [10, 2, 5], state: "minecraft:ladder{waterlogged:false,facing:west}"},
        {pos: [10, 2, 11], state: "minecraft:ladder{waterlogged:false,facing:west}"},
        {pos: [11, 2, 6], state: "minecraft:ladder{waterlogged:false,facing:south}"},
        {pos: [11, 2, 10], state: "minecraft:ladder{waterlogged:false,facing:north}"},
        {pos: [5, 3, 6], state: "minecraft:ladder{waterlogged:false,facing:south}"},
        {pos: [5, 3, 10], state: "minecraft:ladder{waterlogged:false,facing:north}"},
        {pos: [6, 3, 5], state: "minecraft:ladder{waterlogged:false,facing:east}"},
        {pos: [6, 3, 11], state: "minecraft:ladder{waterlogged:false,facing:east}"},
        {pos: [10, 3, 5], state: "minecraft:ladder{waterlogged:false,facing:west}"},
        {pos: [10, 3, 11], state: "minecraft:ladder{waterlogged:false,facing:west}"},
        {pos: [11, 3, 6], state: "minecraft:ladder{waterlogged:false,facing:south}"},
        {pos: [11, 3, 10], state: "minecraft:ladder{waterlogged:false,facing:north}"},
        {pos: [5, 4, 6], state: "minecraft:ladder{waterlogged:false,facing:south}"},
        {pos: [5, 4, 10], state: "minecraft:ladder{waterlogged:false,facing:north}"},
        {pos: [6, 4, 5], state: "minecraft:ladder{waterlogged:false,facing:east}"},
        {pos: [6, 4, 11], state: "minecraft:ladder{waterlogged:false,facing:east}"},
        {pos: [10, 4, 5], state: "minecraft:ladder{waterlogged:false,facing:west}"},
        {pos: [10, 4, 11], state: "minecraft:ladder{waterlogged:false,facing:west}"},
        {pos: [11, 4, 6], state: "minecraft:ladder{waterlogged:false,facing:south}"},
        {pos: [11, 4, 10], state: "minecraft:ladder{waterlogged:false,facing:north}"},
        {pos: [5, 5, 6], state: "minecraft:ladder{waterlogged:false,facing:south}"},
        {pos: [5, 5, 10], state: "minecraft:ladder{waterlogged:false,facing:north}"},
        {pos: [6, 5, 5], state: "minecraft:ladder{waterlogged:false,facing:east}"},
        {pos: [6, 5, 11], state: "minecraft:ladder{waterlogged:false,facing:east}"},
        {pos: [10, 5, 5], state: "minecraft:ladder{waterlogged:false,facing:west}"},
        {pos: [10, 5, 11], state: "minecraft:ladder{waterlogged:false,facing:west}"},
        {pos: [11, 5, 6], state: "minecraft:ladder{waterlogged:false,facing:south}"},
        {pos: [11, 5, 10], state: "minecraft:ladder{waterlogged:false,facing:north}"},
        {pos: [5, 6, 6], state: "minecraft:ladder{waterlogged:false,facing:south}"},
        {pos: [5, 6, 10], state: "minecraft:ladder{waterlogged:false,facing:north}"},
        {pos: [6, 6, 5], state: "minecraft:ladder{waterlogged:false,facing:east}"},
        {pos: [6, 6, 11], state: "minecraft:ladder{waterlogged:false,facing:east}"},
        {pos: [10, 6, 5], state: "minecraft:ladder{waterlogged:false,facing:west}"},
        {pos: [10, 6, 11], state: "minecraft:ladder{waterlogged:false,facing:west}"},
        {pos: [11, 6, 6], state: "minecraft:ladder{waterlogged:false,facing:south}"},
        {pos: [11, 6, 10], state: "minecraft:ladder{waterlogged:false,facing:north}"},
        {pos: [5, 7, 6], state: "minecraft:ladder{waterlogged:false,facing:south}"},
        {pos: [5, 7, 10], state: "minecraft:ladder{waterlogged:false,facing:north}"},
        {pos: [6, 7, 5], state: "minecraft:ladder{waterlogged:false,facing:east}"},
        {pos: [6, 7, 11], state: "minecraft:ladder{waterlogged:false,facing:east}"},
        {pos: [10, 7, 5], state: "minecraft:ladder{waterlogged:false,facing:west}"},
        {pos: [10, 7, 11], state: "minecraft:ladder{waterlogged:false,facing:west}"},
        {pos: [11, 7, 6], state: "minecraft:ladder{waterlogged:false,facing:south}"},
        {pos: [11, 7, 10], state: "minecraft:ladder{waterlogged:false,facing:north}"},
        {pos: [3, 8, 6], state: "minecraft:polished_deepslate_wall{east:none,waterlogged:false,south:none,north:none,west:none,up:true}"},
        {pos: [3, 8, 10], state: "minecraft:polished_deepslate_wall{east:none,waterlogged:false,south:none,north:none,west:none,up:true}"},
        {pos: [5, 8, 6], state: "minecraft:ladder{waterlogged:false,facing:south}"},
        {pos: [5, 8, 10], state: "minecraft:ladder{waterlogged:false,facing:north}"},
        {pos: [6, 8, 3], state: "minecraft:polished_deepslate_wall{east:none,waterlogged:false,south:none,north:none,west:none,up:true}"},
        {pos: [6, 8, 5], state: "minecraft:ladder{waterlogged:false,facing:east}"},
        {pos: [6, 8, 11], state: "minecraft:ladder{waterlogged:false,facing:east}"},
        {pos: [6, 8, 13], state: "minecraft:polished_deepslate_wall{east:none,waterlogged:false,south:none,north:none,west:none,up:true}"},
        {pos: [7, 8, 8], state: "minecraft:ladder{waterlogged:false,facing:west}"},
        {pos: [8, 8, 7], state: "minecraft:ladder{waterlogged:false,facing:north}"},
        {pos: [8, 8, 9], state: "minecraft:ladder{waterlogged:false,facing:south}"},
        {pos: [9, 8, 8], state: "minecraft:ladder{waterlogged:false,facing:east}"},
        {pos: [10, 8, 3], state: "minecraft:polished_deepslate_wall{east:none,waterlogged:false,south:none,north:none,west:none,up:true}"},
        {pos: [10, 8, 5], state: "minecraft:ladder{waterlogged:false,facing:west}"},
        {pos: [10, 8, 11], state: "minecraft:ladder{waterlogged:false,facing:west}"},
        {pos: [10, 8, 13], state: "minecraft:polished_deepslate_wall{east:none,waterlogged:false,south:none,north:none,west:none,up:true}"},
        {pos: [11, 8, 6], state: "minecraft:ladder{waterlogged:false,facing:south}"},
        {pos: [11, 8, 10], state: "minecraft:ladder{waterlogged:false,facing:north}"},
        {pos: [13, 8, 6], state: "minecraft:polished_deepslate_wall{east:none,waterlogged:false,south:none,north:none,west:none,up:true}"},
        {pos: [13, 8, 10], state: "minecraft:polished_deepslate_wall{east:none,waterlogged:false,south:none,north:none,west:none,up:true}"},
        {pos: [3, 9, 6], state: "minecraft:polished_deepslate_wall{east:none,waterlogged:false,south:none,north:none,west:none,up:true}"},
        {pos: [3, 9, 10], state: "minecraft:polished_deepslate_wall{east:none,waterlogged:false,south:none,north:none,west:none,up:true}"},
        {pos: [6, 9, 3], state: "minecraft:polished_deepslate_wall{east:none,waterlogged:false,south:none,north:none,west:none,up:true}"},
        {pos: [6, 9, 13], state: "minecraft:polished_deepslate_wall{east:none,waterlogged:false,south:none,north:none,west:none,up:true}"},
        {pos: [7, 9, 8], state: "minecraft:ladder{waterlogged:false,facing:west}"},
        {pos: [8, 9, 7], state: "minecraft:ladder{waterlogged:false,facing:north}"},
        {pos: [8, 9, 9], state: "minecraft:ladder{waterlogged:false,facing:south}"},
        {pos: [9, 9, 8], state: "minecraft:ladder{waterlogged:false,facing:east}"},
        {pos: [10, 9, 3], state: "minecraft:polished_deepslate_wall{east:none,waterlogged:false,south:none,north:none,west:none,up:true}"},
        {pos: [10, 9, 13], state: "minecraft:polished_deepslate_wall{east:none,waterlogged:false,south:none,north:none,west:none,up:true}"},
        {pos: [13, 9, 6], state: "minecraft:polished_deepslate_wall{east:none,waterlogged:false,south:none,north:none,west:none,up:true}"},
        {pos: [13, 9, 10], state: "minecraft:polished_deepslate_wall{east:none,waterlogged:false,south:none,north:none,west:none,up:true}"},
        {pos: [3, 10, 6], state: "minecraft:polished_deepslate_wall{east:none,waterlogged:false,south:none,north:none,west:none,up:true}"},
        {pos: [3, 10, 10], state: "minecraft:polished_deepslate_wall{east:none,waterlogged:false,south:none,north:none,west:none,up:true}"},
        {pos: [6, 10, 3], state: "minecraft:polished_deepslate_wall{east:none,waterlogged:false,south:none,north:none,west:none,up:true}"},
        {pos: [6, 10, 13], state: "minecraft:polished_deepslate_wall{east:none,waterlogged:false,south:none,north:none,west:none,up:true}"},
        {pos: [7, 10, 8], state: "minecraft:ladder{waterlogged:false,facing:west}"},
        {pos: [8, 10, 7], state: "minecraft:ladder{waterlogged:false,facing:north}"},
        {pos: [8, 10, 9], state: "minecraft:ladder{waterlogged:false,facing:south}"},
        {pos: [9, 10, 8], state: "minecraft:ladder{waterlogged:false,facing:east}"},
        {pos: [10, 10, 3], state: "minecraft:polished_deepslate_wall{east:none,waterlogged:false,south:none,north:none,west:none,up:true}"},
        {pos: [10, 10, 13], state: "minecraft:polished_deepslate_wall{east:none,waterlogged:false,south:none,north:none,west:none,up:true}"},
        {pos: [13, 10, 6], state: "minecraft:polished_deepslate_wall{east:none,waterlogged:false,south:none,north:none,west:none,up:true}"},
        {pos: [13, 10, 10], state: "minecraft:polished_deepslate_wall{east:none,waterlogged:false,south:none,north:none,west:none,up:true}"},
        {pos: [3, 11, 6], state: "minecraft:polished_deepslate_wall{east:none,waterlogged:false,south:none,north:none,west:none,up:true}"},
        {pos: [3, 11, 10], state: "minecraft:polished_deepslate_wall{east:none,waterlogged:false,south:none,north:none,west:none,up:true}"},
        {pos: [6, 11, 3], state: "minecraft:polished_deepslate_wall{east:none,waterlogged:false,south:none,north:none,west:none,up:true}"},
        {pos: [6, 11, 13], state: "minecraft:polished_deepslate_wall{east:none,waterlogged:false,south:none,north:none,west:none,up:true}"},
        {pos: [7, 11, 8], state: "minecraft:ladder{waterlogged:false,facing:west}"},
        {pos: [8, 11, 7], state: "minecraft:ladder{waterlogged:false,facing:north}"},
        {pos: [8, 11, 9], state: "minecraft:ladder{waterlogged:false,facing:south}"},
        {pos: [9, 11, 8], state: "minecraft:ladder{waterlogged:false,facing:east}"},
        {pos: [10, 11, 3], state: "minecraft:polished_deepslate_wall{east:none,waterlogged:false,south:none,north:none,west:none,up:true}"},
        {pos: [10, 11, 13], state: "minecraft:polished_deepslate_wall{east:none,waterlogged:false,south:none,north:none,west:none,up:true}"},
        {pos: [13, 11, 6], state: "minecraft:polished_deepslate_wall{east:none,waterlogged:false,south:none,north:none,west:none,up:true}"},
        {pos: [13, 11, 10], state: "minecraft:polished_deepslate_wall{east:none,waterlogged:false,south:none,north:none,west:none,up:true}"},
        {pos: [3, 12, 6], state: "minecraft:polished_deepslate_wall{east:none,waterlogged:false,south:none,north:none,west:none,up:true}"},
        {pos: [3, 12, 10], state: "minecraft:polished_deepslate_wall{east:none,waterlogged:false,south:none,north:none,west:none,up:true}"},
        {pos: [6, 12, 3], state: "minecraft:polished_deepslate_wall{east:none,waterlogged:false,south:none,north:none,west:none,up:true}"},
        {pos: [6, 12, 13], state: "minecraft:polished_deepslate_wall{east:none,waterlogged:false,south:none,north:none,west:none,up:true}"},
        {pos: [7, 12, 8], state: "minecraft:ladder{waterlogged:false,facing:west}"},
        {pos: [8, 12, 7], state: "minecraft:ladder{waterlogged:false,facing:north}"},
        {pos: [8, 12, 9], state: "minecraft:ladder{waterlogged:false,facing:south}"},
        {pos: [9, 12, 8], state: "minecraft:ladder{waterlogged:false,facing:east}"},
        {pos: [10, 12, 3], state: "minecraft:polished_deepslate_wall{east:none,waterlogged:false,south:none,north:none,west:none,up:true}"},
        {pos: [10, 12, 13], state: "minecraft:polished_deepslate_wall{east:none,waterlogged:false,south:none,north:none,west:none,up:true}"},
        {pos: [13, 12, 6], state: "minecraft:polished_deepslate_wall{east:none,waterlogged:false,south:none,north:none,west:none,up:true}"},
        {pos: [13, 12, 10], state: "minecraft:polished_deepslate_wall{east:none,waterlogged:false,south:none,north:none,west:none,up:true}"},
        {pos: [4, 13, 5], state: "minecraft:deepslate_tile_slab{waterlogged:false,type:top}"},
        {pos: [4, 13, 7], state: "minecraft:deepslate_tile_slab{waterlogged:false,type:top}"},
        {pos: [4, 13, 8], state: "minecraft:deepslate_tile_slab{waterlogged:false,type:top}"},
        {pos: [4, 13, 9], state: "minecraft:deepslate_tile_slab{waterlogged:false,type:top}"},
        {pos: [4, 13, 11], state: "minecraft:deepslate_tile_slab{waterlogged:false,type:top}"},
        {pos: [5, 13, 4], state: "minecraft:deepslate_tile_slab{waterlogged:false,type:top}"},
        {pos: [5, 13, 7], state: "minecraft:deepslate_tile_slab{waterlogged:false,type:top}"},
        {pos: [5, 13, 8], state: "minecraft:deepslate_tile_slab{waterlogged:false,type:top}"},
        {pos: [5, 13, 9], state: "minecraft:deepslate_tile_slab{waterlogged:false,type:top}"},
        {pos: [5, 13, 12], state: "minecraft:deepslate_tile_slab{waterlogged:false,type:top}"},
        {pos: [7, 13, 4], state: "minecraft:deepslate_tile_slab{waterlogged:false,type:top}"},
        {pos: [7, 13, 5], state: "minecraft:deepslate_tile_slab{waterlogged:false,type:top}"},
        {pos: [7, 13, 7], state: "minecraft:deepslate_tile_slab{waterlogged:false,type:top}"},
        {pos: [7, 13, 8], state: "minecraft:ladder{waterlogged:false,facing:west}"},
        {pos: [7, 13, 9], state: "minecraft:deepslate_tile_slab{waterlogged:false,type:top}"},
        {pos: [7, 13, 11], state: "minecraft:deepslate_tile_slab{waterlogged:false,type:top}"},
        {pos: [7, 13, 12], state: "minecraft:deepslate_tile_slab{waterlogged:false,type:top}"},
        {pos: [8, 13, 4], state: "minecraft:deepslate_tile_slab{waterlogged:false,type:top}"},
        {pos: [8, 13, 5], state: "minecraft:deepslate_tile_slab{waterlogged:false,type:top}"},
        {pos: [8, 13, 7], state: "minecraft:ladder{waterlogged:false,facing:north}"},
        {pos: [8, 13, 9], state: "minecraft:ladder{waterlogged:false,facing:south}"},
        {pos: [8, 13, 11], state: "minecraft:deepslate_tile_slab{waterlogged:false,type:top}"},
        {pos: [8, 13, 12], state: "minecraft:deepslate_tile_slab{waterlogged:false,type:top}"},
        {pos: [9, 13, 4], state: "minecraft:deepslate_tile_slab{waterlogged:false,type:top}"},
        {pos: [9, 13, 5], state: "minecraft:deepslate_tile_slab{waterlogged:false,type:top}"},
        {pos: [9, 13, 7], state: "minecraft:deepslate_tile_slab{waterlogged:false,type:top}"},
        {pos: [9, 13, 8], state: "minecraft:ladder{waterlogged:false,facing:east}"},
        {pos: [9, 13, 9], state: "minecraft:deepslate_tile_slab{waterlogged:false,type:top}"},
        {pos: [9, 13, 11], state: "minecraft:deepslate_tile_slab{waterlogged:false,type:top}"},
        {pos: [9, 13, 12], state: "minecraft:deepslate_tile_slab{waterlogged:false,type:top}"},
        {pos: [11, 13, 4], state: "minecraft:deepslate_tile_slab{waterlogged:false,type:top}"},
        {pos: [11, 13, 7], state: "minecraft:deepslate_tile_slab{waterlogged:false,type:top}"},
        {pos: [11, 13, 8], state: "minecraft:deepslate_tile_slab{waterlogged:false,type:top}"},
        {pos: [11, 13, 9], state: "minecraft:deepslate_tile_slab{waterlogged:false,type:top}"},
        {pos: [11, 13, 12], state: "minecraft:deepslate_tile_slab{waterlogged:false,type:top}"},
        {pos: [12, 13, 5], state: "minecraft:deepslate_tile_slab{waterlogged:false,type:top}"},
        {pos: [12, 13, 7], state: "minecraft:deepslate_tile_slab{waterlogged:false,type:top}"},
        {pos: [12, 13, 8], state: "minecraft:deepslate_tile_slab{waterlogged:false,type:top}"},
        {pos: [12, 13, 9], state: "minecraft:deepslate_tile_slab{waterlogged:false,type:top}"},
        {pos: [12, 13, 11], state: "minecraft:deepslate_tile_slab{waterlogged:false,type:top}"},
        {pos: [3, 14, 5], state: "minecraft:deepslate_tile_slab{waterlogged:false,type:top}"},
        {pos: [3, 14, 7], state: "minecraft:deepslate_tile_slab{waterlogged:false,type:top}"},
        {pos: [3, 14, 8], state: "minecraft:deepslate_tile_slab{waterlogged:false,type:top}"},
        {pos: [3, 14, 9], state: "minecraft:deepslate_tile_slab{waterlogged:false,type:top}"},
        {pos: [3, 14, 11], state: "minecraft:deepslate_tile_slab{waterlogged:false,type:top}"},
        {pos: [4, 14, 4], state: "minecraft:deepslate_tile_slab{waterlogged:false,type:top}"},
        {pos: [4, 14, 12], state: "minecraft:deepslate_tile_slab{waterlogged:false,type:top}"},
        {pos: [5, 14, 3], state: "minecraft:deepslate_tile_slab{waterlogged:false,type:top}"},
        {pos: [5, 14, 13], state: "minecraft:deepslate_tile_slab{waterlogged:false,type:top}"},
        {pos: [7, 14, 3], state: "minecraft:deepslate_tile_slab{waterlogged:false,type:top}"},
        {pos: [7, 14, 8], state: "minecraft:ladder{waterlogged:false,facing:west}"},
        {pos: [7, 14, 13], state: "minecraft:deepslate_tile_slab{waterlogged:false,type:top}"},
        {pos: [8, 14, 3], state: "minecraft:deepslate_tile_slab{waterlogged:false,type:top}"},
        {pos: [8, 14, 7], state: "minecraft:ladder{waterlogged:false,facing:north}"},
        {pos: [8, 14, 9], state: "minecraft:ladder{waterlogged:false,facing:south}"},
        {pos: [8, 14, 13], state: "minecraft:deepslate_tile_slab{waterlogged:false,type:top}"},
        {pos: [9, 14, 8], state: "minecraft:ladder{waterlogged:false,facing:east}"},
        {pos: [9, 14, 13], state: "minecraft:deepslate_tile_slab{waterlogged:false,type:top}"},
        {pos: [11, 14, 3], state: "minecraft:deepslate_tile_slab{waterlogged:false,type:top}"},
        {pos: [11, 14, 13], state: "minecraft:deepslate_tile_slab{waterlogged:false,type:top}"},
        {pos: [12, 14, 4], state: "minecraft:deepslate_tile_slab{waterlogged:false,type:top}"},
        {pos: [12, 14, 12], state: "minecraft:deepslate_tile_slab{waterlogged:false,type:top}"},
        {pos: [13, 14, 5], state: "minecraft:deepslate_tile_slab{waterlogged:false,type:top}"},
        {pos: [13, 14, 7], state: "minecraft:deepslate_tile_slab{waterlogged:false,type:top}"},
        {pos: [13, 14, 8], state: "minecraft:deepslate_tile_slab{waterlogged:false,type:top}"},
        {pos: [13, 14, 9], state: "minecraft:deepslate_tile_slab{waterlogged:false,type:top}"},
        {pos: [13, 14, 11], state: "minecraft:deepslate_tile_slab{waterlogged:false,type:top}"},
        {pos: [2, 15, 5], state: "minecraft:deepslate_tile_slab{waterlogged:false,type:top}"},
        {pos: [2, 15, 7], state: "minecraft:deepslate_tile_slab{waterlogged:false,type:top}"},
        {pos: [2, 15, 8], state: "minecraft:deepslate_tile_slab{waterlogged:false,type:top}"},
        {pos: [2, 15, 9], state: "minecraft:deepslate_tile_slab{waterlogged:false,type:top}"},
        {pos: [2, 15, 11], state: "minecraft:deepslate_tile_slab{waterlogged:false,type:top}"},
        {pos: [3, 15, 4], state: "minecraft:deepslate_tile_slab{waterlogged:false,type:top}"},
        {pos: [3, 15, 12], state: "minecraft:deepslate_tile_slab{waterlogged:false,type:top}"},
        {pos: [4, 15, 3], state: "minecraft:deepslate_tile_slab{waterlogged:false,type:top}"},
        {pos: [4, 15, 13], state: "minecraft:deepslate_tile_slab{waterlogged:false,type:top}"},
        {pos: [5, 15, 2], state: "minecraft:deepslate_tile_slab{waterlogged:false,type:top}"},
        {pos: [5, 15, 14], state: "minecraft:deepslate_tile_slab{waterlogged:false,type:top}"},
        {pos: [7, 15, 14], state: "minecraft:deepslate_tile_slab{waterlogged:false,type:top}"},
        {pos: [8, 15, 14], state: "minecraft:deepslate_tile_slab{waterlogged:false,type:top}"},
        {pos: [9, 15, 14], state: "minecraft:deepslate_tile_slab{waterlogged:false,type:top}"},
        {pos: [11, 15, 2], state: "minecraft:deepslate_tile_slab{waterlogged:false,type:top}"},
        {pos: [11, 15, 14], state: "minecraft:deepslate_tile_slab{waterlogged:false,type:top}"},
        {pos: [12, 15, 3], state: "minecraft:deepslate_tile_slab{waterlogged:false,type:top}"},
        {pos: [12, 15, 13], state: "minecraft:deepslate_tile_slab{waterlogged:false,type:top}"},
        {pos: [13, 15, 4], state: "minecraft:deepslate_tile_slab{waterlogged:false,type:top}"},
        {pos: [13, 15, 12], state: "minecraft:deepslate_tile_slab{waterlogged:false,type:top}"},
        {pos: [14, 15, 5], state: "minecraft:deepslate_tile_slab{waterlogged:false,type:top}"},
        {pos: [14, 15, 7], state: "minecraft:deepslate_tile_slab{waterlogged:false,type:top}"},
        {pos: [14, 15, 8], state: "minecraft:deepslate_tile_slab{waterlogged:false,type:top}"},
        {pos: [14, 15, 9], state: "minecraft:deepslate_tile_slab{waterlogged:false,type:top}"},
        {pos: [14, 15, 11], state: "minecraft:deepslate_tile_slab{waterlogged:false,type:top}"},
        {pos: [6, 16, 6], state: "minecraft:soul_lantern{waterlogged:false,hanging:true}"},
        {pos: [6, 16, 10], state: "minecraft:soul_lantern{waterlogged:false,hanging:true}"},
        {pos: [10, 16, 6], state: "minecraft:soul_lantern{waterlogged:false,hanging:true}"},
        {pos: [10, 16, 10], state: "minecraft:soul_lantern{waterlogged:false,hanging:true}"},
        {pos: [6, 17, 6], state: "minecraft:deepslate_tile_wall{east:none,waterlogged:false,south:none,north:none,west:none,up:true}"},
        {pos: [6, 17, 10], state: "minecraft:deepslate_tile_wall{east:none,waterlogged:false,south:none,north:none,west:none,up:true}"},
        {pos: [10, 17, 6], state: "minecraft:deepslate_tile_wall{east:none,waterlogged:false,south:none,north:none,west:none,up:true}"},
        {pos: [10, 17, 10], state: "minecraft:deepslate_tile_wall{east:none,waterlogged:false,south:none,north:none,west:none,up:true}"},
        {pos: [8, 0, 16], state: "minecraft:jigsaw{orientation:south_up}", nbt: {final_state: "minecraft:air", id: "minecraft:jigsaw", joint: "rollable", name: "minecraft:connect_structure", pool: "minecraft:empty", target: "minecraft:empty"}},
        {pos: [8, 16, 8], state: "minecraft:chest{waterlogged:false,facing:south,type:single}", nbt: {LootTable: "minecraft:chests/ancient_city", id: "minecraft:chest"}}
    ],
    entities: [],
    palette: [
        "minecraft:deepslate_tiles",
        "minecraft:deepslate_bricks",
        "minecraft:polished_basalt{axis:y}",
        "minecraft:chiseled_deepslate",
        "minecraft:deepslate_tile_stairs{half:bottom,waterlogged:false,shape:outer_right,facing:east}",
        "minecraft:deepslate_tile_stairs{half:bottom,waterlogged:false,shape:straight,facing:east}",
        "minecraft:deepslate_tile_stairs{half:bottom,waterlogged:false,shape:outer_right,facing:north}",
        "minecraft:deepslate_tile_stairs{half:bottom,waterlogged:false,shape:inner_left,facing:south}",
        "minecraft:deepslate_tile_stairs{half:bottom,waterlogged:false,shape:inner_left,facing:east}",
        "minecraft:deepslate_tile_stairs{half:bottom,waterlogged:false,shape:straight,facing:south}",
        "minecraft:deepslate_tile_stairs{half:bottom,waterlogged:false,shape:straight,facing:north}",
        "minecraft:deepslate_tile_stairs{half:bottom,waterlogged:false,shape:outer_right,facing:south}",
        "minecraft:deepslate_tile_stairs{half:bottom,waterlogged:false,shape:inner_left,facing:west}",
        "minecraft:deepslate_tile_stairs{half:bottom,waterlogged:false,shape:inner_left,facing:north}",
        "minecraft:deepslate_tile_stairs{half:bottom,waterlogged:false,shape:outer_right,facing:west}",
        "minecraft:deepslate_tile_stairs{half:bottom,waterlogged:false,shape:straight,facing:west}",
        "minecraft:deepslate_tile_stairs{half:bottom,waterlogged:false,shape:outer_left,facing:north}",
        "minecraft:ladder{waterlogged:false,facing:south}",
        "minecraft:ladder{waterlogged:false,facing:north}",
        "minecraft:ladder{waterlogged:false,facing:east}",
        "minecraft:ladder{waterlogged:false,facing:west}",
        "minecraft:polished_deepslate_wall{east:none,waterlogged:false,south:none,north:none,west:none,up:true}",
        "minecraft:deepslate_tile_slab{waterlogged:false,type:top}",
        "minecraft:soul_lantern{waterlogged:false,hanging:true}",
        "minecraft:deepslate_tile_wall{east:none,waterlogged:false,south:none,north:none,west:none,up:true}",
        "minecraft:jigsaw{orientation:south_up}",
        "minecraft:chest{waterlogged:false,facing:south,type:single}"
    ]
}