{
    size: [7, 5, 8],
    data: [
        {pos: [0, 0, 3], state: "minecraft:snow_block"},
        {pos: [0, 0, 4], state: "minecraft:snow_block"},
        {pos: [0, 0, 5], state: "minecraft:snow_block"},
        {pos: [1, 0, 2], state: "minecraft:snow_block"},
        {pos: [1, 0, 3], state: "minecraft:snow_block"},
        {pos: [1, 0, 4], state: "minecraft:snow_block"},
        {pos: [1, 0, 5], state: "minecraft:snow_block"},
        {pos: [1, 0, 6], state: "minecraft:snow_block"},
        {pos: [2, 0, 0], state: "minecraft:snow_block"},
        {pos: [2, 0, 1], state: "minecraft:snow_block"},
        {pos: [2, 0, 2], state: "minecraft:snow_block"},
        {pos: [2, 0, 3], state: "minecraft:snow_block"},
        {pos: [2, 0, 4], state: "minecraft:snow_block"},
        {pos: [2, 0, 5], state: "minecraft:snow_block"},
        {pos: [2, 0, 6], state: "minecraft:snow_block"},
        {pos: [2, 0, 7], state: "minecraft:snow_block"},
        {pos: [3, 0, 0], state: "minecraft:snow_block"},
        {pos: [3, 0, 1], state: "minecraft:snow_block"},
        {pos: [3, 0, 2], state: "minecraft:snow_block"},
        {pos: [3, 0, 3], state: "minecraft:snow_block"},
        {pos: [3, 0, 4], state: "minecraft:snow_block"},
        {pos: [3, 0, 6], state: "minecraft:snow_block"},
        {pos: [3, 0, 7], state: "minecraft:snow_block"},
        {pos: [4, 0, 0], state: "minecraft:snow_block"},
        {pos: [4, 0, 1], state: "minecraft:snow_block"},
        {pos: [4, 0, 2], state: "minecraft:snow_block"},
        {pos: [4, 0, 3], state: "minecraft:snow_block"},
        {pos: [4, 0, 4], state: "minecraft:snow_block"},
        {pos: [4, 0, 5], state: "minecraft:snow_block"},
        {pos: [4, 0, 6], state: "minecraft:snow_block"},
        {pos: [4, 0, 7], state: "minecraft:snow_block"},
        {pos: [5, 0, 2], state: "minecraft:snow_block"},
        {pos: [5, 0, 3], state: "minecraft:snow_block"},
        {pos: [5, 0, 4], state: "minecraft:snow_block"},
        {pos: [5, 0, 5], state: "minecraft:snow_block"},
        {pos: [5, 0, 6], state: "minecraft:snow_block"},
        {pos: [6, 0, 3], state: "minecraft:snow_block"},
        {pos: [6, 0, 4], state: "minecraft:snow_block"},
        {pos: [6, 0, 5], state: "minecraft:snow_block"},
        {pos: [0, 1, 3], state: "minecraft:snow_block"},
        {pos: [0, 1, 4], state: "minecraft:ice"},
        {pos: [0, 1, 5], state: "minecraft:snow_block"},
        {pos: [1, 1, 2], state: "minecraft:snow_block"},
        {pos: [1, 1, 5], state: "minecraft:crafting_table"},
        {pos: [1, 1, 6], state: "minecraft:snow_block"},
        {pos: [2, 1, 0], state: "minecraft:snow_block"},
        {pos: [2, 1, 1], state: "minecraft:snow_block"},
        {pos: [2, 1, 7], state: "minecraft:snow_block"},
        {pos: [3, 1, 7], state: "minecraft:snow_block"},
        {pos: [4, 1, 0], state: "minecraft:snow_block"},
        {pos: [4, 1, 1], state: "minecraft:snow_block"},
        {pos: [4, 1, 7], state: "minecraft:snow_block"},
        {pos: [5, 1, 2], state: "minecraft:snow_block"},
        {pos: [5, 1, 6], state: "minecraft:snow_block"},
        {pos: [6, 1, 3], state: "minecraft:snow_block"},
        {pos: [6, 1, 4], state: "minecraft:ice"},
        {pos: [6, 1, 5], state: "minecraft:snow_block"},
        {pos: [0, 2, 3], state: "minecraft:snow_block"},
        {pos: [0, 2, 4], state: "minecraft:snow_block"},
        {pos: [0, 2, 5], state: "minecraft:snow_block"},
        {pos: [1, 2, 2], state: "minecraft:snow_block"},
        {pos: [1, 2, 6], state: "minecraft:snow_block"},
        {pos: [2, 2, 0], state: "minecraft:snow_block"},
        {pos: [2, 2, 1], state: "minecraft:snow_block"},
        {pos: [2, 2, 7], state: "minecraft:snow_block"},
        {pos: [3, 2, 7], state: "minecraft:snow_block"},
        {pos: [4, 2, 0], state: "minecraft:snow_block"},
        {pos: [4, 2, 1], state: "minecraft:snow_block"},
        {pos: [4, 2, 7], state: "minecraft:snow_block"},
        {pos: [5, 2, 2], state: "minecraft:snow_block"},
        {pos: [5, 2, 6], state: "minecraft:snow_block"},
        {pos: [6, 2, 3], state: "minecraft:snow_block"},
        {pos: [6, 2, 4], state: "minecraft:snow_block"},
        {pos: [6, 2, 5], state: "minecraft:snow_block"},
        {pos: [1, 3, 3], state: "minecraft:snow_block"},
        {pos: [1, 3, 4], state: "minecraft:snow_block"},
        {pos: [1, 3, 5], state: "minecraft:snow_block"},
        {pos: [2, 3, 2], state: "minecraft:snow_block"},
        {pos: [2, 3, 6], state: "minecraft:snow_block"},
        {pos: [3, 3, 0], state: "minecraft:snow_block"},
        {pos: [3, 3, 1], state: "minecraft:snow_block"},
        {pos: [3, 3, 2], state: "minecraft:snow_block"},
        {pos: [3, 3, 6], state: "minecraft:snow_block"},
        {pos: [4, 3, 2], state: "minecraft:snow_block"},
        {pos: [4, 3, 6], state: "minecraft:snow_block"},
        {pos: [5, 3, 3], state: "minecraft:snow_block"},
        {pos: [5, 3, 4], state: "minecraft:snow_block"},
        {pos: [5, 3, 5], state: "minecraft:snow_block"},
        {pos: [2, 4, 3], state: "minecraft:snow_block"},
        {pos: [2, 4, 4], state: "minecraft:snow_block"},
        {pos: [2, 4, 5], state: "minecraft:snow_block"},
        {pos: [3, 4, 3], state: "minecraft:snow_block"},
        {pos: [3, 4, 4], state: "minecraft:snow_block"},
        {pos: [3, 4, 5], state: "minecraft:snow_block"},
        {pos: [4, 4, 3], state: "minecraft:snow_block"},
        {pos: [4, 4, 4], state: "minecraft:snow_block"},
        {pos: [4, 4, 5], state: "minecraft:snow_block"},
        {pos: [3, 0, 5], state: "minecraft:oak_trapdoor{half:top,waterlogged:false,powered:false,facing:north,open:false}"},
        {pos: [1, 1, 4], state: "minecraft:redstone_torch{lit:true}"},
        {pos: [2, 1, 2], state: "minecraft:air"},
        {pos: [2, 1, 3], state: "minecraft:white_carpet"},
        {pos: [2, 1, 4], state: "minecraft:white_carpet"},
        {pos: [2, 1, 5], state: "minecraft:white_carpet"},
        {pos: [2, 1, 6], state: "minecraft:light_gray_carpet"},
        {pos: [3, 1, 0], state: "minecraft:air"},
        {pos: [3, 1, 1], state: "minecraft:air"},
        {pos: [3, 1, 2], state: "minecraft:air"},
        {pos: [3, 1, 3], state: "minecraft:white_carpet"},
        {pos: [3, 1, 4], state: "minecraft:white_carpet"},
        {pos: [3, 1, 5], state: "minecraft:white_carpet"},
        {pos: [3, 1, 6], state: "minecraft:light_gray_carpet"},
        {pos: [4, 1, 2], state: "minecraft:air"},
        {pos: [4, 1, 3], state: "minecraft:white_carpet"},
        {pos: [4, 1, 4], state: "minecraft:white_carpet"},
        {pos: [4, 1, 5], state: "minecraft:white_carpet"},
        {pos: [4, 1, 6], state: "minecraft:light_gray_carpet"},
        {pos: [5, 1, 3], state: "minecraft:air"},
        {pos: [1, 2, 3], state: "minecraft:air"},
        {pos: [1, 2, 4], state: "minecraft:air"},
        {pos: [1, 2, 5], state: "minecraft:air"},
        {pos: [2, 2, 2], state: "minecraft:air"},
        {pos: [2, 2, 3], state: "minecraft:air"},
        {pos: [2, 2, 4], state: "minecraft:air"},
        {pos: [2, 2, 5], state: "minecraft:air"},
        {pos: [2, 2, 6], state: "minecraft:air"},
        {pos: [3, 2, 0], state: "minecraft:air"},
        {pos: [3, 2, 1], state: "minecraft:air"},
        {pos: [3, 2, 2], state: "minecraft:air"},
        {pos: [3, 2, 3], state: "minecraft:air"},
        {pos: [3, 2, 4], state: "minecraft:air"},
        {pos: [3, 2, 5], state: "minecraft:air"},
        {pos: [3, 2, 6], state: "minecraft:air"},
        {pos: [4, 2, 2], state: "minecraft:air"},
        {pos: [4, 2, 3], state: "minecraft:air"},
        {pos: [4, 2, 4], state: "minecraft:air"},
        {pos: [4, 2, 5], state: "minecraft:air"},
        {pos: [4, 2, 6], state: "minecraft:air"},
        {pos: [5, 2, 3], state: "minecraft:air"},
        {pos: [5, 2, 4], state: "minecraft:air"},
        {pos: [5, 2, 5], state: "minecraft:air"},
        {pos: [2, 3, 3], state: "minecraft:air"},
        {pos: [2, 3, 4], state: "minecraft:air"},
        {pos: [2, 3, 5], state: "minecraft:air"},
        {pos: [3, 3, 3], state: "minecraft:air"},
        {pos: [3, 3, 4], state: "minecraft:air"},
        {pos: [3, 3, 5], state: "minecraft:air"},
        {pos: [4, 3, 3], state: "minecraft:air"},
        {pos: [4, 3, 4], state: "minecraft:air"},
        {pos: [4, 3, 5], state: "minecraft:air"},
        {pos: [1, 1, 3], state: "minecraft:furnace{lit:false,facing:east}", nbt: {Items: [], RecipesUsed: {}, cooking_time_spent: 0s, cooking_total_time: 0s, id: "minecraft:furnace", lit_time_remaining: 0s, lit_total_time: 0s}},
        {pos: [5, 1, 4], state: "minecraft:red_bed{part:foot,facing:south,occupied:false}", nbt: {id: "minecraft:bed"}},
        {pos: [5, 1, 5], state: "minecraft:red_bed{part:head,facing:south,occupied:false}", nbt: {id: "minecraft:bed"}}
    ],
    entities: [],
    palette: [
        "minecraft:snow_block",
        "minecraft:ice",
        "minecraft:crafting_table",
        "minecraft:oak_trapdoor{half:top,waterlogged:false,powered:false,facing:north,open:false}",
        "minecraft:redstone_torch{lit:true}",
        "minecraft:air",
        "minecraft:white_carpet",
        "minecraft:light_gray_carpet",
        "minecraft:furnace{lit:false,facing:east}",
        "minecraft:red_bed{part:foot,facing:south,occupied:false}",
        "minecraft:red_bed{part:head,facing:south,occupied:false}"
    ]
}