{
    size: [7, 8, 7],
    data: [
        {pos: [1, 0, 1], state: "minecraft:stripped_spruce_wood{axis:y}"},
        {pos: [1, 0, 2], state: "minecraft:stripped_spruce_wood{axis:y}"},
        {pos: [1, 0, 3], state: "minecraft:stripped_spruce_wood{axis:y}"},
        {pos: [1, 0, 4], state: "minecraft:stripped_spruce_wood{axis:y}"},
        {pos: [1, 0, 5], state: "minecraft:stripped_spruce_wood{axis:y}"},
        {pos: [2, 0, 1], state: "minecraft:stripped_spruce_wood{axis:y}"},
        {pos: [2, 0, 2], state: "minecraft:spruce_planks"},
        {pos: [2, 0, 3], state: "minecraft:spruce_planks"},
        {pos: [2, 0, 4], state: "minecraft:spruce_planks"},
        {pos: [2, 0, 5], state: "minecraft:stripped_spruce_wood{axis:y}"},
        {pos: [3, 0, 1], state: "minecraft:stripped_spruce_wood{axis:y}"},
        {pos: [3, 0, 2], state: "minecraft:spruce_planks"},
        {pos: [3, 0, 3], state: "minecraft:spruce_planks"},
        {pos: [3, 0, 4], state: "minecraft:spruce_planks"},
        {pos: [3, 0, 5], state: "minecraft:stripped_spruce_wood{axis:y}"},
        {pos: [4, 0, 1], state: "minecraft:stripped_spruce_wood{axis:y}"},
        {pos: [4, 0, 2], state: "minecraft:spruce_planks"},
        {pos: [4, 0, 3], state: "minecraft:cobblestone"},
        {pos: [4, 0, 4], state: "minecraft:spruce_planks"},
        {pos: [4, 0, 5], state: "minecraft:stripped_spruce_wood{axis:y}"},
        {pos: [5, 0, 1], state: "minecraft:stripped_spruce_wood{axis:y}"},
        {pos: [5, 0, 2], state: "minecraft:stripped_spruce_wood{axis:y}"},
        {pos: [5, 0, 3], state: "minecraft:stripped_spruce_wood{axis:y}"},
        {pos: [5, 0, 4], state: "minecraft:stripped_spruce_wood{axis:y}"},
        {pos: [5, 0, 5], state: "minecraft:stripped_spruce_wood{axis:y}"},
        {pos: [0, 1, 1], state: "minecraft:spruce_planks"},
        {pos: [0, 1, 3], state: "minecraft:spruce_planks"},
        {pos: [0, 1, 5], state: "minecraft:spruce_planks"},
        {pos: [1, 1, 1], state: "minecraft:stripped_spruce_wood{axis:y}"},
        {pos: [1, 1, 2], state: "minecraft:stripped_spruce_wood{axis:y}"},
        {pos: [1, 1, 3], state: "minecraft:stripped_spruce_wood{axis:y}"},
        {pos: [1, 1, 4], state: "minecraft:stripped_spruce_wood{axis:y}"},
        {pos: [1, 1, 5], state: "minecraft:stripped_spruce_wood{axis:y}"},
        {pos: [2, 1, 1], state: "minecraft:stripped_spruce_wood{axis:y}"},
        {pos: [2, 1, 5], state: "minecraft:stripped_spruce_wood{axis:y}"},
        {pos: [3, 1, 5], state: "minecraft:stripped_spruce_wood{axis:y}"},
        {pos: [4, 1, 1], state: "minecraft:stripped_spruce_wood{axis:y}"},
        {pos: [4, 1, 5], state: "minecraft:stripped_spruce_wood{axis:y}"},
        {pos: [5, 1, 1], state: "minecraft:stripped_spruce_wood{axis:y}"},
        {pos: [5, 1, 2], state: "minecraft:stripped_spruce_wood{axis:y}"},
        {pos: [5, 1, 3], state: "minecraft:stripped_spruce_wood{axis:y}"},
        {pos: [5, 1, 4], state: "minecraft:stripped_spruce_wood{axis:y}"},
        {pos: [5, 1, 5], state: "minecraft:stripped_spruce_wood{axis:y}"},
        {pos: [6, 1, 1], state: "minecraft:spruce_planks"},
        {pos: [6, 1, 3], state: "minecraft:spruce_planks"},
        {pos: [6, 1, 5], state: "minecraft:spruce_planks"},
        {pos: [0, 2, 0], state: "minecraft:spruce_planks"},
        {pos: [0, 2, 1], state: "minecraft:spruce_planks"},
        {pos: [0, 2, 2], state: "minecraft:spruce_planks"},
        {pos: [0, 2, 3], state: "minecraft:spruce_planks"},
        {pos: [0, 2, 4], state: "minecraft:spruce_planks"},
        {pos: [0, 2, 5], state: "minecraft:spruce_planks"},
        {pos: [0, 2, 6], state: "minecraft:spruce_planks"},
        {pos: [1, 2, 1], state: "minecraft:stripped_spruce_wood{axis:y}"},
        {pos: [1, 2, 2], state: "minecraft:stripped_spruce_wood{axis:x}"},
        {pos: [1, 2, 3], state: "minecraft:stripped_spruce_wood{axis:x}"},
        {pos: [1, 2, 4], state: "minecraft:stripped_spruce_wood{axis:x}"},
        {pos: [1, 2, 5], state: "minecraft:stripped_spruce_wood{axis:y}"},
        {pos: [2, 2, 1], state: "minecraft:stripped_spruce_wood{axis:y}"},
        {pos: [2, 2, 5], state: "minecraft:stripped_spruce_wood{axis:y}"},
        {pos: [3, 2, 5], state: "minecraft:stripped_spruce_wood{axis:y}"},
        {pos: [4, 2, 1], state: "minecraft:stripped_spruce_wood{axis:y}"},
        {pos: [4, 2, 5], state: "minecraft:stripped_spruce_wood{axis:y}"},
        {pos: [5, 2, 1], state: "minecraft:stripped_spruce_wood{axis:y}"},
        {pos: [5, 2, 2], state: "minecraft:stripped_spruce_wood{axis:x}"},
        {pos: [5, 2, 3], state: "minecraft:stripped_spruce_wood{axis:x}"},
        {pos: [5, 2, 4], state: "minecraft:stripped_spruce_wood{axis:x}"},
        {pos: [5, 2, 5], state: "minecraft:stripped_spruce_wood{axis:y}"},
        {pos: [6, 2, 0], state: "minecraft:spruce_planks"},
        {pos: [6, 2, 1], state: "minecraft:spruce_planks"},
        {pos: [6, 2, 2], state: "minecraft:spruce_planks"},
        {pos: [6, 2, 3], state: "minecraft:spruce_planks"},
        {pos: [6, 2, 4], state: "minecraft:spruce_planks"},
        {pos: [6, 2, 5], state: "minecraft:spruce_planks"},
        {pos: [6, 2, 6], state: "minecraft:spruce_planks"},
        {pos: [1, 3, 0], state: "minecraft:spruce_planks"},
        {pos: [1, 3, 1], state: "minecraft:spruce_planks"},
        {pos: [1, 3, 2], state: "minecraft:spruce_planks"},
        {pos: [1, 3, 4], state: "minecraft:spruce_planks"},
        {pos: [1, 3, 5], state: "minecraft:spruce_planks"},
        {pos: [1, 3, 6], state: "minecraft:spruce_planks"},
        {pos: [2, 3, 1], state: "minecraft:stripped_spruce_wood{axis:y}"},
        {pos: [2, 3, 5], state: "minecraft:stripped_spruce_wood{axis:y}"},
        {pos: [3, 3, 1], state: "minecraft:stripped_spruce_wood{axis:y}"},
        {pos: [4, 3, 1], state: "minecraft:stripped_spruce_wood{axis:y}"},
        {pos: [4, 3, 5], state: "minecraft:stripped_spruce_wood{axis:y}"},
        {pos: [5, 3, 0], state: "minecraft:spruce_planks"},
        {pos: [5, 3, 1], state: "minecraft:spruce_planks"},
        {pos: [5, 3, 2], state: "minecraft:spruce_planks"},
        {pos: [5, 3, 4], state: "minecraft:spruce_planks"},
        {pos: [5, 3, 5], state: "minecraft:spruce_planks"},
        {pos: [5, 3, 6], state: "minecraft:spruce_planks"},
        {pos: [1, 4, 0], state: "minecraft:spruce_planks"},
        {pos: [1, 4, 1], state: "minecraft:spruce_planks"},
        {pos: [1, 4, 2], state: "minecraft:spruce_planks"},
        {pos: [1, 4, 3], state: "minecraft:spruce_planks"},
        {pos: [1, 4, 4], state: "minecraft:spruce_planks"},
        {pos: [1, 4, 5], state: "minecraft:spruce_planks"},
        {pos: [1, 4, 6], state: "minecraft:spruce_planks"},
        {pos: [2, 4, 1], state: "minecraft:stripped_spruce_wood{axis:y}"},
        {pos: [2, 4, 5], state: "minecraft:stripped_spruce_wood{axis:y}"},
        {pos: [3, 4, 1], state: "minecraft:stripped_spruce_wood{axis:y}"},
        {pos: [3, 4, 5], state: "minecraft:stripped_spruce_wood{axis:y}"},
        {pos: [4, 4, 1], state: "minecraft:stripped_spruce_wood{axis:y}"},
        {pos: [4, 4, 5], state: "minecraft:stripped_spruce_wood{axis:y}"},
        {pos: [5, 4, 0], state: "minecraft:spruce_planks"},
        {pos: [5, 4, 1], state: "minecraft:spruce_planks"},
        {pos: [5, 4, 2], state: "minecraft:spruce_planks"},
        {pos: [5, 4, 3], state: "minecraft:spruce_planks"},
        {pos: [5, 4, 4], state: "minecraft:spruce_planks"},
        {pos: [5, 4, 5], state: "minecraft:spruce_planks"},
        {pos: [5, 4, 6], state: "minecraft:spruce_planks"},
        {pos: [2, 5, 0], state: "minecraft:spruce_planks"},
        {pos: [2, 5, 1], state: "minecraft:spruce_planks"},
        {pos: [2, 5, 2], state: "minecraft:spruce_planks"},
        {pos: [2, 5, 3], state: "minecraft:spruce_planks"},
        {pos: [2, 5, 4], state: "minecraft:spruce_planks"},
        {pos: [2, 5, 5], state: "minecraft:spruce_planks"},
        {pos: [2, 5, 6], state: "minecraft:spruce_planks"},
        {pos: [3, 5, 0], state: "minecraft:spruce_slab{waterlogged:false,type:double}"},
        {pos: [3, 5, 1], state: "minecraft:stripped_spruce_wood{axis:y}"},
        {pos: [3, 5, 5], state: "minecraft:stripped_spruce_wood{axis:y}"},
        {pos: [4, 5, 0], state: "minecraft:spruce_planks"},
        {pos: [4, 5, 1], state: "minecraft:spruce_planks"},
        {pos: [4, 5, 2], state: "minecraft:spruce_planks"},
        {pos: [4, 5, 3], state: "minecraft:spruce_planks"},
        {pos: [4, 5, 4], state: "minecraft:cobblestone"},
        {pos: [4, 5, 5], state: "minecraft:spruce_planks"},
        {pos: [4, 5, 6], state: "minecraft:spruce_planks"},
        {pos: [3, 6, 0], state: "minecraft:spruce_planks"},
        {pos: [3, 6, 1], state: "minecraft:spruce_planks"},
        {pos: [3, 6, 2], state: "minecraft:spruce_planks"},
        {pos: [3, 6, 3], state: "minecraft:spruce_planks"},
        {pos: [3, 6, 4], state: "minecraft:spruce_planks"},
        {pos: [3, 6, 5], state: "minecraft:spruce_planks"},
        {pos: [3, 6, 6], state: "minecraft:spruce_planks"},
        {pos: [0, 0, 0], state: "minecraft:snow{layers:1}"},
        {pos: [0, 0, 1], state: "minecraft:snow{layers:1}"},
        {pos: [0, 0, 2], state: "minecraft:snow{layers:1}"},
        {pos: [0, 0, 3], state: "minecraft:snow{layers:1}"},
        {pos: [0, 0, 4], state: "minecraft:snow{layers:1}"},
        {pos: [0, 0, 5], state: "minecraft:snow{layers:1}"},
        {pos: [0, 0, 6], state: "minecraft:snow{layers:1}"},
        {pos: [1, 0, 0], state: "minecraft:snow{layers:1}"},
        {pos: [1, 0, 6], state: "minecraft:snow{layers:1}"},
        {pos: [2, 0, 0], state: "minecraft:spruce_stairs{half:bottom,waterlogged:false,shape:straight,facing:east}"},
        {pos: [2, 0, 6], state: "minecraft:snow{layers:1}"},
        {pos: [3, 0, 6], state: "minecraft:snow{layers:1}"},
        {pos: [4, 0, 0], state: "minecraft:spruce_stairs{half:bottom,waterlogged:false,shape:straight,facing:west}"},
        {pos: [4, 0, 6], state: "minecraft:snow{layers:1}"},
        {pos: [5, 0, 0], state: "minecraft:snow{layers:1}"},
        {pos: [5, 0, 6], state: "minecraft:snow{layers:1}"},
        {pos: [6, 0, 0], state: "minecraft:snow{layers:1}"},
        {pos: [6, 0, 1], state: "minecraft:snow{layers:1}"},
        {pos: [6, 0, 2], state: "minecraft:snow{layers:1}"},
        {pos: [6, 0, 3], state: "minecraft:snow{layers:1}"},
        {pos: [6, 0, 4], state: "minecraft:snow{layers:1}"},
        {pos: [6, 0, 5], state: "minecraft:snow{layers:1}"},
        {pos: [6, 0, 6], state: "minecraft:snow{layers:1}"},
        {pos: [0, 1, 0], state: "minecraft:spruce_slab{waterlogged:false,type:top}"},
        {pos: [0, 1, 2], state: "minecraft:spruce_slab{waterlogged:false,type:top}"},
        {pos: [0, 1, 4], state: "minecraft:spruce_slab{waterlogged:false,type:top}"},
        {pos: [0, 1, 6], state: "minecraft:spruce_slab{waterlogged:false,type:top}"},
        {pos: [1, 1, 0], state: "minecraft:air"},
        {pos: [1, 1, 6], state: "minecraft:air"},
        {pos: [2, 1, 0], state: "minecraft:air"},
        {pos: [2, 1, 2], state: "minecraft:spruce_stairs{half:bottom,waterlogged:false,shape:straight,facing:north}"},
        {pos: [2, 1, 3], state: "minecraft:air"},
        {pos: [2, 1, 4], state: "minecraft:spruce_stairs{half:bottom,waterlogged:false,shape:straight,facing:south}"},
        {pos: [2, 1, 6], state: "minecraft:air"},
        {pos: [3, 1, 0], state: "minecraft:air"},
        {pos: [3, 1, 1], state: "minecraft:spruce_door{hinge:left,half:lower,powered:false,facing:south,open:true}"},
        {pos: [3, 1, 2], state: "minecraft:air"},
        {pos: [3, 1, 3], state: "minecraft:air"},
        {pos: [3, 1, 4], state: "minecraft:air"},
        {pos: [3, 1, 6], state: "minecraft:air"},
        {pos: [4, 1, 0], state: "minecraft:air"},
        {pos: [4, 1, 2], state: "minecraft:air"},
        {pos: [4, 1, 3], state: "minecraft:air"},
        {pos: [4, 1, 6], state: "minecraft:air"},
        {pos: [5, 1, 0], state: "minecraft:air"},
        {pos: [5, 1, 6], state: "minecraft:air"},
        {pos: [6, 1, 0], state: "minecraft:spruce_slab{waterlogged:false,type:top}"},
        {pos: [6, 1, 2], state: "minecraft:spruce_slab{waterlogged:false,type:top}"},
        {pos: [6, 1, 4], state: "minecraft:spruce_slab{waterlogged:false,type:top}"},
        {pos: [6, 1, 6], state: "minecraft:spruce_slab{waterlogged:false,type:top}"},
        {pos: [1, 2, 0], state: "minecraft:air"},
        {pos: [1, 2, 6], state: "minecraft:spruce_slab{waterlogged:false,type:top}"},
        {pos: [2, 2, 0], state: "minecraft:air"},
        {pos: [2, 2, 2], state: "minecraft:air"},
        {pos: [2, 2, 3], state: "minecraft:air"},
        {pos: [2, 2, 4], state: "minecraft:air"},
        {pos: [2, 2, 6], state: "minecraft:air"},
        {pos: [3, 2, 0], state: "minecraft:air"},
        {pos: [3, 2, 1], state: "minecraft:spruce_door{hinge:left,half:upper,powered:false,facing:south,open:true}"},
        {pos: [3, 2, 2], state: "minecraft:air"},
        {pos: [3, 2, 3], state: "minecraft:air"},
        {pos: [3, 2, 4], state: "minecraft:air"},
        {pos: [3, 2, 6], state: "minecraft:air"},
        {pos: [4, 2, 0], state: "minecraft:air"},
        {pos: [4, 2, 2], state: "minecraft:air"},
        {pos: [4, 2, 3], state: "minecraft:air"},
        {pos: [4, 2, 4], state: "minecraft:cobblestone_wall{east:tall,waterlogged:false,south:tall,north:none,west:none,up:true}"},
        {pos: [4, 2, 6], state: "minecraft:air"},
        {pos: [5, 2, 0], state: "minecraft:air"},
        {pos: [5, 2, 6], state: "minecraft:spruce_slab{waterlogged:false,type:top}"},
        {pos: [0, 3, 0], state: "minecraft:spruce_slab{waterlogged:false,type:bottom}"},
        {pos: [0, 3, 1], state: "minecraft:snow{layers:1}"},
        {pos: [0, 3, 2], state: "minecraft:spruce_slab{waterlogged:false,type:bottom}"},
        {pos: [0, 3, 3], state: "minecraft:snow{layers:1}"},
        {pos: [0, 3, 4], state: "minecraft:spruce_slab{waterlogged:false,type:bottom}"},
        {pos: [0, 3, 5], state: "minecraft:snow{layers:1}"},
        {pos: [0, 3, 6], state: "minecraft:spruce_slab{waterlogged:false,type:bottom}"},
        {pos: [1, 3, 3], state: "minecraft:glass_pane{east:false,waterlogged:false,south:true,north:true,west:false}"},
        {pos: [2, 3, 0], state: "minecraft:air"},
        {pos: [2, 3, 2], state: "minecraft:air"},
        {pos: [2, 3, 3], state: "minecraft:air"},
        {pos: [2, 3, 4], state: "minecraft:air"},
        {pos: [2, 3, 6], state: "minecraft:air"},
        {pos: [3, 3, 0], state: "minecraft:air"},
        {pos: [3, 3, 2], state: "minecraft:air"},
        {pos: [3, 3, 3], state: "minecraft:air"},
        {pos: [3, 3, 4], state: "minecraft:air"},
        {pos: [3, 3, 5], state: "minecraft:glass_pane{east:true,waterlogged:false,south:false,north:false,west:true}"},
        {pos: [3, 3, 6], state: "minecraft:air"},
        {pos: [4, 3, 0], state: "minecraft:air"},
        {pos: [4, 3, 2], state: "minecraft:air"},
        {pos: [4, 3, 3], state: "minecraft:air"},
        {pos: [4, 3, 4], state: "minecraft:cobblestone_wall{east:tall,waterlogged:false,south:tall,north:none,west:none,up:true}"},
        {pos: [4, 3, 6], state: "minecraft:air"},
        {pos: [5, 3, 3], state: "minecraft:glass_pane{east:false,waterlogged:false,south:true,north:true,west:false}"},
        {pos: [6, 3, 0], state: "minecraft:spruce_slab{waterlogged:false,type:bottom}"},
        {pos: [6, 3, 1], state: "minecraft:snow{layers:1}"},
        {pos: [6, 3, 2], state: "minecraft:spruce_slab{waterlogged:false,type:bottom}"},
        {pos: [6, 3, 3], state: "minecraft:snow{layers:1}"},
        {pos: [6, 3, 4], state: "minecraft:spruce_slab{waterlogged:false,type:bottom}"},
        {pos: [6, 3, 5], state: "minecraft:snow{layers:1}"},
        {pos: [6, 3, 6], state: "minecraft:spruce_slab{waterlogged:false,type:bottom}"},
        {pos: [0, 4, 0], state: "minecraft:air"},
        {pos: [0, 4, 1], state: "minecraft:air"},
        {pos: [0, 4, 2], state: "minecraft:air"},
        {pos: [0, 4, 3], state: "minecraft:air"},
        {pos: [0, 4, 4], state: "minecraft:air"},
        {pos: [0, 4, 5], state: "minecraft:air"},
        {pos: [0, 4, 6], state: "minecraft:air"},
        {pos: [2, 4, 0], state: "minecraft:spruce_slab{waterlogged:false,type:top}"},
        {pos: [2, 4, 2], state: "minecraft:air"},
        {pos: [2, 4, 3], state: "minecraft:air"},
        {pos: [2, 4, 4], state: "minecraft:air"},
        {pos: [2, 4, 6], state: "minecraft:spruce_slab{waterlogged:false,type:top}"},
        {pos: [3, 4, 0], state: "minecraft:lantern{waterlogged:false,hanging:true}"},
        {pos: [3, 4, 2], state: "minecraft:lantern{waterlogged:false,hanging:true}"},
        {pos: [3, 4, 3], state: "minecraft:air"},
        {pos: [3, 4, 4], state: "minecraft:lantern{waterlogged:false,hanging:true}"},
        {pos: [3, 4, 6], state: "minecraft:air"},
        {pos: [4, 4, 0], state: "minecraft:spruce_slab{waterlogged:false,type:top}"},
        {pos: [4, 4, 2], state: "minecraft:air"},
        {pos: [4, 4, 3], state: "minecraft:air"},
        {pos: [4, 4, 4], state: "minecraft:cobblestone_wall{east:tall,waterlogged:false,south:tall,north:none,west:none,up:true}"},
        {pos: [4, 4, 6], state: "minecraft:spruce_slab{waterlogged:false,type:top}"},
        {pos: [6, 4, 0], state: "minecraft:air"},
        {pos: [6, 4, 1], state: "minecraft:air"},
        {pos: [6, 4, 2], state: "minecraft:air"},
        {pos: [6, 4, 3], state: "minecraft:air"},
        {pos: [6, 4, 4], state: "minecraft:air"},
        {pos: [6, 4, 5], state: "minecraft:air"},
        {pos: [6, 4, 6], state: "minecraft:air"},
        {pos: [0, 5, 0], state: "minecraft:air"},
        {pos: [0, 5, 1], state: "minecraft:air"},
        {pos: [0, 5, 2], state: "minecraft:air"},
        {pos: [0, 5, 3], state: "minecraft:air"},
        {pos: [0, 5, 4], state: "minecraft:air"},
        {pos: [0, 5, 5], state: "minecraft:air"},
        {pos: [0, 5, 6], state: "minecraft:air"},
        {pos: [1, 5, 0], state: "minecraft:snow{layers:1}"},
        {pos: [1, 5, 1], state: "minecraft:snow{layers:1}"},
        {pos: [1, 5, 2], state: "minecraft:snow{layers:1}"},
        {pos: [1, 5, 3], state: "minecraft:spruce_slab{waterlogged:false,type:bottom}"},
        {pos: [1, 5, 4], state: "minecraft:snow{layers:1}"},
        {pos: [1, 5, 5], state: "minecraft:snow{layers:1}"},
        {pos: [1, 5, 6], state: "minecraft:snow{layers:1}"},
        {pos: [3, 5, 2], state: "minecraft:spruce_fence{east:true,waterlogged:false,south:false,north:true,west:true}"},
        {pos: [3, 5, 3], state: "minecraft:air"},
        {pos: [3, 5, 4], state: "minecraft:spruce_fence{east:true,waterlogged:false,south:true,north:false,west:true}"},
        {pos: [3, 5, 6], state: "minecraft:spruce_slab{waterlogged:false,type:top}"},
        {pos: [5, 5, 0], state: "minecraft:snow{layers:1}"},
        {pos: [5, 5, 1], state: "minecraft:snow{layers:1}"},
        {pos: [5, 5, 2], state: "minecraft:snow{layers:1}"},
        {pos: [5, 5, 3], state: "minecraft:spruce_slab{waterlogged:false,type:bottom}"},
        {pos: [5, 5, 4], state: "minecraft:air"},
        {pos: [5, 5, 5], state: "minecraft:snow{layers:1}"},
        {pos: [5, 5, 6], state: "minecraft:snow{layers:1}"},
        {pos: [6, 5, 0], state: "minecraft:air"},
        {pos: [6, 5, 1], state: "minecraft:air"},
        {pos: [6, 5, 2], state: "minecraft:air"},
        {pos: [6, 5, 3], state: "minecraft:air"},
        {pos: [6, 5, 4], state: "minecraft:air"},
        {pos: [6, 5, 5], state: "minecraft:air"},
        {pos: [6, 5, 6], state: "minecraft:air"},
        {pos: [0, 6, 0], state: "minecraft:air"},
        {pos: [0, 6, 1], state: "minecraft:air"},
        {pos: [0, 6, 2], state: "minecraft:air"},
        {pos: [0, 6, 3], state: "minecraft:air"},
        {pos: [0, 6, 4], state: "minecraft:air"},
        {pos: [0, 6, 5], state: "minecraft:air"},
        {pos: [0, 6, 6], state: "minecraft:air"},
        {pos: [1, 6, 0], state: "minecraft:air"},
        {pos: [1, 6, 1], state: "minecraft:air"},
        {pos: [1, 6, 2], state: "minecraft:air"},
        {pos: [1, 6, 3], state: "minecraft:air"},
        {pos: [1, 6, 4], state: "minecraft:air"},
        {pos: [1, 6, 5], state: "minecraft:air"},
        {pos: [1, 6, 6], state: "minecraft:air"},
        {pos: [2, 6, 0], state: "minecraft:snow{layers:1}"},
        {pos: [2, 6, 1], state: "minecraft:snow{layers:1}"},
        {pos: [2, 6, 2], state: "minecraft:snow{layers:1}"},
        {pos: [2, 6, 3], state: "minecraft:snow{layers:1}"},
        {pos: [2, 6, 4], state: "minecraft:snow{layers:1}"},
        {pos: [2, 6, 5], state: "minecraft:snow{layers:1}"},
        {pos: [2, 6, 6], state: "minecraft:snow{layers:1}"},
        {pos: [4, 6, 0], state: "minecraft:snow{layers:1}"},
        {pos: [4, 6, 1], state: "minecraft:snow{layers:1}"},
        {pos: [4, 6, 2], state: "minecraft:snow{layers:1}"},
        {pos: [4, 6, 3], state: "minecraft:snow{layers:1}"},
        {pos: [4, 6, 4], state: "minecraft:cobblestone_wall{east:none,waterlogged:false,south:none,north:none,west:low,up:true}"},
        {pos: [4, 6, 5], state: "minecraft:snow{layers:1}"},
        {pos: [4, 6, 6], state: "minecraft:snow{layers:1}"},
        {pos: [5, 6, 0], state: "minecraft:air"},
        {pos: [5, 6, 1], state: "minecraft:air"},
        {pos: [5, 6, 2], state: "minecraft:air"},
        {pos: [5, 6, 3], state: "minecraft:air"},
        {pos: [5, 6, 4], state: "minecraft:air"},
        {pos: [5, 6, 5], state: "minecraft:air"},
        {pos: [5, 6, 6], state: "minecraft:air"},
        {pos: [6, 6, 0], state: "minecraft:air"},
        {pos: [6, 6, 1], state: "minecraft:air"},
        {pos: [6, 6, 2], state: "minecraft:air"},
        {pos: [6, 6, 3], state: "minecraft:air"},
        {pos: [6, 6, 4], state: "minecraft:air"},
        {pos: [6, 6, 5], state: "minecraft:air"},
        {pos: [6, 6, 6], state: "minecraft:air"},
        {pos: [0, 7, 0], state: "minecraft:air"},
        {pos: [0, 7, 1], state: "minecraft:air"},
        {pos: [0, 7, 2], state: "minecraft:air"},
        {pos: [0, 7, 3], state: "minecraft:air"},
        {pos: [0, 7, 4], state: "minecraft:air"},
        {pos: [0, 7, 5], state: "minecraft:air"},
        {pos: [0, 7, 6], state: "minecraft:air"},
        {pos: [1, 7, 0], state: "minecraft:air"},
        {pos: [1, 7, 1], state: "minecraft:air"},
        {pos: [1, 7, 2], state: "minecraft:air"},
        {pos: [1, 7, 3], state: "minecraft:air"},
        {pos: [1, 7, 4], state: "minecraft:air"},
        {pos: [1, 7, 5], state: "minecraft:air"},
        {pos: [1, 7, 6], state: "minecraft:air"},
        {pos: [2, 7, 0], state: "minecraft:air"},
        {pos: [2, 7, 1], state: "minecraft:air"},
        {pos: [2, 7, 2], state: "minecraft:air"},
        {pos: [2, 7, 3], state: "minecraft:air"},
        {pos: [2, 7, 4], state: "minecraft:air"},
        {pos: [2, 7, 5], state: "minecraft:air"},
        {pos: [2, 7, 6], state: "minecraft:air"},
        {pos: [3, 7, 0], state: "minecraft:snow{layers:1}"},
        {pos: [3, 7, 1], state: "minecraft:snow{layers:1}"},
        {pos: [3, 7, 2], state: "minecraft:snow{layers:1}"},
        {pos: [3, 7, 3], state: "minecraft:snow{layers:1}"},
        {pos: [3, 7, 4], state: "minecraft:snow{layers:1}"},
        {pos: [3, 7, 5], state: "minecraft:snow{layers:1}"},
        {pos: [3, 7, 6], state: "minecraft:snow{layers:1}"},
        {pos: [4, 7, 0], state: "minecraft:air"},
        {pos: [4, 7, 1], state: "minecraft:air"},
        {pos: [4, 7, 2], state: "minecraft:air"},
        {pos: [4, 7, 3], state: "minecraft:air"},
        {pos: [4, 7, 4], state: "minecraft:cobblestone_wall{east:none,waterlogged:false,south:none,north:none,west:none,up:true}"},
        {pos: [4, 7, 5], state: "minecraft:air"},
        {pos: [4, 7, 6], state: "minecraft:air"},
        {pos: [5, 7, 0], state: "minecraft:air"},
        {pos: [5, 7, 1], state: "minecraft:air"},
        {pos: [5, 7, 2], state: "minecraft:air"},
        {pos: [5, 7, 3], state: "minecraft:air"},
        {pos: [5, 7, 4], state: "minecraft:air"},
        {pos: [5, 7, 5], state: "minecraft:air"},
        {pos: [5, 7, 6], state: "minecraft:air"},
        {pos: [6, 7, 0], state: "minecraft:air"},
        {pos: [6, 7, 1], state: "minecraft:air"},
        {pos: [6, 7, 2], state: "minecraft:air"},
        {pos: [6, 7, 3], state: "minecraft:air"},
        {pos: [6, 7, 4], state: "minecraft:air"},
        {pos: [6, 7, 5], state: "minecraft:air"},
        {pos: [6, 7, 6], state: "minecraft:air"},
        {pos: [3, 0, 0], state: "minecraft:jigsaw{orientation:north_up}", nbt: {final_state: "minecraft:spruce_stairs[facing=south]", id: "minecraft:jigsaw", joint: "aligned", name: "minecraft:building_entrance", pool: "minecraft:empty", target: "minecraft:building_entrance"}},
        {pos: [4, 1, 4], state: "minecraft:blast_furnace{lit:false,facing:north}", nbt: {Items: [], RecipesUsed: {}, cooking_time_spent: 0s, cooking_total_time: 0s, id: "minecraft:blast_furnace", lit_time_remaining: 0s, lit_total_time: 0s}}
    ],
    entities: [],
    palette: [
        "minecraft:stripped_spruce_wood{axis:y}",
        "minecraft:spruce_planks",
        "minecraft:cobblestone",
        "minecraft:stripped_spruce_wood{axis:x}",
        "minecraft:spruce_slab{waterlogged:false,type:double}",
        "minecraft:snow{layers:1}",
        "minecraft:spruce_stairs{half:bottom,waterlogged:false,shape:straight,facing:east}",
        "minecraft:spruce_stairs{half:bottom,waterlogged:false,shape:straight,facing:west}",
        "minecraft:spruce_slab{waterlogged:false,type:top}",
        "minecraft:air",
        "minecraft:spruce_stairs{half:bottom,waterlogged:false,shape:straight,facing:north}",
        "minecraft:spruce_stairs{half:bottom,waterlogged:false,shape:straight,facing:south}",
        "minecraft:spruce_door{hinge:left,half:lower,powered:false,facing:south,open:true}",
        "minecraft:spruce_door{hinge:left,half:upper,powered:false,facing:south,open:true}",
        "minecraft:cobblestone_wall{east:tall,waterlogged:false,south:tall,north:none,west:none,up:true}",
        "minecraft:spruce_slab{waterlogged:false,type:bottom}",
        "minecraft:glass_pane{east:false,waterlogged:false,south:true,north:true,west:false}",
        "minecraft:glass_pane{east:true,waterlogged:false,south:false,north:false,west:true}",
        "minecraft:lantern{waterlogged:false,hanging:true}",
        "minecraft:spruce_fence{east:true,waterlogged:false,south:false,north:true,west:true}",
        "minecraft:spruce_fence{east:true,waterlogged:false,south:true,north:false,west:true}",
        "minecraft:cobblestone_wall{east:none,waterlogged:false,south:none,north:none,west:low,up:true}",
        "minecraft:cobblestone_wall{east:none,waterlogged:false,south:none,north:none,west:none,up:true}",
        "minecraft:jigsaw{orientation:north_up}",
        "minecraft:blast_furnace{lit:false,facing:north}"
    ]
}