{
    size: [9, 5, 10],
    data: [
        {pos: [0, 0, 0], state: "minecraft:stripped_spruce_log{axis:y}"},
        {pos: [0, 0, 1], state: "minecraft:stripped_spruce_log{axis:y}"},
        {pos: [0, 0, 2], state: "minecraft:stripped_spruce_log{axis:y}"},
        {pos: [0, 0, 3], state: "minecraft:stripped_spruce_log{axis:y}"},
        {pos: [0, 0, 4], state: "minecraft:stripped_spruce_log{axis:y}"},
        {pos: [0, 0, 5], state: "minecraft:stripped_spruce_log{axis:y}"},
        {pos: [1, 0, 0], state: "minecraft:stripped_spruce_log{axis:y}"},
        {pos: [1, 0, 1], state: "minecraft:grass_block{snowy:false}"},
        {pos: [1, 0, 3], state: "minecraft:grass_block{snowy:false}"},
        {pos: [1, 0, 4], state: "minecraft:grass_block{snowy:false}"},
        {pos: [1, 0, 5], state: "minecraft:grass_block{snowy:false}"},
        {pos: [1, 0, 6], state: "minecraft:stripped_spruce_log{axis:y}"},
        {pos: [1, 0, 7], state: "minecraft:stripped_spruce_log{axis:y}"},
        {pos: [1, 0, 8], state: "minecraft:stripped_spruce_log{axis:y}"},
        {pos: [2, 0, 0], state: "minecraft:stripped_spruce_log{axis:y}"},
        {pos: [2, 0, 1], state: "minecraft:grass_block{snowy:false}"},
        {pos: [2, 0, 2], state: "minecraft:grass_block{snowy:false}"},
        {pos: [2, 0, 3], state: "minecraft:grass_block{snowy:false}"},
        {pos: [2, 0, 4], state: "minecraft:grass_block{snowy:false}"},
        {pos: [2, 0, 5], state: "minecraft:grass_block{snowy:false}"},
        {pos: [2, 0, 6], state: "minecraft:stripped_spruce_log{axis:y}"},
        {pos: [2, 0, 7], state: "minecraft:spruce_planks"},
        {pos: [2, 0, 8], state: "minecraft:stripped_spruce_log{axis:y}"},
        {pos: [3, 0, 0], state: "minecraft:stripped_spruce_log{axis:y}"},
        {pos: [3, 0, 1], state: "minecraft:grass_block{snowy:false}"},
        {pos: [3, 0, 2], state: "minecraft:grass_block{snowy:false}"},
        {pos: [3, 0, 3], state: "minecraft:grass_block{snowy:false}"},
        {pos: [3, 0, 4], state: "minecraft:grass_block{snowy:false}"},
        {pos: [3, 0, 5], state: "minecraft:grass_block{snowy:false}"},
        {pos: [3, 0, 6], state: "minecraft:stripped_spruce_log{axis:y}"},
        {pos: [3, 0, 7], state: "minecraft:spruce_planks"},
        {pos: [3, 0, 8], state: "minecraft:stripped_spruce_log{axis:y}"},
        {pos: [4, 0, 1], state: "minecraft:stripped_spruce_log{axis:y}"},
        {pos: [4, 0, 2], state: "minecraft:stripped_spruce_log{axis:y}"},
        {pos: [4, 0, 3], state: "minecraft:stripped_spruce_log{axis:y}"},
        {pos: [4, 0, 4], state: "minecraft:stripped_spruce_log{axis:y}"},
        {pos: [4, 0, 5], state: "minecraft:stripped_spruce_log{axis:y}"},
        {pos: [4, 0, 6], state: "minecraft:spruce_planks"},
        {pos: [4, 0, 7], state: "minecraft:spruce_planks"},
        {pos: [4, 0, 8], state: "minecraft:stripped_spruce_log{axis:y}"},
        {pos: [5, 0, 1], state: "minecraft:stripped_spruce_log{axis:y}"},
        {pos: [5, 0, 2], state: "minecraft:spruce_planks"},
        {pos: [5, 0, 3], state: "minecraft:spruce_planks"},
        {pos: [5, 0, 4], state: "minecraft:spruce_planks"},
        {pos: [5, 0, 5], state: "minecraft:spruce_planks"},
        {pos: [5, 0, 6], state: "minecraft:spruce_planks"},
        {pos: [5, 0, 7], state: "minecraft:spruce_planks"},
        {pos: [5, 0, 8], state: "minecraft:stripped_spruce_log{axis:y}"},
        {pos: [6, 0, 1], state: "minecraft:stripped_spruce_log{axis:y}"},
        {pos: [6, 0, 2], state: "minecraft:spruce_planks"},
        {pos: [6, 0, 3], state: "minecraft:spruce_planks"},
        {pos: [6, 0, 4], state: "minecraft:spruce_planks"},
        {pos: [6, 0, 5], state: "minecraft:spruce_planks"},
        {pos: [6, 0, 6], state: "minecraft:spruce_planks"},
        {pos: [6, 0, 7], state: "minecraft:spruce_planks"},
        {pos: [6, 0, 8], state: "minecraft:stripped_spruce_log{axis:y}"},
        {pos: [7, 0, 1], state: "minecraft:stripped_spruce_log{axis:y}"},
        {pos: [7, 0, 2], state: "minecraft:stripped_spruce_log{axis:y}"},
        {pos: [7, 0, 3], state: "minecraft:stripped_spruce_log{axis:y}"},
        {pos: [7, 0, 4], state: "minecraft:stripped_spruce_log{axis:y}"},
        {pos: [7, 0, 5], state: "minecraft:stripped_spruce_log{axis:y}"},
        {pos: [7, 0, 6], state: "minecraft:stripped_spruce_log{axis:y}"},
        {pos: [7, 0, 7], state: "minecraft:stripped_spruce_log{axis:y}"},
        {pos: [7, 0, 8], state: "minecraft:stripped_spruce_log{axis:y}"},
        {pos: [0, 1, 5], state: "minecraft:spruce_planks"},
        {pos: [0, 1, 9], state: "minecraft:spruce_planks"},
        {pos: [1, 1, 6], state: "minecraft:stripped_spruce_log{axis:y}"},
        {pos: [1, 1, 8], state: "minecraft:stripped_spruce_log{axis:y}"},
        {pos: [1, 1, 9], state: "minecraft:spruce_planks"},
        {pos: [2, 1, 6], state: "minecraft:stripped_spruce_log{axis:y}"},
        {pos: [2, 1, 8], state: "minecraft:stripped_spruce_log{axis:y}"},
        {pos: [2, 1, 9], state: "minecraft:spruce_planks"},
        {pos: [3, 1, 0], state: "minecraft:spruce_planks"},
        {pos: [3, 1, 6], state: "minecraft:stripped_spruce_log{axis:y}"},
        {pos: [3, 1, 8], state: "minecraft:stripped_spruce_log{axis:y}"},
        {pos: [3, 1, 9], state: "minecraft:spruce_planks"},
        {pos: [4, 1, 1], state: "minecraft:stripped_spruce_log{axis:y}"},
        {pos: [4, 1, 2], state: "minecraft:stripped_spruce_log{axis:y}"},
        {pos: [4, 1, 4], state: "minecraft:stripped_spruce_log{axis:y}"},
        {pos: [4, 1, 5], state: "minecraft:stripped_spruce_log{axis:y}"},
        {pos: [4, 1, 8], state: "minecraft:stripped_spruce_log{axis:y}"},
        {pos: [4, 1, 9], state: "minecraft:spruce_planks"},
        {pos: [5, 1, 1], state: "minecraft:stripped_spruce_log{axis:y}"},
        {pos: [5, 1, 2], state: "minecraft:loom{facing:north}"},
        {pos: [5, 1, 8], state: "minecraft:stripped_spruce_log{axis:y}"},
        {pos: [5, 1, 9], state: "minecraft:spruce_planks"},
        {pos: [6, 1, 1], state: "minecraft:stripped_spruce_log{axis:y}"},
        {pos: [6, 1, 2], state: "minecraft:loom{facing:north}"},
        {pos: [6, 1, 8], state: "minecraft:stripped_spruce_log{axis:y}"},
        {pos: [6, 1, 9], state: "minecraft:spruce_planks"},
        {pos: [7, 1, 1], state: "minecraft:stripped_spruce_log{axis:y}"},
        {pos: [7, 1, 2], state: "minecraft:stripped_spruce_log{axis:y}"},
        {pos: [7, 1, 3], state: "minecraft:stripped_spruce_log{axis:y}"},
        {pos: [7, 1, 4], state: "minecraft:stripped_spruce_log{axis:y}"},
        {pos: [7, 1, 5], state: "minecraft:stripped_spruce_log{axis:y}"},
        {pos: [7, 1, 6], state: "minecraft:stripped_spruce_log{axis:y}"},
        {pos: [7, 1, 7], state: "minecraft:stripped_spruce_log{axis:y}"},
        {pos: [7, 1, 8], state: "minecraft:stripped_spruce_log{axis:y}"},
        {pos: [7, 1, 9], state: "minecraft:spruce_planks"},
        {pos: [8, 1, 0], state: "minecraft:spruce_planks"},
        {pos: [8, 1, 1], state: "minecraft:spruce_planks"},
        {pos: [8, 1, 2], state: "minecraft:spruce_planks"},
        {pos: [8, 1, 3], state: "minecraft:spruce_planks"},
        {pos: [8, 1, 4], state: "minecraft:spruce_planks"},
        {pos: [8, 1, 5], state: "minecraft:spruce_planks"},
        {pos: [8, 1, 9], state: "minecraft:spruce_planks"},
        {pos: [0, 2, 5], state: "minecraft:spruce_planks"},
        {pos: [0, 2, 9], state: "minecraft:spruce_planks"},
        {pos: [1, 2, 6], state: "minecraft:stripped_spruce_log{axis:y}"},
        {pos: [1, 2, 8], state: "minecraft:stripped_spruce_log{axis:y}"},
        {pos: [1, 2, 9], state: "minecraft:spruce_planks"},
        {pos: [2, 2, 6], state: "minecraft:stripped_spruce_log{axis:y}"},
        {pos: [2, 2, 8], state: "minecraft:stripped_spruce_log{axis:y}"},
        {pos: [2, 2, 9], state: "minecraft:spruce_planks"},
        {pos: [3, 2, 0], state: "minecraft:spruce_planks"},
        {pos: [3, 2, 6], state: "minecraft:stripped_spruce_log{axis:y}"},
        {pos: [3, 2, 8], state: "minecraft:stripped_spruce_log{axis:y}"},
        {pos: [3, 2, 9], state: "minecraft:spruce_planks"},
        {pos: [4, 2, 1], state: "minecraft:stripped_spruce_log{axis:y}"},
        {pos: [4, 2, 2], state: "minecraft:stripped_spruce_log{axis:y}"},
        {pos: [4, 2, 4], state: "minecraft:stripped_spruce_log{axis:y}"},
        {pos: [4, 2, 5], state: "minecraft:stripped_spruce_log{axis:y}"},
        {pos: [4, 2, 8], state: "minecraft:stripped_spruce_log{axis:y}"},
        {pos: [4, 2, 9], state: "minecraft:spruce_planks"},
        {pos: [5, 2, 1], state: "minecraft:stripped_spruce_log{axis:y}"},
        {pos: [5, 2, 8], state: "minecraft:stripped_spruce_log{axis:y}"},
        {pos: [5, 2, 9], state: "minecraft:spruce_planks"},
        {pos: [6, 2, 1], state: "minecraft:stripped_spruce_log{axis:y}"},
        {pos: [6, 2, 8], state: "minecraft:stripped_spruce_log{axis:y}"},
        {pos: [6, 2, 9], state: "minecraft:spruce_planks"},
        {pos: [7, 2, 1], state: "minecraft:stripped_spruce_log{axis:y}"},
        {pos: [7, 2, 2], state: "minecraft:stripped_spruce_log{axis:y}"},
        {pos: [7, 2, 3], state: "minecraft:stripped_spruce_log{axis:y}"},
        {pos: [7, 2, 4], state: "minecraft:stripped_spruce_log{axis:y}"},
        {pos: [7, 2, 5], state: "minecraft:stripped_spruce_log{axis:y}"},
        {pos: [7, 2, 6], state: "minecraft:stripped_spruce_log{axis:y}"},
        {pos: [7, 2, 7], state: "minecraft:stripped_spruce_log{axis:y}"},
        {pos: [7, 2, 8], state: "minecraft:stripped_spruce_log{axis:y}"},
        {pos: [7, 2, 9], state: "minecraft:spruce_planks"},
        {pos: [8, 2, 0], state: "minecraft:spruce_planks"},
        {pos: [8, 2, 1], state: "minecraft:spruce_planks"},
        {pos: [8, 2, 2], state: "minecraft:spruce_planks"},
        {pos: [8, 2, 3], state: "minecraft:spruce_planks"},
        {pos: [8, 2, 4], state: "minecraft:spruce_planks"},
        {pos: [8, 2, 5], state: "minecraft:spruce_planks"},
        {pos: [8, 2, 9], state: "minecraft:spruce_planks"},
        {pos: [0, 3, 6], state: "minecraft:spruce_planks"},
        {pos: [0, 3, 8], state: "minecraft:spruce_planks"},
        {pos: [1, 3, 6], state: "minecraft:spruce_planks"},
        {pos: [1, 3, 7], state: "minecraft:stripped_spruce_log{axis:z}"},
        {pos: [1, 3, 8], state: "minecraft:spruce_planks"},
        {pos: [2, 3, 6], state: "minecraft:spruce_planks"},
        {pos: [2, 3, 8], state: "minecraft:spruce_planks"},
        {pos: [3, 3, 6], state: "minecraft:spruce_planks"},
        {pos: [3, 3, 8], state: "minecraft:spruce_planks"},
        {pos: [4, 3, 0], state: "minecraft:spruce_planks"},
        {pos: [4, 3, 1], state: "minecraft:spruce_planks"},
        {pos: [4, 3, 2], state: "minecraft:spruce_planks"},
        {pos: [4, 3, 3], state: "minecraft:spruce_planks"},
        {pos: [4, 3, 4], state: "minecraft:spruce_planks"},
        {pos: [4, 3, 5], state: "minecraft:spruce_planks"},
        {pos: [4, 3, 6], state: "minecraft:spruce_planks"},
        {pos: [4, 3, 8], state: "minecraft:spruce_planks"},
        {pos: [5, 3, 1], state: "minecraft:stripped_spruce_log{axis:y}"},
        {pos: [5, 3, 6], state: "minecraft:spruce_planks"},
        {pos: [5, 3, 8], state: "minecraft:spruce_planks"},
        {pos: [6, 3, 1], state: "minecraft:stripped_spruce_log{axis:y}"},
        {pos: [6, 3, 6], state: "minecraft:spruce_planks"},
        {pos: [6, 3, 8], state: "minecraft:spruce_planks"},
        {pos: [7, 3, 0], state: "minecraft:spruce_planks"},
        {pos: [7, 3, 1], state: "minecraft:spruce_planks"},
        {pos: [7, 3, 2], state: "minecraft:spruce_planks"},
        {pos: [7, 3, 3], state: "minecraft:spruce_planks"},
        {pos: [7, 3, 4], state: "minecraft:spruce_planks"},
        {pos: [7, 3, 5], state: "minecraft:spruce_planks"},
        {pos: [7, 3, 6], state: "minecraft:spruce_planks"},
        {pos: [7, 3, 7], state: "minecraft:stripped_spruce_log{axis:y}"},
        {pos: [7, 3, 8], state: "minecraft:spruce_planks"},
        {pos: [8, 3, 6], state: "minecraft:spruce_planks"},
        {pos: [8, 3, 8], state: "minecraft:spruce_planks"},
        {pos: [0, 4, 7], state: "minecraft:spruce_planks"},
        {pos: [1, 4, 7], state: "minecraft:spruce_planks"},
        {pos: [2, 4, 7], state: "minecraft:spruce_planks"},
        {pos: [3, 4, 7], state: "minecraft:spruce_planks"},
        {pos: [4, 4, 7], state: "minecraft:spruce_planks"},
        {pos: [5, 4, 0], state: "minecraft:spruce_planks"},
        {pos: [5, 4, 1], state: "minecraft:spruce_planks"},
        {pos: [5, 4, 2], state: "minecraft:spruce_planks"},
        {pos: [5, 4, 3], state: "minecraft:spruce_planks"},
        {pos: [5, 4, 4], state: "minecraft:spruce_planks"},
        {pos: [5, 4, 5], state: "minecraft:spruce_planks"},
        {pos: [5, 4, 6], state: "minecraft:spruce_planks"},
        {pos: [5, 4, 7], state: "minecraft:spruce_planks"},
        {pos: [6, 4, 0], state: "minecraft:spruce_planks"},
        {pos: [6, 4, 1], state: "minecraft:spruce_planks"},
        {pos: [6, 4, 2], state: "minecraft:spruce_planks"},
        {pos: [6, 4, 3], state: "minecraft:spruce_planks"},
        {pos: [6, 4, 4], state: "minecraft:spruce_planks"},
        {pos: [6, 4, 5], state: "minecraft:spruce_planks"},
        {pos: [6, 4, 6], state: "minecraft:spruce_planks"},
        {pos: [6, 4, 7], state: "minecraft:spruce_planks"},
        {pos: [7, 4, 7], state: "minecraft:spruce_planks"},
        {pos: [8, 4, 7], state: "minecraft:spruce_planks"},
        {pos: [0, 0, 7], state: "minecraft:spruce_stairs{half:bottom,waterlogged:false,shape:straight,facing:east}"},
        {pos: [0, 0, 8], state: "minecraft:snow{layers:1}"},
        {pos: [0, 0, 9], state: "minecraft:snow{layers:1}"},
        {pos: [1, 0, 9], state: "minecraft:snow{layers:1}"},
        {pos: [2, 0, 9], state: "minecraft:snow{layers:1}"},
        {pos: [3, 0, 9], state: "minecraft:snow{layers:1}"},
        {pos: [4, 0, 0], state: "minecraft:snow{layers:1}"},
        {pos: [4, 0, 9], state: "minecraft:snow{layers:1}"},
        {pos: [5, 0, 0], state: "minecraft:snow{layers:1}"},
        {pos: [5, 0, 9], state: "minecraft:snow{layers:1}"},
        {pos: [6, 0, 0], state: "minecraft:snow{layers:1}"},
        {pos: [6, 0, 9], state: "minecraft:snow{layers:1}"},
        {pos: [7, 0, 0], state: "minecraft:snow{layers:1}"},
        {pos: [7, 0, 9], state: "minecraft:snow{layers:1}"},
        {pos: [8, 0, 0], state: "minecraft:snow{layers:1}"},
        {pos: [8, 0, 1], state: "minecraft:snow{layers:1}"},
        {pos: [8, 0, 2], state: "minecraft:snow{layers:1}"},
        {pos: [8, 0, 3], state: "minecraft:snow{layers:1}"},
        {pos: [8, 0, 4], state: "minecraft:snow{layers:1}"},
        {pos: [8, 0, 5], state: "minecraft:snow{layers:1}"},
        {pos: [8, 0, 6], state: "minecraft:snow{layers:1}"},
        {pos: [8, 0, 7], state: "minecraft:snow{layers:1}"},
        {pos: [8, 0, 8], state: "minecraft:short_grass"},
        {pos: [8, 0, 9], state: "minecraft:snow{layers:1}"},
        {pos: [0, 1, 0], state: "minecraft:spruce_fence{east:true,waterlogged:false,south:true,north:false,west:false}"},
        {pos: [0, 1, 1], state: "minecraft:spruce_fence{east:false,waterlogged:false,south:true,north:true,west:false}"},
        {pos: [0, 1, 2], state: "minecraft:spruce_fence{east:false,waterlogged:false,south:true,north:true,west:false}"},
        {pos: [0, 1, 3], state: "minecraft:spruce_fence{east:false,waterlogged:false,south:true,north:true,west:false}"},
        {pos: [0, 1, 4], state: "minecraft:spruce_fence{east:false,waterlogged:false,south:true,north:true,west:false}"},
        {pos: [0, 1, 6], state: "minecraft:air"},
        {pos: [0, 1, 7], state: "minecraft:air"},
        {pos: [0, 1, 8], state: "minecraft:air"},
        {pos: [1, 1, 0], state: "minecraft:spruce_fence{east:true,waterlogged:false,south:false,north:false,west:true}"},
        {pos: [1, 1, 1], state: "minecraft:air"},
        {pos: [1, 1, 2], state: "minecraft:air"},
        {pos: [1, 1, 3], state: "minecraft:air"},
        {pos: [1, 1, 4], state: "minecraft:air"},
        {pos: [1, 1, 5], state: "minecraft:air"},
        {pos: [1, 1, 7], state: "minecraft:spruce_door{hinge:left,half:lower,powered:false,facing:east,open:false}"},
        {pos: [2, 1, 0], state: "minecraft:spruce_fence{east:true,waterlogged:false,south:false,north:false,west:true}"},
        {pos: [2, 1, 1], state: "minecraft:air"},
        {pos: [2, 1, 2], state: "minecraft:air"},
        {pos: [2, 1, 3], state: "minecraft:air"},
        {pos: [2, 1, 4], state: "minecraft:air"},
        {pos: [2, 1, 5], state: "minecraft:air"},
        {pos: [2, 1, 7], state: "minecraft:air"},
        {pos: [3, 1, 1], state: "minecraft:air"},
        {pos: [3, 1, 2], state: "minecraft:air"},
        {pos: [3, 1, 3], state: "minecraft:air"},
        {pos: [3, 1, 4], state: "minecraft:air"},
        {pos: [3, 1, 5], state: "minecraft:air"},
        {pos: [3, 1, 7], state: "minecraft:air"},
        {pos: [4, 1, 0], state: "minecraft:air"},
        {pos: [4, 1, 3], state: "minecraft:spruce_door{hinge:right,half:lower,powered:false,facing:east,open:false}"},
        {pos: [4, 1, 6], state: "minecraft:air"},
        {pos: [4, 1, 7], state: "minecraft:air"},
        {pos: [5, 1, 0], state: "minecraft:air"},
        {pos: [5, 1, 3], state: "minecraft:air"},
        {pos: [5, 1, 4], state: "minecraft:air"},
        {pos: [5, 1, 5], state: "minecraft:air"},
        {pos: [5, 1, 6], state: "minecraft:air"},
        {pos: [5, 1, 7], state: "minecraft:air"},
        {pos: [6, 1, 0], state: "minecraft:air"},
        {pos: [6, 1, 3], state: "minecraft:air"},
        {pos: [6, 1, 4], state: "minecraft:air"},
        {pos: [6, 1, 5], state: "minecraft:air"},
        {pos: [6, 1, 6], state: "minecraft:air"},
        {pos: [7, 1, 0], state: "minecraft:air"},
        {pos: [8, 1, 6], state: "minecraft:air"},
        {pos: [8, 1, 7], state: "minecraft:air"},
        {pos: [8, 1, 8], state: "minecraft:air"},
        {pos: [0, 2, 0], state: "minecraft:lantern{waterlogged:false,hanging:false}"},
        {pos: [0, 2, 1], state: "minecraft:air"},
        {pos: [0, 2, 2], state: "minecraft:air"},
        {pos: [0, 2, 3], state: "minecraft:air"},
        {pos: [0, 2, 4], state: "minecraft:air"},
        {pos: [0, 2, 6], state: "minecraft:air"},
        {pos: [0, 2, 7], state: "minecraft:air"},
        {pos: [0, 2, 8], state: "minecraft:air"},
        {pos: [1, 2, 0], state: "minecraft:air"},
        {pos: [1, 2, 1], state: "minecraft:air"},
        {pos: [1, 2, 2], state: "minecraft:air"},
        {pos: [1, 2, 3], state: "minecraft:air"},
        {pos: [1, 2, 4], state: "minecraft:air"},
        {pos: [1, 2, 5], state: "minecraft:air"},
        {pos: [1, 2, 7], state: "minecraft:spruce_door{hinge:left,half:upper,powered:false,facing:east,open:false}"},
        {pos: [2, 2, 0], state: "minecraft:air"},
        {pos: [2, 2, 1], state: "minecraft:air"},
        {pos: [2, 2, 2], state: "minecraft:air"},
        {pos: [2, 2, 3], state: "minecraft:air"},
        {pos: [2, 2, 4], state: "minecraft:air"},
        {pos: [2, 2, 5], state: "minecraft:lantern{waterlogged:false,hanging:true}"},
        {pos: [2, 2, 7], state: "minecraft:air"},
        {pos: [3, 2, 1], state: "minecraft:air"},
        {pos: [3, 2, 2], state: "minecraft:air"},
        {pos: [3, 2, 3], state: "minecraft:air"},
        {pos: [3, 2, 4], state: "minecraft:air"},
        {pos: [3, 2, 5], state: "minecraft:air"},
        {pos: [3, 2, 7], state: "minecraft:air"},
        {pos: [4, 2, 0], state: "minecraft:air"},
        {pos: [4, 2, 3], state: "minecraft:spruce_door{hinge:right,half:upper,powered:false,facing:east,open:false}"},
        {pos: [4, 2, 6], state: "minecraft:air"},
        {pos: [4, 2, 7], state: "minecraft:air"},
        {pos: [5, 2, 0], state: "minecraft:air"},
        {pos: [5, 2, 2], state: "minecraft:air"},
        {pos: [5, 2, 3], state: "minecraft:air"},
        {pos: [5, 2, 4], state: "minecraft:air"},
        {pos: [5, 2, 5], state: "minecraft:air"},
        {pos: [5, 2, 6], state: "minecraft:air"},
        {pos: [5, 2, 7], state: "minecraft:wall_torch{facing:north}"},
        {pos: [6, 2, 0], state: "minecraft:air"},
        {pos: [6, 2, 2], state: "minecraft:air"},
        {pos: [6, 2, 3], state: "minecraft:wall_torch{facing:west}"},
        {pos: [6, 2, 4], state: "minecraft:air"},
        {pos: [6, 2, 5], state: "minecraft:air"},
        {pos: [6, 2, 6], state: "minecraft:air"},
        {pos: [6, 2, 7], state: "minecraft:air"},
        {pos: [7, 2, 0], state: "minecraft:air"},
        {pos: [8, 2, 6], state: "minecraft:air"},
        {pos: [8, 2, 7], state: "minecraft:air"},
        {pos: [8, 2, 8], state: "minecraft:air"},
        {pos: [0, 3, 0], state: "minecraft:air"},
        {pos: [0, 3, 1], state: "minecraft:air"},
        {pos: [0, 3, 2], state: "minecraft:air"},
        {pos: [0, 3, 3], state: "minecraft:air"},
        {pos: [0, 3, 4], state: "minecraft:air"},
        {pos: [0, 3, 5], state: "minecraft:spruce_slab{waterlogged:false,type:bottom}"},
        {pos: [0, 3, 7], state: "minecraft:lantern{waterlogged:false,hanging:true}"},
        {pos: [0, 3, 9], state: "minecraft:spruce_slab{waterlogged:false,type:bottom}"},
        {pos: [1, 3, 0], state: "minecraft:air"},
        {pos: [1, 3, 1], state: "minecraft:air"},
        {pos: [1, 3, 2], state: "minecraft:air"},
        {pos: [1, 3, 3], state: "minecraft:air"},
        {pos: [1, 3, 4], state: "minecraft:air"},
        {pos: [1, 3, 5], state: "minecraft:spruce_slab{waterlogged:false,type:bottom}"},
        {pos: [1, 3, 9], state: "minecraft:air"},
        {pos: [2, 3, 0], state: "minecraft:air"},
        {pos: [2, 3, 1], state: "minecraft:air"},
        {pos: [2, 3, 2], state: "minecraft:air"},
        {pos: [2, 3, 3], state: "minecraft:air"},
        {pos: [2, 3, 4], state: "minecraft:air"},
        {pos: [2, 3, 5], state: "minecraft:spruce_slab{waterlogged:false,type:bottom}"},
        {pos: [2, 3, 7], state: "minecraft:air"},
        {pos: [2, 3, 9], state: "minecraft:air"},
        {pos: [3, 3, 0], state: "minecraft:spruce_slab{waterlogged:false,type:bottom}"},
        {pos: [3, 3, 1], state: "minecraft:spruce_slab{waterlogged:false,type:bottom}"},
        {pos: [3, 3, 2], state: "minecraft:spruce_slab{waterlogged:false,type:bottom}"},
        {pos: [3, 3, 3], state: "minecraft:spruce_slab{waterlogged:false,type:bottom}"},
        {pos: [3, 3, 4], state: "minecraft:spruce_slab{waterlogged:false,type:bottom}"},
        {pos: [3, 3, 5], state: "minecraft:spruce_slab{waterlogged:false,type:bottom}"},
        {pos: [3, 3, 7], state: "minecraft:air"},
        {pos: [3, 3, 9], state: "minecraft:air"},
        {pos: [4, 3, 7], state: "minecraft:air"},
        {pos: [4, 3, 9], state: "minecraft:air"},
        {pos: [5, 3, 0], state: "minecraft:air"},
        {pos: [5, 3, 2], state: "minecraft:air"},
        {pos: [5, 3, 3], state: "minecraft:air"},
        {pos: [5, 3, 4], state: "minecraft:air"},
        {pos: [5, 3, 5], state: "minecraft:air"},
        {pos: [5, 3, 7], state: "minecraft:air"},
        {pos: [5, 3, 9], state: "minecraft:air"},
        {pos: [6, 3, 0], state: "minecraft:air"},
        {pos: [6, 3, 2], state: "minecraft:air"},
        {pos: [6, 3, 3], state: "minecraft:air"},
        {pos: [6, 3, 4], state: "minecraft:air"},
        {pos: [6, 3, 5], state: "minecraft:air"},
        {pos: [6, 3, 7], state: "minecraft:air"},
        {pos: [6, 3, 9], state: "minecraft:air"},
        {pos: [7, 3, 9], state: "minecraft:air"},
        {pos: [8, 3, 0], state: "minecraft:spruce_slab{waterlogged:false,type:bottom}"},
        {pos: [8, 3, 1], state: "minecraft:air"},
        {pos: [8, 3, 2], state: "minecraft:air"},
        {pos: [8, 3, 3], state: "minecraft:air"},
        {pos: [8, 3, 4], state: "minecraft:air"},
        {pos: [8, 3, 5], state: "minecraft:spruce_slab{waterlogged:false,type:bottom}"},
        {pos: [8, 3, 7], state: "minecraft:air"},
        {pos: [8, 3, 9], state: "minecraft:spruce_slab{waterlogged:false,type:bottom}"},
        {pos: [0, 4, 0], state: "minecraft:air"},
        {pos: [0, 4, 1], state: "minecraft:air"},
        {pos: [0, 4, 2], state: "minecraft:air"},
        {pos: [0, 4, 3], state: "minecraft:air"},
        {pos: [0, 4, 4], state: "minecraft:air"},
        {pos: [0, 4, 5], state: "minecraft:air"},
        {pos: [0, 4, 6], state: "minecraft:spruce_slab{waterlogged:false,type:bottom}"},
        {pos: [0, 4, 8], state: "minecraft:spruce_slab{waterlogged:false,type:bottom}"},
        {pos: [0, 4, 9], state: "minecraft:air"},
        {pos: [1, 4, 0], state: "minecraft:air"},
        {pos: [1, 4, 1], state: "minecraft:air"},
        {pos: [1, 4, 2], state: "minecraft:air"},
        {pos: [1, 4, 3], state: "minecraft:air"},
        {pos: [1, 4, 4], state: "minecraft:air"},
        {pos: [1, 4, 5], state: "minecraft:air"},
        {pos: [1, 4, 6], state: "minecraft:air"},
        {pos: [1, 4, 8], state: "minecraft:air"},
        {pos: [1, 4, 9], state: "minecraft:air"},
        {pos: [2, 4, 0], state: "minecraft:air"},
        {pos: [2, 4, 1], state: "minecraft:air"},
        {pos: [2, 4, 2], state: "minecraft:air"},
        {pos: [2, 4, 3], state: "minecraft:air"},
        {pos: [2, 4, 4], state: "minecraft:air"},
        {pos: [2, 4, 5], state: "minecraft:air"},
        {pos: [2, 4, 6], state: "minecraft:air"},
        {pos: [2, 4, 8], state: "minecraft:air"},
        {pos: [2, 4, 9], state: "minecraft:air"},
        {pos: [3, 4, 0], state: "minecraft:air"},
        {pos: [3, 4, 1], state: "minecraft:air"},
        {pos: [3, 4, 2], state: "minecraft:air"},
        {pos: [3, 4, 3], state: "minecraft:air"},
        {pos: [3, 4, 4], state: "minecraft:air"},
        {pos: [3, 4, 5], state: "minecraft:air"},
        {pos: [3, 4, 6], state: "minecraft:air"},
        {pos: [3, 4, 8], state: "minecraft:air"},
        {pos: [3, 4, 9], state: "minecraft:air"},
        {pos: [4, 4, 0], state: "minecraft:spruce_slab{waterlogged:false,type:bottom}"},
        {pos: [4, 4, 1], state: "minecraft:air"},
        {pos: [4, 4, 2], state: "minecraft:air"},
        {pos: [4, 4, 3], state: "minecraft:air"},
        {pos: [4, 4, 4], state: "minecraft:air"},
        {pos: [4, 4, 5], state: "minecraft:air"},
        {pos: [4, 4, 6], state: "minecraft:air"},
        {pos: [4, 4, 8], state: "minecraft:air"},
        {pos: [4, 4, 9], state: "minecraft:air"},
        {pos: [5, 4, 8], state: "minecraft:air"},
        {pos: [5, 4, 9], state: "minecraft:air"},
        {pos: [6, 4, 8], state: "minecraft:air"},
        {pos: [6, 4, 9], state: "minecraft:air"},
        {pos: [7, 4, 0], state: "minecraft:spruce_slab{waterlogged:false,type:bottom}"},
        {pos: [7, 4, 1], state: "minecraft:air"},
        {pos: [7, 4, 2], state: "minecraft:air"},
        {pos: [7, 4, 3], state: "minecraft:air"},
        {pos: [7, 4, 4], state: "minecraft:air"},
        {pos: [7, 4, 5], state: "minecraft:air"},
        {pos: [7, 4, 6], state: "minecraft:air"},
        {pos: [7, 4, 8], state: "minecraft:air"},
        {pos: [7, 4, 9], state: "minecraft:air"},
        {pos: [8, 4, 0], state: "minecraft:air"},
        {pos: [8, 4, 1], state: "minecraft:air"},
        {pos: [8, 4, 2], state: "minecraft:air"},
        {pos: [8, 4, 3], state: "minecraft:air"},
        {pos: [8, 4, 4], state: "minecraft:air"},
        {pos: [8, 4, 5], state: "minecraft:air"},
        {pos: [8, 4, 6], state: "minecraft:spruce_slab{waterlogged:false,type:bottom}"},
        {pos: [8, 4, 8], state: "minecraft:spruce_slab{waterlogged:false,type:bottom}"},
        {pos: [8, 4, 9], state: "minecraft:air"},
        {pos: [0, 0, 6], state: "minecraft:jigsaw{orientation:west_up}", nbt: {final_state: "minecraft:structure_void", id: "minecraft:jigsaw", joint: "aligned", name: "minecraft:buidling_entrance", pool: "minecraft:empty", target: "minecraft:buidling_entrance"}},
        {pos: [1, 0, 2], state: "minecraft:jigsaw{orientation:up_north}", nbt: {final_state: "minecraft:grass_block", id: "minecraft:jigsaw", joint: "rollable", name: "minecraft:bottom", pool: "minecraft:village/common/sheep", target: "minecraft:bottom"}},
        {pos: [6, 1, 7], state: "minecraft:chest{waterlogged:false,facing:west,type:single}", nbt: {LootTable: "minecraft:chests/village/village_shepherd", id: "minecraft:chest"}}
    ],
    entities: [],
    palette: [
        "minecraft:stripped_spruce_log{axis:y}",
        "minecraft:grass_block{snowy:false}",
        "minecraft:spruce_planks",
        "minecraft:loom{facing:north}",
        "minecraft:stripped_spruce_log{axis:z}",
        "minecraft:spruce_stairs{half:bottom,waterlogged:false,shape:straight,facing:east}",
        "minecraft:snow{layers:1}",
        "minecraft:short_grass",
        "minecraft:spruce_fence{east:true,waterlogged:false,south:true,north:false,west:false}",
        "minecraft:spruce_fence{east:false,waterlogged:false,south:true,north:true,west:false}",
        "minecraft:air",
        "minecraft:spruce_fence{east:true,waterlogged:false,south:false,north:false,west:true}",
        "minecraft:spruce_door{hinge:left,half:lower,powered:false,facing:east,open:false}",
        "minecraft:spruce_door{hinge:right,half:lower,powered:false,facing:east,open:false}",
        "minecraft:lantern{waterlogged:false,hanging:false}",
        "minecraft:spruce_door{hinge:left,half:upper,powered:false,facing:east,open:false}",
        "minecraft:lantern{waterlogged:false,hanging:true}",
        "minecraft:spruce_door{hinge:right,half:upper,powered:false,facing:east,open:false}",
        "minecraft:wall_torch{facing:north}",
        "minecraft:wall_torch{facing:west}",
        "minecraft:spruce_slab{waterlogged:false,type:bottom}",
        "minecraft:jigsaw{orientation:west_up}",
        "minecraft:jigsaw{orientation:up_north}",
        "minecraft:chest{waterlogged:false,facing:west,type:single}"
    ]
}