{
    size: [7, 6, 7],
    data: [
        {pos: [0, 0, 0], state: "minecraft:spruce_planks"},
        {pos: [0, 0, 1], state: "minecraft:spruce_planks"},
        {pos: [0, 0, 2], state: "minecraft:spruce_planks"},
        {pos: [0, 0, 3], state: "minecraft:spruce_planks"},
        {pos: [0, 0, 4], state: "minecraft:spruce_planks"},
        {pos: [0, 0, 5], state: "minecraft:spruce_planks"},
        {pos: [1, 0, 1], state: "minecraft:stripped_spruce_wood{axis:y}"},
        {pos: [1, 0, 2], state: "minecraft:spruce_planks"},
        {pos: [1, 0, 3], state: "minecraft:spruce_planks"},
        {pos: [1, 0, 4], state: "minecraft:stripped_spruce_wood{axis:y}"},
        {pos: [2, 0, 1], state: "minecraft:stripped_spruce_wood{axis:y}"},
        {pos: [2, 0, 2], state: "minecraft:spruce_planks"},
        {pos: [2, 0, 3], state: "minecraft:spruce_planks"},
        {pos: [2, 0, 4], state: "minecraft:stripped_spruce_wood{axis:y}"},
        {pos: [3, 0, 1], state: "minecraft:stripped_spruce_wood{axis:y}"},
        {pos: [3, 0, 3], state: "minecraft:spruce_planks"},
        {pos: [3, 0, 4], state: "minecraft:stripped_spruce_wood{axis:y}"},
        {pos: [4, 0, 1], state: "minecraft:stripped_spruce_wood{axis:y}"},
        {pos: [4, 0, 2], state: "minecraft:spruce_planks"},
        {pos: [4, 0, 3], state: "minecraft:spruce_planks"},
        {pos: [4, 0, 4], state: "minecraft:stripped_spruce_wood{axis:y}"},
        {pos: [4, 0, 5], state: "minecraft:snow_block"},
        {pos: [5, 0, 0], state: "minecraft:spruce_planks"},
        {pos: [5, 0, 1], state: "minecraft:spruce_planks"},
        {pos: [5, 0, 2], state: "minecraft:spruce_planks"},
        {pos: [5, 0, 3], state: "minecraft:spruce_planks"},
        {pos: [5, 0, 4], state: "minecraft:spruce_planks"},
        {pos: [5, 0, 5], state: "minecraft:spruce_planks"},
        {pos: [5, 0, 6], state: "minecraft:snow_block"},
        {pos: [6, 0, 4], state: "minecraft:snow_block"},
        {pos: [6, 0, 5], state: "minecraft:snow_block"},
        {pos: [0, 1, 0], state: "minecraft:spruce_planks"},
        {pos: [0, 1, 1], state: "minecraft:spruce_planks"},
        {pos: [0, 1, 2], state: "minecraft:spruce_planks"},
        {pos: [0, 1, 3], state: "minecraft:spruce_planks"},
        {pos: [0, 1, 4], state: "minecraft:spruce_planks"},
        {pos: [0, 1, 5], state: "minecraft:spruce_planks"},
        {pos: [1, 1, 1], state: "minecraft:stripped_spruce_wood{axis:y}"},
        {pos: [1, 1, 2], state: "minecraft:spruce_planks"},
        {pos: [1, 1, 3], state: "minecraft:spruce_planks"},
        {pos: [1, 1, 4], state: "minecraft:stripped_spruce_wood{axis:y}"},
        {pos: [2, 1, 1], state: "minecraft:stripped_spruce_wood{axis:y}"},
        {pos: [3, 1, 1], state: "minecraft:stripped_spruce_wood{axis:y}"},
        {pos: [4, 1, 1], state: "minecraft:stripped_spruce_wood{axis:y}"},
        {pos: [4, 1, 4], state: "minecraft:stripped_spruce_wood{axis:y}"},
        {pos: [5, 1, 0], state: "minecraft:spruce_planks"},
        {pos: [5, 1, 1], state: "minecraft:spruce_planks"},
        {pos: [5, 1, 2], state: "minecraft:spruce_planks"},
        {pos: [5, 1, 3], state: "minecraft:spruce_planks"},
        {pos: [5, 1, 4], state: "minecraft:spruce_planks"},
        {pos: [5, 1, 5], state: "minecraft:spruce_planks"},
        {pos: [6, 1, 4], state: "minecraft:snow_block"},
        {pos: [1, 2, 0], state: "minecraft:spruce_planks"},
        {pos: [1, 2, 1], state: "minecraft:spruce_planks"},
        {pos: [1, 2, 2], state: "minecraft:spruce_planks"},
        {pos: [1, 2, 3], state: "minecraft:spruce_planks"},
        {pos: [1, 2, 4], state: "minecraft:stripped_spruce_wood{axis:y}"},
        {pos: [2, 2, 1], state: "minecraft:stripped_spruce_wood{axis:y}"},
        {pos: [3, 2, 1], state: "minecraft:stripped_spruce_wood{axis:y}"},
        {pos: [4, 2, 0], state: "minecraft:spruce_planks"},
        {pos: [4, 2, 1], state: "minecraft:spruce_planks"},
        {pos: [4, 2, 2], state: "minecraft:spruce_planks"},
        {pos: [4, 2, 3], state: "minecraft:spruce_planks"},
        {pos: [4, 2, 4], state: "minecraft:stripped_spruce_wood{axis:y}"},
        {pos: [1, 3, 0], state: "minecraft:spruce_planks"},
        {pos: [1, 3, 1], state: "minecraft:spruce_planks"},
        {pos: [1, 3, 2], state: "minecraft:spruce_planks"},
        {pos: [1, 3, 3], state: "minecraft:spruce_planks"},
        {pos: [1, 3, 4], state: "minecraft:spruce_planks"},
        {pos: [1, 3, 5], state: "minecraft:spruce_planks"},
        {pos: [2, 3, 1], state: "minecraft:stripped_spruce_wood{axis:y}"},
        {pos: [2, 3, 4], state: "minecraft:stripped_spruce_wood{axis:y}"},
        {pos: [3, 3, 1], state: "minecraft:stripped_spruce_wood{axis:y}"},
        {pos: [3, 3, 4], state: "minecraft:stripped_spruce_wood{axis:y}"},
        {pos: [4, 3, 0], state: "minecraft:spruce_planks"},
        {pos: [4, 3, 1], state: "minecraft:spruce_planks"},
        {pos: [4, 3, 2], state: "minecraft:spruce_planks"},
        {pos: [4, 3, 3], state: "minecraft:spruce_planks"},
        {pos: [4, 3, 4], state: "minecraft:spruce_planks"},
        {pos: [4, 3, 5], state: "minecraft:spruce_planks"},
        {pos: [2, 4, 0], state: "minecraft:spruce_planks"},
        {pos: [2, 4, 1], state: "minecraft:spruce_planks"},
        {pos: [2, 4, 2], state: "minecraft:spruce_planks"},
        {pos: [2, 4, 3], state: "minecraft:spruce_planks"},
        {pos: [2, 4, 4], state: "minecraft:stripped_spruce_wood{axis:y}"},
        {pos: [3, 4, 0], state: "minecraft:spruce_planks"},
        {pos: [3, 4, 1], state: "minecraft:spruce_planks"},
        {pos: [3, 4, 2], state: "minecraft:spruce_planks"},
        {pos: [3, 4, 3], state: "minecraft:spruce_planks"},
        {pos: [3, 4, 4], state: "minecraft:stripped_spruce_wood{axis:y}"},
        {pos: [0, 0, 6], state: "minecraft:air"},
        {pos: [1, 0, 0], state: "minecraft:air"},
        {pos: [1, 0, 5], state: "minecraft:air"},
        {pos: [1, 0, 6], state: "minecraft:air"},
        {pos: [2, 0, 0], state: "minecraft:air"},
        {pos: [2, 0, 5], state: "minecraft:spruce_stairs{half:bottom,waterlogged:false,shape:straight,facing:north}"},
        {pos: [2, 0, 6], state: "minecraft:air"},
        {pos: [3, 0, 0], state: "minecraft:air"},
        {pos: [3, 0, 5], state: "minecraft:spruce_stairs{half:bottom,waterlogged:false,shape:straight,facing:north}"},
        {pos: [4, 0, 0], state: "minecraft:air"},
        {pos: [4, 0, 6], state: "minecraft:air"},
        {pos: [6, 0, 0], state: "minecraft:air"},
        {pos: [6, 0, 1], state: "minecraft:air"},
        {pos: [6, 0, 2], state: "minecraft:air"},
        {pos: [6, 0, 3], state: "minecraft:air"},
        {pos: [6, 0, 6], state: "minecraft:air"},
        {pos: [0, 1, 6], state: "minecraft:air"},
        {pos: [1, 1, 0], state: "minecraft:air"},
        {pos: [1, 1, 5], state: "minecraft:air"},
        {pos: [1, 1, 6], state: "minecraft:air"},
        {pos: [2, 1, 0], state: "minecraft:air"},
        {pos: [2, 1, 4], state: "minecraft:spruce_door{hinge:left,half:lower,powered:false,facing:north,open:false}"},
        {pos: [2, 1, 5], state: "minecraft:air"},
        {pos: [2, 1, 6], state: "minecraft:air"},
        {pos: [3, 1, 0], state: "minecraft:air"},
        {pos: [3, 1, 2], state: "minecraft:air"},
        {pos: [3, 1, 3], state: "minecraft:air"},
        {pos: [3, 1, 4], state: "minecraft:spruce_door{hinge:right,half:lower,powered:false,facing:north,open:false}"},
        {pos: [3, 1, 5], state: "minecraft:air"},
        {pos: [3, 1, 6], state: "minecraft:air"},
        {pos: [4, 1, 0], state: "minecraft:air"},
        {pos: [4, 1, 5], state: "minecraft:snow{layers:4}"},
        {pos: [4, 1, 6], state: "minecraft:air"},
        {pos: [5, 1, 6], state: "minecraft:snow{layers:4}"},
        {pos: [6, 1, 0], state: "minecraft:air"},
        {pos: [6, 1, 1], state: "minecraft:air"},
        {pos: [6, 1, 2], state: "minecraft:air"},
        {pos: [6, 1, 3], state: "minecraft:air"},
        {pos: [6, 1, 5], state: "minecraft:snow{layers:1}"},
        {pos: [6, 1, 6], state: "minecraft:air"},
        {pos: [0, 2, 0], state: "minecraft:spruce_stairs{half:bottom,waterlogged:false,shape:straight,facing:east}"},
        {pos: [0, 2, 1], state: "minecraft:spruce_stairs{half:bottom,waterlogged:false,shape:straight,facing:east}"},
        {pos: [0, 2, 2], state: "minecraft:snow{layers:1}"},
        {pos: [0, 2, 3], state: "minecraft:snow{layers:1}"},
        {pos: [0, 2, 4], state: "minecraft:spruce_stairs{half:bottom,waterlogged:false,shape:straight,facing:east}"},
        {pos: [0, 2, 5], state: "minecraft:spruce_stairs{half:bottom,waterlogged:false,shape:straight,facing:east}"},
        {pos: [0, 2, 6], state: "minecraft:air"},
        {pos: [1, 2, 5], state: "minecraft:spruce_stairs{half:top,waterlogged:false,shape:straight,facing:west}"},
        {pos: [1, 2, 6], state: "minecraft:lantern{waterlogged:false,hanging:true}"},
        {pos: [2, 2, 0], state: "minecraft:air"},
        {pos: [2, 2, 2], state: "minecraft:air"},
        {pos: [2, 2, 3], state: "minecraft:air"},
        {pos: [2, 2, 4], state: "minecraft:spruce_door{hinge:left,half:upper,powered:false,facing:north,open:false}"},
        {pos: [2, 2, 5], state: "minecraft:air"},
        {pos: [2, 2, 6], state: "minecraft:air"},
        {pos: [3, 2, 0], state: "minecraft:air"},
        {pos: [3, 2, 2], state: "minecraft:air"},
        {pos: [3, 2, 3], state: "minecraft:air"},
        {pos: [3, 2, 4], state: "minecraft:spruce_door{hinge:right,half:upper,powered:false,facing:north,open:false}"},
        {pos: [3, 2, 5], state: "minecraft:air"},
        {pos: [3, 2, 6], state: "minecraft:air"},
        {pos: [4, 2, 5], state: "minecraft:spruce_stairs{half:top,waterlogged:false,shape:straight,facing:east}"},
        {pos: [4, 2, 6], state: "minecraft:lantern{waterlogged:false,hanging:true}"},
        {pos: [5, 2, 0], state: "minecraft:spruce_stairs{half:bottom,waterlogged:false,shape:straight,facing:west}"},
        {pos: [5, 2, 1], state: "minecraft:spruce_stairs{half:bottom,waterlogged:false,shape:straight,facing:west}"},
        {pos: [5, 2, 2], state: "minecraft:snow{layers:2}"},
        {pos: [5, 2, 3], state: "minecraft:snow{layers:4}"},
        {pos: [5, 2, 4], state: "minecraft:spruce_stairs{half:bottom,waterlogged:false,shape:straight,facing:west}"},
        {pos: [5, 2, 5], state: "minecraft:spruce_stairs{half:bottom,waterlogged:false,shape:straight,facing:west}"},
        {pos: [5, 2, 6], state: "minecraft:air"},
        {pos: [6, 2, 0], state: "minecraft:air"},
        {pos: [6, 2, 1], state: "minecraft:air"},
        {pos: [6, 2, 2], state: "minecraft:air"},
        {pos: [6, 2, 3], state: "minecraft:air"},
        {pos: [6, 2, 4], state: "minecraft:snow{layers:1}"},
        {pos: [6, 2, 5], state: "minecraft:air"},
        {pos: [6, 2, 6], state: "minecraft:air"},
        {pos: [0, 3, 0], state: "minecraft:air"},
        {pos: [0, 3, 1], state: "minecraft:air"},
        {pos: [0, 3, 2], state: "minecraft:air"},
        {pos: [0, 3, 3], state: "minecraft:air"},
        {pos: [0, 3, 4], state: "minecraft:air"},
        {pos: [0, 3, 5], state: "minecraft:air"},
        {pos: [0, 3, 6], state: "minecraft:air"},
        {pos: [1, 3, 6], state: "minecraft:spruce_fence{east:false,waterlogged:false,south:false,north:true,west:false}"},
        {pos: [2, 3, 0], state: "minecraft:air"},
        {pos: [2, 3, 2], state: "minecraft:air"},
        {pos: [2, 3, 3], state: "minecraft:wall_torch{facing:north}"},
        {pos: [2, 3, 5], state: "minecraft:air"},
        {pos: [2, 3, 6], state: "minecraft:air"},
        {pos: [3, 3, 0], state: "minecraft:air"},
        {pos: [3, 3, 2], state: "minecraft:air"},
        {pos: [3, 3, 3], state: "minecraft:wall_torch{facing:north}"},
        {pos: [3, 3, 5], state: "minecraft:air"},
        {pos: [3, 3, 6], state: "minecraft:air"},
        {pos: [4, 3, 6], state: "minecraft:spruce_fence{east:false,waterlogged:false,south:false,north:true,west:false}"},
        {pos: [5, 3, 0], state: "minecraft:air"},
        {pos: [5, 3, 1], state: "minecraft:air"},
        {pos: [5, 3, 2], state: "minecraft:air"},
        {pos: [5, 3, 3], state: "minecraft:air"},
        {pos: [5, 3, 4], state: "minecraft:air"},
        {pos: [5, 3, 5], state: "minecraft:air"},
        {pos: [5, 3, 6], state: "minecraft:air"},
        {pos: [6, 3, 0], state: "minecraft:air"},
        {pos: [6, 3, 1], state: "minecraft:air"},
        {pos: [6, 3, 2], state: "minecraft:air"},
        {pos: [6, 3, 3], state: "minecraft:air"},
        {pos: [6, 3, 4], state: "minecraft:air"},
        {pos: [6, 3, 5], state: "minecraft:air"},
        {pos: [6, 3, 6], state: "minecraft:air"},
        {pos: [0, 4, 0], state: "minecraft:air"},
        {pos: [0, 4, 1], state: "minecraft:air"},
        {pos: [0, 4, 2], state: "minecraft:air"},
        {pos: [0, 4, 3], state: "minecraft:air"},
        {pos: [0, 4, 4], state: "minecraft:air"},
        {pos: [0, 4, 5], state: "minecraft:air"},
        {pos: [0, 4, 6], state: "minecraft:air"},
        {pos: [1, 4, 0], state: "minecraft:spruce_stairs{half:bottom,waterlogged:false,shape:straight,facing:east}"},
        {pos: [1, 4, 1], state: "minecraft:spruce_stairs{half:bottom,waterlogged:false,shape:straight,facing:east}"},
        {pos: [1, 4, 2], state: "minecraft:snow{layers:1}"},
        {pos: [1, 4, 3], state: "minecraft:snow{layers:1}"},
        {pos: [1, 4, 4], state: "minecraft:spruce_stairs{half:bottom,waterlogged:false,shape:straight,facing:east}"},
        {pos: [1, 4, 5], state: "minecraft:spruce_stairs{half:bottom,waterlogged:false,shape:straight,facing:east}"},
        {pos: [1, 4, 6], state: "minecraft:air"},
        {pos: [2, 4, 5], state: "minecraft:spruce_stairs{half:top,waterlogged:false,shape:straight,facing:west}"},
        {pos: [2, 4, 6], state: "minecraft:air"},
        {pos: [3, 4, 5], state: "minecraft:spruce_stairs{half:top,waterlogged:false,shape:straight,facing:east}"},
        {pos: [3, 4, 6], state: "minecraft:air"},
        {pos: [4, 4, 0], state: "minecraft:spruce_stairs{half:bottom,waterlogged:false,shape:straight,facing:west}"},
        {pos: [4, 4, 1], state: "minecraft:spruce_stairs{half:bottom,waterlogged:false,shape:straight,facing:west}"},
        {pos: [4, 4, 2], state: "minecraft:snow{layers:4}"},
        {pos: [4, 4, 3], state: "minecraft:snow{layers:1}"},
        {pos: [4, 4, 4], state: "minecraft:spruce_stairs{half:bottom,waterlogged:false,shape:straight,facing:west}"},
        {pos: [4, 4, 5], state: "minecraft:spruce_stairs{half:bottom,waterlogged:false,shape:straight,facing:west}"},
        {pos: [4, 4, 6], state: "minecraft:air"},
        {pos: [5, 4, 0], state: "minecraft:air"},
        {pos: [5, 4, 1], state: "minecraft:air"},
        {pos: [5, 4, 2], state: "minecraft:air"},
        {pos: [5, 4, 3], state: "minecraft:air"},
        {pos: [5, 4, 4], state: "minecraft:air"},
        {pos: [5, 4, 5], state: "minecraft:air"},
        {pos: [5, 4, 6], state: "minecraft:air"},
        {pos: [6, 4, 0], state: "minecraft:air"},
        {pos: [6, 4, 1], state: "minecraft:air"},
        {pos: [6, 4, 2], state: "minecraft:air"},
        {pos: [6, 4, 3], state: "minecraft:air"},
        {pos: [6, 4, 4], state: "minecraft:air"},
        {pos: [6, 4, 5], state: "minecraft:air"},
        {pos: [6, 4, 6], state: "minecraft:air"},
        {pos: [0, 5, 0], state: "minecraft:air"},
        {pos: [0, 5, 1], state: "minecraft:air"},
        {pos: [0, 5, 2], state: "minecraft:air"},
        {pos: [0, 5, 3], state: "minecraft:air"},
        {pos: [0, 5, 4], state: "minecraft:air"},
        {pos: [0, 5, 5], state: "minecraft:air"},
        {pos: [0, 5, 6], state: "minecraft:air"},
        {pos: [1, 5, 0], state: "minecraft:air"},
        {pos: [1, 5, 1], state: "minecraft:air"},
        {pos: [1, 5, 2], state: "minecraft:air"},
        {pos: [1, 5, 3], state: "minecraft:air"},
        {pos: [1, 5, 4], state: "minecraft:air"},
        {pos: [1, 5, 5], state: "minecraft:air"},
        {pos: [1, 5, 6], state: "minecraft:air"},
        {pos: [2, 5, 0], state: "minecraft:spruce_slab{waterlogged:false,type:bottom}"},
        {pos: [2, 5, 1], state: "minecraft:spruce_slab{waterlogged:false,type:bottom}"},
        {pos: [2, 5, 2], state: "minecraft:spruce_slab{waterlogged:false,type:bottom}"},
        {pos: [2, 5, 3], state: "minecraft:spruce_slab{waterlogged:false,type:bottom}"},
        {pos: [2, 5, 4], state: "minecraft:spruce_slab{waterlogged:false,type:bottom}"},
        {pos: [2, 5, 5], state: "minecraft:spruce_slab{waterlogged:false,type:bottom}"},
        {pos: [2, 5, 6], state: "minecraft:air"},
        {pos: [3, 5, 0], state: "minecraft:spruce_slab{waterlogged:false,type:bottom}"},
        {pos: [3, 5, 1], state: "minecraft:spruce_slab{waterlogged:false,type:bottom}"},
        {pos: [3, 5, 2], state: "minecraft:spruce_slab{waterlogged:false,type:bottom}"},
        {pos: [3, 5, 3], state: "minecraft:spruce_slab{waterlogged:false,type:bottom}"},
        {pos: [3, 5, 4], state: "minecraft:spruce_slab{waterlogged:false,type:bottom}"},
        {pos: [3, 5, 5], state: "minecraft:spruce_slab{waterlogged:false,type:bottom}"},
        {pos: [3, 5, 6], state: "minecraft:air"},
        {pos: [4, 5, 0], state: "minecraft:air"},
        {pos: [4, 5, 1], state: "minecraft:air"},
        {pos: [4, 5, 2], state: "minecraft:air"},
        {pos: [4, 5, 3], state: "minecraft:air"},
        {pos: [4, 5, 4], state: "minecraft:air"},
        {pos: [4, 5, 5], state: "minecraft:air"},
        {pos: [4, 5, 6], state: "minecraft:air"},
        {pos: [5, 5, 0], state: "minecraft:air"},
        {pos: [5, 5, 1], state: "minecraft:air"},
        {pos: [5, 5, 2], state: "minecraft:air"},
        {pos: [5, 5, 3], state: "minecraft:air"},
        {pos: [5, 5, 4], state: "minecraft:air"},
        {pos: [5, 5, 5], state: "minecraft:air"},
        {pos: [5, 5, 6], state: "minecraft:air"},
        {pos: [6, 5, 0], state: "minecraft:air"},
        {pos: [6, 5, 1], state: "minecraft:air"},
        {pos: [6, 5, 2], state: "minecraft:air"},
        {pos: [6, 5, 3], state: "minecraft:air"},
        {pos: [6, 5, 4], state: "minecraft:air"},
        {pos: [6, 5, 5], state: "minecraft:air"},
        {pos: [6, 5, 6], state: "minecraft:air"},
        {pos: [3, 0, 2], state: "minecraft:jigsaw{orientation:up_north}", nbt: {final_state: "minecraft:spruce_planks", id: "minecraft:jigsaw", joint: "rollable", name: "minecraft:bottom", pool: "minecraft:village/snowy/villagers", target: "minecraft:bottom"}},
        {pos: [3, 0, 6], state: "minecraft:jigsaw{orientation:south_up}", nbt: {final_state: "minecraft:structure_void", id: "minecraft:jigsaw", joint: "aligned", name: "minecraft:building_entrance", pool: "minecraft:empty", target: "minecraft:building_entrance"}},
        {pos: [2, 1, 2], state: "minecraft:blue_bed{part:head,facing:north,occupied:false}", nbt: {id: "minecraft:bed"}},
        {pos: [2, 1, 3], state: "minecraft:blue_bed{part:foot,facing:north,occupied:false}", nbt: {id: "minecraft:bed"}},
        {pos: [4, 1, 2], state: "minecraft:furnace{lit:false,facing:west}", nbt: {Items: [], RecipesUsed: {}, cooking_time_spent: 0s, cooking_total_time: 0s, id: "minecraft:furnace", lit_time_remaining: 0s, lit_total_time: 0s}},
        {pos: [4, 1, 3], state: "minecraft:furnace{lit:false,facing:west}", nbt: {Items: [], RecipesUsed: {}, cooking_time_spent: 0s, cooking_total_time: 0s, id: "minecraft:furnace", lit_time_remaining: 0s, lit_total_time: 0s}}
    ],
    entities: [],
    palette: [
        "minecraft:spruce_planks",
        "minecraft:stripped_spruce_wood{axis:y}",
        "minecraft:snow_block",
        "minecraft:air",
        "minecraft:spruce_stairs{half:bottom,waterlogged:false,shape:straight,facing:north}",
        "minecraft:spruce_door{hinge:left,half:lower,powered:false,facing:north,open:false}",
        "minecraft:spruce_door{hinge:right,half:lower,powered:false,facing:north,open:false}",
        "minecraft:snow{layers:4}",
        "minecraft:snow{layers:1}",
        "minecraft:spruce_stairs{half:bottom,waterlogged:false,shape:straight,facing:east}",
        "minecraft:spruce_stairs{half:top,waterlogged:false,shape:straight,facing:west}",
        "minecraft:lantern{waterlogged:false,hanging:true}",
        "minecraft:spruce_door{hinge:left,half:upper,powered:false,facing:north,open:false}",
        "minecraft:spruce_door{hinge:right,half:upper,powered:false,facing:north,open:false}",
        "minecraft:spruce_stairs{half:top,waterlogged:false,shape:straight,facing:east}",
        "minecraft:spruce_stairs{half:bottom,waterlogged:false,shape:straight,facing:west}",
        "minecraft:snow{layers:2}",
        "minecraft:spruce_fence{east:false,waterlogged:false,south:false,north:true,west:false}",
        "minecraft:wall_torch{facing:north}",
        "minecraft:spruce_slab{waterlogged:false,type:bottom}",
        "minecraft:jigsaw{orientation:up_north}",
        "minecraft:jigsaw{orientation:south_up}",
        "minecraft:blue_bed{part:head,facing:north,occupied:false}",
        "minecraft:blue_bed{part:foot,facing:north,occupied:false}",
        "minecraft:furnace{lit:false,facing:west}"
    ]
}