{
    size: [9, 5, 5],
    data: [
        {pos: [0, 0, 0], state: "minecraft:grass_block{snowy:true}"},
        {pos: [0, 0, 1], state: "minecraft:dirt"},
        {pos: [0, 0, 2], state: "minecraft:grass_block{snowy:false}"},
        {pos: [0, 0, 3], state: "minecraft:dirt"},
        {pos: [0, 0, 4], state: "minecraft:grass_block{snowy:true}"},
        {pos: [1, 0, 0], state: "minecraft:dirt"},
        {pos: [1, 0, 1], state: "minecraft:dirt"},
        {pos: [1, 0, 2], state: "minecraft:grass_block{snowy:true}"},
        {pos: [1, 0, 3], state: "minecraft:grass_block{snowy:true}"},
        {pos: [1, 0, 4], state: "minecraft:dirt"},
        {pos: [2, 0, 0], state: "minecraft:dirt"},
        {pos: [2, 0, 1], state: "minecraft:dirt"},
        {pos: [2, 0, 2], state: "minecraft:grass_block{snowy:true}"},
        {pos: [2, 0, 3], state: "minecraft:grass_block{snowy:false}"},
        {pos: [2, 0, 4], state: "minecraft:dirt"},
        {pos: [3, 0, 0], state: "minecraft:dirt"},
        {pos: [3, 0, 1], state: "minecraft:dirt"},
        {pos: [3, 0, 2], state: "minecraft:grass_block{snowy:false}"},
        {pos: [3, 0, 3], state: "minecraft:grass_block{snowy:false}"},
        {pos: [3, 0, 4], state: "minecraft:dirt"},
        {pos: [4, 0, 0], state: "minecraft:grass_block{snowy:false}"},
        {pos: [4, 0, 1], state: "minecraft:dirt"},
        {pos: [4, 0, 2], state: "minecraft:grass_block{snowy:false}"},
        {pos: [4, 0, 3], state: "minecraft:dirt"},
        {pos: [4, 0, 4], state: "minecraft:grass_block{snowy:false}"},
        {pos: [5, 0, 0], state: "minecraft:grass_block{snowy:false}"},
        {pos: [5, 0, 1], state: "minecraft:grass_block{snowy:true}"},
        {pos: [5, 0, 3], state: "minecraft:grass_block{snowy:false}"},
        {pos: [5, 0, 4], state: "minecraft:grass_block{snowy:false}"},
        {pos: [6, 0, 0], state: "minecraft:grass_block{snowy:false}"},
        {pos: [6, 0, 1], state: "minecraft:grass_block{snowy:true}"},
        {pos: [6, 0, 2], state: "minecraft:grass_block{snowy:false}"},
        {pos: [6, 0, 3], state: "minecraft:grass_block{snowy:false}"},
        {pos: [6, 0, 4], state: "minecraft:grass_block{snowy:false}"},
        {pos: [7, 0, 0], state: "minecraft:grass_block{snowy:false}"},
        {pos: [7, 0, 1], state: "minecraft:grass_block{snowy:false}"},
        {pos: [7, 0, 2], state: "minecraft:dirt"},
        {pos: [7, 0, 3], state: "minecraft:grass_block{snowy:false}"},
        {pos: [7, 0, 4], state: "minecraft:grass_block{snowy:false}"},
        {pos: [8, 0, 0], state: "minecraft:grass_block{snowy:false}"},
        {pos: [8, 0, 1], state: "minecraft:grass_block{snowy:false}"},
        {pos: [8, 0, 2], state: "minecraft:grass_block{snowy:false}"},
        {pos: [8, 0, 3], state: "minecraft:grass_block{snowy:false}"},
        {pos: [8, 0, 4], state: "minecraft:grass_block{snowy:false}"},
        {pos: [0, 1, 1], state: "minecraft:snow_block"},
        {pos: [1, 1, 0], state: "minecraft:snow_block"},
        {pos: [1, 1, 1], state: "minecraft:spruce_planks"},
        {pos: [1, 1, 4], state: "minecraft:snow_block"},
        {pos: [2, 1, 0], state: "minecraft:snow_block"},
        {pos: [2, 1, 1], state: "minecraft:spruce_planks"},
        {pos: [2, 1, 4], state: "minecraft:snow_block"},
        {pos: [3, 1, 0], state: "minecraft:snow_block"},
        {pos: [3, 1, 4], state: "minecraft:snow_block"},
        {pos: [4, 1, 1], state: "minecraft:snow_block"},
        {pos: [4, 1, 3], state: "minecraft:snow_block"},
        {pos: [0, 2, 1], state: "minecraft:snow_block"},
        {pos: [0, 2, 3], state: "minecraft:snow_block"},
        {pos: [1, 2, 0], state: "minecraft:snow_block"},
        {pos: [1, 2, 4], state: "minecraft:snow_block"},
        {pos: [2, 2, 0], state: "minecraft:snow_block"},
        {pos: [2, 2, 4], state: "minecraft:snow_block"},
        {pos: [3, 2, 0], state: "minecraft:snow_block"},
        {pos: [3, 2, 4], state: "minecraft:snow_block"},
        {pos: [4, 2, 1], state: "minecraft:snow_block"},
        {pos: [4, 2, 3], state: "minecraft:snow_block"},
        {pos: [0, 3, 1], state: "minecraft:snow_block"},
        {pos: [0, 3, 2], state: "minecraft:snow_block"},
        {pos: [0, 3, 3], state: "minecraft:snow_block"},
        {pos: [1, 3, 1], state: "minecraft:snow_block"},
        {pos: [1, 3, 3], state: "minecraft:snow_block"},
        {pos: [2, 3, 1], state: "minecraft:snow_block"},
        {pos: [2, 3, 3], state: "minecraft:snow_block"},
        {pos: [3, 3, 1], state: "minecraft:snow_block"},
        {pos: [3, 3, 3], state: "minecraft:snow_block"},
        {pos: [4, 3, 1], state: "minecraft:snow_block"},
        {pos: [4, 3, 2], state: "minecraft:snow_block"},
        {pos: [4, 3, 3], state: "minecraft:snow_block"},
        {pos: [1, 4, 2], state: "minecraft:snow_block"},
        {pos: [2, 4, 2], state: "minecraft:snow_block"},
        {pos: [3, 4, 2], state: "minecraft:snow_block"},
        {pos: [0, 1, 0], state: "minecraft:snow{layers:1}"},
        {pos: [0, 1, 2], state: "minecraft:spruce_door{hinge:right,half:lower,powered:false,facing:west,open:false}"},
        {pos: [0, 1, 4], state: "minecraft:snow{layers:1}"},
        {pos: [1, 1, 2], state: "minecraft:snow{layers:1}"},
        {pos: [1, 1, 3], state: "minecraft:snow{layers:1}"},
        {pos: [2, 1, 2], state: "minecraft:snow{layers:1}"},
        {pos: [2, 1, 3], state: "minecraft:air"},
        {pos: [3, 1, 1], state: "minecraft:spruce_stairs{half:bottom,waterlogged:false,shape:straight,facing:north}"},
        {pos: [3, 1, 2], state: "minecraft:air"},
        {pos: [3, 1, 3], state: "minecraft:spruce_fence{east:true,waterlogged:false,south:true,north:false,west:false}"},
        {pos: [4, 1, 0], state: "minecraft:spruce_fence{east:true,waterlogged:false,south:true,north:false,west:true}"},
        {pos: [4, 1, 2], state: "minecraft:spruce_door{hinge:left,half:lower,powered:false,facing:east,open:false}"},
        {pos: [4, 1, 4], state: "minecraft:spruce_fence{east:true,waterlogged:false,south:false,north:true,west:true}"},
        {pos: [5, 1, 0], state: "minecraft:spruce_fence{east:true,waterlogged:false,south:false,north:false,west:true}"},
        {pos: [5, 1, 1], state: "minecraft:snow{layers:1}"},
        {pos: [5, 1, 2], state: "minecraft:air"},
        {pos: [5, 1, 3], state: "minecraft:air"},
        {pos: [5, 1, 4], state: "minecraft:spruce_fence{east:true,waterlogged:false,south:false,north:false,west:true}"},
        {pos: [6, 1, 0], state: "minecraft:spruce_fence{east:true,waterlogged:false,south:false,north:false,west:true}"},
        {pos: [6, 1, 1], state: "minecraft:snow{layers:1}"},
        {pos: [6, 1, 2], state: "minecraft:air"},
        {pos: [6, 1, 3], state: "minecraft:air"},
        {pos: [6, 1, 4], state: "minecraft:spruce_fence{east:true,waterlogged:false,south:false,north:false,west:true}"},
        {pos: [7, 1, 0], state: "minecraft:spruce_fence{east:true,waterlogged:false,south:false,north:false,west:true}"},
        {pos: [7, 1, 1], state: "minecraft:air"},
        {pos: [7, 1, 3], state: "minecraft:air"},
        {pos: [7, 1, 4], state: "minecraft:spruce_fence{east:true,waterlogged:false,south:false,north:false,west:true}"},
        {pos: [8, 1, 0], state: "minecraft:spruce_fence{east:false,waterlogged:false,south:true,north:false,west:true}"},
        {pos: [8, 1, 1], state: "minecraft:spruce_fence{east:false,waterlogged:false,south:true,north:true,west:false}"},
        {pos: [8, 1, 2], state: "minecraft:spruce_fence{east:false,waterlogged:false,south:true,north:true,west:false}"},
        {pos: [8, 1, 3], state: "minecraft:spruce_fence{east:false,waterlogged:false,south:true,north:true,west:false}"},
        {pos: [8, 1, 4], state: "minecraft:spruce_fence{east:false,waterlogged:false,south:false,north:true,west:true}"},
        {pos: [0, 2, 0], state: "minecraft:air"},
        {pos: [0, 2, 2], state: "minecraft:spruce_door{hinge:right,half:upper,powered:false,facing:west,open:false}"},
        {pos: [0, 2, 4], state: "minecraft:air"},
        {pos: [1, 2, 1], state: "minecraft:air"},
        {pos: [1, 2, 2], state: "minecraft:air"},
        {pos: [1, 2, 3], state: "minecraft:air"},
        {pos: [2, 2, 1], state: "minecraft:air"},
        {pos: [2, 2, 2], state: "minecraft:air"},
        {pos: [2, 2, 3], state: "minecraft:air"},
        {pos: [3, 2, 1], state: "minecraft:air"},
        {pos: [3, 2, 2], state: "minecraft:air"},
        {pos: [3, 2, 3], state: "minecraft:torch"},
        {pos: [4, 2, 0], state: "minecraft:air"},
        {pos: [4, 2, 2], state: "minecraft:spruce_door{hinge:left,half:upper,powered:false,facing:east,open:false}"},
        {pos: [4, 2, 4], state: "minecraft:air"},
        {pos: [5, 2, 0], state: "minecraft:air"},
        {pos: [5, 2, 1], state: "minecraft:air"},
        {pos: [5, 2, 2], state: "minecraft:air"},
        {pos: [5, 2, 3], state: "minecraft:air"},
        {pos: [5, 2, 4], state: "minecraft:air"},
        {pos: [6, 2, 0], state: "minecraft:air"},
        {pos: [6, 2, 1], state: "minecraft:air"},
        {pos: [6, 2, 2], state: "minecraft:air"},
        {pos: [6, 2, 3], state: "minecraft:air"},
        {pos: [6, 2, 4], state: "minecraft:spruce_fence{east:false,waterlogged:false,south:false,north:false,west:false}"},
        {pos: [7, 2, 0], state: "minecraft:air"},
        {pos: [7, 2, 1], state: "minecraft:air"},
        {pos: [7, 2, 2], state: "minecraft:air"},
        {pos: [7, 2, 3], state: "minecraft:air"},
        {pos: [7, 2, 4], state: "minecraft:air"},
        {pos: [8, 2, 0], state: "minecraft:air"},
        {pos: [8, 2, 1], state: "minecraft:air"},
        {pos: [8, 2, 2], state: "minecraft:air"},
        {pos: [8, 2, 3], state: "minecraft:air"},
        {pos: [8, 2, 4], state: "minecraft:air"},
        {pos: [0, 3, 0], state: "minecraft:air"},
        {pos: [0, 3, 4], state: "minecraft:air"},
        {pos: [1, 3, 0], state: "minecraft:air"},
        {pos: [1, 3, 2], state: "minecraft:air"},
        {pos: [1, 3, 4], state: "minecraft:air"},
        {pos: [2, 3, 0], state: "minecraft:air"},
        {pos: [2, 3, 2], state: "minecraft:air"},
        {pos: [2, 3, 4], state: "minecraft:air"},
        {pos: [3, 3, 0], state: "minecraft:air"},
        {pos: [3, 3, 2], state: "minecraft:air"},
        {pos: [3, 3, 4], state: "minecraft:air"},
        {pos: [4, 3, 0], state: "minecraft:air"},
        {pos: [4, 3, 4], state: "minecraft:air"},
        {pos: [5, 3, 0], state: "minecraft:air"},
        {pos: [5, 3, 1], state: "minecraft:air"},
        {pos: [5, 3, 2], state: "minecraft:air"},
        {pos: [5, 3, 3], state: "minecraft:air"},
        {pos: [5, 3, 4], state: "minecraft:air"},
        {pos: [6, 3, 0], state: "minecraft:air"},
        {pos: [6, 3, 1], state: "minecraft:air"},
        {pos: [6, 3, 2], state: "minecraft:air"},
        {pos: [6, 3, 3], state: "minecraft:lantern{waterlogged:false,hanging:true}"},
        {pos: [6, 3, 4], state: "minecraft:spruce_fence{east:false,waterlogged:false,south:false,north:false,west:false}"},
        {pos: [7, 3, 0], state: "minecraft:air"},
        {pos: [7, 3, 1], state: "minecraft:air"},
        {pos: [7, 3, 2], state: "minecraft:air"},
        {pos: [7, 3, 3], state: "minecraft:air"},
        {pos: [7, 3, 4], state: "minecraft:air"},
        {pos: [8, 3, 0], state: "minecraft:air"},
        {pos: [8, 3, 1], state: "minecraft:air"},
        {pos: [8, 3, 2], state: "minecraft:air"},
        {pos: [8, 3, 3], state: "minecraft:air"},
        {pos: [8, 3, 4], state: "minecraft:air"},
        {pos: [0, 4, 0], state: "minecraft:air"},
        {pos: [0, 4, 1], state: "minecraft:air"},
        {pos: [0, 4, 2], state: "minecraft:air"},
        {pos: [0, 4, 3], state: "minecraft:air"},
        {pos: [0, 4, 4], state: "minecraft:air"},
        {pos: [1, 4, 0], state: "minecraft:air"},
        {pos: [1, 4, 1], state: "minecraft:air"},
        {pos: [1, 4, 3], state: "minecraft:air"},
        {pos: [1, 4, 4], state: "minecraft:air"},
        {pos: [2, 4, 0], state: "minecraft:air"},
        {pos: [2, 4, 1], state: "minecraft:air"},
        {pos: [2, 4, 3], state: "minecraft:air"},
        {pos: [2, 4, 4], state: "minecraft:air"},
        {pos: [3, 4, 0], state: "minecraft:air"},
        {pos: [3, 4, 1], state: "minecraft:air"},
        {pos: [3, 4, 3], state: "minecraft:air"},
        {pos: [3, 4, 4], state: "minecraft:air"},
        {pos: [4, 4, 0], state: "minecraft:air"},
        {pos: [4, 4, 1], state: "minecraft:air"},
        {pos: [4, 4, 2], state: "minecraft:air"},
        {pos: [4, 4, 3], state: "minecraft:air"},
        {pos: [4, 4, 4], state: "minecraft:air"},
        {pos: [5, 4, 0], state: "minecraft:air"},
        {pos: [5, 4, 1], state: "minecraft:air"},
        {pos: [5, 4, 2], state: "minecraft:air"},
        {pos: [5, 4, 3], state: "minecraft:air"},
        {pos: [5, 4, 4], state: "minecraft:air"},
        {pos: [6, 4, 0], state: "minecraft:air"},
        {pos: [6, 4, 1], state: "minecraft:air"},
        {pos: [6, 4, 2], state: "minecraft:air"},
        {pos: [6, 4, 3], state: "minecraft:spruce_fence{east:false,waterlogged:false,south:true,north:false,west:false}"},
        {pos: [6, 4, 4], state: "minecraft:spruce_fence{east:false,waterlogged:false,south:false,north:true,west:false}"},
        {pos: [7, 4, 0], state: "minecraft:air"},
        {pos: [7, 4, 1], state: "minecraft:air"},
        {pos: [7, 4, 2], state: "minecraft:air"},
        {pos: [7, 4, 3], state: "minecraft:air"},
        {pos: [7, 4, 4], state: "minecraft:air"},
        {pos: [8, 4, 0], state: "minecraft:air"},
        {pos: [8, 4, 1], state: "minecraft:air"},
        {pos: [8, 4, 2], state: "minecraft:air"},
        {pos: [8, 4, 3], state: "minecraft:air"},
        {pos: [8, 4, 4], state: "minecraft:air"},
        {pos: [5, 0, 2], state: "minecraft:jigsaw{orientation:up_north}", nbt: {final_state: "minecraft:dirt", id: "minecraft:jigsaw", joint: "rollable", name: "minecraft:bottom", pool: "minecraft:village/common/butcher_animals", target: "minecraft:bottom"}},
        {pos: [0, 1, 3], state: "minecraft:jigsaw{orientation:west_up}", nbt: {final_state: "minecraft:snow_block", id: "minecraft:jigsaw", joint: "aligned", name: "minecraft:building_entrance", pool: "minecraft:empty", target: "minecraft:building_entrance"}},
        {pos: [7, 1, 2], state: "minecraft:smoker{lit:false,facing:west}", nbt: {Items: [], RecipesUsed: {}, cooking_time_spent: 0s, cooking_total_time: 0s, id: "minecraft:smoker", lit_time_remaining: 0s, lit_total_time: 0s}}
    ],
    entities: [],
    palette: [
        "minecraft:grass_block{snowy:true}",
        "minecraft:dirt",
        "minecraft:grass_block{snowy:false}",
        "minecraft:snow_block",
        "minecraft:spruce_planks",
        "minecraft:snow{layers:1}",
        "minecraft:spruce_door{hinge:right,half:lower,powered:false,facing:west,open:false}",
        "minecraft:air",
        "minecraft:spruce_stairs{half:bottom,waterlogged:false,shape:straight,facing:north}",
        "minecraft:spruce_fence{east:true,waterlogged:false,south:true,north:false,west:false}",
        "minecraft:spruce_fence{east:true,waterlogged:false,south:true,north:false,west:true}",
        "minecraft:spruce_door{hinge:left,half:lower,powered:false,facing:east,open:false}",
        "minecraft:spruce_fence{east:true,waterlogged:false,south:false,north:true,west:true}",
        "minecraft:spruce_fence{east:true,waterlogged:false,south:false,north:false,west:true}",
        "minecraft:spruce_fence{east:false,waterlogged:false,south:true,north:false,west:true}",
        "minecraft:spruce_fence{east:false,waterlogged:false,south:true,north:true,west:false}",
        "minecraft:spruce_fence{east:false,waterlogged:false,south:false,north:true,west:true}",
        "minecraft:spruce_door{hinge:right,half:upper,powered:false,facing:west,open:false}",
        "minecraft:torch",
        "minecraft:spruce_door{hinge:left,half:upper,powered:false,facing:east,open:false}",
        "minecraft:spruce_fence{east:false,waterlogged:false,south:false,north:false,west:false}",
        "minecraft:lantern{waterlogged:false,hanging:true}",
        "minecraft:spruce_fence{east:false,waterlogged:false,south:true,north:false,west:false}",
        "minecraft:spruce_fence{east:false,waterlogged:false,south:false,north:true,west:false}",
        "minecraft:jigsaw{orientation:up_north}",
        "minecraft:jigsaw{orientation:west_up}",
        "minecraft:smoker{lit:false,facing:west}"
    ]
}