{
    size: [8, 8, 7],
    data: [
        {pos: [1, 0, 1], state: "minecraft:stripped_spruce_log{axis:y}"},
        {pos: [1, 0, 2], state: "minecraft:stripped_spruce_log{axis:y}"},
        {pos: [1, 0, 3], state: "minecraft:stripped_spruce_log{axis:y}"},
        {pos: [2, 0, 1], state: "minecraft:stripped_spruce_log{axis:y}"},
        {pos: [2, 0, 2], state: "minecraft:spruce_planks"},
        {pos: [2, 0, 3], state: "minecraft:stripped_spruce_log{axis:y}"},
        {pos: [3, 0, 1], state: "minecraft:stripped_spruce_log{axis:y}"},
        {pos: [3, 0, 2], state: "minecraft:spruce_planks"},
        {pos: [3, 0, 3], state: "minecraft:stripped_spruce_log{axis:y}"},
        {pos: [3, 0, 4], state: "minecraft:stripped_spruce_log{axis:y}"},
        {pos: [3, 0, 5], state: "minecraft:stripped_spruce_log{axis:y}"},
        {pos: [4, 0, 1], state: "minecraft:stripped_spruce_log{axis:y}"},
        {pos: [4, 0, 2], state: "minecraft:spruce_planks"},
        {pos: [4, 0, 3], state: "minecraft:spruce_planks"},
        {pos: [4, 0, 4], state: "minecraft:spruce_planks"},
        {pos: [4, 0, 5], state: "minecraft:stripped_spruce_log{axis:y}"},
        {pos: [5, 0, 1], state: "minecraft:stripped_spruce_log{axis:y}"},
        {pos: [5, 0, 2], state: "minecraft:spruce_planks"},
        {pos: [5, 0, 3], state: "minecraft:spruce_planks"},
        {pos: [5, 0, 4], state: "minecraft:spruce_planks"},
        {pos: [5, 0, 5], state: "minecraft:stripped_spruce_log{axis:y}"},
        {pos: [6, 0, 1], state: "minecraft:stripped_spruce_log{axis:y}"},
        {pos: [6, 0, 2], state: "minecraft:stripped_spruce_log{axis:y}"},
        {pos: [6, 0, 3], state: "minecraft:stripped_spruce_log{axis:y}"},
        {pos: [6, 0, 4], state: "minecraft:stripped_spruce_log{axis:y}"},
        {pos: [6, 0, 5], state: "minecraft:stripped_spruce_log{axis:y}"},
        {pos: [1, 1, 1], state: "minecraft:stripped_spruce_log{axis:y}"},
        {pos: [1, 1, 3], state: "minecraft:stripped_spruce_log{axis:y}"},
        {pos: [2, 1, 1], state: "minecraft:stripped_spruce_log{axis:y}"},
        {pos: [2, 1, 3], state: "minecraft:stripped_spruce_log{axis:y}"},
        {pos: [3, 1, 1], state: "minecraft:stripped_spruce_log{axis:y}"},
        {pos: [3, 1, 3], state: "minecraft:stripped_spruce_log{axis:y}"},
        {pos: [3, 1, 4], state: "minecraft:stripped_spruce_log{axis:y}"},
        {pos: [3, 1, 5], state: "minecraft:stripped_spruce_log{axis:y}"},
        {pos: [4, 1, 1], state: "minecraft:stripped_spruce_log{axis:y}"},
        {pos: [4, 1, 4], state: "minecraft:spruce_planks"},
        {pos: [4, 1, 5], state: "minecraft:stripped_spruce_log{axis:y}"},
        {pos: [5, 1, 1], state: "minecraft:stripped_spruce_log{axis:y}"},
        {pos: [5, 1, 4], state: "minecraft:smithing_table"},
        {pos: [5, 1, 5], state: "minecraft:stripped_spruce_log{axis:y}"},
        {pos: [6, 1, 1], state: "minecraft:stripped_spruce_log{axis:y}"},
        {pos: [6, 1, 2], state: "minecraft:stripped_spruce_log{axis:y}"},
        {pos: [6, 1, 3], state: "minecraft:stripped_spruce_log{axis:y}"},
        {pos: [6, 1, 4], state: "minecraft:stripped_spruce_log{axis:y}"},
        {pos: [6, 1, 5], state: "minecraft:stripped_spruce_log{axis:y}"},
        {pos: [0, 2, 0], state: "minecraft:spruce_planks"},
        {pos: [0, 2, 4], state: "minecraft:spruce_planks"},
        {pos: [1, 2, 0], state: "minecraft:spruce_planks"},
        {pos: [1, 2, 1], state: "minecraft:stripped_spruce_log{axis:y}"},
        {pos: [1, 2, 3], state: "minecraft:stripped_spruce_log{axis:y}"},
        {pos: [1, 2, 4], state: "minecraft:spruce_planks"},
        {pos: [2, 2, 0], state: "minecraft:spruce_planks"},
        {pos: [2, 2, 1], state: "minecraft:stripped_spruce_log{axis:y}"},
        {pos: [2, 2, 3], state: "minecraft:stripped_spruce_log{axis:y}"},
        {pos: [2, 2, 4], state: "minecraft:spruce_planks"},
        {pos: [2, 2, 5], state: "minecraft:spruce_planks"},
        {pos: [2, 2, 6], state: "minecraft:spruce_planks"},
        {pos: [3, 2, 0], state: "minecraft:spruce_planks"},
        {pos: [3, 2, 1], state: "minecraft:stripped_spruce_log{axis:y}"},
        {pos: [3, 2, 3], state: "minecraft:stripped_spruce_log{axis:y}"},
        {pos: [3, 2, 4], state: "minecraft:stripped_spruce_log{axis:y}"},
        {pos: [3, 2, 5], state: "minecraft:stripped_spruce_log{axis:y}"},
        {pos: [3, 2, 6], state: "minecraft:spruce_planks"},
        {pos: [4, 2, 0], state: "minecraft:spruce_planks"},
        {pos: [4, 2, 1], state: "minecraft:stripped_spruce_log{axis:y}"},
        {pos: [4, 2, 5], state: "minecraft:stripped_spruce_log{axis:y}"},
        {pos: [4, 2, 6], state: "minecraft:spruce_planks"},
        {pos: [5, 2, 0], state: "minecraft:spruce_planks"},
        {pos: [5, 2, 1], state: "minecraft:stripped_spruce_log{axis:y}"},
        {pos: [5, 2, 5], state: "minecraft:stripped_spruce_log{axis:y}"},
        {pos: [5, 2, 6], state: "minecraft:spruce_planks"},
        {pos: [6, 2, 0], state: "minecraft:spruce_planks"},
        {pos: [6, 2, 1], state: "minecraft:stripped_spruce_log{axis:y}"},
        {pos: [6, 2, 2], state: "minecraft:stripped_spruce_log{axis:y}"},
        {pos: [6, 2, 3], state: "minecraft:stripped_spruce_log{axis:y}"},
        {pos: [6, 2, 4], state: "minecraft:stripped_spruce_log{axis:y}"},
        {pos: [6, 2, 5], state: "minecraft:stripped_spruce_log{axis:y}"},
        {pos: [6, 2, 6], state: "minecraft:spruce_planks"},
        {pos: [7, 2, 0], state: "minecraft:spruce_planks"},
        {pos: [7, 2, 6], state: "minecraft:spruce_planks"},
        {pos: [0, 3, 0], state: "minecraft:spruce_planks"},
        {pos: [0, 3, 4], state: "minecraft:spruce_planks"},
        {pos: [1, 3, 0], state: "minecraft:spruce_planks"},
        {pos: [1, 3, 1], state: "minecraft:stripped_spruce_log{axis:y}"},
        {pos: [1, 3, 2], state: "minecraft:stripped_spruce_log{axis:x}"},
        {pos: [1, 3, 3], state: "minecraft:stripped_spruce_log{axis:y}"},
        {pos: [1, 3, 4], state: "minecraft:spruce_planks"},
        {pos: [2, 3, 0], state: "minecraft:spruce_planks"},
        {pos: [2, 3, 1], state: "minecraft:stripped_spruce_log{axis:z}"},
        {pos: [2, 3, 3], state: "minecraft:stripped_spruce_log{axis:z}"},
        {pos: [2, 3, 4], state: "minecraft:spruce_planks"},
        {pos: [2, 3, 5], state: "minecraft:spruce_planks"},
        {pos: [2, 3, 6], state: "minecraft:spruce_planks"},
        {pos: [3, 3, 0], state: "minecraft:spruce_planks"},
        {pos: [3, 3, 1], state: "minecraft:stripped_spruce_log{axis:x}"},
        {pos: [3, 3, 3], state: "minecraft:stripped_spruce_log{axis:x}"},
        {pos: [3, 3, 4], state: "minecraft:stripped_spruce_log{axis:z}"},
        {pos: [3, 3, 5], state: "minecraft:stripped_spruce_log{axis:y}"},
        {pos: [3, 3, 6], state: "minecraft:spruce_planks"},
        {pos: [4, 3, 0], state: "minecraft:spruce_planks"},
        {pos: [4, 3, 1], state: "minecraft:stripped_spruce_log{axis:z}"},
        {pos: [4, 3, 5], state: "minecraft:stripped_spruce_log{axis:z}"},
        {pos: [4, 3, 6], state: "minecraft:spruce_planks"},
        {pos: [5, 3, 0], state: "minecraft:spruce_planks"},
        {pos: [5, 3, 1], state: "minecraft:stripped_spruce_log{axis:x}"},
        {pos: [5, 3, 5], state: "minecraft:stripped_spruce_log{axis:x}"},
        {pos: [5, 3, 6], state: "minecraft:spruce_planks"},
        {pos: [6, 3, 0], state: "minecraft:spruce_planks"},
        {pos: [6, 3, 1], state: "minecraft:stripped_spruce_log{axis:y}"},
        {pos: [6, 3, 2], state: "minecraft:stripped_spruce_log{axis:x}"},
        {pos: [6, 3, 3], state: "minecraft:stripped_spruce_log{axis:z}"},
        {pos: [6, 3, 4], state: "minecraft:stripped_spruce_log{axis:x}"},
        {pos: [6, 3, 5], state: "minecraft:stripped_spruce_log{axis:y}"},
        {pos: [6, 3, 6], state: "minecraft:spruce_planks"},
        {pos: [7, 3, 0], state: "minecraft:spruce_planks"},
        {pos: [7, 3, 6], state: "minecraft:spruce_planks"},
        {pos: [0, 4, 1], state: "minecraft:spruce_planks"},
        {pos: [0, 4, 3], state: "minecraft:spruce_planks"},
        {pos: [1, 4, 1], state: "minecraft:spruce_planks"},
        {pos: [1, 4, 2], state: "minecraft:stripped_spruce_log{axis:y}"},
        {pos: [1, 4, 3], state: "minecraft:spruce_planks"},
        {pos: [2, 4, 1], state: "minecraft:spruce_planks"},
        {pos: [2, 4, 3], state: "minecraft:spruce_planks"},
        {pos: [3, 4, 1], state: "minecraft:spruce_planks"},
        {pos: [3, 4, 3], state: "minecraft:spruce_planks"},
        {pos: [3, 4, 4], state: "minecraft:spruce_planks"},
        {pos: [3, 4, 5], state: "minecraft:spruce_planks"},
        {pos: [4, 4, 1], state: "minecraft:spruce_planks"},
        {pos: [4, 4, 5], state: "minecraft:spruce_planks"},
        {pos: [5, 4, 1], state: "minecraft:spruce_planks"},
        {pos: [5, 4, 5], state: "minecraft:spruce_planks"},
        {pos: [6, 4, 1], state: "minecraft:spruce_planks"},
        {pos: [6, 4, 2], state: "minecraft:stripped_spruce_log{axis:y}"},
        {pos: [6, 4, 3], state: "minecraft:stripped_spruce_log{axis:y}"},
        {pos: [6, 4, 4], state: "minecraft:stripped_spruce_log{axis:y}"},
        {pos: [6, 4, 5], state: "minecraft:spruce_planks"},
        {pos: [7, 4, 1], state: "minecraft:spruce_planks"},
        {pos: [7, 4, 5], state: "minecraft:spruce_planks"},
        {pos: [0, 5, 1], state: "minecraft:spruce_planks"},
        {pos: [0, 5, 3], state: "minecraft:spruce_planks"},
        {pos: [1, 5, 1], state: "minecraft:spruce_planks"},
        {pos: [1, 5, 2], state: "minecraft:stripped_spruce_log{axis:y}"},
        {pos: [1, 5, 3], state: "minecraft:spruce_planks"},
        {pos: [2, 5, 1], state: "minecraft:spruce_planks"},
        {pos: [2, 5, 3], state: "minecraft:spruce_planks"},
        {pos: [3, 5, 1], state: "minecraft:spruce_planks"},
        {pos: [3, 5, 3], state: "minecraft:spruce_planks"},
        {pos: [3, 5, 4], state: "minecraft:spruce_planks"},
        {pos: [3, 5, 5], state: "minecraft:spruce_planks"},
        {pos: [4, 5, 1], state: "minecraft:spruce_planks"},
        {pos: [4, 5, 5], state: "minecraft:spruce_planks"},
        {pos: [5, 5, 1], state: "minecraft:spruce_planks"},
        {pos: [5, 5, 5], state: "minecraft:spruce_planks"},
        {pos: [6, 5, 1], state: "minecraft:spruce_planks"},
        {pos: [6, 5, 2], state: "minecraft:stripped_spruce_log{axis:y}"},
        {pos: [6, 5, 3], state: "minecraft:stripped_spruce_log{axis:y}"},
        {pos: [6, 5, 4], state: "minecraft:stripped_spruce_log{axis:y}"},
        {pos: [6, 5, 5], state: "minecraft:spruce_planks"},
        {pos: [7, 5, 1], state: "minecraft:spruce_planks"},
        {pos: [7, 5, 5], state: "minecraft:spruce_planks"},
        {pos: [0, 6, 2], state: "minecraft:spruce_planks"},
        {pos: [1, 6, 2], state: "minecraft:spruce_planks"},
        {pos: [2, 6, 2], state: "minecraft:spruce_planks"},
        {pos: [3, 6, 2], state: "minecraft:spruce_planks"},
        {pos: [4, 6, 2], state: "minecraft:spruce_planks"},
        {pos: [4, 6, 3], state: "minecraft:spruce_planks"},
        {pos: [4, 6, 4], state: "minecraft:spruce_planks"},
        {pos: [5, 6, 2], state: "minecraft:spruce_planks"},
        {pos: [5, 6, 3], state: "minecraft:spruce_planks"},
        {pos: [5, 6, 4], state: "minecraft:spruce_planks"},
        {pos: [6, 6, 2], state: "minecraft:spruce_planks"},
        {pos: [6, 6, 3], state: "minecraft:stripped_spruce_log{axis:y}"},
        {pos: [6, 6, 4], state: "minecraft:spruce_planks"},
        {pos: [7, 6, 2], state: "minecraft:spruce_planks"},
        {pos: [7, 6, 4], state: "minecraft:spruce_planks"},
        {pos: [5, 7, 3], state: "minecraft:spruce_slab{waterlogged:false,type:double}"},
        {pos: [6, 7, 3], state: "minecraft:spruce_slab{waterlogged:false,type:double}"},
        {pos: [7, 7, 3], state: "minecraft:spruce_slab{waterlogged:false,type:double}"},
        {pos: [0, 0, 0], state: "minecraft:snow{layers:1}"},
        {pos: [0, 0, 1], state: "minecraft:spruce_stairs{half:bottom,waterlogged:false,shape:outer_left,facing:south}"},
        {pos: [0, 0, 2], state: "minecraft:spruce_stairs{half:bottom,waterlogged:false,shape:straight,facing:east}"},
        {pos: [0, 0, 3], state: "minecraft:spruce_stairs{half:bottom,waterlogged:false,shape:outer_right,facing:north}"},
        {pos: [0, 0, 5], state: "minecraft:snow{layers:1}"},
        {pos: [0, 0, 6], state: "minecraft:snow{layers:1}"},
        {pos: [1, 0, 0], state: "minecraft:snow{layers:1}"},
        {pos: [1, 0, 4], state: "minecraft:snow{layers:1}"},
        {pos: [1, 0, 5], state: "minecraft:snow{layers:1}"},
        {pos: [1, 0, 6], state: "minecraft:snow{layers:1}"},
        {pos: [2, 0, 0], state: "minecraft:snow{layers:1}"},
        {pos: [2, 0, 4], state: "minecraft:snow{layers:1}"},
        {pos: [2, 0, 5], state: "minecraft:snow{layers:1}"},
        {pos: [2, 0, 6], state: "minecraft:snow{layers:1}"},
        {pos: [3, 0, 0], state: "minecraft:snow{layers:1}"},
        {pos: [3, 0, 6], state: "minecraft:snow{layers:1}"},
        {pos: [4, 0, 0], state: "minecraft:snow{layers:1}"},
        {pos: [4, 0, 6], state: "minecraft:snow{layers:1}"},
        {pos: [5, 0, 0], state: "minecraft:snow{layers:1}"},
        {pos: [5, 0, 6], state: "minecraft:snow{layers:1}"},
        {pos: [6, 0, 0], state: "minecraft:snow{layers:1}"},
        {pos: [6, 0, 6], state: "minecraft:snow{layers:1}"},
        {pos: [7, 0, 0], state: "minecraft:snow{layers:1}"},
        {pos: [7, 0, 1], state: "minecraft:snow{layers:1}"},
        {pos: [7, 0, 2], state: "minecraft:snow{layers:1}"},
        {pos: [7, 0, 3], state: "minecraft:snow{layers:1}"},
        {pos: [7, 0, 4], state: "minecraft:snow{layers:1}"},
        {pos: [7, 0, 5], state: "minecraft:snow{layers:1}"},
        {pos: [7, 0, 6], state: "minecraft:snow{layers:1}"},
        {pos: [0, 1, 0], state: "minecraft:air"},
        {pos: [0, 1, 1], state: "minecraft:air"},
        {pos: [0, 1, 2], state: "minecraft:air"},
        {pos: [0, 1, 3], state: "minecraft:air"},
        {pos: [0, 1, 4], state: "minecraft:air"},
        {pos: [0, 1, 5], state: "minecraft:air"},
        {pos: [0, 1, 6], state: "minecraft:air"},
        {pos: [1, 1, 0], state: "minecraft:air"},
        {pos: [1, 1, 2], state: "minecraft:spruce_door{hinge:right,half:lower,powered:false,facing:east,open:false}"},
        {pos: [1, 1, 4], state: "minecraft:air"},
        {pos: [1, 1, 5], state: "minecraft:air"},
        {pos: [1, 1, 6], state: "minecraft:air"},
        {pos: [2, 1, 0], state: "minecraft:air"},
        {pos: [2, 1, 2], state: "minecraft:air"},
        {pos: [2, 1, 4], state: "minecraft:air"},
        {pos: [2, 1, 5], state: "minecraft:air"},
        {pos: [2, 1, 6], state: "minecraft:air"},
        {pos: [3, 1, 0], state: "minecraft:air"},
        {pos: [3, 1, 2], state: "minecraft:air"},
        {pos: [3, 1, 6], state: "minecraft:air"},
        {pos: [4, 1, 0], state: "minecraft:air"},
        {pos: [4, 1, 2], state: "minecraft:air"},
        {pos: [4, 1, 3], state: "minecraft:air"},
        {pos: [4, 1, 6], state: "minecraft:air"},
        {pos: [5, 1, 0], state: "minecraft:air"},
        {pos: [5, 1, 2], state: "minecraft:air"},
        {pos: [5, 1, 3], state: "minecraft:air"},
        {pos: [5, 1, 6], state: "minecraft:air"},
        {pos: [6, 1, 0], state: "minecraft:air"},
        {pos: [6, 1, 6], state: "minecraft:air"},
        {pos: [7, 1, 0], state: "minecraft:air"},
        {pos: [7, 1, 1], state: "minecraft:air"},
        {pos: [7, 1, 2], state: "minecraft:air"},
        {pos: [7, 1, 3], state: "minecraft:air"},
        {pos: [7, 1, 4], state: "minecraft:air"},
        {pos: [7, 1, 5], state: "minecraft:air"},
        {pos: [7, 1, 6], state: "minecraft:air"},
        {pos: [0, 2, 1], state: "minecraft:air"},
        {pos: [0, 2, 2], state: "minecraft:air"},
        {pos: [0, 2, 3], state: "minecraft:air"},
        {pos: [0, 2, 5], state: "minecraft:air"},
        {pos: [0, 2, 6], state: "minecraft:air"},
        {pos: [1, 2, 2], state: "minecraft:spruce_door{hinge:right,half:upper,powered:false,facing:east,open:false}"},
        {pos: [1, 2, 5], state: "minecraft:air"},
        {pos: [1, 2, 6], state: "minecraft:air"},
        {pos: [2, 2, 2], state: "minecraft:air"},
        {pos: [3, 2, 2], state: "minecraft:air"},
        {pos: [4, 2, 2], state: "minecraft:air"},
        {pos: [4, 2, 3], state: "minecraft:air"},
        {pos: [4, 2, 4], state: "minecraft:lantern{waterlogged:false,hanging:false}"},
        {pos: [5, 2, 2], state: "minecraft:air"},
        {pos: [5, 2, 3], state: "minecraft:air"},
        {pos: [5, 2, 4], state: "minecraft:air"},
        {pos: [7, 2, 1], state: "minecraft:air"},
        {pos: [7, 2, 2], state: "minecraft:air"},
        {pos: [7, 2, 3], state: "minecraft:air"},
        {pos: [7, 2, 4], state: "minecraft:air"},
        {pos: [7, 2, 5], state: "minecraft:air"},
        {pos: [0, 3, 1], state: "minecraft:air"},
        {pos: [0, 3, 2], state: "minecraft:air"},
        {pos: [0, 3, 3], state: "minecraft:air"},
        {pos: [0, 3, 5], state: "minecraft:air"},
        {pos: [0, 3, 6], state: "minecraft:air"},
        {pos: [1, 3, 5], state: "minecraft:air"},
        {pos: [1, 3, 6], state: "minecraft:air"},
        {pos: [2, 3, 2], state: "minecraft:air"},
        {pos: [3, 3, 2], state: "minecraft:air"},
        {pos: [4, 3, 2], state: "minecraft:air"},
        {pos: [4, 3, 3], state: "minecraft:air"},
        {pos: [4, 3, 4], state: "minecraft:air"},
        {pos: [5, 3, 2], state: "minecraft:air"},
        {pos: [5, 3, 3], state: "minecraft:air"},
        {pos: [5, 3, 4], state: "minecraft:air"},
        {pos: [7, 3, 1], state: "minecraft:air"},
        {pos: [7, 3, 2], state: "minecraft:air"},
        {pos: [7, 3, 3], state: "minecraft:air"},
        {pos: [7, 3, 4], state: "minecraft:air"},
        {pos: [7, 3, 5], state: "minecraft:air"},
        {pos: [0, 4, 0], state: "minecraft:spruce_slab{waterlogged:false,type:bottom}"},
        {pos: [0, 4, 2], state: "minecraft:air"},
        {pos: [0, 4, 4], state: "minecraft:spruce_slab{waterlogged:false,type:bottom}"},
        {pos: [0, 4, 5], state: "minecraft:air"},
        {pos: [0, 4, 6], state: "minecraft:air"},
        {pos: [1, 4, 0], state: "minecraft:spruce_slab{waterlogged:false,type:bottom}"},
        {pos: [1, 4, 4], state: "minecraft:spruce_stairs{half:bottom,waterlogged:false,shape:straight,facing:north}"},
        {pos: [1, 4, 5], state: "minecraft:air"},
        {pos: [1, 4, 6], state: "minecraft:air"},
        {pos: [2, 4, 0], state: "minecraft:spruce_slab{waterlogged:false,type:bottom}"},
        {pos: [2, 4, 2], state: "minecraft:air"},
        {pos: [2, 4, 4], state: "minecraft:spruce_stairs{half:bottom,waterlogged:false,shape:inner_left,facing:east}"},
        {pos: [2, 4, 5], state: "minecraft:spruce_stairs{half:bottom,waterlogged:false,shape:straight,facing:east}"},
        {pos: [2, 4, 6], state: "minecraft:spruce_slab{waterlogged:false,type:bottom}"},
        {pos: [3, 4, 0], state: "minecraft:spruce_slab{waterlogged:false,type:bottom}"},
        {pos: [3, 4, 2], state: "minecraft:air"},
        {pos: [3, 4, 6], state: "minecraft:spruce_slab{waterlogged:false,type:bottom}"},
        {pos: [4, 4, 0], state: "minecraft:spruce_slab{waterlogged:false,type:bottom}"},
        {pos: [4, 4, 2], state: "minecraft:air"},
        {pos: [4, 4, 3], state: "minecraft:air"},
        {pos: [4, 4, 4], state: "minecraft:air"},
        {pos: [4, 4, 6], state: "minecraft:spruce_slab{waterlogged:false,type:bottom}"},
        {pos: [5, 4, 0], state: "minecraft:spruce_slab{waterlogged:false,type:bottom}"},
        {pos: [5, 4, 2], state: "minecraft:air"},
        {pos: [5, 4, 3], state: "minecraft:air"},
        {pos: [5, 4, 4], state: "minecraft:air"},
        {pos: [5, 4, 6], state: "minecraft:spruce_slab{waterlogged:false,type:bottom}"},
        {pos: [6, 4, 0], state: "minecraft:spruce_slab{waterlogged:false,type:bottom}"},
        {pos: [6, 4, 6], state: "minecraft:spruce_slab{waterlogged:false,type:bottom}"},
        {pos: [7, 4, 0], state: "minecraft:spruce_slab{waterlogged:false,type:bottom}"},
        {pos: [7, 4, 2], state: "minecraft:air"},
        {pos: [7, 4, 3], state: "minecraft:air"},
        {pos: [7, 4, 4], state: "minecraft:air"},
        {pos: [7, 4, 6], state: "minecraft:spruce_slab{waterlogged:false,type:bottom}"},
        {pos: [0, 5, 0], state: "minecraft:air"},
        {pos: [0, 5, 2], state: "minecraft:air"},
        {pos: [0, 5, 4], state: "minecraft:air"},
        {pos: [0, 5, 5], state: "minecraft:air"},
        {pos: [0, 5, 6], state: "minecraft:air"},
        {pos: [1, 5, 0], state: "minecraft:air"},
        {pos: [1, 5, 4], state: "minecraft:air"},
        {pos: [1, 5, 5], state: "minecraft:air"},
        {pos: [1, 5, 6], state: "minecraft:air"},
        {pos: [2, 5, 0], state: "minecraft:air"},
        {pos: [2, 5, 2], state: "minecraft:air"},
        {pos: [2, 5, 4], state: "minecraft:air"},
        {pos: [2, 5, 5], state: "minecraft:air"},
        {pos: [2, 5, 6], state: "minecraft:air"},
        {pos: [3, 5, 0], state: "minecraft:air"},
        {pos: [3, 5, 2], state: "minecraft:air"},
        {pos: [3, 5, 6], state: "minecraft:air"},
        {pos: [4, 5, 0], state: "minecraft:air"},
        {pos: [4, 5, 2], state: "minecraft:lantern{waterlogged:false,hanging:true}"},
        {pos: [4, 5, 3], state: "minecraft:air"},
        {pos: [4, 5, 4], state: "minecraft:air"},
        {pos: [4, 5, 6], state: "minecraft:air"},
        {pos: [5, 5, 0], state: "minecraft:air"},
        {pos: [5, 5, 2], state: "minecraft:air"},
        {pos: [5, 5, 3], state: "minecraft:air"},
        {pos: [5, 5, 4], state: "minecraft:air"},
        {pos: [5, 5, 6], state: "minecraft:air"},
        {pos: [6, 5, 0], state: "minecraft:air"},
        {pos: [6, 5, 6], state: "minecraft:air"},
        {pos: [7, 5, 0], state: "minecraft:air"},
        {pos: [7, 5, 2], state: "minecraft:air"},
        {pos: [7, 5, 3], state: "minecraft:air"},
        {pos: [7, 5, 4], state: "minecraft:air"},
        {pos: [7, 5, 6], state: "minecraft:air"},
        {pos: [0, 6, 0], state: "minecraft:air"},
        {pos: [0, 6, 1], state: "minecraft:spruce_slab{waterlogged:false,type:bottom}"},
        {pos: [0, 6, 3], state: "minecraft:spruce_slab{waterlogged:false,type:bottom}"},
        {pos: [0, 6, 4], state: "minecraft:air"},
        {pos: [0, 6, 5], state: "minecraft:air"},
        {pos: [0, 6, 6], state: "minecraft:air"},
        {pos: [1, 6, 0], state: "minecraft:air"},
        {pos: [1, 6, 1], state: "minecraft:spruce_slab{waterlogged:false,type:bottom}"},
        {pos: [1, 6, 3], state: "minecraft:spruce_slab{waterlogged:false,type:bottom}"},
        {pos: [1, 6, 4], state: "minecraft:air"},
        {pos: [1, 6, 5], state: "minecraft:air"},
        {pos: [1, 6, 6], state: "minecraft:air"},
        {pos: [2, 6, 0], state: "minecraft:air"},
        {pos: [2, 6, 1], state: "minecraft:spruce_slab{waterlogged:false,type:bottom}"},
        {pos: [2, 6, 3], state: "minecraft:spruce_stairs{half:bottom,waterlogged:false,shape:straight,facing:north}"},
        {pos: [2, 6, 4], state: "minecraft:air"},
        {pos: [2, 6, 5], state: "minecraft:air"},
        {pos: [2, 6, 6], state: "minecraft:air"},
        {pos: [3, 6, 0], state: "minecraft:air"},
        {pos: [3, 6, 1], state: "minecraft:spruce_slab{waterlogged:false,type:bottom}"},
        {pos: [3, 6, 3], state: "minecraft:spruce_stairs{half:bottom,waterlogged:false,shape:inner_left,facing:east}"},
        {pos: [3, 6, 4], state: "minecraft:spruce_stairs{half:bottom,waterlogged:false,shape:straight,facing:east}"},
        {pos: [3, 6, 5], state: "minecraft:spruce_slab{waterlogged:false,type:bottom}"},
        {pos: [3, 6, 6], state: "minecraft:air"},
        {pos: [4, 6, 0], state: "minecraft:air"},
        {pos: [4, 6, 1], state: "minecraft:spruce_slab{waterlogged:false,type:bottom}"},
        {pos: [4, 6, 5], state: "minecraft:spruce_slab{waterlogged:false,type:bottom}"},
        {pos: [4, 6, 6], state: "minecraft:air"},
        {pos: [5, 6, 0], state: "minecraft:air"},
        {pos: [5, 6, 1], state: "minecraft:spruce_slab{waterlogged:false,type:bottom}"},
        {pos: [5, 6, 5], state: "minecraft:spruce_slab{waterlogged:false,type:bottom}"},
        {pos: [5, 6, 6], state: "minecraft:air"},
        {pos: [6, 6, 0], state: "minecraft:air"},
        {pos: [6, 6, 1], state: "minecraft:spruce_slab{waterlogged:false,type:bottom}"},
        {pos: [6, 6, 5], state: "minecraft:spruce_slab{waterlogged:false,type:bottom}"},
        {pos: [6, 6, 6], state: "minecraft:air"},
        {pos: [7, 6, 0], state: "minecraft:air"},
        {pos: [7, 6, 1], state: "minecraft:spruce_slab{waterlogged:false,type:bottom}"},
        {pos: [7, 6, 3], state: "minecraft:spruce_slab{waterlogged:false,type:top}"},
        {pos: [7, 6, 5], state: "minecraft:spruce_slab{waterlogged:false,type:bottom}"},
        {pos: [7, 6, 6], state: "minecraft:air"},
        {pos: [0, 7, 0], state: "minecraft:air"},
        {pos: [0, 7, 1], state: "minecraft:air"},
        {pos: [0, 7, 2], state: "minecraft:air"},
        {pos: [0, 7, 3], state: "minecraft:air"},
        {pos: [0, 7, 4], state: "minecraft:air"},
        {pos: [0, 7, 5], state: "minecraft:air"},
        {pos: [0, 7, 6], state: "minecraft:air"},
        {pos: [1, 7, 0], state: "minecraft:air"},
        {pos: [1, 7, 1], state: "minecraft:air"},
        {pos: [1, 7, 2], state: "minecraft:air"},
        {pos: [1, 7, 3], state: "minecraft:air"},
        {pos: [1, 7, 4], state: "minecraft:air"},
        {pos: [1, 7, 5], state: "minecraft:air"},
        {pos: [1, 7, 6], state: "minecraft:air"},
        {pos: [2, 7, 0], state: "minecraft:air"},
        {pos: [2, 7, 1], state: "minecraft:air"},
        {pos: [2, 7, 2], state: "minecraft:air"},
        {pos: [2, 7, 3], state: "minecraft:air"},
        {pos: [2, 7, 4], state: "minecraft:air"},
        {pos: [2, 7, 5], state: "minecraft:air"},
        {pos: [2, 7, 6], state: "minecraft:air"},
        {pos: [3, 7, 0], state: "minecraft:air"},
        {pos: [3, 7, 1], state: "minecraft:air"},
        {pos: [3, 7, 2], state: "minecraft:air"},
        {pos: [3, 7, 3], state: "minecraft:air"},
        {pos: [3, 7, 4], state: "minecraft:air"},
        {pos: [3, 7, 5], state: "minecraft:air"},
        {pos: [3, 7, 6], state: "minecraft:air"},
        {pos: [4, 7, 0], state: "minecraft:air"},
        {pos: [4, 7, 1], state: "minecraft:air"},
        {pos: [4, 7, 2], state: "minecraft:air"},
        {pos: [4, 7, 3], state: "minecraft:air"},
        {pos: [4, 7, 4], state: "minecraft:air"},
        {pos: [4, 7, 5], state: "minecraft:air"},
        {pos: [4, 7, 6], state: "minecraft:air"},
        {pos: [5, 7, 0], state: "minecraft:air"},
        {pos: [5, 7, 1], state: "minecraft:air"},
        {pos: [5, 7, 2], state: "minecraft:air"},
        {pos: [5, 7, 4], state: "minecraft:air"},
        {pos: [5, 7, 5], state: "minecraft:air"},
        {pos: [5, 7, 6], state: "minecraft:air"},
        {pos: [6, 7, 0], state: "minecraft:air"},
        {pos: [6, 7, 1], state: "minecraft:air"},
        {pos: [6, 7, 2], state: "minecraft:air"},
        {pos: [6, 7, 4], state: "minecraft:air"},
        {pos: [6, 7, 5], state: "minecraft:air"},
        {pos: [6, 7, 6], state: "minecraft:air"},
        {pos: [7, 7, 0], state: "minecraft:air"},
        {pos: [7, 7, 1], state: "minecraft:air"},
        {pos: [7, 7, 2], state: "minecraft:air"},
        {pos: [7, 7, 4], state: "minecraft:air"},
        {pos: [7, 7, 5], state: "minecraft:air"},
        {pos: [7, 7, 6], state: "minecraft:air"},
        {pos: [0, 0, 4], state: "minecraft:jigsaw{orientation:west_up}", nbt: {final_state: "minecraft:structure_void", id: "minecraft:jigsaw", joint: "aligned", name: "minecraft:building_entrance", pool: "minecraft:empty", target: "minecraft:building_entrance"}}
    ],
    entities: [],
    palette: [
        "minecraft:stripped_spruce_log{axis:y}",
        "minecraft:spruce_planks",
        "minecraft:smithing_table",
        "minecraft:stripped_spruce_log{axis:x}",
        "minecraft:stripped_spruce_log{axis:z}",
        "minecraft:spruce_slab{waterlogged:false,type:double}",
        "minecraft:snow{layers:1}",
        "minecraft:spruce_stairs{half:bottom,waterlogged:false,shape:outer_left,facing:south}",
        "minecraft:spruce_stairs{half:bottom,waterlogged:false,shape:straight,facing:east}",
        "minecraft:spruce_stairs{half:bottom,waterlogged:false,shape:outer_right,facing:north}",
        "minecraft:air",
        "minecraft:spruce_door{hinge:right,half:lower,powered:false,facing:east,open:false}",
        "minecraft:spruce_door{hinge:right,half:upper,powered:false,facing:east,open:false}",
        "minecraft:lantern{waterlogged:false,hanging:false}",
        "minecraft:spruce_slab{waterlogged:false,type:bottom}",
        "minecraft:spruce_stairs{half:bottom,waterlogged:false,shape:straight,facing:north}",
        "minecraft:spruce_stairs{half:bottom,waterlogged:false,shape:inner_left,facing:east}",
        "minecraft:lantern{waterlogged:false,hanging:true}",
        "minecraft:spruce_slab{waterlogged:false,type:top}",
        "minecraft:jigsaw{orientation:west_up}"
    ]
}