{
    size: [7, 7, 7],
    data: [
        {pos: [0, 0, 0], state: "minecraft:grass_block{snowy:false}"},
        {pos: [0, 0, 1], state: "minecraft:grass_block{snowy:false}"},
        {pos: [0, 0, 2], state: "minecraft:grass_block{snowy:false}"},
        {pos: [0, 0, 3], state: "minecraft:grass_block{snowy:false}"},
        {pos: [0, 0, 4], state: "minecraft:grass_block{snowy:false}"},
        {pos: [0, 0, 5], state: "minecraft:grass_block{snowy:false}"},
        {pos: [0, 0, 6], state: "minecraft:grass_block{snowy:false}"},
        {pos: [1, 0, 0], state: "minecraft:grass_block{snowy:false}"},
        {pos: [1, 0, 1], state: "minecraft:grass_block{snowy:false}"},
        {pos: [1, 0, 2], state: "minecraft:dirt"},
        {pos: [1, 0, 3], state: "minecraft:dirt"},
        {pos: [1, 0, 4], state: "minecraft:dirt"},
        {pos: [1, 0, 5], state: "minecraft:grass_block{snowy:false}"},
        {pos: [1, 0, 6], state: "minecraft:grass_block{snowy:false}"},
        {pos: [2, 0, 0], state: "minecraft:grass_block{snowy:false}"},
        {pos: [2, 0, 1], state: "minecraft:dirt"},
        {pos: [2, 0, 2], state: "minecraft:acacia_wood{axis:y}"},
        {pos: [2, 0, 3], state: "minecraft:acacia_wood{axis:z}"},
        {pos: [2, 0, 4], state: "minecraft:acacia_wood{axis:y}"},
        {pos: [2, 0, 5], state: "minecraft:dirt"},
        {pos: [2, 0, 6], state: "minecraft:dirt"},
        {pos: [3, 0, 0], state: "minecraft:grass_block{snowy:false}"},
        {pos: [3, 0, 1], state: "minecraft:dirt"},
        {pos: [3, 0, 2], state: "minecraft:acacia_wood{axis:y}"},
        {pos: [3, 0, 3], state: "minecraft:acacia_wood{axis:y}"},
        {pos: [3, 0, 4], state: "minecraft:acacia_wood{axis:y}"},
        {pos: [3, 0, 5], state: "minecraft:acacia_wood{axis:z}"},
        {pos: [4, 0, 0], state: "minecraft:grass_block{snowy:false}"},
        {pos: [4, 0, 1], state: "minecraft:dirt"},
        {pos: [4, 0, 2], state: "minecraft:acacia_wood{axis:y}"},
        {pos: [4, 0, 3], state: "minecraft:acacia_wood{axis:y}"},
        {pos: [4, 0, 4], state: "minecraft:acacia_wood{axis:y}"},
        {pos: [4, 0, 5], state: "minecraft:dirt"},
        {pos: [4, 0, 6], state: "minecraft:grass_block{snowy:false}"},
        {pos: [5, 0, 0], state: "minecraft:grass_block{snowy:false}"},
        {pos: [5, 0, 1], state: "minecraft:grass_block{snowy:false}"},
        {pos: [5, 0, 2], state: "minecraft:dirt"},
        {pos: [5, 0, 3], state: "minecraft:dirt"},
        {pos: [5, 0, 4], state: "minecraft:dirt"},
        {pos: [5, 0, 5], state: "minecraft:grass_block{snowy:false}"},
        {pos: [6, 0, 0], state: "minecraft:grass_block{snowy:false}"},
        {pos: [6, 0, 1], state: "minecraft:grass_block{snowy:false}"},
        {pos: [6, 0, 2], state: "minecraft:grass_block{snowy:false}"},
        {pos: [6, 0, 3], state: "minecraft:grass_block{snowy:false}"},
        {pos: [6, 0, 4], state: "minecraft:grass_block{snowy:false}"},
        {pos: [6, 0, 5], state: "minecraft:grass_block{snowy:false}"},
        {pos: [6, 0, 6], state: "minecraft:grass_block{snowy:false}"},
        {pos: [1, 1, 2], state: "minecraft:acacia_log{axis:y}"},
        {pos: [1, 1, 3], state: "minecraft:acacia_log{axis:z}"},
        {pos: [1, 1, 4], state: "minecraft:acacia_log{axis:y}"},
        {pos: [2, 1, 1], state: "minecraft:acacia_log{axis:y}"},
        {pos: [2, 1, 5], state: "minecraft:acacia_log{axis:y}"},
        {pos: [3, 1, 1], state: "minecraft:acacia_log{axis:x}"},
        {pos: [4, 1, 1], state: "minecraft:acacia_log{axis:y}"},
        {pos: [4, 1, 3], state: "minecraft:acacia_wood{axis:y}"},
        {pos: [4, 1, 5], state: "minecraft:acacia_log{axis:y}"},
        {pos: [5, 1, 2], state: "minecraft:acacia_log{axis:y}"},
        {pos: [5, 1, 3], state: "minecraft:acacia_log{axis:z}"},
        {pos: [5, 1, 4], state: "minecraft:acacia_log{axis:y}"},
        {pos: [1, 2, 2], state: "minecraft:acacia_log{axis:y}"},
        {pos: [1, 2, 4], state: "minecraft:acacia_log{axis:y}"},
        {pos: [2, 2, 1], state: "minecraft:acacia_log{axis:y}"},
        {pos: [2, 2, 5], state: "minecraft:acacia_log{axis:y}"},
        {pos: [4, 2, 1], state: "minecraft:acacia_log{axis:y}"},
        {pos: [4, 2, 5], state: "minecraft:acacia_log{axis:y}"},
        {pos: [5, 2, 2], state: "minecraft:acacia_log{axis:y}"},
        {pos: [5, 2, 4], state: "minecraft:acacia_log{axis:y}"},
        {pos: [1, 3, 2], state: "minecraft:acacia_log{axis:y}"},
        {pos: [1, 3, 3], state: "minecraft:acacia_log{axis:z}"},
        {pos: [1, 3, 4], state: "minecraft:acacia_log{axis:y}"},
        {pos: [2, 3, 1], state: "minecraft:acacia_log{axis:y}"},
        {pos: [2, 3, 5], state: "minecraft:acacia_log{axis:y}"},
        {pos: [3, 3, 1], state: "minecraft:acacia_log{axis:x}"},
        {pos: [3, 3, 5], state: "minecraft:acacia_log{axis:x}"},
        {pos: [4, 3, 1], state: "minecraft:acacia_log{axis:y}"},
        {pos: [4, 3, 5], state: "minecraft:acacia_log{axis:y}"},
        {pos: [5, 3, 2], state: "minecraft:acacia_log{axis:y}"},
        {pos: [5, 3, 3], state: "minecraft:acacia_log{axis:z}"},
        {pos: [5, 3, 4], state: "minecraft:acacia_log{axis:y}"},
        {pos: [1, 4, 1], state: "minecraft:acacia_planks"},
        {pos: [1, 4, 2], state: "minecraft:acacia_planks"},
        {pos: [1, 4, 3], state: "minecraft:acacia_planks"},
        {pos: [1, 4, 4], state: "minecraft:acacia_planks"},
        {pos: [1, 4, 5], state: "minecraft:acacia_planks"},
        {pos: [2, 4, 1], state: "minecraft:acacia_planks"},
        {pos: [2, 4, 5], state: "minecraft:acacia_planks"},
        {pos: [3, 4, 1], state: "minecraft:acacia_planks"},
        {pos: [3, 4, 5], state: "minecraft:acacia_planks"},
        {pos: [4, 4, 1], state: "minecraft:acacia_planks"},
        {pos: [4, 4, 5], state: "minecraft:acacia_planks"},
        {pos: [5, 4, 1], state: "minecraft:acacia_planks"},
        {pos: [5, 4, 2], state: "minecraft:acacia_planks"},
        {pos: [5, 4, 3], state: "minecraft:acacia_planks"},
        {pos: [5, 4, 4], state: "minecraft:acacia_planks"},
        {pos: [5, 4, 5], state: "minecraft:acacia_planks"},
        {pos: [2, 5, 2], state: "minecraft:acacia_planks"},
        {pos: [2, 5, 3], state: "minecraft:acacia_planks"},
        {pos: [2, 5, 4], state: "minecraft:acacia_planks"},
        {pos: [3, 5, 2], state: "minecraft:acacia_planks"},
        {pos: [3, 5, 3], state: "minecraft:acacia_planks"},
        {pos: [3, 5, 4], state: "minecraft:acacia_planks"},
        {pos: [4, 5, 2], state: "minecraft:acacia_planks"},
        {pos: [4, 5, 3], state: "minecraft:acacia_planks"},
        {pos: [4, 5, 4], state: "minecraft:acacia_planks"},
        {pos: [3, 6, 3], state: "minecraft:acacia_planks"},
        {pos: [3, 0, 6], state: "minecraft:dirt_path"},
        {pos: [0, 1, 0], state: "minecraft:short_grass"},
        {pos: [0, 1, 1], state: "minecraft:air"},
        {pos: [0, 1, 2], state: "minecraft:air"},
        {pos: [0, 1, 3], state: "minecraft:short_grass"},
        {pos: [0, 1, 4], state: "minecraft:air"},
        {pos: [0, 1, 5], state: "minecraft:air"},
        {pos: [0, 1, 6], state: "minecraft:short_grass"},
        {pos: [1, 1, 0], state: "minecraft:short_grass"},
        {pos: [1, 1, 1], state: "minecraft:short_grass"},
        {pos: [1, 1, 5], state: "minecraft:short_grass"},
        {pos: [1, 1, 6], state: "minecraft:short_grass"},
        {pos: [2, 1, 0], state: "minecraft:air"},
        {pos: [3, 1, 0], state: "minecraft:air"},
        {pos: [3, 1, 2], state: "minecraft:air"},
        {pos: [3, 1, 3], state: "minecraft:air"},
        {pos: [3, 1, 4], state: "minecraft:air"},
        {pos: [3, 1, 5], state: "minecraft:acacia_door{hinge:right,half:lower,powered:false,facing:south,open:false}"},
        {pos: [3, 1, 6], state: "minecraft:air"},
        {pos: [4, 1, 0], state: "minecraft:air"},
        {pos: [4, 1, 2], state: "minecraft:acacia_stairs{half:bottom,waterlogged:false,shape:straight,facing:north}"},
        {pos: [4, 1, 4], state: "minecraft:acacia_stairs{half:bottom,waterlogged:false,shape:straight,facing:south}"},
        {pos: [4, 1, 6], state: "minecraft:short_grass"},
        {pos: [5, 1, 0], state: "minecraft:short_grass"},
        {pos: [5, 1, 1], state: "minecraft:short_grass"},
        {pos: [5, 1, 5], state: "minecraft:air"},
        {pos: [5, 1, 6], state: "minecraft:air"},
        {pos: [6, 1, 0], state: "minecraft:short_grass"},
        {pos: [6, 1, 1], state: "minecraft:air"},
        {pos: [6, 1, 2], state: "minecraft:short_grass"},
        {pos: [6, 1, 3], state: "minecraft:air"},
        {pos: [6, 1, 4], state: "minecraft:air"},
        {pos: [6, 1, 5], state: "minecraft:air"},
        {pos: [6, 1, 6], state: "minecraft:air"},
        {pos: [0, 2, 0], state: "minecraft:air"},
        {pos: [0, 2, 1], state: "minecraft:air"},
        {pos: [0, 2, 2], state: "minecraft:air"},
        {pos: [0, 2, 3], state: "minecraft:air"},
        {pos: [0, 2, 4], state: "minecraft:air"},
        {pos: [0, 2, 5], state: "minecraft:air"},
        {pos: [0, 2, 6], state: "minecraft:air"},
        {pos: [1, 2, 0], state: "minecraft:air"},
        {pos: [1, 2, 1], state: "minecraft:air"},
        {pos: [1, 2, 3], state: "minecraft:glass_pane{east:false,waterlogged:false,south:true,north:true,west:false}"},
        {pos: [1, 2, 5], state: "minecraft:air"},
        {pos: [1, 2, 6], state: "minecraft:air"},
        {pos: [2, 2, 0], state: "minecraft:air"},
        {pos: [2, 2, 2], state: "minecraft:air"},
        {pos: [2, 2, 3], state: "minecraft:air"},
        {pos: [2, 2, 4], state: "minecraft:air"},
        {pos: [2, 2, 6], state: "minecraft:air"},
        {pos: [3, 2, 0], state: "minecraft:air"},
        {pos: [3, 2, 1], state: "minecraft:glass_pane{east:true,waterlogged:false,south:false,north:false,west:true}"},
        {pos: [3, 2, 2], state: "minecraft:air"},
        {pos: [3, 2, 3], state: "minecraft:air"},
        {pos: [3, 2, 4], state: "minecraft:air"},
        {pos: [3, 2, 5], state: "minecraft:acacia_door{hinge:right,half:upper,powered:false,facing:south,open:false}"},
        {pos: [3, 2, 6], state: "minecraft:air"},
        {pos: [4, 2, 0], state: "minecraft:air"},
        {pos: [4, 2, 2], state: "minecraft:air"},
        {pos: [4, 2, 3], state: "minecraft:torch"},
        {pos: [4, 2, 4], state: "minecraft:air"},
        {pos: [4, 2, 6], state: "minecraft:air"},
        {pos: [5, 2, 0], state: "minecraft:air"},
        {pos: [5, 2, 1], state: "minecraft:air"},
        {pos: [5, 2, 3], state: "minecraft:glass_pane{east:false,waterlogged:false,south:true,north:true,west:false}"},
        {pos: [5, 2, 5], state: "minecraft:air"},
        {pos: [5, 2, 6], state: "minecraft:air"},
        {pos: [6, 2, 0], state: "minecraft:air"},
        {pos: [6, 2, 1], state: "minecraft:air"},
        {pos: [6, 2, 2], state: "minecraft:air"},
        {pos: [6, 2, 3], state: "minecraft:air"},
        {pos: [6, 2, 4], state: "minecraft:air"},
        {pos: [6, 2, 5], state: "minecraft:air"},
        {pos: [6, 2, 6], state: "minecraft:air"},
        {pos: [0, 3, 0], state: "minecraft:air"},
        {pos: [0, 3, 1], state: "minecraft:air"},
        {pos: [0, 3, 2], state: "minecraft:air"},
        {pos: [0, 3, 3], state: "minecraft:air"},
        {pos: [0, 3, 4], state: "minecraft:air"},
        {pos: [0, 3, 5], state: "minecraft:air"},
        {pos: [0, 3, 6], state: "minecraft:air"},
        {pos: [1, 3, 0], state: "minecraft:air"},
        {pos: [1, 3, 1], state: "minecraft:air"},
        {pos: [1, 3, 5], state: "minecraft:air"},
        {pos: [1, 3, 6], state: "minecraft:air"},
        {pos: [2, 3, 0], state: "minecraft:air"},
        {pos: [2, 3, 2], state: "minecraft:air"},
        {pos: [2, 3, 3], state: "minecraft:air"},
        {pos: [2, 3, 4], state: "minecraft:air"},
        {pos: [2, 3, 6], state: "minecraft:air"},
        {pos: [3, 3, 0], state: "minecraft:air"},
        {pos: [3, 3, 2], state: "minecraft:air"},
        {pos: [3, 3, 3], state: "minecraft:air"},
        {pos: [3, 3, 4], state: "minecraft:air"},
        {pos: [3, 3, 6], state: "minecraft:wall_torch{facing:south}"},
        {pos: [4, 3, 0], state: "minecraft:air"},
        {pos: [4, 3, 2], state: "minecraft:air"},
        {pos: [4, 3, 3], state: "minecraft:air"},
        {pos: [4, 3, 4], state: "minecraft:air"},
        {pos: [4, 3, 6], state: "minecraft:air"},
        {pos: [5, 3, 0], state: "minecraft:air"},
        {pos: [5, 3, 1], state: "minecraft:air"},
        {pos: [5, 3, 5], state: "minecraft:air"},
        {pos: [5, 3, 6], state: "minecraft:air"},
        {pos: [6, 3, 0], state: "minecraft:air"},
        {pos: [6, 3, 1], state: "minecraft:air"},
        {pos: [6, 3, 2], state: "minecraft:air"},
        {pos: [6, 3, 3], state: "minecraft:air"},
        {pos: [6, 3, 4], state: "minecraft:air"},
        {pos: [6, 3, 5], state: "minecraft:air"},
        {pos: [6, 3, 6], state: "minecraft:air"},
        {pos: [0, 4, 0], state: "minecraft:air"},
        {pos: [0, 4, 1], state: "minecraft:acacia_stairs{half:bottom,waterlogged:false,shape:straight,facing:east}"},
        {pos: [0, 4, 2], state: "minecraft:acacia_stairs{half:bottom,waterlogged:false,shape:straight,facing:east}"},
        {pos: [0, 4, 3], state: "minecraft:acacia_stairs{half:bottom,waterlogged:false,shape:straight,facing:east}"},
        {pos: [0, 4, 4], state: "minecraft:acacia_stairs{half:bottom,waterlogged:false,shape:straight,facing:east}"},
        {pos: [0, 4, 5], state: "minecraft:acacia_stairs{half:bottom,waterlogged:false,shape:straight,facing:east}"},
        {pos: [0, 4, 6], state: "minecraft:air"},
        {pos: [1, 4, 0], state: "minecraft:acacia_stairs{half:bottom,waterlogged:false,shape:straight,facing:south}"},
        {pos: [1, 4, 6], state: "minecraft:acacia_stairs{half:bottom,waterlogged:false,shape:straight,facing:north}"},
        {pos: [2, 4, 0], state: "minecraft:acacia_stairs{half:bottom,waterlogged:false,shape:straight,facing:south}"},
        {pos: [2, 4, 2], state: "minecraft:air"},
        {pos: [2, 4, 3], state: "minecraft:air"},
        {pos: [2, 4, 4], state: "minecraft:air"},
        {pos: [2, 4, 6], state: "minecraft:acacia_stairs{half:bottom,waterlogged:false,shape:straight,facing:north}"},
        {pos: [3, 4, 0], state: "minecraft:acacia_stairs{half:bottom,waterlogged:false,shape:straight,facing:south}"},
        {pos: [3, 4, 2], state: "minecraft:air"},
        {pos: [3, 4, 3], state: "minecraft:air"},
        {pos: [3, 4, 4], state: "minecraft:air"},
        {pos: [3, 4, 6], state: "minecraft:acacia_stairs{half:bottom,waterlogged:false,shape:straight,facing:north}"},
        {pos: [4, 4, 0], state: "minecraft:acacia_stairs{half:bottom,waterlogged:false,shape:straight,facing:south}"},
        {pos: [4, 4, 2], state: "minecraft:air"},
        {pos: [4, 4, 3], state: "minecraft:air"},
        {pos: [4, 4, 4], state: "minecraft:air"},
        {pos: [4, 4, 6], state: "minecraft:acacia_stairs{half:bottom,waterlogged:false,shape:straight,facing:north}"},
        {pos: [5, 4, 0], state: "minecraft:acacia_stairs{half:bottom,waterlogged:false,shape:straight,facing:south}"},
        {pos: [5, 4, 6], state: "minecraft:acacia_stairs{half:bottom,waterlogged:false,shape:straight,facing:north}"},
        {pos: [6, 4, 0], state: "minecraft:air"},
        {pos: [6, 4, 1], state: "minecraft:acacia_stairs{half:bottom,waterlogged:false,shape:straight,facing:west}"},
        {pos: [6, 4, 2], state: "minecraft:acacia_stairs{half:bottom,waterlogged:false,shape:straight,facing:west}"},
        {pos: [6, 4, 3], state: "minecraft:acacia_stairs{half:bottom,waterlogged:false,shape:straight,facing:west}"},
        {pos: [6, 4, 4], state: "minecraft:acacia_stairs{half:bottom,waterlogged:false,shape:straight,facing:west}"},
        {pos: [6, 4, 5], state: "minecraft:acacia_stairs{half:bottom,waterlogged:false,shape:straight,facing:west}"},
        {pos: [6, 4, 6], state: "minecraft:air"},
        {pos: [0, 5, 0], state: "minecraft:air"},
        {pos: [0, 5, 1], state: "minecraft:air"},
        {pos: [0, 5, 2], state: "minecraft:air"},
        {pos: [0, 5, 3], state: "minecraft:air"},
        {pos: [0, 5, 4], state: "minecraft:air"},
        {pos: [0, 5, 5], state: "minecraft:air"},
        {pos: [0, 5, 6], state: "minecraft:air"},
        {pos: [1, 5, 0], state: "minecraft:air"},
        {pos: [1, 5, 1], state: "minecraft:acacia_stairs{half:bottom,waterlogged:false,shape:outer_right,facing:east}"},
        {pos: [1, 5, 2], state: "minecraft:acacia_stairs{half:bottom,waterlogged:false,shape:straight,facing:east}"},
        {pos: [1, 5, 3], state: "minecraft:acacia_stairs{half:bottom,waterlogged:false,shape:straight,facing:east}"},
        {pos: [1, 5, 4], state: "minecraft:acacia_stairs{half:bottom,waterlogged:false,shape:straight,facing:east}"},
        {pos: [1, 5, 5], state: "minecraft:acacia_stairs{half:bottom,waterlogged:false,shape:outer_left,facing:east}"},
        {pos: [1, 5, 6], state: "minecraft:air"},
        {pos: [2, 5, 0], state: "minecraft:air"},
        {pos: [2, 5, 1], state: "minecraft:acacia_stairs{half:bottom,waterlogged:false,shape:straight,facing:south}"},
        {pos: [2, 5, 5], state: "minecraft:acacia_stairs{half:bottom,waterlogged:false,shape:straight,facing:north}"},
        {pos: [2, 5, 6], state: "minecraft:air"},
        {pos: [3, 5, 0], state: "minecraft:air"},
        {pos: [3, 5, 1], state: "minecraft:acacia_stairs{half:bottom,waterlogged:false,shape:straight,facing:south}"},
        {pos: [3, 5, 5], state: "minecraft:acacia_stairs{half:bottom,waterlogged:false,shape:straight,facing:north}"},
        {pos: [3, 5, 6], state: "minecraft:air"},
        {pos: [4, 5, 0], state: "minecraft:air"},
        {pos: [4, 5, 1], state: "minecraft:acacia_stairs{half:bottom,waterlogged:false,shape:straight,facing:south}"},
        {pos: [4, 5, 5], state: "minecraft:acacia_stairs{half:bottom,waterlogged:false,shape:straight,facing:north}"},
        {pos: [4, 5, 6], state: "minecraft:air"},
        {pos: [5, 5, 0], state: "minecraft:air"},
        {pos: [5, 5, 1], state: "minecraft:acacia_stairs{half:bottom,waterlogged:false,shape:outer_right,facing:south}"},
        {pos: [5, 5, 2], state: "minecraft:acacia_stairs{half:bottom,waterlogged:false,shape:straight,facing:west}"},
        {pos: [5, 5, 3], state: "minecraft:acacia_stairs{half:bottom,waterlogged:false,shape:straight,facing:west}"},
        {pos: [5, 5, 4], state: "minecraft:acacia_stairs{half:bottom,waterlogged:false,shape:straight,facing:west}"},
        {pos: [5, 5, 5], state: "minecraft:acacia_stairs{half:bottom,waterlogged:false,shape:outer_left,facing:north}"},
        {pos: [5, 5, 6], state: "minecraft:air"},
        {pos: [6, 5, 0], state: "minecraft:air"},
        {pos: [6, 5, 1], state: "minecraft:air"},
        {pos: [6, 5, 2], state: "minecraft:air"},
        {pos: [6, 5, 3], state: "minecraft:air"},
        {pos: [6, 5, 4], state: "minecraft:air"},
        {pos: [6, 5, 5], state: "minecraft:air"},
        {pos: [6, 5, 6], state: "minecraft:air"},
        {pos: [0, 6, 0], state: "minecraft:air"},
        {pos: [0, 6, 1], state: "minecraft:air"},
        {pos: [0, 6, 2], state: "minecraft:air"},
        {pos: [0, 6, 3], state: "minecraft:air"},
        {pos: [0, 6, 4], state: "minecraft:air"},
        {pos: [0, 6, 5], state: "minecraft:air"},
        {pos: [0, 6, 6], state: "minecraft:air"},
        {pos: [1, 6, 0], state: "minecraft:air"},
        {pos: [1, 6, 1], state: "minecraft:air"},
        {pos: [1, 6, 2], state: "minecraft:air"},
        {pos: [1, 6, 3], state: "minecraft:air"},
        {pos: [1, 6, 4], state: "minecraft:air"},
        {pos: [1, 6, 5], state: "minecraft:air"},
        {pos: [1, 6, 6], state: "minecraft:air"},
        {pos: [2, 6, 0], state: "minecraft:air"},
        {pos: [2, 6, 1], state: "minecraft:air"},
        {pos: [2, 6, 2], state: "minecraft:acacia_stairs{half:bottom,waterlogged:false,shape:outer_left,facing:south}"},
        {pos: [2, 6, 3], state: "minecraft:acacia_stairs{half:bottom,waterlogged:false,shape:straight,facing:east}"},
        {pos: [2, 6, 4], state: "minecraft:acacia_stairs{half:bottom,waterlogged:false,shape:outer_left,facing:east}"},
        {pos: [2, 6, 5], state: "minecraft:air"},
        {pos: [2, 6, 6], state: "minecraft:air"},
        {pos: [3, 6, 0], state: "minecraft:air"},
        {pos: [3, 6, 1], state: "minecraft:air"},
        {pos: [3, 6, 2], state: "minecraft:acacia_stairs{half:bottom,waterlogged:false,shape:straight,facing:south}"},
        {pos: [3, 6, 4], state: "minecraft:acacia_stairs{half:bottom,waterlogged:false,shape:straight,facing:north}"},
        {pos: [3, 6, 5], state: "minecraft:air"},
        {pos: [3, 6, 6], state: "minecraft:air"},
        {pos: [4, 6, 0], state: "minecraft:air"},
        {pos: [4, 6, 1], state: "minecraft:air"},
        {pos: [4, 6, 2], state: "minecraft:acacia_stairs{half:bottom,waterlogged:false,shape:outer_left,facing:west}"},
        {pos: [4, 6, 3], state: "minecraft:acacia_stairs{half:bottom,waterlogged:false,shape:straight,facing:west}"},
        {pos: [4, 6, 4], state: "minecraft:acacia_stairs{half:bottom,waterlogged:false,shape:outer_left,facing:north}"},
        {pos: [4, 6, 5], state: "minecraft:air"},
        {pos: [4, 6, 6], state: "minecraft:air"},
        {pos: [5, 6, 0], state: "minecraft:air"},
        {pos: [5, 6, 1], state: "minecraft:air"},
        {pos: [5, 6, 2], state: "minecraft:air"},
        {pos: [5, 6, 3], state: "minecraft:air"},
        {pos: [5, 6, 4], state: "minecraft:air"},
        {pos: [5, 6, 5], state: "minecraft:air"},
        {pos: [5, 6, 6], state: "minecraft:air"},
        {pos: [6, 6, 0], state: "minecraft:air"},
        {pos: [6, 6, 1], state: "minecraft:air"},
        {pos: [6, 6, 2], state: "minecraft:air"},
        {pos: [6, 6, 3], state: "minecraft:air"},
        {pos: [6, 6, 4], state: "minecraft:air"},
        {pos: [6, 6, 5], state: "minecraft:air"},
        {pos: [6, 6, 6], state: "minecraft:air"},
        {pos: [5, 0, 6], state: "minecraft:jigsaw{orientation:up_north}", nbt: {final_state: "minecraft:grass_block", id: "minecraft:jigsaw", joint: "rollable", name: "minecraft:bottom", pool: "minecraft:village/savanna/zombie/villagers", target: "minecraft:bottom"}},
        {pos: [2, 1, 2], state: "minecraft:orange_bed{part:head,facing:north,occupied:false}", nbt: {id: "minecraft:bed"}},
        {pos: [2, 1, 3], state: "minecraft:orange_bed{part:foot,facing:north,occupied:false}", nbt: {id: "minecraft:bed"}},
        {pos: [2, 1, 4], state: "minecraft:chest{waterlogged:false,facing:east,type:single}", nbt: {LootTable: "minecraft:chests/village/village_savanna_house", id: "minecraft:chest"}},
        {pos: [2, 1, 6], state: "minecraft:jigsaw{orientation:south_up}", nbt: {final_state: "minecraft:structure_void", id: "minecraft:jigsaw", joint: "aligned", name: "minecraft:building_entrance", pool: "minecraft:empty", target: "minecraft:building_entrance"}}
    ],
    entities: [],
    palette: [
        "minecraft:grass_block{snowy:false}",
        "minecraft:dirt",
        "minecraft:acacia_wood{axis:y}",
        "minecraft:acacia_wood{axis:z}",
        "minecraft:acacia_log{axis:y}",
        "minecraft:acacia_log{axis:z}",
        "minecraft:acacia_log{axis:x}",
        "minecraft:acacia_planks",
        "minecraft:dirt_path",
        "minecraft:short_grass",
        "minecraft:air",
        "minecraft:acacia_door{hinge:right,half:lower,powered:false,facing:south,open:false}",
        "minecraft:acacia_stairs{half:bottom,waterlogged:false,shape:straight,facing:north}",
        "minecraft:acacia_stairs{half:bottom,waterlogged:false,shape:straight,facing:south}",
        "minecraft:glass_pane{east:false,waterlogged:false,south:true,north:true,west:false}",
        "minecraft:glass_pane{east:true,waterlogged:false,south:false,north:false,west:true}",
        "minecraft:acacia_door{hinge:right,half:upper,powered:false,facing:south,open:false}",
        "minecraft:torch",
        "minecraft:wall_torch{facing:south}",
        "minecraft:acacia_stairs{half:bottom,waterlogged:false,shape:straight,facing:east}",
        "minecraft:acacia_stairs{half:bottom,waterlogged:false,shape:straight,facing:west}",
        "minecraft:acacia_stairs{half:bottom,waterlogged:false,shape:outer_right,facing:east}",
        "minecraft:acacia_stairs{half:bottom,waterlogged:false,shape:outer_left,facing:east}",
        "minecraft:acacia_stairs{half:bottom,waterlogged:false,shape:outer_right,facing:south}",
        "minecraft:acacia_stairs{half:bottom,waterlogged:false,shape:outer_left,facing:north}",
        "minecraft:acacia_stairs{half:bottom,waterlogged:false,shape:outer_left,facing:south}",
        "minecraft:acacia_stairs{half:bottom,waterlogged:false,shape:outer_left,facing:west}",
        "minecraft:jigsaw{orientation:up_north}",
        "minecraft:orange_bed{part:head,facing:north,occupied:false}",
        "minecraft:orange_bed{part:foot,facing:north,occupied:false}",
        "minecraft:chest{waterlogged:false,facing:east,type:single}",
        "minecraft:jigsaw{orientation:south_up}"
    ]
}