{
    size: [7, 7, 8],
    data: [
        {pos: [0, 0, 0], state: "minecraft:dirt"},
        {pos: [0, 0, 1], state: "minecraft:dirt"},
        {pos: [0, 0, 2], state: "minecraft:dirt"},
        {pos: [0, 0, 3], state: "minecraft:dirt"},
        {pos: [0, 0, 4], state: "minecraft:dirt"},
        {pos: [0, 0, 5], state: "minecraft:dirt"},
        {pos: [0, 0, 6], state: "minecraft:dirt"},
        {pos: [0, 0, 7], state: "minecraft:dirt"},
        {pos: [1, 0, 0], state: "minecraft:dirt"},
        {pos: [1, 0, 1], state: "minecraft:dirt"},
        {pos: [1, 0, 2], state: "minecraft:grass_block{snowy:false}"},
        {pos: [1, 0, 3], state: "minecraft:dirt"},
        {pos: [1, 0, 4], state: "minecraft:grass_block{snowy:false}"},
        {pos: [1, 0, 5], state: "minecraft:dirt"},
        {pos: [1, 0, 6], state: "minecraft:grass_block{snowy:false}"},
        {pos: [1, 0, 7], state: "minecraft:dirt"},
        {pos: [2, 0, 0], state: "minecraft:dirt"},
        {pos: [2, 0, 1], state: "minecraft:grass_block{snowy:false}"},
        {pos: [2, 0, 2], state: "minecraft:grass_block{snowy:false}"},
        {pos: [2, 0, 3], state: "minecraft:dirt"},
        {pos: [2, 0, 4], state: "minecraft:grass_block{snowy:false}"},
        {pos: [2, 0, 6], state: "minecraft:grass_block{snowy:false}"},
        {pos: [2, 0, 7], state: "minecraft:dirt"},
        {pos: [3, 0, 0], state: "minecraft:dirt"},
        {pos: [3, 0, 1], state: "minecraft:dirt"},
        {pos: [3, 0, 2], state: "minecraft:grass_block{snowy:false}"},
        {pos: [3, 0, 3], state: "minecraft:dirt"},
        {pos: [3, 0, 4], state: "minecraft:grass_block{snowy:false}"},
        {pos: [3, 0, 5], state: "minecraft:grass_block{snowy:false}"},
        {pos: [3, 0, 6], state: "minecraft:grass_block{snowy:false}"},
        {pos: [3, 0, 7], state: "minecraft:dirt"},
        {pos: [4, 0, 0], state: "minecraft:dirt"},
        {pos: [4, 0, 1], state: "minecraft:grass_block{snowy:false}"},
        {pos: [4, 0, 2], state: "minecraft:grass_block{snowy:false}"},
        {pos: [4, 0, 3], state: "minecraft:dirt"},
        {pos: [4, 0, 4], state: "minecraft:grass_block{snowy:false}"},
        {pos: [4, 0, 5], state: "minecraft:grass_block{snowy:false}"},
        {pos: [4, 0, 6], state: "minecraft:dirt"},
        {pos: [4, 0, 7], state: "minecraft:dirt"},
        {pos: [5, 0, 0], state: "minecraft:dirt"},
        {pos: [5, 0, 1], state: "minecraft:dirt"},
        {pos: [5, 0, 2], state: "minecraft:grass_block{snowy:false}"},
        {pos: [5, 0, 3], state: "minecraft:dirt"},
        {pos: [5, 0, 4], state: "minecraft:grass_block{snowy:false}"},
        {pos: [5, 0, 5], state: "minecraft:dirt"},
        {pos: [5, 0, 6], state: "minecraft:dirt"},
        {pos: [5, 0, 7], state: "minecraft:dirt"},
        {pos: [6, 0, 0], state: "minecraft:dirt"},
        {pos: [6, 0, 1], state: "minecraft:dirt"},
        {pos: [6, 0, 2], state: "minecraft:dirt"},
        {pos: [6, 0, 3], state: "minecraft:dirt"},
        {pos: [6, 0, 4], state: "minecraft:dirt"},
        {pos: [6, 0, 5], state: "minecraft:dirt"},
        {pos: [6, 0, 6], state: "minecraft:dirt"},
        {pos: [6, 0, 7], state: "minecraft:dirt"},
        {pos: [0, 1, 0], state: "minecraft:mossy_cobblestone"},
        {pos: [0, 1, 1], state: "minecraft:cobblestone"},
        {pos: [0, 1, 2], state: "minecraft:mossy_cobblestone"},
        {pos: [0, 1, 3], state: "minecraft:mossy_cobblestone"},
        {pos: [0, 1, 4], state: "minecraft:cobblestone"},
        {pos: [0, 1, 5], state: "minecraft:cobblestone"},
        {pos: [0, 1, 6], state: "minecraft:mossy_cobblestone"},
        {pos: [0, 1, 7], state: "minecraft:cobblestone"},
        {pos: [1, 1, 0], state: "minecraft:mossy_cobblestone"},
        {pos: [1, 1, 3], state: "minecraft:dirt"},
        {pos: [1, 1, 5], state: "minecraft:mossy_cobblestone"},
        {pos: [1, 1, 7], state: "minecraft:cobblestone"},
        {pos: [2, 1, 0], state: "minecraft:mossy_cobblestone"},
        {pos: [2, 1, 3], state: "minecraft:dirt"},
        {pos: [2, 1, 7], state: "minecraft:mossy_cobblestone"},
        {pos: [3, 1, 1], state: "minecraft:mossy_cobblestone"},
        {pos: [3, 1, 7], state: "minecraft:cobblestone"},
        {pos: [4, 1, 0], state: "minecraft:mossy_cobblestone"},
        {pos: [4, 1, 3], state: "minecraft:mossy_cobblestone"},
        {pos: [4, 1, 6], state: "minecraft:dirt"},
        {pos: [4, 1, 7], state: "minecraft:mossy_cobblestone"},
        {pos: [5, 1, 0], state: "minecraft:mossy_cobblestone"},
        {pos: [5, 1, 3], state: "minecraft:dirt"},
        {pos: [5, 1, 5], state: "minecraft:mossy_cobblestone"},
        {pos: [5, 1, 7], state: "minecraft:mossy_cobblestone"},
        {pos: [6, 1, 1], state: "minecraft:cobblestone"},
        {pos: [6, 1, 2], state: "minecraft:mossy_cobblestone"},
        {pos: [6, 1, 3], state: "minecraft:mossy_cobblestone"},
        {pos: [6, 1, 4], state: "minecraft:cobblestone"},
        {pos: [6, 1, 5], state: "minecraft:mossy_cobblestone"},
        {pos: [6, 1, 6], state: "minecraft:cobblestone"},
        {pos: [6, 1, 7], state: "minecraft:mossy_cobblestone"},
        {pos: [1, 2, 3], state: "minecraft:pumpkin"},
        {pos: [2, 2, 3], state: "minecraft:pumpkin"},
        {pos: [4, 2, 6], state: "minecraft:pumpkin"},
        {pos: [5, 2, 3], state: "minecraft:pumpkin"},
        {pos: [2, 0, 5], state: "minecraft:water{level:8}"},
        {pos: [1, 1, 1], state: "minecraft:water{level:0}"},
        {pos: [1, 1, 2], state: "minecraft:farmland{moisture:7}"},
        {pos: [1, 1, 4], state: "minecraft:farmland{moisture:7}"},
        {pos: [1, 1, 6], state: "minecraft:farmland{moisture:7}"},
        {pos: [2, 1, 1], state: "minecraft:farmland{moisture:7}"},
        {pos: [2, 1, 2], state: "minecraft:farmland{moisture:7}"},
        {pos: [2, 1, 4], state: "minecraft:farmland{moisture:7}"},
        {pos: [2, 1, 5], state: "minecraft:water{level:0}"},
        {pos: [2, 1, 6], state: "minecraft:farmland{moisture:7}"},
        {pos: [3, 1, 2], state: "minecraft:farmland{moisture:7}"},
        {pos: [3, 1, 3], state: "minecraft:water{level:0}"},
        {pos: [3, 1, 4], state: "minecraft:farmland{moisture:7}"},
        {pos: [3, 1, 5], state: "minecraft:farmland{moisture:7}"},
        {pos: [3, 1, 6], state: "minecraft:farmland{moisture:7}"},
        {pos: [4, 1, 1], state: "minecraft:farmland{moisture:7}"},
        {pos: [4, 1, 2], state: "minecraft:farmland{moisture:7}"},
        {pos: [4, 1, 4], state: "minecraft:farmland{moisture:7}"},
        {pos: [4, 1, 5], state: "minecraft:farmland{moisture:7}"},
        {pos: [5, 1, 1], state: "minecraft:water{level:0}"},
        {pos: [5, 1, 2], state: "minecraft:farmland{moisture:7}"},
        {pos: [5, 1, 4], state: "minecraft:farmland{moisture:7}"},
        {pos: [5, 1, 6], state: "minecraft:water{level:0}"},
        {pos: [0, 2, 0], state: "minecraft:air"},
        {pos: [0, 2, 1], state: "minecraft:air"},
        {pos: [0, 2, 2], state: "minecraft:air"},
        {pos: [0, 2, 3], state: "minecraft:air"},
        {pos: [0, 2, 4], state: "minecraft:air"},
        {pos: [0, 2, 5], state: "minecraft:air"},
        {pos: [0, 2, 6], state: "minecraft:air"},
        {pos: [0, 2, 7], state: "minecraft:air"},
        {pos: [1, 2, 0], state: "minecraft:air"},
        {pos: [1, 2, 1], state: "minecraft:air"},
        {pos: [1, 2, 2], state: "minecraft:pumpkin_stem{age:7}"},
        {pos: [1, 2, 4], state: "minecraft:pumpkin_stem{age:7}"},
        {pos: [1, 2, 5], state: "minecraft:air"},
        {pos: [1, 2, 6], state: "minecraft:pumpkin_stem{age:7}"},
        {pos: [1, 2, 7], state: "minecraft:air"},
        {pos: [2, 2, 0], state: "minecraft:cobblestone_wall{east:none,waterlogged:false,south:none,north:none,west:none,up:true}"},
        {pos: [2, 2, 1], state: "minecraft:pumpkin_stem{age:7}"},
        {pos: [2, 2, 2], state: "minecraft:pumpkin_stem{age:7}"},
        {pos: [2, 2, 4], state: "minecraft:pumpkin_stem{age:7}"},
        {pos: [2, 2, 5], state: "minecraft:air"},
        {pos: [2, 2, 6], state: "minecraft:pumpkin_stem{age:7}"},
        {pos: [2, 2, 7], state: "minecraft:air"},
        {pos: [3, 2, 0], state: "minecraft:air"},
        {pos: [3, 2, 1], state: "minecraft:air"},
        {pos: [3, 2, 2], state: "minecraft:pumpkin_stem{age:7}"},
        {pos: [3, 2, 3], state: "minecraft:air"},
        {pos: [3, 2, 4], state: "minecraft:pumpkin_stem{age:7}"},
        {pos: [3, 2, 5], state: "minecraft:pumpkin_stem{age:7}"},
        {pos: [3, 2, 6], state: "minecraft:pumpkin_stem{age:7}"},
        {pos: [3, 2, 7], state: "minecraft:air"},
        {pos: [4, 2, 0], state: "minecraft:cobblestone_wall{east:none,waterlogged:false,south:none,north:none,west:none,up:true}"},
        {pos: [4, 2, 1], state: "minecraft:pumpkin_stem{age:7}"},
        {pos: [4, 2, 2], state: "minecraft:pumpkin_stem{age:7}"},
        {pos: [4, 2, 3], state: "minecraft:composter{level:0}"},
        {pos: [4, 2, 4], state: "minecraft:pumpkin_stem{age:7}"},
        {pos: [4, 2, 5], state: "minecraft:pumpkin_stem{age:7}"},
        {pos: [4, 2, 7], state: "minecraft:air"},
        {pos: [5, 2, 0], state: "minecraft:air"},
        {pos: [5, 2, 1], state: "minecraft:air"},
        {pos: [5, 2, 2], state: "minecraft:pumpkin_stem{age:7}"},
        {pos: [5, 2, 4], state: "minecraft:pumpkin_stem{age:7}"},
        {pos: [5, 2, 5], state: "minecraft:air"},
        {pos: [5, 2, 6], state: "minecraft:air"},
        {pos: [5, 2, 7], state: "minecraft:air"},
        {pos: [6, 2, 0], state: "minecraft:air"},
        {pos: [6, 2, 1], state: "minecraft:air"},
        {pos: [6, 2, 2], state: "minecraft:air"},
        {pos: [6, 2, 3], state: "minecraft:air"},
        {pos: [6, 2, 4], state: "minecraft:air"},
        {pos: [6, 2, 5], state: "minecraft:air"},
        {pos: [6, 2, 6], state: "minecraft:air"},
        {pos: [6, 2, 7], state: "minecraft:air"},
        {pos: [0, 3, 0], state: "minecraft:air"},
        {pos: [0, 3, 1], state: "minecraft:air"},
        {pos: [0, 3, 2], state: "minecraft:air"},
        {pos: [0, 3, 3], state: "minecraft:air"},
        {pos: [0, 3, 4], state: "minecraft:air"},
        {pos: [0, 3, 5], state: "minecraft:air"},
        {pos: [0, 3, 6], state: "minecraft:air"},
        {pos: [0, 3, 7], state: "minecraft:air"},
        {pos: [1, 3, 0], state: "minecraft:air"},
        {pos: [1, 3, 1], state: "minecraft:air"},
        {pos: [1, 3, 2], state: "minecraft:air"},
        {pos: [1, 3, 3], state: "minecraft:air"},
        {pos: [1, 3, 4], state: "minecraft:air"},
        {pos: [1, 3, 5], state: "minecraft:air"},
        {pos: [1, 3, 6], state: "minecraft:air"},
        {pos: [1, 3, 7], state: "minecraft:air"},
        {pos: [2, 3, 0], state: "minecraft:torch"},
        {pos: [2, 3, 1], state: "minecraft:air"},
        {pos: [2, 3, 2], state: "minecraft:air"},
        {pos: [2, 3, 3], state: "minecraft:air"},
        {pos: [2, 3, 4], state: "minecraft:air"},
        {pos: [2, 3, 5], state: "minecraft:air"},
        {pos: [2, 3, 6], state: "minecraft:air"},
        {pos: [2, 3, 7], state: "minecraft:air"},
        {pos: [3, 3, 0], state: "minecraft:air"},
        {pos: [3, 3, 1], state: "minecraft:air"},
        {pos: [3, 3, 2], state: "minecraft:air"},
        {pos: [3, 3, 3], state: "minecraft:air"},
        {pos: [3, 3, 4], state: "minecraft:air"},
        {pos: [3, 3, 5], state: "minecraft:air"},
        {pos: [3, 3, 6], state: "minecraft:air"},
        {pos: [3, 3, 7], state: "minecraft:air"},
        {pos: [4, 3, 0], state: "minecraft:torch"},
        {pos: [4, 3, 1], state: "minecraft:air"},
        {pos: [4, 3, 2], state: "minecraft:air"},
        {pos: [4, 3, 3], state: "minecraft:air"},
        {pos: [4, 3, 4], state: "minecraft:air"},
        {pos: [4, 3, 5], state: "minecraft:air"},
        {pos: [4, 3, 6], state: "minecraft:air"},
        {pos: [4, 3, 7], state: "minecraft:air"},
        {pos: [5, 3, 0], state: "minecraft:air"},
        {pos: [5, 3, 1], state: "minecraft:air"},
        {pos: [5, 3, 2], state: "minecraft:air"},
        {pos: [5, 3, 3], state: "minecraft:air"},
        {pos: [5, 3, 4], state: "minecraft:air"},
        {pos: [5, 3, 5], state: "minecraft:air"},
        {pos: [5, 3, 6], state: "minecraft:air"},
        {pos: [5, 3, 7], state: "minecraft:air"},
        {pos: [6, 3, 0], state: "minecraft:air"},
        {pos: [6, 3, 1], state: "minecraft:air"},
        {pos: [6, 3, 2], state: "minecraft:air"},
        {pos: [6, 3, 3], state: "minecraft:air"},
        {pos: [6, 3, 4], state: "minecraft:air"},
        {pos: [6, 3, 5], state: "minecraft:air"},
        {pos: [6, 3, 6], state: "minecraft:air"},
        {pos: [6, 3, 7], state: "minecraft:air"},
        {pos: [3, 1, 0], state: "minecraft:jigsaw{orientation:north_up}", nbt: {final_state: "minecraft:cobblestone_stairs[facing=south]", id: "minecraft:jigsaw", joint: "aligned", name: "minecraft:building_entrance", pool: "minecraft:empty", target: "minecraft:building_entrance"}},
        {pos: [6, 1, 0], state: "minecraft:jigsaw{orientation:up_north}", nbt: {final_state: "minecraft:cobblestone", id: "minecraft:jigsaw", joint: "rollable", name: "minecraft:bottom", pool: "minecraft:village/common/cats", target: "minecraft:bottom"}}
    ],
    entities: [],
    palette: [
        "minecraft:dirt",
        "minecraft:grass_block{snowy:false}",
        "minecraft:mossy_cobblestone",
        "minecraft:cobblestone",
        "minecraft:pumpkin",
        "minecraft:water{level:8}",
        "minecraft:water{level:0}",
        "minecraft:farmland{moisture:7}",
        "minecraft:air",
        "minecraft:pumpkin_stem{age:7}",
        "minecraft:cobblestone_wall{east:none,waterlogged:false,south:none,north:none,west:none,up:true}",
        "minecraft:composter{level:0}",
        "minecraft:torch",
        "minecraft:jigsaw{orientation:north_up}",
        "minecraft:jigsaw{orientation:up_north}"
    ]
}