{
    size: [12, 7, 8],
    data: [
        {pos: [0, 0, 2], state: "minecraft:bricks"},
        {pos: [0, 0, 3], state: "minecraft:bricks"},
        {pos: [0, 0, 4], state: "minecraft:bricks"},
        {pos: [0, 0, 5], state: "minecraft:bricks"},
        {pos: [1, 0, 1], state: "minecraft:bricks"},
        {pos: [1, 0, 2], state: "minecraft:bricks"},
        {pos: [1, 0, 4], state: "minecraft:bricks"},
        {pos: [1, 0, 5], state: "minecraft:bricks"},
        {pos: [1, 0, 6], state: "minecraft:bricks"},
        {pos: [2, 0, 0], state: "minecraft:bricks"},
        {pos: [2, 0, 1], state: "minecraft:gravel"},
        {pos: [2, 0, 2], state: "minecraft:gravel"},
        {pos: [2, 0, 3], state: "minecraft:gravel"},
        {pos: [2, 0, 4], state: "minecraft:gravel"},
        {pos: [2, 0, 5], state: "minecraft:gravel"},
        {pos: [2, 0, 6], state: "minecraft:bricks"},
        {pos: [2, 0, 7], state: "minecraft:bricks"},
        {pos: [3, 0, 0], state: "minecraft:bricks"},
        {pos: [3, 0, 1], state: "minecraft:gravel"},
        {pos: [3, 0, 2], state: "minecraft:gravel"},
        {pos: [3, 0, 3], state: "minecraft:gravel"},
        {pos: [3, 0, 4], state: "minecraft:gravel"},
        {pos: [3, 0, 5], state: "minecraft:gravel"},
        {pos: [3, 0, 6], state: "minecraft:bricks"},
        {pos: [3, 0, 7], state: "minecraft:bricks"},
        {pos: [4, 0, 0], state: "minecraft:bricks"},
        {pos: [4, 0, 1], state: "minecraft:gravel"},
        {pos: [4, 0, 2], state: "minecraft:gravel"},
        {pos: [4, 0, 3], state: "minecraft:gravel"},
        {pos: [4, 0, 4], state: "minecraft:gravel"},
        {pos: [4, 0, 5], state: "minecraft:gravel"},
        {pos: [4, 0, 6], state: "minecraft:gravel"},
        {pos: [4, 0, 7], state: "minecraft:bricks"},
        {pos: [5, 0, 0], state: "minecraft:bricks"},
        {pos: [5, 0, 1], state: "minecraft:gravel"},
        {pos: [5, 0, 2], state: "minecraft:gravel"},
        {pos: [5, 0, 3], state: "minecraft:gravel"},
        {pos: [5, 0, 4], state: "minecraft:gravel"},
        {pos: [5, 0, 5], state: "minecraft:gravel"},
        {pos: [5, 0, 6], state: "minecraft:bricks"},
        {pos: [5, 0, 7], state: "minecraft:bricks"},
        {pos: [6, 0, 1], state: "minecraft:gravel"},
        {pos: [6, 0, 2], state: "minecraft:bricks"},
        {pos: [6, 0, 3], state: "minecraft:gravel"},
        {pos: [6, 0, 4], state: "minecraft:gravel"},
        {pos: [6, 0, 5], state: "minecraft:gravel"},
        {pos: [6, 0, 6], state: "minecraft:gravel"},
        {pos: [6, 0, 7], state: "minecraft:bricks"},
        {pos: [7, 0, 0], state: "minecraft:bricks"},
        {pos: [7, 0, 1], state: "minecraft:bricks"},
        {pos: [7, 0, 2], state: "minecraft:bricks"},
        {pos: [7, 0, 3], state: "minecraft:bricks"},
        {pos: [7, 0, 4], state: "minecraft:bricks"},
        {pos: [7, 0, 5], state: "minecraft:gravel"},
        {pos: [7, 0, 6], state: "minecraft:bricks"},
        {pos: [7, 0, 7], state: "minecraft:bricks"},
        {pos: [8, 0, 0], state: "minecraft:bricks"},
        {pos: [8, 0, 1], state: "minecraft:bricks"},
        {pos: [8, 0, 2], state: "minecraft:bricks"},
        {pos: [8, 0, 3], state: "minecraft:bricks"},
        {pos: [8, 0, 4], state: "minecraft:bricks"},
        {pos: [8, 0, 5], state: "minecraft:bricks"},
        {pos: [8, 0, 6], state: "minecraft:bricks"},
        {pos: [8, 0, 7], state: "minecraft:bricks"},
        {pos: [9, 0, 1], state: "minecraft:bricks"},
        {pos: [9, 0, 2], state: "minecraft:bricks"},
        {pos: [9, 0, 3], state: "minecraft:bricks"},
        {pos: [9, 0, 4], state: "minecraft:bricks"},
        {pos: [9, 0, 5], state: "minecraft:bricks"},
        {pos: [9, 0, 6], state: "minecraft:bricks"},
        {pos: [9, 0, 7], state: "minecraft:bricks"},
        {pos: [10, 0, 1], state: "minecraft:bricks"},
        {pos: [10, 0, 2], state: "minecraft:bricks"},
        {pos: [10, 0, 3], state: "minecraft:bricks"},
        {pos: [10, 0, 4], state: "minecraft:bricks"},
        {pos: [10, 0, 5], state: "minecraft:bricks"},
        {pos: [10, 0, 6], state: "minecraft:bricks"},
        {pos: [11, 0, 2], state: "minecraft:bricks"},
        {pos: [11, 0, 3], state: "minecraft:bricks"},
        {pos: [11, 0, 4], state: "minecraft:bricks"},
        {pos: [11, 0, 5], state: "minecraft:bricks"},
        {pos: [0, 1, 2], state: "minecraft:bricks"},
        {pos: [0, 1, 3], state: "minecraft:bricks"},
        {pos: [0, 1, 4], state: "minecraft:bricks"},
        {pos: [0, 1, 5], state: "minecraft:bricks"},
        {pos: [1, 1, 1], state: "minecraft:bricks"},
        {pos: [1, 1, 2], state: "minecraft:gravel"},
        {pos: [1, 1, 4], state: "minecraft:gravel"},
        {pos: [1, 1, 5], state: "minecraft:bricks"},
        {pos: [1, 1, 6], state: "minecraft:bricks"},
        {pos: [2, 1, 0], state: "minecraft:bricks"},
        {pos: [2, 1, 2], state: "minecraft:gravel"},
        {pos: [2, 1, 3], state: "minecraft:gravel"},
        {pos: [2, 1, 4], state: "minecraft:gravel"},
        {pos: [2, 1, 5], state: "minecraft:gravel"},
        {pos: [2, 1, 6], state: "minecraft:bricks"},
        {pos: [2, 1, 7], state: "minecraft:bricks"},
        {pos: [3, 1, 0], state: "minecraft:gravel"},
        {pos: [3, 1, 1], state: "minecraft:gravel"},
        {pos: [3, 1, 2], state: "minecraft:gravel"},
        {pos: [3, 1, 3], state: "minecraft:gravel"},
        {pos: [3, 1, 4], state: "minecraft:gravel"},
        {pos: [3, 1, 5], state: "minecraft:gravel"},
        {pos: [3, 1, 6], state: "minecraft:bricks"},
        {pos: [3, 1, 7], state: "minecraft:bricks"},
        {pos: [4, 1, 0], state: "minecraft:bricks"},
        {pos: [4, 1, 1], state: "minecraft:gravel"},
        {pos: [4, 1, 2], state: "minecraft:gravel"},
        {pos: [4, 1, 3], state: "minecraft:gravel"},
        {pos: [4, 1, 4], state: "minecraft:gravel"},
        {pos: [4, 1, 5], state: "minecraft:gravel"},
        {pos: [4, 1, 6], state: "minecraft:gravel"},
        {pos: [4, 1, 7], state: "minecraft:bricks"},
        {pos: [5, 1, 0], state: "minecraft:bricks"},
        {pos: [5, 1, 1], state: "minecraft:gravel"},
        {pos: [5, 1, 2], state: "minecraft:gravel"},
        {pos: [5, 1, 3], state: "minecraft:gravel"},
        {pos: [5, 1, 4], state: "minecraft:gravel"},
        {pos: [5, 1, 5], state: "minecraft:gravel"},
        {pos: [5, 1, 6], state: "minecraft:gravel"},
        {pos: [5, 1, 7], state: "minecraft:bricks"},
        {pos: [6, 1, 0], state: "minecraft:bricks"},
        {pos: [6, 1, 1], state: "minecraft:gravel"},
        {pos: [6, 1, 2], state: "minecraft:gravel"},
        {pos: [6, 1, 3], state: "minecraft:gravel"},
        {pos: [6, 1, 4], state: "minecraft:gravel"},
        {pos: [6, 1, 5], state: "minecraft:gravel"},
        {pos: [6, 1, 6], state: "minecraft:gravel"},
        {pos: [6, 1, 7], state: "minecraft:gravel"},
        {pos: [7, 1, 0], state: "minecraft:bricks"},
        {pos: [7, 1, 1], state: "minecraft:gravel"},
        {pos: [7, 1, 2], state: "minecraft:gravel"},
        {pos: [7, 1, 3], state: "minecraft:gravel"},
        {pos: [7, 1, 4], state: "minecraft:gravel"},
        {pos: [7, 1, 5], state: "minecraft:gravel"},
        {pos: [7, 1, 6], state: "minecraft:gravel"},
        {pos: [8, 1, 0], state: "minecraft:bricks"},
        {pos: [8, 1, 1], state: "minecraft:gravel"},
        {pos: [8, 1, 2], state: "minecraft:gravel"},
        {pos: [8, 1, 3], state: "minecraft:gravel"},
        {pos: [8, 1, 4], state: "minecraft:gravel"},
        {pos: [8, 1, 5], state: "minecraft:gravel"},
        {pos: [8, 1, 6], state: "minecraft:gravel"},
        {pos: [8, 1, 7], state: "minecraft:gravel"},
        {pos: [9, 1, 1], state: "minecraft:bricks"},
        {pos: [9, 1, 2], state: "minecraft:bricks"},
        {pos: [9, 1, 4], state: "minecraft:gravel"},
        {pos: [9, 1, 5], state: "minecraft:gravel"},
        {pos: [9, 1, 6], state: "minecraft:bricks"},
        {pos: [9, 1, 7], state: "minecraft:bricks"},
        {pos: [10, 1, 1], state: "minecraft:bricks"},
        {pos: [10, 1, 2], state: "minecraft:bricks"},
        {pos: [10, 1, 3], state: "minecraft:bricks"},
        {pos: [10, 1, 4], state: "minecraft:bricks"},
        {pos: [10, 1, 5], state: "minecraft:bricks"},
        {pos: [10, 1, 6], state: "minecraft:bricks"},
        {pos: [11, 1, 2], state: "minecraft:bricks"},
        {pos: [11, 1, 3], state: "minecraft:bricks"},
        {pos: [11, 1, 4], state: "minecraft:bricks"},
        {pos: [11, 1, 5], state: "minecraft:bricks"},
        {pos: [0, 2, 2], state: "minecraft:bricks"},
        {pos: [0, 2, 3], state: "minecraft:bricks"},
        {pos: [0, 2, 4], state: "minecraft:bricks"},
        {pos: [0, 2, 5], state: "minecraft:bricks"},
        {pos: [1, 2, 1], state: "minecraft:bricks"},
        {pos: [1, 2, 2], state: "minecraft:bricks"},
        {pos: [1, 2, 3], state: "minecraft:bricks"},
        {pos: [1, 2, 4], state: "minecraft:bricks"},
        {pos: [1, 2, 5], state: "minecraft:bricks"},
        {pos: [1, 2, 6], state: "minecraft:bricks"},
        {pos: [2, 2, 0], state: "minecraft:bricks"},
        {pos: [2, 2, 2], state: "minecraft:gravel"},
        {pos: [2, 2, 3], state: "minecraft:gravel"},
        {pos: [2, 2, 4], state: "minecraft:gravel"},
        {pos: [2, 2, 5], state: "minecraft:gravel"},
        {pos: [2, 2, 6], state: "minecraft:gravel"},
        {pos: [2, 2, 7], state: "minecraft:gravel"},
        {pos: [3, 2, 0], state: "minecraft:bricks"},
        {pos: [3, 2, 2], state: "minecraft:gravel"},
        {pos: [3, 2, 3], state: "minecraft:gravel"},
        {pos: [3, 2, 4], state: "minecraft:gravel"},
        {pos: [3, 2, 5], state: "minecraft:gravel"},
        {pos: [3, 2, 6], state: "minecraft:gravel"},
        {pos: [3, 2, 7], state: "minecraft:gravel"},
        {pos: [4, 2, 0], state: "minecraft:bricks"},
        {pos: [4, 2, 1], state: "minecraft:gravel"},
        {pos: [4, 2, 2], state: "minecraft:gravel"},
        {pos: [4, 2, 3], state: "minecraft:gravel"},
        {pos: [4, 2, 4], state: "minecraft:gravel"},
        {pos: [4, 2, 5], state: "minecraft:gravel"},
        {pos: [4, 2, 6], state: "minecraft:gravel"},
        {pos: [4, 2, 7], state: "minecraft:gravel"},
        {pos: [5, 2, 0], state: "minecraft:bricks"},
        {pos: [5, 2, 1], state: "minecraft:gravel"},
        {pos: [5, 2, 2], state: "minecraft:gravel"},
        {pos: [5, 2, 3], state: "minecraft:gravel"},
        {pos: [5, 2, 4], state: "minecraft:gravel"},
        {pos: [5, 2, 5], state: "minecraft:gravel"},
        {pos: [5, 2, 6], state: "minecraft:gravel"},
        {pos: [5, 2, 7], state: "minecraft:gravel"},
        {pos: [6, 2, 0], state: "minecraft:bricks"},
        {pos: [6, 2, 1], state: "minecraft:gravel"},
        {pos: [6, 2, 2], state: "minecraft:gravel"},
        {pos: [6, 2, 3], state: "minecraft:gravel"},
        {pos: [6, 2, 4], state: "minecraft:gravel"},
        {pos: [6, 2, 5], state: "minecraft:gravel"},
        {pos: [6, 2, 6], state: "minecraft:gravel"},
        {pos: [6, 2, 7], state: "minecraft:gravel"},
        {pos: [7, 2, 0], state: "minecraft:bricks"},
        {pos: [7, 2, 1], state: "minecraft:gravel"},
        {pos: [7, 2, 2], state: "minecraft:gravel"},
        {pos: [7, 2, 3], state: "minecraft:gravel"},
        {pos: [7, 2, 4], state: "minecraft:gravel"},
        {pos: [7, 2, 5], state: "minecraft:gravel"},
        {pos: [7, 2, 6], state: "minecraft:gravel"},
        {pos: [7, 2, 7], state: "minecraft:gravel"},
        {pos: [8, 2, 0], state: "minecraft:bricks"},
        {pos: [8, 2, 1], state: "minecraft:gravel"},
        {pos: [8, 2, 2], state: "minecraft:gravel"},
        {pos: [8, 2, 3], state: "minecraft:gravel"},
        {pos: [8, 2, 4], state: "minecraft:gravel"},
        {pos: [8, 2, 5], state: "minecraft:gravel"},
        {pos: [8, 2, 6], state: "minecraft:gravel"},
        {pos: [8, 2, 7], state: "minecraft:gravel"},
        {pos: [9, 2, 1], state: "minecraft:bricks"},
        {pos: [9, 2, 2], state: "minecraft:gravel"},
        {pos: [9, 2, 3], state: "minecraft:gravel"},
        {pos: [9, 2, 4], state: "minecraft:gravel"},
        {pos: [9, 2, 5], state: "minecraft:gravel"},
        {pos: [9, 2, 6], state: "minecraft:gravel"},
        {pos: [9, 2, 7], state: "minecraft:bricks"},
        {pos: [10, 2, 1], state: "minecraft:bricks"},
        {pos: [10, 2, 3], state: "minecraft:gravel"},
        {pos: [10, 2, 4], state: "minecraft:gravel"},
        {pos: [10, 2, 6], state: "minecraft:bricks"},
        {pos: [11, 2, 2], state: "minecraft:bricks"},
        {pos: [11, 2, 3], state: "minecraft:bricks"},
        {pos: [11, 2, 4], state: "minecraft:bricks"},
        {pos: [11, 2, 5], state: "minecraft:bricks"},
        {pos: [0, 3, 2], state: "minecraft:gray_terracotta"},
        {pos: [0, 3, 3], state: "minecraft:gravel"},
        {pos: [0, 3, 5], state: "minecraft:gray_terracotta"},
        {pos: [1, 3, 1], state: "minecraft:gray_terracotta"},
        {pos: [1, 3, 2], state: "minecraft:gray_terracotta"},
        {pos: [1, 3, 3], state: "minecraft:gravel"},
        {pos: [1, 3, 4], state: "minecraft:gravel"},
        {pos: [1, 3, 5], state: "minecraft:gray_terracotta"},
        {pos: [1, 3, 6], state: "minecraft:gray_terracotta"},
        {pos: [2, 3, 0], state: "minecraft:gray_terracotta"},
        {pos: [2, 3, 2], state: "minecraft:gravel"},
        {pos: [2, 3, 3], state: "minecraft:gravel"},
        {pos: [2, 3, 6], state: "minecraft:bricks"},
        {pos: [2, 3, 7], state: "minecraft:gray_terracotta"},
        {pos: [3, 3, 0], state: "minecraft:gravel"},
        {pos: [3, 3, 2], state: "minecraft:gravel"},
        {pos: [3, 3, 6], state: "minecraft:gravel"},
        {pos: [3, 3, 7], state: "minecraft:gravel"},
        {pos: [4, 3, 0], state: "minecraft:gray_terracotta"},
        {pos: [4, 3, 1], state: "minecraft:gravel"},
        {pos: [4, 3, 2], state: "minecraft:gravel"},
        {pos: [4, 3, 3], state: "minecraft:gravel"},
        {pos: [4, 3, 5], state: "minecraft:gravel"},
        {pos: [4, 3, 7], state: "minecraft:gravel"},
        {pos: [5, 3, 0], state: "minecraft:gray_terracotta"},
        {pos: [5, 3, 5], state: "minecraft:gravel"},
        {pos: [5, 3, 6], state: "minecraft:gravel"},
        {pos: [5, 3, 7], state: "minecraft:gravel"},
        {pos: [6, 3, 0], state: "minecraft:gray_terracotta"},
        {pos: [6, 3, 2], state: "minecraft:gravel"},
        {pos: [6, 3, 7], state: "minecraft:gravel"},
        {pos: [7, 3, 0], state: "minecraft:gravel"},
        {pos: [7, 3, 1], state: "minecraft:gravel"},
        {pos: [7, 3, 2], state: "minecraft:gravel"},
        {pos: [7, 3, 3], state: "minecraft:gravel"},
        {pos: [7, 3, 4], state: "minecraft:gravel"},
        {pos: [7, 3, 6], state: "minecraft:gravel"},
        {pos: [7, 3, 7], state: "minecraft:gravel"},
        {pos: [8, 3, 0], state: "minecraft:gray_terracotta"},
        {pos: [8, 3, 1], state: "minecraft:gravel"},
        {pos: [8, 3, 2], state: "minecraft:gravel"},
        {pos: [8, 3, 3], state: "minecraft:gravel"},
        {pos: [8, 3, 4], state: "minecraft:gravel"},
        {pos: [8, 3, 5], state: "minecraft:gravel"},
        {pos: [8, 3, 6], state: "minecraft:gravel"},
        {pos: [8, 3, 7], state: "minecraft:gravel"},
        {pos: [9, 3, 1], state: "minecraft:bricks"},
        {pos: [9, 3, 2], state: "minecraft:gravel"},
        {pos: [9, 3, 3], state: "minecraft:gravel"},
        {pos: [9, 3, 4], state: "minecraft:gravel"},
        {pos: [9, 3, 5], state: "minecraft:gravel"},
        {pos: [9, 3, 6], state: "minecraft:gravel"},
        {pos: [9, 3, 7], state: "minecraft:gravel"},
        {pos: [10, 3, 1], state: "minecraft:gray_terracotta"},
        {pos: [10, 3, 2], state: "minecraft:gravel"},
        {pos: [10, 3, 3], state: "minecraft:gravel"},
        {pos: [10, 3, 4], state: "minecraft:gravel"},
        {pos: [10, 3, 5], state: "minecraft:gravel"},
        {pos: [10, 3, 6], state: "minecraft:gray_terracotta"},
        {pos: [11, 3, 2], state: "minecraft:gray_terracotta"},
        {pos: [11, 3, 3], state: "minecraft:gravel"},
        {pos: [11, 3, 4], state: "minecraft:gravel"},
        {pos: [11, 3, 5], state: "minecraft:gray_terracotta"},
        {pos: [0, 4, 2], state: "minecraft:red_terracotta"},
        {pos: [0, 4, 3], state: "minecraft:red_terracotta"},
        {pos: [0, 4, 4], state: "minecraft:red_terracotta"},
        {pos: [0, 4, 5], state: "minecraft:red_terracotta"},
        {pos: [1, 4, 1], state: "minecraft:red_terracotta"},
        {pos: [1, 4, 2], state: "minecraft:gravel"},
        {pos: [1, 4, 3], state: "minecraft:gravel"},
        {pos: [1, 4, 4], state: "minecraft:gravel"},
        {pos: [1, 4, 5], state: "minecraft:gravel"},
        {pos: [1, 4, 6], state: "minecraft:gravel"},
        {pos: [2, 4, 0], state: "minecraft:gravel"},
        {pos: [2, 4, 1], state: "minecraft:bricks"},
        {pos: [2, 4, 6], state: "minecraft:gravel"},
        {pos: [2, 4, 7], state: "minecraft:red_terracotta"},
        {pos: [3, 4, 0], state: "minecraft:gravel"},
        {pos: [3, 4, 6], state: "minecraft:gravel"},
        {pos: [3, 4, 7], state: "minecraft:red_terracotta"},
        {pos: [4, 4, 0], state: "minecraft:red_terracotta"},
        {pos: [4, 4, 7], state: "minecraft:gravel"},
        {pos: [5, 4, 0], state: "minecraft:red_terracotta"},
        {pos: [5, 4, 6], state: "minecraft:gravel"},
        {pos: [5, 4, 7], state: "minecraft:gravel"},
        {pos: [6, 4, 0], state: "minecraft:red_terracotta"},
        {pos: [6, 4, 2], state: "minecraft:gravel"},
        {pos: [6, 4, 7], state: "minecraft:gravel"},
        {pos: [7, 4, 0], state: "minecraft:red_terracotta"},
        {pos: [7, 4, 1], state: "minecraft:gravel"},
        {pos: [7, 4, 2], state: "minecraft:gravel"},
        {pos: [7, 4, 3], state: "minecraft:gravel"},
        {pos: [7, 4, 4], state: "minecraft:gravel"},
        {pos: [7, 4, 6], state: "minecraft:gravel"},
        {pos: [7, 4, 7], state: "minecraft:gravel"},
        {pos: [8, 4, 0], state: "minecraft:red_terracotta"},
        {pos: [8, 4, 1], state: "minecraft:gravel"},
        {pos: [8, 4, 2], state: "minecraft:gravel"},
        {pos: [8, 4, 3], state: "minecraft:gravel"},
        {pos: [8, 4, 4], state: "minecraft:gravel"},
        {pos: [8, 4, 5], state: "minecraft:gravel"},
        {pos: [8, 4, 6], state: "minecraft:gravel"},
        {pos: [8, 4, 7], state: "minecraft:gravel"},
        {pos: [9, 4, 1], state: "minecraft:bricks"},
        {pos: [9, 4, 2], state: "minecraft:gravel"},
        {pos: [9, 4, 3], state: "minecraft:gravel"},
        {pos: [9, 4, 4], state: "minecraft:gravel"},
        {pos: [9, 4, 5], state: "minecraft:gravel"},
        {pos: [9, 4, 6], state: "minecraft:gravel"},
        {pos: [9, 4, 7], state: "minecraft:gravel"},
        {pos: [10, 4, 1], state: "minecraft:red_terracotta"},
        {pos: [10, 4, 2], state: "minecraft:gravel"},
        {pos: [10, 4, 3], state: "minecraft:gravel"},
        {pos: [10, 4, 4], state: "minecraft:gravel"},
        {pos: [10, 4, 5], state: "minecraft:gravel"},
        {pos: [10, 4, 6], state: "minecraft:red_terracotta"},
        {pos: [11, 4, 2], state: "minecraft:red_terracotta"},
        {pos: [11, 4, 3], state: "minecraft:red_terracotta"},
        {pos: [11, 4, 4], state: "minecraft:red_terracotta"},
        {pos: [11, 4, 5], state: "minecraft:red_terracotta"},
        {pos: [0, 5, 3], state: "minecraft:gravel"},
        {pos: [1, 5, 2], state: "minecraft:red_terracotta"},
        {pos: [1, 5, 3], state: "minecraft:gravel"},
        {pos: [1, 5, 4], state: "minecraft:gravel"},
        {pos: [1, 5, 5], state: "minecraft:gravel"},
        {pos: [1, 5, 6], state: "minecraft:gravel"},
        {pos: [2, 5, 1], state: "minecraft:gravel"},
        {pos: [2, 5, 6], state: "minecraft:gravel"},
        {pos: [2, 5, 7], state: "minecraft:gravel"},
        {pos: [3, 5, 0], state: "minecraft:gravel"},
        {pos: [3, 5, 1], state: "minecraft:red_terracotta"},
        {pos: [3, 5, 6], state: "minecraft:gravel"},
        {pos: [3, 5, 7], state: "minecraft:gravel"},
        {pos: [4, 5, 0], state: "minecraft:gravel"},
        {pos: [4, 5, 7], state: "minecraft:gravel"},
        {pos: [5, 5, 6], state: "minecraft:gravel"},
        {pos: [5, 5, 7], state: "minecraft:gravel"},
        {pos: [6, 5, 2], state: "minecraft:gravel"},
        {pos: [6, 5, 7], state: "minecraft:gravel"},
        {pos: [7, 5, 1], state: "minecraft:red_terracotta"},
        {pos: [7, 5, 2], state: "minecraft:gravel"},
        {pos: [7, 5, 3], state: "minecraft:gravel"},
        {pos: [7, 5, 4], state: "minecraft:gravel"},
        {pos: [7, 5, 6], state: "minecraft:gravel"},
        {pos: [7, 5, 7], state: "minecraft:gravel"},
        {pos: [8, 5, 1], state: "minecraft:red_terracotta"},
        {pos: [8, 5, 2], state: "minecraft:gravel"},
        {pos: [8, 5, 3], state: "minecraft:gravel"},
        {pos: [8, 5, 4], state: "minecraft:gravel"},
        {pos: [8, 5, 5], state: "minecraft:gravel"},
        {pos: [8, 5, 6], state: "minecraft:gravel"},
        {pos: [8, 5, 7], state: "minecraft:gravel"},
        {pos: [9, 5, 1], state: "minecraft:gravel"},
        {pos: [9, 5, 2], state: "minecraft:bricks"},
        {pos: [9, 5, 3], state: "minecraft:gravel"},
        {pos: [9, 5, 4], state: "minecraft:gravel"},
        {pos: [9, 5, 5], state: "minecraft:gravel"},
        {pos: [9, 5, 6], state: "minecraft:gravel"},
        {pos: [9, 5, 7], state: "minecraft:gravel"},
        {pos: [10, 5, 2], state: "minecraft:red_terracotta"},
        {pos: [10, 5, 3], state: "minecraft:red_terracotta"},
        {pos: [10, 5, 4], state: "minecraft:red_terracotta"},
        {pos: [10, 5, 5], state: "minecraft:red_terracotta"},
        {pos: [10, 5, 6], state: "minecraft:gravel"},
        {pos: [11, 5, 2], state: "minecraft:gravel"},
        {pos: [11, 5, 3], state: "minecraft:gravel"},
        {pos: [11, 5, 4], state: "minecraft:gravel"},
        {pos: [11, 5, 5], state: "minecraft:gravel"},
        {pos: [1, 6, 3], state: "minecraft:gravel"},
        {pos: [1, 6, 4], state: "minecraft:gravel"},
        {pos: [1, 6, 5], state: "minecraft:gravel"},
        {pos: [2, 6, 1], state: "minecraft:gravel"},
        {pos: [2, 6, 7], state: "minecraft:gravel"},
        {pos: [3, 6, 1], state: "minecraft:gravel"},
        {pos: [3, 6, 7], state: "minecraft:gravel"},
        {pos: [4, 6, 0], state: "minecraft:gravel"},
        {pos: [6, 6, 7], state: "minecraft:gravel"},
        {pos: [7, 6, 3], state: "minecraft:gravel"},
        {pos: [8, 6, 3], state: "minecraft:gravel"},
        {pos: [8, 6, 4], state: "minecraft:gravel"},
        {pos: [8, 6, 5], state: "minecraft:gravel"},
        {pos: [9, 6, 2], state: "minecraft:gravel"},
        {pos: [9, 6, 3], state: "minecraft:gravel"},
        {pos: [9, 6, 4], state: "minecraft:gravel"},
        {pos: [9, 6, 5], state: "minecraft:gravel"},
        {pos: [10, 6, 2], state: "minecraft:gravel"},
        {pos: [10, 6, 3], state: "minecraft:gravel"},
        {pos: [10, 6, 4], state: "minecraft:gravel"},
        {pos: [10, 6, 5], state: "minecraft:gravel"},
        {pos: [11, 6, 4], state: "minecraft:gravel"},
        {pos: [11, 6, 5], state: "minecraft:gravel"},
        {pos: [1, 0, 3], state: "minecraft:air"},
        {pos: [6, 0, 0], state: "minecraft:air"},
        {pos: [0, 1, 6], state: "minecraft:air"},
        {pos: [1, 1, 3], state: "minecraft:air"},
        {pos: [2, 1, 1], state: "minecraft:air"},
        {pos: [9, 1, 3], state: "minecraft:brick_stairs{half:bottom,waterlogged:false,shape:straight,facing:north}"},
        {pos: [2, 2, 1], state: "minecraft:air"},
        {pos: [3, 2, 1], state: "minecraft:air"},
        {pos: [10, 2, 2], state: "minecraft:brick_slab{waterlogged:false,type:bottom}"},
        {pos: [10, 2, 5], state: "minecraft:brick_slab{waterlogged:false,type:bottom}"},
        {pos: [2, 3, 1], state: "minecraft:air"},
        {pos: [2, 3, 4], state: "minecraft:air"},
        {pos: [2, 3, 5], state: "minecraft:air"},
        {pos: [3, 3, 1], state: "minecraft:air"},
        {pos: [3, 3, 3], state: "minecraft:air"},
        {pos: [3, 3, 4], state: "minecraft:air"},
        {pos: [3, 3, 5], state: "minecraft:air"},
        {pos: [4, 3, 4], state: "minecraft:air"},
        {pos: [4, 3, 6], state: "minecraft:air"},
        {pos: [5, 3, 1], state: "minecraft:air"},
        {pos: [5, 3, 2], state: "minecraft:air"},
        {pos: [5, 3, 3], state: "minecraft:air"},
        {pos: [5, 3, 4], state: "minecraft:air"},
        {pos: [6, 3, 1], state: "minecraft:air"},
        {pos: [6, 3, 3], state: "minecraft:air"},
        {pos: [6, 3, 4], state: "minecraft:air"},
        {pos: [6, 3, 5], state: "minecraft:air"},
        {pos: [6, 3, 6], state: "minecraft:air"},
        {pos: [7, 3, 5], state: "minecraft:air"},
        {pos: [0, 4, 1], state: "minecraft:air"},
        {pos: [2, 4, 2], state: "minecraft:air"},
        {pos: [2, 4, 3], state: "minecraft:air"},
        {pos: [2, 4, 4], state: "minecraft:air"},
        {pos: [2, 4, 5], state: "minecraft:air"},
        {pos: [3, 4, 1], state: "minecraft:air"},
        {pos: [3, 4, 2], state: "minecraft:air"},
        {pos: [3, 4, 3], state: "minecraft:air"},
        {pos: [3, 4, 4], state: "minecraft:air"},
        {pos: [3, 4, 5], state: "minecraft:air"},
        {pos: [4, 4, 1], state: "minecraft:air"},
        {pos: [4, 4, 2], state: "minecraft:air"},
        {pos: [4, 4, 3], state: "minecraft:air"},
        {pos: [4, 4, 4], state: "minecraft:air"},
        {pos: [4, 4, 5], state: "minecraft:air"},
        {pos: [4, 4, 6], state: "minecraft:air"},
        {pos: [5, 4, 1], state: "minecraft:air"},
        {pos: [5, 4, 2], state: "minecraft:air"},
        {pos: [5, 4, 3], state: "minecraft:air"},
        {pos: [5, 4, 4], state: "minecraft:air"},
        {pos: [5, 4, 5], state: "minecraft:air"},
        {pos: [6, 4, 1], state: "minecraft:air"},
        {pos: [6, 4, 3], state: "minecraft:air"},
        {pos: [6, 4, 4], state: "minecraft:air"},
        {pos: [6, 4, 5], state: "minecraft:air"},
        {pos: [6, 4, 6], state: "minecraft:air"},
        {pos: [7, 4, 5], state: "minecraft:air"},
        {pos: [2, 5, 2], state: "minecraft:air"},
        {pos: [2, 5, 3], state: "minecraft:air"},
        {pos: [2, 5, 4], state: "minecraft:air"},
        {pos: [2, 5, 5], state: "minecraft:air"},
        {pos: [3, 5, 2], state: "minecraft:air"},
        {pos: [3, 5, 3], state: "minecraft:air"},
        {pos: [3, 5, 4], state: "minecraft:air"},
        {pos: [3, 5, 5], state: "minecraft:air"},
        {pos: [4, 5, 1], state: "minecraft:air"},
        {pos: [4, 5, 2], state: "minecraft:air"},
        {pos: [4, 5, 3], state: "minecraft:air"},
        {pos: [4, 5, 4], state: "minecraft:air"},
        {pos: [4, 5, 5], state: "minecraft:air"},
        {pos: [4, 5, 6], state: "minecraft:air"},
        {pos: [5, 5, 1], state: "minecraft:air"},
        {pos: [5, 5, 2], state: "minecraft:air"},
        {pos: [5, 5, 3], state: "minecraft:air"},
        {pos: [5, 5, 4], state: "minecraft:air"},
        {pos: [5, 5, 5], state: "minecraft:air"},
        {pos: [6, 5, 1], state: "minecraft:air"},
        {pos: [6, 5, 3], state: "minecraft:air"},
        {pos: [6, 5, 4], state: "minecraft:air"},
        {pos: [6, 5, 5], state: "minecraft:air"},
        {pos: [6, 5, 6], state: "minecraft:air"},
        {pos: [7, 5, 5], state: "minecraft:air"},
        {pos: [2, 6, 0], state: "minecraft:air"},
        {pos: [2, 6, 2], state: "minecraft:air"},
        {pos: [2, 6, 3], state: "minecraft:air"},
        {pos: [3, 6, 2], state: "minecraft:air"},
        {pos: [4, 6, 1], state: "minecraft:air"},
        {pos: [4, 6, 2], state: "minecraft:air"},
        {pos: [4, 6, 3], state: "minecraft:air"},
        {pos: [4, 6, 5], state: "minecraft:air"},
        {pos: [5, 6, 5], state: "minecraft:air"},
        {pos: [7, 6, 2], state: "minecraft:air"},
        {pos: [7, 1, 7], state: "minecraft:jigsaw{orientation:south_up}", nbt: {final_state: "minecraft:dirt", id: "minecraft:jigsaw", joint: "rollable", name: "minecraft:large_hall_connector", pool: "minecraft:trail_ruins/tower", target: "minecraft:road_anchor"}}
    ],
    entities: [],
    palette: [
        "minecraft:bricks",
        "minecraft:gravel",
        "minecraft:gray_terracotta",
        "minecraft:red_terracotta",
        "minecraft:air",
        "minecraft:brick_stairs{half:bottom,waterlogged:false,shape:straight,facing:north}",
        "minecraft:brick_slab{waterlogged:false,type:bottom}",
        "minecraft:jigsaw{orientation:south_up}"
    ]
}