{
    size: [6, 7, 7],
    data: [
        {pos: [0, 0, 0], state: "minecraft:mud_bricks"},
        {pos: [0, 0, 1], state: "minecraft:mud_bricks"},
        {pos: [0, 0, 2], state: "minecraft:mud_bricks"},
        {pos: [0, 0, 3], state: "minecraft:mud_bricks"},
        {pos: [0, 0, 4], state: "minecraft:mud_bricks"},
        {pos: [0, 0, 5], state: "minecraft:mud_bricks"},
        {pos: [1, 0, 0], state: "minecraft:mud_bricks"},
        {pos: [1, 0, 1], state: "minecraft:mud_bricks"},
        {pos: [1, 0, 2], state: "minecraft:mud_bricks"},
        {pos: [1, 0, 3], state: "minecraft:mud_bricks"},
        {pos: [1, 0, 4], state: "minecraft:mud_bricks"},
        {pos: [1, 0, 5], state: "minecraft:mud_bricks"},
        {pos: [2, 0, 0], state: "minecraft:mud_bricks"},
        {pos: [2, 0, 1], state: "minecraft:mud_bricks"},
        {pos: [2, 0, 2], state: "minecraft:mud_bricks"},
        {pos: [2, 0, 3], state: "minecraft:mud_bricks"},
        {pos: [2, 0, 4], state: "minecraft:mud_bricks"},
        {pos: [2, 0, 5], state: "minecraft:mud_bricks"},
        {pos: [2, 0, 6], state: "minecraft:mud_bricks"},
        {pos: [3, 0, 0], state: "minecraft:mud_bricks"},
        {pos: [3, 0, 1], state: "minecraft:mud_bricks"},
        {pos: [3, 0, 2], state: "minecraft:mud_bricks"},
        {pos: [3, 0, 3], state: "minecraft:mud_bricks"},
        {pos: [3, 0, 4], state: "minecraft:mud_bricks"},
        {pos: [3, 0, 5], state: "minecraft:mud_bricks"},
        {pos: [3, 0, 6], state: "minecraft:mud_bricks"},
        {pos: [4, 0, 0], state: "minecraft:mud_bricks"},
        {pos: [4, 0, 1], state: "minecraft:mud_bricks"},
        {pos: [4, 0, 2], state: "minecraft:mud_bricks"},
        {pos: [4, 0, 3], state: "minecraft:mud_bricks"},
        {pos: [4, 0, 4], state: "minecraft:mud_bricks"},
        {pos: [4, 0, 5], state: "minecraft:mud_bricks"},
        {pos: [5, 0, 0], state: "minecraft:mud_bricks"},
        {pos: [5, 0, 1], state: "minecraft:mud_bricks"},
        {pos: [5, 0, 2], state: "minecraft:mud_bricks"},
        {pos: [5, 0, 3], state: "minecraft:mud_bricks"},
        {pos: [5, 0, 4], state: "minecraft:mud_bricks"},
        {pos: [5, 0, 5], state: "minecraft:mud_bricks"},
        {pos: [0, 1, 0], state: "minecraft:mud_bricks"},
        {pos: [0, 1, 1], state: "minecraft:mud_bricks"},
        {pos: [0, 1, 2], state: "minecraft:mud_bricks"},
        {pos: [0, 1, 3], state: "minecraft:mud_bricks"},
        {pos: [0, 1, 4], state: "minecraft:mud_bricks"},
        {pos: [0, 1, 5], state: "minecraft:mud_bricks"},
        {pos: [1, 1, 0], state: "minecraft:mud_bricks"},
        {pos: [1, 1, 1], state: "minecraft:mud_bricks"},
        {pos: [1, 1, 2], state: "minecraft:yellow_glazed_terracotta{facing:south}"},
        {pos: [1, 1, 3], state: "minecraft:yellow_glazed_terracotta{facing:east}"},
        {pos: [1, 1, 4], state: "minecraft:mud_bricks"},
        {pos: [1, 1, 5], state: "minecraft:mud_bricks"},
        {pos: [2, 1, 0], state: "minecraft:mud_bricks"},
        {pos: [2, 1, 1], state: "minecraft:yellow_glazed_terracotta{facing:south}"},
        {pos: [2, 1, 2], state: "minecraft:yellow_glazed_terracotta{facing:north}"},
        {pos: [2, 1, 3], state: "minecraft:yellow_glazed_terracotta{facing:west}"},
        {pos: [2, 1, 4], state: "minecraft:gravel"},
        {pos: [2, 1, 5], state: "minecraft:mud_bricks"},
        {pos: [2, 1, 6], state: "minecraft:mud_bricks"},
        {pos: [3, 1, 0], state: "minecraft:mud_bricks"},
        {pos: [3, 1, 1], state: "minecraft:gravel"},
        {pos: [3, 1, 2], state: "minecraft:gravel"},
        {pos: [3, 1, 3], state: "minecraft:yellow_glazed_terracotta{facing:south}"},
        {pos: [3, 1, 4], state: "minecraft:yellow_glazed_terracotta{facing:north}"},
        {pos: [3, 1, 5], state: "minecraft:mud_bricks"},
        {pos: [4, 1, 0], state: "minecraft:mud_bricks"},
        {pos: [4, 1, 1], state: "minecraft:mud_bricks"},
        {pos: [4, 1, 2], state: "minecraft:yellow_glazed_terracotta{facing:west}"},
        {pos: [4, 1, 3], state: "minecraft:yellow_glazed_terracotta{facing:north}"},
        {pos: [4, 1, 4], state: "minecraft:mud_bricks"},
        {pos: [4, 1, 5], state: "minecraft:mud_bricks"},
        {pos: [5, 1, 0], state: "minecraft:mud_bricks"},
        {pos: [5, 1, 1], state: "minecraft:mud_bricks"},
        {pos: [5, 1, 2], state: "minecraft:mud_bricks"},
        {pos: [5, 1, 3], state: "minecraft:mud_bricks"},
        {pos: [5, 1, 4], state: "minecraft:mud_bricks"},
        {pos: [5, 1, 5], state: "minecraft:mud_bricks"},
        {pos: [0, 2, 0], state: "minecraft:mud_bricks"},
        {pos: [0, 2, 2], state: "minecraft:gravel"},
        {pos: [0, 2, 5], state: "minecraft:mud_bricks"},
        {pos: [1, 2, 2], state: "minecraft:gravel"},
        {pos: [1, 2, 3], state: "minecraft:blue_terracotta"},
        {pos: [2, 2, 0], state: "minecraft:gravel"},
        {pos: [2, 2, 1], state: "minecraft:gravel"},
        {pos: [2, 2, 2], state: "minecraft:gravel"},
        {pos: [2, 2, 3], state: "minecraft:gravel"},
        {pos: [2, 2, 4], state: "minecraft:gravel"},
        {pos: [2, 2, 6], state: "minecraft:gravel"},
        {pos: [3, 2, 0], state: "minecraft:blue_terracotta"},
        {pos: [3, 2, 1], state: "minecraft:gravel"},
        {pos: [3, 2, 2], state: "minecraft:gravel"},
        {pos: [3, 2, 3], state: "minecraft:gravel"},
        {pos: [3, 2, 4], state: "minecraft:gravel"},
        {pos: [3, 2, 5], state: "minecraft:gravel"},
        {pos: [3, 2, 6], state: "minecraft:gravel"},
        {pos: [4, 2, 0], state: "minecraft:red_terracotta"},
        {pos: [4, 2, 1], state: "minecraft:gravel"},
        {pos: [4, 2, 2], state: "minecraft:gravel"},
        {pos: [4, 2, 3], state: "minecraft:gravel"},
        {pos: [5, 2, 0], state: "minecraft:mud_bricks"},
        {pos: [5, 2, 2], state: "minecraft:gravel"},
        {pos: [5, 2, 3], state: "minecraft:gravel"},
        {pos: [5, 2, 5], state: "minecraft:mud_bricks"},
        {pos: [0, 3, 0], state: "minecraft:red_terracotta"},
        {pos: [0, 3, 5], state: "minecraft:red_terracotta"},
        {pos: [1, 3, 1], state: "minecraft:gravel"},
        {pos: [1, 3, 2], state: "minecraft:gravel"},
        {pos: [1, 3, 3], state: "minecraft:gravel"},
        {pos: [1, 3, 4], state: "minecraft:gravel"},
        {pos: [1, 3, 5], state: "minecraft:gravel"},
        {pos: [2, 3, 1], state: "minecraft:gravel"},
        {pos: [2, 3, 2], state: "minecraft:gravel"},
        {pos: [2, 3, 3], state: "minecraft:gravel"},
        {pos: [2, 3, 4], state: "minecraft:gravel"},
        {pos: [2, 3, 5], state: "minecraft:gravel"},
        {pos: [2, 3, 6], state: "minecraft:gravel"},
        {pos: [3, 3, 1], state: "minecraft:gravel"},
        {pos: [3, 3, 2], state: "minecraft:gravel"},
        {pos: [3, 3, 3], state: "minecraft:gravel"},
        {pos: [3, 3, 4], state: "minecraft:gravel"},
        {pos: [3, 3, 5], state: "minecraft:gravel"},
        {pos: [3, 3, 6], state: "minecraft:gravel"},
        {pos: [4, 3, 1], state: "minecraft:gravel"},
        {pos: [4, 3, 2], state: "minecraft:gravel"},
        {pos: [4, 3, 3], state: "minecraft:gravel"},
        {pos: [4, 3, 4], state: "minecraft:gravel"},
        {pos: [4, 3, 5], state: "minecraft:gravel"},
        {pos: [5, 3, 1], state: "minecraft:gravel"},
        {pos: [5, 3, 2], state: "minecraft:gravel"},
        {pos: [5, 3, 3], state: "minecraft:gravel"},
        {pos: [5, 3, 4], state: "minecraft:gravel"},
        {pos: [5, 3, 5], state: "minecraft:red_terracotta"},
        {pos: [0, 4, 0], state: "minecraft:mud_bricks"},
        {pos: [0, 4, 5], state: "minecraft:mud_bricks"},
        {pos: [1, 4, 1], state: "minecraft:gravel"},
        {pos: [1, 4, 2], state: "minecraft:gravel"},
        {pos: [1, 4, 3], state: "minecraft:gravel"},
        {pos: [1, 4, 4], state: "minecraft:gravel"},
        {pos: [1, 4, 5], state: "minecraft:gravel"},
        {pos: [2, 4, 1], state: "minecraft:gravel"},
        {pos: [2, 4, 2], state: "minecraft:gravel"},
        {pos: [2, 4, 3], state: "minecraft:gravel"},
        {pos: [2, 4, 4], state: "minecraft:gravel"},
        {pos: [2, 4, 5], state: "minecraft:gravel"},
        {pos: [2, 4, 6], state: "minecraft:gravel"},
        {pos: [3, 4, 1], state: "minecraft:gravel"},
        {pos: [3, 4, 2], state: "minecraft:gravel"},
        {pos: [3, 4, 3], state: "minecraft:gravel"},
        {pos: [3, 4, 4], state: "minecraft:gravel"},
        {pos: [3, 4, 5], state: "minecraft:gravel"},
        {pos: [3, 4, 6], state: "minecraft:gravel"},
        {pos: [4, 4, 3], state: "minecraft:gravel"},
        {pos: [4, 4, 4], state: "minecraft:gravel"},
        {pos: [5, 4, 3], state: "minecraft:gravel"},
        {pos: [5, 4, 5], state: "minecraft:mud_bricks"},
        {pos: [0, 5, 0], state: "minecraft:mud_bricks"},
        {pos: [0, 5, 1], state: "minecraft:mud_bricks"},
        {pos: [0, 5, 4], state: "minecraft:mud_bricks"},
        {pos: [1, 5, 0], state: "minecraft:mud_bricks"},
        {pos: [1, 5, 1], state: "minecraft:gravel"},
        {pos: [1, 5, 2], state: "minecraft:gravel"},
        {pos: [1, 5, 3], state: "minecraft:gravel"},
        {pos: [2, 5, 1], state: "minecraft:gravel"},
        {pos: [2, 5, 2], state: "minecraft:gravel"},
        {pos: [2, 5, 3], state: "minecraft:gravel"},
        {pos: [2, 5, 4], state: "minecraft:gravel"},
        {pos: [3, 5, 2], state: "minecraft:gravel"},
        {pos: [3, 5, 3], state: "minecraft:gravel"},
        {pos: [3, 5, 4], state: "minecraft:gravel"},
        {pos: [4, 5, 3], state: "minecraft:gravel"},
        {pos: [4, 5, 4], state: "minecraft:gravel"},
        {pos: [4, 5, 5], state: "minecraft:mud_bricks"},
        {pos: [5, 5, 4], state: "minecraft:mud_bricks"},
        {pos: [0, 6, 1], state: "minecraft:blue_terracotta"},
        {pos: [0, 6, 2], state: "minecraft:red_terracotta"},
        {pos: [0, 6, 3], state: "minecraft:red_terracotta"},
        {pos: [0, 6, 4], state: "minecraft:blue_terracotta"},
        {pos: [1, 6, 0], state: "minecraft:blue_terracotta"},
        {pos: [1, 6, 1], state: "minecraft:blue_terracotta"},
        {pos: [1, 6, 2], state: "minecraft:blue_terracotta"},
        {pos: [2, 6, 1], state: "minecraft:blue_terracotta"},
        {pos: [2, 6, 2], state: "minecraft:yellow_terracotta"},
        {pos: [2, 6, 5], state: "minecraft:red_terracotta"},
        {pos: [3, 6, 2], state: "minecraft:yellow_terracotta"},
        {pos: [3, 6, 3], state: "minecraft:yellow_terracotta"},
        {pos: [3, 6, 4], state: "minecraft:blue_terracotta"},
        {pos: [3, 6, 5], state: "minecraft:red_terracotta"},
        {pos: [4, 6, 3], state: "minecraft:blue_terracotta"},
        {pos: [4, 6, 4], state: "minecraft:blue_terracotta"},
        {pos: [4, 6, 5], state: "minecraft:blue_terracotta"},
        {pos: [5, 6, 4], state: "minecraft:blue_terracotta"},
        {pos: [0, 2, 1], state: "minecraft:mud_brick_stairs{half:bottom,waterlogged:false,shape:straight,facing:north}"},
        {pos: [0, 2, 4], state: "minecraft:mud_brick_stairs{half:bottom,waterlogged:false,shape:straight,facing:south}"},
        {pos: [1, 2, 0], state: "minecraft:mud_brick_stairs{half:bottom,waterlogged:false,shape:straight,facing:west}"},
        {pos: [1, 2, 1], state: "minecraft:mud_brick_stairs{half:bottom,waterlogged:false,shape:outer_right,facing:west}"},
        {pos: [1, 2, 4], state: "minecraft:mud_brick_stairs{half:bottom,waterlogged:false,shape:outer_left,facing:west}"},
        {pos: [1, 2, 5], state: "minecraft:mud_brick_stairs{half:bottom,waterlogged:false,shape:inner_left,facing:west}"},
        {pos: [2, 2, 5], state: "minecraft:mud_brick_stairs{half:bottom,waterlogged:false,shape:straight,facing:south}"},
        {pos: [4, 2, 4], state: "minecraft:mud_brick_stairs{half:bottom,waterlogged:false,shape:outer_right,facing:east}"},
        {pos: [4, 2, 5], state: "minecraft:mud_brick_stairs{half:bottom,waterlogged:false,shape:straight,facing:east}"},
        {pos: [5, 2, 1], state: "minecraft:mud_brick_stairs{half:bottom,waterlogged:false,shape:straight,facing:north}"},
        {pos: [5, 2, 4], state: "minecraft:mud_brick_stairs{half:bottom,waterlogged:false,shape:straight,facing:south}"},
        {pos: [0, 4, 1], state: "minecraft:mud_brick_stairs{half:top,waterlogged:false,shape:straight,facing:north}"},
        {pos: [0, 4, 4], state: "minecraft:mud_brick_stairs{half:top,waterlogged:false,shape:straight,facing:south}"},
        {pos: [1, 4, 0], state: "minecraft:mud_brick_stairs{half:top,waterlogged:false,shape:straight,facing:west}"},
        {pos: [4, 4, 5], state: "minecraft:mud_brick_stairs{half:top,waterlogged:false,shape:straight,facing:east}"},
        {pos: [5, 4, 4], state: "minecraft:mud_brick_stairs{half:top,waterlogged:false,shape:straight,facing:south}"},
        {pos: [3, 1, 6], state: "minecraft:jigsaw{orientation:south_up}", nbt: {final_state: "minecraft:mud_bricks", id: "minecraft:jigsaw", joint: "rollable", name: "minecraft:large_hall_connector", pool: "minecraft:trail_ruins/tower", target: "minecraft:road_anchor"}}
    ],
    entities: [],
    palette: [
        "minecraft:mud_bricks",
        "minecraft:yellow_glazed_terracotta{facing:south}",
        "minecraft:yellow_glazed_terracotta{facing:east}",
        "minecraft:yellow_glazed_terracotta{facing:north}",
        "minecraft:yellow_glazed_terracotta{facing:west}",
        "minecraft:gravel",
        "minecraft:blue_terracotta",
        "minecraft:red_terracotta",
        "minecraft:yellow_terracotta",
        "minecraft:mud_brick_stairs{half:bottom,waterlogged:false,shape:straight,facing:north}",
        "minecraft:mud_brick_stairs{half:bottom,waterlogged:false,shape:straight,facing:south}",
        "minecraft:mud_brick_stairs{half:bottom,waterlogged:false,shape:straight,facing:west}",
        "minecraft:mud_brick_stairs{half:bottom,waterlogged:false,shape:outer_right,facing:west}",
        "minecraft:mud_brick_stairs{half:bottom,waterlogged:false,shape:outer_left,facing:west}",
        "minecraft:mud_brick_stairs{half:bottom,waterlogged:false,shape:inner_left,facing:west}",
        "minecraft:mud_brick_stairs{half:bottom,waterlogged:false,shape:outer_right,facing:east}",
        "minecraft:mud_brick_stairs{half:bottom,waterlogged:false,shape:straight,facing:east}",
        "minecraft:mud_brick_stairs{half:top,waterlogged:false,shape:straight,facing:north}",
        "minecraft:mud_brick_stairs{half:top,waterlogged:false,shape:straight,facing:south}",
        "minecraft:mud_brick_stairs{half:top,waterlogged:false,shape:straight,facing:west}",
        "minecraft:mud_brick_stairs{half:top,waterlogged:false,shape:straight,facing:east}",
        "minecraft:jigsaw{orientation:south_up}"
    ]
}