{
    size: [6, 7, 7],
    data: [
        {pos: [0, 0, 0], state: "minecraft:bricks"},
        {pos: [0, 0, 1], state: "minecraft:bricks"},
        {pos: [0, 0, 2], state: "minecraft:bricks"},
        {pos: [0, 0, 3], state: "minecraft:bricks"},
        {pos: [0, 0, 4], state: "minecraft:bricks"},
        {pos: [0, 0, 5], state: "minecraft:bricks"},
        {pos: [0, 0, 6], state: "minecraft:bricks"},
        {pos: [1, 0, 0], state: "minecraft:bricks"},
        {pos: [1, 0, 1], state: "minecraft:bricks"},
        {pos: [1, 0, 2], state: "minecraft:bricks"},
        {pos: [1, 0, 3], state: "minecraft:bricks"},
        {pos: [1, 0, 4], state: "minecraft:bricks"},
        {pos: [1, 0, 5], state: "minecraft:bricks"},
        {pos: [1, 0, 6], state: "minecraft:bricks"},
        {pos: [2, 0, 0], state: "minecraft:bricks"},
        {pos: [2, 0, 1], state: "minecraft:bricks"},
        {pos: [2, 0, 2], state: "minecraft:bricks"},
        {pos: [2, 0, 3], state: "minecraft:bricks"},
        {pos: [2, 0, 4], state: "minecraft:bricks"},
        {pos: [2, 0, 5], state: "minecraft:bricks"},
        {pos: [2, 0, 6], state: "minecraft:bricks"},
        {pos: [3, 0, 0], state: "minecraft:bricks"},
        {pos: [3, 0, 1], state: "minecraft:bricks"},
        {pos: [3, 0, 2], state: "minecraft:bricks"},
        {pos: [3, 0, 3], state: "minecraft:bricks"},
        {pos: [3, 0, 4], state: "minecraft:bricks"},
        {pos: [3, 0, 5], state: "minecraft:bricks"},
        {pos: [3, 0, 6], state: "minecraft:bricks"},
        {pos: [4, 0, 0], state: "minecraft:bricks"},
        {pos: [4, 0, 1], state: "minecraft:bricks"},
        {pos: [4, 0, 2], state: "minecraft:bricks"},
        {pos: [4, 0, 3], state: "minecraft:bricks"},
        {pos: [4, 0, 4], state: "minecraft:bricks"},
        {pos: [4, 0, 5], state: "minecraft:bricks"},
        {pos: [4, 0, 6], state: "minecraft:bricks"},
        {pos: [5, 0, 0], state: "minecraft:bricks"},
        {pos: [5, 0, 1], state: "minecraft:bricks"},
        {pos: [5, 0, 2], state: "minecraft:bricks"},
        {pos: [5, 0, 3], state: "minecraft:bricks"},
        {pos: [5, 0, 4], state: "minecraft:bricks"},
        {pos: [5, 0, 5], state: "minecraft:bricks"},
        {pos: [5, 0, 6], state: "minecraft:bricks"},
        {pos: [0, 1, 0], state: "minecraft:bricks"},
        {pos: [0, 1, 1], state: "minecraft:bricks"},
        {pos: [0, 1, 2], state: "minecraft:bricks"},
        {pos: [0, 1, 3], state: "minecraft:bricks"},
        {pos: [0, 1, 4], state: "minecraft:bricks"},
        {pos: [0, 1, 5], state: "minecraft:bricks"},
        {pos: [0, 1, 6], state: "minecraft:bricks"},
        {pos: [1, 1, 0], state: "minecraft:bricks"},
        {pos: [1, 1, 1], state: "minecraft:bricks"},
        {pos: [1, 1, 2], state: "minecraft:bricks"},
        {pos: [1, 1, 3], state: "minecraft:bricks"},
        {pos: [1, 1, 4], state: "minecraft:light_gray_terracotta"},
        {pos: [1, 1, 5], state: "minecraft:light_gray_terracotta"},
        {pos: [1, 1, 6], state: "minecraft:bricks"},
        {pos: [2, 1, 0], state: "minecraft:bricks"},
        {pos: [2, 1, 1], state: "minecraft:bricks"},
        {pos: [2, 1, 2], state: "minecraft:bricks"},
        {pos: [2, 1, 3], state: "minecraft:bricks"},
        {pos: [2, 1, 4], state: "minecraft:light_gray_terracotta"},
        {pos: [2, 1, 5], state: "minecraft:light_gray_terracotta"},
        {pos: [2, 1, 6], state: "minecraft:bricks"},
        {pos: [3, 1, 0], state: "minecraft:bricks"},
        {pos: [3, 1, 1], state: "minecraft:bricks"},
        {pos: [3, 1, 2], state: "minecraft:bricks"},
        {pos: [3, 1, 3], state: "minecraft:bricks"},
        {pos: [3, 1, 4], state: "minecraft:light_gray_terracotta"},
        {pos: [3, 1, 5], state: "minecraft:light_gray_terracotta"},
        {pos: [4, 1, 0], state: "minecraft:bricks"},
        {pos: [4, 1, 1], state: "minecraft:bricks"},
        {pos: [4, 1, 2], state: "minecraft:bricks"},
        {pos: [4, 1, 3], state: "minecraft:bricks"},
        {pos: [4, 1, 4], state: "minecraft:light_gray_terracotta"},
        {pos: [4, 1, 5], state: "minecraft:light_gray_terracotta"},
        {pos: [4, 1, 6], state: "minecraft:bricks"},
        {pos: [5, 1, 0], state: "minecraft:bricks"},
        {pos: [5, 1, 1], state: "minecraft:bricks"},
        {pos: [5, 1, 2], state: "minecraft:bricks"},
        {pos: [5, 1, 3], state: "minecraft:bricks"},
        {pos: [5, 1, 4], state: "minecraft:bricks"},
        {pos: [5, 1, 5], state: "minecraft:bricks"},
        {pos: [5, 1, 6], state: "minecraft:bricks"},
        {pos: [0, 2, 0], state: "minecraft:bricks"},
        {pos: [0, 2, 1], state: "minecraft:bricks"},
        {pos: [0, 2, 2], state: "minecraft:bricks"},
        {pos: [0, 2, 3], state: "minecraft:bricks"},
        {pos: [0, 2, 4], state: "minecraft:gravel"},
        {pos: [0, 2, 5], state: "minecraft:gravel"},
        {pos: [0, 2, 6], state: "minecraft:bricks"},
        {pos: [1, 2, 0], state: "minecraft:bricks"},
        {pos: [1, 2, 1], state: "minecraft:white_terracotta"},
        {pos: [1, 2, 2], state: "minecraft:white_terracotta"},
        {pos: [1, 2, 4], state: "minecraft:gravel"},
        {pos: [1, 2, 5], state: "minecraft:bricks"},
        {pos: [2, 2, 0], state: "minecraft:bricks"},
        {pos: [2, 2, 1], state: "minecraft:white_terracotta"},
        {pos: [2, 2, 2], state: "minecraft:white_terracotta"},
        {pos: [2, 2, 4], state: "minecraft:gravel"},
        {pos: [2, 2, 5], state: "minecraft:gravel"},
        {pos: [2, 2, 6], state: "minecraft:gravel"},
        {pos: [3, 2, 0], state: "minecraft:bricks"},
        {pos: [3, 2, 1], state: "minecraft:white_terracotta"},
        {pos: [3, 2, 2], state: "minecraft:white_terracotta"},
        {pos: [3, 2, 4], state: "minecraft:gravel"},
        {pos: [3, 2, 5], state: "minecraft:gravel"},
        {pos: [3, 2, 6], state: "minecraft:gravel"},
        {pos: [4, 2, 0], state: "minecraft:bricks"},
        {pos: [4, 2, 1], state: "minecraft:white_terracotta"},
        {pos: [4, 2, 2], state: "minecraft:gravel"},
        {pos: [4, 2, 4], state: "minecraft:gravel"},
        {pos: [4, 2, 5], state: "minecraft:gravel"},
        {pos: [4, 2, 6], state: "minecraft:gravel"},
        {pos: [5, 2, 0], state: "minecraft:bricks"},
        {pos: [5, 2, 1], state: "minecraft:bricks"},
        {pos: [5, 2, 2], state: "minecraft:bricks"},
        {pos: [5, 2, 3], state: "minecraft:bricks"},
        {pos: [5, 2, 4], state: "minecraft:gravel"},
        {pos: [5, 2, 6], state: "minecraft:bricks"},
        {pos: [0, 3, 0], state: "minecraft:blue_terracotta"},
        {pos: [0, 3, 2], state: "minecraft:gravel"},
        {pos: [0, 3, 3], state: "minecraft:gravel"},
        {pos: [0, 3, 4], state: "minecraft:gravel"},
        {pos: [0, 3, 5], state: "minecraft:gravel"},
        {pos: [1, 3, 0], state: "minecraft:light_blue_glazed_terracotta{facing:west}"},
        {pos: [1, 3, 1], state: "minecraft:gravel"},
        {pos: [1, 3, 2], state: "minecraft:blue_terracotta"},
        {pos: [1, 3, 3], state: "minecraft:gravel"},
        {pos: [1, 3, 4], state: "minecraft:gravel"},
        {pos: [1, 3, 5], state: "minecraft:gravel"},
        {pos: [1, 3, 6], state: "minecraft:gravel"},
        {pos: [2, 3, 0], state: "minecraft:light_blue_glazed_terracotta{facing:south}"},
        {pos: [2, 3, 2], state: "minecraft:gravel"},
        {pos: [2, 3, 3], state: "minecraft:gravel"},
        {pos: [2, 3, 4], state: "minecraft:gravel"},
        {pos: [2, 3, 5], state: "minecraft:gravel"},
        {pos: [2, 3, 6], state: "minecraft:gravel"},
        {pos: [3, 3, 0], state: "minecraft:light_blue_glazed_terracotta{facing:west}"},
        {pos: [3, 3, 2], state: "minecraft:gravel"},
        {pos: [3, 3, 3], state: "minecraft:gravel"},
        {pos: [3, 3, 4], state: "minecraft:gravel"},
        {pos: [3, 3, 5], state: "minecraft:gravel"},
        {pos: [3, 3, 6], state: "minecraft:gravel"},
        {pos: [4, 3, 0], state: "minecraft:light_blue_glazed_terracotta{facing:south}"},
        {pos: [4, 3, 1], state: "minecraft:gravel"},
        {pos: [4, 3, 2], state: "minecraft:gravel"},
        {pos: [4, 3, 3], state: "minecraft:gravel"},
        {pos: [4, 3, 4], state: "minecraft:gravel"},
        {pos: [4, 3, 5], state: "minecraft:gravel"},
        {pos: [4, 3, 6], state: "minecraft:gravel"},
        {pos: [5, 3, 0], state: "minecraft:blue_terracotta"},
        {pos: [5, 3, 1], state: "minecraft:gravel"},
        {pos: [5, 3, 2], state: "minecraft:gravel"},
        {pos: [5, 3, 3], state: "minecraft:gravel"},
        {pos: [5, 3, 4], state: "minecraft:gravel"},
        {pos: [5, 3, 6], state: "minecraft:bricks"},
        {pos: [0, 4, 0], state: "minecraft:blue_terracotta"},
        {pos: [0, 4, 2], state: "minecraft:gravel"},
        {pos: [0, 4, 3], state: "minecraft:gravel"},
        {pos: [0, 4, 4], state: "minecraft:gravel"},
        {pos: [1, 4, 0], state: "minecraft:light_blue_glazed_terracotta{facing:south}"},
        {pos: [1, 4, 1], state: "minecraft:gravel"},
        {pos: [1, 4, 2], state: "minecraft:gravel"},
        {pos: [1, 4, 3], state: "minecraft:gravel"},
        {pos: [1, 4, 4], state: "minecraft:gravel"},
        {pos: [1, 4, 5], state: "minecraft:gravel"},
        {pos: [1, 4, 6], state: "minecraft:gravel"},
        {pos: [2, 4, 0], state: "minecraft:light_blue_glazed_terracotta{facing:west}"},
        {pos: [2, 4, 1], state: "minecraft:gravel"},
        {pos: [2, 4, 2], state: "minecraft:gravel"},
        {pos: [2, 4, 3], state: "minecraft:gravel"},
        {pos: [2, 4, 4], state: "minecraft:gravel"},
        {pos: [2, 4, 5], state: "minecraft:gravel"},
        {pos: [2, 4, 6], state: "minecraft:gravel"},
        {pos: [3, 4, 0], state: "minecraft:light_blue_glazed_terracotta{facing:south}"},
        {pos: [3, 4, 1], state: "minecraft:gravel"},
        {pos: [3, 4, 2], state: "minecraft:gravel"},
        {pos: [3, 4, 3], state: "minecraft:gravel"},
        {pos: [3, 4, 4], state: "minecraft:gravel"},
        {pos: [3, 4, 5], state: "minecraft:gravel"},
        {pos: [3, 4, 6], state: "minecraft:gravel"},
        {pos: [4, 4, 0], state: "minecraft:light_blue_glazed_terracotta{facing:west}"},
        {pos: [4, 4, 1], state: "minecraft:gravel"},
        {pos: [4, 4, 2], state: "minecraft:gravel"},
        {pos: [4, 4, 3], state: "minecraft:gravel"},
        {pos: [4, 4, 4], state: "minecraft:gravel"},
        {pos: [4, 4, 5], state: "minecraft:gravel"},
        {pos: [4, 4, 6], state: "minecraft:gravel"},
        {pos: [5, 4, 0], state: "minecraft:blue_terracotta"},
        {pos: [5, 4, 1], state: "minecraft:gravel"},
        {pos: [5, 4, 2], state: "minecraft:gravel"},
        {pos: [5, 4, 3], state: "minecraft:gravel"},
        {pos: [5, 4, 6], state: "minecraft:bricks"},
        {pos: [0, 5, 2], state: "minecraft:gravel"},
        {pos: [1, 5, 1], state: "minecraft:gravel"},
        {pos: [1, 5, 2], state: "minecraft:gravel"},
        {pos: [1, 5, 3], state: "minecraft:gravel"},
        {pos: [1, 5, 4], state: "minecraft:gravel"},
        {pos: [2, 5, 0], state: "minecraft:light_blue_glazed_terracotta{facing:south}"},
        {pos: [2, 5, 1], state: "minecraft:gravel"},
        {pos: [2, 5, 2], state: "minecraft:gravel"},
        {pos: [2, 5, 3], state: "minecraft:gravel"},
        {pos: [2, 5, 4], state: "minecraft:gravel"},
        {pos: [2, 5, 5], state: "minecraft:gravel"},
        {pos: [3, 5, 0], state: "minecraft:light_blue_glazed_terracotta{facing:west}"},
        {pos: [3, 5, 1], state: "minecraft:gravel"},
        {pos: [3, 5, 2], state: "minecraft:gravel"},
        {pos: [3, 5, 3], state: "minecraft:gravel"},
        {pos: [3, 5, 4], state: "minecraft:gravel"},
        {pos: [3, 5, 5], state: "minecraft:gravel"},
        {pos: [4, 5, 0], state: "minecraft:light_blue_glazed_terracotta{facing:south}"},
        {pos: [4, 5, 2], state: "minecraft:gravel"},
        {pos: [4, 5, 3], state: "minecraft:gravel"},
        {pos: [4, 5, 4], state: "minecraft:gravel"},
        {pos: [4, 5, 6], state: "minecraft:bricks"},
        {pos: [5, 5, 0], state: "minecraft:blue_terracotta"},
        {pos: [2, 6, 3], state: "minecraft:gravel"},
        {pos: [2, 6, 4], state: "minecraft:gravel"},
        {pos: [3, 6, 0], state: "minecraft:blue_terracotta"},
        {pos: [3, 6, 2], state: "minecraft:gravel"},
        {pos: [3, 6, 3], state: "minecraft:gravel"},
        {pos: [3, 6, 4], state: "minecraft:gravel"},
        {pos: [4, 6, 0], state: "minecraft:blue_terracotta"},
        {pos: [1, 2, 3], state: "minecraft:brick_stairs{half:bottom,waterlogged:false,shape:straight,facing:north}"},
        {pos: [1, 2, 6], state: "minecraft:brick_slab{waterlogged:false,type:bottom}"},
        {pos: [2, 2, 3], state: "minecraft:brick_stairs{half:bottom,waterlogged:false,shape:straight,facing:north}"},
        {pos: [3, 2, 3], state: "minecraft:brick_stairs{half:bottom,waterlogged:false,shape:straight,facing:north}"},
        {pos: [4, 2, 3], state: "minecraft:brick_stairs{half:bottom,waterlogged:false,shape:straight,facing:north}"},
        {pos: [2, 3, 1], state: "minecraft:brick_stairs{half:bottom,waterlogged:false,shape:straight,facing:west}"},
        {pos: [3, 3, 1], state: "minecraft:brick_stairs{half:bottom,waterlogged:false,shape:straight,facing:east}"},
        {pos: [3, 5, 6], state: "minecraft:brick_slab{waterlogged:false,type:top}"},
        {pos: [5, 5, 6], state: "minecraft:brick_stairs{half:bottom,waterlogged:false,shape:straight,facing:west}"},
        {pos: [2, 6, 6], state: "minecraft:brick_stairs{half:top,waterlogged:false,shape:straight,facing:west}"},
        {pos: [3, 6, 6], state: "minecraft:brick_stairs{half:top,waterlogged:false,shape:straight,facing:east}"},
        {pos: [4, 6, 6], state: "minecraft:brick_stairs{half:bottom,waterlogged:false,shape:straight,facing:west}"},
        {pos: [3, 1, 6], state: "minecraft:jigsaw{orientation:south_up}", nbt: {final_state: "minecraft:mud_bricks", id: "minecraft:jigsaw", joint: "rollable", name: "minecraft:large_hall_connector", pool: "minecraft:trail_ruins/tower", target: "minecraft:road_anchor"}}
    ],
    entities: [],
    palette: [
        "minecraft:bricks",
        "minecraft:light_gray_terracotta",
        "minecraft:gravel",
        "minecraft:white_terracotta",
        "minecraft:blue_terracotta",
        "minecraft:light_blue_glazed_terracotta{facing:west}",
        "minecraft:light_blue_glazed_terracotta{facing:south}",
        "minecraft:brick_stairs{half:bottom,waterlogged:false,shape:straight,facing:north}",
        "minecraft:brick_slab{waterlogged:false,type:bottom}",
        "minecraft:brick_stairs{half:bottom,waterlogged:false,shape:straight,facing:west}",
        "minecraft:brick_stairs{half:bottom,waterlogged:false,shape:straight,facing:east}",
        "minecraft:brick_slab{waterlogged:false,type:top}",
        "minecraft:brick_stairs{half:top,waterlogged:false,shape:straight,facing:west}",
        "minecraft:brick_stairs{half:top,waterlogged:false,shape:straight,facing:east}",
        "minecraft:jigsaw{orientation:south_up}"
    ]
}