{
    size: [7, 4, 7],
    data: [
        {pos: [1, 0, 1], state: "minecraft:orange_terracotta"},
        {pos: [1, 0, 2], state: "minecraft:gravel"},
        {pos: [1, 0, 3], state: "minecraft:gravel"},
        {pos: [2, 0, 1], state: "minecraft:orange_terracotta"},
        {pos: [2, 0, 2], state: "minecraft:gravel"},
        {pos: [2, 0, 3], state: "minecraft:gravel"},
        {pos: [2, 0, 4], state: "minecraft:gravel"},
        {pos: [3, 0, 2], state: "minecraft:gravel"},
        {pos: [3, 0, 3], state: "minecraft:gravel"},
        {pos: [3, 0, 4], state: "minecraft:gravel"},
        {pos: [3, 0, 5], state: "minecraft:gravel"},
        {pos: [4, 0, 1], state: "minecraft:orange_terracotta"},
        {pos: [4, 0, 2], state: "minecraft:gravel"},
        {pos: [4, 0, 3], state: "minecraft:gravel"},
        {pos: [4, 0, 5], state: "minecraft:orange_terracotta"},
        {pos: [5, 0, 4], state: "minecraft:orange_terracotta"},
        {pos: [5, 0, 5], state: "minecraft:orange_terracotta"},
        {pos: [1, 1, 1], state: "minecraft:white_terracotta"},
        {pos: [2, 1, 2], state: "minecraft:gravel"},
        {pos: [3, 1, 1], state: "minecraft:gravel"},
        {pos: [3, 1, 2], state: "minecraft:gravel"},
        {pos: [3, 1, 3], state: "minecraft:gravel"},
        {pos: [3, 1, 4], state: "minecraft:gravel"},
        {pos: [3, 1, 5], state: "minecraft:gravel"},
        {pos: [4, 1, 1], state: "minecraft:orange_terracotta"},
        {pos: [4, 1, 2], state: "minecraft:gravel"},
        {pos: [4, 1, 3], state: "minecraft:gravel"},
        {pos: [4, 1, 4], state: "minecraft:gravel"},
        {pos: [4, 1, 5], state: "minecraft:orange_terracotta"},
        {pos: [5, 1, 2], state: "minecraft:orange_terracotta"},
        {pos: [5, 1, 3], state: "minecraft:orange_terracotta"},
        {pos: [5, 1, 4], state: "minecraft:orange_terracotta"},
        {pos: [5, 1, 5], state: "minecraft:white_terracotta"},
        {pos: [4, 2, 2], state: "minecraft:gravel"},
        {pos: [4, 2, 3], state: "minecraft:gravel"},
        {pos: [4, 2, 4], state: "minecraft:gravel"},
        {pos: [4, 2, 5], state: "minecraft:orange_terracotta"},
        {pos: [5, 2, 2], state: "minecraft:orange_terracotta"},
        {pos: [5, 2, 3], state: "minecraft:gravel"},
        {pos: [5, 2, 4], state: "minecraft:gravel"},
        {pos: [5, 2, 5], state: "minecraft:orange_terracotta"},
        {pos: [5, 3, 5], state: "minecraft:orange_terracotta"},
        {pos: [3, 0, 1], state: "minecraft:mud_brick_slab{waterlogged:false,type:top}"},
        {pos: [4, 0, 4], state: "minecraft:mud_brick_slab{waterlogged:false,type:top}"},
        {pos: [5, 0, 3], state: "minecraft:mud_brick_slab{waterlogged:false,type:top}"},
        {pos: [5, 0, 1], state: "minecraft:jigsaw{orientation:down_east}", nbt: {final_state: "minecraft:dirt", id: "minecraft:jigsaw", joint: "aligned", name: "minecraft:tower_top_3", pool: "minecraft:trail_ruins/tower", target: "minecraft:tower_bottom_3"}}
    ],
    entities: [],
    palette: [
        "minecraft:orange_terracotta",
        "minecraft:gravel",
        "minecraft:white_terracotta",
        "minecraft:mud_brick_slab{waterlogged:false,type:top}",
        "minecraft:jigsaw{orientation:down_east}"
    ]
}