{
    size: [7, 13, 7],
    data: [
        {pos: [0, 0, 1], state: "minecraft:cobblestone"},
        {pos: [0, 0, 2], state: "minecraft:cracked_stone_bricks"},
        {pos: [0, 0, 3], state: "minecraft:stone_bricks"},
        {pos: [0, 0, 4], state: "minecraft:stone_bricks"},
        {pos: [0, 0, 5], state: "minecraft:cobblestone"},
        {pos: [1, 0, 0], state: "minecraft:cobblestone"},
        {pos: [1, 0, 1], state: "minecraft:cobblestone"},
        {pos: [1, 0, 2], state: "minecraft:cobblestone"},
        {pos: [1, 0, 3], state: "minecraft:cobblestone"},
        {pos: [1, 0, 4], state: "minecraft:cobblestone"},
        {pos: [1, 0, 5], state: "minecraft:cobblestone"},
        {pos: [1, 0, 6], state: "minecraft:cobblestone"},
        {pos: [2, 0, 0], state: "minecraft:cracked_stone_bricks"},
        {pos: [2, 0, 1], state: "minecraft:cobblestone"},
        {pos: [2, 0, 2], state: "minecraft:cobblestone"},
        {pos: [2, 0, 3], state: "minecraft:cobblestone"},
        {pos: [2, 0, 4], state: "minecraft:cobblestone"},
        {pos: [2, 0, 5], state: "minecraft:cobblestone"},
        {pos: [2, 0, 6], state: "minecraft:stone_bricks"},
        {pos: [3, 0, 0], state: "minecraft:stone_bricks"},
        {pos: [3, 0, 1], state: "minecraft:cobblestone"},
        {pos: [3, 0, 2], state: "minecraft:cobblestone"},
        {pos: [3, 0, 3], state: "minecraft:cobblestone"},
        {pos: [3, 0, 4], state: "minecraft:cobblestone"},
        {pos: [3, 0, 5], state: "minecraft:cobblestone"},
        {pos: [3, 0, 6], state: "minecraft:stone_bricks"},
        {pos: [4, 0, 0], state: "minecraft:stone_bricks"},
        {pos: [4, 0, 1], state: "minecraft:cobblestone"},
        {pos: [4, 0, 2], state: "minecraft:cobblestone"},
        {pos: [4, 0, 3], state: "minecraft:cobblestone"},
        {pos: [4, 0, 4], state: "minecraft:cobblestone"},
        {pos: [4, 0, 5], state: "minecraft:cobblestone"},
        {pos: [4, 0, 6], state: "minecraft:cracked_stone_bricks"},
        {pos: [5, 0, 0], state: "minecraft:cobblestone"},
        {pos: [5, 0, 1], state: "minecraft:cobblestone"},
        {pos: [5, 0, 2], state: "minecraft:cobblestone"},
        {pos: [5, 0, 3], state: "minecraft:cobblestone"},
        {pos: [5, 0, 4], state: "minecraft:cobblestone"},
        {pos: [5, 0, 5], state: "minecraft:cobblestone"},
        {pos: [5, 0, 6], state: "minecraft:cobblestone"},
        {pos: [6, 0, 1], state: "minecraft:cobblestone"},
        {pos: [6, 0, 2], state: "minecraft:stone_bricks"},
        {pos: [6, 0, 3], state: "minecraft:cracked_stone_bricks"},
        {pos: [6, 0, 4], state: "minecraft:cracked_stone_bricks"},
        {pos: [6, 0, 5], state: "minecraft:cobblestone"},
        {pos: [0, 1, 1], state: "minecraft:cobblestone"},
        {pos: [0, 1, 2], state: "minecraft:stone_bricks"},
        {pos: [0, 1, 4], state: "minecraft:stone_bricks"},
        {pos: [0, 1, 5], state: "minecraft:cobblestone"},
        {pos: [1, 1, 0], state: "minecraft:cobblestone"},
        {pos: [1, 1, 1], state: "minecraft:stone_bricks"},
        {pos: [1, 1, 2], state: "minecraft:stone_bricks"},
        {pos: [1, 1, 3], state: "minecraft:cracked_stone_bricks"},
        {pos: [1, 1, 4], state: "minecraft:cracked_stone_bricks"},
        {pos: [1, 1, 5], state: "minecraft:cobblestone"},
        {pos: [1, 1, 6], state: "minecraft:cobblestone"},
        {pos: [2, 1, 0], state: "minecraft:stone_bricks"},
        {pos: [2, 1, 1], state: "minecraft:cobblestone"},
        {pos: [2, 1, 2], state: "minecraft:stone_bricks"},
        {pos: [2, 1, 3], state: "minecraft:cobblestone"},
        {pos: [2, 1, 4], state: "minecraft:cobblestone"},
        {pos: [2, 1, 5], state: "minecraft:cracked_stone_bricks"},
        {pos: [2, 1, 6], state: "minecraft:stone_bricks"},
        {pos: [3, 1, 1], state: "minecraft:stone_bricks"},
        {pos: [3, 1, 2], state: "minecraft:cracked_stone_bricks"},
        {pos: [3, 1, 3], state: "minecraft:cracked_stone_bricks"},
        {pos: [3, 1, 4], state: "minecraft:cracked_stone_bricks"},
        {pos: [3, 1, 5], state: "minecraft:stone_bricks"},
        {pos: [4, 1, 0], state: "minecraft:stone_bricks"},
        {pos: [4, 1, 1], state: "minecraft:cobblestone"},
        {pos: [4, 1, 2], state: "minecraft:cracked_stone_bricks"},
        {pos: [4, 1, 3], state: "minecraft:cracked_stone_bricks"},
        {pos: [4, 1, 4], state: "minecraft:cobblestone"},
        {pos: [4, 1, 5], state: "minecraft:cracked_stone_bricks"},
        {pos: [4, 1, 6], state: "minecraft:stone_bricks"},
        {pos: [5, 1, 0], state: "minecraft:cobblestone"},
        {pos: [5, 1, 1], state: "minecraft:cobblestone"},
        {pos: [5, 1, 2], state: "minecraft:stone_bricks"},
        {pos: [5, 1, 3], state: "minecraft:cracked_stone_bricks"},
        {pos: [5, 1, 4], state: "minecraft:cracked_stone_bricks"},
        {pos: [5, 1, 5], state: "minecraft:cobblestone"},
        {pos: [5, 1, 6], state: "minecraft:cobblestone"},
        {pos: [6, 1, 1], state: "minecraft:cobblestone"},
        {pos: [6, 1, 2], state: "minecraft:stone_bricks"},
        {pos: [6, 1, 4], state: "minecraft:stone_bricks"},
        {pos: [6, 1, 5], state: "minecraft:cobblestone"},
        {pos: [0, 2, 1], state: "minecraft:bricks"},
        {pos: [0, 2, 2], state: "minecraft:gravel"},
        {pos: [0, 2, 3], state: "minecraft:gravel"},
        {pos: [0, 2, 4], state: "minecraft:gravel"},
        {pos: [0, 2, 5], state: "minecraft:bricks"},
        {pos: [1, 2, 0], state: "minecraft:bricks"},
        {pos: [1, 2, 1], state: "minecraft:gravel"},
        {pos: [1, 2, 2], state: "minecraft:gravel"},
        {pos: [1, 2, 3], state: "minecraft:gravel"},
        {pos: [1, 2, 4], state: "minecraft:gravel"},
        {pos: [1, 2, 5], state: "minecraft:gravel"},
        {pos: [1, 2, 6], state: "minecraft:bricks"},
        {pos: [2, 2, 0], state: "minecraft:gravel"},
        {pos: [2, 2, 1], state: "minecraft:gravel"},
        {pos: [2, 2, 2], state: "minecraft:gravel"},
        {pos: [2, 2, 3], state: "minecraft:gravel"},
        {pos: [2, 2, 4], state: "minecraft:gravel"},
        {pos: [2, 2, 5], state: "minecraft:gravel"},
        {pos: [2, 2, 6], state: "minecraft:gravel"},
        {pos: [3, 2, 0], state: "minecraft:gravel"},
        {pos: [3, 2, 1], state: "minecraft:gravel"},
        {pos: [3, 2, 2], state: "minecraft:gravel"},
        {pos: [3, 2, 3], state: "minecraft:gravel"},
        {pos: [3, 2, 4], state: "minecraft:gravel"},
        {pos: [3, 2, 5], state: "minecraft:gravel"},
        {pos: [3, 2, 6], state: "minecraft:gravel"},
        {pos: [4, 2, 0], state: "minecraft:gravel"},
        {pos: [4, 2, 1], state: "minecraft:gravel"},
        {pos: [4, 2, 2], state: "minecraft:gravel"},
        {pos: [4, 2, 3], state: "minecraft:gravel"},
        {pos: [4, 2, 4], state: "minecraft:gravel"},
        {pos: [4, 2, 5], state: "minecraft:gravel"},
        {pos: [4, 2, 6], state: "minecraft:gravel"},
        {pos: [5, 2, 0], state: "minecraft:bricks"},
        {pos: [5, 2, 1], state: "minecraft:gravel"},
        {pos: [5, 2, 2], state: "minecraft:gravel"},
        {pos: [5, 2, 3], state: "minecraft:gravel"},
        {pos: [5, 2, 4], state: "minecraft:gravel"},
        {pos: [5, 2, 5], state: "minecraft:gravel"},
        {pos: [5, 2, 6], state: "minecraft:bricks"},
        {pos: [6, 2, 1], state: "minecraft:bricks"},
        {pos: [6, 2, 2], state: "minecraft:gravel"},
        {pos: [6, 2, 3], state: "minecraft:gravel"},
        {pos: [6, 2, 4], state: "minecraft:gravel"},
        {pos: [6, 2, 5], state: "minecraft:bricks"},
        {pos: [0, 3, 1], state: "minecraft:bricks"},
        {pos: [0, 3, 2], state: "minecraft:gravel"},
        {pos: [0, 3, 3], state: "minecraft:gravel"},
        {pos: [0, 3, 4], state: "minecraft:gravel"},
        {pos: [0, 3, 5], state: "minecraft:bricks"},
        {pos: [1, 3, 0], state: "minecraft:bricks"},
        {pos: [1, 3, 1], state: "minecraft:gravel"},
        {pos: [1, 3, 2], state: "minecraft:gravel"},
        {pos: [1, 3, 3], state: "minecraft:gravel"},
        {pos: [1, 3, 4], state: "minecraft:gravel"},
        {pos: [1, 3, 5], state: "minecraft:gravel"},
        {pos: [1, 3, 6], state: "minecraft:bricks"},
        {pos: [2, 3, 0], state: "minecraft:gravel"},
        {pos: [2, 3, 1], state: "minecraft:gravel"},
        {pos: [2, 3, 2], state: "minecraft:gravel"},
        {pos: [2, 3, 3], state: "minecraft:gravel"},
        {pos: [2, 3, 4], state: "minecraft:gravel"},
        {pos: [2, 3, 5], state: "minecraft:gravel"},
        {pos: [2, 3, 6], state: "minecraft:gravel"},
        {pos: [3, 3, 0], state: "minecraft:gravel"},
        {pos: [3, 3, 1], state: "minecraft:gravel"},
        {pos: [3, 3, 2], state: "minecraft:gravel"},
        {pos: [3, 3, 3], state: "minecraft:gravel"},
        {pos: [3, 3, 4], state: "minecraft:gravel"},
        {pos: [3, 3, 5], state: "minecraft:gravel"},
        {pos: [3, 3, 6], state: "minecraft:gravel"},
        {pos: [4, 3, 0], state: "minecraft:gravel"},
        {pos: [4, 3, 1], state: "minecraft:gravel"},
        {pos: [4, 3, 2], state: "minecraft:gravel"},
        {pos: [4, 3, 3], state: "minecraft:gravel"},
        {pos: [4, 3, 4], state: "minecraft:gravel"},
        {pos: [4, 3, 5], state: "minecraft:gravel"},
        {pos: [4, 3, 6], state: "minecraft:gravel"},
        {pos: [5, 3, 0], state: "minecraft:bricks"},
        {pos: [5, 3, 1], state: "minecraft:gravel"},
        {pos: [5, 3, 2], state: "minecraft:gravel"},
        {pos: [5, 3, 3], state: "minecraft:gravel"},
        {pos: [5, 3, 4], state: "minecraft:gravel"},
        {pos: [5, 3, 5], state: "minecraft:gravel"},
        {pos: [5, 3, 6], state: "minecraft:bricks"},
        {pos: [6, 3, 1], state: "minecraft:bricks"},
        {pos: [6, 3, 3], state: "minecraft:gravel"},
        {pos: [6, 3, 4], state: "minecraft:gravel"},
        {pos: [6, 3, 5], state: "minecraft:gravel"},
        {pos: [0, 4, 1], state: "minecraft:bricks"},
        {pos: [0, 4, 2], state: "minecraft:gravel"},
        {pos: [0, 4, 3], state: "minecraft:gravel"},
        {pos: [0, 4, 4], state: "minecraft:gravel"},
        {pos: [0, 4, 5], state: "minecraft:gravel"},
        {pos: [1, 4, 0], state: "minecraft:bricks"},
        {pos: [1, 4, 1], state: "minecraft:gravel"},
        {pos: [1, 4, 2], state: "minecraft:gravel"},
        {pos: [1, 4, 3], state: "minecraft:gravel"},
        {pos: [1, 4, 4], state: "minecraft:gravel"},
        {pos: [1, 4, 5], state: "minecraft:gravel"},
        {pos: [1, 4, 6], state: "minecraft:gravel"},
        {pos: [2, 4, 0], state: "minecraft:gravel"},
        {pos: [2, 4, 1], state: "minecraft:gravel"},
        {pos: [2, 4, 2], state: "minecraft:gravel"},
        {pos: [2, 4, 3], state: "minecraft:gravel"},
        {pos: [2, 4, 4], state: "minecraft:gravel"},
        {pos: [2, 4, 5], state: "minecraft:gravel"},
        {pos: [2, 4, 6], state: "minecraft:gravel"},
        {pos: [3, 4, 0], state: "minecraft:gravel"},
        {pos: [3, 4, 1], state: "minecraft:gravel"},
        {pos: [3, 4, 2], state: "minecraft:gravel"},
        {pos: [3, 4, 3], state: "minecraft:gravel"},
        {pos: [3, 4, 4], state: "minecraft:gravel"},
        {pos: [3, 4, 5], state: "minecraft:gravel"},
        {pos: [3, 4, 6], state: "minecraft:gravel"},
        {pos: [4, 4, 1], state: "minecraft:gravel"},
        {pos: [4, 4, 2], state: "minecraft:gravel"},
        {pos: [4, 4, 3], state: "minecraft:gravel"},
        {pos: [4, 4, 4], state: "minecraft:gravel"},
        {pos: [4, 4, 5], state: "minecraft:gravel"},
        {pos: [4, 4, 6], state: "minecraft:gravel"},
        {pos: [5, 4, 0], state: "minecraft:bricks"},
        {pos: [5, 4, 1], state: "minecraft:gravel"},
        {pos: [5, 4, 2], state: "minecraft:gravel"},
        {pos: [5, 4, 3], state: "minecraft:gravel"},
        {pos: [5, 4, 4], state: "minecraft:gravel"},
        {pos: [5, 4, 5], state: "minecraft:gravel"},
        {pos: [5, 4, 6], state: "minecraft:bricks"},
        {pos: [6, 4, 1], state: "minecraft:bricks"},
        {pos: [6, 4, 4], state: "minecraft:gravel"},
        {pos: [6, 4, 5], state: "minecraft:gravel"},
        {pos: [0, 5, 3], state: "minecraft:bricks"},
        {pos: [0, 5, 5], state: "minecraft:bricks"},
        {pos: [1, 5, 1], state: "minecraft:gravel"},
        {pos: [1, 5, 2], state: "minecraft:gravel"},
        {pos: [1, 5, 3], state: "minecraft:gravel"},
        {pos: [1, 5, 4], state: "minecraft:gravel"},
        {pos: [1, 5, 5], state: "minecraft:gravel"},
        {pos: [1, 5, 6], state: "minecraft:gravel"},
        {pos: [2, 5, 1], state: "minecraft:gravel"},
        {pos: [2, 5, 2], state: "minecraft:gravel"},
        {pos: [2, 5, 3], state: "minecraft:gravel"},
        {pos: [2, 5, 4], state: "minecraft:gravel"},
        {pos: [2, 5, 5], state: "minecraft:gravel"},
        {pos: [3, 5, 0], state: "minecraft:bricks"},
        {pos: [3, 5, 1], state: "minecraft:gravel"},
        {pos: [3, 5, 2], state: "minecraft:gravel"},
        {pos: [3, 5, 3], state: "minecraft:gravel"},
        {pos: [3, 5, 4], state: "minecraft:gravel"},
        {pos: [3, 5, 5], state: "minecraft:gravel"},
        {pos: [3, 5, 6], state: "minecraft:bricks"},
        {pos: [4, 5, 1], state: "minecraft:gravel"},
        {pos: [4, 5, 2], state: "minecraft:gravel"},
        {pos: [4, 5, 3], state: "minecraft:gravel"},
        {pos: [4, 5, 4], state: "minecraft:gravel"},
        {pos: [4, 5, 5], state: "minecraft:gravel"},
        {pos: [5, 5, 1], state: "minecraft:gravel"},
        {pos: [5, 5, 2], state: "minecraft:gravel"},
        {pos: [5, 5, 3], state: "minecraft:gravel"},
        {pos: [5, 5, 4], state: "minecraft:gravel"},
        {pos: [5, 5, 5], state: "minecraft:gravel"},
        {pos: [6, 5, 3], state: "minecraft:bricks"},
        {pos: [6, 5, 4], state: "minecraft:gravel"},
        {pos: [1, 6, 1], state: "minecraft:gravel"},
        {pos: [1, 6, 2], state: "minecraft:gravel"},
        {pos: [1, 6, 3], state: "minecraft:blue_terracotta"},
        {pos: [1, 6, 4], state: "minecraft:blue_terracotta"},
        {pos: [1, 6, 5], state: "minecraft:blue_terracotta"},
        {pos: [2, 6, 1], state: "minecraft:blue_terracotta"},
        {pos: [2, 6, 2], state: "minecraft:light_blue_glazed_terracotta{facing:south}"},
        {pos: [2, 6, 3], state: "minecraft:light_blue_glazed_terracotta{facing:east}"},
        {pos: [2, 6, 4], state: "minecraft:light_blue_glazed_terracotta{facing:north}"},
        {pos: [2, 6, 5], state: "minecraft:blue_terracotta"},
        {pos: [3, 6, 1], state: "minecraft:blue_terracotta"},
        {pos: [3, 6, 2], state: "minecraft:light_blue_glazed_terracotta{facing:west}"},
        {pos: [3, 6, 3], state: "minecraft:light_blue_glazed_terracotta{facing:south}"},
        {pos: [3, 6, 4], state: "minecraft:light_blue_glazed_terracotta{facing:east}"},
        {pos: [3, 6, 5], state: "minecraft:blue_terracotta"},
        {pos: [4, 6, 1], state: "minecraft:blue_terracotta"},
        {pos: [4, 6, 2], state: "minecraft:light_blue_glazed_terracotta{facing:north}"},
        {pos: [4, 6, 3], state: "minecraft:light_blue_glazed_terracotta{facing:east}"},
        {pos: [4, 6, 4], state: "minecraft:light_blue_glazed_terracotta{facing:south}"},
        {pos: [4, 6, 5], state: "minecraft:blue_terracotta"},
        {pos: [5, 6, 1], state: "minecraft:blue_terracotta"},
        {pos: [5, 6, 2], state: "minecraft:blue_terracotta"},
        {pos: [5, 6, 3], state: "minecraft:blue_terracotta"},
        {pos: [5, 6, 4], state: "minecraft:blue_terracotta"},
        {pos: [5, 6, 5], state: "minecraft:gravel"},
        {pos: [1, 7, 2], state: "minecraft:gravel"},
        {pos: [1, 7, 3], state: "minecraft:gravel"},
        {pos: [1, 7, 4], state: "minecraft:blue_terracotta"},
        {pos: [1, 7, 5], state: "minecraft:white_terracotta"},
        {pos: [2, 7, 1], state: "minecraft:blue_terracotta"},
        {pos: [2, 7, 2], state: "minecraft:gravel"},
        {pos: [2, 7, 3], state: "minecraft:gravel"},
        {pos: [2, 7, 4], state: "minecraft:gravel"},
        {pos: [2, 7, 5], state: "minecraft:blue_terracotta"},
        {pos: [3, 7, 1], state: "minecraft:blue_terracotta"},
        {pos: [3, 7, 2], state: "minecraft:gravel"},
        {pos: [3, 7, 3], state: "minecraft:gravel"},
        {pos: [3, 7, 4], state: "minecraft:gravel"},
        {pos: [3, 7, 5], state: "minecraft:blue_terracotta"},
        {pos: [4, 7, 1], state: "minecraft:blue_terracotta"},
        {pos: [4, 7, 2], state: "minecraft:gravel"},
        {pos: [4, 7, 3], state: "minecraft:gravel"},
        {pos: [4, 7, 4], state: "minecraft:gravel"},
        {pos: [4, 7, 5], state: "minecraft:blue_terracotta"},
        {pos: [5, 7, 1], state: "minecraft:white_terracotta"},
        {pos: [5, 7, 2], state: "minecraft:blue_terracotta"},
        {pos: [5, 7, 3], state: "minecraft:blue_terracotta"},
        {pos: [5, 7, 4], state: "minecraft:gravel"},
        {pos: [5, 7, 5], state: "minecraft:gravel"},
        {pos: [1, 8, 3], state: "minecraft:gravel"},
        {pos: [1, 8, 4], state: "minecraft:white_terracotta"},
        {pos: [1, 8, 5], state: "minecraft:blue_terracotta"},
        {pos: [2, 8, 1], state: "minecraft:white_terracotta"},
        {pos: [2, 8, 2], state: "minecraft:gravel"},
        {pos: [2, 8, 3], state: "minecraft:gravel"},
        {pos: [2, 8, 4], state: "minecraft:gravel"},
        {pos: [2, 8, 5], state: "minecraft:white_terracotta"},
        {pos: [3, 8, 1], state: "minecraft:white_terracotta"},
        {pos: [3, 8, 2], state: "minecraft:gravel"},
        {pos: [3, 8, 3], state: "minecraft:gravel"},
        {pos: [3, 8, 4], state: "minecraft:gravel"},
        {pos: [3, 8, 5], state: "minecraft:white_terracotta"},
        {pos: [4, 8, 1], state: "minecraft:white_terracotta"},
        {pos: [4, 8, 2], state: "minecraft:gravel"},
        {pos: [4, 8, 3], state: "minecraft:gravel"},
        {pos: [4, 8, 4], state: "minecraft:gravel"},
        {pos: [4, 8, 5], state: "minecraft:gravel"},
        {pos: [5, 8, 1], state: "minecraft:gravel"},
        {pos: [5, 8, 2], state: "minecraft:white_terracotta"},
        {pos: [5, 8, 3], state: "minecraft:gravel"},
        {pos: [5, 8, 4], state: "minecraft:gravel"},
        {pos: [5, 8, 5], state: "minecraft:gravel"},
        {pos: [1, 9, 1], state: "minecraft:white_terracotta"},
        {pos: [1, 9, 2], state: "minecraft:white_terracotta"},
        {pos: [1, 9, 4], state: "minecraft:white_terracotta"},
        {pos: [1, 9, 5], state: "minecraft:white_terracotta"},
        {pos: [2, 9, 1], state: "minecraft:white_terracotta"},
        {pos: [2, 9, 2], state: "minecraft:gravel"},
        {pos: [2, 9, 3], state: "minecraft:gravel"},
        {pos: [2, 9, 4], state: "minecraft:gravel"},
        {pos: [2, 9, 5], state: "minecraft:white_terracotta"},
        {pos: [3, 9, 2], state: "minecraft:gravel"},
        {pos: [3, 9, 3], state: "minecraft:gravel"},
        {pos: [3, 9, 4], state: "minecraft:gravel"},
        {pos: [4, 9, 1], state: "minecraft:white_terracotta"},
        {pos: [4, 9, 2], state: "minecraft:gravel"},
        {pos: [4, 9, 3], state: "minecraft:gravel"},
        {pos: [4, 9, 4], state: "minecraft:gravel"},
        {pos: [4, 9, 5], state: "minecraft:gravel"},
        {pos: [5, 9, 1], state: "minecraft:white_terracotta"},
        {pos: [5, 9, 2], state: "minecraft:white_terracotta"},
        {pos: [5, 9, 3], state: "minecraft:gravel"},
        {pos: [5, 9, 4], state: "minecraft:gravel"},
        {pos: [1, 10, 1], state: "minecraft:light_blue_glazed_terracotta{facing:east}"},
        {pos: [1, 10, 2], state: "minecraft:light_blue_glazed_terracotta{facing:south}"},
        {pos: [1, 10, 4], state: "minecraft:light_blue_glazed_terracotta{facing:west}"},
        {pos: [1, 10, 5], state: "minecraft:light_blue_glazed_terracotta{facing:north}"},
        {pos: [2, 10, 1], state: "minecraft:light_blue_glazed_terracotta{facing:north}"},
        {pos: [2, 10, 2], state: "minecraft:gravel"},
        {pos: [2, 10, 3], state: "minecraft:gravel"},
        {pos: [2, 10, 4], state: "minecraft:gravel"},
        {pos: [2, 10, 5], state: "minecraft:light_blue_glazed_terracotta{facing:east}"},
        {pos: [3, 10, 1], state: "minecraft:gravel"},
        {pos: [3, 10, 2], state: "minecraft:gravel"},
        {pos: [3, 10, 3], state: "minecraft:gravel"},
        {pos: [3, 10, 4], state: "minecraft:gravel"},
        {pos: [3, 10, 5], state: "minecraft:gravel"},
        {pos: [4, 10, 1], state: "minecraft:light_blue_glazed_terracotta{facing:west}"},
        {pos: [4, 10, 2], state: "minecraft:gravel"},
        {pos: [4, 10, 3], state: "minecraft:gravel"},
        {pos: [4, 10, 4], state: "minecraft:gravel"},
        {pos: [5, 10, 1], state: "minecraft:light_blue_glazed_terracotta{facing:north}"},
        {pos: [5, 10, 2], state: "minecraft:light_blue_glazed_terracotta{facing:east}"},
        {pos: [5, 10, 3], state: "minecraft:gravel"},
        {pos: [5, 10, 4], state: "minecraft:gravel"},
        {pos: [1, 11, 1], state: "minecraft:gravel"},
        {pos: [1, 11, 2], state: "minecraft:light_gray_terracotta"},
        {pos: [1, 11, 3], state: "minecraft:light_gray_terracotta"},
        {pos: [1, 11, 4], state: "minecraft:light_gray_terracotta"},
        {pos: [1, 11, 5], state: "minecraft:gravel"},
        {pos: [2, 11, 1], state: "minecraft:light_gray_terracotta"},
        {pos: [2, 11, 2], state: "minecraft:gravel"},
        {pos: [2, 11, 4], state: "minecraft:gravel"},
        {pos: [2, 11, 5], state: "minecraft:light_gray_terracotta"},
        {pos: [3, 11, 2], state: "minecraft:gravel"},
        {pos: [3, 11, 3], state: "minecraft:gravel"},
        {pos: [3, 11, 4], state: "minecraft:gravel"},
        {pos: [3, 11, 5], state: "minecraft:light_gray_terracotta"},
        {pos: [4, 11, 1], state: "minecraft:light_gray_terracotta"},
        {pos: [4, 11, 2], state: "minecraft:gravel"},
        {pos: [4, 11, 3], state: "minecraft:gravel"},
        {pos: [4, 11, 4], state: "minecraft:gravel"},
        {pos: [4, 11, 5], state: "minecraft:light_gray_terracotta"},
        {pos: [5, 11, 1], state: "minecraft:gravel"},
        {pos: [5, 11, 3], state: "minecraft:light_gray_terracotta"},
        {pos: [5, 11, 4], state: "minecraft:gravel"},
        {pos: [1, 12, 2], state: "minecraft:gravel"},
        {pos: [1, 12, 3], state: "minecraft:gravel"},
        {pos: [1, 12, 5], state: "minecraft:gravel"},
        {pos: [2, 12, 2], state: "minecraft:gravel"},
        {pos: [2, 12, 3], state: "minecraft:gravel"},
        {pos: [2, 12, 4], state: "minecraft:gravel"},
        {pos: [2, 12, 5], state: "minecraft:light_gray_terracotta"},
        {pos: [3, 12, 3], state: "minecraft:gravel"},
        {pos: [3, 12, 4], state: "minecraft:gravel"},
        {pos: [3, 12, 5], state: "minecraft:white_terracotta"},
        {pos: [4, 12, 1], state: "minecraft:light_gray_terracotta"},
        {pos: [4, 12, 2], state: "minecraft:gravel"},
        {pos: [4, 12, 3], state: "minecraft:gravel"},
        {pos: [4, 12, 4], state: "minecraft:gravel"},
        {pos: [4, 12, 5], state: "minecraft:light_gray_terracotta"},
        {pos: [5, 12, 2], state: "minecraft:light_gray_terracotta"},
        {pos: [5, 12, 3], state: "minecraft:white_terracotta"},
        {pos: [5, 12, 4], state: "minecraft:gravel"},
        {pos: [0, 5, 1], state: "minecraft:brick_stairs{half:bottom,waterlogged:false,shape:straight,facing:south}"},
        {pos: [0, 5, 2], state: "minecraft:brick_stairs{half:top,waterlogged:false,shape:straight,facing:north}"},
        {pos: [0, 5, 4], state: "minecraft:brick_stairs{half:top,waterlogged:false,shape:straight,facing:south}"},
        {pos: [1, 5, 0], state: "minecraft:brick_stairs{half:bottom,waterlogged:false,shape:straight,facing:east}"},
        {pos: [2, 5, 0], state: "minecraft:brick_stairs{half:top,waterlogged:false,shape:straight,facing:west}"},
        {pos: [2, 5, 6], state: "minecraft:brick_stairs{half:top,waterlogged:false,shape:straight,facing:west}"},
        {pos: [4, 5, 0], state: "minecraft:brick_stairs{half:top,waterlogged:false,shape:straight,facing:east}"},
        {pos: [4, 5, 6], state: "minecraft:brick_stairs{half:top,waterlogged:false,shape:straight,facing:east}"},
        {pos: [5, 5, 0], state: "minecraft:brick_stairs{half:bottom,waterlogged:false,shape:straight,facing:west}"},
        {pos: [5, 5, 6], state: "minecraft:brick_stairs{half:bottom,waterlogged:false,shape:straight,facing:west}"},
        {pos: [6, 5, 1], state: "minecraft:brick_stairs{half:bottom,waterlogged:false,shape:straight,facing:south}"},
        {pos: [6, 5, 2], state: "minecraft:brick_stairs{half:top,waterlogged:false,shape:straight,facing:north}"},
        {pos: [0, 6, 2], state: "minecraft:brick_slab{waterlogged:false,type:bottom}"},
        {pos: [0, 6, 3], state: "minecraft:brick_slab{waterlogged:false,type:bottom}"},
        {pos: [0, 6, 4], state: "minecraft:brick_slab{waterlogged:false,type:bottom}"},
        {pos: [2, 6, 0], state: "minecraft:brick_slab{waterlogged:false,type:bottom}"},
        {pos: [2, 6, 6], state: "minecraft:brick_slab{waterlogged:false,type:bottom}"},
        {pos: [3, 6, 0], state: "minecraft:brick_slab{waterlogged:false,type:bottom}"},
        {pos: [3, 6, 6], state: "minecraft:brick_slab{waterlogged:false,type:bottom}"},
        {pos: [4, 6, 0], state: "minecraft:brick_slab{waterlogged:false,type:bottom}"},
        {pos: [4, 6, 6], state: "minecraft:brick_slab{waterlogged:false,type:bottom}"},
        {pos: [6, 6, 2], state: "minecraft:brick_slab{waterlogged:false,type:bottom}"},
        {pos: [6, 6, 3], state: "minecraft:brick_slab{waterlogged:false,type:bottom}"},
        {pos: [1, 9, 3], state: "minecraft:brick_slab{waterlogged:false,type:bottom}"},
        {pos: [3, 9, 1], state: "minecraft:brick_slab{waterlogged:false,type:bottom}"},
        {pos: [3, 9, 5], state: "minecraft:brick_slab{waterlogged:false,type:bottom}"},
        {pos: [2, 11, 3], state: "minecraft:brick_slab{waterlogged:false,type:top}"},
        {pos: [3, 12, 2], state: "minecraft:brick_slab{waterlogged:false,type:top}"},
        {pos: [0, 1, 3], state: "minecraft:jigsaw{orientation:west_up}", nbt: {final_state: "minecraft:cobblestone", id: "minecraft:jigsaw", joint: "rollable", name: "minecraft:road_anchor", pool: "minecraft:trail_ruins/tower/additions", target: "minecraft:road_hall_anchor"}},
        {pos: [3, 1, 0], state: "minecraft:jigsaw{orientation:north_up}", nbt: {final_state: "minecraft:mud_bricks", id: "minecraft:jigsaw", joint: "rollable", name: "minecraft:road_connector", pool: "minecraft:trail_ruins/roads", target: "minecraft:long_road_end"}},
        {pos: [3, 1, 6], state: "minecraft:jigsaw{orientation:south_up}", nbt: {final_state: "minecraft:cobblestone", id: "minecraft:jigsaw", joint: "rollable", name: "minecraft:hall_road", pool: "minecraft:trail_ruins/roads", target: "minecraft:road_spacer"}},
        {pos: [6, 1, 3], state: "minecraft:jigsaw{orientation:east_up}", nbt: {final_state: "minecraft:cobblestone", id: "minecraft:jigsaw", joint: "rollable", name: "minecraft:road_anchor", pool: "minecraft:trail_ruins/tower/additions", target: "minecraft:large_hall_connector"}},
        {pos: [5, 12, 1], state: "minecraft:jigsaw{orientation:up_east}", nbt: {final_state: "minecraft:dirt", id: "minecraft:jigsaw", joint: "aligned", name: "minecraft:tower_bottom_4", pool: "minecraft:trail_ruins/tower/tower_top", target: "minecraft:tower_top_4"}}
    ],
    entities: [],
    palette: [
        "minecraft:cobblestone",
        "minecraft:cracked_stone_bricks",
        "minecraft:stone_bricks",
        "minecraft:bricks",
        "minecraft:gravel",
        "minecraft:blue_terracotta",
        "minecraft:light_blue_glazed_terracotta{facing:south}",
        "minecraft:light_blue_glazed_terracotta{facing:east}",
        "minecraft:light_blue_glazed_terracotta{facing:north}",
        "minecraft:light_blue_glazed_terracotta{facing:west}",
        "minecraft:white_terracotta",
        "minecraft:light_gray_terracotta",
        "minecraft:brick_stairs{half:bottom,waterlogged:false,shape:straight,facing:south}",
        "minecraft:brick_stairs{half:top,waterlogged:false,shape:straight,facing:north}",
        "minecraft:brick_stairs{half:top,waterlogged:false,shape:straight,facing:south}",
        "minecraft:brick_stairs{half:bottom,waterlogged:false,shape:straight,facing:east}",
        "minecraft:brick_stairs{half:top,waterlogged:false,shape:straight,facing:west}",
        "minecraft:brick_stairs{half:top,waterlogged:false,shape:straight,facing:east}",
        "minecraft:brick_stairs{half:bottom,waterlogged:false,shape:straight,facing:west}",
        "minecraft:brick_slab{waterlogged:false,type:bottom}",
        "minecraft:brick_slab{waterlogged:false,type:top}",
        "minecraft:jigsaw{orientation:west_up}",
        "minecraft:jigsaw{orientation:north_up}",
        "minecraft:jigsaw{orientation:south_up}",
        "minecraft:jigsaw{orientation:east_up}",
        "minecraft:jigsaw{orientation:up_east}"
    ]
}