{
    size: [7, 6, 8],
    data: [
        {pos: [0, 0, 0], state: "minecraft:blackstone"},
        {pos: [0, 0, 1], state: "minecraft:polished_blackstone_bricks"},
        {pos: [0, 0, 2], state: "minecraft:polished_blackstone_bricks"},
        {pos: [0, 0, 5], state: "minecraft:polished_blackstone_bricks"},
        {pos: [0, 0, 6], state: "minecraft:polished_blackstone_bricks"},
        {pos: [0, 0, 7], state: "minecraft:polished_blackstone_bricks"},
        {pos: [1, 0, 0], state: "minecraft:polished_blackstone_bricks"},
        {pos: [1, 0, 1], state: "minecraft:polished_blackstone_bricks"},
        {pos: [1, 0, 2], state: "minecraft:polished_blackstone_bricks"},
        {pos: [1, 0, 5], state: "minecraft:polished_blackstone_bricks"},
        {pos: [1, 0, 6], state: "minecraft:polished_blackstone_bricks"},
        {pos: [1, 0, 7], state: "minecraft:polished_blackstone_bricks"},
        {pos: [2, 0, 0], state: "minecraft:polished_blackstone_bricks"},
        {pos: [2, 0, 1], state: "minecraft:polished_blackstone_bricks"},
        {pos: [2, 0, 2], state: "minecraft:polished_blackstone_bricks"},
        {pos: [2, 0, 5], state: "minecraft:polished_blackstone_bricks"},
        {pos: [2, 0, 6], state: "minecraft:polished_blackstone_bricks"},
        {pos: [2, 0, 7], state: "minecraft:polished_blackstone_bricks"},
        {pos: [5, 0, 0], state: "minecraft:polished_blackstone_bricks"},
        {pos: [5, 0, 1], state: "minecraft:polished_blackstone_bricks"},
        {pos: [5, 0, 2], state: "minecraft:polished_blackstone_bricks"},
        {pos: [5, 0, 3], state: "minecraft:polished_blackstone_bricks"},
        {pos: [5, 0, 4], state: "minecraft:polished_blackstone_bricks"},
        {pos: [5, 0, 5], state: "minecraft:polished_blackstone_bricks"},
        {pos: [5, 0, 6], state: "minecraft:polished_blackstone_bricks"},
        {pos: [5, 0, 7], state: "minecraft:polished_blackstone_bricks"},
        {pos: [6, 0, 0], state: "minecraft:polished_blackstone_bricks"},
        {pos: [6, 0, 1], state: "minecraft:polished_blackstone_bricks"},
        {pos: [6, 0, 2], state: "minecraft:polished_blackstone_bricks"},
        {pos: [6, 0, 3], state: "minecraft:polished_blackstone_bricks"},
        {pos: [6, 0, 4], state: "minecraft:polished_blackstone_bricks"},
        {pos: [6, 0, 5], state: "minecraft:polished_blackstone_bricks"},
        {pos: [6, 0, 6], state: "minecraft:polished_blackstone_bricks"},
        {pos: [6, 0, 7], state: "minecraft:polished_blackstone_bricks"},
        {pos: [0, 1, 1], state: "minecraft:polished_blackstone_bricks"},
        {pos: [0, 1, 2], state: "minecraft:polished_blackstone_bricks"},
        {pos: [0, 1, 7], state: "minecraft:polished_blackstone_bricks"},
        {pos: [1, 1, 1], state: "minecraft:polished_blackstone_bricks"},
        {pos: [1, 1, 2], state: "minecraft:polished_blackstone_bricks"},
        {pos: [1, 1, 7], state: "minecraft:polished_blackstone_bricks"},
        {pos: [2, 1, 6], state: "minecraft:polished_blackstone_bricks"},
        {pos: [2, 1, 7], state: "minecraft:polished_blackstone_bricks"},
        {pos: [5, 1, 2], state: "minecraft:polished_blackstone_bricks"},
        {pos: [5, 1, 3], state: "minecraft:polished_blackstone_bricks"},
        {pos: [5, 1, 5], state: "minecraft:polished_blackstone_bricks"},
        {pos: [5, 1, 7], state: "minecraft:polished_blackstone_bricks"},
        {pos: [6, 1, 2], state: "minecraft:polished_blackstone_bricks"},
        {pos: [6, 1, 3], state: "minecraft:polished_blackstone_bricks"},
        {pos: [6, 1, 4], state: "minecraft:polished_blackstone_bricks"},
        {pos: [6, 1, 5], state: "minecraft:polished_blackstone_bricks"},
        {pos: [6, 1, 6], state: "minecraft:polished_blackstone_bricks"},
        {pos: [6, 1, 7], state: "minecraft:polished_blackstone_bricks"},
        {pos: [0, 2, 0], state: "minecraft:blackstone"},
        {pos: [0, 2, 2], state: "minecraft:polished_blackstone_bricks"},
        {pos: [0, 2, 3], state: "minecraft:blackstone"},
        {pos: [1, 2, 0], state: "minecraft:polished_blackstone_bricks"},
        {pos: [1, 2, 1], state: "minecraft:polished_blackstone_bricks"},
        {pos: [1, 2, 2], state: "minecraft:polished_blackstone_bricks"},
        {pos: [2, 2, 1], state: "minecraft:polished_blackstone_bricks"},
        {pos: [2, 2, 2], state: "minecraft:polished_blackstone_bricks"},
        {pos: [2, 2, 3], state: "minecraft:polished_blackstone_bricks"},
        {pos: [2, 2, 4], state: "minecraft:polished_blackstone_bricks"},
        {pos: [2, 2, 6], state: "minecraft:polished_blackstone_bricks"},
        {pos: [2, 2, 7], state: "minecraft:polished_blackstone_bricks"},
        {pos: [3, 2, 1], state: "minecraft:polished_blackstone_bricks"},
        {pos: [3, 2, 2], state: "minecraft:polished_blackstone_bricks"},
        {pos: [3, 2, 5], state: "minecraft:gilded_blackstone"},
        {pos: [3, 2, 6], state: "minecraft:polished_blackstone_bricks"},
        {pos: [3, 2, 7], state: "minecraft:polished_blackstone_bricks"},
        {pos: [4, 2, 5], state: "minecraft:polished_blackstone_bricks"},
        {pos: [4, 2, 6], state: "minecraft:polished_blackstone_bricks"},
        {pos: [4, 2, 7], state: "minecraft:polished_blackstone_bricks"},
        {pos: [5, 2, 7], state: "minecraft:polished_blackstone_bricks"},
        {pos: [6, 2, 3], state: "minecraft:polished_blackstone_bricks"},
        {pos: [6, 2, 7], state: "minecraft:polished_blackstone_bricks"},
        {pos: [1, 3, 1], state: "minecraft:polished_blackstone_bricks"},
        {pos: [2, 3, 0], state: "minecraft:polished_blackstone_bricks"},
        {pos: [2, 3, 1], state: "minecraft:gold_block"},
        {pos: [2, 3, 2], state: "minecraft:gold_block"},
        {pos: [3, 3, 1], state: "minecraft:gold_block"},
        {pos: [3, 3, 2], state: "minecraft:gold_block"},
        {pos: [3, 3, 6], state: "minecraft:gold_block"},
        {pos: [4, 3, 5], state: "minecraft:gold_block"},
        {pos: [4, 3, 6], state: "minecraft:gold_block"},
        {pos: [2, 4, 0], state: "minecraft:gold_block"},
        {pos: [2, 4, 1], state: "minecraft:gold_block"},
        {pos: [2, 4, 2], state: "minecraft:gold_block"},
        {pos: [3, 4, 0], state: "minecraft:blackstone"},
        {pos: [3, 4, 1], state: "minecraft:gold_block"},
        {pos: [3, 4, 6], state: "minecraft:gold_block"},
        {pos: [2, 5, 1], state: "minecraft:gold_block"},
        {pos: [1, 1, 6], state: "minecraft:jigsaw{orientation:up_north}", nbt: {final_state: "minecraft:blackstone", id: "minecraft:jigsaw", joint: "rollable", name: "minecraft:empty", pool: "minecraft:bastion/mobs/piglin_melee", target: "minecraft:melee_connector"}},
        {pos: [6, 2, 2], state: "minecraft:jigsaw{orientation:east_up}", nbt: {final_state: "minecraft:polished_blackstone_bricks", id: "minecraft:jigsaw", joint: "rollable", name: "minecraft:treasure", pool: "minecraft:empty", target: "minecraft:empty"}},
        {pos: [3, 3, 5], state: "minecraft:chest{waterlogged:false,facing:west,type:single}", nbt: {LootTable: "minecraft:chests/bastion_treasure", id: "minecraft:chest"}}
    ],
    entities: [],
    palette: [
        "minecraft:blackstone",
        "minecraft:polished_blackstone_bricks",
        "minecraft:gilded_blackstone",
        "minecraft:gold_block",
        "minecraft:jigsaw{orientation:up_north}",
        "minecraft:jigsaw{orientation:east_up}",
        "minecraft:chest{waterlogged:false,facing:west,type:single}"
    ]
}