{
    size: [5, 5, 5],
    data: [
        {pos: [0, 0, 0], state: "minecraft:cobblestone"},
        {pos: [0, 0, 1], state: "minecraft:cobblestone"},
        {pos: [0, 0, 2], state: "minecraft:cobblestone"},
        {pos: [0, 0, 3], state: "minecraft:cobblestone"},
        {pos: [0, 0, 4], state: "minecraft:cobblestone"},
        {pos: [1, 0, 0], state: "minecraft:cobblestone"},
        {pos: [1, 0, 1], state: "minecraft:cobblestone"},
        {pos: [1, 0, 2], state: "minecraft:cobblestone"},
        {pos: [1, 0, 3], state: "minecraft:cobblestone"},
        {pos: [1, 0, 4], state: "minecraft:cobblestone"},
        {pos: [2, 0, 0], state: "minecraft:cobblestone"},
        {pos: [2, 0, 1], state: "minecraft:cobblestone"},
        {pos: [2, 0, 2], state: "minecraft:cobblestone"},
        {pos: [2, 0, 3], state: "minecraft:cobblestone"},
        {pos: [2, 0, 4], state: "minecraft:cobblestone"},
        {pos: [3, 0, 0], state: "minecraft:cobblestone"},
        {pos: [3, 0, 1], state: "minecraft:cobblestone"},
        {pos: [3, 0, 2], state: "minecraft:cobblestone"},
        {pos: [3, 0, 3], state: "minecraft:cobblestone"},
        {pos: [3, 0, 4], state: "minecraft:cobblestone"},
        {pos: [4, 0, 0], state: "minecraft:cobblestone"},
        {pos: [4, 0, 1], state: "minecraft:cobblestone"},
        {pos: [4, 0, 2], state: "minecraft:cobblestone"},
        {pos: [4, 0, 3], state: "minecraft:cobblestone"},
        {pos: [4, 0, 4], state: "minecraft:cobblestone"},
        {pos: [0, 1, 0], state: "minecraft:cobblestone"},
        {pos: [0, 1, 1], state: "minecraft:cobblestone"},
        {pos: [0, 1, 2], state: "minecraft:cobblestone"},
        {pos: [0, 1, 3], state: "minecraft:cobblestone"},
        {pos: [0, 1, 4], state: "minecraft:cobblestone"},
        {pos: [1, 1, 0], state: "minecraft:cobblestone"},
        {pos: [1, 1, 1], state: "minecraft:cobblestone"},
        {pos: [1, 1, 2], state: "minecraft:cobblestone"},
        {pos: [1, 1, 3], state: "minecraft:cobblestone"},
        {pos: [1, 1, 4], state: "minecraft:cobblestone"},
        {pos: [2, 1, 0], state: "minecraft:cobblestone"},
        {pos: [2, 1, 1], state: "minecraft:coal_block"},
        {pos: [2, 1, 2], state: "minecraft:cobblestone"},
        {pos: [2, 1, 3], state: "minecraft:coal_block"},
        {pos: [2, 1, 4], state: "minecraft:cobblestone"},
        {pos: [3, 1, 0], state: "minecraft:cobblestone"},
        {pos: [3, 1, 1], state: "minecraft:cobblestone"},
        {pos: [3, 1, 2], state: "minecraft:cobblestone"},
        {pos: [3, 1, 3], state: "minecraft:cobblestone"},
        {pos: [3, 1, 4], state: "minecraft:cobblestone"},
        {pos: [4, 1, 0], state: "minecraft:cobblestone"},
        {pos: [4, 1, 1], state: "minecraft:cobblestone"},
        {pos: [4, 1, 2], state: "minecraft:cobblestone"},
        {pos: [4, 1, 3], state: "minecraft:cobblestone"},
        {pos: [4, 1, 4], state: "minecraft:cobblestone"},
        {pos: [0, 2, 0], state: "minecraft:gravel"},
        {pos: [0, 2, 1], state: "minecraft:gravel"},
        {pos: [0, 2, 2], state: "minecraft:gravel"},
        {pos: [0, 2, 3], state: "minecraft:gravel"},
        {pos: [1, 2, 2], state: "minecraft:gravel"},
        {pos: [1, 2, 4], state: "minecraft:gravel"},
        {pos: [2, 2, 1], state: "minecraft:gravel"},
        {pos: [2, 2, 2], state: "minecraft:gravel"},
        {pos: [2, 2, 3], state: "minecraft:gravel"},
        {pos: [2, 2, 4], state: "minecraft:gravel"},
        {pos: [3, 2, 2], state: "minecraft:gravel"},
        {pos: [3, 2, 4], state: "minecraft:gravel"},
        {pos: [4, 2, 0], state: "minecraft:gravel"},
        {pos: [4, 2, 1], state: "minecraft:gravel"},
        {pos: [4, 2, 2], state: "minecraft:gravel"},
        {pos: [4, 2, 3], state: "minecraft:gravel"},
        {pos: [0, 3, 2], state: "minecraft:gravel"},
        {pos: [1, 3, 1], state: "minecraft:gravel"},
        {pos: [1, 3, 2], state: "minecraft:gravel"},
        {pos: [1, 3, 3], state: "minecraft:gravel"},
        {pos: [2, 3, 1], state: "minecraft:gravel"},
        {pos: [2, 3, 2], state: "minecraft:gravel"},
        {pos: [2, 3, 3], state: "minecraft:gravel"},
        {pos: [3, 3, 1], state: "minecraft:gravel"},
        {pos: [3, 3, 2], state: "minecraft:gravel"},
        {pos: [3, 3, 3], state: "minecraft:gravel"},
        {pos: [4, 3, 1], state: "minecraft:gravel"},
        {pos: [4, 3, 2], state: "minecraft:gravel"},
        {pos: [1, 4, 3], state: "minecraft:gravel"},
        {pos: [2, 4, 2], state: "minecraft:gravel"},
        {pos: [1, 2, 1], state: "minecraft:brick_stairs{half:bottom,waterlogged:false,shape:straight,facing:east}"},
        {pos: [1, 2, 3], state: "minecraft:brick_stairs{half:bottom,waterlogged:false,shape:straight,facing:east}"},
        {pos: [3, 2, 1], state: "minecraft:brick_stairs{half:bottom,waterlogged:false,shape:straight,facing:west}"},
        {pos: [3, 2, 3], state: "minecraft:brick_stairs{half:bottom,waterlogged:false,shape:straight,facing:west}"},
        {pos: [2, 2, 0], state: "minecraft:jigsaw{orientation:north_up}", nbt: {final_state: "minecraft:red_terracotta", id: "minecraft:jigsaw", joint: "rollable", name: "minecraft:decor_anchor", pool: "minecraft:trail_ruins/roads", target: "minecraft:road_anchor"}}
    ],
    entities: [],
    palette: [
        "minecraft:cobblestone",
        "minecraft:coal_block",
        "minecraft:gravel",
        "minecraft:brick_stairs{half:bottom,waterlogged:false,shape:straight,facing:east}",
        "minecraft:brick_stairs{half:bottom,waterlogged:false,shape:straight,facing:west}",
        "minecraft:jigsaw{orientation:north_up}"
    ]
}