{
    size: [7, 7, 7],
    data: [
        {pos: [1, 0, 1], state: "minecraft:oak_log{axis:y}"},
        {pos: [1, 0, 2], state: "minecraft:cobblestone"},
        {pos: [1, 0, 3], state: "minecraft:cobblestone"},
        {pos: [1, 0, 4], state: "minecraft:cobblestone"},
        {pos: [1, 0, 5], state: "minecraft:oak_log{axis:y}"},
        {pos: [2, 0, 1], state: "minecraft:cobblestone"},
        {pos: [2, 0, 2], state: "minecraft:oak_planks"},
        {pos: [2, 0, 3], state: "minecraft:oak_planks"},
        {pos: [2, 0, 4], state: "minecraft:oak_planks"},
        {pos: [2, 0, 5], state: "minecraft:cobblestone"},
        {pos: [3, 0, 1], state: "minecraft:cobblestone"},
        {pos: [3, 0, 2], state: "minecraft:oak_planks"},
        {pos: [3, 0, 4], state: "minecraft:oak_planks"},
        {pos: [3, 0, 5], state: "minecraft:cobblestone"},
        {pos: [4, 0, 1], state: "minecraft:cobblestone"},
        {pos: [4, 0, 2], state: "minecraft:oak_planks"},
        {pos: [4, 0, 3], state: "minecraft:oak_planks"},
        {pos: [4, 0, 4], state: "minecraft:oak_planks"},
        {pos: [4, 0, 5], state: "minecraft:cobblestone"},
        {pos: [5, 0, 1], state: "minecraft:oak_log{axis:y}"},
        {pos: [5, 0, 2], state: "minecraft:cobblestone"},
        {pos: [5, 0, 3], state: "minecraft:cobblestone"},
        {pos: [5, 0, 4], state: "minecraft:cobblestone"},
        {pos: [5, 0, 5], state: "minecraft:oak_log{axis:y}"},
        {pos: [1, 1, 1], state: "minecraft:oak_log{axis:y}"},
        {pos: [1, 1, 2], state: "minecraft:cobblestone"},
        {pos: [1, 1, 4], state: "minecraft:cobblestone"},
        {pos: [1, 1, 5], state: "minecraft:oak_log{axis:y}"},
        {pos: [2, 1, 1], state: "minecraft:cobblestone"},
        {pos: [2, 1, 5], state: "minecraft:cobblestone"},
        {pos: [3, 1, 1], state: "minecraft:cobblestone"},
        {pos: [3, 1, 5], state: "minecraft:cobblestone"},
        {pos: [4, 1, 1], state: "minecraft:cobblestone"},
        {pos: [4, 1, 5], state: "minecraft:cobblestone"},
        {pos: [5, 1, 1], state: "minecraft:oak_log{axis:y}"},
        {pos: [5, 1, 2], state: "minecraft:cobblestone"},
        {pos: [5, 1, 3], state: "minecraft:cobblestone"},
        {pos: [5, 1, 4], state: "minecraft:cobblestone"},
        {pos: [5, 1, 5], state: "minecraft:oak_log{axis:y}"},
        {pos: [1, 2, 1], state: "minecraft:oak_log{axis:y}"},
        {pos: [1, 2, 2], state: "minecraft:cobblestone"},
        {pos: [1, 2, 4], state: "minecraft:cobblestone"},
        {pos: [1, 2, 5], state: "minecraft:oak_log{axis:y}"},
        {pos: [2, 2, 1], state: "minecraft:oak_log{axis:x}"},
        {pos: [2, 2, 5], state: "minecraft:oak_log{axis:x}"},
        {pos: [4, 2, 1], state: "minecraft:oak_log{axis:x}"},
        {pos: [4, 2, 5], state: "minecraft:oak_log{axis:x}"},
        {pos: [5, 2, 1], state: "minecraft:oak_log{axis:y}"},
        {pos: [5, 2, 2], state: "minecraft:cobblestone"},
        {pos: [5, 2, 4], state: "minecraft:cobblestone"},
        {pos: [5, 2, 5], state: "minecraft:oak_log{axis:y}"},
        {pos: [1, 3, 1], state: "minecraft:oak_log{axis:y}"},
        {pos: [1, 3, 2], state: "minecraft:cobblestone"},
        {pos: [1, 3, 3], state: "minecraft:cobblestone"},
        {pos: [1, 3, 4], state: "minecraft:cobblestone"},
        {pos: [1, 3, 5], state: "minecraft:oak_log{axis:y}"},
        {pos: [2, 3, 1], state: "minecraft:cobblestone"},
        {pos: [2, 3, 5], state: "minecraft:cobblestone"},
        {pos: [3, 3, 1], state: "minecraft:cobblestone"},
        {pos: [3, 3, 5], state: "minecraft:cobblestone"},
        {pos: [4, 3, 1], state: "minecraft:cobblestone"},
        {pos: [4, 3, 5], state: "minecraft:cobblestone"},
        {pos: [5, 3, 1], state: "minecraft:oak_log{axis:y}"},
        {pos: [5, 3, 2], state: "minecraft:cobblestone"},
        {pos: [5, 3, 3], state: "minecraft:cobblestone"},
        {pos: [5, 3, 4], state: "minecraft:cobblestone"},
        {pos: [5, 3, 5], state: "minecraft:oak_log{axis:y}"},
        {pos: [1, 4, 1], state: "minecraft:oak_log{axis:y}"},
        {pos: [1, 4, 2], state: "minecraft:oak_log{axis:z}"},
        {pos: [1, 4, 3], state: "minecraft:oak_log{axis:z}"},
        {pos: [1, 4, 4], state: "minecraft:oak_log{axis:z}"},
        {pos: [1, 4, 5], state: "minecraft:oak_log{axis:y}"},
        {pos: [2, 4, 1], state: "minecraft:oak_planks"},
        {pos: [2, 4, 5], state: "minecraft:oak_planks"},
        {pos: [3, 4, 1], state: "minecraft:oak_planks"},
        {pos: [3, 4, 5], state: "minecraft:oak_planks"},
        {pos: [4, 4, 1], state: "minecraft:oak_planks"},
        {pos: [4, 4, 5], state: "minecraft:oak_planks"},
        {pos: [5, 4, 1], state: "minecraft:oak_log{axis:y}"},
        {pos: [5, 4, 2], state: "minecraft:oak_log{axis:z}"},
        {pos: [5, 4, 3], state: "minecraft:oak_log{axis:z}"},
        {pos: [5, 4, 4], state: "minecraft:oak_log{axis:z}"},
        {pos: [5, 4, 5], state: "minecraft:oak_log{axis:y}"},
        {pos: [1, 5, 2], state: "minecraft:cobblestone"},
        {pos: [1, 5, 3], state: "minecraft:cobblestone"},
        {pos: [1, 5, 4], state: "minecraft:cobblestone"},
        {pos: [2, 5, 2], state: "minecraft:oak_planks"},
        {pos: [2, 5, 3], state: "minecraft:oak_planks"},
        {pos: [2, 5, 4], state: "minecraft:oak_planks"},
        {pos: [3, 5, 2], state: "minecraft:oak_planks"},
        {pos: [3, 5, 4], state: "minecraft:oak_planks"},
        {pos: [4, 5, 2], state: "minecraft:oak_planks"},
        {pos: [4, 5, 3], state: "minecraft:oak_planks"},
        {pos: [4, 5, 4], state: "minecraft:oak_planks"},
        {pos: [5, 5, 2], state: "minecraft:cobblestone"},
        {pos: [5, 5, 3], state: "minecraft:cobblestone"},
        {pos: [5, 5, 4], state: "minecraft:cobblestone"},
        {pos: [0, 6, 3], state: "minecraft:oak_planks"},
        {pos: [1, 6, 3], state: "minecraft:oak_planks"},
        {pos: [2, 6, 3], state: "minecraft:oak_planks"},
        {pos: [3, 6, 3], state: "minecraft:oak_planks"},
        {pos: [4, 6, 3], state: "minecraft:oak_planks"},
        {pos: [5, 6, 3], state: "minecraft:oak_planks"},
        {pos: [6, 6, 3], state: "minecraft:oak_planks"},
        {pos: [0, 0, 0], state: "minecraft:short_grass"},
        {pos: [0, 0, 1], state: "minecraft:poppy"},
        {pos: [0, 0, 2], state: "minecraft:air"},
        {pos: [0, 0, 4], state: "minecraft:short_grass"},
        {pos: [0, 0, 5], state: "minecraft:tall_grass{half:lower}"},
        {pos: [0, 0, 6], state: "minecraft:tall_grass{half:lower}"},
        {pos: [1, 0, 0], state: "minecraft:tall_grass{half:lower}"},
        {pos: [1, 0, 6], state: "minecraft:short_grass"},
        {pos: [2, 0, 0], state: "minecraft:short_grass"},
        {pos: [2, 0, 6], state: "minecraft:short_grass"},
        {pos: [3, 0, 0], state: "minecraft:air"},
        {pos: [3, 0, 6], state: "minecraft:air"},
        {pos: [4, 0, 0], state: "minecraft:air"},
        {pos: [4, 0, 6], state: "minecraft:air"},
        {pos: [5, 0, 0], state: "minecraft:air"},
        {pos: [5, 0, 6], state: "minecraft:air"},
        {pos: [6, 0, 0], state: "minecraft:air"},
        {pos: [6, 0, 1], state: "minecraft:air"},
        {pos: [6, 0, 2], state: "minecraft:air"},
        {pos: [6, 0, 3], state: "minecraft:air"},
        {pos: [6, 0, 4], state: "minecraft:air"},
        {pos: [6, 0, 5], state: "minecraft:air"},
        {pos: [6, 0, 6], state: "minecraft:air"},
        {pos: [0, 1, 0], state: "minecraft:air"},
        {pos: [0, 1, 1], state: "minecraft:air"},
        {pos: [0, 1, 2], state: "minecraft:air"},
        {pos: [0, 1, 3], state: "minecraft:air"},
        {pos: [0, 1, 4], state: "minecraft:air"},
        {pos: [0, 1, 5], state: "minecraft:tall_grass{half:upper}"},
        {pos: [0, 1, 6], state: "minecraft:tall_grass{half:upper}"},
        {pos: [1, 1, 0], state: "minecraft:tall_grass{half:upper}"},
        {pos: [1, 1, 3], state: "minecraft:oak_door{hinge:right,half:lower,powered:false,facing:east,open:false}"},
        {pos: [1, 1, 6], state: "minecraft:air"},
        {pos: [2, 1, 0], state: "minecraft:air"},
        {pos: [2, 1, 2], state: "minecraft:air"},
        {pos: [2, 1, 3], state: "minecraft:air"},
        {pos: [2, 1, 4], state: "minecraft:cobblestone_stairs{half:bottom,waterlogged:false,shape:straight,facing:south}"},
        {pos: [2, 1, 6], state: "minecraft:air"},
        {pos: [3, 1, 0], state: "minecraft:air"},
        {pos: [3, 1, 3], state: "minecraft:air"},
        {pos: [3, 1, 4], state: "minecraft:cobblestone_stairs{half:bottom,waterlogged:false,shape:straight,facing:south}"},
        {pos: [3, 1, 6], state: "minecraft:air"},
        {pos: [4, 1, 0], state: "minecraft:air"},
        {pos: [4, 1, 3], state: "minecraft:air"},
        {pos: [4, 1, 4], state: "minecraft:cobblestone_stairs{half:bottom,waterlogged:false,shape:straight,facing:south}"},
        {pos: [4, 1, 6], state: "minecraft:air"},
        {pos: [5, 1, 0], state: "minecraft:air"},
        {pos: [5, 1, 6], state: "minecraft:air"},
        {pos: [6, 1, 0], state: "minecraft:air"},
        {pos: [6, 1, 1], state: "minecraft:air"},
        {pos: [6, 1, 2], state: "minecraft:air"},
        {pos: [6, 1, 3], state: "minecraft:air"},
        {pos: [6, 1, 4], state: "minecraft:air"},
        {pos: [6, 1, 5], state: "minecraft:air"},
        {pos: [6, 1, 6], state: "minecraft:air"},
        {pos: [0, 2, 0], state: "minecraft:air"},
        {pos: [0, 2, 1], state: "minecraft:air"},
        {pos: [0, 2, 2], state: "minecraft:air"},
        {pos: [0, 2, 3], state: "minecraft:air"},
        {pos: [0, 2, 4], state: "minecraft:air"},
        {pos: [0, 2, 5], state: "minecraft:air"},
        {pos: [0, 2, 6], state: "minecraft:air"},
        {pos: [1, 2, 0], state: "minecraft:air"},
        {pos: [1, 2, 3], state: "minecraft:oak_door{hinge:right,half:upper,powered:false,facing:east,open:false}"},
        {pos: [1, 2, 6], state: "minecraft:air"},
        {pos: [2, 2, 0], state: "minecraft:air"},
        {pos: [2, 2, 2], state: "minecraft:air"},
        {pos: [2, 2, 3], state: "minecraft:air"},
        {pos: [2, 2, 4], state: "minecraft:air"},
        {pos: [2, 2, 6], state: "minecraft:air"},
        {pos: [3, 2, 0], state: "minecraft:air"},
        {pos: [3, 2, 1], state: "minecraft:glass_pane{east:true,waterlogged:false,south:false,north:false,west:true}"},
        {pos: [3, 2, 2], state: "minecraft:air"},
        {pos: [3, 2, 3], state: "minecraft:air"},
        {pos: [3, 2, 4], state: "minecraft:air"},
        {pos: [3, 2, 5], state: "minecraft:glass_pane{east:true,waterlogged:false,south:false,north:false,west:true}"},
        {pos: [3, 2, 6], state: "minecraft:air"},
        {pos: [4, 2, 0], state: "minecraft:air"},
        {pos: [4, 2, 2], state: "minecraft:air"},
        {pos: [4, 2, 3], state: "minecraft:air"},
        {pos: [4, 2, 4], state: "minecraft:air"},
        {pos: [4, 2, 6], state: "minecraft:air"},
        {pos: [5, 2, 0], state: "minecraft:air"},
        {pos: [5, 2, 3], state: "minecraft:glass_pane{east:false,waterlogged:false,south:true,north:true,west:false}"},
        {pos: [5, 2, 6], state: "minecraft:air"},
        {pos: [6, 2, 0], state: "minecraft:air"},
        {pos: [6, 2, 1], state: "minecraft:air"},
        {pos: [6, 2, 2], state: "minecraft:air"},
        {pos: [6, 2, 3], state: "minecraft:air"},
        {pos: [6, 2, 4], state: "minecraft:air"},
        {pos: [6, 2, 5], state: "minecraft:air"},
        {pos: [6, 2, 6], state: "minecraft:air"},
        {pos: [0, 3, 0], state: "minecraft:air"},
        {pos: [0, 3, 1], state: "minecraft:air"},
        {pos: [0, 3, 2], state: "minecraft:air"},
        {pos: [0, 3, 3], state: "minecraft:air"},
        {pos: [0, 3, 4], state: "minecraft:air"},
        {pos: [0, 3, 5], state: "minecraft:air"},
        {pos: [0, 3, 6], state: "minecraft:air"},
        {pos: [1, 3, 0], state: "minecraft:air"},
        {pos: [1, 3, 6], state: "minecraft:air"},
        {pos: [2, 3, 0], state: "minecraft:air"},
        {pos: [2, 3, 2], state: "minecraft:air"},
        {pos: [2, 3, 3], state: "minecraft:air"},
        {pos: [2, 3, 4], state: "minecraft:air"},
        {pos: [2, 3, 6], state: "minecraft:air"},
        {pos: [3, 3, 0], state: "minecraft:air"},
        {pos: [3, 3, 2], state: "minecraft:air"},
        {pos: [3, 3, 3], state: "minecraft:air"},
        {pos: [3, 3, 4], state: "minecraft:air"},
        {pos: [3, 3, 6], state: "minecraft:air"},
        {pos: [4, 3, 0], state: "minecraft:air"},
        {pos: [4, 3, 2], state: "minecraft:air"},
        {pos: [4, 3, 3], state: "minecraft:wall_torch{facing:west}"},
        {pos: [4, 3, 4], state: "minecraft:air"},
        {pos: [4, 3, 6], state: "minecraft:air"},
        {pos: [5, 3, 0], state: "minecraft:air"},
        {pos: [5, 3, 6], state: "minecraft:air"},
        {pos: [6, 3, 0], state: "minecraft:air"},
        {pos: [6, 3, 1], state: "minecraft:air"},
        {pos: [6, 3, 2], state: "minecraft:air"},
        {pos: [6, 3, 3], state: "minecraft:air"},
        {pos: [6, 3, 4], state: "minecraft:air"},
        {pos: [6, 3, 5], state: "minecraft:air"},
        {pos: [6, 3, 6], state: "minecraft:air"},
        {pos: [0, 4, 0], state: "minecraft:oak_stairs{half:bottom,waterlogged:false,shape:straight,facing:south}"},
        {pos: [0, 4, 1], state: "minecraft:oak_stairs{half:top,waterlogged:false,shape:straight,facing:north}"},
        {pos: [0, 4, 2], state: "minecraft:air"},
        {pos: [0, 4, 3], state: "minecraft:air"},
        {pos: [0, 4, 4], state: "minecraft:air"},
        {pos: [0, 4, 5], state: "minecraft:oak_stairs{half:top,waterlogged:false,shape:straight,facing:south}"},
        {pos: [0, 4, 6], state: "minecraft:oak_stairs{half:bottom,waterlogged:false,shape:straight,facing:north}"},
        {pos: [1, 4, 0], state: "minecraft:oak_stairs{half:bottom,waterlogged:false,shape:straight,facing:south}"},
        {pos: [1, 4, 6], state: "minecraft:oak_stairs{half:bottom,waterlogged:false,shape:straight,facing:north}"},
        {pos: [2, 4, 0], state: "minecraft:oak_stairs{half:bottom,waterlogged:false,shape:straight,facing:south}"},
        {pos: [2, 4, 2], state: "minecraft:air"},
        {pos: [2, 4, 3], state: "minecraft:air"},
        {pos: [2, 4, 4], state: "minecraft:air"},
        {pos: [2, 4, 6], state: "minecraft:oak_stairs{half:bottom,waterlogged:false,shape:straight,facing:north}"},
        {pos: [3, 4, 0], state: "minecraft:oak_stairs{half:bottom,waterlogged:false,shape:straight,facing:south}"},
        {pos: [3, 4, 2], state: "minecraft:air"},
        {pos: [3, 4, 3], state: "minecraft:air"},
        {pos: [3, 4, 4], state: "minecraft:air"},
        {pos: [3, 4, 6], state: "minecraft:oak_stairs{half:bottom,waterlogged:false,shape:straight,facing:north}"},
        {pos: [4, 4, 0], state: "minecraft:oak_stairs{half:bottom,waterlogged:false,shape:straight,facing:south}"},
        {pos: [4, 4, 2], state: "minecraft:air"},
        {pos: [4, 4, 3], state: "minecraft:air"},
        {pos: [4, 4, 4], state: "minecraft:air"},
        {pos: [4, 4, 6], state: "minecraft:oak_stairs{half:bottom,waterlogged:false,shape:straight,facing:north}"},
        {pos: [5, 4, 0], state: "minecraft:oak_stairs{half:bottom,waterlogged:false,shape:straight,facing:south}"},
        {pos: [5, 4, 6], state: "minecraft:oak_stairs{half:bottom,waterlogged:false,shape:straight,facing:north}"},
        {pos: [6, 4, 0], state: "minecraft:oak_stairs{half:bottom,waterlogged:false,shape:straight,facing:south}"},
        {pos: [6, 4, 1], state: "minecraft:oak_stairs{half:top,waterlogged:false,shape:straight,facing:north}"},
        {pos: [6, 4, 2], state: "minecraft:air"},
        {pos: [6, 4, 3], state: "minecraft:air"},
        {pos: [6, 4, 4], state: "minecraft:air"},
        {pos: [6, 4, 5], state: "minecraft:oak_stairs{half:top,waterlogged:false,shape:straight,facing:south}"},
        {pos: [6, 4, 6], state: "minecraft:oak_stairs{half:bottom,waterlogged:false,shape:straight,facing:north}"},
        {pos: [0, 5, 0], state: "minecraft:air"},
        {pos: [0, 5, 1], state: "minecraft:oak_stairs{half:bottom,waterlogged:false,shape:straight,facing:south}"},
        {pos: [0, 5, 2], state: "minecraft:oak_stairs{half:top,waterlogged:false,shape:straight,facing:north}"},
        {pos: [0, 5, 3], state: "minecraft:air"},
        {pos: [0, 5, 4], state: "minecraft:oak_stairs{half:top,waterlogged:false,shape:straight,facing:south}"},
        {pos: [0, 5, 5], state: "minecraft:oak_stairs{half:bottom,waterlogged:false,shape:straight,facing:north}"},
        {pos: [0, 5, 6], state: "minecraft:air"},
        {pos: [1, 5, 0], state: "minecraft:air"},
        {pos: [1, 5, 1], state: "minecraft:oak_stairs{half:bottom,waterlogged:false,shape:straight,facing:south}"},
        {pos: [1, 5, 5], state: "minecraft:oak_stairs{half:bottom,waterlogged:false,shape:straight,facing:north}"},
        {pos: [1, 5, 6], state: "minecraft:air"},
        {pos: [2, 5, 0], state: "minecraft:air"},
        {pos: [2, 5, 1], state: "minecraft:oak_stairs{half:bottom,waterlogged:false,shape:straight,facing:south}"},
        {pos: [2, 5, 5], state: "minecraft:oak_stairs{half:bottom,waterlogged:false,shape:straight,facing:north}"},
        {pos: [2, 5, 6], state: "minecraft:air"},
        {pos: [3, 5, 0], state: "minecraft:air"},
        {pos: [3, 5, 1], state: "minecraft:oak_stairs{half:bottom,waterlogged:false,shape:straight,facing:south}"},
        {pos: [3, 5, 3], state: "minecraft:air"},
        {pos: [3, 5, 5], state: "minecraft:oak_stairs{half:bottom,waterlogged:false,shape:straight,facing:north}"},
        {pos: [3, 5, 6], state: "minecraft:air"},
        {pos: [4, 5, 0], state: "minecraft:air"},
        {pos: [4, 5, 1], state: "minecraft:oak_stairs{half:bottom,waterlogged:false,shape:straight,facing:south}"},
        {pos: [4, 5, 5], state: "minecraft:oak_stairs{half:bottom,waterlogged:false,shape:straight,facing:north}"},
        {pos: [4, 5, 6], state: "minecraft:air"},
        {pos: [5, 5, 0], state: "minecraft:air"},
        {pos: [5, 5, 1], state: "minecraft:oak_stairs{half:bottom,waterlogged:false,shape:straight,facing:south}"},
        {pos: [5, 5, 5], state: "minecraft:oak_stairs{half:bottom,waterlogged:false,shape:straight,facing:north}"},
        {pos: [5, 5, 6], state: "minecraft:air"},
        {pos: [6, 5, 0], state: "minecraft:air"},
        {pos: [6, 5, 1], state: "minecraft:oak_stairs{half:bottom,waterlogged:false,shape:straight,facing:south}"},
        {pos: [6, 5, 2], state: "minecraft:oak_stairs{half:top,waterlogged:false,shape:straight,facing:north}"},
        {pos: [6, 5, 3], state: "minecraft:air"},
        {pos: [6, 5, 4], state: "minecraft:oak_stairs{half:top,waterlogged:false,shape:straight,facing:south}"},
        {pos: [6, 5, 5], state: "minecraft:oak_stairs{half:bottom,waterlogged:false,shape:straight,facing:north}"},
        {pos: [6, 5, 6], state: "minecraft:air"},
        {pos: [0, 6, 0], state: "minecraft:air"},
        {pos: [0, 6, 1], state: "minecraft:air"},
        {pos: [0, 6, 2], state: "minecraft:oak_stairs{half:bottom,waterlogged:false,shape:straight,facing:south}"},
        {pos: [0, 6, 4], state: "minecraft:oak_stairs{half:bottom,waterlogged:false,shape:straight,facing:north}"},
        {pos: [0, 6, 5], state: "minecraft:air"},
        {pos: [0, 6, 6], state: "minecraft:air"},
        {pos: [1, 6, 0], state: "minecraft:air"},
        {pos: [1, 6, 1], state: "minecraft:air"},
        {pos: [1, 6, 2], state: "minecraft:oak_stairs{half:bottom,waterlogged:false,shape:straight,facing:south}"},
        {pos: [1, 6, 4], state: "minecraft:oak_stairs{half:bottom,waterlogged:false,shape:straight,facing:north}"},
        {pos: [1, 6, 5], state: "minecraft:air"},
        {pos: [1, 6, 6], state: "minecraft:air"},
        {pos: [2, 6, 0], state: "minecraft:air"},
        {pos: [2, 6, 1], state: "minecraft:air"},
        {pos: [2, 6, 2], state: "minecraft:oak_stairs{half:bottom,waterlogged:false,shape:straight,facing:south}"},
        {pos: [2, 6, 4], state: "minecraft:oak_stairs{half:bottom,waterlogged:false,shape:straight,facing:north}"},
        {pos: [2, 6, 5], state: "minecraft:air"},
        {pos: [2, 6, 6], state: "minecraft:air"},
        {pos: [3, 6, 0], state: "minecraft:air"},
        {pos: [3, 6, 1], state: "minecraft:air"},
        {pos: [3, 6, 2], state: "minecraft:oak_stairs{half:bottom,waterlogged:false,shape:straight,facing:south}"},
        {pos: [3, 6, 4], state: "minecraft:oak_stairs{half:bottom,waterlogged:false,shape:straight,facing:north}"},
        {pos: [3, 6, 5], state: "minecraft:air"},
        {pos: [3, 6, 6], state: "minecraft:air"},
        {pos: [4, 6, 0], state: "minecraft:air"},
        {pos: [4, 6, 1], state: "minecraft:air"},
        {pos: [4, 6, 2], state: "minecraft:oak_stairs{half:bottom,waterlogged:false,shape:straight,facing:south}"},
        {pos: [4, 6, 4], state: "minecraft:oak_stairs{half:bottom,waterlogged:false,shape:straight,facing:north}"},
        {pos: [4, 6, 5], state: "minecraft:air"},
        {pos: [4, 6, 6], state: "minecraft:air"},
        {pos: [5, 6, 0], state: "minecraft:air"},
        {pos: [5, 6, 1], state: "minecraft:air"},
        {pos: [5, 6, 2], state: "minecraft:oak_stairs{half:bottom,waterlogged:false,shape:straight,facing:south}"},
        {pos: [5, 6, 4], state: "minecraft:oak_stairs{half:bottom,waterlogged:false,shape:straight,facing:north}"},
        {pos: [5, 6, 5], state: "minecraft:air"},
        {pos: [5, 6, 6], state: "minecraft:air"},
        {pos: [6, 6, 0], state: "minecraft:air"},
        {pos: [6, 6, 1], state: "minecraft:air"},
        {pos: [6, 6, 2], state: "minecraft:oak_stairs{half:bottom,waterlogged:false,shape:straight,facing:south}"},
        {pos: [6, 6, 4], state: "minecraft:oak_stairs{half:bottom,waterlogged:false,shape:straight,facing:north}"},
        {pos: [6, 6, 5], state: "minecraft:air"},
        {pos: [6, 6, 6], state: "minecraft:air"},
        {pos: [0, 0, 3], state: "minecraft:jigsaw{orientation:west_up}", nbt: {final_state: "minecraft:oak_stairs[facing=east,half=bottom,shape=straight,waterlogged=false]", id: "minecraft:jigsaw", joint: "aligned", name: "minecraft:building_entrance", pool: "minecraft:village/plains/zombie/streets", target: "minecraft:building_entrance"}},
        {pos: [3, 0, 3], state: "minecraft:jigsaw{orientation:up_north}", nbt: {final_state: "minecraft:oak_planks", id: "minecraft:jigsaw", joint: "rollable", name: "minecraft:bottom", pool: "minecraft:village/plains/zombie/villagers", target: "minecraft:bottom"}},
        {pos: [3, 1, 2], state: "minecraft:white_bed{part:foot,facing:east,occupied:false}", nbt: {id: "minecraft:bed"}},
        {pos: [4, 1, 2], state: "minecraft:white_bed{part:head,facing:east,occupied:false}", nbt: {id: "minecraft:bed"}}
    ],
    entities: [],
    palette: [
        "minecraft:oak_log{axis:y}",
        "minecraft:cobblestone",
        "minecraft:oak_planks",
        "minecraft:oak_log{axis:x}",
        "minecraft:oak_log{axis:z}",
        "minecraft:short_grass",
        "minecraft:poppy",
        "minecraft:air",
        "minecraft:tall_grass{half:lower}",
        "minecraft:tall_grass{half:upper}",
        "minecraft:oak_door{hinge:right,half:lower,powered:false,facing:east,open:false}",
        "minecraft:cobblestone_stairs{half:bottom,waterlogged:false,shape:straight,facing:south}",
        "minecraft:oak_door{hinge:right,half:upper,powered:false,facing:east,open:false}",
        "minecraft:glass_pane{east:true,waterlogged:false,south:false,north:false,west:true}",
        "minecraft:glass_pane{east:false,waterlogged:false,south:true,north:true,west:false}",
        "minecraft:wall_torch{facing:west}",
        "minecraft:oak_stairs{half:bottom,waterlogged:false,shape:straight,facing:south}",
        "minecraft:oak_stairs{half:top,waterlogged:false,shape:straight,facing:north}",
        "minecraft:oak_stairs{half:top,waterlogged:false,shape:straight,facing:south}",
        "minecraft:oak_stairs{half:bottom,waterlogged:false,shape:straight,facing:north}",
        "minecraft:jigsaw{orientation:west_up}",
        "minecraft:jigsaw{orientation:up_north}",
        "minecraft:white_bed{part:foot,facing:east,occupied:false}",
        "minecraft:white_bed{part:head,facing:east,occupied:false}"
    ]
}