{
    size: [4, 4, 4],
    data: [
        {pos: [0, 0, 1], state: "minecraft:cobblestone"},
        {pos: [0, 0, 2], state: "minecraft:cobblestone"},
        {pos: [1, 0, 0], state: "minecraft:cobblestone"},
        {pos: [1, 0, 1], state: "minecraft:cobblestone"},
        {pos: [1, 0, 2], state: "minecraft:cobblestone"},
        {pos: [2, 0, 0], state: "minecraft:cobblestone"},
        {pos: [2, 0, 1], state: "minecraft:cobblestone"},
        {pos: [2, 0, 2], state: "minecraft:cobblestone"},
        {pos: [0, 1, 1], state: "minecraft:dark_oak_planks"},
        {pos: [0, 1, 2], state: "minecraft:dark_oak_planks"},
        {pos: [1, 1, 0], state: "minecraft:dark_oak_planks"},
        {pos: [1, 1, 1], state: "minecraft:dark_oak_planks"},
        {pos: [1, 1, 2], state: "minecraft:dark_oak_planks"},
        {pos: [2, 1, 0], state: "minecraft:dark_oak_planks"},
        {pos: [2, 1, 1], state: "minecraft:dark_oak_planks"},
        {pos: [2, 1, 2], state: "minecraft:dark_oak_planks"},
        {pos: [0, 2, 1], state: "minecraft:dark_oak_planks"},
        {pos: [1, 2, 0], state: "minecraft:dark_oak_planks"},
        {pos: [1, 2, 1], state: "minecraft:dark_oak_planks"},
        {pos: [0, 3, 0], state: "minecraft:dark_oak_planks"},
        {pos: [0, 0, 3], state: "minecraft:air"},
        {pos: [1, 0, 3], state: "minecraft:air"},
        {pos: [2, 0, 3], state: "minecraft:air"},
        {pos: [3, 0, 0], state: "minecraft:air"},
        {pos: [3, 0, 1], state: "minecraft:air"},
        {pos: [3, 0, 2], state: "minecraft:air"},
        {pos: [3, 0, 3], state: "minecraft:air"},
        {pos: [0, 1, 3], state: "minecraft:dark_oak_stairs{half:bottom,waterlogged:false,shape:straight,facing:north}"},
        {pos: [1, 1, 3], state: "minecraft:dark_oak_stairs{half:bottom,waterlogged:false,shape:straight,facing:north}"},
        {pos: [2, 1, 3], state: "minecraft:dark_oak_stairs{half:bottom,waterlogged:false,shape:straight,facing:north}"},
        {pos: [3, 1, 0], state: "minecraft:dark_oak_stairs{half:bottom,waterlogged:false,shape:straight,facing:west}"},
        {pos: [3, 1, 1], state: "minecraft:dark_oak_stairs{half:bottom,waterlogged:false,shape:straight,facing:west}"},
        {pos: [3, 1, 2], state: "minecraft:dark_oak_stairs{half:bottom,waterlogged:false,shape:straight,facing:west}"},
        {pos: [3, 1, 3], state: "minecraft:dark_oak_stairs{half:bottom,waterlogged:false,shape:outer_left,facing:north}"},
        {pos: [0, 2, 0], state: "minecraft:dark_oak_stairs{half:top,waterlogged:false,shape:straight,facing:south}"},
        {pos: [0, 2, 2], state: "minecraft:dark_oak_stairs{half:bottom,waterlogged:false,shape:straight,facing:north}"},
        {pos: [1, 2, 2], state: "minecraft:dark_oak_stairs{half:bottom,waterlogged:false,shape:straight,facing:north}"},
        {pos: [1, 2, 3], state: "minecraft:air"},
        {pos: [2, 2, 0], state: "minecraft:dark_oak_stairs{half:bottom,waterlogged:false,shape:straight,facing:west}"},
        {pos: [2, 2, 1], state: "minecraft:dark_oak_stairs{half:bottom,waterlogged:false,shape:straight,facing:west}"},
        {pos: [2, 2, 2], state: "minecraft:dark_oak_stairs{half:bottom,waterlogged:false,shape:outer_left,facing:north}"},
        {pos: [2, 2, 3], state: "minecraft:air"},
        {pos: [3, 2, 1], state: "minecraft:air"},
        {pos: [3, 2, 2], state: "minecraft:air"},
        {pos: [3, 2, 3], state: "minecraft:air"},
        {pos: [0, 3, 1], state: "minecraft:dark_oak_stairs{half:bottom,waterlogged:false,shape:straight,facing:north}"},
        {pos: [1, 3, 0], state: "minecraft:dark_oak_stairs{half:bottom,waterlogged:false,shape:straight,facing:west}"},
        {pos: [1, 3, 1], state: "minecraft:dark_oak_stairs{half:bottom,waterlogged:false,shape:outer_left,facing:north}"},
        {pos: [1, 3, 2], state: "minecraft:air"},
        {pos: [1, 3, 3], state: "minecraft:air"},
        {pos: [2, 3, 1], state: "minecraft:air"},
        {pos: [2, 3, 2], state: "minecraft:air"},
        {pos: [2, 3, 3], state: "minecraft:air"},
        {pos: [3, 3, 1], state: "minecraft:air"},
        {pos: [3, 3, 2], state: "minecraft:air"},
        {pos: [3, 3, 3], state: "minecraft:air"}
    ],
    entities: [],
    palette: [
        "minecraft:cobblestone",
        "minecraft:dark_oak_planks",
        "minecraft:air",
        "minecraft:dark_oak_stairs{half:bottom,waterlogged:false,shape:straight,facing:north}",
        "minecraft:dark_oak_stairs{half:bottom,waterlogged:false,shape:straight,facing:west}",
        "minecraft:dark_oak_stairs{half:bottom,waterlogged:false,shape:outer_left,facing:north}",
        "minecraft:dark_oak_stairs{half:top,waterlogged:false,shape:straight,facing:south}"
    ]
}