{
    size: [18, 15, 21],
    data: [
        {pos: [0, 0, 7], state: "minecraft:deepslate_tiles"},
        {pos: [0, 0, 8], state: "minecraft:gray_wool"},
        {pos: [0, 0, 9], state: "minecraft:gray_wool"},
        {pos: [0, 0, 11], state: "minecraft:gray_wool"},
        {pos: [0, 0, 12], state: "minecraft:gray_wool"},
        {pos: [0, 0, 13], state: "minecraft:deepslate_tiles"},
        {pos: [1, 0, 7], state: "minecraft:deepslate_tiles"},
        {pos: [1, 0, 8], state: "minecraft:gray_wool"},
        {pos: [1, 0, 9], state: "minecraft:gray_wool"},
        {pos: [1, 0, 10], state: "minecraft:deepslate_tiles"},
        {pos: [1, 0, 11], state: "minecraft:gray_wool"},
        {pos: [1, 0, 12], state: "minecraft:gray_wool"},
        {pos: [1, 0, 13], state: "minecraft:deepslate_tiles"},
        {pos: [1, 0, 15], state: "minecraft:deepslate_bricks"},
        {pos: [1, 0, 16], state: "minecraft:deepslate_bricks"},
        {pos: [2, 0, 7], state: "minecraft:deepslate_tiles"},
        {pos: [2, 0, 8], state: "minecraft:gray_wool"},
        {pos: [2, 0, 9], state: "minecraft:gray_wool"},
        {pos: [2, 0, 10], state: "minecraft:chiseled_deepslate"},
        {pos: [2, 0, 11], state: "minecraft:gray_wool"},
        {pos: [2, 0, 12], state: "minecraft:gray_wool"},
        {pos: [2, 0, 13], state: "minecraft:deepslate_tiles"},
        {pos: [3, 0, 4], state: "minecraft:deepslate_bricks"},
        {pos: [3, 0, 5], state: "minecraft:deepslate_bricks"},
        {pos: [3, 0, 7], state: "minecraft:deepslate_tiles"},
        {pos: [3, 0, 10], state: "minecraft:deepslate_tiles"},
        {pos: [3, 0, 11], state: "minecraft:gray_wool"},
        {pos: [3, 0, 12], state: "minecraft:gray_wool"},
        {pos: [3, 0, 13], state: "minecraft:deepslate_tiles"},
        {pos: [3, 0, 15], state: "minecraft:deepslate_bricks"},
        {pos: [3, 0, 16], state: "minecraft:deepslate_bricks"},
        {pos: [4, 0, 10], state: "minecraft:deepslate_tiles"},
        {pos: [4, 0, 13], state: "minecraft:deepslate_tiles"},
        {pos: [5, 0, 5], state: "minecraft:deepslate_bricks"},
        {pos: [5, 0, 13], state: "minecraft:deepslate_tiles"},
        {pos: [5, 0, 15], state: "minecraft:deepslate_bricks"},
        {pos: [5, 0, 16], state: "minecraft:deepslate_bricks"},
        {pos: [6, 0, 13], state: "minecraft:deepslate_tiles"},
        {pos: [7, 0, 13], state: "minecraft:deepslate_tiles"},
        {pos: [7, 0, 15], state: "minecraft:deepslate_bricks"},
        {pos: [7, 0, 16], state: "minecraft:deepslate_bricks"},
        {pos: [9, 0, 14], state: "minecraft:deepslate_tiles"},
        {pos: [13, 0, 4], state: "minecraft:deepslate_bricks"},
        {pos: [13, 0, 5], state: "minecraft:deepslate_bricks"},
        {pos: [13, 0, 16], state: "minecraft:deepslate_bricks"},
        {pos: [15, 0, 4], state: "minecraft:deepslate_bricks"},
        {pos: [15, 0, 5], state: "minecraft:deepslate_bricks"},
        {pos: [15, 0, 15], state: "minecraft:deepslate_bricks"},
        {pos: [15, 0, 16], state: "minecraft:deepslate_bricks"},
        {pos: [16, 0, 13], state: "minecraft:deepslate_tiles"},
        {pos: [17, 0, 7], state: "minecraft:deepslate_tiles"},
        {pos: [17, 0, 13], state: "minecraft:deepslate_tiles"},
        {pos: [0, 1, 7], state: "minecraft:deepslate_bricks"},
        {pos: [0, 1, 8], state: "minecraft:gray_wool"},
        {pos: [0, 1, 9], state: "minecraft:gray_wool"},
        {pos: [0, 1, 10], state: "minecraft:deepslate_bricks"},
        {pos: [0, 1, 11], state: "minecraft:gray_wool"},
        {pos: [0, 1, 12], state: "minecraft:gray_wool"},
        {pos: [0, 1, 13], state: "minecraft:deepslate_bricks"},
        {pos: [1, 1, 7], state: "minecraft:deepslate_bricks"},
        {pos: [1, 1, 8], state: "minecraft:gray_wool"},
        {pos: [1, 1, 9], state: "minecraft:gray_wool"},
        {pos: [1, 1, 10], state: "minecraft:deepslate_bricks"},
        {pos: [1, 1, 11], state: "minecraft:gray_wool"},
        {pos: [1, 1, 12], state: "minecraft:gray_wool"},
        {pos: [1, 1, 13], state: "minecraft:deepslate_bricks"},
        {pos: [2, 1, 7], state: "minecraft:deepslate_bricks"},
        {pos: [2, 1, 8], state: "minecraft:gray_wool"},
        {pos: [2, 1, 10], state: "minecraft:deepslate_bricks"},
        {pos: [2, 1, 11], state: "minecraft:gray_wool"},
        {pos: [2, 1, 12], state: "minecraft:gray_wool"},
        {pos: [2, 1, 13], state: "minecraft:deepslate_bricks"},
        {pos: [3, 1, 7], state: "minecraft:deepslate_bricks"},
        {pos: [3, 1, 10], state: "minecraft:deepslate_bricks"},
        {pos: [3, 1, 11], state: "minecraft:gray_wool"},
        {pos: [3, 1, 13], state: "minecraft:deepslate_bricks"},
        {pos: [4, 1, 13], state: "minecraft:deepslate_bricks"},
        {pos: [5, 1, 13], state: "minecraft:deepslate_bricks"},
        {pos: [16, 1, 13], state: "minecraft:deepslate_bricks"},
        {pos: [17, 1, 7], state: "minecraft:deepslate_bricks"},
        {pos: [17, 1, 13], state: "minecraft:deepslate_bricks"},
        {pos: [0, 2, 10], state: "minecraft:deepslate_tiles"},
        {pos: [1, 2, 7], state: "minecraft:polished_deepslate"},
        {pos: [1, 2, 10], state: "minecraft:deepslate_tiles"},
        {pos: [1, 2, 13], state: "minecraft:polished_deepslate"},
        {pos: [2, 2, 10], state: "minecraft:deepslate_tiles"},
        {pos: [3, 2, 10], state: "minecraft:chiseled_deepslate"},
        {pos: [3, 2, 13], state: "minecraft:deepslate_bricks"},
        {pos: [5, 2, 13], state: "minecraft:deepslate_bricks"},
        {pos: [17, 2, 13], state: "minecraft:deepslate_bricks"},
        {pos: [0, 3, 10], state: "minecraft:deepslate_bricks"},
        {pos: [1, 3, 7], state: "minecraft:polished_deepslate"},
        {pos: [1, 3, 10], state: "minecraft:deepslate_bricks"},
        {pos: [1, 3, 13], state: "minecraft:polished_deepslate"},
        {pos: [2, 3, 10], state: "minecraft:deepslate_bricks"},
        {pos: [3, 3, 10], state: "minecraft:deepslate_tiles"},
        {pos: [0, 4, 10], state: "minecraft:deepslate_tiles"},
        {pos: [1, 4, 7], state: "minecraft:polished_deepslate"},
        {pos: [1, 4, 10], state: "minecraft:deepslate_tiles"},
        {pos: [1, 4, 13], state: "minecraft:polished_deepslate"},
        {pos: [2, 4, 10], state: "minecraft:deepslate_tiles"},
        {pos: [0, 5, 6], state: "minecraft:deepslate_bricks"},
        {pos: [0, 5, 7], state: "minecraft:deepslate_bricks"},
        {pos: [0, 5, 8], state: "minecraft:gray_wool"},
        {pos: [0, 5, 9], state: "minecraft:gray_wool"},
        {pos: [0, 5, 10], state: "minecraft:deepslate_bricks"},
        {pos: [0, 5, 13], state: "minecraft:deepslate_bricks"},
        {pos: [0, 5, 14], state: "minecraft:deepslate_bricks"},
        {pos: [1, 5, 6], state: "minecraft:deepslate_bricks"},
        {pos: [1, 5, 7], state: "minecraft:deepslate_bricks"},
        {pos: [1, 5, 8], state: "minecraft:gray_wool"},
        {pos: [1, 5, 9], state: "minecraft:gray_wool"},
        {pos: [1, 5, 13], state: "minecraft:deepslate_bricks"},
        {pos: [1, 5, 14], state: "minecraft:deepslate_bricks"},
        {pos: [2, 5, 6], state: "minecraft:deepslate_bricks"},
        {pos: [2, 5, 7], state: "minecraft:deepslate_bricks"},
        {pos: [2, 5, 14], state: "minecraft:deepslate_bricks"},
        {pos: [3, 5, 6], state: "minecraft:deepslate_bricks"},
        {pos: [3, 5, 7], state: "minecraft:deepslate_bricks"},
        {pos: [3, 5, 14], state: "minecraft:deepslate_bricks"},
        {pos: [4, 5, 6], state: "minecraft:deepslate_bricks"},
        {pos: [4, 5, 7], state: "minecraft:deepslate_bricks"},
        {pos: [5, 5, 6], state: "minecraft:deepslate_bricks"},
        {pos: [1, 6, 7], state: "minecraft:deepslate_bricks"},
        {pos: [3, 6, 7], state: "minecraft:deepslate_bricks"},
        {pos: [0, 0, 3], state: "minecraft:deepslate_tile_slab{waterlogged:false,type:bottom}"},
        {pos: [0, 0, 4], state: "minecraft:deepslate_tile_slab{waterlogged:false,type:bottom}"},
        {pos: [0, 0, 5], state: "minecraft:deepslate_tile_slab{waterlogged:false,type:bottom}"},
        {pos: [0, 0, 6], state: "minecraft:deepslate_tile_slab{waterlogged:false,type:bottom}"},
        {pos: [0, 0, 14], state: "minecraft:deepslate_tile_slab{waterlogged:false,type:bottom}"},
        {pos: [0, 0, 15], state: "minecraft:deepslate_tile_slab{waterlogged:false,type:bottom}"},
        {pos: [0, 0, 16], state: "minecraft:deepslate_tile_slab{waterlogged:false,type:bottom}"},
        {pos: [0, 0, 17], state: "minecraft:deepslate_tile_slab{waterlogged:false,type:bottom}"},
        {pos: [1, 0, 2], state: "minecraft:deepslate_tile_slab{waterlogged:false,type:bottom}"},
        {pos: [1, 0, 3], state: "minecraft:deepslate_tile_slab{waterlogged:false,type:bottom}"},
        {pos: [1, 0, 4], state: "minecraft:deepslate_tile_slab{waterlogged:false,type:bottom}"},
        {pos: [1, 0, 5], state: "minecraft:deepslate_tile_slab{waterlogged:false,type:bottom}"},
        {pos: [1, 0, 6], state: "minecraft:deepslate_tile_slab{waterlogged:false,type:bottom}"},
        {pos: [1, 0, 14], state: "minecraft:deepslate_tile_slab{waterlogged:false,type:bottom}"},
        {pos: [1, 0, 17], state: "minecraft:deepslate_tile_slab{waterlogged:false,type:bottom}"},
        {pos: [1, 0, 18], state: "minecraft:deepslate_tile_slab{waterlogged:false,type:bottom}"},
        {pos: [2, 0, 2], state: "minecraft:deepslate_tile_slab{waterlogged:false,type:bottom}"},
        {pos: [2, 0, 3], state: "minecraft:deepslate_tile_slab{waterlogged:false,type:bottom}"},
        {pos: [2, 0, 4], state: "minecraft:deepslate_tile_slab{waterlogged:false,type:bottom}"},
        {pos: [2, 0, 5], state: "minecraft:deepslate_tile_slab{waterlogged:false,type:bottom}"},
        {pos: [2, 0, 6], state: "minecraft:deepslate_tile_slab{waterlogged:false,type:bottom}"},
        {pos: [2, 0, 14], state: "minecraft:deepslate_tile_slab{waterlogged:false,type:bottom}"},
        {pos: [2, 0, 15], state: "minecraft:deepslate_tile_slab{waterlogged:false,type:bottom}"},
        {pos: [2, 0, 16], state: "minecraft:deepslate_tile_slab{waterlogged:false,type:bottom}"},
        {pos: [2, 0, 17], state: "minecraft:deepslate_tile_slab{waterlogged:false,type:bottom}"},
        {pos: [2, 0, 18], state: "minecraft:deepslate_tile_slab{waterlogged:false,type:bottom}"},
        {pos: [3, 0, 2], state: "minecraft:deepslate_tile_slab{waterlogged:false,type:bottom}"},
        {pos: [3, 0, 3], state: "minecraft:deepslate_tile_slab{waterlogged:false,type:bottom}"},
        {pos: [3, 0, 6], state: "minecraft:deepslate_tile_slab{waterlogged:false,type:bottom}"},
        {pos: [3, 0, 14], state: "minecraft:deepslate_tile_slab{waterlogged:false,type:bottom}"},
        {pos: [3, 0, 17], state: "minecraft:deepslate_tile_slab{waterlogged:false,type:bottom}"},
        {pos: [3, 0, 18], state: "minecraft:deepslate_tile_slab{waterlogged:false,type:bottom}"},
        {pos: [4, 0, 2], state: "minecraft:deepslate_tile_slab{waterlogged:false,type:bottom}"},
        {pos: [4, 0, 3], state: "minecraft:deepslate_tile_slab{waterlogged:false,type:bottom}"},
        {pos: [4, 0, 4], state: "minecraft:deepslate_tile_slab{waterlogged:false,type:bottom}"},
        {pos: [4, 0, 5], state: "minecraft:deepslate_tile_slab{waterlogged:false,type:bottom}"},
        {pos: [4, 0, 6], state: "minecraft:deepslate_tile_slab{waterlogged:false,type:bottom}"},
        {pos: [4, 0, 14], state: "minecraft:deepslate_tile_slab{waterlogged:false,type:bottom}"},
        {pos: [4, 0, 15], state: "minecraft:deepslate_tile_slab{waterlogged:false,type:bottom}"},
        {pos: [4, 0, 16], state: "minecraft:deepslate_tile_slab{waterlogged:false,type:bottom}"},
        {pos: [4, 0, 17], state: "minecraft:deepslate_tile_slab{waterlogged:false,type:bottom}"},
        {pos: [4, 0, 18], state: "minecraft:deepslate_tile_slab{waterlogged:false,type:bottom}"},
        {pos: [5, 0, 2], state: "minecraft:deepslate_tile_slab{waterlogged:false,type:bottom}"},
        {pos: [5, 0, 6], state: "minecraft:deepslate_tile_slab{waterlogged:false,type:bottom}"},
        {pos: [5, 0, 14], state: "minecraft:deepslate_tile_slab{waterlogged:false,type:bottom}"},
        {pos: [5, 0, 17], state: "minecraft:deepslate_tile_slab{waterlogged:false,type:bottom}"},
        {pos: [5, 0, 18], state: "minecraft:deepslate_tile_slab{waterlogged:false,type:bottom}"},
        {pos: [6, 0, 14], state: "minecraft:deepslate_tile_slab{waterlogged:false,type:bottom}"},
        {pos: [6, 0, 15], state: "minecraft:deepslate_tile_slab{waterlogged:false,type:bottom}"},
        {pos: [6, 0, 16], state: "minecraft:deepslate_tile_slab{waterlogged:false,type:bottom}"},
        {pos: [6, 0, 17], state: "minecraft:deepslate_tile_slab{waterlogged:false,type:bottom}"},
        {pos: [6, 0, 18], state: "minecraft:deepslate_tile_slab{waterlogged:false,type:bottom}"},
        {pos: [7, 0, 14], state: "minecraft:deepslate_tile_slab{waterlogged:false,type:bottom}"},
        {pos: [7, 0, 17], state: "minecraft:deepslate_tile_slab{waterlogged:false,type:bottom}"},
        {pos: [7, 0, 18], state: "minecraft:deepslate_tile_slab{waterlogged:false,type:bottom}"},
        {pos: [8, 0, 14], state: "minecraft:deepslate_tile_slab{waterlogged:false,type:bottom}"},
        {pos: [8, 0, 15], state: "minecraft:deepslate_tile_slab{waterlogged:false,type:bottom}"},
        {pos: [8, 0, 16], state: "minecraft:deepslate_tile_slab{waterlogged:false,type:bottom}"},
        {pos: [8, 0, 17], state: "minecraft:deepslate_tile_slab{waterlogged:false,type:bottom}"},
        {pos: [8, 0, 18], state: "minecraft:deepslate_tile_slab{waterlogged:false,type:bottom}"},
        {pos: [9, 0, 2], state: "minecraft:deepslate_tile_slab{waterlogged:false,type:bottom}"},
        {pos: [9, 0, 3], state: "minecraft:deepslate_brick_slab{waterlogged:false,type:bottom}"},
        {pos: [9, 0, 4], state: "minecraft:deepslate_brick_slab{waterlogged:false,type:bottom}"},
        {pos: [9, 0, 5], state: "minecraft:deepslate_brick_slab{waterlogged:false,type:bottom}"},
        {pos: [9, 0, 6], state: "minecraft:deepslate_brick_stairs{half:bottom,waterlogged:false,shape:straight,facing:south}"},
        {pos: [9, 0, 15], state: "minecraft:deepslate_brick_stairs{half:bottom,waterlogged:false,shape:straight,facing:north}"},
        {pos: [9, 0, 16], state: "minecraft:deepslate_brick_slab{waterlogged:false,type:bottom}"},
        {pos: [9, 0, 17], state: "minecraft:deepslate_brick_slab{waterlogged:false,type:bottom}"},
        {pos: [9, 0, 18], state: "minecraft:deepslate_tile_slab{waterlogged:false,type:bottom}"},
        {pos: [10, 0, 2], state: "minecraft:deepslate_tile_slab{waterlogged:false,type:bottom}"},
        {pos: [10, 0, 3], state: "minecraft:deepslate_brick_slab{waterlogged:false,type:bottom}"},
        {pos: [10, 0, 4], state: "minecraft:deepslate_brick_slab{waterlogged:false,type:bottom}"},
        {pos: [10, 0, 5], state: "minecraft:deepslate_brick_slab{waterlogged:false,type:bottom}"},
        {pos: [10, 0, 15], state: "minecraft:deepslate_brick_stairs{half:bottom,waterlogged:false,shape:straight,facing:north}"},
        {pos: [10, 0, 16], state: "minecraft:deepslate_brick_slab{waterlogged:false,type:bottom}"},
        {pos: [10, 0, 17], state: "minecraft:deepslate_brick_slab{waterlogged:false,type:bottom}"},
        {pos: [10, 0, 18], state: "minecraft:deepslate_tile_slab{waterlogged:false,type:bottom}"},
        {pos: [11, 0, 2], state: "minecraft:deepslate_tile_slab{waterlogged:false,type:bottom}"},
        {pos: [11, 0, 3], state: "minecraft:deepslate_brick_slab{waterlogged:false,type:bottom}"},
        {pos: [11, 0, 4], state: "minecraft:deepslate_brick_slab{waterlogged:false,type:bottom}"},
        {pos: [11, 0, 5], state: "minecraft:deepslate_brick_slab{waterlogged:false,type:bottom}"},
        {pos: [11, 0, 6], state: "minecraft:deepslate_brick_stairs{half:bottom,waterlogged:false,shape:straight,facing:south}"},
        {pos: [11, 0, 15], state: "minecraft:deepslate_brick_stairs{half:bottom,waterlogged:false,shape:straight,facing:north}"},
        {pos: [11, 0, 16], state: "minecraft:deepslate_brick_slab{waterlogged:false,type:bottom}"},
        {pos: [11, 0, 17], state: "minecraft:deepslate_brick_slab{waterlogged:false,type:bottom}"},
        {pos: [11, 0, 18], state: "minecraft:deepslate_tile_slab{waterlogged:false,type:bottom}"},
        {pos: [12, 0, 2], state: "minecraft:deepslate_tile_slab{waterlogged:false,type:bottom}"},
        {pos: [12, 0, 3], state: "minecraft:deepslate_tile_slab{waterlogged:false,type:bottom}"},
        {pos: [12, 0, 4], state: "minecraft:deepslate_tile_slab{waterlogged:false,type:bottom}"},
        {pos: [12, 0, 5], state: "minecraft:deepslate_tile_slab{waterlogged:false,type:bottom}"},
        {pos: [12, 0, 6], state: "minecraft:deepslate_tile_slab{waterlogged:false,type:bottom}"},
        {pos: [12, 0, 15], state: "minecraft:deepslate_tile_slab{waterlogged:false,type:bottom}"},
        {pos: [12, 0, 16], state: "minecraft:deepslate_tile_slab{waterlogged:false,type:bottom}"},
        {pos: [12, 0, 17], state: "minecraft:deepslate_tile_slab{waterlogged:false,type:bottom}"},
        {pos: [12, 0, 18], state: "minecraft:deepslate_tile_slab{waterlogged:false,type:bottom}"},
        {pos: [13, 0, 2], state: "minecraft:deepslate_tile_slab{waterlogged:false,type:bottom}"},
        {pos: [13, 0, 3], state: "minecraft:deepslate_tile_slab{waterlogged:false,type:bottom}"},
        {pos: [13, 0, 6], state: "minecraft:deepslate_tile_slab{waterlogged:false,type:bottom}"},
        {pos: [13, 0, 17], state: "minecraft:deepslate_tile_slab{waterlogged:false,type:bottom}"},
        {pos: [13, 0, 18], state: "minecraft:deepslate_tile_slab{waterlogged:false,type:bottom}"},
        {pos: [14, 0, 2], state: "minecraft:deepslate_tile_slab{waterlogged:false,type:bottom}"},
        {pos: [14, 0, 3], state: "minecraft:deepslate_tile_slab{waterlogged:false,type:bottom}"},
        {pos: [14, 0, 4], state: "minecraft:deepslate_tile_slab{waterlogged:false,type:bottom}"},
        {pos: [14, 0, 5], state: "minecraft:deepslate_tile_slab{waterlogged:false,type:bottom}"},
        {pos: [14, 0, 15], state: "minecraft:deepslate_tile_slab{waterlogged:false,type:bottom}"},
        {pos: [14, 0, 16], state: "minecraft:deepslate_tile_slab{waterlogged:false,type:bottom}"},
        {pos: [14, 0, 17], state: "minecraft:deepslate_tile_slab{waterlogged:false,type:bottom}"},
        {pos: [14, 0, 18], state: "minecraft:deepslate_tile_slab{waterlogged:false,type:bottom}"},
        {pos: [15, 0, 2], state: "minecraft:deepslate_tile_slab{waterlogged:false,type:bottom}"},
        {pos: [15, 0, 3], state: "minecraft:deepslate_tile_slab{waterlogged:false,type:bottom}"},
        {pos: [15, 0, 14], state: "minecraft:deepslate_tile_slab{waterlogged:false,type:bottom}"},
        {pos: [15, 0, 17], state: "minecraft:deepslate_tile_slab{waterlogged:false,type:bottom}"},
        {pos: [15, 0, 18], state: "minecraft:deepslate_tile_slab{waterlogged:false,type:bottom}"},
        {pos: [16, 0, 2], state: "minecraft:deepslate_tile_slab{waterlogged:false,type:bottom}"},
        {pos: [16, 0, 3], state: "minecraft:deepslate_tile_slab{waterlogged:false,type:bottom}"},
        {pos: [16, 0, 4], state: "minecraft:deepslate_tile_slab{waterlogged:false,type:bottom}"},
        {pos: [16, 0, 5], state: "minecraft:deepslate_tile_slab{waterlogged:false,type:bottom}"},
        {pos: [16, 0, 6], state: "minecraft:deepslate_tile_slab{waterlogged:false,type:bottom}"},
        {pos: [16, 0, 14], state: "minecraft:deepslate_tile_slab{waterlogged:false,type:bottom}"},
        {pos: [16, 0, 15], state: "minecraft:deepslate_tile_slab{waterlogged:false,type:bottom}"},
        {pos: [16, 0, 16], state: "minecraft:deepslate_tile_slab{waterlogged:false,type:bottom}"},
        {pos: [16, 0, 17], state: "minecraft:deepslate_tile_slab{waterlogged:false,type:bottom}"},
        {pos: [16, 0, 18], state: "minecraft:deepslate_tile_slab{waterlogged:false,type:bottom}"},
        {pos: [17, 0, 3], state: "minecraft:deepslate_tile_slab{waterlogged:false,type:bottom}"},
        {pos: [17, 0, 4], state: "minecraft:deepslate_tile_slab{waterlogged:false,type:bottom}"},
        {pos: [17, 0, 5], state: "minecraft:deepslate_tile_slab{waterlogged:false,type:bottom}"},
        {pos: [17, 0, 6], state: "minecraft:deepslate_tile_slab{waterlogged:false,type:bottom}"},
        {pos: [17, 0, 14], state: "minecraft:deepslate_tile_slab{waterlogged:false,type:bottom}"},
        {pos: [17, 0, 15], state: "minecraft:deepslate_tile_slab{waterlogged:false,type:bottom}"},
        {pos: [17, 0, 16], state: "minecraft:deepslate_tile_slab{waterlogged:false,type:bottom}"},
        {pos: [17, 0, 17], state: "minecraft:deepslate_tile_slab{waterlogged:false,type:bottom}"},
        {pos: [9, 1, 14], state: "minecraft:deepslate_brick_stairs{half:bottom,waterlogged:false,shape:straight,facing:north}"},
        {pos: [0, 0, 10], state: "minecraft:jigsaw{orientation:west_up}", nbt: {final_state: "minecraft:deepslate_tiles", id: "minecraft:jigsaw", joint: "rollable", name: "minecraft:connect_wall", pool: "minecraft:ancient_city/walls", target: "minecraft:connect_wall"}},
        {pos: [9, 0, 0], state: "minecraft:jigsaw{orientation:north_up}", nbt: {final_state: "minecraft:structure_void", id: "minecraft:jigsaw", joint: "rollable", name: "minecraft:empty", pool: "minecraft:ancient_city/structures", target: "minecraft:connect_structure"}},
        {pos: [9, 0, 20], state: "minecraft:jigsaw{orientation:south_up}", nbt: {final_state: "minecraft:deepslate_tile_slab", id: "minecraft:jigsaw", joint: "rollable", name: "minecraft:empty", pool: "minecraft:ancient_city/structures", target: "minecraft:connect_structure"}},
        {pos: [17, 0, 10], state: "minecraft:jigsaw{orientation:east_up}", nbt: {final_state: "minecraft:deepslate_tiles", id: "minecraft:jigsaw", joint: "rollable", name: "minecraft:connect_wall", pool: "minecraft:ancient_city/walls", target: "minecraft:connect_wall"}}
    ],
    entities: [],
    palette: [
        "minecraft:deepslate_tiles",
        "minecraft:gray_wool",
        "minecraft:deepslate_bricks",
        "minecraft:chiseled_deepslate",
        "minecraft:polished_deepslate",
        "minecraft:deepslate_tile_slab{waterlogged:false,type:bottom}",
        "minecraft:deepslate_brick_slab{waterlogged:false,type:bottom}",
        "minecraft:deepslate_brick_stairs{half:bottom,waterlogged:false,shape:straight,facing:south}",
        "minecraft:deepslate_brick_stairs{half:bottom,waterlogged:false,shape:straight,facing:north}",
        "minecraft:jigsaw{orientation:west_up}",
        "minecraft:jigsaw{orientation:north_up}",
        "minecraft:jigsaw{orientation:south_up}",
        "minecraft:jigsaw{orientation:east_up}"
    ]
}