{
    size: [19, 19, 5],
    data: [
        {pos: [0, 0, 0], state: "minecraft:tuff_bricks"},
        {pos: [0, 0, 1], state: "minecraft:tuff_bricks"},
        {pos: [0, 0, 2], state: "minecraft:tuff_bricks"},
        {pos: [0, 0, 3], state: "minecraft:tuff_bricks"},
        {pos: [0, 0, 4], state: "minecraft:tuff_bricks"},
        {pos: [1, 0, 0], state: "minecraft:tuff_bricks"},
        {pos: [1, 0, 1], state: "minecraft:tuff_bricks"},
        {pos: [1, 0, 2], state: "minecraft:tuff_bricks"},
        {pos: [1, 0, 3], state: "minecraft:tuff_bricks"},
        {pos: [1, 0, 4], state: "minecraft:tuff_bricks"},
        {pos: [2, 0, 0], state: "minecraft:tuff_bricks"},
        {pos: [2, 0, 1], state: "minecraft:tuff_bricks"},
        {pos: [2, 0, 2], state: "minecraft:tuff_bricks"},
        {pos: [2, 0, 3], state: "minecraft:tuff_bricks"},
        {pos: [2, 0, 4], state: "minecraft:tuff_bricks"},
        {pos: [3, 0, 0], state: "minecraft:tuff_bricks"},
        {pos: [3, 0, 1], state: "minecraft:tuff_bricks"},
        {pos: [3, 0, 2], state: "minecraft:tuff_bricks"},
        {pos: [3, 0, 3], state: "minecraft:tuff_bricks"},
        {pos: [3, 0, 4], state: "minecraft:tuff_bricks"},
        {pos: [4, 0, 0], state: "minecraft:tuff_bricks"},
        {pos: [4, 0, 1], state: "minecraft:tuff_bricks"},
        {pos: [4, 0, 2], state: "minecraft:tuff_bricks"},
        {pos: [4, 0, 3], state: "minecraft:tuff_bricks"},
        {pos: [4, 0, 4], state: "minecraft:tuff_bricks"},
        {pos: [5, 0, 0], state: "minecraft:tuff_bricks"},
        {pos: [5, 0, 1], state: "minecraft:tuff_bricks"},
        {pos: [5, 0, 2], state: "minecraft:tuff_bricks"},
        {pos: [5, 0, 3], state: "minecraft:tuff_bricks"},
        {pos: [5, 0, 4], state: "minecraft:tuff_bricks"},
        {pos: [6, 0, 0], state: "minecraft:tuff_bricks"},
        {pos: [6, 0, 1], state: "minecraft:tuff_bricks"},
        {pos: [6, 0, 2], state: "minecraft:tuff_bricks"},
        {pos: [6, 0, 3], state: "minecraft:tuff_bricks"},
        {pos: [6, 0, 4], state: "minecraft:tuff_bricks"},
        {pos: [7, 0, 0], state: "minecraft:tuff_bricks"},
        {pos: [7, 0, 1], state: "minecraft:tuff_bricks"},
        {pos: [7, 0, 2], state: "minecraft:tuff_bricks"},
        {pos: [7, 0, 3], state: "minecraft:tuff_bricks"},
        {pos: [7, 0, 4], state: "minecraft:tuff_bricks"},
        {pos: [8, 0, 0], state: "minecraft:tuff_bricks"},
        {pos: [8, 0, 1], state: "minecraft:tuff_bricks"},
        {pos: [8, 0, 2], state: "minecraft:tuff_bricks"},
        {pos: [8, 0, 3], state: "minecraft:tuff_bricks"},
        {pos: [8, 0, 4], state: "minecraft:tuff_bricks"},
        {pos: [9, 0, 0], state: "minecraft:tuff_bricks"},
        {pos: [9, 0, 1], state: "minecraft:tuff_bricks"},
        {pos: [9, 0, 3], state: "minecraft:tuff_bricks"},
        {pos: [9, 0, 4], state: "minecraft:tuff_bricks"},
        {pos: [10, 0, 0], state: "minecraft:tuff_bricks"},
        {pos: [10, 0, 1], state: "minecraft:tuff_bricks"},
        {pos: [10, 0, 2], state: "minecraft:tuff_bricks"},
        {pos: [10, 0, 3], state: "minecraft:tuff_bricks"},
        {pos: [10, 0, 4], state: "minecraft:tuff_bricks"},
        {pos: [11, 0, 0], state: "minecraft:tuff_bricks"},
        {pos: [11, 0, 1], state: "minecraft:tuff_bricks"},
        {pos: [11, 0, 2], state: "minecraft:tuff_bricks"},
        {pos: [11, 0, 3], state: "minecraft:tuff_bricks"},
        {pos: [11, 0, 4], state: "minecraft:tuff_bricks"},
        {pos: [12, 0, 0], state: "minecraft:tuff_bricks"},
        {pos: [12, 0, 1], state: "minecraft:tuff_bricks"},
        {pos: [12, 0, 2], state: "minecraft:tuff_bricks"},
        {pos: [12, 0, 3], state: "minecraft:tuff_bricks"},
        {pos: [12, 0, 4], state: "minecraft:tuff_bricks"},
        {pos: [13, 0, 0], state: "minecraft:tuff_bricks"},
        {pos: [13, 0, 1], state: "minecraft:tuff_bricks"},
        {pos: [13, 0, 2], state: "minecraft:tuff_bricks"},
        {pos: [13, 0, 3], state: "minecraft:tuff_bricks"},
        {pos: [13, 0, 4], state: "minecraft:tuff_bricks"},
        {pos: [14, 0, 0], state: "minecraft:tuff_bricks"},
        {pos: [14, 0, 1], state: "minecraft:tuff_bricks"},
        {pos: [14, 0, 2], state: "minecraft:tuff_bricks"},
        {pos: [14, 0, 3], state: "minecraft:tuff_bricks"},
        {pos: [14, 0, 4], state: "minecraft:tuff_bricks"},
        {pos: [15, 0, 0], state: "minecraft:tuff_bricks"},
        {pos: [15, 0, 1], state: "minecraft:tuff_bricks"},
        {pos: [15, 0, 2], state: "minecraft:tuff_bricks"},
        {pos: [15, 0, 3], state: "minecraft:tuff_bricks"},
        {pos: [15, 0, 4], state: "minecraft:tuff_bricks"},
        {pos: [16, 0, 0], state: "minecraft:tuff_bricks"},
        {pos: [16, 0, 1], state: "minecraft:tuff_bricks"},
        {pos: [16, 0, 2], state: "minecraft:tuff_bricks"},
        {pos: [16, 0, 3], state: "minecraft:tuff_bricks"},
        {pos: [16, 0, 4], state: "minecraft:tuff_bricks"},
        {pos: [17, 0, 0], state: "minecraft:tuff_bricks"},
        {pos: [17, 0, 1], state: "minecraft:tuff_bricks"},
        {pos: [17, 0, 2], state: "minecraft:tuff_bricks"},
        {pos: [17, 0, 3], state: "minecraft:tuff_bricks"},
        {pos: [17, 0, 4], state: "minecraft:tuff_bricks"},
        {pos: [18, 0, 0], state: "minecraft:tuff_bricks"},
        {pos: [18, 0, 1], state: "minecraft:tuff_bricks"},
        {pos: [18, 0, 2], state: "minecraft:tuff_bricks"},
        {pos: [18, 0, 3], state: "minecraft:tuff_bricks"},
        {pos: [18, 0, 4], state: "minecraft:tuff_bricks"},
        {pos: [0, 1, 0], state: "minecraft:tuff_bricks"},
        {pos: [0, 1, 1], state: "minecraft:tuff_bricks"},
        {pos: [0, 1, 2], state: "minecraft:tuff_bricks"},
        {pos: [0, 1, 3], state: "minecraft:tuff_bricks"},
        {pos: [0, 1, 4], state: "minecraft:tuff_bricks"},
        {pos: [1, 1, 0], state: "minecraft:tuff_bricks"},
        {pos: [1, 1, 1], state: "minecraft:tuff_bricks"},
        {pos: [1, 1, 2], state: "minecraft:tuff_bricks"},
        {pos: [1, 1, 3], state: "minecraft:tuff_bricks"},
        {pos: [1, 1, 4], state: "minecraft:tuff_bricks"},
        {pos: [2, 1, 0], state: "minecraft:tuff_bricks"},
        {pos: [2, 1, 1], state: "minecraft:tuff_bricks"},
        {pos: [2, 1, 2], state: "minecraft:tuff_bricks"},
        {pos: [2, 1, 3], state: "minecraft:tuff_bricks"},
        {pos: [2, 1, 4], state: "minecraft:tuff_bricks"},
        {pos: [3, 1, 0], state: "minecraft:tuff_bricks"},
        {pos: [3, 1, 1], state: "minecraft:tuff_bricks"},
        {pos: [3, 1, 2], state: "minecraft:tuff_bricks"},
        {pos: [3, 1, 3], state: "minecraft:tuff_bricks"},
        {pos: [3, 1, 4], state: "minecraft:tuff_bricks"},
        {pos: [4, 1, 0], state: "minecraft:tuff_bricks"},
        {pos: [4, 1, 1], state: "minecraft:tuff_bricks"},
        {pos: [4, 1, 2], state: "minecraft:tuff_bricks"},
        {pos: [4, 1, 3], state: "minecraft:tuff_bricks"},
        {pos: [4, 1, 4], state: "minecraft:tuff_bricks"},
        {pos: [5, 1, 0], state: "minecraft:tuff_bricks"},
        {pos: [5, 1, 1], state: "minecraft:tuff_bricks"},
        {pos: [5, 1, 2], state: "minecraft:tuff_bricks"},
        {pos: [5, 1, 3], state: "minecraft:tuff_bricks"},
        {pos: [5, 1, 4], state: "minecraft:tuff_bricks"},
        {pos: [6, 1, 0], state: "minecraft:tuff_bricks"},
        {pos: [6, 1, 1], state: "minecraft:tuff_bricks"},
        {pos: [6, 1, 2], state: "minecraft:tuff_bricks"},
        {pos: [6, 1, 3], state: "minecraft:tuff_bricks"},
        {pos: [6, 1, 4], state: "minecraft:tuff_bricks"},
        {pos: [7, 1, 0], state: "minecraft:tuff_bricks"},
        {pos: [7, 1, 1], state: "minecraft:waxed_oxidized_cut_copper"},
        {pos: [7, 1, 2], state: "minecraft:waxed_oxidized_cut_copper"},
        {pos: [7, 1, 4], state: "minecraft:tuff_bricks"},
        {pos: [8, 1, 0], state: "minecraft:waxed_oxidized_copper"},
        {pos: [8, 1, 4], state: "minecraft:waxed_oxidized_copper"},
        {pos: [9, 1, 0], state: "minecraft:waxed_oxidized_copper"},
        {pos: [9, 1, 1], state: "minecraft:waxed_oxidized_copper"},
        {pos: [9, 1, 2], state: "minecraft:waxed_oxidized_copper"},
        {pos: [9, 1, 3], state: "minecraft:waxed_oxidized_copper"},
        {pos: [9, 1, 4], state: "minecraft:waxed_oxidized_copper"},
        {pos: [10, 1, 0], state: "minecraft:waxed_oxidized_copper"},
        {pos: [10, 1, 4], state: "minecraft:waxed_oxidized_copper"},
        {pos: [11, 1, 0], state: "minecraft:tuff_bricks"},
        {pos: [11, 1, 2], state: "minecraft:waxed_oxidized_cut_copper"},
        {pos: [11, 1, 3], state: "minecraft:waxed_oxidized_cut_copper"},
        {pos: [11, 1, 4], state: "minecraft:tuff_bricks"},
        {pos: [12, 1, 0], state: "minecraft:tuff_bricks"},
        {pos: [12, 1, 1], state: "minecraft:tuff_bricks"},
        {pos: [12, 1, 2], state: "minecraft:tuff_bricks"},
        {pos: [12, 1, 3], state: "minecraft:tuff_bricks"},
        {pos: [12, 1, 4], state: "minecraft:tuff_bricks"},
        {pos: [13, 1, 0], state: "minecraft:tuff_bricks"},
        {pos: [13, 1, 1], state: "minecraft:tuff_bricks"},
        {pos: [13, 1, 2], state: "minecraft:tuff_bricks"},
        {pos: [13, 1, 3], state: "minecraft:tuff_bricks"},
        {pos: [13, 1, 4], state: "minecraft:tuff_bricks"},
        {pos: [14, 1, 0], state: "minecraft:tuff_bricks"},
        {pos: [14, 1, 1], state: "minecraft:tuff_bricks"},
        {pos: [14, 1, 2], state: "minecraft:tuff_bricks"},
        {pos: [14, 1, 3], state: "minecraft:tuff_bricks"},
        {pos: [14, 1, 4], state: "minecraft:tuff_bricks"},
        {pos: [15, 1, 0], state: "minecraft:tuff_bricks"},
        {pos: [15, 1, 1], state: "minecraft:tuff_bricks"},
        {pos: [15, 1, 2], state: "minecraft:tuff_bricks"},
        {pos: [15, 1, 3], state: "minecraft:tuff_bricks"},
        {pos: [15, 1, 4], state: "minecraft:tuff_bricks"},
        {pos: [16, 1, 0], state: "minecraft:tuff_bricks"},
        {pos: [16, 1, 1], state: "minecraft:tuff_bricks"},
        {pos: [16, 1, 2], state: "minecraft:tuff_bricks"},
        {pos: [16, 1, 3], state: "minecraft:tuff_bricks"},
        {pos: [16, 1, 4], state: "minecraft:tuff_bricks"},
        {pos: [17, 1, 0], state: "minecraft:tuff_bricks"},
        {pos: [17, 1, 1], state: "minecraft:tuff_bricks"},
        {pos: [17, 1, 2], state: "minecraft:tuff_bricks"},
        {pos: [17, 1, 3], state: "minecraft:tuff_bricks"},
        {pos: [17, 1, 4], state: "minecraft:tuff_bricks"},
        {pos: [18, 1, 0], state: "minecraft:tuff_bricks"},
        {pos: [18, 1, 1], state: "minecraft:tuff_bricks"},
        {pos: [18, 1, 2], state: "minecraft:tuff_bricks"},
        {pos: [18, 1, 3], state: "minecraft:tuff_bricks"},
        {pos: [18, 1, 4], state: "minecraft:tuff_bricks"},
        {pos: [0, 2, 0], state: "minecraft:tuff_bricks"},
        {pos: [0, 2, 1], state: "minecraft:tuff_bricks"},
        {pos: [0, 2, 2], state: "minecraft:tuff_bricks"},
        {pos: [0, 2, 3], state: "minecraft:tuff_bricks"},
        {pos: [0, 2, 4], state: "minecraft:tuff_bricks"},
        {pos: [1, 2, 0], state: "minecraft:tuff_bricks"},
        {pos: [1, 2, 1], state: "minecraft:tuff_bricks"},
        {pos: [1, 2, 2], state: "minecraft:tuff_bricks"},
        {pos: [1, 2, 3], state: "minecraft:tuff_bricks"},
        {pos: [1, 2, 4], state: "minecraft:tuff_bricks"},
        {pos: [2, 2, 0], state: "minecraft:tuff_bricks"},
        {pos: [2, 2, 1], state: "minecraft:tuff_bricks"},
        {pos: [2, 2, 2], state: "minecraft:tuff_bricks"},
        {pos: [2, 2, 3], state: "minecraft:tuff_bricks"},
        {pos: [2, 2, 4], state: "minecraft:tuff_bricks"},
        {pos: [3, 2, 0], state: "minecraft:tuff_bricks"},
        {pos: [3, 2, 1], state: "minecraft:tuff_bricks"},
        {pos: [3, 2, 2], state: "minecraft:tuff_bricks"},
        {pos: [3, 2, 3], state: "minecraft:tuff_bricks"},
        {pos: [3, 2, 4], state: "minecraft:tuff_bricks"},
        {pos: [4, 2, 0], state: "minecraft:tuff_bricks"},
        {pos: [4, 2, 1], state: "minecraft:tuff_bricks"},
        {pos: [4, 2, 2], state: "minecraft:tuff_bricks"},
        {pos: [4, 2, 3], state: "minecraft:tuff_bricks"},
        {pos: [4, 2, 4], state: "minecraft:tuff_bricks"},
        {pos: [5, 2, 0], state: "minecraft:tuff_bricks"},
        {pos: [5, 2, 1], state: "minecraft:tuff_bricks"},
        {pos: [5, 2, 2], state: "minecraft:tuff_bricks"},
        {pos: [5, 2, 3], state: "minecraft:tuff_bricks"},
        {pos: [5, 2, 4], state: "minecraft:tuff_bricks"},
        {pos: [6, 2, 0], state: "minecraft:waxed_oxidized_cut_copper"},
        {pos: [6, 2, 1], state: "minecraft:waxed_oxidized_cut_copper"},
        {pos: [6, 2, 2], state: "minecraft:waxed_oxidized_cut_copper"},
        {pos: [6, 2, 3], state: "minecraft:waxed_oxidized_cut_copper"},
        {pos: [6, 2, 4], state: "minecraft:waxed_oxidized_cut_copper"},
        {pos: [7, 2, 0], state: "minecraft:waxed_oxidized_cut_copper"},
        {pos: [7, 2, 4], state: "minecraft:waxed_oxidized_cut_copper"},
        {pos: [11, 2, 0], state: "minecraft:waxed_oxidized_cut_copper"},
        {pos: [11, 2, 4], state: "minecraft:waxed_oxidized_cut_copper"},
        {pos: [12, 2, 0], state: "minecraft:waxed_oxidized_cut_copper"},
        {pos: [12, 2, 1], state: "minecraft:waxed_oxidized_cut_copper"},
        {pos: [12, 2, 2], state: "minecraft:waxed_oxidized_cut_copper"},
        {pos: [12, 2, 3], state: "minecraft:waxed_oxidized_cut_copper"},
        {pos: [12, 2, 4], state: "minecraft:waxed_oxidized_cut_copper"},
        {pos: [13, 2, 0], state: "minecraft:tuff_bricks"},
        {pos: [13, 2, 1], state: "minecraft:tuff_bricks"},
        {pos: [13, 2, 2], state: "minecraft:tuff_bricks"},
        {pos: [13, 2, 3], state: "minecraft:tuff_bricks"},
        {pos: [13, 2, 4], state: "minecraft:tuff_bricks"},
        {pos: [14, 2, 0], state: "minecraft:tuff_bricks"},
        {pos: [14, 2, 1], state: "minecraft:tuff_bricks"},
        {pos: [14, 2, 2], state: "minecraft:tuff_bricks"},
        {pos: [14, 2, 3], state: "minecraft:tuff_bricks"},
        {pos: [14, 2, 4], state: "minecraft:tuff_bricks"},
        {pos: [15, 2, 0], state: "minecraft:tuff_bricks"},
        {pos: [15, 2, 1], state: "minecraft:tuff_bricks"},
        {pos: [15, 2, 2], state: "minecraft:tuff_bricks"},
        {pos: [15, 2, 3], state: "minecraft:tuff_bricks"},
        {pos: [15, 2, 4], state: "minecraft:tuff_bricks"},
        {pos: [16, 2, 0], state: "minecraft:tuff_bricks"},
        {pos: [16, 2, 1], state: "minecraft:tuff_bricks"},
        {pos: [16, 2, 2], state: "minecraft:tuff_bricks"},
        {pos: [16, 2, 3], state: "minecraft:tuff_bricks"},
        {pos: [16, 2, 4], state: "minecraft:tuff_bricks"},
        {pos: [17, 2, 0], state: "minecraft:tuff_bricks"},
        {pos: [17, 2, 1], state: "minecraft:tuff_bricks"},
        {pos: [17, 2, 2], state: "minecraft:tuff_bricks"},
        {pos: [17, 2, 3], state: "minecraft:tuff_bricks"},
        {pos: [17, 2, 4], state: "minecraft:tuff_bricks"},
        {pos: [18, 2, 0], state: "minecraft:tuff_bricks"},
        {pos: [18, 2, 1], state: "minecraft:tuff_bricks"},
        {pos: [18, 2, 2], state: "minecraft:tuff_bricks"},
        {pos: [18, 2, 3], state: "minecraft:tuff_bricks"},
        {pos: [18, 2, 4], state: "minecraft:tuff_bricks"},
        {pos: [0, 3, 0], state: "minecraft:tuff_bricks"},
        {pos: [0, 3, 1], state: "minecraft:tuff_bricks"},
        {pos: [0, 3, 2], state: "minecraft:tuff_bricks"},
        {pos: [0, 3, 3], state: "minecraft:tuff_bricks"},
        {pos: [0, 3, 4], state: "minecraft:tuff_bricks"},
        {pos: [1, 3, 0], state: "minecraft:tuff_bricks"},
        {pos: [1, 3, 1], state: "minecraft:tuff_bricks"},
        {pos: [1, 3, 2], state: "minecraft:tuff_bricks"},
        {pos: [1, 3, 3], state: "minecraft:tuff_bricks"},
        {pos: [1, 3, 4], state: "minecraft:tuff_bricks"},
        {pos: [2, 3, 0], state: "minecraft:tuff_bricks"},
        {pos: [2, 3, 1], state: "minecraft:waxed_oxidized_cut_copper"},
        {pos: [2, 3, 2], state: "minecraft:waxed_oxidized_cut_copper"},
        {pos: [2, 3, 3], state: "minecraft:waxed_oxidized_cut_copper"},
        {pos: [2, 3, 4], state: "minecraft:tuff_bricks"},
        {pos: [3, 3, 0], state: "minecraft:waxed_oxidized_copper"},
        {pos: [3, 3, 4], state: "minecraft:waxed_oxidized_copper"},
        {pos: [4, 3, 0], state: "minecraft:waxed_oxidized_copper"},
        {pos: [4, 3, 1], state: "minecraft:waxed_oxidized_copper"},
        {pos: [4, 3, 2], state: "minecraft:waxed_oxidized_copper"},
        {pos: [4, 3, 3], state: "minecraft:waxed_oxidized_copper"},
        {pos: [4, 3, 4], state: "minecraft:waxed_oxidized_copper"},
        {pos: [5, 3, 0], state: "minecraft:waxed_oxidized_cut_copper"},
        {pos: [5, 3, 2], state: "minecraft:waxed_oxidized_cut_copper"},
        {pos: [5, 3, 4], state: "minecraft:waxed_oxidized_cut_copper"},
        {pos: [6, 3, 0], state: "minecraft:waxed_copper_block"},
        {pos: [6, 3, 1], state: "minecraft:waxed_copper_block"},
        {pos: [6, 3, 2], state: "minecraft:waxed_copper_bulb{powered:false,lit:true}"},
        {pos: [6, 3, 3], state: "minecraft:waxed_copper_block"},
        {pos: [6, 3, 4], state: "minecraft:waxed_copper_block"},
        {pos: [7, 3, 0], state: "minecraft:waxed_copper_block"},
        {pos: [7, 3, 4], state: "minecraft:waxed_copper_block"},
        {pos: [11, 3, 0], state: "minecraft:waxed_copper_block"},
        {pos: [11, 3, 4], state: "minecraft:waxed_copper_block"},
        {pos: [12, 3, 0], state: "minecraft:waxed_copper_block"},
        {pos: [12, 3, 1], state: "minecraft:waxed_copper_block"},
        {pos: [12, 3, 2], state: "minecraft:waxed_copper_bulb{powered:false,lit:true}"},
        {pos: [12, 3, 3], state: "minecraft:waxed_copper_block"},
        {pos: [12, 3, 4], state: "minecraft:waxed_copper_block"},
        {pos: [13, 3, 0], state: "minecraft:waxed_oxidized_cut_copper"},
        {pos: [13, 3, 1], state: "minecraft:waxed_oxidized_cut_copper"},
        {pos: [13, 3, 2], state: "minecraft:waxed_oxidized_cut_copper"},
        {pos: [13, 3, 3], state: "minecraft:waxed_oxidized_cut_copper"},
        {pos: [13, 3, 4], state: "minecraft:waxed_oxidized_cut_copper"},
        {pos: [14, 3, 0], state: "minecraft:waxed_oxidized_copper"},
        {pos: [14, 3, 1], state: "minecraft:waxed_oxidized_copper"},
        {pos: [14, 3, 2], state: "minecraft:waxed_oxidized_copper"},
        {pos: [14, 3, 3], state: "minecraft:waxed_oxidized_copper"},
        {pos: [14, 3, 4], state: "minecraft:waxed_oxidized_copper"},
        {pos: [15, 3, 0], state: "minecraft:waxed_oxidized_copper"},
        {pos: [15, 3, 4], state: "minecraft:waxed_oxidized_copper"},
        {pos: [16, 3, 0], state: "minecraft:tuff_bricks"},
        {pos: [16, 3, 1], state: "minecraft:waxed_oxidized_cut_copper"},
        {pos: [16, 3, 2], state: "minecraft:waxed_oxidized_cut_copper"},
        {pos: [16, 3, 3], state: "minecraft:waxed_oxidized_cut_copper"},
        {pos: [16, 3, 4], state: "minecraft:tuff_bricks"},
        {pos: [17, 3, 0], state: "minecraft:tuff_bricks"},
        {pos: [17, 3, 1], state: "minecraft:tuff_bricks"},
        {pos: [17, 3, 2], state: "minecraft:tuff_bricks"},
        {pos: [17, 3, 3], state: "minecraft:tuff_bricks"},
        {pos: [17, 3, 4], state: "minecraft:tuff_bricks"},
        {pos: [18, 3, 0], state: "minecraft:tuff_bricks"},
        {pos: [18, 3, 1], state: "minecraft:tuff_bricks"},
        {pos: [18, 3, 2], state: "minecraft:tuff_bricks"},
        {pos: [18, 3, 3], state: "minecraft:tuff_bricks"},
        {pos: [18, 3, 4], state: "minecraft:tuff_bricks"},
        {pos: [0, 4, 0], state: "minecraft:tuff_bricks"},
        {pos: [0, 4, 1], state: "minecraft:tuff_bricks"},
        {pos: [0, 4, 2], state: "minecraft:tuff_bricks"},
        {pos: [0, 4, 3], state: "minecraft:tuff_bricks"},
        {pos: [0, 4, 4], state: "minecraft:tuff_bricks"},
        {pos: [1, 4, 0], state: "minecraft:waxed_copper_block"},
        {pos: [1, 4, 1], state: "minecraft:waxed_copper_block"},
        {pos: [1, 4, 2], state: "minecraft:waxed_copper_block"},
        {pos: [1, 4, 3], state: "minecraft:waxed_copper_block"},
        {pos: [1, 4, 4], state: "minecraft:waxed_copper_block"},
        {pos: [2, 4, 0], state: "minecraft:waxed_copper_block"},
        {pos: [2, 4, 4], state: "minecraft:waxed_copper_block"},
        {pos: [6, 4, 0], state: "minecraft:chiseled_tuff_bricks"},
        {pos: [6, 4, 4], state: "minecraft:chiseled_tuff_bricks"},
        {pos: [7, 4, 0], state: "minecraft:chiseled_tuff_bricks"},
        {pos: [7, 4, 4], state: "minecraft:chiseled_tuff_bricks"},
        {pos: [11, 4, 0], state: "minecraft:chiseled_tuff_bricks"},
        {pos: [11, 4, 4], state: "minecraft:chiseled_tuff_bricks"},
        {pos: [12, 4, 0], state: "minecraft:chiseled_tuff_bricks"},
        {pos: [12, 4, 4], state: "minecraft:chiseled_tuff_bricks"},
        {pos: [16, 4, 0], state: "minecraft:waxed_copper_block"},
        {pos: [16, 4, 4], state: "minecraft:waxed_copper_block"},
        {pos: [17, 4, 0], state: "minecraft:waxed_copper_block"},
        {pos: [17, 4, 1], state: "minecraft:waxed_copper_block"},
        {pos: [17, 4, 2], state: "minecraft:waxed_copper_block"},
        {pos: [17, 4, 3], state: "minecraft:waxed_copper_block"},
        {pos: [17, 4, 4], state: "minecraft:waxed_copper_block"},
        {pos: [18, 4, 0], state: "minecraft:tuff_bricks"},
        {pos: [18, 4, 1], state: "minecraft:tuff_bricks"},
        {pos: [18, 4, 2], state: "minecraft:tuff_bricks"},
        {pos: [18, 4, 3], state: "minecraft:tuff_bricks"},
        {pos: [18, 4, 4], state: "minecraft:tuff_bricks"},
        {pos: [0, 5, 0], state: "minecraft:tuff_bricks"},
        {pos: [0, 5, 1], state: "minecraft:tuff_bricks"},
        {pos: [0, 5, 2], state: "minecraft:tuff_bricks"},
        {pos: [0, 5, 3], state: "minecraft:tuff_bricks"},
        {pos: [0, 5, 4], state: "minecraft:tuff_bricks"},
        {pos: [1, 5, 0], state: "minecraft:tuff_bricks"},
        {pos: [1, 5, 1], state: "minecraft:tuff_bricks"},
        {pos: [1, 5, 2], state: "minecraft:waxed_copper_bulb{powered:false,lit:true}"},
        {pos: [1, 5, 3], state: "minecraft:tuff_bricks"},
        {pos: [1, 5, 4], state: "minecraft:tuff_bricks"},
        {pos: [2, 5, 0], state: "minecraft:tuff_bricks"},
        {pos: [2, 5, 4], state: "minecraft:tuff_bricks"},
        {pos: [6, 5, 0], state: "minecraft:tuff_bricks"},
        {pos: [6, 5, 4], state: "minecraft:tuff_bricks"},
        {pos: [7, 5, 0], state: "minecraft:tuff_bricks"},
        {pos: [7, 5, 4], state: "minecraft:tuff_bricks"},
        {pos: [11, 5, 0], state: "minecraft:tuff_bricks"},
        {pos: [11, 5, 4], state: "minecraft:tuff_bricks"},
        {pos: [12, 5, 0], state: "minecraft:tuff_bricks"},
        {pos: [12, 5, 4], state: "minecraft:tuff_bricks"},
        {pos: [16, 5, 0], state: "minecraft:tuff_bricks"},
        {pos: [16, 5, 4], state: "minecraft:tuff_bricks"},
        {pos: [17, 5, 0], state: "minecraft:tuff_bricks"},
        {pos: [17, 5, 1], state: "minecraft:tuff_bricks"},
        {pos: [17, 5, 2], state: "minecraft:waxed_copper_bulb{powered:false,lit:true}"},
        {pos: [17, 5, 3], state: "minecraft:tuff_bricks"},
        {pos: [17, 5, 4], state: "minecraft:tuff_bricks"},
        {pos: [18, 5, 0], state: "minecraft:tuff_bricks"},
        {pos: [18, 5, 1], state: "minecraft:tuff_bricks"},
        {pos: [18, 5, 2], state: "minecraft:tuff_bricks"},
        {pos: [18, 5, 3], state: "minecraft:tuff_bricks"},
        {pos: [18, 5, 4], state: "minecraft:tuff_bricks"},
        {pos: [0, 6, 0], state: "minecraft:tuff_bricks"},
        {pos: [0, 6, 1], state: "minecraft:tuff_bricks"},
        {pos: [0, 6, 2], state: "minecraft:tuff_bricks"},
        {pos: [0, 6, 3], state: "minecraft:tuff_bricks"},
        {pos: [0, 6, 4], state: "minecraft:tuff_bricks"},
        {pos: [1, 6, 0], state: "minecraft:chiseled_tuff_bricks"},
        {pos: [1, 6, 1], state: "minecraft:chiseled_tuff"},
        {pos: [1, 6, 2], state: "minecraft:chiseled_tuff_bricks"},
        {pos: [1, 6, 3], state: "minecraft:chiseled_tuff"},
        {pos: [1, 6, 4], state: "minecraft:chiseled_tuff_bricks"},
        {pos: [2, 6, 0], state: "minecraft:chiseled_tuff_bricks"},
        {pos: [2, 6, 4], state: "minecraft:chiseled_tuff_bricks"},
        {pos: [6, 6, 0], state: "minecraft:tuff_bricks"},
        {pos: [6, 6, 4], state: "minecraft:tuff_bricks"},
        {pos: [7, 6, 0], state: "minecraft:tuff_bricks"},
        {pos: [7, 6, 4], state: "minecraft:tuff_bricks"},
        {pos: [11, 6, 0], state: "minecraft:tuff_bricks"},
        {pos: [11, 6, 4], state: "minecraft:tuff_bricks"},
        {pos: [12, 6, 0], state: "minecraft:tuff_bricks"},
        {pos: [12, 6, 4], state: "minecraft:tuff_bricks"},
        {pos: [16, 6, 0], state: "minecraft:chiseled_tuff_bricks"},
        {pos: [16, 6, 4], state: "minecraft:chiseled_tuff_bricks"},
        {pos: [17, 6, 0], state: "minecraft:chiseled_tuff_bricks"},
        {pos: [17, 6, 1], state: "minecraft:chiseled_tuff"},
        {pos: [17, 6, 2], state: "minecraft:chiseled_tuff_bricks"},
        {pos: [17, 6, 3], state: "minecraft:chiseled_tuff"},
        {pos: [17, 6, 4], state: "minecraft:chiseled_tuff_bricks"},
        {pos: [18, 6, 0], state: "minecraft:tuff_bricks"},
        {pos: [18, 6, 1], state: "minecraft:tuff_bricks"},
        {pos: [18, 6, 2], state: "minecraft:tuff_bricks"},
        {pos: [18, 6, 3], state: "minecraft:tuff_bricks"},
        {pos: [18, 6, 4], state: "minecraft:tuff_bricks"},
        {pos: [0, 7, 0], state: "minecraft:tuff_bricks"},
        {pos: [0, 7, 1], state: "minecraft:tuff_bricks"},
        {pos: [0, 7, 2], state: "minecraft:tuff_bricks"},
        {pos: [0, 7, 3], state: "minecraft:tuff_bricks"},
        {pos: [0, 7, 4], state: "minecraft:tuff_bricks"},
        {pos: [1, 7, 0], state: "minecraft:tuff_bricks"},
        {pos: [1, 7, 1], state: "minecraft:tuff_bricks"},
        {pos: [1, 7, 2], state: "minecraft:tuff_bricks"},
        {pos: [1, 7, 3], state: "minecraft:tuff_bricks"},
        {pos: [1, 7, 4], state: "minecraft:tuff_bricks"},
        {pos: [2, 7, 0], state: "minecraft:tuff_bricks"},
        {pos: [2, 7, 1], state: "minecraft:polished_tuff"},
        {pos: [2, 7, 2], state: "minecraft:polished_tuff"},
        {pos: [2, 7, 3], state: "minecraft:polished_tuff"},
        {pos: [2, 7, 4], state: "minecraft:tuff_bricks"},
        {pos: [3, 7, 0], state: "minecraft:polished_tuff"},
        {pos: [3, 7, 1], state: "minecraft:polished_tuff"},
        {pos: [3, 7, 2], state: "minecraft:polished_tuff"},
        {pos: [3, 7, 3], state: "minecraft:polished_tuff"},
        {pos: [3, 7, 4], state: "minecraft:polished_tuff"},
        {pos: [4, 7, 0], state: "minecraft:polished_tuff"},
        {pos: [4, 7, 1], state: "minecraft:polished_tuff"},
        {pos: [4, 7, 3], state: "minecraft:polished_tuff"},
        {pos: [4, 7, 4], state: "minecraft:polished_tuff"},
        {pos: [5, 7, 0], state: "minecraft:polished_tuff"},
        {pos: [5, 7, 1], state: "minecraft:polished_tuff"},
        {pos: [5, 7, 2], state: "minecraft:polished_tuff"},
        {pos: [5, 7, 3], state: "minecraft:polished_tuff"},
        {pos: [5, 7, 4], state: "minecraft:polished_tuff"},
        {pos: [6, 7, 0], state: "minecraft:tuff_bricks"},
        {pos: [6, 7, 1], state: "minecraft:polished_tuff"},
        {pos: [6, 7, 2], state: "minecraft:polished_tuff"},
        {pos: [6, 7, 3], state: "minecraft:polished_tuff"},
        {pos: [6, 7, 4], state: "minecraft:tuff_bricks"},
        {pos: [7, 7, 1], state: "minecraft:polished_tuff"},
        {pos: [7, 7, 2], state: "minecraft:polished_tuff"},
        {pos: [7, 7, 3], state: "minecraft:polished_tuff"},
        {pos: [7, 7, 4], state: "minecraft:tuff_bricks"},
        {pos: [11, 7, 0], state: "minecraft:tuff_bricks"},
        {pos: [11, 7, 1], state: "minecraft:polished_tuff"},
        {pos: [11, 7, 2], state: "minecraft:polished_tuff"},
        {pos: [11, 7, 3], state: "minecraft:polished_tuff"},
        {pos: [11, 7, 4], state: "minecraft:tuff_bricks"},
        {pos: [12, 7, 0], state: "minecraft:tuff_bricks"},
        {pos: [12, 7, 1], state: "minecraft:polished_tuff"},
        {pos: [12, 7, 2], state: "minecraft:polished_tuff"},
        {pos: [12, 7, 3], state: "minecraft:polished_tuff"},
        {pos: [12, 7, 4], state: "minecraft:tuff_bricks"},
        {pos: [13, 7, 0], state: "minecraft:polished_tuff"},
        {pos: [13, 7, 1], state: "minecraft:polished_tuff"},
        {pos: [13, 7, 2], state: "minecraft:polished_tuff"},
        {pos: [13, 7, 3], state: "minecraft:polished_tuff"},
        {pos: [13, 7, 4], state: "minecraft:polished_tuff"},
        {pos: [14, 7, 0], state: "minecraft:polished_tuff"},
        {pos: [14, 7, 1], state: "minecraft:polished_tuff"},
        {pos: [14, 7, 2], state: "minecraft:polished_tuff"},
        {pos: [14, 7, 3], state: "minecraft:polished_tuff"},
        {pos: [14, 7, 4], state: "minecraft:polished_tuff"},
        {pos: [15, 7, 0], state: "minecraft:polished_tuff"},
        {pos: [15, 7, 1], state: "minecraft:polished_tuff"},
        {pos: [15, 7, 2], state: "minecraft:polished_tuff"},
        {pos: [15, 7, 3], state: "minecraft:polished_tuff"},
        {pos: [15, 7, 4], state: "minecraft:polished_tuff"},
        {pos: [16, 7, 0], state: "minecraft:tuff_bricks"},
        {pos: [16, 7, 1], state: "minecraft:polished_tuff"},
        {pos: [16, 7, 2], state: "minecraft:polished_tuff"},
        {pos: [16, 7, 3], state: "minecraft:polished_tuff"},
        {pos: [16, 7, 4], state: "minecraft:tuff_bricks"},
        {pos: [17, 7, 0], state: "minecraft:tuff_bricks"},
        {pos: [17, 7, 1], state: "minecraft:tuff_bricks"},
        {pos: [17, 7, 2], state: "minecraft:tuff_bricks"},
        {pos: [17, 7, 3], state: "minecraft:tuff_bricks"},
        {pos: [17, 7, 4], state: "minecraft:tuff_bricks"},
        {pos: [18, 7, 0], state: "minecraft:tuff_bricks"},
        {pos: [18, 7, 1], state: "minecraft:tuff_bricks"},
        {pos: [18, 7, 2], state: "minecraft:tuff_bricks"},
        {pos: [18, 7, 3], state: "minecraft:tuff_bricks"},
        {pos: [18, 7, 4], state: "minecraft:tuff_bricks"},
        {pos: [0, 8, 0], state: "minecraft:tuff_bricks"},
        {pos: [0, 8, 1], state: "minecraft:waxed_oxidized_cut_copper"},
        {pos: [0, 8, 2], state: "minecraft:waxed_oxidized_copper"},
        {pos: [0, 8, 3], state: "minecraft:waxed_oxidized_cut_copper"},
        {pos: [0, 8, 4], state: "minecraft:tuff_bricks"},
        {pos: [1, 8, 0], state: "minecraft:tuff_bricks"},
        {pos: [1, 8, 1], state: "minecraft:tuff_bricks"},
        {pos: [1, 8, 2], state: "minecraft:waxed_oxidized_copper"},
        {pos: [1, 8, 3], state: "minecraft:tuff_bricks"},
        {pos: [1, 8, 4], state: "minecraft:tuff_bricks"},
        {pos: [2, 8, 0], state: "minecraft:tuff_bricks"},
        {pos: [2, 8, 1], state: "minecraft:waxed_oxidized_cut_copper"},
        {pos: [2, 8, 2], state: "minecraft:waxed_oxidized_copper"},
        {pos: [2, 8, 3], state: "minecraft:waxed_oxidized_cut_copper"},
        {pos: [2, 8, 4], state: "minecraft:tuff_bricks"},
        {pos: [3, 8, 0], state: "minecraft:waxed_oxidized_copper"},
        {pos: [3, 8, 2], state: "minecraft:waxed_oxidized_copper"},
        {pos: [3, 8, 4], state: "minecraft:waxed_oxidized_copper"},
        {pos: [4, 8, 0], state: "minecraft:waxed_oxidized_copper"},
        {pos: [4, 8, 1], state: "minecraft:waxed_oxidized_copper"},
        {pos: [4, 8, 2], state: "minecraft:waxed_copper_grate{waterlogged:false}"},
        {pos: [4, 8, 3], state: "minecraft:waxed_oxidized_copper"},
        {pos: [4, 8, 4], state: "minecraft:waxed_oxidized_copper"},
        {pos: [5, 8, 0], state: "minecraft:waxed_oxidized_copper"},
        {pos: [5, 8, 2], state: "minecraft:waxed_oxidized_copper"},
        {pos: [5, 8, 4], state: "minecraft:waxed_oxidized_copper"},
        {pos: [6, 8, 0], state: "minecraft:tuff_bricks"},
        {pos: [6, 8, 1], state: "minecraft:waxed_oxidized_cut_copper"},
        {pos: [6, 8, 2], state: "minecraft:waxed_oxidized_cut_copper"},
        {pos: [6, 8, 3], state: "minecraft:waxed_oxidized_cut_copper"},
        {pos: [6, 8, 4], state: "minecraft:tuff_bricks"},
        {pos: [7, 8, 0], state: "minecraft:tuff_bricks"},
        {pos: [7, 8, 1], state: "minecraft:waxed_copper_block"},
        {pos: [7, 8, 2], state: "minecraft:waxed_copper_block"},
        {pos: [7, 8, 3], state: "minecraft:waxed_copper_block"},
        {pos: [7, 8, 4], state: "minecraft:tuff_bricks"},
        {pos: [11, 8, 0], state: "minecraft:tuff_bricks"},
        {pos: [11, 8, 1], state: "minecraft:tuff_bricks"},
        {pos: [11, 8, 2], state: "minecraft:tuff_bricks"},
        {pos: [11, 8, 3], state: "minecraft:tuff_bricks"},
        {pos: [11, 8, 4], state: "minecraft:tuff_bricks"},
        {pos: [12, 8, 0], state: "minecraft:tuff_bricks"},
        {pos: [12, 8, 1], state: "minecraft:tuff_bricks"},
        {pos: [12, 8, 2], state: "minecraft:tuff_bricks"},
        {pos: [12, 8, 3], state: "minecraft:tuff_bricks"},
        {pos: [12, 8, 4], state: "minecraft:tuff_bricks"},
        {pos: [13, 8, 0], state: "minecraft:tuff_bricks"},
        {pos: [13, 8, 1], state: "minecraft:tuff_bricks"},
        {pos: [13, 8, 2], state: "minecraft:tuff_bricks"},
        {pos: [13, 8, 3], state: "minecraft:tuff_bricks"},
        {pos: [13, 8, 4], state: "minecraft:tuff_bricks"},
        {pos: [14, 8, 0], state: "minecraft:tuff_bricks"},
        {pos: [14, 8, 1], state: "minecraft:tuff_bricks"},
        {pos: [14, 8, 2], state: "minecraft:tuff_bricks"},
        {pos: [14, 8, 3], state: "minecraft:tuff_bricks"},
        {pos: [14, 8, 4], state: "minecraft:tuff_bricks"},
        {pos: [15, 8, 0], state: "minecraft:tuff_bricks"},
        {pos: [15, 8, 1], state: "minecraft:tuff_bricks"},
        {pos: [15, 8, 2], state: "minecraft:tuff_bricks"},
        {pos: [15, 8, 3], state: "minecraft:tuff_bricks"},
        {pos: [15, 8, 4], state: "minecraft:tuff_bricks"},
        {pos: [16, 8, 0], state: "minecraft:tuff_bricks"},
        {pos: [16, 8, 1], state: "minecraft:tuff_bricks"},
        {pos: [16, 8, 2], state: "minecraft:tuff_bricks"},
        {pos: [16, 8, 3], state: "minecraft:tuff_bricks"},
        {pos: [16, 8, 4], state: "minecraft:tuff_bricks"},
        {pos: [17, 8, 0], state: "minecraft:tuff_bricks"},
        {pos: [17, 8, 1], state: "minecraft:tuff_bricks"},
        {pos: [17, 8, 2], state: "minecraft:tuff_bricks"},
        {pos: [17, 8, 3], state: "minecraft:tuff_bricks"},
        {pos: [17, 8, 4], state: "minecraft:tuff_bricks"},
        {pos: [18, 8, 0], state: "minecraft:tuff_bricks"},
        {pos: [18, 8, 1], state: "minecraft:tuff_bricks"},
        {pos: [18, 8, 2], state: "minecraft:tuff_bricks"},
        {pos: [18, 8, 3], state: "minecraft:tuff_bricks"},
        {pos: [18, 8, 4], state: "minecraft:tuff_bricks"},
        {pos: [0, 9, 0], state: "minecraft:waxed_copper_block"},
        {pos: [0, 9, 4], state: "minecraft:waxed_copper_block"},
        {pos: [1, 9, 0], state: "minecraft:waxed_copper_block"},
        {pos: [1, 9, 1], state: "minecraft:waxed_copper_block"},
        {pos: [1, 9, 3], state: "minecraft:waxed_copper_block"},
        {pos: [1, 9, 4], state: "minecraft:waxed_copper_block"},
        {pos: [2, 9, 0], state: "minecraft:waxed_copper_block"},
        {pos: [2, 9, 4], state: "minecraft:waxed_copper_block"},
        {pos: [6, 9, 0], state: "minecraft:chiseled_tuff_bricks"},
        {pos: [6, 9, 4], state: "minecraft:chiseled_tuff_bricks"},
        {pos: [7, 9, 0], state: "minecraft:chiseled_tuff_bricks"},
        {pos: [7, 9, 4], state: "minecraft:chiseled_tuff_bricks"},
        {pos: [11, 9, 0], state: "minecraft:chiseled_tuff_bricks"},
        {pos: [11, 9, 1], state: "minecraft:chiseled_tuff_bricks"},
        {pos: [11, 9, 2], state: "minecraft:chiseled_tuff_bricks"},
        {pos: [11, 9, 3], state: "minecraft:chiseled_tuff_bricks"},
        {pos: [11, 9, 4], state: "minecraft:chiseled_tuff_bricks"},
        {pos: [12, 9, 0], state: "minecraft:chiseled_tuff_bricks"},
        {pos: [12, 9, 1], state: "minecraft:tuff_bricks"},
        {pos: [12, 9, 2], state: "minecraft:tuff_bricks"},
        {pos: [12, 9, 3], state: "minecraft:tuff_bricks"},
        {pos: [12, 9, 4], state: "minecraft:chiseled_tuff_bricks"},
        {pos: [13, 9, 0], state: "minecraft:chiseled_tuff_bricks"},
        {pos: [13, 9, 1], state: "minecraft:tuff_bricks"},
        {pos: [13, 9, 2], state: "minecraft:tuff_bricks"},
        {pos: [13, 9, 3], state: "minecraft:tuff_bricks"},
        {pos: [13, 9, 4], state: "minecraft:chiseled_tuff_bricks"},
        {pos: [14, 9, 0], state: "minecraft:chiseled_tuff_bricks"},
        {pos: [14, 9, 1], state: "minecraft:tuff_bricks"},
        {pos: [14, 9, 2], state: "minecraft:tuff_bricks"},
        {pos: [14, 9, 3], state: "minecraft:tuff_bricks"},
        {pos: [14, 9, 4], state: "minecraft:chiseled_tuff_bricks"},
        {pos: [15, 9, 0], state: "minecraft:chiseled_tuff_bricks"},
        {pos: [15, 9, 1], state: "minecraft:tuff_bricks"},
        {pos: [15, 9, 2], state: "minecraft:tuff_bricks"},
        {pos: [15, 9, 3], state: "minecraft:tuff_bricks"},
        {pos: [15, 9, 4], state: "minecraft:chiseled_tuff_bricks"},
        {pos: [16, 9, 0], state: "minecraft:chiseled_tuff_bricks"},
        {pos: [16, 9, 1], state: "minecraft:tuff_bricks"},
        {pos: [16, 9, 2], state: "minecraft:tuff_bricks"},
        {pos: [16, 9, 3], state: "minecraft:tuff_bricks"},
        {pos: [16, 9, 4], state: "minecraft:chiseled_tuff_bricks"},
        {pos: [17, 9, 0], state: "minecraft:tuff_bricks"},
        {pos: [17, 9, 1], state: "minecraft:tuff_bricks"},
        {pos: [17, 9, 2], state: "minecraft:tuff_bricks"},
        {pos: [17, 9, 3], state: "minecraft:tuff_bricks"},
        {pos: [17, 9, 4], state: "minecraft:tuff_bricks"},
        {pos: [18, 9, 0], state: "minecraft:tuff_bricks"},
        {pos: [18, 9, 1], state: "minecraft:tuff_bricks"},
        {pos: [18, 9, 2], state: "minecraft:tuff_bricks"},
        {pos: [18, 9, 3], state: "minecraft:tuff_bricks"},
        {pos: [18, 9, 4], state: "minecraft:tuff_bricks"},
        {pos: [0, 10, 0], state: "minecraft:waxed_copper_block"},
        {pos: [0, 10, 4], state: "minecraft:waxed_copper_block"},
        {pos: [1, 10, 0], state: "minecraft:waxed_copper_block"},
        {pos: [1, 10, 1], state: "minecraft:waxed_chiseled_copper"},
        {pos: [1, 10, 3], state: "minecraft:waxed_chiseled_copper"},
        {pos: [1, 10, 4], state: "minecraft:waxed_copper_block"},
        {pos: [2, 10, 0], state: "minecraft:waxed_copper_block"},
        {pos: [2, 10, 4], state: "minecraft:waxed_copper_block"},
        {pos: [6, 10, 0], state: "minecraft:tuff_bricks"},
        {pos: [6, 10, 4], state: "minecraft:tuff_bricks"},
        {pos: [7, 10, 0], state: "minecraft:tuff_bricks"},
        {pos: [7, 10, 4], state: "minecraft:tuff_bricks"},
        {pos: [11, 10, 0], state: "minecraft:tuff_bricks"},
        {pos: [11, 10, 1], state: "minecraft:tuff_bricks"},
        {pos: [11, 10, 2], state: "minecraft:tuff_bricks"},
        {pos: [11, 10, 3], state: "minecraft:tuff_bricks"},
        {pos: [11, 10, 4], state: "minecraft:tuff_bricks"},
        {pos: [12, 10, 0], state: "minecraft:tuff_bricks"},
        {pos: [12, 10, 1], state: "minecraft:tuff_bricks"},
        {pos: [12, 10, 2], state: "minecraft:tuff_bricks"},
        {pos: [12, 10, 3], state: "minecraft:tuff_bricks"},
        {pos: [12, 10, 4], state: "minecraft:tuff_bricks"},
        {pos: [13, 10, 0], state: "minecraft:tuff_bricks"},
        {pos: [13, 10, 1], state: "minecraft:tuff_bricks"},
        {pos: [13, 10, 2], state: "minecraft:tuff_bricks"},
        {pos: [13, 10, 3], state: "minecraft:tuff_bricks"},
        {pos: [13, 10, 4], state: "minecraft:tuff_bricks"},
        {pos: [14, 10, 0], state: "minecraft:waxed_copper_grate{waterlogged:false}"},
        {pos: [14, 10, 4], state: "minecraft:waxed_copper_grate{waterlogged:false}"},
        {pos: [15, 10, 0], state: "minecraft:tuff_bricks"},
        {pos: [15, 10, 1], state: "minecraft:tuff_bricks"},
        {pos: [15, 10, 2], state: "minecraft:tuff_bricks"},
        {pos: [15, 10, 3], state: "minecraft:tuff_bricks"},
        {pos: [15, 10, 4], state: "minecraft:tuff_bricks"},
        {pos: [16, 10, 0], state: "minecraft:tuff_bricks"},
        {pos: [16, 10, 1], state: "minecraft:tuff_bricks"},
        {pos: [16, 10, 2], state: "minecraft:tuff_bricks"},
        {pos: [16, 10, 3], state: "minecraft:tuff_bricks"},
        {pos: [16, 10, 4], state: "minecraft:tuff_bricks"},
        {pos: [17, 10, 0], state: "minecraft:tuff_bricks"},
        {pos: [17, 10, 1], state: "minecraft:tuff_bricks"},
        {pos: [17, 10, 2], state: "minecraft:tuff_bricks"},
        {pos: [17, 10, 3], state: "minecraft:tuff_bricks"},
        {pos: [17, 10, 4], state: "minecraft:tuff_bricks"},
        {pos: [18, 10, 0], state: "minecraft:tuff_bricks"},
        {pos: [18, 10, 1], state: "minecraft:tuff_bricks"},
        {pos: [18, 10, 2], state: "minecraft:tuff_bricks"},
        {pos: [18, 10, 3], state: "minecraft:tuff_bricks"},
        {pos: [18, 10, 4], state: "minecraft:tuff_bricks"},
        {pos: [0, 11, 0], state: "minecraft:waxed_copper_block"},
        {pos: [0, 11, 4], state: "minecraft:waxed_copper_block"},
        {pos: [1, 11, 0], state: "minecraft:waxed_copper_block"},
        {pos: [1, 11, 1], state: "minecraft:waxed_copper_block"},
        {pos: [1, 11, 3], state: "minecraft:waxed_copper_block"},
        {pos: [1, 11, 4], state: "minecraft:waxed_copper_block"},
        {pos: [2, 11, 0], state: "minecraft:waxed_copper_block"},
        {pos: [2, 11, 4], state: "minecraft:waxed_copper_block"},
        {pos: [6, 11, 0], state: "minecraft:chiseled_tuff_bricks"},
        {pos: [6, 11, 4], state: "minecraft:chiseled_tuff_bricks"},
        {pos: [7, 11, 0], state: "minecraft:chiseled_tuff_bricks"},
        {pos: [7, 11, 4], state: "minecraft:chiseled_tuff_bricks"},
        {pos: [11, 11, 0], state: "minecraft:chiseled_tuff_bricks"},
        {pos: [11, 11, 1], state: "minecraft:chiseled_tuff_bricks"},
        {pos: [11, 11, 2], state: "minecraft:chiseled_tuff_bricks"},
        {pos: [11, 11, 3], state: "minecraft:chiseled_tuff_bricks"},
        {pos: [11, 11, 4], state: "minecraft:chiseled_tuff_bricks"},
        {pos: [12, 11, 0], state: "minecraft:chiseled_tuff_bricks"},
        {pos: [12, 11, 1], state: "minecraft:tuff_bricks"},
        {pos: [12, 11, 2], state: "minecraft:tuff_bricks"},
        {pos: [12, 11, 3], state: "minecraft:tuff_bricks"},
        {pos: [12, 11, 4], state: "minecraft:chiseled_tuff_bricks"},
        {pos: [13, 11, 0], state: "minecraft:chiseled_tuff_bricks"},
        {pos: [13, 11, 1], state: "minecraft:tuff_bricks"},
        {pos: [13, 11, 2], state: "minecraft:tuff_bricks"},
        {pos: [13, 11, 3], state: "minecraft:tuff_bricks"},
        {pos: [13, 11, 4], state: "minecraft:chiseled_tuff_bricks"},
        {pos: [14, 11, 0], state: "minecraft:chiseled_tuff_bricks"},
        {pos: [14, 11, 1], state: "minecraft:tuff_bricks"},
        {pos: [14, 11, 2], state: "minecraft:tuff_bricks"},
        {pos: [14, 11, 3], state: "minecraft:tuff_bricks"},
        {pos: [14, 11, 4], state: "minecraft:chiseled_tuff_bricks"},
        {pos: [15, 11, 0], state: "minecraft:chiseled_tuff_bricks"},
        {pos: [15, 11, 1], state: "minecraft:tuff_bricks"},
        {pos: [15, 11, 2], state: "minecraft:tuff_bricks"},
        {pos: [15, 11, 3], state: "minecraft:tuff_bricks"},
        {pos: [15, 11, 4], state: "minecraft:chiseled_tuff_bricks"},
        {pos: [16, 11, 0], state: "minecraft:chiseled_tuff_bricks"},
        {pos: [16, 11, 1], state: "minecraft:tuff_bricks"},
        {pos: [16, 11, 2], state: "minecraft:tuff_bricks"},
        {pos: [16, 11, 3], state: "minecraft:tuff_bricks"},
        {pos: [16, 11, 4], state: "minecraft:chiseled_tuff_bricks"},
        {pos: [17, 11, 0], state: "minecraft:tuff_bricks"},
        {pos: [17, 11, 1], state: "minecraft:tuff_bricks"},
        {pos: [17, 11, 2], state: "minecraft:tuff_bricks"},
        {pos: [17, 11, 3], state: "minecraft:tuff_bricks"},
        {pos: [17, 11, 4], state: "minecraft:tuff_bricks"},
        {pos: [18, 11, 0], state: "minecraft:tuff_bricks"},
        {pos: [18, 11, 1], state: "minecraft:tuff_bricks"},
        {pos: [18, 11, 2], state: "minecraft:tuff_bricks"},
        {pos: [18, 11, 3], state: "minecraft:tuff_bricks"},
        {pos: [18, 11, 4], state: "minecraft:tuff_bricks"},
        {pos: [0, 12, 0], state: "minecraft:waxed_copper_block"},
        {pos: [0, 12, 1], state: "minecraft:waxed_copper_block"},
        {pos: [0, 12, 2], state: "minecraft:waxed_copper_bulb{powered:false,lit:true}"},
        {pos: [0, 12, 3], state: "minecraft:waxed_copper_block"},
        {pos: [0, 12, 4], state: "minecraft:waxed_copper_block"},
        {pos: [1, 12, 0], state: "minecraft:waxed_copper_block"},
        {pos: [1, 12, 1], state: "minecraft:waxed_copper_block"},
        {pos: [1, 12, 2], state: "minecraft:waxed_copper_block"},
        {pos: [1, 12, 3], state: "minecraft:waxed_copper_block"},
        {pos: [1, 12, 4], state: "minecraft:waxed_copper_block"},
        {pos: [2, 12, 0], state: "minecraft:waxed_copper_block"},
        {pos: [2, 12, 1], state: "minecraft:waxed_copper_block"},
        {pos: [2, 12, 2], state: "minecraft:waxed_copper_bulb{powered:false,lit:true}"},
        {pos: [2, 12, 3], state: "minecraft:waxed_copper_block"},
        {pos: [2, 12, 4], state: "minecraft:waxed_copper_block"},
        {pos: [6, 12, 0], state: "minecraft:tuff_bricks"},
        {pos: [6, 12, 4], state: "minecraft:tuff_bricks"},
        {pos: [7, 12, 0], state: "minecraft:tuff_bricks"},
        {pos: [7, 12, 4], state: "minecraft:tuff_bricks"},
        {pos: [11, 12, 0], state: "minecraft:tuff_bricks"},
        {pos: [11, 12, 1], state: "minecraft:tuff_bricks"},
        {pos: [11, 12, 2], state: "minecraft:tuff_bricks"},
        {pos: [11, 12, 3], state: "minecraft:tuff_bricks"},
        {pos: [11, 12, 4], state: "minecraft:tuff_bricks"},
        {pos: [12, 12, 0], state: "minecraft:tuff_bricks"},
        {pos: [12, 12, 1], state: "minecraft:tuff_bricks"},
        {pos: [12, 12, 2], state: "minecraft:tuff_bricks"},
        {pos: [12, 12, 3], state: "minecraft:tuff_bricks"},
        {pos: [12, 12, 4], state: "minecraft:tuff_bricks"},
        {pos: [13, 12, 0], state: "minecraft:tuff_bricks"},
        {pos: [13, 12, 1], state: "minecraft:tuff_bricks"},
        {pos: [13, 12, 2], state: "minecraft:tuff_bricks"},
        {pos: [13, 12, 3], state: "minecraft:tuff_bricks"},
        {pos: [13, 12, 4], state: "minecraft:tuff_bricks"},
        {pos: [14, 12, 0], state: "minecraft:tuff_bricks"},
        {pos: [14, 12, 1], state: "minecraft:tuff_bricks"},
        {pos: [14, 12, 2], state: "minecraft:tuff_bricks"},
        {pos: [14, 12, 3], state: "minecraft:tuff_bricks"},
        {pos: [14, 12, 4], state: "minecraft:tuff_bricks"},
        {pos: [15, 12, 0], state: "minecraft:tuff_bricks"},
        {pos: [15, 12, 1], state: "minecraft:tuff_bricks"},
        {pos: [15, 12, 2], state: "minecraft:tuff_bricks"},
        {pos: [15, 12, 3], state: "minecraft:tuff_bricks"},
        {pos: [15, 12, 4], state: "minecraft:tuff_bricks"},
        {pos: [16, 12, 0], state: "minecraft:tuff_bricks"},
        {pos: [16, 12, 1], state: "minecraft:tuff_bricks"},
        {pos: [16, 12, 2], state: "minecraft:tuff_bricks"},
        {pos: [16, 12, 3], state: "minecraft:tuff_bricks"},
        {pos: [16, 12, 4], state: "minecraft:tuff_bricks"},
        {pos: [17, 12, 0], state: "minecraft:tuff_bricks"},
        {pos: [17, 12, 1], state: "minecraft:tuff_bricks"},
        {pos: [17, 12, 2], state: "minecraft:tuff_bricks"},
        {pos: [17, 12, 3], state: "minecraft:tuff_bricks"},
        {pos: [17, 12, 4], state: "minecraft:tuff_bricks"},
        {pos: [18, 12, 0], state: "minecraft:tuff_bricks"},
        {pos: [18, 12, 1], state: "minecraft:tuff_bricks"},
        {pos: [18, 12, 2], state: "minecraft:tuff_bricks"},
        {pos: [18, 12, 3], state: "minecraft:tuff_bricks"},
        {pos: [18, 12, 4], state: "minecraft:tuff_bricks"},
        {pos: [0, 13, 0], state: "minecraft:tuff_bricks"},
        {pos: [0, 13, 1], state: "minecraft:tuff_bricks"},
        {pos: [0, 13, 2], state: "minecraft:tuff_bricks"},
        {pos: [0, 13, 3], state: "minecraft:tuff_bricks"},
        {pos: [0, 13, 4], state: "minecraft:tuff_bricks"},
        {pos: [1, 13, 0], state: "minecraft:tuff_bricks"},
        {pos: [1, 13, 1], state: "minecraft:tuff_bricks"},
        {pos: [1, 13, 2], state: "minecraft:tuff_bricks"},
        {pos: [1, 13, 3], state: "minecraft:tuff_bricks"},
        {pos: [1, 13, 4], state: "minecraft:tuff_bricks"},
        {pos: [2, 13, 0], state: "minecraft:tuff_bricks"},
        {pos: [2, 13, 1], state: "minecraft:waxed_copper_grate{waterlogged:false}"},
        {pos: [2, 13, 2], state: "minecraft:waxed_copper_grate{waterlogged:false}"},
        {pos: [2, 13, 3], state: "minecraft:waxed_copper_grate{waterlogged:false}"},
        {pos: [2, 13, 4], state: "minecraft:tuff_bricks"},
        {pos: [3, 13, 0], state: "minecraft:waxed_copper_grate{waterlogged:false}"},
        {pos: [3, 13, 1], state: "minecraft:waxed_copper_grate{waterlogged:false}"},
        {pos: [3, 13, 2], state: "minecraft:waxed_copper_grate{waterlogged:false}"},
        {pos: [3, 13, 3], state: "minecraft:waxed_copper_grate{waterlogged:false}"},
        {pos: [3, 13, 4], state: "minecraft:waxed_copper_grate{waterlogged:false}"},
        {pos: [4, 13, 0], state: "minecraft:waxed_copper_grate{waterlogged:false}"},
        {pos: [4, 13, 1], state: "minecraft:waxed_copper_grate{waterlogged:false}"},
        {pos: [4, 13, 2], state: "minecraft:waxed_copper_grate{waterlogged:false}"},
        {pos: [4, 13, 3], state: "minecraft:waxed_copper_grate{waterlogged:false}"},
        {pos: [4, 13, 4], state: "minecraft:waxed_copper_grate{waterlogged:false}"},
        {pos: [6, 13, 0], state: "minecraft:tuff_bricks"},
        {pos: [6, 13, 4], state: "minecraft:tuff_bricks"},
        {pos: [7, 13, 0], state: "minecraft:tuff_bricks"},
        {pos: [7, 13, 4], state: "minecraft:tuff_bricks"},
        {pos: [11, 13, 0], state: "minecraft:tuff_bricks"},
        {pos: [11, 13, 1], state: "minecraft:tuff_bricks"},
        {pos: [11, 13, 2], state: "minecraft:tuff_bricks"},
        {pos: [11, 13, 3], state: "minecraft:tuff_bricks"},
        {pos: [11, 13, 4], state: "minecraft:tuff_bricks"},
        {pos: [12, 13, 0], state: "minecraft:tuff_bricks"},
        {pos: [12, 13, 1], state: "minecraft:tuff_bricks"},
        {pos: [12, 13, 2], state: "minecraft:tuff_bricks"},
        {pos: [12, 13, 3], state: "minecraft:tuff_bricks"},
        {pos: [12, 13, 4], state: "minecraft:tuff_bricks"},
        {pos: [13, 13, 0], state: "minecraft:tuff_bricks"},
        {pos: [13, 13, 1], state: "minecraft:tuff_bricks"},
        {pos: [13, 13, 2], state: "minecraft:tuff_bricks"},
        {pos: [13, 13, 3], state: "minecraft:tuff_bricks"},
        {pos: [13, 13, 4], state: "minecraft:tuff_bricks"},
        {pos: [14, 13, 0], state: "minecraft:tuff_bricks"},
        {pos: [14, 13, 1], state: "minecraft:tuff_bricks"},
        {pos: [14, 13, 2], state: "minecraft:tuff_bricks"},
        {pos: [14, 13, 3], state: "minecraft:tuff_bricks"},
        {pos: [14, 13, 4], state: "minecraft:tuff_bricks"},
        {pos: [15, 13, 0], state: "minecraft:tuff_bricks"},
        {pos: [15, 13, 1], state: "minecraft:tuff_bricks"},
        {pos: [15, 13, 2], state: "minecraft:tuff_bricks"},
        {pos: [15, 13, 3], state: "minecraft:tuff_bricks"},
        {pos: [15, 13, 4], state: "minecraft:tuff_bricks"},
        {pos: [16, 13, 0], state: "minecraft:tuff_bricks"},
        {pos: [16, 13, 1], state: "minecraft:tuff_bricks"},
        {pos: [16, 13, 2], state: "minecraft:tuff_bricks"},
        {pos: [16, 13, 3], state: "minecraft:tuff_bricks"},
        {pos: [16, 13, 4], state: "minecraft:tuff_bricks"},
        {pos: [17, 13, 0], state: "minecraft:tuff_bricks"},
        {pos: [17, 13, 1], state: "minecraft:tuff_bricks"},
        {pos: [17, 13, 2], state: "minecraft:tuff_bricks"},
        {pos: [17, 13, 3], state: "minecraft:tuff_bricks"},
        {pos: [17, 13, 4], state: "minecraft:tuff_bricks"},
        {pos: [18, 13, 0], state: "minecraft:tuff_bricks"},
        {pos: [18, 13, 1], state: "minecraft:tuff_bricks"},
        {pos: [18, 13, 2], state: "minecraft:tuff_bricks"},
        {pos: [18, 13, 3], state: "minecraft:tuff_bricks"},
        {pos: [18, 13, 4], state: "minecraft:tuff_bricks"},
        {pos: [0, 14, 0], state: "minecraft:tuff_bricks"},
        {pos: [0, 14, 1], state: "minecraft:tuff_bricks"},
        {pos: [0, 14, 2], state: "minecraft:tuff_bricks"},
        {pos: [0, 14, 3], state: "minecraft:tuff_bricks"},
        {pos: [0, 14, 4], state: "minecraft:tuff_bricks"},
        {pos: [1, 14, 0], state: "minecraft:waxed_copper_block"},
        {pos: [1, 14, 1], state: "minecraft:waxed_copper_block"},
        {pos: [1, 14, 2], state: "minecraft:waxed_copper_block"},
        {pos: [1, 14, 3], state: "minecraft:waxed_copper_block"},
        {pos: [1, 14, 4], state: "minecraft:waxed_copper_block"},
        {pos: [2, 14, 0], state: "minecraft:waxed_copper_block"},
        {pos: [2, 14, 4], state: "minecraft:waxed_copper_block"},
        {pos: [6, 14, 0], state: "minecraft:waxed_copper_block"},
        {pos: [6, 14, 4], state: "minecraft:waxed_copper_block"},
        {pos: [7, 14, 0], state: "minecraft:waxed_copper_block"},
        {pos: [7, 14, 4], state: "minecraft:waxed_copper_block"},
        {pos: [11, 14, 0], state: "minecraft:waxed_copper_block"},
        {pos: [11, 14, 1], state: "minecraft:waxed_copper_block"},
        {pos: [11, 14, 2], state: "minecraft:waxed_copper_block"},
        {pos: [11, 14, 3], state: "minecraft:waxed_copper_block"},
        {pos: [11, 14, 4], state: "minecraft:waxed_copper_block"},
        {pos: [12, 14, 0], state: "minecraft:waxed_copper_block"},
        {pos: [12, 14, 1], state: "minecraft:waxed_copper_block"},
        {pos: [12, 14, 2], state: "minecraft:waxed_copper_block"},
        {pos: [12, 14, 3], state: "minecraft:waxed_copper_block"},
        {pos: [12, 14, 4], state: "minecraft:waxed_copper_block"},
        {pos: [13, 14, 0], state: "minecraft:waxed_copper_block"},
        {pos: [13, 14, 1], state: "minecraft:tuff_bricks"},
        {pos: [13, 14, 2], state: "minecraft:tuff_bricks"},
        {pos: [13, 14, 3], state: "minecraft:tuff_bricks"},
        {pos: [13, 14, 4], state: "minecraft:waxed_copper_block"},
        {pos: [14, 14, 0], state: "minecraft:waxed_copper_block"},
        {pos: [14, 14, 1], state: "minecraft:tuff_bricks"},
        {pos: [14, 14, 2], state: "minecraft:tuff_bricks"},
        {pos: [14, 14, 3], state: "minecraft:tuff_bricks"},
        {pos: [14, 14, 4], state: "minecraft:waxed_copper_block"},
        {pos: [15, 14, 0], state: "minecraft:waxed_copper_block"},
        {pos: [15, 14, 1], state: "minecraft:tuff_bricks"},
        {pos: [15, 14, 2], state: "minecraft:tuff_bricks"},
        {pos: [15, 14, 3], state: "minecraft:tuff_bricks"},
        {pos: [15, 14, 4], state: "minecraft:waxed_copper_block"},
        {pos: [16, 14, 0], state: "minecraft:waxed_copper_block"},
        {pos: [16, 14, 1], state: "minecraft:tuff_bricks"},
        {pos: [16, 14, 2], state: "minecraft:tuff_bricks"},
        {pos: [16, 14, 3], state: "minecraft:tuff_bricks"},
        {pos: [16, 14, 4], state: "minecraft:waxed_copper_block"},
        {pos: [17, 14, 0], state: "minecraft:tuff_bricks"},
        {pos: [17, 14, 1], state: "minecraft:tuff_bricks"},
        {pos: [17, 14, 2], state: "minecraft:tuff_bricks"},
        {pos: [17, 14, 3], state: "minecraft:tuff_bricks"},
        {pos: [17, 14, 4], state: "minecraft:tuff_bricks"},
        {pos: [18, 14, 0], state: "minecraft:tuff_bricks"},
        {pos: [18, 14, 1], state: "minecraft:tuff_bricks"},
        {pos: [18, 14, 2], state: "minecraft:tuff_bricks"},
        {pos: [18, 14, 3], state: "minecraft:tuff_bricks"},
        {pos: [18, 14, 4], state: "minecraft:tuff_bricks"},
        {pos: [0, 15, 0], state: "minecraft:tuff_bricks"},
        {pos: [0, 15, 1], state: "minecraft:tuff_bricks"},
        {pos: [0, 15, 2], state: "minecraft:tuff_bricks"},
        {pos: [0, 15, 3], state: "minecraft:tuff_bricks"},
        {pos: [0, 15, 4], state: "minecraft:tuff_bricks"},
        {pos: [1, 15, 0], state: "minecraft:tuff_bricks"},
        {pos: [1, 15, 1], state: "minecraft:tuff_bricks"},
        {pos: [1, 15, 2], state: "minecraft:waxed_copper_bulb{powered:false,lit:true}"},
        {pos: [1, 15, 3], state: "minecraft:tuff_bricks"},
        {pos: [1, 15, 4], state: "minecraft:tuff_bricks"},
        {pos: [2, 15, 0], state: "minecraft:tuff_bricks"},
        {pos: [2, 15, 4], state: "minecraft:tuff_bricks"},
        {pos: [6, 15, 0], state: "minecraft:tuff_bricks"},
        {pos: [6, 15, 4], state: "minecraft:tuff_bricks"},
        {pos: [7, 15, 0], state: "minecraft:tuff_bricks"},
        {pos: [7, 15, 4], state: "minecraft:tuff_bricks"},
        {pos: [11, 15, 0], state: "minecraft:tuff_bricks"},
        {pos: [11, 15, 1], state: "minecraft:tuff_bricks"},
        {pos: [11, 15, 2], state: "minecraft:tuff_bricks"},
        {pos: [11, 15, 3], state: "minecraft:tuff_bricks"},
        {pos: [11, 15, 4], state: "minecraft:tuff_bricks"},
        {pos: [12, 15, 0], state: "minecraft:tuff_bricks"},
        {pos: [12, 15, 1], state: "minecraft:tuff_bricks"},
        {pos: [12, 15, 2], state: "minecraft:tuff_bricks"},
        {pos: [12, 15, 3], state: "minecraft:tuff_bricks"},
        {pos: [12, 15, 4], state: "minecraft:tuff_bricks"},
        {pos: [13, 15, 0], state: "minecraft:tuff_bricks"},
        {pos: [13, 15, 1], state: "minecraft:tuff_bricks"},
        {pos: [13, 15, 2], state: "minecraft:tuff_bricks"},
        {pos: [13, 15, 3], state: "minecraft:tuff_bricks"},
        {pos: [13, 15, 4], state: "minecraft:tuff_bricks"},
        {pos: [14, 15, 0], state: "minecraft:tuff_bricks"},
        {pos: [14, 15, 1], state: "minecraft:tuff_bricks"},
        {pos: [14, 15, 2], state: "minecraft:tuff_bricks"},
        {pos: [14, 15, 3], state: "minecraft:tuff_bricks"},
        {pos: [14, 15, 4], state: "minecraft:tuff_bricks"},
        {pos: [15, 15, 0], state: "minecraft:tuff_bricks"},
        {pos: [15, 15, 1], state: "minecraft:tuff_bricks"},
        {pos: [15, 15, 2], state: "minecraft:tuff_bricks"},
        {pos: [15, 15, 3], state: "minecraft:tuff_bricks"},
        {pos: [15, 15, 4], state: "minecraft:tuff_bricks"},
        {pos: [16, 15, 0], state: "minecraft:tuff_bricks"},
        {pos: [16, 15, 1], state: "minecraft:tuff_bricks"},
        {pos: [16, 15, 2], state: "minecraft:tuff_bricks"},
        {pos: [16, 15, 3], state: "minecraft:tuff_bricks"},
        {pos: [16, 15, 4], state: "minecraft:tuff_bricks"},
        {pos: [17, 15, 0], state: "minecraft:tuff_bricks"},
        {pos: [17, 15, 1], state: "minecraft:tuff_bricks"},
        {pos: [17, 15, 2], state: "minecraft:tuff_bricks"},
        {pos: [17, 15, 3], state: "minecraft:tuff_bricks"},
        {pos: [17, 15, 4], state: "minecraft:tuff_bricks"},
        {pos: [18, 15, 0], state: "minecraft:tuff_bricks"},
        {pos: [18, 15, 1], state: "minecraft:tuff_bricks"},
        {pos: [18, 15, 2], state: "minecraft:tuff_bricks"},
        {pos: [18, 15, 3], state: "minecraft:tuff_bricks"},
        {pos: [18, 15, 4], state: "minecraft:tuff_bricks"},
        {pos: [0, 16, 0], state: "minecraft:tuff_bricks"},
        {pos: [0, 16, 1], state: "minecraft:tuff_bricks"},
        {pos: [0, 16, 2], state: "minecraft:tuff_bricks"},
        {pos: [0, 16, 3], state: "minecraft:tuff_bricks"},
        {pos: [0, 16, 4], state: "minecraft:tuff_bricks"},
        {pos: [1, 16, 0], state: "minecraft:chiseled_tuff_bricks"},
        {pos: [1, 16, 1], state: "minecraft:chiseled_tuff_bricks"},
        {pos: [1, 16, 2], state: "minecraft:chiseled_tuff_bricks"},
        {pos: [1, 16, 3], state: "minecraft:chiseled_tuff_bricks"},
        {pos: [1, 16, 4], state: "minecraft:chiseled_tuff_bricks"},
        {pos: [2, 16, 0], state: "minecraft:chiseled_tuff_bricks"},
        {pos: [2, 16, 4], state: "minecraft:chiseled_tuff_bricks"},
        {pos: [6, 16, 0], state: "minecraft:chiseled_tuff_bricks"},
        {pos: [6, 16, 4], state: "minecraft:chiseled_tuff_bricks"},
        {pos: [7, 16, 0], state: "minecraft:chiseled_tuff_bricks"},
        {pos: [7, 16, 4], state: "minecraft:chiseled_tuff_bricks"},
        {pos: [11, 16, 0], state: "minecraft:chiseled_tuff_bricks"},
        {pos: [11, 16, 1], state: "minecraft:chiseled_tuff_bricks"},
        {pos: [11, 16, 2], state: "minecraft:chiseled_tuff_bricks"},
        {pos: [11, 16, 3], state: "minecraft:chiseled_tuff_bricks"},
        {pos: [11, 16, 4], state: "minecraft:chiseled_tuff_bricks"},
        {pos: [12, 16, 0], state: "minecraft:chiseled_tuff_bricks"},
        {pos: [12, 16, 1], state: "minecraft:chiseled_tuff_bricks"},
        {pos: [12, 16, 2], state: "minecraft:chiseled_tuff_bricks"},
        {pos: [12, 16, 3], state: "minecraft:chiseled_tuff_bricks"},
        {pos: [12, 16, 4], state: "minecraft:chiseled_tuff_bricks"},
        {pos: [13, 16, 0], state: "minecraft:chiseled_tuff_bricks"},
        {pos: [13, 16, 1], state: "minecraft:tuff_bricks"},
        {pos: [13, 16, 2], state: "minecraft:tuff_bricks"},
        {pos: [13, 16, 3], state: "minecraft:tuff_bricks"},
        {pos: [13, 16, 4], state: "minecraft:chiseled_tuff_bricks"},
        {pos: [14, 16, 0], state: "minecraft:chiseled_tuff_bricks"},
        {pos: [14, 16, 1], state: "minecraft:tuff_bricks"},
        {pos: [14, 16, 2], state: "minecraft:tuff_bricks"},
        {pos: [14, 16, 3], state: "minecraft:tuff_bricks"},
        {pos: [14, 16, 4], state: "minecraft:chiseled_tuff_bricks"},
        {pos: [15, 16, 0], state: "minecraft:chiseled_tuff_bricks"},
        {pos: [15, 16, 1], state: "minecraft:tuff_bricks"},
        {pos: [15, 16, 2], state: "minecraft:tuff_bricks"},
        {pos: [15, 16, 3], state: "minecraft:tuff_bricks"},
        {pos: [15, 16, 4], state: "minecraft:chiseled_tuff_bricks"},
        {pos: [16, 16, 0], state: "minecraft:chiseled_tuff_bricks"},
        {pos: [16, 16, 1], state: "minecraft:tuff_bricks"},
        {pos: [16, 16, 2], state: "minecraft:tuff_bricks"},
        {pos: [16, 16, 3], state: "minecraft:tuff_bricks"},
        {pos: [16, 16, 4], state: "minecraft:chiseled_tuff_bricks"},
        {pos: [17, 16, 0], state: "minecraft:tuff_bricks"},
        {pos: [17, 16, 1], state: "minecraft:tuff_bricks"},
        {pos: [17, 16, 2], state: "minecraft:tuff_bricks"},
        {pos: [17, 16, 3], state: "minecraft:tuff_bricks"},
        {pos: [17, 16, 4], state: "minecraft:tuff_bricks"},
        {pos: [18, 16, 0], state: "minecraft:tuff_bricks"},
        {pos: [18, 16, 1], state: "minecraft:tuff_bricks"},
        {pos: [18, 16, 2], state: "minecraft:tuff_bricks"},
        {pos: [18, 16, 3], state: "minecraft:tuff_bricks"},
        {pos: [18, 16, 4], state: "minecraft:tuff_bricks"},
        {pos: [0, 17, 0], state: "minecraft:tuff_bricks"},
        {pos: [0, 17, 1], state: "minecraft:tuff_bricks"},
        {pos: [0, 17, 2], state: "minecraft:tuff_bricks"},
        {pos: [0, 17, 3], state: "minecraft:tuff_bricks"},
        {pos: [0, 17, 4], state: "minecraft:tuff_bricks"},
        {pos: [1, 17, 0], state: "minecraft:tuff_bricks"},
        {pos: [1, 17, 1], state: "minecraft:tuff_bricks"},
        {pos: [1, 17, 2], state: "minecraft:tuff_bricks"},
        {pos: [1, 17, 3], state: "minecraft:tuff_bricks"},
        {pos: [1, 17, 4], state: "minecraft:tuff_bricks"},
        {pos: [2, 17, 0], state: "minecraft:tuff_bricks"},
        {pos: [2, 17, 1], state: "minecraft:polished_tuff"},
        {pos: [2, 17, 2], state: "minecraft:polished_tuff"},
        {pos: [2, 17, 3], state: "minecraft:polished_tuff"},
        {pos: [2, 17, 4], state: "minecraft:tuff_bricks"},
        {pos: [3, 17, 0], state: "minecraft:polished_tuff"},
        {pos: [3, 17, 1], state: "minecraft:polished_tuff"},
        {pos: [3, 17, 2], state: "minecraft:polished_tuff"},
        {pos: [3, 17, 3], state: "minecraft:polished_tuff"},
        {pos: [3, 17, 4], state: "minecraft:polished_tuff"},
        {pos: [4, 17, 0], state: "minecraft:polished_tuff"},
        {pos: [4, 17, 1], state: "minecraft:polished_tuff"},
        {pos: [4, 17, 2], state: "minecraft:polished_tuff"},
        {pos: [4, 17, 3], state: "minecraft:polished_tuff"},
        {pos: [4, 17, 4], state: "minecraft:polished_tuff"},
        {pos: [5, 17, 0], state: "minecraft:polished_tuff"},
        {pos: [5, 17, 1], state: "minecraft:polished_tuff"},
        {pos: [5, 17, 2], state: "minecraft:polished_tuff"},
        {pos: [5, 17, 3], state: "minecraft:polished_tuff"},
        {pos: [5, 17, 4], state: "minecraft:polished_tuff"},
        {pos: [6, 17, 0], state: "minecraft:tuff_bricks"},
        {pos: [6, 17, 1], state: "minecraft:polished_tuff"},
        {pos: [6, 17, 2], state: "minecraft:polished_tuff"},
        {pos: [6, 17, 3], state: "minecraft:polished_tuff"},
        {pos: [6, 17, 4], state: "minecraft:tuff_bricks"},
        {pos: [7, 17, 0], state: "minecraft:tuff_bricks"},
        {pos: [7, 17, 1], state: "minecraft:polished_tuff"},
        {pos: [7, 17, 2], state: "minecraft:polished_tuff"},
        {pos: [7, 17, 3], state: "minecraft:polished_tuff"},
        {pos: [7, 17, 4], state: "minecraft:tuff_bricks"},
        {pos: [8, 17, 0], state: "minecraft:polished_tuff"},
        {pos: [8, 17, 1], state: "minecraft:polished_tuff"},
        {pos: [8, 17, 2], state: "minecraft:polished_tuff"},
        {pos: [8, 17, 3], state: "minecraft:polished_tuff"},
        {pos: [8, 17, 4], state: "minecraft:polished_tuff"},
        {pos: [9, 17, 0], state: "minecraft:polished_tuff"},
        {pos: [9, 17, 1], state: "minecraft:polished_tuff"},
        {pos: [9, 17, 2], state: "minecraft:polished_tuff"},
        {pos: [9, 17, 3], state: "minecraft:polished_tuff"},
        {pos: [9, 17, 4], state: "minecraft:polished_tuff"},
        {pos: [10, 17, 0], state: "minecraft:polished_tuff"},
        {pos: [10, 17, 1], state: "minecraft:polished_tuff"},
        {pos: [10, 17, 2], state: "minecraft:polished_tuff"},
        {pos: [10, 17, 3], state: "minecraft:polished_tuff"},
        {pos: [10, 17, 4], state: "minecraft:polished_tuff"},
        {pos: [11, 17, 0], state: "minecraft:tuff_bricks"},
        {pos: [11, 17, 1], state: "minecraft:tuff_bricks"},
        {pos: [11, 17, 2], state: "minecraft:tuff_bricks"},
        {pos: [11, 17, 3], state: "minecraft:tuff_bricks"},
        {pos: [11, 17, 4], state: "minecraft:tuff_bricks"},
        {pos: [12, 17, 0], state: "minecraft:tuff_bricks"},
        {pos: [12, 17, 1], state: "minecraft:tuff_bricks"},
        {pos: [12, 17, 2], state: "minecraft:tuff_bricks"},
        {pos: [12, 17, 3], state: "minecraft:tuff_bricks"},
        {pos: [12, 17, 4], state: "minecraft:tuff_bricks"},
        {pos: [13, 17, 0], state: "minecraft:tuff_bricks"},
        {pos: [13, 17, 1], state: "minecraft:tuff_bricks"},
        {pos: [13, 17, 2], state: "minecraft:tuff_bricks"},
        {pos: [13, 17, 3], state: "minecraft:tuff_bricks"},
        {pos: [13, 17, 4], state: "minecraft:tuff_bricks"},
        {pos: [14, 17, 0], state: "minecraft:tuff_bricks"},
        {pos: [14, 17, 1], state: "minecraft:tuff_bricks"},
        {pos: [14, 17, 2], state: "minecraft:tuff_bricks"},
        {pos: [14, 17, 3], state: "minecraft:tuff_bricks"},
        {pos: [14, 17, 4], state: "minecraft:tuff_bricks"},
        {pos: [15, 17, 0], state: "minecraft:tuff_bricks"},
        {pos: [15, 17, 1], state: "minecraft:tuff_bricks"},
        {pos: [15, 17, 2], state: "minecraft:tuff_bricks"},
        {pos: [15, 17, 3], state: "minecraft:tuff_bricks"},
        {pos: [15, 17, 4], state: "minecraft:tuff_bricks"},
        {pos: [16, 17, 0], state: "minecraft:tuff_bricks"},
        {pos: [16, 17, 1], state: "minecraft:tuff_bricks"},
        {pos: [16, 17, 2], state: "minecraft:tuff_bricks"},
        {pos: [16, 17, 3], state: "minecraft:tuff_bricks"},
        {pos: [16, 17, 4], state: "minecraft:tuff_bricks"},
        {pos: [17, 17, 0], state: "minecraft:tuff_bricks"},
        {pos: [17, 17, 1], state: "minecraft:tuff_bricks"},
        {pos: [17, 17, 2], state: "minecraft:tuff_bricks"},
        {pos: [17, 17, 3], state: "minecraft:tuff_bricks"},
        {pos: [17, 17, 4], state: "minecraft:tuff_bricks"},
        {pos: [18, 17, 0], state: "minecraft:tuff_bricks"},
        {pos: [18, 17, 1], state: "minecraft:tuff_bricks"},
        {pos: [18, 17, 2], state: "minecraft:tuff_bricks"},
        {pos: [18, 17, 3], state: "minecraft:tuff_bricks"},
        {pos: [18, 17, 4], state: "minecraft:tuff_bricks"},
        {pos: [0, 18, 0], state: "minecraft:tuff_bricks"},
        {pos: [0, 18, 1], state: "minecraft:tuff_bricks"},
        {pos: [0, 18, 2], state: "minecraft:tuff_bricks"},
        {pos: [0, 18, 3], state: "minecraft:tuff_bricks"},
        {pos: [0, 18, 4], state: "minecraft:tuff_bricks"},
        {pos: [1, 18, 0], state: "minecraft:tuff_bricks"},
        {pos: [1, 18, 1], state: "minecraft:tuff_bricks"},
        {pos: [1, 18, 2], state: "minecraft:tuff_bricks"},
        {pos: [1, 18, 3], state: "minecraft:tuff_bricks"},
        {pos: [1, 18, 4], state: "minecraft:tuff_bricks"},
        {pos: [2, 18, 0], state: "minecraft:tuff_bricks"},
        {pos: [2, 18, 1], state: "minecraft:tuff_bricks"},
        {pos: [2, 18, 2], state: "minecraft:tuff_bricks"},
        {pos: [2, 18, 3], state: "minecraft:tuff_bricks"},
        {pos: [2, 18, 4], state: "minecraft:tuff_bricks"},
        {pos: [3, 18, 0], state: "minecraft:tuff_bricks"},
        {pos: [3, 18, 1], state: "minecraft:tuff_bricks"},
        {pos: [3, 18, 2], state: "minecraft:tuff_bricks"},
        {pos: [3, 18, 3], state: "minecraft:tuff_bricks"},
        {pos: [3, 18, 4], state: "minecraft:tuff_bricks"},
        {pos: [4, 18, 0], state: "minecraft:tuff_bricks"},
        {pos: [4, 18, 1], state: "minecraft:tuff_bricks"},
        {pos: [4, 18, 2], state: "minecraft:tuff_bricks"},
        {pos: [4, 18, 3], state: "minecraft:tuff_bricks"},
        {pos: [4, 18, 4], state: "minecraft:tuff_bricks"},
        {pos: [5, 18, 0], state: "minecraft:tuff_bricks"},
        {pos: [5, 18, 1], state: "minecraft:tuff_bricks"},
        {pos: [5, 18, 2], state: "minecraft:tuff_bricks"},
        {pos: [5, 18, 3], state: "minecraft:tuff_bricks"},
        {pos: [5, 18, 4], state: "minecraft:tuff_bricks"},
        {pos: [6, 18, 0], state: "minecraft:tuff_bricks"},
        {pos: [6, 18, 1], state: "minecraft:tuff_bricks"},
        {pos: [6, 18, 2], state: "minecraft:tuff_bricks"},
        {pos: [6, 18, 3], state: "minecraft:tuff_bricks"},
        {pos: [6, 18, 4], state: "minecraft:tuff_bricks"},
        {pos: [7, 18, 0], state: "minecraft:tuff_bricks"},
        {pos: [7, 18, 1], state: "minecraft:tuff_bricks"},
        {pos: [7, 18, 2], state: "minecraft:tuff_bricks"},
        {pos: [7, 18, 3], state: "minecraft:tuff_bricks"},
        {pos: [7, 18, 4], state: "minecraft:tuff_bricks"},
        {pos: [8, 18, 0], state: "minecraft:tuff_bricks"},
        {pos: [8, 18, 1], state: "minecraft:tuff_bricks"},
        {pos: [8, 18, 2], state: "minecraft:tuff_bricks"},
        {pos: [8, 18, 3], state: "minecraft:tuff_bricks"},
        {pos: [8, 18, 4], state: "minecraft:tuff_bricks"},
        {pos: [9, 18, 0], state: "minecraft:tuff_bricks"},
        {pos: [9, 18, 1], state: "minecraft:tuff_bricks"},
        {pos: [9, 18, 2], state: "minecraft:tuff_bricks"},
        {pos: [9, 18, 3], state: "minecraft:tuff_bricks"},
        {pos: [9, 18, 4], state: "minecraft:tuff_bricks"},
        {pos: [10, 18, 0], state: "minecraft:tuff_bricks"},
        {pos: [10, 18, 1], state: "minecraft:tuff_bricks"},
        {pos: [10, 18, 2], state: "minecraft:tuff_bricks"},
        {pos: [10, 18, 3], state: "minecraft:tuff_bricks"},
        {pos: [10, 18, 4], state: "minecraft:tuff_bricks"},
        {pos: [11, 18, 0], state: "minecraft:tuff_bricks"},
        {pos: [11, 18, 1], state: "minecraft:tuff_bricks"},
        {pos: [11, 18, 2], state: "minecraft:tuff_bricks"},
        {pos: [11, 18, 3], state: "minecraft:tuff_bricks"},
        {pos: [11, 18, 4], state: "minecraft:tuff_bricks"},
        {pos: [12, 18, 0], state: "minecraft:tuff_bricks"},
        {pos: [12, 18, 1], state: "minecraft:tuff_bricks"},
        {pos: [12, 18, 2], state: "minecraft:tuff_bricks"},
        {pos: [12, 18, 3], state: "minecraft:tuff_bricks"},
        {pos: [12, 18, 4], state: "minecraft:tuff_bricks"},
        {pos: [13, 18, 0], state: "minecraft:tuff_bricks"},
        {pos: [13, 18, 1], state: "minecraft:tuff_bricks"},
        {pos: [13, 18, 2], state: "minecraft:tuff_bricks"},
        {pos: [13, 18, 3], state: "minecraft:tuff_bricks"},
        {pos: [13, 18, 4], state: "minecraft:tuff_bricks"},
        {pos: [14, 18, 0], state: "minecraft:tuff_bricks"},
        {pos: [14, 18, 1], state: "minecraft:tuff_bricks"},
        {pos: [14, 18, 2], state: "minecraft:tuff_bricks"},
        {pos: [14, 18, 3], state: "minecraft:tuff_bricks"},
        {pos: [14, 18, 4], state: "minecraft:tuff_bricks"},
        {pos: [15, 18, 0], state: "minecraft:tuff_bricks"},
        {pos: [15, 18, 1], state: "minecraft:tuff_bricks"},
        {pos: [15, 18, 2], state: "minecraft:tuff_bricks"},
        {pos: [15, 18, 3], state: "minecraft:tuff_bricks"},
        {pos: [15, 18, 4], state: "minecraft:tuff_bricks"},
        {pos: [16, 18, 0], state: "minecraft:tuff_bricks"},
        {pos: [16, 18, 1], state: "minecraft:tuff_bricks"},
        {pos: [16, 18, 2], state: "minecraft:tuff_bricks"},
        {pos: [16, 18, 3], state: "minecraft:tuff_bricks"},
        {pos: [16, 18, 4], state: "minecraft:tuff_bricks"},
        {pos: [17, 18, 0], state: "minecraft:tuff_bricks"},
        {pos: [17, 18, 1], state: "minecraft:tuff_bricks"},
        {pos: [17, 18, 2], state: "minecraft:tuff_bricks"},
        {pos: [17, 18, 3], state: "minecraft:tuff_bricks"},
        {pos: [17, 18, 4], state: "minecraft:tuff_bricks"},
        {pos: [18, 18, 0], state: "minecraft:tuff_bricks"},
        {pos: [18, 18, 1], state: "minecraft:tuff_bricks"},
        {pos: [18, 18, 2], state: "minecraft:tuff_bricks"},
        {pos: [18, 18, 3], state: "minecraft:tuff_bricks"},
        {pos: [18, 18, 4], state: "minecraft:tuff_bricks"},
        {pos: [7, 2, 1], state: "minecraft:air"},
        {pos: [7, 2, 2], state: "minecraft:air"},
        {pos: [7, 2, 3], state: "minecraft:air"},
        {pos: [8, 2, 0], state: "minecraft:air"},
        {pos: [8, 2, 1], state: "minecraft:air"},
        {pos: [8, 2, 2], state: "minecraft:air"},
        {pos: [8, 2, 3], state: "minecraft:air"},
        {pos: [8, 2, 4], state: "minecraft:air"},
        {pos: [9, 2, 0], state: "minecraft:air"},
        {pos: [9, 2, 1], state: "minecraft:air"},
        {pos: [9, 2, 2], state: "minecraft:air"},
        {pos: [9, 2, 3], state: "minecraft:air"},
        {pos: [9, 2, 4], state: "minecraft:air"},
        {pos: [10, 2, 0], state: "minecraft:air"},
        {pos: [10, 2, 1], state: "minecraft:air"},
        {pos: [10, 2, 2], state: "minecraft:air"},
        {pos: [10, 2, 3], state: "minecraft:air"},
        {pos: [10, 2, 4], state: "minecraft:air"},
        {pos: [11, 2, 1], state: "minecraft:air"},
        {pos: [11, 2, 2], state: "minecraft:air"},
        {pos: [11, 2, 3], state: "minecraft:air"},
        {pos: [7, 3, 1], state: "minecraft:air"},
        {pos: [7, 3, 2], state: "minecraft:air"},
        {pos: [7, 3, 3], state: "minecraft:air"},
        {pos: [8, 3, 0], state: "minecraft:air"},
        {pos: [8, 3, 1], state: "minecraft:air"},
        {pos: [8, 3, 2], state: "minecraft:air"},
        {pos: [8, 3, 3], state: "minecraft:air"},
        {pos: [8, 3, 4], state: "minecraft:air"},
        {pos: [9, 3, 0], state: "minecraft:air"},
        {pos: [9, 3, 1], state: "minecraft:air"},
        {pos: [9, 3, 2], state: "minecraft:air"},
        {pos: [9, 3, 3], state: "minecraft:air"},
        {pos: [9, 3, 4], state: "minecraft:air"},
        {pos: [10, 3, 0], state: "minecraft:air"},
        {pos: [10, 3, 1], state: "minecraft:air"},
        {pos: [10, 3, 2], state: "minecraft:air"},
        {pos: [10, 3, 3], state: "minecraft:air"},
        {pos: [10, 3, 4], state: "minecraft:air"},
        {pos: [11, 3, 1], state: "minecraft:air"},
        {pos: [11, 3, 2], state: "minecraft:air"},
        {pos: [11, 3, 3], state: "minecraft:air"},
        {pos: [2, 4, 1], state: "minecraft:air"},
        {pos: [2, 4, 2], state: "minecraft:air"},
        {pos: [2, 4, 3], state: "minecraft:air"},
        {pos: [3, 4, 0], state: "minecraft:air"},
        {pos: [3, 4, 1], state: "minecraft:air"},
        {pos: [3, 4, 2], state: "minecraft:air"},
        {pos: [3, 4, 3], state: "minecraft:air"},
        {pos: [3, 4, 4], state: "minecraft:air"},
        {pos: [4, 4, 0], state: "minecraft:air"},
        {pos: [4, 4, 1], state: "minecraft:air"},
        {pos: [4, 4, 2], state: "minecraft:air"},
        {pos: [4, 4, 3], state: "minecraft:air"},
        {pos: [4, 4, 4], state: "minecraft:air"},
        {pos: [5, 4, 0], state: "minecraft:air"},
        {pos: [5, 4, 1], state: "minecraft:air"},
        {pos: [5, 4, 2], state: "minecraft:air"},
        {pos: [5, 4, 3], state: "minecraft:air"},
        {pos: [5, 4, 4], state: "minecraft:air"},
        {pos: [6, 4, 1], state: "minecraft:air"},
        {pos: [6, 4, 2], state: "minecraft:air"},
        {pos: [6, 4, 3], state: "minecraft:air"},
        {pos: [7, 4, 1], state: "minecraft:air"},
        {pos: [7, 4, 2], state: "minecraft:air"},
        {pos: [7, 4, 3], state: "minecraft:air"},
        {pos: [8, 4, 0], state: "minecraft:air"},
        {pos: [8, 4, 1], state: "minecraft:air"},
        {pos: [8, 4, 2], state: "minecraft:air"},
        {pos: [8, 4, 3], state: "minecraft:air"},
        {pos: [8, 4, 4], state: "minecraft:air"},
        {pos: [9, 4, 0], state: "minecraft:air"},
        {pos: [9, 4, 1], state: "minecraft:air"},
        {pos: [9, 4, 2], state: "minecraft:air"},
        {pos: [9, 4, 3], state: "minecraft:air"},
        {pos: [9, 4, 4], state: "minecraft:air"},
        {pos: [10, 4, 0], state: "minecraft:air"},
        {pos: [10, 4, 1], state: "minecraft:air"},
        {pos: [10, 4, 2], state: "minecraft:air"},
        {pos: [10, 4, 3], state: "minecraft:air"},
        {pos: [10, 4, 4], state: "minecraft:air"},
        {pos: [11, 4, 1], state: "minecraft:air"},
        {pos: [11, 4, 2], state: "minecraft:air"},
        {pos: [11, 4, 3], state: "minecraft:air"},
        {pos: [12, 4, 1], state: "minecraft:air"},
        {pos: [12, 4, 2], state: "minecraft:air"},
        {pos: [12, 4, 3], state: "minecraft:air"},
        {pos: [13, 4, 0], state: "minecraft:air"},
        {pos: [13, 4, 1], state: "minecraft:air"},
        {pos: [13, 4, 2], state: "minecraft:air"},
        {pos: [13, 4, 3], state: "minecraft:air"},
        {pos: [13, 4, 4], state: "minecraft:air"},
        {pos: [14, 4, 0], state: "minecraft:air"},
        {pos: [14, 4, 1], state: "minecraft:air"},
        {pos: [14, 4, 2], state: "minecraft:air"},
        {pos: [14, 4, 3], state: "minecraft:air"},
        {pos: [14, 4, 4], state: "minecraft:air"},
        {pos: [15, 4, 0], state: "minecraft:air"},
        {pos: [15, 4, 1], state: "minecraft:air"},
        {pos: [15, 4, 2], state: "minecraft:air"},
        {pos: [15, 4, 3], state: "minecraft:air"},
        {pos: [15, 4, 4], state: "minecraft:air"},
        {pos: [16, 4, 1], state: "minecraft:air"},
        {pos: [16, 4, 2], state: "minecraft:air"},
        {pos: [16, 4, 3], state: "minecraft:air"},
        {pos: [2, 5, 1], state: "minecraft:air"},
        {pos: [2, 5, 2], state: "minecraft:air"},
        {pos: [2, 5, 3], state: "minecraft:air"},
        {pos: [3, 5, 0], state: "minecraft:air"},
        {pos: [3, 5, 1], state: "minecraft:air"},
        {pos: [3, 5, 2], state: "minecraft:air"},
        {pos: [3, 5, 3], state: "minecraft:air"},
        {pos: [3, 5, 4], state: "minecraft:air"},
        {pos: [4, 5, 0], state: "minecraft:air"},
        {pos: [4, 5, 1], state: "minecraft:air"},
        {pos: [4, 5, 2], state: "minecraft:air"},
        {pos: [4, 5, 3], state: "minecraft:air"},
        {pos: [4, 5, 4], state: "minecraft:air"},
        {pos: [5, 5, 0], state: "minecraft:air"},
        {pos: [5, 5, 1], state: "minecraft:air"},
        {pos: [5, 5, 2], state: "minecraft:air"},
        {pos: [5, 5, 3], state: "minecraft:air"},
        {pos: [5, 5, 4], state: "minecraft:air"},
        {pos: [6, 5, 1], state: "minecraft:air"},
        {pos: [6, 5, 2], state: "minecraft:air"},
        {pos: [6, 5, 3], state: "minecraft:air"},
        {pos: [7, 5, 1], state: "minecraft:air"},
        {pos: [7, 5, 2], state: "minecraft:air"},
        {pos: [7, 5, 3], state: "minecraft:air"},
        {pos: [8, 5, 0], state: "minecraft:air"},
        {pos: [8, 5, 1], state: "minecraft:air"},
        {pos: [8, 5, 2], state: "minecraft:air"},
        {pos: [8, 5, 3], state: "minecraft:air"},
        {pos: [8, 5, 4], state: "minecraft:air"},
        {pos: [9, 5, 0], state: "minecraft:air"},
        {pos: [9, 5, 1], state: "minecraft:air"},
        {pos: [9, 5, 2], state: "minecraft:air"},
        {pos: [9, 5, 3], state: "minecraft:air"},
        {pos: [9, 5, 4], state: "minecraft:air"},
        {pos: [10, 5, 0], state: "minecraft:air"},
        {pos: [10, 5, 1], state: "minecraft:air"},
        {pos: [10, 5, 2], state: "minecraft:air"},
        {pos: [10, 5, 3], state: "minecraft:air"},
        {pos: [10, 5, 4], state: "minecraft:air"},
        {pos: [11, 5, 1], state: "minecraft:air"},
        {pos: [11, 5, 2], state: "minecraft:air"},
        {pos: [11, 5, 3], state: "minecraft:air"},
        {pos: [12, 5, 1], state: "minecraft:air"},
        {pos: [12, 5, 2], state: "minecraft:air"},
        {pos: [12, 5, 3], state: "minecraft:air"},
        {pos: [13, 5, 0], state: "minecraft:air"},
        {pos: [13, 5, 1], state: "minecraft:air"},
        {pos: [13, 5, 2], state: "minecraft:air"},
        {pos: [13, 5, 3], state: "minecraft:air"},
        {pos: [13, 5, 4], state: "minecraft:air"},
        {pos: [14, 5, 0], state: "minecraft:air"},
        {pos: [14, 5, 1], state: "minecraft:air"},
        {pos: [14, 5, 2], state: "minecraft:air"},
        {pos: [14, 5, 3], state: "minecraft:air"},
        {pos: [14, 5, 4], state: "minecraft:air"},
        {pos: [15, 5, 0], state: "minecraft:air"},
        {pos: [15, 5, 1], state: "minecraft:air"},
        {pos: [15, 5, 2], state: "minecraft:air"},
        {pos: [15, 5, 3], state: "minecraft:air"},
        {pos: [15, 5, 4], state: "minecraft:air"},
        {pos: [16, 5, 1], state: "minecraft:air"},
        {pos: [16, 5, 2], state: "minecraft:air"},
        {pos: [16, 5, 3], state: "minecraft:air"},
        {pos: [2, 6, 1], state: "minecraft:air"},
        {pos: [2, 6, 2], state: "minecraft:air"},
        {pos: [2, 6, 3], state: "minecraft:air"},
        {pos: [3, 6, 0], state: "minecraft:air"},
        {pos: [3, 6, 1], state: "minecraft:air"},
        {pos: [3, 6, 2], state: "minecraft:air"},
        {pos: [3, 6, 3], state: "minecraft:air"},
        {pos: [3, 6, 4], state: "minecraft:air"},
        {pos: [4, 6, 0], state: "minecraft:air"},
        {pos: [4, 6, 1], state: "minecraft:air"},
        {pos: [4, 6, 2], state: "minecraft:air"},
        {pos: [4, 6, 3], state: "minecraft:air"},
        {pos: [4, 6, 4], state: "minecraft:air"},
        {pos: [5, 6, 0], state: "minecraft:air"},
        {pos: [5, 6, 1], state: "minecraft:air"},
        {pos: [5, 6, 2], state: "minecraft:air"},
        {pos: [5, 6, 3], state: "minecraft:air"},
        {pos: [5, 6, 4], state: "minecraft:air"},
        {pos: [6, 6, 1], state: "minecraft:air"},
        {pos: [6, 6, 2], state: "minecraft:air"},
        {pos: [6, 6, 3], state: "minecraft:air"},
        {pos: [7, 6, 1], state: "minecraft:air"},
        {pos: [7, 6, 2], state: "minecraft:air"},
        {pos: [7, 6, 3], state: "minecraft:air"},
        {pos: [8, 6, 0], state: "minecraft:air"},
        {pos: [8, 6, 1], state: "minecraft:air"},
        {pos: [8, 6, 2], state: "minecraft:air"},
        {pos: [8, 6, 3], state: "minecraft:air"},
        {pos: [8, 6, 4], state: "minecraft:air"},
        {pos: [9, 6, 0], state: "minecraft:air"},
        {pos: [9, 6, 1], state: "minecraft:air"},
        {pos: [9, 6, 2], state: "minecraft:air"},
        {pos: [9, 6, 3], state: "minecraft:air"},
        {pos: [9, 6, 4], state: "minecraft:air"},
        {pos: [10, 6, 0], state: "minecraft:air"},
        {pos: [10, 6, 1], state: "minecraft:air"},
        {pos: [10, 6, 2], state: "minecraft:air"},
        {pos: [10, 6, 3], state: "minecraft:air"},
        {pos: [10, 6, 4], state: "minecraft:air"},
        {pos: [11, 6, 1], state: "minecraft:air"},
        {pos: [11, 6, 2], state: "minecraft:air"},
        {pos: [11, 6, 3], state: "minecraft:air"},
        {pos: [12, 6, 1], state: "minecraft:air"},
        {pos: [12, 6, 2], state: "minecraft:air"},
        {pos: [12, 6, 3], state: "minecraft:air"},
        {pos: [13, 6, 0], state: "minecraft:air"},
        {pos: [13, 6, 1], state: "minecraft:air"},
        {pos: [13, 6, 2], state: "minecraft:air"},
        {pos: [13, 6, 3], state: "minecraft:air"},
        {pos: [13, 6, 4], state: "minecraft:air"},
        {pos: [14, 6, 0], state: "minecraft:air"},
        {pos: [14, 6, 1], state: "minecraft:air"},
        {pos: [14, 6, 2], state: "minecraft:air"},
        {pos: [14, 6, 3], state: "minecraft:air"},
        {pos: [14, 6, 4], state: "minecraft:air"},
        {pos: [15, 6, 0], state: "minecraft:air"},
        {pos: [15, 6, 1], state: "minecraft:air"},
        {pos: [15, 6, 2], state: "minecraft:air"},
        {pos: [15, 6, 3], state: "minecraft:air"},
        {pos: [15, 6, 4], state: "minecraft:air"},
        {pos: [16, 6, 1], state: "minecraft:air"},
        {pos: [16, 6, 2], state: "minecraft:air"},
        {pos: [16, 6, 3], state: "minecraft:air"},
        {pos: [4, 7, 2], state: "minecraft:air"},
        {pos: [8, 7, 0], state: "minecraft:air"},
        {pos: [8, 7, 1], state: "minecraft:air"},
        {pos: [8, 7, 2], state: "minecraft:air"},
        {pos: [8, 7, 3], state: "minecraft:air"},
        {pos: [8, 7, 4], state: "minecraft:air"},
        {pos: [9, 7, 0], state: "minecraft:air"},
        {pos: [9, 7, 1], state: "minecraft:air"},
        {pos: [9, 7, 2], state: "minecraft:air"},
        {pos: [9, 7, 3], state: "minecraft:air"},
        {pos: [9, 7, 4], state: "minecraft:air"},
        {pos: [10, 7, 0], state: "minecraft:air"},
        {pos: [10, 7, 1], state: "minecraft:air"},
        {pos: [10, 7, 2], state: "minecraft:air"},
        {pos: [10, 7, 3], state: "minecraft:air"},
        {pos: [10, 7, 4], state: "minecraft:air"},
        {pos: [8, 8, 0], state: "minecraft:air"},
        {pos: [8, 8, 1], state: "minecraft:air"},
        {pos: [8, 8, 2], state: "minecraft:air"},
        {pos: [8, 8, 3], state: "minecraft:air"},
        {pos: [8, 8, 4], state: "minecraft:air"},
        {pos: [9, 8, 0], state: "minecraft:air"},
        {pos: [9, 8, 1], state: "minecraft:air"},
        {pos: [9, 8, 2], state: "minecraft:air"},
        {pos: [9, 8, 3], state: "minecraft:air"},
        {pos: [9, 8, 4], state: "minecraft:air"},
        {pos: [10, 8, 0], state: "minecraft:air"},
        {pos: [10, 8, 1], state: "minecraft:air"},
        {pos: [10, 8, 2], state: "minecraft:air"},
        {pos: [10, 8, 3], state: "minecraft:air"},
        {pos: [10, 8, 4], state: "minecraft:air"},
        {pos: [0, 9, 1], state: "minecraft:air"},
        {pos: [0, 9, 2], state: "minecraft:air"},
        {pos: [0, 9, 3], state: "minecraft:air"},
        {pos: [1, 9, 2], state: "minecraft:waxed_oxidized_copper_door{hinge:right,half:lower,powered:false,facing:west,open:false}"},
        {pos: [2, 9, 1], state: "minecraft:air"},
        {pos: [2, 9, 2], state: "minecraft:air"},
        {pos: [2, 9, 3], state: "minecraft:air"},
        {pos: [3, 9, 0], state: "minecraft:air"},
        {pos: [3, 9, 1], state: "minecraft:air"},
        {pos: [3, 9, 2], state: "minecraft:air"},
        {pos: [3, 9, 3], state: "minecraft:air"},
        {pos: [3, 9, 4], state: "minecraft:air"},
        {pos: [4, 9, 0], state: "minecraft:air"},
        {pos: [4, 9, 1], state: "minecraft:air"},
        {pos: [4, 9, 2], state: "minecraft:air"},
        {pos: [4, 9, 3], state: "minecraft:air"},
        {pos: [4, 9, 4], state: "minecraft:air"},
        {pos: [5, 9, 0], state: "minecraft:air"},
        {pos: [5, 9, 1], state: "minecraft:air"},
        {pos: [5, 9, 2], state: "minecraft:air"},
        {pos: [5, 9, 3], state: "minecraft:air"},
        {pos: [5, 9, 4], state: "minecraft:air"},
        {pos: [6, 9, 1], state: "minecraft:air"},
        {pos: [6, 9, 2], state: "minecraft:air"},
        {pos: [6, 9, 3], state: "minecraft:air"},
        {pos: [7, 9, 1], state: "minecraft:air"},
        {pos: [7, 9, 2], state: "minecraft:air"},
        {pos: [7, 9, 3], state: "minecraft:air"},
        {pos: [8, 9, 0], state: "minecraft:air"},
        {pos: [8, 9, 1], state: "minecraft:air"},
        {pos: [8, 9, 2], state: "minecraft:air"},
        {pos: [8, 9, 3], state: "minecraft:air"},
        {pos: [8, 9, 4], state: "minecraft:air"},
        {pos: [9, 9, 0], state: "minecraft:air"},
        {pos: [9, 9, 1], state: "minecraft:air"},
        {pos: [9, 9, 2], state: "minecraft:air"},
        {pos: [9, 9, 3], state: "minecraft:air"},
        {pos: [9, 9, 4], state: "minecraft:air"},
        {pos: [10, 9, 0], state: "minecraft:air"},
        {pos: [10, 9, 1], state: "minecraft:air"},
        {pos: [10, 9, 2], state: "minecraft:air"},
        {pos: [10, 9, 3], state: "minecraft:air"},
        {pos: [10, 9, 4], state: "minecraft:air"},
        {pos: [0, 10, 1], state: "minecraft:air"},
        {pos: [0, 10, 3], state: "minecraft:air"},
        {pos: [1, 10, 2], state: "minecraft:waxed_oxidized_copper_door{hinge:right,half:upper,powered:false,facing:west,open:false}"},
        {pos: [2, 10, 1], state: "minecraft:air"},
        {pos: [2, 10, 2], state: "minecraft:air"},
        {pos: [2, 10, 3], state: "minecraft:air"},
        {pos: [3, 10, 0], state: "minecraft:air"},
        {pos: [3, 10, 1], state: "minecraft:air"},
        {pos: [3, 10, 2], state: "minecraft:air"},
        {pos: [3, 10, 3], state: "minecraft:air"},
        {pos: [3, 10, 4], state: "minecraft:air"},
        {pos: [4, 10, 0], state: "minecraft:air"},
        {pos: [4, 10, 1], state: "minecraft:air"},
        {pos: [4, 10, 2], state: "minecraft:air"},
        {pos: [4, 10, 3], state: "minecraft:air"},
        {pos: [4, 10, 4], state: "minecraft:air"},
        {pos: [5, 10, 0], state: "minecraft:air"},
        {pos: [5, 10, 1], state: "minecraft:air"},
        {pos: [5, 10, 2], state: "minecraft:air"},
        {pos: [5, 10, 3], state: "minecraft:air"},
        {pos: [5, 10, 4], state: "minecraft:air"},
        {pos: [6, 10, 1], state: "minecraft:air"},
        {pos: [6, 10, 2], state: "minecraft:air"},
        {pos: [6, 10, 3], state: "minecraft:air"},
        {pos: [7, 10, 1], state: "minecraft:air"},
        {pos: [7, 10, 2], state: "minecraft:air"},
        {pos: [7, 10, 3], state: "minecraft:air"},
        {pos: [8, 10, 0], state: "minecraft:air"},
        {pos: [8, 10, 1], state: "minecraft:air"},
        {pos: [8, 10, 2], state: "minecraft:air"},
        {pos: [8, 10, 3], state: "minecraft:air"},
        {pos: [8, 10, 4], state: "minecraft:air"},
        {pos: [9, 10, 0], state: "minecraft:air"},
        {pos: [9, 10, 1], state: "minecraft:air"},
        {pos: [9, 10, 2], state: "minecraft:air"},
        {pos: [9, 10, 3], state: "minecraft:air"},
        {pos: [9, 10, 4], state: "minecraft:air"},
        {pos: [10, 10, 0], state: "minecraft:air"},
        {pos: [10, 10, 1], state: "minecraft:air"},
        {pos: [10, 10, 2], state: "minecraft:air"},
        {pos: [10, 10, 3], state: "minecraft:air"},
        {pos: [10, 10, 4], state: "minecraft:air"},
        {pos: [14, 10, 1], state: "minecraft:air"},
        {pos: [14, 10, 2], state: "minecraft:air"},
        {pos: [14, 10, 3], state: "minecraft:air"},
        {pos: [0, 11, 1], state: "minecraft:air"},
        {pos: [0, 11, 2], state: "minecraft:air"},
        {pos: [0, 11, 3], state: "minecraft:air"},
        {pos: [1, 11, 2], state: "minecraft:air"},
        {pos: [2, 11, 1], state: "minecraft:air"},
        {pos: [2, 11, 2], state: "minecraft:air"},
        {pos: [2, 11, 3], state: "minecraft:air"},
        {pos: [3, 11, 0], state: "minecraft:air"},
        {pos: [3, 11, 1], state: "minecraft:air"},
        {pos: [3, 11, 2], state: "minecraft:air"},
        {pos: [3, 11, 3], state: "minecraft:air"},
        {pos: [3, 11, 4], state: "minecraft:air"},
        {pos: [4, 11, 0], state: "minecraft:air"},
        {pos: [4, 11, 1], state: "minecraft:air"},
        {pos: [4, 11, 2], state: "minecraft:air"},
        {pos: [4, 11, 3], state: "minecraft:air"},
        {pos: [4, 11, 4], state: "minecraft:air"},
        {pos: [5, 11, 0], state: "minecraft:air"},
        {pos: [5, 11, 1], state: "minecraft:air"},
        {pos: [5, 11, 2], state: "minecraft:air"},
        {pos: [5, 11, 3], state: "minecraft:air"},
        {pos: [5, 11, 4], state: "minecraft:air"},
        {pos: [6, 11, 1], state: "minecraft:air"},
        {pos: [6, 11, 2], state: "minecraft:air"},
        {pos: [6, 11, 3], state: "minecraft:air"},
        {pos: [7, 11, 1], state: "minecraft:air"},
        {pos: [7, 11, 2], state: "minecraft:air"},
        {pos: [7, 11, 3], state: "minecraft:air"},
        {pos: [8, 11, 0], state: "minecraft:air"},
        {pos: [8, 11, 1], state: "minecraft:air"},
        {pos: [8, 11, 2], state: "minecraft:air"},
        {pos: [8, 11, 3], state: "minecraft:air"},
        {pos: [8, 11, 4], state: "minecraft:air"},
        {pos: [9, 11, 0], state: "minecraft:air"},
        {pos: [9, 11, 1], state: "minecraft:air"},
        {pos: [9, 11, 2], state: "minecraft:air"},
        {pos: [9, 11, 3], state: "minecraft:air"},
        {pos: [9, 11, 4], state: "minecraft:air"},
        {pos: [10, 11, 0], state: "minecraft:air"},
        {pos: [10, 11, 1], state: "minecraft:air"},
        {pos: [10, 11, 2], state: "minecraft:air"},
        {pos: [10, 11, 3], state: "minecraft:air"},
        {pos: [10, 11, 4], state: "minecraft:air"},
        {pos: [3, 12, 0], state: "minecraft:air"},
        {pos: [3, 12, 1], state: "minecraft:air"},
        {pos: [3, 12, 2], state: "minecraft:air"},
        {pos: [3, 12, 3], state: "minecraft:air"},
        {pos: [3, 12, 4], state: "minecraft:air"},
        {pos: [4, 12, 0], state: "minecraft:air"},
        {pos: [4, 12, 1], state: "minecraft:air"},
        {pos: [4, 12, 2], state: "minecraft:air"},
        {pos: [4, 12, 3], state: "minecraft:air"},
        {pos: [4, 12, 4], state: "minecraft:air"},
        {pos: [5, 12, 0], state: "minecraft:air"},
        {pos: [5, 12, 1], state: "minecraft:air"},
        {pos: [5, 12, 2], state: "minecraft:air"},
        {pos: [5, 12, 3], state: "minecraft:air"},
        {pos: [5, 12, 4], state: "minecraft:air"},
        {pos: [6, 12, 1], state: "minecraft:air"},
        {pos: [6, 12, 2], state: "minecraft:air"},
        {pos: [6, 12, 3], state: "minecraft:air"},
        {pos: [7, 12, 1], state: "minecraft:air"},
        {pos: [7, 12, 2], state: "minecraft:air"},
        {pos: [7, 12, 3], state: "minecraft:air"},
        {pos: [8, 12, 0], state: "minecraft:air"},
        {pos: [8, 12, 1], state: "minecraft:air"},
        {pos: [8, 12, 2], state: "minecraft:air"},
        {pos: [8, 12, 3], state: "minecraft:air"},
        {pos: [8, 12, 4], state: "minecraft:air"},
        {pos: [9, 12, 0], state: "minecraft:air"},
        {pos: [9, 12, 1], state: "minecraft:air"},
        {pos: [9, 12, 2], state: "minecraft:air"},
        {pos: [9, 12, 3], state: "minecraft:air"},
        {pos: [9, 12, 4], state: "minecraft:air"},
        {pos: [10, 12, 0], state: "minecraft:air"},
        {pos: [10, 12, 1], state: "minecraft:air"},
        {pos: [10, 12, 2], state: "minecraft:air"},
        {pos: [10, 12, 3], state: "minecraft:air"},
        {pos: [10, 12, 4], state: "minecraft:air"},
        {pos: [5, 13, 0], state: "minecraft:air"},
        {pos: [5, 13, 1], state: "minecraft:air"},
        {pos: [5, 13, 2], state: "minecraft:air"},
        {pos: [5, 13, 3], state: "minecraft:air"},
        {pos: [5, 13, 4], state: "minecraft:air"},
        {pos: [6, 13, 1], state: "minecraft:air"},
        {pos: [6, 13, 2], state: "minecraft:air"},
        {pos: [6, 13, 3], state: "minecraft:air"},
        {pos: [7, 13, 2], state: "minecraft:air"},
        {pos: [7, 13, 3], state: "minecraft:air"},
        {pos: [8, 13, 0], state: "minecraft:air"},
        {pos: [8, 13, 1], state: "minecraft:air"},
        {pos: [8, 13, 2], state: "minecraft:air"},
        {pos: [8, 13, 3], state: "minecraft:air"},
        {pos: [8, 13, 4], state: "minecraft:air"},
        {pos: [9, 13, 0], state: "minecraft:air"},
        {pos: [9, 13, 1], state: "minecraft:air"},
        {pos: [9, 13, 2], state: "minecraft:air"},
        {pos: [9, 13, 3], state: "minecraft:air"},
        {pos: [9, 13, 4], state: "minecraft:air"},
        {pos: [10, 13, 0], state: "minecraft:air"},
        {pos: [10, 13, 1], state: "minecraft:air"},
        {pos: [10, 13, 2], state: "minecraft:air"},
        {pos: [10, 13, 3], state: "minecraft:air"},
        {pos: [10, 13, 4], state: "minecraft:air"},
        {pos: [2, 14, 1], state: "minecraft:air"},
        {pos: [2, 14, 2], state: "minecraft:air"},
        {pos: [2, 14, 3], state: "minecraft:air"},
        {pos: [3, 14, 0], state: "minecraft:air"},
        {pos: [3, 14, 1], state: "minecraft:air"},
        {pos: [3, 14, 2], state: "minecraft:air"},
        {pos: [3, 14, 3], state: "minecraft:air"},
        {pos: [3, 14, 4], state: "minecraft:air"},
        {pos: [4, 14, 0], state: "minecraft:air"},
        {pos: [4, 14, 1], state: "minecraft:air"},
        {pos: [4, 14, 2], state: "minecraft:air"},
        {pos: [4, 14, 3], state: "minecraft:air"},
        {pos: [4, 14, 4], state: "minecraft:air"},
        {pos: [5, 14, 0], state: "minecraft:air"},
        {pos: [5, 14, 1], state: "minecraft:air"},
        {pos: [5, 14, 2], state: "minecraft:air"},
        {pos: [5, 14, 3], state: "minecraft:air"},
        {pos: [5, 14, 4], state: "minecraft:air"},
        {pos: [6, 14, 1], state: "minecraft:air"},
        {pos: [6, 14, 2], state: "minecraft:air"},
        {pos: [6, 14, 3], state: "minecraft:air"},
        {pos: [7, 14, 1], state: "minecraft:air"},
        {pos: [7, 14, 2], state: "minecraft:air"},
        {pos: [7, 14, 3], state: "minecraft:air"},
        {pos: [8, 14, 0], state: "minecraft:air"},
        {pos: [8, 14, 1], state: "minecraft:air"},
        {pos: [8, 14, 2], state: "minecraft:air"},
        {pos: [8, 14, 3], state: "minecraft:air"},
        {pos: [8, 14, 4], state: "minecraft:air"},
        {pos: [9, 14, 0], state: "minecraft:air"},
        {pos: [9, 14, 1], state: "minecraft:air"},
        {pos: [9, 14, 2], state: "minecraft:air"},
        {pos: [9, 14, 3], state: "minecraft:air"},
        {pos: [9, 14, 4], state: "minecraft:air"},
        {pos: [10, 14, 0], state: "minecraft:air"},
        {pos: [10, 14, 1], state: "minecraft:air"},
        {pos: [10, 14, 2], state: "minecraft:air"},
        {pos: [10, 14, 3], state: "minecraft:air"},
        {pos: [10, 14, 4], state: "minecraft:air"},
        {pos: [2, 15, 1], state: "minecraft:air"},
        {pos: [2, 15, 2], state: "minecraft:air"},
        {pos: [2, 15, 3], state: "minecraft:air"},
        {pos: [3, 15, 0], state: "minecraft:air"},
